Workbook

Sheet GLOC Master Sheet
D2: Size | E2: 8x20 )ffice | F2: 8x40 O/S
B3: Item | C3: Description | D3: Total
B4: Chassis
C5: None, skid mount | E5: 1 | F5: 1
B9: Floor
C10: Std ISO Container Floor | E10: 1 | F10: 1
C11: Polystyrene to code under floor
B18: Exterior Wall Framing
C19: N/A ISO Container | F19: 1 | G19: 1
C20: Framed interior to accommodate insulation and interior wall covering
C21: Fiberglass Batt Insulation to code.
B26: Exterior Wall Finish
C27: Std ISO Container | F27: 1 | G27: 1 | H27: 1 | I27: 1
C28: Miller Paint V-315 Color: Agate Grey
B39: Roof
C40: Std ISO Container | F40: 1 | G40: 1
C41: Framed Interior to accommodate insulation and interior covering
C42: Polystyrene insulation to code
B51: Exterior Doors
C52: 3068 18ga. Hollow metal door with 16ga. Welded steel jamb - galvanized | F52: 1 | G52: 1
C53: Hinges - SS-BBH NRP
C54: Tell DB2051 deadbolt
C55: Tell LC2475 passage lever
C56: Tell LT2081 door chain
C57: Weatherstripping - ADA threshold and sweep
C58: Provide exterior security door bar
B59: Windows
C60: 4'x3' White vinyl horizontal slider | F60: 1 | G60: 1
C61: Glazing - dual- low E Argon filled
C62: Windows standard door height
C63: Provide interior security bars
B64: Floor Cover
C65: None- Std ISO container | F65: 1 | G65: 1
C66: Armstrong 4" rubber cove base "Light Gray" #69
C67: COVE BASE TO BE CONTINUOUS
B68: Wall Cover
C69: 5/8" vinyl wrap sheetrock - "Pebble Beach" texture "Pure White" color | F69: 1 | G69: 1
C70: 1/2" plywood storage side of interior wall | G70: 1
B71: Ceiling
C72: 5/8" vinyl wrap sheetrock - "Pebble Beach" texture "Pure White" color | F72: 1 | G72: 1
...

Sheet 08x20 GLOC Off
B2: Date: | E2: Size: | F2: 08x20 | H2: DESIGN LOADS:
B3: Customer: | E3: Description: | F3: GLOC office | H3: Floor: | I3: 50
B4: Location: | E4: Insignias: | F4: OR, WA, ID Gold | H4: Wind: | I4: 145/C
B5: Project: | E5: Climate Zone | H5: Roof: | I5: 40
C7: Chassis | I7: Floor
C8: ='GLOC Master Sheet'!C5 -> None, skid mount | I8: ='GLOC Master Sheet'!C10 -> Std ISO Container Floor
I9: ='GLOC Master Sheet'!C11 -> Polystyrene to code under floor
C12: Exterior Wall Framing | I12: Roof
C13: ='GLOC Master Sheet'!C19 -> N/A ISO Container | I13: ='GLOC Master Sheet'!C40 -> Std ISO Container
C14: ='GLOC Master Sheet'!C20 -> Framed interior to accommodate insulation and interior wall covering | I14: ='GLOC Master Sheet'!C41 -> Framed Interior to accommodate insulation and interior covering
C15: ='GLOC Master Sheet'!C21 -> Fiberglass Batt Insulation to code. | I15: ='GLOC Master Sheet'!C42 -> Polystyrene insulation to code
C19: Exterior Wall Finish | I19: Exterior Doors
C20: ='GLOC Master Sheet'!C27 -> Std ISO Container | I20: ='GLOC Master Sheet'!C52 -> 3068 18ga. Hollow metal door with 16ga. Welded steel jamb - galvanized
C21: ='GLOC Master Sheet'!C28 -> Miller Paint V-315 Color: Agate Grey | I21: ='GLOC Master Sheet'!C53 -> Hinges - SS-BBH NRP
I22: ='GLOC Master Sheet'!C54 -> Tell DB2051 deadbolt
I23: ='GLOC Master Sheet'!C55 -> Tell LC2475 passage lever
I24: ='GLOC Master Sheet'!C56 -> Tell LT2081 door chain
I25: ='GLOC Master Sheet'!C57 -> Weatherstripping - ADA threshold and sweep
I26: ='GLOC Master Sheet'!C58 -> Provide exterior security door bar
C28: Windows | I28: Floor Cover
C29: ='GLOC Master Sheet'!C60 -> 4'x3' White vinyl horizontal slider | I29: ='GLOC Master Sheet'!C65 -> None- Std ISO container
C30: ='GLOC Master Sheet'!C61 -> Glazing - dual- low E Argon filled | I30: ='GLOC Master Sheet'!C66 -> Armstrong 4" rubber cove base "Light Gray" #69
C31: ='GLOC Master Sheet'!C62 -> Windows standard door height | I31: ='GLOC Master Sheet'!C67 -> COVE BASE TO BE CONTINUOUS
C32: ='GLOC Master Sheet'!C63 -> Provide interior security bars
C33: Wall Cover | I33: Interior Trim
C34: ='GLOC Master Sheet'!C69 -> 5/8" vinyl wrap sheetrock - "Pebble Beach" texture "Pure White" color | I34: ='GLOC Master Sheet'!C76 -> Vinyl wrap corners
I35: ='GLOC Master Sheet'!C77 -> Vinyl wrap batts at each side of windows and doors at relief cuts
I36: ='GLOC Master Sheet'!C78 -> Window surrounds and casing - oak vinyl wrap
C37: HVAC | I37: Electrical
C38: ='GLOC Master Sheet'!C80 -> 1 ton 5KW Bard wall hung heat pump with economizer | I38: ='GLOC Master Sheet'!C92 -> 120/240V Single phase service-stub conduit through wall with LB
C39: ='GLOC Master Sheet'!C81 -> Direct blow HVAC - mount as high as possible | I39: ='GLOC Master Sheet'!C93 -> 100 amp load center
C40: ='GLOC Master Sheet'!C82 -> Bard model 8403-060 T-stat | I40: ='GLOC Master Sheet'!C94 -> 20 amp duplex receptacles per drawing
C41: ='GLOC Master Sheet'!C83 -> Outdoor T-stat | I41: ='GLOC Master Sheet'!C95 -> 20 amp GFCI per drawing
I42: ='GLOC Master Sheet'!C96 -> Occupancy sensor switching at exterior door
I43: ='GLOC Master Sheet'!C97 -> Phone/Data boxes per drawing stubbed above grid with 1/2" flex conduit.
I44: ='GLOC Master Sheet'!C98 -> Sign circuit at exterior per drawing to (1) 20 amp dedicated circuit
I45: ='GLOC Master Sheet'!C99 -> Harris model 300 porch light with vandal resistant cover-on photocell
I46: ='GLOC Master Sheet'!C100 -> 48" surface mount LED light fixtures per drawing
C48: Misc. | I48: Ceiling
C49: ='GLOC Master Sheet'!C112 -> 6"x6" W/P j-box-1" conduits with pull string stubbued above grid for future data | I49: ='GLOC Master Sheet'!C72 -> 5/8" vinyl wrap sheetrock - "Pebble Beach" texture "Pure White" color
...

Sheet 08x40 GLOC Off Stor
B2: Date: | E2: Size: | F2: 08x40 | H2: DESIGN LOADS:
B3: Customer: | E3: Description: | F3: GLOC office | H3: Floor: | I3: 50
B4: Location: | E4: Insignias: | F4: OR, WA, ID Gold | H4: Wind: | I4: 145/C
B5: Project: | E5: Climate Zone | H5: Roof: | I5: 40
C7: Chassis | I7: Floor
C8: ='GLOC Master Sheet'!C5 -> None, skid mount | I8: ='GLOC Master Sheet'!C10 -> Std ISO Container Floor
I9: ='GLOC Master Sheet'!C11 -> Polystyrene to code under floor
C12: Exterior Wall Framing | I12: Roof
C13: ='GLOC Master Sheet'!C19 -> N/A ISO Container | I13: ='GLOC Master Sheet'!C40 -> Std ISO Container
C14: ='GLOC Master Sheet'!C20 -> Framed interior to accommodate insulation and interior wall covering | I14: ='GLOC Master Sheet'!C41 -> Framed Interior to accommodate insulation and interior covering
C15: ='GLOC Master Sheet'!C21 -> Fiberglass Batt Insulation to code. | I15: ='GLOC Master Sheet'!C42 -> Polystyrene insulation to code
C19: Exterior Wall Finish | I19: Exterior Doors
C20: ='GLOC Master Sheet'!C27 -> Std ISO Container | I20: ='GLOC Master Sheet'!C52 -> 3068 18ga. Hollow metal door with 16ga. Welded steel jamb - galvanized
C21: ='GLOC Master Sheet'!C28 -> Miller Paint V-315 Color: Agate Grey | I21: ='GLOC Master Sheet'!C53 -> Hinges - SS-BBH NRP
I22: ='GLOC Master Sheet'!C54 -> Tell DB2051 deadbolt
I23: ='GLOC Master Sheet'!C55 -> Tell LC2475 passage lever
I24: ='GLOC Master Sheet'!C56 -> Tell LT2081 door chain
I25: ='GLOC Master Sheet'!C57 -> Weatherstripping - ADA threshold and sweep
I26: ='GLOC Master Sheet'!C58 -> Provide exterior security door bar
C28: Windows | I28: Floor Cover
C29: ='GLOC Master Sheet'!C60 -> 4'x3' White vinyl horizontal slider | I29: ='GLOC Master Sheet'!C65 -> None- Std ISO container
C30: ='GLOC Master Sheet'!C61 -> Glazing - dual- low E Argon filled | I30: ='GLOC Master Sheet'!C66 -> Armstrong 4" rubber cove base "Light Gray" #69
C31: ='GLOC Master Sheet'!C62 -> Windows standard door height | I31: ='GLOC Master Sheet'!C67 -> COVE BASE TO BE CONTINUOUS
C32: ='GLOC Master Sheet'!C63 -> Provide interior security bars
C33: Wall Cover | I33: Interior Trim
C34: ='GLOC Master Sheet'!C69 -> 5/8" vinyl wrap sheetrock - "Pebble Beach" texture "Pure White" color | I34: ='GLOC Master Sheet'!C76 -> Vinyl wrap corners
C35: ='GLOC Master Sheet'!C70 -> 1/2" plywood storage side of interior wall | I35: ='GLOC Master Sheet'!C77 -> Vinyl wrap batts at each side of windows and doors at relief cuts
I36: ='GLOC Master Sheet'!C78 -> Window surrounds and casing - oak vinyl wrap
C37: HVAC | I37: Electrical
C38: ='GLOC Master Sheet'!C80 -> 1 ton 5KW Bard wall hung heat pump with economizer | I38: ='GLOC Master Sheet'!C92 -> 120/240V Single phase service-stub conduit through wall with LB
C39: ='GLOC Master Sheet'!C81 -> Direct blow HVAC - mount as high as possible | I39: ='GLOC Master Sheet'!C93 -> 100 amp load center
C40: ='GLOC Master Sheet'!C82 -> Bard model 8403-060 T-stat | I40: ='GLOC Master Sheet'!C94 -> 20 amp duplex receptacles per drawing
C41: ='GLOC Master Sheet'!C83 -> Outdoor T-stat | I41: ='GLOC Master Sheet'!C95 -> 20 amp GFCI per drawing
I42: ='GLOC Master Sheet'!C96 -> Occupancy sensor switching at exterior door
I43: ='GLOC Master Sheet'!C97 -> Phone/Data boxes per drawing stubbed above grid with 1/2" flex conduit.
I44: ='GLOC Master Sheet'!C98 -> Sign circuit at exterior per drawing to (1) 20 amp dedicated circuit
I45: ='GLOC Master Sheet'!C99 -> Harris model 300 porch light with vandal resistant cover-on photocell
I46: ='GLOC Master Sheet'!C100 -> 48" surface mount LED light fixtures per drawing
C48: Misc. | I48: Ceiling
C49: ='GLOC Master Sheet'!C112 -> 6"x6" W/P j-box-1" conduits with pull string stubbued above grid for future data | I49: ='GLOC Master Sheet'!C72 -> 5/8" vinyl wrap sheetrock - "Pebble Beach" texture "Pure White" color
...

Sheet Single Wide Master Sheet
D2: Size | E2: 8x12 | F2: 8x16 | G2: 8x20 | H2: 8x24 | I2: 8x30 | J2: 10x24 | K2: 10x30 | L2: 10x30 RR | M2: 10x40 | N2: 10x40 RR | O2: 12x40 | P2: 12x44 RR | Q2: 12x56 | R2: 12x56 RR | S2: 14x66 | T2: 14x66 RR
B3: Item | C3: Description | D3: Total
B4: Chassis
C5: Conventional (outriggers every 8' with full length front and rear C-channel cross members) | F5: 1
C6: 8" I-beam main rail.
C7: 1-Brake axle with 8:00x14.5 14 ply tires - all new
C8: Detachable Hitch.
C9: Conventional (outriggers every 8' with full length front and rear C-channel cross members) | G9: 1 | H9: 1 | I9: 1 | J9: 1 | K9: 1 | L9: 1 | M9: 1 | N9: 1
C10: 10" I-beam main rail.
C11: 2-Brake axle with 8:00x14.5 14 ply tires - all new
C12: Detachable Hitch.
C13: Conventional (outriggers every 8' with full length front and rear C-channel cross members) | O13: 1 | P13: 1
C14: 12" I-beam main rail.
C15: 3-Brake axle with 8:00x14.5 14 ply tires - all new
C16: Detachable Hitch.
C17: Conventional (outriggers every 8' with full length front and rear C-channel cross members) | Q17: 1 | R17: 1
C18: 12" I-beam main rail. Provide double I-beam and full depth cross members at axle assemblies.
C19: 4-Brake axle with 8:00x14.5 14 ply tires.
C20: Detachable Hitch.
C21: Conventional (outriggers every 8' with full length front and rear C-channel cross members) | S21: 1 | T21: 1
C22: 12" I-beam main rail. Provide double I-beam and full depth cross members at axle assemblies.
C23: 5-Brake axle with 8:00x14.5 14 ply tires - all new
C24: Detachable Hitch.
B25: Floor
C26: 2"x8" floor joists @ 16" o/c with 2"x8" double rim joists. | F26: 1 | G26: 1 | H26: 1 | I26: 1 | J26: 1 | K26: 1 | L26: 1 | M26: 1 | N26: 1
C27: Class "A" woven poly fabric bottom board.
C28: Fiberglass batt insulation to code.
C29: 3/4" T&G decking-glued and nailed
C30: 2"x8" floor joists @ 16" o/c with 2"x8" double rim joists. | O30: 1 | P30: 1 | Q30: 1 | R30: 1 | S30: 1 | T30: 1
C31: Class "A" woven poly fabric bottom board.
C32: Fiberglass batt insulation to code.
C33: 3/4" T&G decking-glued and nailed.
B34: Exterior Wall Framing
C35: 2"x6" framing @ 16" o/c | F35: 1 | G35: 1 | H35: 1 | I35: 1
C36: Insulation to code.
C37: End wall sheathing full height interior side of wall
C38: 2"x6" framing @ 16" o/c | J38: 1 | K38: 1 | L38: 1 | M38: 1 | N38: 1
C39: Insulation to code.
C40: End wall sheathing full height interior side of wall
C42: 2x6 framing @ 16" o/c | O42: 1 | P42: 1 | Q42: 1 | R42: 1 | S42: 1 | T42: 1
...

Sheet 8x16
B2: Date: | E2: Size: | F2: 08x16 | H2: DESIGN LOADS:
B3: Customer: | E3: Description: | F3: Mobile Office | H3: Floor: | I3: 50
B4: Location: | E4: Insignias: | F4: OR, WA, ID Gold | H4: Wind: | I4: 110/B
B5: Project: | E5: Climate Zone | H5: Roof: | I5: 40
C7: Chassis | I7: Floor
C8: ='Single Wide Master Sheet'!C5 -> Conventional (outriggers every 8' with full length front and rear C-channel cross members) | I8: ='Single Wide Master Sheet'!C26 -> 2"x8" floor joists @ 16" o/c with 2"x8" double rim joists.
C9: ='Single Wide Master Sheet'!C6 -> 8" I-beam main rail. | I9: ='Single Wide Master Sheet'!C27 -> Class "A" woven poly fabric bottom board.
C10: ='Single Wide Master Sheet'!C7 -> 1-Brake axle with 8:00x14.5 14 ply tires - all new | I10: ='Single Wide Master Sheet'!C28 -> Fiberglass batt insulation to code.
C11: ='Single Wide Master Sheet'!C8 -> Detachable Hitch. | I11: ='Single Wide Master Sheet'!C29 -> 3/4" T&G decking-glued and nailed
C12: Exterior Wall Framing | I12: Roof
C13: ='Single Wide Master Sheet'!C35 -> 2"x6" framing @ 16" o/c | I13: ='Single Wide Master Sheet'!C66 -> Single slope away from doors
C14: ='Single Wide Master Sheet'!C36 -> Insulation to code. | I14: ='Single Wide Master Sheet'!C67 -> Bottom cover class "A" woven polyethelene fabric
C15: ='Single Wide Master Sheet'!C37 -> End wall sheathing full height interior side of wall | I15: ='Single Wide Master Sheet'!C68 -> 45 mil Black EPDM roofing with J-rail - Fasten j-rail with grommeted screws
I16: ='Single Wide Master Sheet'!#REF! -> #REF!
I17: ='Single Wide Master Sheet'!C69 -> 7/16" OSB sheathing
I18: ='Single Wide Master Sheet'!C70 -> Eave venting
C19: Exterior Wall Finish | I19: Exterior Doors
C20: ='Single Wide Master Sheet'!C47 -> 7/16" LP Smartside Panel T1-11 siding with grooves 8" o/c - roof deck to top of belt rail | I20: ='Single Wide Master Sheet'!C83 -> 3068 Telstar Pro - painted
C21: ='Single Wide Master Sheet'!C48 -> Wrap building with Tyvek building wrap (or equivalent) | I21: ='Single Wide Master Sheet'!C84 -> Hinges - SS-BBH NRP
C22: ='Single Wide Master Sheet'!C49 -> Corner trim - 5/8"x4" Smartside trim - 2"x2" galvanized flashing installed over siding and under corners. | I22: ='Single Wide Master Sheet'!C85 -> Tell DB2051 deadbolt
I23: ='Single Wide Master Sheet'!C86 -> Int/Ext pull handles
C24: ='Single Wide Master Sheet'!C50 -> Window trim - 5/8"x4" Smartside Trim. | I24: ='Single Wide Master Sheet'!C87 -> Tell 12916 door closer
C25: ='Single Wide Master Sheet'!C51 -> Fascia - 5/8"x8" Smartside trim, no grooves | I25: ='Single Wide Master Sheet'!C88 -> Weatherstripping - ADA threshold and sweep
C26: ='Single Wide Master Sheet'!C52 -> Belt Rail - 4"x7/16" LP Smartside trim. 1/2" Z-flashing installed at bottom of siding and top of belt rail - 2" back leg and 3/4" front leg. | I26: ='Single Wide Master Sheet'!C89 -> DEADBOLTS TO BE INSTALLED BELOW PULL HANDLES
I27: ='Single Wide Master Sheet'!C90 -> "THIS DOOR TO REMAIN UNLOCKED WHEN BUILDING IS OCCUPIED" SIGN ABOVE EXTERIOR DOORS
I28: ='Single Wide Master Sheet'!C91 -> DOOR HARDWARE TO HAVE #626 SATIN CHROMIUM PLATED FINISH
C29: Windows | I29: Floor Cover
C30: ='Single Wide Master Sheet'!C93 -> 4'x3' White vinyl horizontal slider | I30: ='Single Wide Master Sheet'!C98 -> Armstrong "Standard Excelon" 1/8" VCT "Shelter White" #51836
C31: ='Single Wide Master Sheet'!C94 -> Glazing - dual- low E Argon filled | I31: ='Single Wide Master Sheet'!C99 -> VCT layout - 1/4 turn with 6" offset
C32: ='Single Wide Master Sheet'!C95 -> Windows installed over siding | I32: ='Single Wide Master Sheet'!C100 -> Armstrong 4" rubber cove base "Light Gray" #69
C33: ='Single Wide Master Sheet'!C96 -> Galvanized flashing installed under siding and over top flange of window, under trim. | I33: ='Single Wide Master Sheet'!C101 -> COVE BASE TO BE CONTINUOUS
C34: Wall Cover | I34: Interior Trim
C35: ='Single Wide Master Sheet'!C103 -> 7/16" OSB sheathing above sheetrock at sidewalls | I35: ='Single Wide Master Sheet'!C111 -> Vinyl wrap corners
C36: ='Single Wide Master Sheet'!C104 -> 7/16" OSB sheathing under sheetrock at endwalls- full height | I36: ='Single Wide Master Sheet'!C112 -> Vinyl wrap batts at each side of windows and doors at relief cuts
C37: ='Single Wide Master Sheet'!C105 -> 5/8" vinyl wrap sheetrock - "Pebble Beach" texture "Pure White" color | I37: ='Single Wide Master Sheet'!C113 -> Window and exterior door surrounds and casing - oak vinyl wrap
C38: HVAC | I38: Electrical
C39: ='Single Wide Master Sheet'!C115 -> 1.5 ton 4KW Bard wall hung heat pump with economizer | I39: ='Single Wide Master Sheet'!C145 -> 120/240V Single phase service-stub conduit below joists
C40: ='Single Wide Master Sheet'!C116 -> Overhead supply ducting | I40: ='Single Wide Master Sheet'!C146 -> 125 amp load center
C41: ='Single Wide Master Sheet'!C117 -> 24"x24" diffuser with no dampers | I41: ='Single Wide Master Sheet'!C147 -> 20 amp duplex receptacles per drawing - white finishes
C42: ='Single Wide Master Sheet'!C118 -> Bard model 8403-060 T-stat | I42: ='Single Wide Master Sheet'!C148 -> 15 amp GFCI per drawing
...

Sheet 08x20
B2: Date: | E2: Size: | F2: 08x20 | H2: DESIGN LOADS:
B3: Customer: | E3: Description: | F3: Mobile Office | H3: Floor: | I3: 50
B4: Location: | E4: Insignias: | F4: OR, WA, ID Gold | H4: Wind: | I4: 110/B
B5: Project: | E5: Climate Zone | H5: Roof: | I5: 40
C7: Chassis | I7: Floor
C8: ='Single Wide Master Sheet'!C9 -> Conventional (outriggers every 8' with full length front and rear C-channel cross members) | I8: ='Single Wide Master Sheet'!C26 -> 2"x8" floor joists @ 16" o/c with 2"x8" double rim joists.
C9: ='Single Wide Master Sheet'!C10 -> 10" I-beam main rail. | I9: ='Single Wide Master Sheet'!C27 -> Class "A" woven poly fabric bottom board.
C10: ='Single Wide Master Sheet'!C11 -> 2-Brake axle with 8:00x14.5 14 ply tires - all new | I10: ='Single Wide Master Sheet'!C28 -> Fiberglass batt insulation to code.
C11: ='Single Wide Master Sheet'!C12 -> Detachable Hitch. | I11: ='Single Wide Master Sheet'!C29 -> 3/4" T&G decking-glued and nailed
C12: Exterior Wall Framing | I12: Roof
C13: ='Single Wide Master Sheet'!C35 -> 2"x6" framing @ 16" o/c | I13: ='Single Wide Master Sheet'!C66 -> Single slope away from doors
C14: ='Single Wide Master Sheet'!C36 -> Insulation to code. | I14: ='Single Wide Master Sheet'!C67 -> Bottom cover class "A" woven polyethelene fabric
C15: ='Single Wide Master Sheet'!C37 -> End wall sheathing full height interior side of wall | I15: ='Single Wide Master Sheet'!C68 -> 45 mil Black EPDM roofing with J-rail - Fasten j-rail with grommeted screws
I16: ='Single Wide Master Sheet'!#REF! -> #REF!
I17: ='Single Wide Master Sheet'!C69 -> 7/16" OSB sheathing
I18: ='Single Wide Master Sheet'!C70 -> Eave venting
C19: Exterior Wall Finish | I19: Exterior Doors
C20: ='Single Wide Master Sheet'!C47 -> 7/16" LP Smartside Panel T1-11 siding with grooves 8" o/c - roof deck to top of belt rail | I20: ='Single Wide Master Sheet'!C83 -> 3068 Telstar Pro - painted
C21: ='Single Wide Master Sheet'!C48 -> Wrap building with Tyvek building wrap (or equivalent) | I21: ='Single Wide Master Sheet'!C84 -> Hinges - SS-BBH NRP
C22: ='Single Wide Master Sheet'!C49 -> Corner trim - 5/8"x4" Smartside trim - 2"x2" galvanized flashing installed over siding and under corners. | I22: ='Single Wide Master Sheet'!C85 -> Tell DB2051 deadbolt
I23: ='Single Wide Master Sheet'!C86 -> Int/Ext pull handles
C24: ='Single Wide Master Sheet'!C50 -> Window trim - 5/8"x4" Smartside Trim. | I24: ='Single Wide Master Sheet'!C87 -> Tell 12916 door closer
C25: ='Single Wide Master Sheet'!C51 -> Fascia - 5/8"x8" Smartside trim, no grooves | I25: ='Single Wide Master Sheet'!C88 -> Weatherstripping - ADA threshold and sweep
C26: ='Single Wide Master Sheet'!C52 -> Belt Rail - 4"x7/16" LP Smartside trim. 1/2" Z-flashing installed at bottom of siding and top of belt rail - 2" back leg and 3/4" front leg. | I26: ='Single Wide Master Sheet'!C89 -> DEADBOLTS TO BE INSTALLED BELOW PULL HANDLES
I27: ='Single Wide Master Sheet'!C90 -> "THIS DOOR TO REMAIN UNLOCKED WHEN BUILDING IS OCCUPIED" SIGN ABOVE EXTERIOR DOORS
I28: ='Single Wide Master Sheet'!C91 -> DOOR HARDWARE TO HAVE #626 SATIN CHROMIUM PLATED FINISH
C29: Windows | I29: Floor Cover
C30: ='Single Wide Master Sheet'!C93 -> 4'x3' White vinyl horizontal slider | I30: ='Single Wide Master Sheet'!C98 -> Armstrong "Standard Excelon" 1/8" VCT "Shelter White" #51836
C31: ='Single Wide Master Sheet'!C94 -> Glazing - dual- low E Argon filled | I31: ='Single Wide Master Sheet'!C99 -> VCT layout - 1/4 turn with 6" offset
C32: ='Single Wide Master Sheet'!C95 -> Windows installed over siding | I32: ='Single Wide Master Sheet'!C100 -> Armstrong 4" rubber cove base "Light Gray" #69
C33: ='Single Wide Master Sheet'!C96 -> Galvanized flashing installed under siding and over top flange of window, under trim. | I33: ='Single Wide Master Sheet'!C101 -> COVE BASE TO BE CONTINUOUS
C34: Wall Cover | I34: Interior Trim
C35: ='Single Wide Master Sheet'!C103 -> 7/16" OSB sheathing above sheetrock at sidewalls | I35: ='Single Wide Master Sheet'!C111 -> Vinyl wrap corners
C36: ='Single Wide Master Sheet'!C104 -> 7/16" OSB sheathing under sheetrock at endwalls- full height | I36: ='Single Wide Master Sheet'!C112 -> Vinyl wrap batts at each side of windows and doors at relief cuts
C37: ='Single Wide Master Sheet'!C105 -> 5/8" vinyl wrap sheetrock - "Pebble Beach" texture "Pure White" color | I37: ='Single Wide Master Sheet'!C113 -> Window and exterior door surrounds and casing - oak vinyl wrap
C38: HVAC | I38: Electrical
C39: ='Single Wide Master Sheet'!C115 -> 1.5 ton 4KW Bard wall hung heat pump with economizer | I39: ='Single Wide Master Sheet'!C145 -> 120/240V Single phase service-stub conduit below joists
C40: ='Single Wide Master Sheet'!C116 -> Overhead supply ducting | I40: ='Single Wide Master Sheet'!C146 -> 125 amp load center
C41: ='Single Wide Master Sheet'!C117 -> 24"x24" diffuser with no dampers | I41: ='Single Wide Master Sheet'!C147 -> 20 amp duplex receptacles per drawing - white finishes
C42: ='Single Wide Master Sheet'!C118 -> Bard model 8403-060 T-stat | I42: ='Single Wide Master Sheet'!C148 -> 15 amp GFCI per drawing
...

Sheet 8x24
B2: Date: | E2: Size: | F2: 08x24 | H2: DESIGN LOADS:
B3: Customer: | E3: Description: | F3: Mobile Office | H3: Floor: | I3: 50
B4: Location: | E4: Insignias: | F4: OR, WA, ID Gold | H4: Wind: | I4: 110/B
B5: Project: | E5: Climate Zone | H5: Roof: | I5: 40
C7: Chassis | I7: Floor
C8: ='Single Wide Master Sheet'!C9 -> Conventional (outriggers every 8' with full length front and rear C-channel cross members) | I8: ='Single Wide Master Sheet'!C26 -> 2"x8" floor joists @ 16" o/c with 2"x8" double rim joists.
C9: ='Single Wide Master Sheet'!C10 -> 10" I-beam main rail. | I9: ='Single Wide Master Sheet'!C27 -> Class "A" woven poly fabric bottom board.
C10: ='Single Wide Master Sheet'!C11 -> 2-Brake axle with 8:00x14.5 14 ply tires - all new | I10: ='Single Wide Master Sheet'!C28 -> Fiberglass batt insulation to code.
C11: ='Single Wide Master Sheet'!C12 -> Detachable Hitch. | I11: ='Single Wide Master Sheet'!C29 -> 3/4" T&G decking-glued and nailed
C12: Exterior Wall Framing | I12: Roof
C13: ='Single Wide Master Sheet'!C35 -> 2"x6" framing @ 16" o/c | I13: ='Single Wide Master Sheet'!C66 -> Single slope away from doors
C14: ='Single Wide Master Sheet'!C36 -> Insulation to code. | I14: ='Single Wide Master Sheet'!C67 -> Bottom cover class "A" woven polyethelene fabric
C15: ='Single Wide Master Sheet'!C37 -> End wall sheathing full height interior side of wall | I15: ='Single Wide Master Sheet'!C68 -> 45 mil Black EPDM roofing with J-rail - Fasten j-rail with grommeted screws
I16: ='Single Wide Master Sheet'!#REF! -> #REF!
I17: ='Single Wide Master Sheet'!C69 -> 7/16" OSB sheathing
I18: ='Single Wide Master Sheet'!C70 -> Eave venting
C19: Exterior Wall Finish | I19: Exterior Doors
C20: ='Single Wide Master Sheet'!C47 -> 7/16" LP Smartside Panel T1-11 siding with grooves 8" o/c - roof deck to top of belt rail | I20: ='Single Wide Master Sheet'!C83 -> 3068 Telstar Pro - painted
C21: ='Single Wide Master Sheet'!C48 -> Wrap building with Tyvek building wrap (or equivalent) | I21: ='Single Wide Master Sheet'!C84 -> Hinges - SS-BBH NRP
C22: ='Single Wide Master Sheet'!C49 -> Corner trim - 5/8"x4" Smartside trim - 2"x2" galvanized flashing installed over siding and under corners. | I22: ='Single Wide Master Sheet'!C85 -> Tell DB2051 deadbolt
I23: ='Single Wide Master Sheet'!C86 -> Int/Ext pull handles
C24: ='Single Wide Master Sheet'!C50 -> Window trim - 5/8"x4" Smartside Trim. | I24: ='Single Wide Master Sheet'!C87 -> Tell 12916 door closer
C25: ='Single Wide Master Sheet'!C51 -> Fascia - 5/8"x8" Smartside trim, no grooves | I25: ='Single Wide Master Sheet'!C88 -> Weatherstripping - ADA threshold and sweep
C26: ='Single Wide Master Sheet'!C52 -> Belt Rail - 4"x7/16" LP Smartside trim. 1/2" Z-flashing installed at bottom of siding and top of belt rail - 2" back leg and 3/4" front leg. | I26: ='Single Wide Master Sheet'!C89 -> DEADBOLTS TO BE INSTALLED BELOW PULL HANDLES
I27: ='Single Wide Master Sheet'!C90 -> "THIS DOOR TO REMAIN UNLOCKED WHEN BUILDING IS OCCUPIED" SIGN ABOVE EXTERIOR DOORS
I28: ='Single Wide Master Sheet'!C91 -> DOOR HARDWARE TO HAVE #626 SATIN CHROMIUM PLATED FINISH
C29: Windows | I29: Floor Cover
C30: ='Single Wide Master Sheet'!C93 -> 4'x3' White vinyl horizontal slider | I30: ='Single Wide Master Sheet'!C98 -> Armstrong "Standard Excelon" 1/8" VCT "Shelter White" #51836
C31: ='Single Wide Master Sheet'!C94 -> Glazing - dual- low E Argon filled | I31: ='Single Wide Master Sheet'!C99 -> VCT layout - 1/4 turn with 6" offset
C32: ='Single Wide Master Sheet'!C95 -> Windows installed over siding | I32: ='Single Wide Master Sheet'!C100 -> Armstrong 4" rubber cove base "Light Gray" #69
C33: ='Single Wide Master Sheet'!C96 -> Galvanized flashing installed under siding and over top flange of window, under trim. | I33: ='Single Wide Master Sheet'!C101 -> COVE BASE TO BE CONTINUOUS
C34: Wall Cover | I34: Interior Trim
C35: ='Single Wide Master Sheet'!C103 -> 7/16" OSB sheathing above sheetrock at sidewalls | I35: ='Single Wide Master Sheet'!C111 -> Vinyl wrap corners
C36: ='Single Wide Master Sheet'!C104 -> 7/16" OSB sheathing under sheetrock at endwalls- full height | I36: ='Single Wide Master Sheet'!C112 -> Vinyl wrap batts at each side of windows and doors at relief cuts
C37: ='Single Wide Master Sheet'!C105 -> 5/8" vinyl wrap sheetrock - "Pebble Beach" texture "Pure White" color | I37: ='Single Wide Master Sheet'!C113 -> Window and exterior door surrounds and casing - oak vinyl wrap
C38: HVAC | I38: Electrical
C39: ='Single Wide Master Sheet'!C115 -> 1.5 ton 4KW Bard wall hung heat pump with economizer | I39: ='Single Wide Master Sheet'!C145 -> 120/240V Single phase service-stub conduit below joists
C40: ='Single Wide Master Sheet'!C116 -> Overhead supply ducting | I40: ='Single Wide Master Sheet'!C146 -> 125 amp load center
C41: ='Single Wide Master Sheet'!C117 -> 24"x24" diffuser with no dampers | I41: ='Single Wide Master Sheet'!C147 -> 20 amp duplex receptacles per drawing - white finishes
C42: ='Single Wide Master Sheet'!C118 -> Bard model 8403-060 T-stat | I42: ='Single Wide Master Sheet'!C148 -> 15 amp GFCI per drawing
...

Sheet 8x30
B2: Date: | E2: Size: | F2: 08x30 | H2: DESIGN LOADS:
B3: Customer: | E3: Description: | F3: Mobile Office | H3: Floor: | I3: 50
B4: Location: | E4: Insignias: | F4: OR, WA, ID Gold | H4: Wind: | I4: 110/B
B5: Project: | E5: Climate Zone | H5: Roof: | I5: 40
C7: Chassis | I7: Floor
C8: ='Single Wide Master Sheet'!C9 -> Conventional (outriggers every 8' with full length front and rear C-channel cross members) | I8: ='Single Wide Master Sheet'!C26 -> 2"x8" floor joists @ 16" o/c with 2"x8" double rim joists.
C9: ='Single Wide Master Sheet'!C10 -> 10" I-beam main rail. | I9: ='Single Wide Master Sheet'!C27 -> Class "A" woven poly fabric bottom board.
C10: ='Single Wide Master Sheet'!C11 -> 2-Brake axle with 8:00x14.5 14 ply tires - all new | I10: ='Single Wide Master Sheet'!C28 -> Fiberglass batt insulation to code.
C11: ='Single Wide Master Sheet'!C12 -> Detachable Hitch. | I11: ='Single Wide Master Sheet'!C29 -> 3/4" T&G decking-glued and nailed
C12: Exterior Wall Framing | I12: Roof
C13: ='Single Wide Master Sheet'!C35 -> 2"x6" framing @ 16" o/c | I13: ='Single Wide Master Sheet'!C66 -> Single slope away from doors
C14: ='Single Wide Master Sheet'!C36 -> Insulation to code. | I14: ='Single Wide Master Sheet'!C67 -> Bottom cover class "A" woven polyethelene fabric
C15: ='Single Wide Master Sheet'!C37 -> End wall sheathing full height interior side of wall | I15: ='Single Wide Master Sheet'!C68 -> 45 mil Black EPDM roofing with J-rail - Fasten j-rail with grommeted screws
I16: ='Single Wide Master Sheet'!#REF! -> #REF!
I17: ='Single Wide Master Sheet'!C69 -> 7/16" OSB sheathing
I18: ='Single Wide Master Sheet'!C70 -> Eave venting
C19: Exterior Wall Finish | I19: Exterior Doors
C20: ='Single Wide Master Sheet'!C47 -> 7/16" LP Smartside Panel T1-11 siding with grooves 8" o/c - roof deck to top of belt rail | I20: ='Single Wide Master Sheet'!C83 -> 3068 Telstar Pro - painted
C21: ='Single Wide Master Sheet'!C48 -> Wrap building with Tyvek building wrap (or equivalent) | I21: ='Single Wide Master Sheet'!C84 -> Hinges - SS-BBH NRP
C22: ='Single Wide Master Sheet'!C49 -> Corner trim - 5/8"x4" Smartside trim - 2"x2" galvanized flashing installed over siding and under corners. | I22: ='Single Wide Master Sheet'!C85 -> Tell DB2051 deadbolt
I23: ='Single Wide Master Sheet'!C86 -> Int/Ext pull handles
C24: ='Single Wide Master Sheet'!C50 -> Window trim - 5/8"x4" Smartside Trim. | I24: ='Single Wide Master Sheet'!C87 -> Tell 12916 door closer
C25: ='Single Wide Master Sheet'!C51 -> Fascia - 5/8"x8" Smartside trim, no grooves | I25: ='Single Wide Master Sheet'!C88 -> Weatherstripping - ADA threshold and sweep
C26: ='Single Wide Master Sheet'!C52 -> Belt Rail - 4"x7/16" LP Smartside trim. 1/2" Z-flashing installed at bottom of siding and top of belt rail - 2" back leg and 3/4" front leg. | I26: ='Single Wide Master Sheet'!C89 -> DEADBOLTS TO BE INSTALLED BELOW PULL HANDLES
I27: ='Single Wide Master Sheet'!C90 -> "THIS DOOR TO REMAIN UNLOCKED WHEN BUILDING IS OCCUPIED" SIGN ABOVE EXTERIOR DOORS
I28: ='Single Wide Master Sheet'!C91 -> DOOR HARDWARE TO HAVE #626 SATIN CHROMIUM PLATED FINISH
C29: Windows | I29: Floor Cover
C30: ='Single Wide Master Sheet'!C93 -> 4'x3' White vinyl horizontal slider | I30: ='Single Wide Master Sheet'!C98 -> Armstrong "Standard Excelon" 1/8" VCT "Shelter White" #51836
C31: ='Single Wide Master Sheet'!C94 -> Glazing - dual- low E Argon filled | I31: ='Single Wide Master Sheet'!C99 -> VCT layout - 1/4 turn with 6" offset
C32: ='Single Wide Master Sheet'!C95 -> Windows installed over siding | I32: ='Single Wide Master Sheet'!C100 -> Armstrong 4" rubber cove base "Light Gray" #69
C33: ='Single Wide Master Sheet'!C96 -> Galvanized flashing installed under siding and over top flange of window, under trim. | I33: ='Single Wide Master Sheet'!C101 -> COVE BASE TO BE CONTINUOUS
C34: Wall Cover | I34: Interior Trim
C35: ='Single Wide Master Sheet'!C103 -> 7/16" OSB sheathing above sheetrock at sidewalls | I35: ='Single Wide Master Sheet'!C111 -> Vinyl wrap corners
C36: ='Single Wide Master Sheet'!C104 -> 7/16" OSB sheathing under sheetrock at endwalls- full height | I36: ='Single Wide Master Sheet'!C112 -> Vinyl wrap batts at each side of windows and doors at relief cuts
C37: ='Single Wide Master Sheet'!C105 -> 5/8" vinyl wrap sheetrock - "Pebble Beach" texture "Pure White" color | I37: ='Single Wide Master Sheet'!C113 -> Window and exterior door surrounds and casing - oak vinyl wrap
C38: HVAC | I38: Electrical
C39: ='Single Wide Master Sheet'!C115 -> 1.5 ton 4KW Bard wall hung heat pump with economizer | I39: ='Single Wide Master Sheet'!C145 -> 120/240V Single phase service-stub conduit below joists
C40: ='Single Wide Master Sheet'!C116 -> Overhead supply ducting | I40: ='Single Wide Master Sheet'!C146 -> 125 amp load center
C41: ='Single Wide Master Sheet'!C117 -> 24"x24" diffuser with no dampers | I41: ='Single Wide Master Sheet'!C147 -> 20 amp duplex receptacles per drawing - white finishes
C42: ='Single Wide Master Sheet'!C118 -> Bard model 8403-060 T-stat | I42: ='Single Wide Master Sheet'!C148 -> 15 amp GFCI per drawing
...

Sheet 10x24
B2: Date: | E2: Size: | F2: 10x24 | H2: DESIGN LOADS:
B3: Customer: | E3: Description: | F3: Mobile Office | H3: Floor: | I3: 50
B4: Location: | E4: Insignias: | F4: OR, WA, ID | H4: Wind: | I4: 135/C
B5: Project: | E5: Climate Zone | H5: Roof: | I5: 40
C7: Chassis | I7: Floor
C8: ='Single Wide Master Sheet'!C9 -> Conventional (outriggers every 8' with full length front and rear C-channel cross members) | I8: ='Single Wide Master Sheet'!C26 -> 2"x8" floor joists @ 16" o/c with 2"x8" double rim joists.
C9: ='Single Wide Master Sheet'!C10 -> 10" I-beam main rail. | I9: ='Single Wide Master Sheet'!C27 -> Class "A" woven poly fabric bottom board.
C10: ='Single Wide Master Sheet'!C11 -> 2-Brake axle with 8:00x14.5 14 ply tires - all new | I10: ='Single Wide Master Sheet'!C28 -> Fiberglass batt insulation to code.
C11: ='Single Wide Master Sheet'!C12 -> Detachable Hitch. | I11: ='Single Wide Master Sheet'!C29 -> 3/4" T&G decking-glued and nailed
C12: Exterior Wall Framing | I12: Roof
C13: ='Single Wide Master Sheet'!C38 -> 2"x6" framing @ 16" o/c | I13: ='Single Wide Master Sheet'!C71 -> Single slope away from doors
C14: ='Single Wide Master Sheet'!C39 -> Insulation to code. | I14: ='Single Wide Master Sheet'!C72 -> Bottom cover class "A" woven polyethelene fabric
C15: ='Single Wide Master Sheet'!C40 -> End wall sheathing full height interior side of wall | I15: ='Single Wide Master Sheet'!C73 -> 45 mil Black EPDM roofing with J-rail - Fasten j-rail with grommeted screws
I16: ='Single Wide Master Sheet'!C74 -> Insulation to code.
I17: ='Single Wide Master Sheet'!C75 -> 7/16" OSB sheathing
I18: ='Single Wide Master Sheet'!C76 -> Eave venting
C19: Exterior Wall Finish | I19: Exterior Doors
C20: ='Single Wide Master Sheet'!C53 -> 7/16" LP Smartside Panel T1-11 siding with grooves 8" o/c - roof deck to top of belt rail | I20: ='Single Wide Master Sheet'!C83 -> 3068 Telstar Pro - painted
C21: ='Single Wide Master Sheet'!C54 -> Wrap building with Tyvek building wrap (or equivalent) | I21: ='Single Wide Master Sheet'!C84 -> Hinges - SS-BBH NRP
C22: ='Single Wide Master Sheet'!C55 -> Corner trim - 5/8"x4" Smartside trim - 2"x2" galvanized flashing installed over siding and under corners. | I22: ='Single Wide Master Sheet'!C85 -> Tell DB2051 deadbolt
I23: ='Single Wide Master Sheet'!C86 -> Int/Ext pull handles
C24: ='Single Wide Master Sheet'!C56 -> Window trim - 5/8"x4" Smartside Trim. | I24: ='Single Wide Master Sheet'!C87 -> Tell 12916 door closer
C25: ='Single Wide Master Sheet'!C57 -> Fascia - 5/8"x8" Smartside trim, no grooves | I25: ='Single Wide Master Sheet'!C88 -> Weatherstripping - ADA threshold and sweep
C26: ='Single Wide Master Sheet'!C58 -> Belt Rail - 6"x7/16" LP Smartside trim. 1/2" Z-flashing installed at bottom of siding and top of belt rail - 2" back leg and 3/4" front leg. | I26: ='Single Wide Master Sheet'!C89 -> DEADBOLTS TO BE INSTALLED BELOW PULL HANDLES
I27: ='Single Wide Master Sheet'!C90 -> "THIS DOOR TO REMAIN UNLOCKED WHEN BUILDING IS OCCUPIED" SIGN ABOVE EXTERIOR DOORS
I28: ='Single Wide Master Sheet'!C91 -> DOOR HARDWARE TO HAVE #626 SATIN CHROMIUM PLATED FINISH
C29: Windows | I29: Floor Cover
C30: ='Single Wide Master Sheet'!C93 -> 4'x3' White vinyl horizontal slider | I30: ='Single Wide Master Sheet'!C98 -> Armstrong "Standard Excelon" 1/8" VCT "Shelter White" #51836
C31: ='Single Wide Master Sheet'!C94 -> Glazing - dual- low E Argon filled | I31: ='Single Wide Master Sheet'!C99 -> VCT layout - 1/4 turn with 6" offset
C32: ='Single Wide Master Sheet'!C95 -> Windows installed over siding | I32: ='Single Wide Master Sheet'!C100 -> Armstrong 4" rubber cove base "Light Gray" #69
C33: ='Single Wide Master Sheet'!C96 -> Galvanized flashing installed under siding and over top flange of window, under trim. | I33: ='Single Wide Master Sheet'!C101 -> COVE BASE TO BE CONTINUOUS
C34: Wall Cover | I34: Interior Trim
C35: ='Single Wide Master Sheet'!C103 -> 7/16" OSB sheathing above sheetrock at sidewalls | I35: ='Single Wide Master Sheet'!C111 -> Vinyl wrap corners
C36: ='Single Wide Master Sheet'!C104 -> 7/16" OSB sheathing under sheetrock at endwalls- full height | I36: ='Single Wide Master Sheet'!C112 -> Vinyl wrap batts at each side of windows and doors at relief cuts
C37: ='Single Wide Master Sheet'!C105 -> 5/8" vinyl wrap sheetrock - "Pebble Beach" texture "Pure White" color | I37: ='Single Wide Master Sheet'!C113 -> Window and exterior door surrounds and casing - oak vinyl wrap
C38: HVAC | I38: Electrical
C39: ='Single Wide Master Sheet'!C120 -> 1.5 ton 8KW Bard wall hung heat pump with economizer | I39: ='Single Wide Master Sheet'!C145 -> 120/240V Single phase service-stub conduit below joists
C40: ='Single Wide Master Sheet'!C121 -> Overhead supply ducting | I40: ='Single Wide Master Sheet'!C146 -> 125 amp load center
C41: ='Single Wide Master Sheet'!C122 -> 24"x24" diffuser with no dampers | I41: ='Single Wide Master Sheet'!C147 -> 20 amp duplex receptacles per drawing - white finishes
C42: ='Single Wide Master Sheet'!C123 -> Bard model 8403-060 T-stat | I42: ='Single Wide Master Sheet'!C148 -> 15 amp GFCI per drawing
...

Sheet 10x30
B2: Date: | E2: Size: | F2: 10x30 | H2: DESIGN LOADS:
B3: Customer: | E3: Description: | F3: Mobile Office | H3: Floor: | I3: 50
B4: Location: | E4: Insignias: | F4: OR, WA, ID | H4: Wind: | I4: 135/C
B5: Project: | E5: Climate Zone | H5: Roof: | I5: 40
C7: Chassis | I7: Floor
C8: ='Single Wide Master Sheet'!C9 -> Conventional (outriggers every 8' with full length front and rear C-channel cross members) | I8: ='Single Wide Master Sheet'!C26 -> 2"x8" floor joists @ 16" o/c with 2"x8" double rim joists.
C9: ='Single Wide Master Sheet'!C10 -> 10" I-beam main rail. | I9: ='Single Wide Master Sheet'!C27 -> Class "A" woven poly fabric bottom board.
C10: ='Single Wide Master Sheet'!C11 -> 2-Brake axle with 8:00x14.5 14 ply tires - all new | I10: ='Single Wide Master Sheet'!C28 -> Fiberglass batt insulation to code.
C11: ='Single Wide Master Sheet'!C12 -> Detachable Hitch. | I11: ='Single Wide Master Sheet'!C29 -> 3/4" T&G decking-glued and nailed
C12: Exterior Wall Framing | I12: Roof
C13: ='Single Wide Master Sheet'!C38 -> 2"x6" framing @ 16" o/c | I13: ='Single Wide Master Sheet'!C71 -> Single slope away from doors
C14: ='Single Wide Master Sheet'!C39 -> Insulation to code. | I14: ='Single Wide Master Sheet'!C72 -> Bottom cover class "A" woven polyethelene fabric
C15: ='Single Wide Master Sheet'!C40 -> End wall sheathing full height interior side of wall | I15: ='Single Wide Master Sheet'!C73 -> 45 mil Black EPDM roofing with J-rail - Fasten j-rail with grommeted screws
I16: ='Single Wide Master Sheet'!C74 -> Insulation to code.
I17: ='Single Wide Master Sheet'!C75 -> 7/16" OSB sheathing
I18: ='Single Wide Master Sheet'!C76 -> Eave venting
C19: Exterior Wall Finish | I19: Exterior Doors
C20: ='Single Wide Master Sheet'!C53 -> 7/16" LP Smartside Panel T1-11 siding with grooves 8" o/c - roof deck to top of belt rail | I20: ='Single Wide Master Sheet'!C83 -> 3068 Telstar Pro - painted
C21: ='Single Wide Master Sheet'!C54 -> Wrap building with Tyvek building wrap (or equivalent) | I21: ='Single Wide Master Sheet'!C84 -> Hinges - SS-BBH NRP
C22: ='Single Wide Master Sheet'!C55 -> Corner trim - 5/8"x4" Smartside trim - 2"x2" galvanized flashing installed over siding and under corners. | I22: ='Single Wide Master Sheet'!C85 -> Tell DB2051 deadbolt
I23: ='Single Wide Master Sheet'!C86 -> Int/Ext pull handles
C24: ='Single Wide Master Sheet'!C56 -> Window trim - 5/8"x4" Smartside Trim. | I24: ='Single Wide Master Sheet'!C87 -> Tell 12916 door closer
C25: ='Single Wide Master Sheet'!C57 -> Fascia - 5/8"x8" Smartside trim, no grooves | I25: ='Single Wide Master Sheet'!C88 -> Weatherstripping - ADA threshold and sweep
C26: ='Single Wide Master Sheet'!C58 -> Belt Rail - 6"x7/16" LP Smartside trim. 1/2" Z-flashing installed at bottom of siding and top of belt rail - 2" back leg and 3/4" front leg. | I26: ='Single Wide Master Sheet'!C89 -> DEADBOLTS TO BE INSTALLED BELOW PULL HANDLES
I27: ='Single Wide Master Sheet'!C90 -> "THIS DOOR TO REMAIN UNLOCKED WHEN BUILDING IS OCCUPIED" SIGN ABOVE EXTERIOR DOORS
I28: ='Single Wide Master Sheet'!C91 -> DOOR HARDWARE TO HAVE #626 SATIN CHROMIUM PLATED FINISH
C29: Windows | I29: Floor Cover
C30: ='Single Wide Master Sheet'!C93 -> 4'x3' White vinyl horizontal slider | I30: ='Single Wide Master Sheet'!C98 -> Armstrong "Standard Excelon" 1/8" VCT "Shelter White" #51836
C31: ='Single Wide Master Sheet'!C94 -> Glazing - dual- low E Argon filled | I31: ='Single Wide Master Sheet'!C99 -> VCT layout - 1/4 turn with 6" offset
C32: ='Single Wide Master Sheet'!C95 -> Windows installed over siding | I32: ='Single Wide Master Sheet'!C100 -> Armstrong 4" rubber cove base "Light Gray" #69
C33: ='Single Wide Master Sheet'!C96 -> Galvanized flashing installed under siding and over top flange of window, under trim. | I33: ='Single Wide Master Sheet'!C101 -> COVE BASE TO BE CONTINUOUS
C34: Wall Cover | I34: Interior Trim
C35: ='Single Wide Master Sheet'!C103 -> 7/16" OSB sheathing above sheetrock at sidewalls | I35: ='Single Wide Master Sheet'!C111 -> Vinyl wrap corners
C36: ='Single Wide Master Sheet'!C104 -> 7/16" OSB sheathing under sheetrock at endwalls- full height | I36: ='Single Wide Master Sheet'!C112 -> Vinyl wrap batts at each side of windows and doors at relief cuts
C37: ='Single Wide Master Sheet'!C105 -> 5/8" vinyl wrap sheetrock - "Pebble Beach" texture "Pure White" color | I37: ='Single Wide Master Sheet'!C113 -> Window and exterior door surrounds and casing - oak vinyl wrap
C38: HVAC | I38: Electrical
C39: ='Single Wide Master Sheet'!C120 -> 1.5 ton 8KW Bard wall hung heat pump with economizer | I39: ='Single Wide Master Sheet'!C145 -> 120/240V Single phase service-stub conduit below joists
C40: ='Single Wide Master Sheet'!C121 -> Overhead supply ducting | I40: ='Single Wide Master Sheet'!C146 -> 125 amp load center
C41: ='Single Wide Master Sheet'!C122 -> 24"x24" diffuser with no dampers | I41: ='Single Wide Master Sheet'!C147 -> 20 amp duplex receptacles per drawing - white finishes
C42: ='Single Wide Master Sheet'!C123 -> Bard model 8403-060 T-stat | I42: ='Single Wide Master Sheet'!C148 -> 15 amp GFCI per drawing
...

Sheet 10x30RR
B2: Date: | E2: Size: | F2: 10x30 | H2: DESIGN LOADS:
B3: Customer: | E3: Description: | F3: Mobile Office with Restroom | H3: Floor: | I3: 50
B4: Location: | E4: Insignias: | F4: OR, WA, ID | H4: Wind: | I4: 135/C
B5: Project: | E5: Climate Zone | H5: Roof: | I5: 40
C7: Chassis | I7: Floor
C8: ='Single Wide Master Sheet'!C9 -> Conventional (outriggers every 8' with full length front and rear C-channel cross members) | I8: ='Single Wide Master Sheet'!C26 -> 2"x8" floor joists @ 16" o/c with 2"x8" double rim joists.
C9: ='Single Wide Master Sheet'!C10 -> 10" I-beam main rail. | I9: ='Single Wide Master Sheet'!C27 -> Class "A" woven poly fabric bottom board.
C10: ='Single Wide Master Sheet'!C11 -> 2-Brake axle with 8:00x14.5 14 ply tires - all new | I10: ='Single Wide Master Sheet'!C28 -> Fiberglass batt insulation to code.
C11: ='Single Wide Master Sheet'!C12 -> Detachable Hitch. | I11: ='Single Wide Master Sheet'!C29 -> 3/4" T&G decking-glued and nailed
C12: Exterior Wall Framing | I12: Roof
C13: ='Single Wide Master Sheet'!C38 -> 2"x6" framing @ 16" o/c | I13: ='Single Wide Master Sheet'!C71 -> Single slope away from doors
C14: ='Single Wide Master Sheet'!C39 -> Insulation to code. | I14: ='Single Wide Master Sheet'!C72 -> Bottom cover class "A" woven polyethelene fabric
C15: ='Single Wide Master Sheet'!C40 -> End wall sheathing full height interior side of wall | I15: ='Single Wide Master Sheet'!C73 -> 45 mil Black EPDM roofing with J-rail - Fasten j-rail with grommeted screws
I16: ='Single Wide Master Sheet'!C74 -> Insulation to code.
I17: ='Single Wide Master Sheet'!C75 -> 7/16" OSB sheathing
I18: ='Single Wide Master Sheet'!C76 -> Eave venting
C19: Exterior Wall Finish | I19: Exterior Doors
C20: ='Single Wide Master Sheet'!C53 -> 7/16" LP Smartside Panel T1-11 siding with grooves 8" o/c - roof deck to top of belt rail | I20: ='Single Wide Master Sheet'!C83 -> 3068 Telstar Pro - painted
C21: ='Single Wide Master Sheet'!C54 -> Wrap building with Tyvek building wrap (or equivalent) | I21: ='Single Wide Master Sheet'!C84 -> Hinges - SS-BBH NRP
C22: ='Single Wide Master Sheet'!C55 -> Corner trim - 5/8"x4" Smartside trim - 2"x2" galvanized flashing installed over siding and under corners. | I22: ='Single Wide Master Sheet'!C85 -> Tell DB2051 deadbolt
I23: ='Single Wide Master Sheet'!C86 -> Int/Ext pull handles
C24: ='Single Wide Master Sheet'!C56 -> Window trim - 5/8"x4" Smartside Trim. | I24: ='Single Wide Master Sheet'!C87 -> Tell 12916 door closer
C25: ='Single Wide Master Sheet'!C57 -> Fascia - 5/8"x8" Smartside trim, no grooves | I25: ='Single Wide Master Sheet'!C88 -> Weatherstripping - ADA threshold and sweep
C26: ='Single Wide Master Sheet'!C58 -> Belt Rail - 6"x7/16" LP Smartside trim. 1/2" Z-flashing installed at bottom of siding and top of belt rail - 2" back leg and 3/4" front leg. | I26: ='Single Wide Master Sheet'!C89 -> DEADBOLTS TO BE INSTALLED BELOW PULL HANDLES
I27: ='Single Wide Master Sheet'!C90 -> "THIS DOOR TO REMAIN UNLOCKED WHEN BUILDING IS OCCUPIED" SIGN ABOVE EXTERIOR DOORS
I28: ='Single Wide Master Sheet'!C91 -> DOOR HARDWARE TO HAVE #626 SATIN CHROMIUM PLATED FINISH
C29: Windows | I29: Floor Cover
C30: ='Single Wide Master Sheet'!C93 -> 4'x3' White vinyl horizontal slider | I30: ='Single Wide Master Sheet'!C98 -> Armstrong "Standard Excelon" 1/8" VCT "Shelter White" #51836
C31: ='Single Wide Master Sheet'!C94 -> Glazing - dual- low E Argon filled | I31: ='Single Wide Master Sheet'!C99 -> VCT layout - 1/4 turn with 6" offset
C32: ='Single Wide Master Sheet'!C95 -> Windows installed over siding | I32: ='Single Wide Master Sheet'!C100 -> Armstrong 4" rubber cove base "Light Gray" #69
C33: ='Single Wide Master Sheet'!C96 -> Galvanized flashing installed under siding and over top flange of window, under trim. | I33: ='Single Wide Master Sheet'!C101 -> COVE BASE TO BE CONTINUOUS
C34: Wall Cover | I34: Interior Trim
C35: ='Single Wide Master Sheet'!C103 -> 7/16" OSB sheathing above sheetrock at sidewalls | I35: ='Single Wide Master Sheet'!C111 -> Vinyl wrap corners
C36: ='Single Wide Master Sheet'!C104 -> 7/16" OSB sheathing under sheetrock at endwalls- full height | I36: ='Single Wide Master Sheet'!C112 -> Vinyl wrap batts at each side of windows and doors at relief cuts
C37: ='Single Wide Master Sheet'!C105 -> 5/8" vinyl wrap sheetrock - "Pebble Beach" texture "Pure White" color | I37: ='Single Wide Master Sheet'!C113 -> Window and exterior door surrounds and casing - oak vinyl wrap
C38: HVAC | I38: Electrical
C39: ='Single Wide Master Sheet'!C120 -> 1.5 ton 8KW Bard wall hung heat pump with economizer | I39: ='Single Wide Master Sheet'!C145 -> 120/240V Single phase service-stub conduit below joists
C40: ='Single Wide Master Sheet'!C121 -> Overhead supply ducting | I40: ='Single Wide Master Sheet'!C146 -> 125 amp load center
C41: ='Single Wide Master Sheet'!C122 -> 24"x24" diffuser with no dampers | I41: ='Single Wide Master Sheet'!C147 -> 20 amp duplex receptacles per drawing - white finishes
C42: ='Single Wide Master Sheet'!C123 -> Bard model 8403-060 T-stat | I42: ='Single Wide Master Sheet'!C148 -> 15 amp GFCI per drawing
...

Sheet 10x40
B2: Date: | E2: Size: | F2: 10x40 | H2: DESIGN LOADS:
B3: Customer: | E3: Description: | F3: Mobile Office | H3: Floor: | I3: 50
B4: Location: | E4: Insignias: | F4: OR, WA, ID | H4: Wind: | I4: 135/C
B5: Project: | E5: Climate Zone | H5: Roof: | I5: 40
C7: Chassis | I7: Floor
C8: ='Single Wide Master Sheet'!C9 -> Conventional (outriggers every 8' with full length front and rear C-channel cross members) | I8: ='Single Wide Master Sheet'!C26 -> 2"x8" floor joists @ 16" o/c with 2"x8" double rim joists.
C9: ='Single Wide Master Sheet'!C10 -> 10" I-beam main rail. | I9: ='Single Wide Master Sheet'!C27 -> Class "A" woven poly fabric bottom board.
C10: ='Single Wide Master Sheet'!C11 -> 2-Brake axle with 8:00x14.5 14 ply tires - all new | I10: ='Single Wide Master Sheet'!C28 -> Fiberglass batt insulation to code.
C11: ='Single Wide Master Sheet'!C12 -> Detachable Hitch. | I11: ='Single Wide Master Sheet'!C29 -> 3/4" T&G decking-glued and nailed
C12: Exterior Wall Framing | I12: Roof
C13: ='Single Wide Master Sheet'!C38 -> 2"x6" framing @ 16" o/c | I13: ='Single Wide Master Sheet'!C71 -> Single slope away from doors
C14: ='Single Wide Master Sheet'!C39 -> Insulation to code. | I14: ='Single Wide Master Sheet'!C72 -> Bottom cover class "A" woven polyethelene fabric
C15: ='Single Wide Master Sheet'!C40 -> End wall sheathing full height interior side of wall | I15: ='Single Wide Master Sheet'!C73 -> 45 mil Black EPDM roofing with J-rail - Fasten j-rail with grommeted screws
I16: ='Single Wide Master Sheet'!C74 -> Insulation to code.
I17: ='Single Wide Master Sheet'!C75 -> 7/16" OSB sheathing
I18: ='Single Wide Master Sheet'!C76 -> Eave venting
C19: Exterior Wall Finish | I19: Exterior Doors
C20: ='Single Wide Master Sheet'!C53 -> 7/16" LP Smartside Panel T1-11 siding with grooves 8" o/c - roof deck to top of belt rail | I20: ='Single Wide Master Sheet'!C83 -> 3068 Telstar Pro - painted
C21: ='Single Wide Master Sheet'!C54 -> Wrap building with Tyvek building wrap (or equivalent) | I21: ='Single Wide Master Sheet'!C84 -> Hinges - SS-BBH NRP
C22: ='Single Wide Master Sheet'!C55 -> Corner trim - 5/8"x4" Smartside trim - 2"x2" galvanized flashing installed over siding and under corners. | I22: ='Single Wide Master Sheet'!C85 -> Tell DB2051 deadbolt
I23: ='Single Wide Master Sheet'!C86 -> Int/Ext pull handles
C24: ='Single Wide Master Sheet'!C56 -> Window trim - 5/8"x4" Smartside Trim. | I24: ='Single Wide Master Sheet'!C87 -> Tell 12916 door closer
C25: ='Single Wide Master Sheet'!C57 -> Fascia - 5/8"x8" Smartside trim, no grooves | I25: ='Single Wide Master Sheet'!C88 -> Weatherstripping - ADA threshold and sweep
C26: ='Single Wide Master Sheet'!C58 -> Belt Rail - 6"x7/16" LP Smartside trim. 1/2" Z-flashing installed at bottom of siding and top of belt rail - 2" back leg and 3/4" front leg. | I26: ='Single Wide Master Sheet'!C89 -> DEADBOLTS TO BE INSTALLED BELOW PULL HANDLES
I27: ='Single Wide Master Sheet'!C90 -> "THIS DOOR TO REMAIN UNLOCKED WHEN BUILDING IS OCCUPIED" SIGN ABOVE EXTERIOR DOORS
I28: ='Single Wide Master Sheet'!C91 -> DOOR HARDWARE TO HAVE #626 SATIN CHROMIUM PLATED FINISH
C29: Windows | I29: Floor Cover
C30: ='Single Wide Master Sheet'!C93 -> 4'x3' White vinyl horizontal slider | I30: ='Single Wide Master Sheet'!C98 -> Armstrong "Standard Excelon" 1/8" VCT "Shelter White" #51836
C31: ='Single Wide Master Sheet'!C94 -> Glazing - dual- low E Argon filled | I31: ='Single Wide Master Sheet'!C99 -> VCT layout - 1/4 turn with 6" offset
C32: ='Single Wide Master Sheet'!C95 -> Windows installed over siding | I32: ='Single Wide Master Sheet'!C100 -> Armstrong 4" rubber cove base "Light Gray" #69
C33: ='Single Wide Master Sheet'!C96 -> Galvanized flashing installed under siding and over top flange of window, under trim. | I33: ='Single Wide Master Sheet'!C101 -> COVE BASE TO BE CONTINUOUS
C34: Wall Cover | I34: Interior Trim
C35: ='Single Wide Master Sheet'!C103 -> 7/16" OSB sheathing above sheetrock at sidewalls | I35: ='Single Wide Master Sheet'!C111 -> Vinyl wrap corners
C36: ='Single Wide Master Sheet'!C104 -> 7/16" OSB sheathing under sheetrock at endwalls- full height | I36: ='Single Wide Master Sheet'!C112 -> Vinyl wrap batts at each side of windows and doors at relief cuts
C37: ='Single Wide Master Sheet'!C105 -> 5/8" vinyl wrap sheetrock - "Pebble Beach" texture "Pure White" color | I37: ='Single Wide Master Sheet'!C113 -> Window and exterior door surrounds and casing - oak vinyl wrap
C38: HVAC | I38: Electrical
C39: ='Single Wide Master Sheet'!C120 -> 1.5 ton 8KW Bard wall hung heat pump with economizer | I39: ='Single Wide Master Sheet'!C145 -> 120/240V Single phase service-stub conduit below joists
C40: ='Single Wide Master Sheet'!C121 -> Overhead supply ducting | I40: ='Single Wide Master Sheet'!C146 -> 125 amp load center
C41: ='Single Wide Master Sheet'!C122 -> 24"x24" diffuser with no dampers | I41: ='Single Wide Master Sheet'!C147 -> 20 amp duplex receptacles per drawing - white finishes
C42: ='Single Wide Master Sheet'!C123 -> Bard model 8403-060 T-stat | I42: ='Single Wide Master Sheet'!C148 -> 15 amp GFCI per drawing
...

Sheet 10x40RR
B2: Date: | E2: Size: | F2: 10x40 | H2: DESIGN LOADS:
B3: Customer: | E3: Description: | F3: Mobile Office with Restroom | H3: Floor: | I3: 50
B4: Location: | E4: Insignias: | F4: OR, WA, ID | H4: Wind: | I4: 135/C
B5: Project: | E5: Climate Zone | H5: Roof: | I5: 40
C7: Chassis | I7: Floor
C8: ='Single Wide Master Sheet'!C9 -> Conventional (outriggers every 8' with full length front and rear C-channel cross members) | I8: ='Single Wide Master Sheet'!C26 -> 2"x8" floor joists @ 16" o/c with 2"x8" double rim joists.
C9: ='Single Wide Master Sheet'!C10 -> 10" I-beam main rail. | I9: ='Single Wide Master Sheet'!C27 -> Class "A" woven poly fabric bottom board.
C10: ='Single Wide Master Sheet'!C11 -> 2-Brake axle with 8:00x14.5 14 ply tires - all new | I10: ='Single Wide Master Sheet'!C28 -> Fiberglass batt insulation to code.
C11: ='Single Wide Master Sheet'!C12 -> Detachable Hitch. | I11: ='Single Wide Master Sheet'!C29 -> 3/4" T&G decking-glued and nailed
C12: Exterior Wall Framing | I12: Roof
C13: ='Single Wide Master Sheet'!C38 -> 2"x6" framing @ 16" o/c | I13: ='Single Wide Master Sheet'!C71 -> Single slope away from doors
C14: ='Single Wide Master Sheet'!C39 -> Insulation to code. | I14: ='Single Wide Master Sheet'!C72 -> Bottom cover class "A" woven polyethelene fabric
C15: ='Single Wide Master Sheet'!C40 -> End wall sheathing full height interior side of wall | I15: ='Single Wide Master Sheet'!C73 -> 45 mil Black EPDM roofing with J-rail - Fasten j-rail with grommeted screws
I16: ='Single Wide Master Sheet'!C74 -> Insulation to code.
I17: ='Single Wide Master Sheet'!C75 -> 7/16" OSB sheathing
I18: ='Single Wide Master Sheet'!C76 -> Eave venting
C19: Exterior Wall Finish | I19: Exterior Doors
C20: ='Single Wide Master Sheet'!C53 -> 7/16" LP Smartside Panel T1-11 siding with grooves 8" o/c - roof deck to top of belt rail | I20: ='Single Wide Master Sheet'!C83 -> 3068 Telstar Pro - painted
C21: ='Single Wide Master Sheet'!C54 -> Wrap building with Tyvek building wrap (or equivalent) | I21: ='Single Wide Master Sheet'!C84 -> Hinges - SS-BBH NRP
C22: ='Single Wide Master Sheet'!C55 -> Corner trim - 5/8"x4" Smartside trim - 2"x2" galvanized flashing installed over siding and under corners. | I22: ='Single Wide Master Sheet'!C85 -> Tell DB2051 deadbolt
I23: ='Single Wide Master Sheet'!C86 -> Int/Ext pull handles
C24: ='Single Wide Master Sheet'!C56 -> Window trim - 5/8"x4" Smartside Trim. | I24: ='Single Wide Master Sheet'!C87 -> Tell 12916 door closer
C25: ='Single Wide Master Sheet'!C57 -> Fascia - 5/8"x8" Smartside trim, no grooves | I25: ='Single Wide Master Sheet'!C88 -> Weatherstripping - ADA threshold and sweep
C26: ='Single Wide Master Sheet'!C58 -> Belt Rail - 6"x7/16" LP Smartside trim. 1/2" Z-flashing installed at bottom of siding and top of belt rail - 2" back leg and 3/4" front leg. | I26: ='Single Wide Master Sheet'!C89 -> DEADBOLTS TO BE INSTALLED BELOW PULL HANDLES
I27: ='Single Wide Master Sheet'!C90 -> "THIS DOOR TO REMAIN UNLOCKED WHEN BUILDING IS OCCUPIED" SIGN ABOVE EXTERIOR DOORS
I28: ='Single Wide Master Sheet'!C91 -> DOOR HARDWARE TO HAVE #626 SATIN CHROMIUM PLATED FINISH
C29: Windows | I29: Floor Cover
C30: ='Single Wide Master Sheet'!C93 -> 4'x3' White vinyl horizontal slider | I30: ='Single Wide Master Sheet'!C98 -> Armstrong "Standard Excelon" 1/8" VCT "Shelter White" #51836
C31: ='Single Wide Master Sheet'!C94 -> Glazing - dual- low E Argon filled | I31: ='Single Wide Master Sheet'!C99 -> VCT layout - 1/4 turn with 6" offset
C32: ='Single Wide Master Sheet'!C95 -> Windows installed over siding | I32: ='Single Wide Master Sheet'!C100 -> Armstrong 4" rubber cove base "Light Gray" #69
C33: ='Single Wide Master Sheet'!C96 -> Galvanized flashing installed under siding and over top flange of window, under trim. | I33: ='Single Wide Master Sheet'!C101 -> COVE BASE TO BE CONTINUOUS
C34: Wall Cover | I34: Interior Trim
C35: ='Single Wide Master Sheet'!C103 -> 7/16" OSB sheathing above sheetrock at sidewalls | I35: ='Single Wide Master Sheet'!C111 -> Vinyl wrap corners
C36: ='Single Wide Master Sheet'!C104 -> 7/16" OSB sheathing under sheetrock at endwalls- full height | I36: ='Single Wide Master Sheet'!C112 -> Vinyl wrap batts at each side of windows and doors at relief cuts
C37: ='Single Wide Master Sheet'!C105 -> 5/8" vinyl wrap sheetrock - "Pebble Beach" texture "Pure White" color | I37: ='Single Wide Master Sheet'!C113 -> Window and exterior door surrounds and casing - oak vinyl wrap
C38: HVAC | I38: Electrical
C39: ='Single Wide Master Sheet'!C120 -> 1.5 ton 8KW Bard wall hung heat pump with economizer | I39: ='Single Wide Master Sheet'!C145 -> 120/240V Single phase service-stub conduit below joists
C40: ='Single Wide Master Sheet'!C121 -> Overhead supply ducting | I40: ='Single Wide Master Sheet'!C146 -> 125 amp load center
C41: ='Single Wide Master Sheet'!C122 -> 24"x24" diffuser with no dampers | I41: ='Single Wide Master Sheet'!C147 -> 20 amp duplex receptacles per drawing - white finishes
C42: ='Single Wide Master Sheet'!C123 -> Bard model 8403-060 T-stat | I42: ='Single Wide Master Sheet'!C148 -> 15 amp GFCI per drawing
...

Sheet 12x40
B2: Date: | E2: Size: | F2: 12x40 | H2: DESIGN LOADS:
B3: Customer: | E3: Description: | F3: Mobile Office | H3: Floor: | I3: 50
B4: Location: | E4: Insignias: | F4: OR, WA, ID | H4: Wind: | I4: 135/C
B5: Project: | E5: Climate Zone | H5: Roof: | I5: 40
C7: Chassis | I7: Floor
C8: ='Single Wide Master Sheet'!C13 -> Conventional (outriggers every 8' with full length front and rear C-channel cross members) | I8: ='Single Wide Master Sheet'!C30 -> 2"x8" floor joists @ 16" o/c with 2"x8" double rim joists.
C9: ='Single Wide Master Sheet'!C14 -> 12" I-beam main rail. | I9: ='Single Wide Master Sheet'!C31 -> Class "A" woven poly fabric bottom board.
C10: ='Single Wide Master Sheet'!C15 -> 3-Brake axle with 8:00x14.5 14 ply tires - all new | I10: ='Single Wide Master Sheet'!C32 -> Fiberglass batt insulation to code.
C11: ='Single Wide Master Sheet'!C16 -> Detachable Hitch. | I11: ='Single Wide Master Sheet'!C33 -> 3/4" T&G decking-glued and nailed.
C12: Exterior Wall Framing | I12: Roof
C13: ='Single Wide Master Sheet'!C42 -> 2x6 framing @ 16" o/c | I13: ='Single Wide Master Sheet'!C77 -> Single slope away from doors
C14: ='Single Wide Master Sheet'!C43 -> Insulation to code. | I14: ='Single Wide Master Sheet'!C78 -> Bottom cover class "A" woven polyethelene fabric
C15: ='Single Wide Master Sheet'!C44 -> End wall sheathing full height interior side of wall | I15: ='Single Wide Master Sheet'!C79 -> 45 mil Black EPDM roofing with J-rail - Fasten j-rail with grommeted screws
C16: ='Single Wide Master Sheet'!C45 -> Standard plenum wall for sound reduction-lined with 5/8" sheetrock. | I16: ='Single Wide Master Sheet'!C80 -> Insulation to code.
I17: ='Single Wide Master Sheet'!C81 -> 7/16" OSB sheathing - Eave venting
C18: Exterior Wall Finish | I18: Exterior Doors
