Workbook
Name ConstrucS: '2021 area Table 506.2'!$Q$2:$AB$2
Name ConstrucS: 'Allowable area Table 506.2'!$N$2:$V$2
Name Construction13D: '2021 area Table 506.2'!$BJ$2:$BU$2
Name Construction13D: 'Allowable area Table 506.2'!$AX$2:$BF$2
Name Construction13R: '2021 area Table 506.2'!$BY$2:$CJ$2
Name Construction13R: 'Allowable area Table 506.2'!$BJ$2:$BR$2
Name ConstructionAIL: '2021 area Table 506.2'!$AU$2:$BF$2
Name ConstructionAIL: 'Allowable area Table 506.2'!$AL$2:$AT$2
Name ConstructionHt13D: '2021 Bldg Ht Table 504.3'!$AR$2:$BC$2
Name ConstructionHt13D: 'Allowable Bldg Ht Table 504.3'!$AI$2:$AQ$2
Name ConstructionHt13R: '2021 Bldg Ht Table 504.3'!$BF$2:$BQ$2
Name ConstructionHt13R: 'Allowable Bldg Ht Table 504.3'!$AT$2:$BB$2
Name ConstructionHtAIL: '2021 Bldg Ht Table 504.3'!$AD$2:$AO$2
Name ConstructionHtAIL: 'Allowable Bldg Ht Table 504.3'!$X$2:$AF$2
Name ConstructionHtNS: '2021 Bldg Ht Table 504.3'!$B$2:$M$2
Name ConstructionHtNS: 'Allowable Bldg Ht Table 504.3'!$B$2:$J$2
Name ConstructionHtSS: '2021 Bldg Ht Table 504.3'!$P$2:$AA$2
Name ConstructionHtSS: 'Allowable Bldg Ht Table 504.3'!$M$2:$U$2
Name ConstructionNS: '2021 area Table 506.2'!$B$2:$M$2
Name ConstructionNS: 'Allowable area Table 506.2'!$B$2:$J$2
Name ConstructionSM: '2021 area Table 506.2'!$AF$2:$AQ$2
Name ConstructionSM: 'Allowable area Table 506.2'!$Z$2:$AH$2
Name ConstructionStories13D: '2021 Stories Table 504.4'!$AU$2:$BF$2
Name ConstructionStories13D: 'Allowable Stories Table 504.4'!$AL$2:$AT$2
Name ConstructionStories13R: '2021 Stories Table 504.4'!$BJ$2:$BU$2
Name ConstructionStories13R: 'Allowable Stories Table 504.4'!$AX$2:$BF$2
Name ConstructionStoriesAIL: '2021 Stories Table 504.4'!$AF$2:$AQ$2
Name ConstructionStoriesAIL: 'Allowable Stories Table 504.4'!$Z$2:$AH$2
Name ConstructionStoriesNS: '2021 Stories Table 504.4'!$B$2:$M$2
Name ConstructionStoriesNS: 'Allowable Stories Table 504.4'!$B$2:$J$2
Name ConstructionStoriesSS: '2021 Stories Table 504.4'!$Q$2:$AB$2
Name ConstructionStoriesSS: 'Allowable Stories Table 504.4'!$N$2:$V$2
Name Occ13D: '2021 area Table 506.2'!$BI$3:$BI$33
Name Occ13D: 'Allowable area Table 506.2'!$AW$3:$AW$33
Name Occ13R: '2021 area Table 506.2'!$BX$3:$BX$33
Name Occ13R: 'Allowable area Table 506.2'!$BI$3:$BI$33
Name OccAIL: '2021 area Table 506.2'!$AT$3:$AT$33
Name OccAIL: 'Allowable area Table 506.2'!$AK$3:$AK$33
Name OccHt13D: '2021 Bldg Ht Table 504.3'!$AQ$3:$AQ$32
Name OccHt13D: 'Allowable Bldg Ht Table 504.3'!$AH$3:$AH$32
Name OccHt13R: '2021 Bldg Ht Table 504.3'!$BE$3:$BE$32
Name OccHt13R: 'Allowable Bldg Ht Table 504.3'!$AS$3:$AS$32
Name OccHtAIL: '2021 Bldg Ht Table 504.3'!$AC$3:$AC$32
Name OccHtAIL: 'Allowable Bldg Ht Table 504.3'!$W$3:$W$32
Name OccHtNS: '2021 Bldg Ht Table 504.3'!$A$3:$A$32
Name OccHtNS: 'Allowable Bldg Ht Table 504.3'!$A$3:$A$32
Name OccHtSS: '2021 Bldg Ht Table 504.3'!$O$3:$O$32
Name OccHtSS: 'Allowable Bldg Ht Table 504.3'!$L$3:$L$32
Name OccNS: '2021 area Table 506.2'!$A$3:$A$33
Name OccNS: 'Allowable area Table 506.2'!$A$3:$A$33
Name OccS: '2021 area Table 506.2'!$P$2:$P$33
Name OccS: 'Allowable area Table 506.2'!$M$2:$M$33
Name OccSM: '2021 area Table 506.2'!$AE$3:$AE$33
Name OccSM: 'Allowable area Table 506.2'!$Y$3:$Y$33
Name OccSS: '2021 area Table 506.2'!$P$3:$P$33
Name OccSS: 'Allowable area Table 506.2'!$M$3:$M$33
Name OccStories13D: '2021 Stories Table 504.4'!$AT$3:$AT$32
Name OccStories13D: 'Allowable Stories Table 504.4'!$AK$3:$AK$32
Name OccStories13R: '2021 Stories Table 504.4'!$BI$3:$BI$32
Name OccStories13R: 'Allowable Stories Table 504.4'!$AW$3:$AW$32

Sheet 2021-2024 Frontage Increase
A1: 2021-2024 IBC FRONTAGE INCREASE CALCULATOR | G1: =IF(B5="E","AZ: Sprinklers required is above grade set.","") | O1: Occupancy Classifications: | T1: Fire Alarm Requirements:
G2: =IF(B5="E","FL, GA, RI, & DE: Sprinklers required. Exception: Under 1,000 sq. ft., single classroom, and less than 30' from other buildings. (NFPA 101: 14.3.5) / No exception for SREF classroom for FL.","") | O2: =IF(OR(B5="A-1",2="A-2",B5="A-3",B5="A-4",B5="A-5"),"A: Assembly Group",IF(B5="B","B: Business Group",IF(B5="E","E: Educational Group",IF(OR(B5="F-1",B5="F-2"),"F: Factory Group",IF(OR(B5="H-1",B5="H-2",B5="H-3",B5="H-4",B5="H-5"),"H: High Hazard Group",IF(OR(B5="I-1 Cond. 1",B5="I-1 Cond. 2",B5="I-2/I-2.1",B5="I-3",B5="I-4"),"I: Institutional Group",IF(B5="M","M: Mercantile Group",IF(OR(B5="R-1",B5="r-2",B5="r-2.1",B5="r-2.2 (ca only)",B5="r-3/r-3.1",B5="r-4"),"R: Residential Group",IF(OR(B5="s-1",B5="s-2"),"S: Storage Group",IF(B5="U","U: Utility & Miscellaneous Group",IF(B5="L","L: Labortories Group",""))))))))))) -> B: Business Group | T2: =$B$5 -> B
A3: Project #: | O3: =IF(B5="a-1","A-1: Assembly use intended for the production & viewing of performing arts or motion pictures. Motion Picture Theaters, Concert Halls, TV/Radio Studios w/ audience, Theaters.",IF(B5="a-2","A-2: Assembly use intended for food / drink consumption. Banquet Halls, Casinos, Nightclubs, Restaurants, Break Rooms.",IF(B5="A-3","A-3: Assembly use for worship, recreation/amusement, and other assembly uses. Conferences, Lecture Halls, Libraries, Places of Worship, Waiting areas, Bowling Alleys, Court Rooms, Amusement Arcades, Community Halls, Dance Halls, Etc.",IF(B5="A-4","A-4: Assembly use intended for viewing indoor sporting events/activities with seating. Arenas, Skating Rinks, Swimming Pools, Tennis Courts.",IF(B5="A-5","A-5: assembly use intended for participation in or viewing outdoor activities. Amusement park structures, Bleachers, Grandstands, Stadiums",IF(B5="b","B: Air Traffic Towers, Ambulatory Care (serving 6 or fewer), Banks, Barber/Beauty Shops, Vet Clinic, Bank, Offices, Outpatient Clinic, Education grade over 12th grade, food processing, print shops, radio/TV stations.",IF(B5="E","E: Grades Pre-K thru 12th occupied by more than 6 persons. Group E Daycare occupied by 5 or more kids older than 2-1/2 yo and receive less than 24hr. care. See Section 303.1.4 for accessory to places of worship.",IF(B5="F-1","F-1: Factory industrial that are considered Moderate Hazard. Aircraft repair, Appliances, Bakeries, Bicylces, Boats, Business Machines, Clothing, Construction and Agricultural Machinery, Dry Cleaning, Engines, Electronics, Paper Mill, Tabacco, Wood.",IF(B5="f-2","F-2: Factory industrial that are considered Low Hazard. Beverage up to 16% alcohol content, Brick/Masonry, Ceramic Products, Foundries, Glass Products, Gypsum, Ice, Metal Procucts.",IF(B5="H-1","H-1: Occupancies containing explosives. Explosives, Div. 1.1, 1.2, 1.3, 1.5, 1.6.",IF(B5="H-2","H-2: Buildings containing materials that pose a deflagration hazard or hazard from accelerated burning. Combustible Duct & Liquid, Cryogentic Liquid/Flammable, Div. 1.3 Explosives, Flammable Gas or Liquid (Type IA, IB, or IC).",IF(B5="H-3","H-3: Buildings containing materials that readily support combustion or pose a physical hazard. Combustible Fiber, Liquid (Type II or IIIA, Cryogenic oxidizing, Flammable Liquid, solid or combination, organic peroxide.",IF(B5="H-4","H-4: Buildings containing materials that are health hazards. Corrosives, Highly Toxic materials, Toxic materials.",IF(B5="H-5","H-5: Semiconductor fabrication facilities and comparable research and develpment areas in which hazardous production materials are used and the aggregate quantity of materials is in excess of those listed in Tables 307.1(1) & 307.1(2).",IF(B5="I-1 Cond. 1","I-1 Cond. 1: Buildings for more than 16 persons, excluding staff who reside on a 24-hr. basis in a supv enriroment and receive custodial care. Halfway house, Assisted Living. Cond 1: Person in custodial care, but can respond to an emergency situation.",IF(B5="I-1 Cond. 2","I-1 Cond. 2: Bldgs for 16+ persons, excl. staff who reside on a 24-hr basis in a supv enriroment and receive custodial care. Halfway house, Assisted Living. Cond 2: Person in care who require limited verbal/physical asst. while rspnd to emer. sitn.",IF(B5="i-2/i-2.1","I-2: Buildings for medical care on 24hr. basis for more than 5 persons who are incapable of self-preservation or nonambulatory. Hospitals, Nursing Homes, Psyc. Hospitals. 5 or fewer persons receiving medical care shall be classifed as Group R-3.",IF(B5="I-3","I-3: Buildings or portions of that are inhabited by one or more than 5 who are under restaint or security. Corrections centers, hospitals, nursing, mental, holding, treatment. Detention Centers, Jails, Juvenile Halls, Prisons, Temporary Holding.",IF(B5="i-4","I-4: Buildings occupied by more than 6 clients of any age who recieve custodial care for fewer than 24hr per day other than parents or guardians. Adult Daycare, Child Daycare. See Section 308.5.1 to classify as Group E daycare",IF(B5="L","L: Building contains 1 or more labatory suites as defined in Section 453 (2019 CBC).",IF(B5="M","M: Buildings for the display and sale of merchandise, and involves stocks or goods, wares or merchandise incidental to such purposes and accessible to the public. Department Stores, Drug Stores, Greenhouses (Display and Sale), Markets, Sales Rooms.",IF(B5="R-1","R-1: Building for sleeping purposes where occupants are transient in nature. Hotels, Motels.",IF(B5="r-2","R-2: Buildings for sleeping purposes when not classified as an Institutional Group I or when not regulated by the International Residential Code. Boarding House, Dormatory, Congregate Living, Group Home, Hotels, Motels, Fraternities, Transient.",IF(B5="R-2.1","R-2.1: Buildings housing clients on a 24hr. basis, who because of age, mental disability or other reasons, live in a supervised enviroment. Res. Care Facilities for children or elderly, Group Homes, Comm. Correction centers, alcohol/drug treatment.",IF(B5="R-2.2 (CA Only)","R-2.2: Residential occupanies operated by CDCR in a community located facility that provides housing and community based program services for nontransient ambulatory care in a nonlicensed facility w/ 24/7 upervision.",IF(B5="R-3/r-3.1","R-3/R-3.1: Occupants are primary in nature and not classified as R-1, R-2, R-2.1, R-2.2 (CA), R-3.1, R-4, or I. Nontransient with 16 or fewer occupants, Boarding houses, Convents, Dorms, Fraternities, Monasteries, Adult/Child care with 6 or fewer.",IF(B5="R-4","R-4: Buildings for more than 6 ambulatory clients, but no more than 16 persons, excluding staff, who reisde on a 24hr basis in a supervised residential enviroment. R-4 shall meet the requirements of R-3. Section 310.5 (CBC)",IF(B5="s-1","S-1: Moderate-Hazard Storage buildings not classified as S-2. Aerol products, Aircraft Hanger (Storage/Repari), Bags, Bamboo, Books/Paper in rolls or packs, Boots/Shoes, Cardboard, Dry boat storage, Lino, Lumber, Soaps, Wax candles.",IF(B5="s-2","S-2: Low Hazard Storage. Asbestos, Cement Bags, Chalk/Crayons, Dairy Products in nonwaxed containers, Dry Cell Batteries, Electrical Coils, Empty Cans, Glass, Gypsu Board, Meats, Metal Parts, Porcelain, Stoves.",IF(B5="U","U: Buildings not classified in any specific occupancy shall be constructed, equipped and maintained to conform with code requirements. Agriculural buildings, Barns, Carports, Comm equip., Private garages, Sheds, Stables, Tanks, Towers.","")))))))))))))))))))))))))))))) -> B: Air Traffic Towers, Ambulatory Care (serving 6 or fewer), Banks, Barber/Beauty Shops, Vet Clinic, Bank, Offices, Outpatient Clinic, Education grade over 12th grade, food processing, print shops, radio/TV stations. | T3: =IF(OR(T2="A-1",T2="A-2",T2="A-3",T2="A-4",T2="A-5"),"Occupant load 300+ @ grade level, or 100+ above/below grade. Exception: Where a building is equipped with sprinkler system and occ. notification appliances activate throughout upon sprinkler water flow.",IF(T2="B","Combined occupant load of 500+, or 100+ above/below grade. Fire area contains an ambulatory care facility. Exception: Where a building is equipped with sprinkler system and occ. notification appliances activate throughout upon sprinkler water flow.",IF(T2="E","Required. Exception: Occupants of 50 or less. Emer. voice/arlarm communication installed and occupant load is 100 or less. Alarm boxes not required if: building has a sprinkler system, emer. voice/alarm installed, activation from an norm. occupied area.",IF(OR(T2="F-1",T2="F-2"),"Combined occupant load of 500+ above or below grade and has 2+ stories in height. Exception: Where a building is equipped with sprinkler system and occ. notification appliances activate throughout upon sprinkler water flow.",IF(OR(T2="I-1 Cond. 1",T2="I-1 Cond. 2",T2="I-2/I-2.1",T2="I-3",T2="I-4"),"Required. Exception: Alarm boxes in sleeping units of I-1 & I-2 are not required at all care provider stations or constantly attended staff lctns. See Sections 907.2.6.1 thru 907.2.6.3.3 for additional exceptions.",IF(T2="M","Combined occupant load of 500+, or 100+ above/below grade. Exception: Where a building is equipped with sprinkler system and occ. notification appliances activate throughout upon sprinkler water flow. Not required in covered or open mall buildings.",IF(T2="R-1","Required. Exception: Where a building is equipped with sprinkler system and occ. notification appliances activate throughout upon sprinkler water flow and no fewer than one manual fire box at approved lctn. See 907.2.8.1 for additional exceptions.",IF(OR(T2="R-2",T2="R-2.1",T2="R-2.2 (CA Only)"),"Contains 16+ dwelling units or Units are 3+ stories below or 1+ story above grade. Exception: Where a bldg is equipped with sprinkler system and occ. notification appliances activate throughout upon sprinkler water flow. See 907.2.9.1 for exceptions.",IF(OR(T2="R-3/R-3.1",T2="R-4"),"Required @ ceiling or wall ourside each dwelling unit. Each sleeping room. Each story withing a dwelling unit.",IF(T2="H-5","Required. No exceptions.",IF(OR(T2="S-1",T2="S-2",T2="U",T2="H-1",T2="H-2",T2="H-3",T2="H-4",T2="L"),"Not Required",""))))))))))) -> Combined occupant load of 500+, or 100+ above/below grade. Fire area contains an ambulatory care facility. Exception: Where a building is equipped with sprinkler system and occ. notification appliances activate throughout upon sprinkler water flow.
B4: =IF(AND(B5="i-3",(OR(B6="v-b",B6="v-a",B6="iv-ht",B6="iv-c",B6="iv-b",B6="iv-a",B6="iii-b",B6="iii-a",B6="ii-b",B6="ii-a"))),"NP in California only. Use Construction Type I-A or I-B.",IF(AND(B5="I-2/I-2.1",(OR(B6="iv-c",B6="iv-b",B6="iv-a",B6="iii-b"))),"Construction type IV-A, IV-B, IV-C, & III-B NP in California only.","")) | F4: Notes: | L4: =IF(OR(K5="NP",K5="NP W/ S13R",K5="NP / Use I-A or I-B Construction",K5="NP W/ S13D",K5="NP W/O S1 or SM Sprinklers",K5="NP W/ II-B, III-B, IV-HT, V-B Construction",K5="NP W/ II-B, III-B, IV-HT (OK Sprinkled), V-B Construction",K5="NP / Construction V-A Only",K5="NP W/ V-B Construction",K6="NP",K6="NP W/ S13R",K6="NP / Use I-A or I-B Construction",K6="NP W/ S13D",K6="NP W/O S1 or SM Sprinklers",K6="NP W/ II-B, III-B, IV-HT, V-B Construction",K6="NP W/ II-B, III-B, IV-HT (OK Sprinkled), V-B Construction",K6="NP / Construction V-A Only",K6="NP W/ V-B Construction",K7="NP",K7="NP W/ S13R",K7="NP / Use I-A or I-B Construction",K7="NP W/ S13D",K7="NP W/O S1 or SM Sprinklers",K7="NP W/ II-B, III-B, IV-HT, V-B Construction",K7="NP W/ II-B, III-B, IV-HT (OK Sprinkled), V-B Construction",K7="NP / Construction V-A Only",K7="NP W/ V-B Construction"),"Note: NP = Not Permitted",IF(OR(K5="UL",K6="UL",K7="UL",K8="UL",K9="UL"),"Note: UL = Unlimited",""))
A5: Occupancy Classification: | B5: B | F5: 1 | G5: Tubular per floor area limit per Table 506.2: | K5: =IF(B7="NS",'2021 area Table 506.2'!A34,IF(B7="S1",'2021 area Table 506.2'!P34,IF(B7="SM",'2021 area Table 506.2'!AE34,IF(B7="S13D",'2021 area Table 506.2'!BI34,IF(B7="S13R",'2021 area Table 506.2'!BX34,0))))) -> 9000
A6: Construction Type: | B6: V-B | F6: 2 | G6: Allowed height: | K6: =IF(B7="NS",'2021 Bldg Ht Table 504.3'!A33,IF(B7="SM",'2021 Bldg Ht Table 504.3'!O33,IF(B7="S1",'2021 Bldg Ht Table 504.3'!O33,IF(B7="S13R",'2021 Bldg Ht Table 504.3'!BE33,IF(B7="S13D",'2021 Bldg Ht Table 504.3'!AQ33,0))))) -> 40
A7: Sprinkled: | B7: NS | G7: Allowed Stories: | K7: =IF(B7="NS",'2021 Stories Table 504.4'!A33,IF(B7="S13D",'2021 Stories Table 504.4'!AT33,IF(B7="S13R",'2021 Stories Table 504.4'!BI33,IF(B7="S1",'2021 Stories Table 504.4'!P33,IF(B7="SM",'2021 Stories Table 504.4'!P33,0))))) -> 2
A8: Number Of Stories: | B8: 1 | G8: Group R and NFPA 13R/D: | K8: =IF(AND(B5="R-1",OR(B7="NS",B7="S13D")),"S13R Required",IF(AND(B5="R-2",OR(B7="NS",B7="S13D")),"S13R Required",IF(AND(B5="R-2.1",OR(B7="NS",B7="S13D")),"S13R Required",IF(AND(B5="R-2.2 (CA Only)",OR(B7="NS",B7="S13R",B7="S13D")),"S1 OR SM Required",IF(AND(B5="R-3/r-3.1",OR(B7="NS")),"S13D OR S13R Required",IF(AND(B5="R-4",OR(B7="NS",B7="S13D")),"S13D OR S13R Required",IF(AND(B5="i-1 Cond. 1",OR(B7="NS",B7="S13D")),"S13R or S1 or SM Required",IF(AND(B7="S13R",OR(B5="A-1",B5="A-2",B5="A-3",B5="A-4",B5="A-5",B5="B",B5="E",B5="F-1",B5="F-2",B5="H-1",B5="H-2",B5="H-3",B5="H-4",B5="H-5",B5="I-1 COND. 2",B5="I-2/I-2.1",B5="I-3",B5="I-4",B5="L",B5="M",B5="S-1",B5="S-2",B5="U")),"NP",IF(AND(B7="S13D",OR(B5="A-1",B5="A-2",B5="A-3",B5="A-4",B5="A-5",B5="B",B5="E",B5="F-1",B5="F-2",B5="H-1",B5="H-2",B5="H-3",B5="H-4",B5="H-5",B5="I-1 COND. 2",B5="I-2/I-2.1",B5="I-3",B5="I-4",B5="L",B5="M",B5="S-1",B5="S-2",B5="U")),"NP",IF(K5="NP W/ 13D","NP",IF(B7="S13R","Yes",IF(B7="S13D","Yes","None")))))))))))) -> None
G9: NFPA 13 Sprinklers: | K9: =IF(AND(B5="I-1 Cond. 2",OR(B7="S13R",B7="S13D",B7="NS")),"Required",IF(AND(B5="I-4",OR(B7="S13R",B7="S13D",B7="NS")),"Required",IF(AND(B5="I-1",OR(B7="S13R",B7="S13D",B7="NS")),"Required",IF(AND(B5="I-2/I-2.1",OR(B7="S13R",B7="S13D",B7="NS")),"Required",IF(AND(B5="I-3",OR(B7="S13R",B7="S13D",B7="NS")),"Required",IF(AND(B5="H-1",OR(B7="S13R",B7="S13D",B7="NS")),"Required",IF(AND(B5="H-2",OR(B7="S13R",B7="S13D",B7="NS")),"Required",IF(AND(B5="H-3",OR(B7="S13R",B7="S13D",B7="NS")),"Required",IF(AND(B5="H-4",OR(B7="S13R",B7="S13D",B7="NS")),"Required",IF(AND(B5="H-5",OR(B7="S13R",B7="S13D",B7="NS")),"Required",IF(B7="NS","None",IF(B7="S13R","None",IF(B7="S13D","None","Yes"))))))))))))) -> None | L9: =IF(AND(K9="REQUIRED",B5="I-4"),"<--- Exception: Each daycare room / classroom has an exterior at exit level discharge.",IF(B5="A-1","<--- Sprinklers required when over 12,000 sq. ft. or occupant load is greater than 300 or fire area is above or below exit discharge. Fire area contains a multitheater complex.",IF(B5="A-3","<--- Sprinklers required when over 12,000 sq. ft. or occupant load is greater than 300 or fire area is above or below exit discharge.",IF(B5="A-4","<--- Sprinklers required when over 12,000 sq. ft. or occupant load is greater than 300 or fire area is above or below exit discharge.",IF(B5="A-5","<--- Sprinkler required when enclosed area(s) are greater than 1,000 sq. ft. Enclosed spaces under bleachers 1,000 sf. ft. of less and not constructed in accordance with Section 1029.1.1.1. or enclosed area exceeds 1,000 sq. ft.",IF(B5="E","<--- Sprinklers required when over 12,000 sq. ft. or occupant load is greater than 300 or fire area is above or below exit discharge. Exception: Each classroom at level of discharge and has a direct exit.",IF(AND(B5="A-2",B7="NS"),"<--- Sprinklers required when over 5000 sq. ft. or occupant load is greater than 100 or fire area is above or below grade.",IF(AND(B5="M",B7="NS"),"<--- Sprinkler required when 12,000 sq. ft. or greater or all combined floors (including mezzanines) exceeds 24,000 sq. ft. or area for furniture or mattresses exceed 5,000 sq. ft. or M occupancy located over 3 stories above grade.",IF(B5="F-1","Fire area exceeds 12,000 sq. ft., fire area is located more the 3-stories above grade, all combined areas exceed 24,000 sq. ft., manufacture of upholstered furniture or matresses exceed 2,500 sq. ft.",IF(B5="I-1","<--- Group I-1, Condition 1 facilities allowed to have an NFPA 13R sprinkler system",IF(B5="S-1","<--- Sprinkler required when enclosed area is 12,000 sq. ft.+ or more than 3-Stories above grade or all combined areas exceed 24,000 sq. ft. or motor vehicle storage exceed 5,000 sq. ft. or upholstered furniture or matress storage exceed 2,500 sq. ft.",IF(B5="S-2","<--- Sprinkler required in enclosed parking garage exceed 12,000 sq. ft. or when enclosed parking garage is located beneath other groups (Exception: Parking garages located beneath Group R-3 occupancies.",""))))))))))))
B10: Building Perimeter Lengths (Feet): | D10: *Distance to property line or to far side of R.O.W. (feet): | F10: 3 | G10: Frontage Increase Factor: Table 506.3 | O10: Notes: | T10: Notes:
G11: Perimeter, (P): | K11: =SUM(B13:B27) -> 168 | O11: 1 | P11: See Chapter 3 for Occupancy Classifications. | T11: 1 | U11: See Section 907 for Fire Alarm requirements.
G12: Frontage perimeter, (F): | J12: =IF(K12<(K11/4),"(See note 8)","") | K12: =IF(D13<20,0,B13)+IF(D14<20,0,B14)+IF(D15<20,0,B15)+IF(D17<20,0,B17)+IF(D18<20,0,B18)+IF(D19<20,0,B19)+IF(D21<20,0,B21)+IF(D22<20,0,B22)+IF(D23<20,0,B23)+IF(D25<20,0,B25)+IF(D26<20,0,B26)+IF(D27<20,0,B27) -> 168
A13: Facing North (Ft): | B13: 60 | D13: 30 | G13: Percentage of perimeter > 20': | K13: =K12/K11 -> 1 | O13: CONSTRUCTION TYPES:
G14: Minimum distance (W): | K14: {=MIN(IF(D13:D27>=20,D13:D27))} -> 24 | O14: =$B$6 -> V-B | T14: Sprinkler Types:
G15: Frontage Increase Factor (If): | K15: =IF(AND(AND(AND(K14>=20),K14<25),K13>=25%,K13<50%),0.17,IF(AND(AND(AND(K14>=25),K14<30),K13>=25%,K13<50%),0.21,IF(AND(AND(K14>=30),K13>=25%,K13<50%),0.25,IF(AND(AND(AND(K14>=20),K14<25),K13>=50%,K13<75%),0.33,IF(AND(AND(AND(K14>=25),K14<30),K13>=50%,K13<75%),0.42,IF(AND(AND(K14>=30),K13>=50%,K13<75%),0.5,IF(AND(AND(AND(K14>=20),K14<25),K13>=75%,K13<=100%),0.5,IF(AND(AND(AND(K14>=25),K14<30),K13>=75%,K13<=100%),0.63,IF(AND(AND(K14>=30),K13>=75%,K13<=100%),0.75,0))))))))) -> 0.5 | O15: =IF(O14="I-A","Buildings of Non-Combustible material. Type A require structural framing / elements to be 3-hr. rated. Exception: Fire retardent treated wood at non-bearing walls rated 2-hrs or less. See Section 603 for additional exceptions.",IF(O14="I-B","Buildings of Non-Combustible material. Type B require no fire rating. Exception: Fire retardent treated wood at non-bearing walls rated 2-hrs or less. See Section 603 for additional exceptions",IF(O14="II-A","Buildings of Non-Combustible material. Type A require structural framing / elements to be 1-hr. rating. Exception: Fire retardent treated wood at non-bearing walls rated 2-hrs or less. See Section 603 for additional exceptions.",IF(O14="II-B","Buildings of Non-Combustible material. Type B require no fire rating. Exception: Fire retardent treated wood at non-bearing walls rated 2-hrs or less. See Section 603 for additional exceptions.",IF(O14="III-A","Ext. walls are non-combustible material, int. walls are non-combustible material. Type A require structural framing / elements to be 1-hr. rated, ext. walls are 2-hr rated. Ext. walls can be reduced to 1-hr. rated when supporting a roof only.",IF(O14="III-B","Exterior walls are of non-combustible material and interior walls can be made of non-combustible material. Type B require no fire rating of structural framing / elements.",IF(O14="IV-HT","Ext. walls are of non-combustible material and int. building elements are of solid wood, laminate wood, heavy timber or structural composite lumber. Ext. walls are required to be 2-hr. rated. Structural elements are to be with material listed above.",IF(O14="V-A","All exterior and interior walls made of combustible material. Type A require structural framing / elements to be 1-hr. rated.",IF(O14="V-B","All exterior and interior walls made of combustible material. Type B requires no rating of structural framing / elements.",IF(O14="IV-A","Ext. walls are of non-combustible material w/ min. rating of 40 min. and int. elements include mass timber walls and roof w/ min. 80 min. rating. See section 602.4.1 for all requirements.",IF(O14="IV-B","Ext. walls are of non-combustible material w/ min. rating of 40 min. and int. elements include mass timber walls and roof w/ min. 80 min. rating. See section 602.4.2 for all requirements.",IF(O14="IV-C","Ext. walls are of non-combustible material w/ min. rating of 40 min. and int. elements include mass timber walls and roof permitted to be unprotected. See section 602.4.3 for all requirements.","")))))))))))) -> All exterior and interior walls made of combustible material. Type B requires no rating of structural framing / elements. | T15: =$B$7 -> NS
F16: 4 | G16: Allowable per story area, Aa = At+(NS x If): | K16: =IF(OR(K5="UL",K5="NP",K5="NP W/ S13R",K5="NP / Use I-A or I-B Construction",K5="NP W/ S13D",K5="NP W/O S1 or SM Sprinklers",K5="NP W/ II-B, III-B, IV-HT, V-B Construction",K5="NP W/ II-B, III-B, IV-HT (OK Sprinkled), V-B Construction",K5="NP / Construction V-A Only",K5="NP W/ V-B Construction",K7="Choose Spinkler SM"),K5,(K5+('2021 area Table 506.2'!A34*K15))) -> 13500 | T16: =IF(T15="NS","NS: Non Sprinkled",IF(T15="S1","S1: NFPA 13 Single Story Sprinkled",IF(T15="SM","SM: NFPA 13 Multi-Story Sprinkled",IF(T15="S13R","S13R: Residential Sprinkler System",IF(T15="S13D","S13D: Residential Sprinkler System",""))))) -> NS: Non Sprinkled
A17: Facing East (Ft): | B17: 24 | D17: 35 | F17: 5 | G17: Maximum allowable area, Aa=[At+(NSxIf)]xSa: | K17: =IF(OR(K5="UL",K5="NP",K5="NP W/ S13R",K5="NP / Use I-A or I-B Construction",K5="NP W/ S13D",K5="NP W/O S1 or SM Sprinklers",K5="NP W/ II-B, III-B, IV-HT, V-B Construction",K5="NP W/ II-B, III-B, IV-HT (OK Sprinkled), V-B Construction",K5="NP / Construction V-A Only",K5="NP W/ V-B Construction",K7="Choose Spinkler SM"),K5,(K16*B8)) -> 13500
F19: Special Conditions:
F20: 1 | G20: Unlimited area reduction in public ways or yard allowed (60' to 40'). Restrictions apply. Section 507.
A21: Facing South (Ft): | B21: 60 | D21: 24
F22: 2 | G22: Unlimited area allowed with 1-Story (non-sprinkled), Groups F-2 or S-2 with public ways or yards not less than 60' on all sides. Section 507.3. | O22: Notes:
O23: 1 | P23: Type A construction referes to "Protected" (rated) construction, except with Type I structures.
A25: Facing West (Ft): | B25: 24 | D25: 60 | F25: 3 | G25: Unlimited area allowed with 1-Story (NFPA-13 sprinkled), Groups A-4 (other than type V) or B, F, M or S with public ways or yards not less than 60' on all sides. Section 507.4.
O26: 2 | P26: Type B construction referes to "Unprotected" (non-rated) construction, except with Type I structures.
F28: 4 | G28: Sprinklers required for all Group R occupancies. Certain R occupancies / conditions allow for an NFPA 13D system. Section 903.2.8.
O29: 3 | P29: See Table 601 for fire resistance requirements.
A30: Allowable area per floor (Aa=[At+(NSxIf)]: | B30: =(K16) -> 13500 | C30: Sq. Ft. per floor | F30: 5 | G30: Type V-A construction requires all structural elements / members be 1-hour rated (Ext. Walls, floors, roof, ridge beams, and columns). Table 601.
A31: Total allowable area [Aa x # of Stories]: | B31: =(K17) -> 13500 | C31: Sq. Ft. total | O31: 4 | P31: See Table 705.5 for fire resistance requirements for exterior walls based on seperation distance.
A32: Max. allowable Height (Table 504.3): | B32: =(K6) -> 40 | C32: Feet
A33: Max. Allowable Stories (Aa=[At+(NSxIf)]xSa: | B33: =IF(B8>K7,"NP",K7) -> 2 | C33: Storie(s) | F33: 6 | G33: See Table 705.5 for fire rating requirements for exterior walls based on seperation distance.
A34: Allowed Area Increase Multi-Story (CA only): | B34: ='2021 area Table 506.2'!AT34 -> No Limitations | C34: Sq. Ft. each story
A35: Allowed Height W/ Area Increase (CA only): | B35: =IF(OR(B7="S1",B7="SM"),'2021 Bldg Ht Table 504.3'!AC33,'2021-2024 Frontage Increase'!K6) -> 40 | C35: Feet total | F35: 7 | G35: Multi-Story not to exceed 3 without sprinkler system. See Section 506.2.3.
A36: Allowed Stories W/ Area Increase (CA only): | B36: ='2021 Stories Table 504.4'!AE33 -> No Limitations | C36: Storie(s)
F37: 8 | G37: To qualify for area factor increase based on frontage, at least 25% of the building perimeter on public way / space shall have min. width of 20'. Section 506.3.1.
A46: PROPERTY LINE EXAMPLE: | D46: (R.O.W.=Right Of Way)
F48: Note: Per section 506.3.2, the smallest public way or open space must be used.

Sheet 2009-2018 Frontage Increase
A1: 2009 - 2018 IBC FRONTAGE INCREASE CALCULATOR | G1: =IF(B5="E","AZ: Sprinklers required is above grade set.","") | O1: Occupancy Classifications: | T1: Fire Alarm Requirements:
G2: =IF(B5="E","FL, GA, RI, & DE: Sprinklers required. Exception: Under 1,000 sq. ft., single classroom, and less than 30' from other buildings. (NFPA 101: 14.3.5) / No exception for SREF classroom for FL.","") | O2: =IF(OR(B5="A-1",2="A-2",B5="A-3",B5="A-4",B5="A-5"),"A: Assembly Group",IF(B5="B","B: Business Group",IF(B5="E","E: Educational Group",IF(OR(B5="F-1",B5="F-2"),"F: Factory Group",IF(OR(B5="H-1",B5="H-2",B5="H-3",B5="H-4",B5="H-5"),"H: High Hazard Group",IF(OR(B5="I-1 Cond. 1",B5="I-1 Cond. 2",B5="I-2/I-2.1",B5="I-3",B5="I-4"),"I: Institutional Group",IF(B5="M","M: Mercantile Group",IF(OR(B5="R-1",B5="r-2",B5="r-2.1",B5="r-2.2 (ca only)",B5="r-3/r-3.1",B5="r-4"),"R: Residential Group",IF(OR(B5="s-1",B5="s-2"),"S: Storage Group",IF(B5="U","U: Utility & Miscellaneous Group",IF(B5="L","L: Labortories Group",""))))))))))) -> B: Business Group | T2: =$B$5 -> B
A3: Project #: | O3: =IF(B5="a-1","A-1: Assembly use intended for the production & viewing of performing arts or motion pictures. Motion Picture Theaters, Concert Halls, TV/Radio Studios w/ audience, Theaters.",IF(B5="a-2","A-2: Assembly use intended for food / drink consumption. Banquet Halls, Casinos, Nightclubs, Restaurants, Break Rooms.",IF(B5="A-3","A-3: Assembly use for worship, recreation/amusement, and other assembly uses. Conferences, Lecture Halls, Libraries, Places of Worship, Waiting areas, Bowling Alleys, Court Rooms, Amusement Arcades, Community Halls, Dance Halls, Etc.",IF(B5="A-4","A-4: Assembly use intended for viewing indoor sporting events/activities with seating. Arenas, Skating Rinks, Swimming Pools, Tennis Courts.",IF(B5="A-5","A-5: assembly use intended for participation in or viewing outdoor activities. Amusement park structures, Bleachers, Grandstands, Stadiums",IF(B5="b","B: Air Traffic Towers, Ambulatory Care (serving 6 or fewer), Banks, Barber/Beauty Shops, Vet Clinic, Bank, Offices, Outpatient Clinic, Education grade over 12th grade, food processing, print shops, radio/TV stations.",IF(B5="E","E: Grades Pre-K thru 12th occupied by more than 6 persons. Group E Daycare occupied by 5 or more kids older than 2-1/2 yo and receive less than 24hr. care. See Section 303.1.4 for accessory to places of worship.",IF(B5="F-1","F-1: Factory industrial that are considered Moderate Hazard. Aircraft repair, Appliances, Bakeries, Bicylces, Boats, Business Machines, Clothing, Construction and Agricultural Machinery, Dry Cleaning, Engines, Electronics, Paper Mill, Tabacco, Wood.",IF(B5="f-2","F-2: Factory industrial that are considered Low Hazard. Beverage up to 16% alcohol content, Brick/Masonry, Ceramic Products, Foundries, Glass Products, Gypsum, Ice, Metal Procucts.",IF(B5="H-1","H-1: Occupancies containing explosives. Explosives, Div. 1.1, 1.2, 1.3, 1.5, 1.6.",IF(B5="H-2","H-2: Buildings containing materials that pose a deflagration hazard or hazard from accelerated burning. Combustible Duct & Liquid, Cryogentic Liquid/Flammable, Div. 1.3 Explosives, Flammable Gas or Liquid (Type IA, IB, or IC).",IF(B5="H-3","H-3: Buildings containing materials that readily support combustion or pose a physical hazard. Combustible Fiber, Liquid (Type II or IIIA, Cryogenic oxidizing, Flammable Liquid, solid or combination, organic peroxide.",IF(B5="H-4","H-4: Buildings containing materials that are health hazards. Corrosives, Highly Toxic materials, Toxic materials.",IF(B5="H-5","H-5: Semiconductor fabrication facilities and comparable research and develpment areas in which hazardous production materials are used and the aggregate quantity of materials is in excess of those listed in Tables 307.1(1) & 307.1(2).",IF(B5="I-1 Cond. 1","I-1 Cond. 1: Buildings for more than 16 persons, excluding staff who reside on a 24-hr. basis in a supv enriroment and receive custodial care. Halfway house, Assisted Living. Cond 1: Person in custodial care, but can respond to an emergency situation.",IF(B5="I-1 Cond. 2","I-1 Cond. 2: Bldgs for 16+ persons, excl. staff who reside on a 24-hr basis in a supv enriroment and receive custodial care. Halfway house, Assisted Living. Cond 2: Person in care who require limited verbal/physical asst. while rspnd to emer. sitn.",IF(B5="i-2/i-2.1","I-2: Buildings for medical care on 24hr. basis for more than 5 persons who are incapable of self-preservation or nonambulatory. Hospitals, Nursing Homes, Psyc. Hospitals. 5 or fewer persons receiving medical care shall be classifed as Group R-3.",IF(B5="I-3","I-3: Buildings or portions of that are inhabited by one or more than 5 who are under restaint or security. Corrections centers, hospitals, nursing, mental, holding, treatment. Detention Centers, Jails, Juvenile Halls, Prisons, Temporary Holding.",IF(B5="i-4","I-4: Buildings occupied by more than 6 clients of any age who recieve custodial care for fewer than 24hr per day other than parents or guardians. Adult Daycare, Child Daycare. See Section 308.5.1 to classify as Group E daycare",IF(B5="L","L: Building contains 1 or more labatory suites as defined in Section 453 (2019 CBC).",IF(B5="M","M: Buildings for the display and sale of merchandise, and involves stocks or goods, wares or merchandise incidental to such purposes and accessible to the public. Department Stores, Drug Stores, Greenhouses (Display and Sale), Markets, Sales Rooms.",IF(B5="R-1","R-1: Building for sleeping purposes where occupants are transient in nature. Hotels, Motels.",IF(B5="r-2","R-2: Buildings for sleeping purposes when not classified as an Institutional Group I or when not regulated by the International Residential Code. Boarding House, Dormatory, Congregate Living, Group Home, Hotels, Motels, Fraternities, Transient.",IF(B5="R-2.1","R-2.1: Buildings housing clients on a 24hr. basis, who because of age, mental disability or other reasons, live in a supervised enviroment. Res. Care Facilities for children or elderly, Group Homes, Comm. Correction centers, alcohol/drug treatment.",IF(B5="R-2.2 (CA Only)","R-2.2: Residential occupanies operated by CDCR in a community located facility that provides housing and community based program services for nontransient ambulatory care in a nonlicensed facility w/ 24/7 upervision.",IF(B5="R-3/r-3.1","R-3/R-3.1: Occupants are primary in nature and not classified as R-1, R-2, R-2.1, R-2.2 (CA), R-3.1, R-4, or I. Nontransient with 16 or fewer occupants, Boarding houses, Convents, Dorms, Fraternities, Monasteries, Adult/Child care with 6 or fewer.",IF(B5="R-4","R-4: Buildings for more than 6 ambulatory clients, but no more than 16 persons, excluding staff, who reisde on a 24hr basis in a supervised residential enviroment. R-4 shall meet the requirements of R-3. Section 310.5 (CBC)",IF(B5="s-1","S-1: Moderate-Hazard Storage buildings not classified as S-2. Aerol products, Aircraft Hanger (Storage/Repari), Bags, Bamboo, Books/Paper in rolls or packs, Boots/Shoes, Cardboard, Dry boat storage, Lino, Lumber, Soaps, Wax candles.",IF(B5="s-2","S-2: Low Hazard Storage. Asbestos, Cement Bags, Chalk/Crayons, Dairy Products in nonwaxed containers, Dry Cell Batteries, Electrical Coils, Empty Cans, Glass, Gypsu Board, Meats, Metal Parts, Porcelain, Stoves.",IF(B5="U","U: Buildings not classified in any specific occupancy shall be constructed, equipped and maintained to conform with code requirements. Agriculural buildings, Barns, Carports, Comm equip., Private garages, Sheds, Stables, Tanks, Towers.","")))))))))))))))))))))))))))))) -> B: Air Traffic Towers, Ambulatory Care (serving 6 or fewer), Banks, Barber/Beauty Shops, Vet Clinic, Bank, Offices, Outpatient Clinic, Education grade over 12th grade, food processing, print shops, radio/TV stations. | T3: =IF(OR(T2="A-1",T2="A-2",T2="A-3",T2="A-4",T2="A-5"),"Occupant load 300+ @ grade level, or 100+ above/below grade. Exception: Where a building is equipped with sprinkler system and occ. notification appliances activate throughout upon sprinkler water flow.",IF(T2="B","Combined occupant load of 500+, or 100+ above/below grade. Fire area contains an ambulatory care facility. Exception: Where a building is equipped with sprinkler system and occ. notification appliances activate throughout upon sprinkler water flow.",IF(T2="E","Required. Exception: Occupants of 50 or less. Emer. voice/arlarm communication installed and occupant load is 100 or less. Alarm boxes not required if: building has a sprinkler system, emer. voice/alarm installed, activation from an norm. occupied area.",IF(OR(T2="F-1",T2="F-2"),"Combined occupant load of 500+ above or below grade and has 2+ stories in height. Exception: Where a building is equipped with sprinkler system and occ. notification appliances activate throughout upon sprinkler water flow.",IF(OR(T2="I-1 Cond. 1",T2="I-1 Cond. 2",T2="I-2/I-2.1",T2="I-3",T2="I-4"),"Required. Exception: Alarm boxes in sleeping units of I-1 & I-2 are not required at all care provider stations or constantly attended staff lctns. See Sections 907.2.6.1 thru 907.2.6.3.3 for additional exceptions.",IF(T2="M","Combined occupant load of 500+, or 100+ above/below grade. Exception: Where a building is equipped with sprinkler system and occ. notification appliances activate throughout upon sprinkler water flow. Not required in covered or open mall buildings.",IF(T2="R-1","Required. Exception: Where a building is equipped with sprinkler system and occ. notification appliances activate throughout upon sprinkler water flow and no fewer than one manual fire box at approved lctn. See 907.2.8.1 for additional exceptions.",IF(OR(T2="R-2",T2="R-2.1",T2="R-2.2 (CA Only)"),"Contains 16+ dwelling units or Units are 3+ stories below or 1+ story above grade. Exception: Where a bldg is equipped with sprinkler system and occ. notification appliances activate throughout upon sprinkler water flow. See 907.2.9.1 for exceptions.",IF(OR(T2="R-3/R-3.1",T2="R-4"),"Required @ ceiling or wall ourside each dwelling unit. Each sleeping room. Each story withing a dwelling unit.",IF(T2="H-5","Required. No exceptions.",IF(OR(T2="S-1",T2="S-2",T2="U",T2="H-1",T2="H-2",T2="H-3",T2="H-4",T2="L"),"Not Required",""))))))))))) -> Combined occupant load of 500+, or 100+ above/below grade. Fire area contains an ambulatory care facility. Exception: Where a building is equipped with sprinkler system and occ. notification appliances activate throughout upon sprinkler water flow.
B4: =IF(AND(B5="i-3",(OR(B6="v-b",B6="v-a",B6="iv-ht",B6="iv-c",B6="iv-b",B6="iv-a",B6="iii-b",B6="iii-a",B6="ii-b",B6="ii-a"))),"NP in California only. Use Construction Type I-A or I-B.",IF(AND(B5="I-2/I-2.1",(OR(B6="iv-c",B6="iv-b",B6="iv-a",B6="iii-b"))),"Construction type IV-A, IV-B, IV-C, & III-B NP in California only.","")) | F4: Notes: | L4: =IF(OR(K5="NP",K5="NP W/ S13R",K5="NP / Use I-A or I-B Construction",K5="NP W/ S13D",K5="NP W/O S1 or SM Sprinklers",K5="NP W/ II-B, III-B, IV-HT, V-B Construction",K5="NP W/ II-B, III-B, IV-HT (OK Sprinkled), V-B Construction",K5="NP / Construction V-A Only",K5="NP W/ V-B Construction",K6="NP",K6="NP W/ S13R",K6="NP / Use I-A or I-B Construction",K6="NP W/ S13D",K6="NP W/O S1 or SM Sprinklers",K6="NP W/ II-B, III-B, IV-HT, V-B Construction",K6="NP W/ II-B, III-B, IV-HT (OK Sprinkled), V-B Construction",K6="NP / Construction V-A Only",K6="NP W/ V-B Construction",K7="NP",K7="NP W/ S13R",K7="NP / Use I-A or I-B Construction",K7="NP W/ S13D",K7="NP W/O S1 or SM Sprinklers",K7="NP W/ II-B, III-B, IV-HT, V-B Construction",K7="NP W/ II-B, III-B, IV-HT (OK Sprinkled), V-B Construction",K7="NP / Construction V-A Only",K7="NP W/ V-B Construction"),"Note: NP = Not Permitted",IF(OR(K5="UL",K6="UL",K7="UL",K8="UL",K9="UL"),"Note: UL = Unlimited",""))
A5: Occupancy Classification: | B5: B | F5: 1 | G5: Tubular per floor area limit per Table 506.2: | K5: =IF(B7="NS",'Allowable area Table 506.2'!A34,IF(B7="S1",'Allowable area Table 506.2'!M34,IF(B7="SM",'Allowable area Table 506.2'!Y34,IF(B7="S13D",'Allowable area Table 506.2'!AW34,IF(B7="S13R",'Allowable area Table 506.2'!BI34,0))))) -> 9000
A6: Construction Type: | B6: V-B | F6: 2 | G6: Allowed height: | K6: =IF(B7="NS",'Allowable Bldg Ht Table 504.3'!A33,IF(B7="SM",'Allowable Bldg Ht Table 504.3'!L33,IF(B7="S1",'Allowable Bldg Ht Table 504.3'!L33,IF(B7="S13R",'Allowable Bldg Ht Table 504.3'!AS33,IF(B7="S13D",'Allowable Bldg Ht Table 504.3'!AH33,0))))) -> 40
A7: Sprinkled: | B7: NS | G7: Allowed Stories: | K7: =IF(B7="NS",'Allowable Stories Table 504.4'!A33,IF(B7="S13D",'Allowable Stories Table 504.4'!AK33,IF(B7="S13R",'Allowable Stories Table 504.4'!AW33,IF(B7="S1",'Allowable Stories Table 504.4'!M33,IF(B7="SM",'Allowable Stories Table 504.4'!M33,0))))) -> 2
A8: Number Of Stories: | B8: 1 | G8: Group R and NFPA 13R/D: | K8: =IF(AND(B5="R-1",OR(B7="NS",B7="S13D")),"S13R Required",IF(AND(B5="R-2",OR(B7="NS",B7="S13D")),"S13R Required",IF(AND(B5="R-2.1",OR(B7="NS",B7="S13D")),"S13R Required",IF(AND(B5="R-2.2 (CA Only)",OR(B7="NS",B7="S13R",B7="S13D")),"S1 OR SM Required",IF(AND(B5="R-3/r-3.1",OR(B7="NS")),"S13D OR S13R Required",IF(AND(B5="R-4",OR(B7="NS",B7="S13D")),"S13D OR S13R Required",IF(AND(B5="i-1 Cond. 1",OR(B7="NS",B7="S13D")),"S13R or S1 or SM Required",IF(AND(B7="S13R",OR(B5="A-1",B5="A-2",B5="A-3",B5="A-4",B5="A-5",B5="B",B5="E",B5="F-1",B5="F-2",B5="H-1",B5="H-2",B5="H-3",B5="H-4",B5="H-5",B5="I-1 COND. 2",B5="I-2/I-2.1",B5="I-3",B5="I-4",B5="L",B5="M",B5="S-1",B5="S-2",B5="U")),"NP",IF(AND(B7="S13D",OR(B5="A-1",B5="A-2",B5="A-3",B5="A-4",B5="A-5",B5="B",B5="E",B5="F-1",B5="F-2",B5="H-1",B5="H-2",B5="H-3",B5="H-4",B5="H-5",B5="I-1 COND. 2",B5="I-2/I-2.1",B5="I-3",B5="I-4",B5="L",B5="M",B5="S-1",B5="S-2",B5="U")),"NP",IF(K5="NP W/ 13D","NP",IF(B7="S13R","Yes",IF(B7="S13D","Yes","None")))))))))))) -> None
G9: NFPA 13 Sprinklers: | K9: =IF(AND(B5="I-1 Cond. 2",OR(B7="S13R",B7="S13D",B7="NS")),"Required",IF(AND(B5="I-4",OR(B7="S13R",B7="S13D",B7="NS")),"Required",IF(AND(B5="I-1",OR(B7="S13R",B7="S13D",B7="NS")),"Required",IF(AND(B5="I-2/I-2.1",OR(B7="S13R",B7="S13D",B7="NS")),"Required",IF(AND(B5="I-3",OR(B7="S13R",B7="S13D",B7="NS")),"Required",IF(AND(B5="H-1",OR(B7="S13R",B7="S13D",B7="NS")),"Required",IF(AND(B5="H-2",OR(B7="S13R",B7="S13D",B7="NS")),"Required",IF(AND(B5="H-3",OR(B7="S13R",B7="S13D",B7="NS")),"Required",IF(AND(B5="H-4",OR(B7="S13R",B7="S13D",B7="NS")),"Required",IF(AND(B5="H-5",OR(B7="S13R",B7="S13D",B7="NS")),"Required",IF(B7="NS","None",IF(B7="S13R","None",IF(B7="S13D","None","Yes"))))))))))))) -> None | L9: =IF(AND(K9="REQUIRED",B5="I-4"),"<--- Exception: Each daycare room / classroom has an exterior at exit level discharge.",IF(B5="A-1","<--- Sprinklers required when over 12,000 sq. ft. or occupant load is greater than 300 or fire area is above or below exit discharge. Fire area contains a multitheater complex.",IF(B5="A-3","<--- Sprinklers required when over 12,000 sq. ft. or occupant load is greater than 300 or fire area is above or below exit discharge.",IF(B5="A-4","<--- Sprinklers required when over 12,000 sq. ft. or occupant load is greater than 300 or fire area is above or below exit discharge.",IF(B5="A-5","<--- Sprinkler required when enclosed area(s) are greater than 1,000 sq. ft. Enclosed spaces under bleachers 1,000 sf. ft. of less and not constructed in accordance with Section 1029.1.1.1. or enclosed area exceeds 1,000 sq. ft.",IF(B5="E","<--- Sprinklers required when over 12,000 sq. ft. or occupant load is greater than 300 or fire area is above or below exit discharge. Exception: Each classroom at level of discharge and has a direct exit.",IF(AND(B5="A-2",B7="NS"),"<--- Sprinklers required when over 5000 sq. ft. or occupant load is greater than 100 or fire area is above or below grade.",IF(AND(B5="M",B7="NS"),"<--- Sprinkler required when 12,000 sq. ft. or greater or all combined floors (including mezzanines) exceeds 24,000 sq. ft. or area for furniture or mattresses exceed 5,000 sq. ft. or M occupancy located over 3 stories above grade.",IF(B5="F-1","Fire area exceeds 12,000 sq. ft., fire area is located more the 3-stories above grade, all combined areas exceed 24,000 sq. ft., manufacture of upholstered furniture or matresses exceed 2,500 sq. ft.",IF(B5="I-1","<--- Group I-1, Condition 1 facilities allowed to have an NFPA 13R sprinkler system",IF(B5="S-1","<--- Sprinkler required when enclosed area is 12,000 sq. ft.+ or more than 3-Stories above grade or all combined areas exceed 24,000 sq. ft. or motor vehicle storage exceed 5,000 sq. ft. or upholstered furniture or matress storage exceed 2,500 sq. ft.",IF(B5="S-2","<--- Sprinkler required in enclosed parking garage exceed 12,000 sq. ft. or when enclosed parking garage is located beneath other groups (Exception: Parking garages located beneath Group R-3 occupancies.",""))))))))))))
B10: Building Perimeter Lengths (Feet): | D10: *Distance to property line or to far side of R.O.W. (feet): | F10: 3 | G10: Frontage Increase: If=[F/P - 0.25]W/30 | O10: Notes: | T10: Notes:
G11: Frontage coefficient, (If): | K11: =SUM(((K13/K12)-0.25)*(K14/30)) -> 0.32407407 | O11: 1 | P11: See Chapter 3 for Occupancy Classifications. | T11: 1 | U11: See Section 907 for Fire Alarm requirements (2018 IBC / 2019 CBC).
G12: Perimeter, (P): | K12: =SUM(B13:B27) -> 300
A13: Facing North (Ft): | B13: 120 | D13: 18 | G13: Frontage perimeter, (F): | J13: =IF(K13<(K12/4),"(See note 8)","") | K13: =IF(D13<20,0,B13)+IF(D14<20,0,B14)+IF(D15<20,0,B15)+IF(D17<20,0,B17)+IF(D18<20,0,B18)+IF(D19<20,0,B19)+IF(D21<20,0,B21)+IF(D22<20,0,B22)+IF(D23<20,0,B23)+IF(D25<20,0,B25)+IF(D26<20,0,B26)+IF(D27<20,0,B27) -> 180 | O13: CONSTRUCTION TYPES:
G14: Average frontage distance (W): | K14: =SUM(IF(OR(D13<20,D13>30),0,(B13*D13))+IF(D13>30,(B13*30),0)+IF(OR(D14<20,D14>30),0,(B14*D14))+IF(D14>30,(B14*30),0)+IF(OR(D15<20,D15>30),0,(B15*D15))+IF(D15>30,(B15*30),0)+IF(OR(D17<20,D17>30),0,(B17*D17))+IF(D17>30,(B17*30),0)+IF(OR(D18<20,D18>30),0,(B18*D18))+IF(D18>30,(B18*30),0)+IF(OR(D19<20,D19>30),0,(B19*D19))+IF(D19>30,(B19*30),0)+IF(OR(D21<20,D21>30),0,(B21*D21))+IF(D21>30,(B21*30),0)+IF(OR(D22<20,D22>30),0,(B22*D22))+IF(D22>30,(B22*30),0)+IF(OR(D23<20,D23>30),0,(B23*D23))+IF(D23>30,(B23*30),0)+IF(OR(D25<20,D25>30),0,(B25*D25))+IF(D25>30,(B25*30),0)+IF(OR(D26<20,D26>30),0,(B26*D26))+IF(D26>30,(B26*30),0)+IF(OR(D27<20,D27>30),0,(B27*D27))+IF(D27>30,(B27*30),0),0)/K13 -> 27.777778 | O14: =$B$6 -> V-B | T14: Sprinkler Types:
F15: 4 | G15: Allowable per story area, Aa = At+(NS x If): | K15: =IF(OR(K5="UL",K5="NP",K5="NP W/ S13R",K5="NP / Use I-A or I-B Construction",K5="NP W/ S13D",K5="NP W/O S1 or SM Sprinklers",K5="NP W/ II-B, III-B, IV-HT, V-B Construction",K5="NP W/ II-B, III-B, IV-HT (OK Sprinkled), V-B Construction",K5="NP / Construction V-A Only",K5="NP W/ V-B Construction",K7="Choose Spinkler SM"),K5,(K5+('Allowable area Table 506.2'!A34*'2009-2018 Frontage Increase'!K11))) -> 11916.667 | O15: =IF(O14="I-A","Buildings of Non-Combustible material. Type A require structural framing / elements to be 3-hr. rated. Exception: Fire retardent treated wood at non-bearing walls rated 2-hrs or less. See Section 603 for additional exceptions.",IF(O14="I-B","Buildings of Non-Combustible material. Type B require no fire rating. Exception: Fire retardent treated wood at non-bearing walls rated 2-hrs or less. See Section 603 for additional exceptions",IF(O14="II-A","Buildings of Non-Combustible material. Type A require structural framing / elements to be 1-hr. rating. Exception: Fire retardent treated wood at non-bearing walls rated 2-hrs or less. See Section 603 for additional exceptions.",IF(O14="II-B","Buildings of Non-Combustible material. Type B require no fire rating. Exception: Fire retardent treated wood at non-bearing walls rated 2-hrs or less. See Section 603 for additional exceptions.",IF(O14="III-A","Ext. walls are non-combustible material, int. walls are non-combustible material. Type A require structural framing / elements to be 1-hr. rated, ext. walls are 2-hr rated. Ext. walls can be reduced to 1-hr. rated when supporting a roof only.",IF(O14="III-B","Exterior walls are of non-combustible material and interior walls can be made of non-combustible material. Type B require no fire rating of structural framing / elements.",IF(O14="IV-HT","Ext. walls are of non-combustible material and int. building elements are of solid wood, laminate wood, heavy timber or structural composite lumber. Ext. walls are required to be 2-hr. rated. Structural elements are to be with material listed above.",IF(O14="V-A","All exterior and interior walls made of combustible material. Type A require structural framing / elements to be 1-hr. rated.",IF(O14="V-B","All exterior and interior walls made of combustible material. Type B requires no rating of structural framing / elements.",""))))))))) -> All exterior and interior walls made of combustible material. Type B requires no rating of structural framing / elements. | T15: =$B$7 -> NS
F16: 5 | G16: Maximum allowable area, Aa=[At+(NSxIf)]xSa: | K16: =IF(OR(K5="UL",K5="NP",K5="NP W/ S13R",K5="NP / Use I-A or I-B Construction",K5="NP W/ S13D",K5="NP W/O S1 or SM Sprinklers",K5="NP W/ II-B, III-B, IV-HT, V-B Construction",K5="NP W/ II-B, III-B, IV-HT (OK Sprinkled), V-B Construction",K5="NP / Construction V-A Only",K5="NP W/ V-B Construction",K7="Choose Spinkler SM"),K5,(K15*B8)) -> 11916.667 | T16: =IF(T15="NS","NS: Non Sprinkled",IF(T15="S1","S1: NFPA 13 Single Story Sprinkled",IF(T15="SM","SM: NFPA 13 Multi-Story Sprinkled",IF(T15="S13R","S13R: Residential Sprinkler System",IF(T15="S13D","S13D: Residential Sprinkler System",""))))) -> NS: Non Sprinkled
A17: Facing East (Ft): | B17: 80 | D17: 50
F18: Special Conditions:
F19: 1 | G19: Unlimited area reduction in public ways or yard allowed (60' to 40'). Restrictions apply. Section 507.2 (2018 IBC / 2019 CBC)
A21: Facing South (Ft): | B21: 60 | D21: 40 | F21: 2 | G21: Unlimited area allowed with 1-Story (non-sprinkled), Groups F-2 or S-2 with public ways or yards not less than 60' on all sides. Section 507.3 (2018 IBC / 2019 CBC)
O22: Notes:
O23: 1 | P23: Type A construction referes to "Protected" (rated) construction, except with Type I structures.
F24: 3 | G24: Unlimited area allowed with 1-Story (sprinkled), Groups A-4 (other than type V) A-3, B, F, M or S with public ways or yards not less than 60' on all sides. Section 507.4 (2018 IBC / 2019 CBC)
A25: Facing West (Ft): | B25: 40 | D25: 20
O26: 2 | P26: Type B construction referes to "Unprotected" (non-rated) construction, except with Type I structures.
F27: 4 | G27: Sprinklers required for all Group R occupancies. Certain R occupancies / conditions allow for an NFPA 13D system (See sub-sections). Section 903.2.8 (2018 IBC / 2019 CBC)
F29: 5 | G29: Type V-A construction requires all structural elements / members be 1-hour rated (Ext. Walls, floors, roof, ridge beams, and columns). Table 601. | O29: 3 | P29: See Table 601 for fire resistance requirements.
A30: Allowable area per floor (Aa=[At+(NSxIf)]: | B30: =(K15) -> 11916.667 | C30: Sq. Ft. per floor
A31: Total allowable area [Aa x # of Stories]: | B31: =(K16) -> 11916.667 | C31: Sq. Ft. total | O31: 4 | P31: See Table 602 for fire resistance requirements for exterior walls based on seperation distance.
A32: Max. allowable Height (Table 504.3): | B32: =(K6) -> 40 | C32: Feet | F32: 6 | G32: See Table 602 for fire rating requirements for exterior walls based on seperation distance.
A33: Max. Allowable Stories (Aa=[At+(NSxIf)]xSa: | B33: =IF(B8>K7,"NP",K7) -> 2 | C33: Storie(s)
A34: Allowed Area Increase Multi-Story (CA only): | B34: ='Allowable area Table 506.2'!AK34 -> No Limitations | C34: Sq. Ft. each story | F34: 7 | G34: Multi-Story not to exceed 3 without sprinkler system. See Section 506.2.3 (2018 IBC / 2019 CBC)
A35: Allowed Height W/ Area Increase (CA only): | B35: =IF(OR(B7="S1",B7="SM"),'Allowable Bldg Ht Table 504.3'!W33,'2009-2018 Frontage Increase'!K6) -> 40 | C35: Feet total
A36: Allowed Stories W/ Area Increase (CA only): | B36: =('Allowable Stories Table 504.4'!Y33) -> No Limitations | C36: Storie(s) | F36: 8 | G36: To qualify for area factor increase based on frontage, at least 25% of the building perimeter on public way / space shall have min. width of 20'. Section 506.3.1 (2018 IBC / 2019 CBC)
A46: PROPERTY LINE EXAMPLE: | D46: (R.O.W.=Right Of Way)

Sheet 2021-2024 Mixed Occupancy
A1: 2021-2024 IBC MIXED OCCUPANCY SINGLE STORY | G1: =IF(B5="E","AZ: Sprinklers required is above grade set.","") | O1: CONSTRUCTION TYPES: | T1: Sprinkler Types:
G2: =IF(B5="E","FL, GA, RI, & DE: Sprinklers required. Exception: Under 1,000 sq. ft., single classroom, and less than 30' from other buildings. (NFPA 101: 14.3.5) / No exception for SREF classroom for FL.","") | O2: =B$6 -> V-B | T2: =B7 -> NS
A3: Project #: | O3: =IF(O2="I-A","Buildings of Non-Combustible material. Type A require structural framing / elements to be 3-hr. rated. Exception: Fire retardent treated wood at non-bearing walls rated 2-hrs or less. See Section 603 for additional exceptions.",IF(O2="I-B","Buildings of Non-Combustible material. Type B require no fire rating. Exception: Fire retardent treated wood at non-bearing walls rated 2-hrs or less. See Section 603 for additional exceptions",IF(O2="II-A","Buildings of Non-Combustible material. Type A require structural framing / elements to be 1-hr. rating. Exception: Fire retardent treated wood at non-bearing walls rated 2-hrs or less. See Section 603 for additional exceptions.",IF(O2="II-B","Buildings of Non-Combustible material. Type B require no fire rating. Exception: Fire retardent treated wood at non-bearing walls rated 2-hrs or less. See Section 603 for additional exceptions.",IF(O2="III-A","Ext. walls are non-combustible material, int. walls are non-combustible material. Type A require structural framing / elements to be 1-hr. rated, ext. walls are 2-hr rated. Ext. walls can be reduced to 1-hr. rated when supporting a roof only.",IF(O2="III-B","Exterior walls are of non-combustible material and interior walls can be made of non-combustible material. Type B require no fire rating of structural framing / elements.",IF(O2="IV-HT","Ext. walls are of non-combustible material and int. building elements are of solid wood, laminate wood, heavy timber or structural composite lumber. Ext. walls are required to be 2-hr. rated. Structural elements are to be with material listed above.",IF(O2="V-A","All exterior and interior walls made of combustible material. Type A require structural framing / elements to be 1-hr. rated.",IF(O2="V-B","All exterior and interior walls made of combustible material. Type B requires no rating of structural framing / elements.",IF(O14="IV-A","Ext. walls are of non-combustible material w/ min. rating of 40 min. and int. elements include mass timber walls and roof w/ min. 80 min. rating. See section 602.4.1 for all requirements.",IF(O14="IV-B","Ext. walls are of non-combustible material w/ min. rating of 40 min. and int. elements include mass timber walls and roof w/ min. 80 min. rating. See section 602.4.2 for all requirements.",IF(O14="IV-C","Ext. walls are of non-combustible material w/ min. rating of 40 min. and int. elements include mass timber walls and roof permitted to be unprotected. See section 602.4.3 for all requirements.","")))))))))))) -> All exterior and interior walls made of combustible material. Type B requires no rating of structural framing / elements. | T3: =IF(T2="NS","NS: Non Sprinkled",IF(T2="S1","S1: NFPA 13 Single Story Sprinkled",IF(T2="SM","SM: NFPA 13 Multi-Story Sprinkled",IF(T2="S13R","S13R: Residential Sprinkler System",IF(T2="S13D","S13D: Residential Sprinkler System",""))))) -> NS: Non Sprinkled
B4: OCCUPANCY 1 | D4: OCCUPANCY 2 | F4: Notes: | K4: =IF(OR(L5="NP",L5="NP W/ S13R",L5="NP / Use I-A or I-B Construction",L5="NP W/ S13D",L5="NP W/O S1 or SM Sprinklers",L5="NP W/ II-B, III-B, IV-HT, V-B Construction",L5="NP W/ II-B, III-B, IV-HT (OK Sprinkled), V-B Construction",L5="NP / Construction V-A Only",L5="NP W/ V-B Construction",L6="NP",L6="NP W/ S13R",L6="NP / Use I-A or I-B Construction",L6="NP W/ S13D",L6="NP W/O S1 or SM Sprinklers",L6="NP W/ II-B, III-B, IV-HT, V-B Construction",L6="NP W/ II-B, III-B, IV-HT (OK Sprinkled), V-B Construction",L6="NP / Construction V-A Only",L6="NP W/ V-B Construction"),"Note: NP = Not Permitted",IF(OR(L5="UL",L6="UL",L7="UL",),"Note: UL = Unlimited",""))
A5: Occupancy Classification: | B5: B | D5: E | F5: 1 | G5: Tubular per floor area limit per Table 506.2: | K5: =IF(B7="NS",'2021 area Table 506.2'!M34,IF(B7="S1",'2021 area Table 506.2'!AB34,IF(B7="SM",'2021 area Table 506.2'!AQ34,IF(B7="S13D",'2021 area Table 506.2'!BI34,IF(B7="S13R",'2021 area Table 506.2'!BX34,0))))) -> 9000 | L5: =IF(B7="NS",'2021 area Table 506.2'!N34,IF(B7="S1",'2021 area Table 506.2'!AC34,IF(B7="SM",'2021 area Table 506.2'!AR34,IF(B7="S13D",'2021 area Table 506.2'!BI34,IF(B7="S13R",'2021 area Table 506.2'!BX34,0))))) -> 9500
A6: Construction Type: | B6: V-B | G6: Group R and NFPA 13R/D: | K6: =IF(AND(B5="R-1",OR(B7="NS",B7="S13D")),"S13R Required",IF(AND(B5="R-2",OR(B7="NS",B7="S13D")),"S13R Required",IF(AND(B5="R-2.1",OR(B7="NS",B7="S13D")),"S13R Required",IF(AND(B5="R-2.2 (CA Only)",OR(B7="NS",B7="S13R",B7="S13D")),"S1 OR SM Required",IF(AND(B5="R-3/r-3.1",OR(B7="NS")),"S13D OR S13R Required",IF(AND(B5="R-4",OR(B7="NS",B7="S13D")),"S13D OR S13R Required",IF(AND(B5="i-1 Cond. 1",OR(B7="NS",B7="S13D")),"S13R or S1 or SM Required",IF(AND(B7="S13R",OR(B5="A-1",B5="A-2",B5="A-3",B5="A-4",B5="A-5",B5="B",B5="E",B5="F-1",B5="F-2",B5="H-1",B5="H-2",B5="H-3",B5="H-4",B5="H-5",B5="I-1 COND. 2",B5="I-2/I-2.1",B5="I-3",B5="I-4",B5="L",B5="M",B5="S-1",B5="S-2",B5="U")),"NP",IF(AND(B7="S13D",OR(B5="A-1",B5="A-2",B5="A-3",B5="A-4",B5="A-5",B5="B",B5="E",B5="F-1",B5="F-2",B5="H-1",B5="H-2",B5="H-3",B5="H-4",B5="H-5",B5="I-1 COND. 2",B5="I-2/I-2.1",B5="I-3",B5="I-4",B5="L",B5="M",B5="S-1",B5="S-2",B5="U")),"NP",IF(K5="NP W/ 13D","NP",IF(B7="S13R","Yes",IF(B7="S13D","Yes","None")))))))))))) -> None | L6: =IF(AND(D5="R-1",OR(B7="NS",B7="S13D")),"S13R Required",IF(AND(D5="R-2",OR(B7="NS",B7="S13D")),"S13R Required",IF(AND(D5="R-2.1",OR(B7="NS",B7="S13D")),"S13R Required",IF(AND(D5="R-2.2 (CA Only)",OR(B7="NS",B7="S13R",B7="S13D")),"S1 OR SM Required",IF(AND(D5="R-3/r-3.1",OR(B7="NS")),"S13D OR S13R Required",IF(AND(D5="R-4",OR(B7="NS",B7="S13D")),"S13D OR S13R Required",IF(AND(D5="i-1 Cond. 1",OR(B7="NS",B7="S13D")),"S13R or S1 or SM Required",IF(AND(B7="S13R",OR(D5="A-1",D5="A-2",D5="A-3",D5="A-4",D5="A-5",D5="B",D5="E",D5="F-1",D5="F-2",D5="H-1",D5="H-2",D5="H-3",D5="H-4",D5="H-5",D5="I-1 COND. 2",D5="I-2/I-2.1",D5="I-3",D5="I-4",D5="L",D5="M",D5="S-1",D5="S-2",D5="U")),"NP",IF(AND(B7="S13D",OR(D5="A-1",D5="A-2",D5="A-3",D5="A-4",D5="A-5",D5="B",D5="E",D5="F-1",D5="F-2",D5="H-1",D5="H-2",D5="H-3",D5="H-4",D5="H-5",D5="I-1 COND. 2",D5="I-2/I-2.1",D5="I-3",D5="I-4",D5="L",D5="M",D5="S-1",D5="S-2",D5="U")),"NP",IF(K5="NP W/ 13D","NP",IF(B7="S13R","Yes",IF(B7="S13D","Yes","None")))))))))))) -> None
