Workbook

Sheet C&C 7-22
E1: WIND LOADS - Components and Cladding
E2: (Part 1 - Low-Rise Buildings) | N2: Building Dimensions
E3: (ASCE 7-22 Applies to 2023 FL Code, 2021 VA Code & 2024 IBC) | N3: Width: | O3: Lenth:
M4: Building Dimensions= | N4: 24 | O4: 60 | AK4: Wind Area | AR4: Velocity Pressure Exposure (Kh or Kz)
C5: Conditions: | D5: - Simple Diaphragm | M5: Roof Type = | N5: Gable / Mono | AK5: =N4*0.1 -> 2.4 | AL5: =E16*0.4 -> 6 | AM5: <---Wind Zones 4 & 5 Endwalls | AS5: B | AT5: C | AU5: D
D6: - Low rise / Low slope building | AK6: =O4*0.1 -> 6 | AL6: =E16*0.4 -> 6 | AM6: <---Wind Zones 4 & 5 Sidewalls | AR6: 15 | AS6: 0.57 | AT6: 0.85 | AU6: 1.03
D7: - Regular Shaped | N7: Ht. to Peak | AK7: =MIN(N4,O4)*0.1 -> 2.4 | AL7: =E16*0.4 -> 6 | AM7: <---Wind Zones @ Roof | AR7: 20 | AS7: 0.62 | AT7: 0.9 | AU7: 1.08
D8: - Not Classified as Flexible | N8: =MAX(AK13,AK14) -> 15.25 | AK8: width | AL8: length | AR8: 25 | AS8: 0.66 | AT8: 0.94 | AU8: 1.12
D9: - Does not have special response characteristics | AR9: 30 | AS9: 0.7 | AT9: 0.98 | AU9: 1.16
D10: - Symetrical with roof slope less than 45 degrees | N10: Zone Dimensions (FT.) | AK10: =IF(E19<=7,(N4-(X14*2)),IF(AND(E19>7,E19<=45),(N4-(X14*4)),0)) -> 18 | AL10: =IF(E19<=7,(O4-(Y14*2)),IF(AND(E19>7,E19<=45),(O4-(Y14*2)),0)) -> 54 | AM10: <---Zone 2 | AR10: 40 | AS10: 0.74 | AT10: 1.04 | AU10: 1.22
D11: - Exempt from Torsional requirements | N11: Zone 4: | P11: Zone 5: | R11: Zone 1: | T11: Zone 1': | V11: Zone 2: | X11: Zone 3: | AK11: =IF(E19<=7,(N4-V13*2),IF(AND(E19>7,E19<=27),(N4-(V13*2)),IF(AND(E19>27,E19<=45),(N4-(V13*2)),0))) -> 6 | AL11: =IF(E19<=7,(O4-(V13*2)),IF(AND(E19>7,E19<=45),(O4-(Y13*4)),0)) -> 42 | AM11: <---Zone 1 | AR11: 50 | AS11: 0.79 | AT11: 1.09 | AU11: 1.27
D12: - Effective Wind Area figured at 10 sq. ft. | N12: Endwall: | O12: Sidewall: | P12: Endwall: | Q12: Sidewall: | R12: Endwall: | S12: Sidewall: | T12: Endwall: | U12: Sidewall: | V12: Endwall: | W12: =IF(AND(E17>7,E17<=27),"along centerline of roof","Sidewall:") -> along centerline of roof | X12: Endwall: | Y12: Sidewall: | AR12: 60 | AS12: 0.83 | AT12: 1.13 | AU12: 1.31
D13: Wind Speed, V = | E13: 130 | F13: mph | M13: Total Width (ft) each corner / side: | N13: - | O13: - | P13: =IF(MIN(AK5,AL5)<3,3,MIN(AK5,AL5)) -> 3 | Q13: =IF(MIN(AK6,AL6)<3,3,MIN(AK6,AL6)) -> 6 | R13: =IF(E19<=7,E17*0.6,"-") -> 9 | S13: =IF(E19<=7,E17*0.6,"-") -> 9 | T13: =IF(H30="Leave Out Zone 1'","N/A",IF(E19<=7,"-",IF(MIN(AJ6,AK6)<3,3,MIN(AJ6,AK6)))) -> N/A | U13: =IF(H30="Leave Out Zone 1'","N/A",IF(E19<=7,"-",IF(MIN(AJ5,AK5)<3,3,MIN(AJ5,AK5)))) -> N/A | V13: =IF(E19<=7,E17*0.6,IF(MIN(AJ6,AK6)<3,3,MIN(AJ6,AK6))) -> 9 | W13: =IF(V11="Zone 2n:","-",IF(E19<=7,E17*0.6,IF(MIN(AJ6,AK6)<3,3,MIN(AJ6,AK6)))) -> 9 | X13: =IF(X11="Zone 2r:","-",IF(E19<=7,E17*0.6,MIN(AJ5,AK5))) -> 9 | Y13: =IF(E19<=7,E17*0.6,IF(MIN(AJ5,AK5)<3,3,MIN(AJ5,AK5))) -> 9 | AK13: =IF(N5="transverse / complex",(E16+(E18*((O4/2)/12))),IF(N5="gable / mono",(E16+(E18*((N4/2)/12))),0)) -> 15.25 | AL13: <---Ht. w/o parapet | AR13: 70 | AS13: 0.86 | AT13: 1.17 | AU13: 1.34
D14: Wind Speed, V(asd) = | E14: =SUM(E13*SQRT(0.6)) -> 100.69757 | F14: mph | M14: Total Length (ft): | N14: =SUM(N4-P14*2) -> 18 | O14: =SUM(O4-Q14*2) -> 48 | P14: =IF(MIN(AK5,AL5)<3,3,MIN(AK5,AL5)) -> 3 | Q14: =IF(MIN(AK6,AL6)<3,3,MIN(AK6,AL6)) -> 6 | R14: =IF(AK11<=0,"N/A",IF(E19<=7,(N4-V13*2),IF(AND(E19>7,E19<=27),(N4-(V13*2)),IF(E19>27,N4,0)))) -> 6 | S14: =IF(AL11<=0,"N/A",IF(E19<=7,(O4-(V13*2)),IF(E19>7,(O4-(V13*2)),0))) -> 42 | T14: =IF(H30="Leave Out Zone 1'","N/A",IF(E19>7,E17*0.4,(N4-(R13+V13)))) -> N/A | U14: =IF(H30="Leave Out Zone 1'","N/A",IF(E19>7,(O4-(AA13*2)),(O4-(W13*4)))) -> N/A | V14: =IF(E19<=7,(N4),IF(E19>7,(N4-((Z14*2)+(AB14*2))),0)) -> 24 | W14: =IF(V11="Zone 2n:","-",IF(E18<=7,(O4),IF(AND(E18>7,E18<=45),(O4-(Y14*2)),0))) -> 60 | X14: =IF(X11="Zone 2r:","-",IF(E19<=7,E17*0.2,IF(MIN(AJ5,AK5)<3,3,MIN(AJ5,AK5)))) -> 3 | Y14: =IF(E19<=7,E17*0.2,IF(E19>7,(O4-(AC13*2)))) -> 3 | AK14: =E16+E20 -> 15 | AL14: <---Ht. w/ parapet | AR14: 80 | AS14: 0.9 | AT14: 1.21 | AU14: 1.38
D15: Wind Exposure, λ= | E15: C | P15: Each Corner | X15: Each Corner | AR15: 90 | AS15: 0.92 | AT15: 1.24 | AU15: 1.4
D16: Eave Height = | E16: 15 | F16: ft. (Max 57') | AR16: 100 | AS16: 0.95 | AT16: 1.26 | AU16: 1.43
D17: h = | E17: =IF(E20>0,E16+E20,IF(E19<=10,E16,IF(N5="transverse / complex",(E16+(E18*((O4/2)/12)/2)),IF(N5="gable / mono",(E16+(E18*((N4/2)/12)/2)),E16+E20)))) -> 15 | AR17: 120 | AS17: 1 | AT17: 1.31 | AU17: 1.48
D18: Enter Roof Slope (decimals) = | E18: 0.25 | F18: in 12 | AR18: 140 | AS18: 1.04 | AT18: 1.34 | AU18: 1.52
D19: Roof Slope (Degrees) = | E19: =ATAN(E18/12)*(180/PI()) -> 1.1934894 | AR19: 160 | AS19: 1.08 | AT19: 1.39 | AU19: 1.55
D20: Height of Parapet (ft.)= | E20: 0 | AR20: 180 | AS20: 1.11 | AT20: 1.41 | AU20: 1.58
D21: Topographic Factor (Kzt) = | E21: 1 | F21: (Avg) (Section 26.8.2) | AR21: 200 | AS21: 1.14 | AT21: 1.44 | AU21: 1.61
D22: Wind Directionanlity Factor (Kd)= | E22: 0.85 | F22: (Table 26.6-1) | AR22: 250 | AS22: 1.21 | AT22: 1.51 | AU22: 1.68
D23: Ground Elevation (Ke)= | E23: =IF(F23=0,1,IF(F23=1000,0.96,IF(F23=2000,0.93,IF(F23=3000,0.9,IF(F23=4000,0.86,IF(F23=5000,0.83,IF(F23=6000,0.8,IF(F23=7000,0.78,IF(F23=8000,0.75,IF(F23=9000,0.72)))))))))) -> 1 | F23: 0 | G23: (Table 26.9-1) | AR23: 300 | AS23: 1.27 | AT23: 1.57 | AU23: 1.73
D24: Internal Pressure Coefficient (GCpi)= | E24: =IF(F24="(enclosed)",-0.18,IF(F24="(Patially Enclosed)",-0.55,IF(F24="(open)",0,IF(F24="(Partially Open)",-0.18,0)))) -> -0.18 | F24: (Enclosed) | G24: (Table 26.13-1) | AR24: 350 | AS24: 1.33 | AT24: 1.62 | AU24: 1.78
D25: Internal Pressure Coefficient (GCpi)= | E25: =IF(F24="(enclosed)",0.18,IF(F24="(Patially Enclosed)",0.55,IF(F24="(open)",0,IF(F24="(Partially Open)",0.18,0)))) -> 0.18 | AR25: 400 | AS25: 1.38 | AT25: 1.66 | AU25: 1.82
D26: Velocity Pressure Exposure (Kh / Kz)= | E26: =IF(E17<=15,INDEX(AS6:AU6,MATCH(E15,AS5:AU5,0)),IF(AND(E17>15,E17<=20),INDEX(AS7:AU7,MATCH(E15,AS5:AU5,0)),IF(AND(E17>20,E17<=25),INDEX(AS8:AU8,MATCH(E15,AS5:AU5,0)),IF(AND(E17>25,E17<=30),INDEX(AS9:AU9,MATCH(E15,AS5:AU5,0)),IF(AND(E17>30,E17<=40),INDEX(AS10:AU10,MATCH(E15,AS5:AU5,0)),IF(AND(E17>40,E17<=50),INDEX(AS11:AU11,MATCH(E15,AS5:AU5,0)),IF(AND(E17>50,E17<=60),INDEX(AS12:AU12,MATCH(E15,AS5:AU5,0)),IF(AND(E17>60,E17<=70),INDEX(AS13:AU13,MATCH(E15,AS5:AU5,0)),IF(AND(E17>70,E17<=80),INDEX(AS14:AU14,MATCH(E15,AS5:AU5,0)),IF(AND(E17>80,E17<=90),INDEX(AS15:AU15,MATCH(E15,AS5:AU5,0)),IF(AND(E17>90,E17<=100),INDEX(AS16:AU16,MATCH(E15,AS5:AU5,0)),IF(AND(E17>100,E17<=120),INDEX(AS17:AU17,MATCH(E15,AS5:AU5,0)),IF(AND(E17>120,E17<=140),INDEX(AS18:AU18,MATCH(E15,AS5:AU5,0)),IF(AND(E17>140,E17<=160),INDEX(AS19:AU19,MATCH(E15,AS5:AU5,0)),IF(AND(E17>160,E17<=180),INDEX(AS20:AU20,MATCH(E15,AS5:AU5,0)),IF(AND(E17>180,E17<=200),INDEX(AS21:AU21,MATCH(E15,AS5:AU5,0)),IF(AND(E17>200,E17<=250),INDEX(AS22:AU22,MATCH(E15,AS5:AU5,0)),IF(AND(E17>250,E17<=300),INDEX(AS23:AU23,MATCH(E15,AS5:AU5,0)),IF(AND(E17>300,E17<=350),INDEX(AS24:AU24,MATCH(E15,AS5:AU5,0)),IF(AND(E17>350,E17<=400),INDEX(AS25:AU25,MATCH(E15,AS5:AU5,0)),IF(AND(E17>400,E17<=450),INDEX(AS26:AU26,MATCH(E15,AS5:AU5,0)),IF(AND(E17>450,E17<=500),INDEX(AS27:AU27,MATCH(E15,AS5:AU5,0)),0)))))))))))))))))))))) -> 0.85 | F26: (Table 26.10-1) | AR26: 450 | AS26: 1.42 | AT26: 1.7 | AU26: 1.86
D27: Velocity Pressure (Qh / Qz)= | E27: =(0.00256*E26*E21*E23*(E13^2)) -> 36.7744 | F27: psf (0.00256KzKztKeV^2) | AR27: 500 | AS27: 1.46 | AT27: 1.74 | AU27: 1.89
A28: p=qhKd[(GCp)-(GCpi)] - (Section 30.3.2)
A29: Design Pressure (p)
A30: Pult (Ultimate Design Pressure) | B30: Zone 4: | D30: Zone 5: | F30: Zone 1: | H30: =IF(AND(E19<=7,((E17*0.6)*4)>=N4),"Leave Out Zone 1'",IF(E19<=7,"Zone 1':",0)) -> Leave Out Zone 1'
B31: =IF(E20>0,"Windward","Postive") -> Postive | C31: =IF(E20>0,"Leeward","Negative") -> Negative | D31: =IF(E20>0,"Windward","Postive") -> Postive | E31: =IF(E20>0,"Leeward","Negative") -> Negative | F31: Postive | G31: Negative | H31: =IF(H30="leave out zone 1'","","Postive") | I31: =IF(H30="leave out zone 1'","","Negative") | AR31: Alerternate Kz Formula (See Table 26.10-1) | AS31: =IF(AND(E15="B",E16<15),(2.41*(15/3280)^(2/7.5)),IF(AND(E15="B",E16>=15),(2.41*(E17/3280)^(2/7.5)),IF(E15="C",(2.41*(E17/2460)^(2/9.8)),IF(E15="D",(2.41*(E17/1935)^(2/11.5)),0)))) -> 0.8511539
B32: =IF(E19<=10,E27*E22*((1*0.9)-E24),IF(E19>10,E27*E22*(1-E24),0)) -> 33.758899 | C32: =IF(E19<=10,E27*E22*(((-1.1*0.9)*0.9)-E25),IF(E19>10,E27*E22*((-1.1)-E25),0)) -> -33.477575 | D32: =IF(E19<=10,E27*E22*((1*0.9)-E24),IF(E19>10,E27*E22*(1-E24),0)) -> 33.758899 | E32: =IF(E19<=10,E27*E22*((-1.4*0.9)-E25),IF(E19>10,E27*E22*((-1.4)-E25),0)) -> -45.011866 | F32: =IF(E19<=7,E27*E22*((0.3)-E24),IF(AND(E19>7,E19<=20),E27*E22*((0.6)-E24),IF(AND(E19>20,E19<=27),E27*E22*((0.6)-E24),IF(AND(E19>27,E19<=45),E27*E22*((0.9)-E24),0)))) -> 15.003955 | G32: =IF(E19<=7,E27*E22*((-1.7)-E25),IF(AND(E19>7,E19<=20),E27*E22*((-2)-E25),IF(AND(E19>20,E19<=27),E27*E22*((-1.5)-E25),IF(AND(E19>27,E19<=45),E27*E22*((-1.8)-E25),0)))) -> -58.765491 | H32: =IF(H30="leave out zone 1'","",IF(E19<=7,E27*((0.3)-E24),IF(AND(E19>7,E19<=20),E27*((0.5)-E24),IF(AND(E19>20,E19<=27),E27*((0.5)-E24),IF(AND(E19>27,E19<=45),E27*((0.9)-E24),0))))) | I32: =IF(H30="leave out zone 1'","",IF(E19<=7,E27*((-0.9)-E25),IF(AND(E19>7,E19<=20),E27*((-1.5)-E25),IF(AND(E19>20,E19<=27),E27*((-1.5)-E25),IF(AND(E19>27,E19<=45),E27*((-1.8)-E25),0)))))
AR33: Alternate Formula Table 26.9-1
B34: Zone 2: | D34: Zone 3: | AR34: Ground Elevation: | AS34: 6000
B35: =IF(E20>0,"Windward","Postive") -> Postive | C35: =IF(E20>0,"Leeward","Negative") -> Negative | D35: =IF(E20>0,"Windward","Postive") -> Postive | E35: =IF(E20>0,"Leeward","Negative") -> Negative | AS35: =(2.71828^(-0.0000362*AS34)) -> 0.80476912 | AT35: Ke=e^0.0000362Kg (Kg=Elevation)
B36: =IF(AND(E19<=7,E20>=3),E27*E22*((1)-E24),IF(E19<=7,E27*E22*((0.3)-E24),IF(AND(E19>7,E19<=20),E27*E22*((0.6)-E24),IF(AND(E19>20,E19<=27),E27*E22*((0.6)-E24),IF(AND(E19>27,E19<=45),E27*E22*((0.9)-E24),0))))) -> 15.003955 | C36: =IF(E19<=7,E27*E22*((-2.3)-E25),IF(AND(E19>7,E19<=20),E27*E22*((-2.7)-E25),IF(AND(E19>20,E19<=27),E27*E22*((-2.5)-E25),IF(AND(E19>27,E19<=45),E27*E22*((-2)-E25),0)))) -> -77.520435 | D36: =IF(AND(E19<=7,E20>=3),E27*E22*((1)-E24),IF(E19<=7,E27*E22*((0.3)-E24),IF(AND(E19>7,E19<=20),E27*E22*((0.6)-E24),IF(AND(E19>20,E19<=27),E27*E22*((0.6)-E24),IF(AND(E19>27,E19<=45),E27*E22*((0.9)-E24),0))))) -> 15.003955 | E36: =IF(AND(E19<=7,E20>=3),E27*E22*((-2.3)-E25),IF(E19<=7,E27*E22*((-3.2)-E25),IF(AND(E19>7,E19<=20),E27*E22*((-3.6)-E25),IF(AND(E19>20,E19<=27),E27*E22*((-3)-E25),IF(AND(E19>27,E19<=45),E27*E22*((-2.5)-E25),0))))) -> -105.65285 | AT36: (e=Euler's number - 2.71828)
A38: Pasd (Allowable Stress Design) | B38: =B30 -> Zone 4: | D38: =D30 -> Zone 5: | F38: =F30 -> Zone 1: | H38: =H30 -> Leave Out Zone 1'
B39: Postive | C39: Negative | D39: Postive | E39: Negative | F39: Postive | G39: Negative | H39: =IF(H38="leave out zone 1'","","Postive") | I39: =IF(H38="leave out zone 1'","","Negative")
B40: =(B32*0.6) -> 20.25534 | C40: =(C32*0.6) -> -20.086545 | D40: =(D32*0.6) -> 20.25534 | E40: =(E32*0.6) -> -27.007119 | F40: =(F32*0.6) -> 9.0023731 | G40: =(G32*0.6) -> -35.259295 | H40: =IF(H32="","",H32*0.6) | I40: =IF(I32="","",I32*0.6)
K41: Slope: 0 to 7 Degrees | O41: Slope: 7 to 27 Degrees | S41: Slope: 27 to 45 Degrees
...

Sheet C&C 7-16 Simplified
E1: WIND LOADS - Components and Cladding | K1: Wind Speed Conversion
E2: (PART 2 - SIMPLIFIED METHOD) | L2: Wind Speed V = | M2: 160 | N2: mph | AN2: Wind Speed, V = | AO2: =E13 -> 130 | AP2: mph
E3: (ASCE 7-16 Applies to 2018 IBC & 2021 IBC) | L3: Wind Speed V(asd) = | M3: =SUM(M2*SQRT(0.6)) -> 123.93547 | N3: mph | AN3: Wind Speed, V(asd) = | AO3: =SUM(AO2*SQRT(0.6)) -> 100.69757 | AP3: mph
AF4: Wind Area | AN4: Wind Exposure, λ= | AO4: =E14 -> C
C5: Conditions: | D5: - Simple Diaphragm | M5: Building Dimensions | AF5: =M7*0.1 -> 3.6 | AG5: =E16*0.4 -> 8.4 | AH5: <---Wind Zones 4 & 5 Endwalls | AN5: Eave Height = | AO5: =E16 -> 21 | AP5: ft.
D6: - Low rise / Low slope building | M6: Width: | N6: Lenth: | AF6: =N7*0.1 -> 6 | AG6: =E16*0.4 -> 8.4 | AH6: <---Wind Zones 4 & 5 Sidewalls | AN6: Enter Roof Slope (decimals) = | AO6: =E17 -> 0.25 | AP6: in 12
D7: - Regular Shaped | L7: Building Dimensions= | M7: 36 | N7: 60 | AF7: =MIN(M7,N7)*0.1 -> 3.6 | AG7: =E16*0.4 -> 8.4 | AH7: <---Wind Zones @ Roof | AN7: Roof Slope (Degrees) = | AO7: =E18 -> 1.1934894
D8: - Not Classified as Flexible | L8: Roof Type = | M8: Transverse / Complex | AF8: width | AG8: length | AN8: Height of Parapet (ft.)= | AO8: 0
D9: - Does not have special response characteristics | AN9: Topographic Factor (Kzt) = | AO9: 1 | AP9: (Avg)
D10: - Symetrical with roof slope less than 45 degrees | M10: Ht. to Peak | AF10: =IF(E18<=7,(M7-(X17*2)),IF(E18>7,(M7-(X17*4)),0)) -> 27.6 | AG10: =IF(E18<=7,(N7-(X16*2)),IF(AND(E18>7,E18<=45),(N7-(X16*2)),0)) -> 34.8 | AH10: <---Zone 2 | AN10: Wind Directionanlity Factor (Kd)= | AO10: 0.85
D11: - Exempt from Torsional requirements | M11: =MAX(AF13,AF14) -> 21.625 | AF11: =IF(E18<=7,(M7-U16*2),IF(AND(E18>7,E18<=27),(M7-(U16*2)),IF(AND(E18>27,E18<=45),(M7-(U16*4))*0))) -> 10.8 | AG11: =IF(E18<=7,(N7-(U16*2)),IF(AND(E18>7,E18<=45),(N7-(X16*4)),0)) -> 34.8 | AH11: <---Zone 1 | AN11: Ground Elevation (Ke)= | AO11: =IF(AP11=0,1,IF(AP11=1000,0.96,IF(AP11=2000,0.93,IF(AP11=3000,0.9,IF(AP11=4000,0.86,IF(AP11=5000,0.83,IF(AP11=6000,0.8,0))))))) -> 1 | AP11: 0
D12: - Effective Wind Area figured at 10 sq. ft. | AN12: Internal Pressure Coefficient (GCpi)= | AO12: =IF(AP12="(enclosed)",-0.18,IF(AP12="(Partially Enclosed)",-0.55,IF(AP12="(open)",0,IF(AP12="(Partially Open)",-0.18,0)))) -> -0.18 | AP12: (Enclosed)
D13: Wind Speed, V = | E13: 130 | F13: mph | M13: Zone Dimensions (FT.) | AF13: =IF(M8="transverse / complex",(E15+(E17*((N7/2)/12))),IF(M8="gable / mono",(E15+(E17*((M7/2)/12))),0)) -> 21.625 | AG13: <---Ht. w/o parapet | AN13: Internal Pressure Coefficient (GCpi)= | AO13: =IF(AP12="(enclosed)",0.18,IF(AP12="(Partially Enclosed)",0.55,IF(AP12="(open)",0,IF(AP12="(Partially Open)",0.18,0)))) -> 0.18
D14: Wind Exposure, λ= | E14: C | M14: Zone 4: | O14: Zone 5: | Q14: Zone 1: | S14: =IF(E18>7,"Zone 2e:","Zone 1':") -> Zone 1': | U14: =IF(E18>7,"Zone 2n:","Zone 2:") -> Zone 2: | W14: =IF(E18>7,"Zone 2r:","Zone 3:") -> Zone 3: | Y14: =IF(E18>7,"Zone 3e:","") | AA14: =IF(E18>7,"Zone 3r:","") | AF14: =E15+E19 -> 21 | AG14: <---Ht. w/ parapet | AN14: Building Height and Exposure (λ=) | AO14: =IF(AND(AO4="B",AO5<=15),"0.82",IF(AND(AO4="B",AO5=20),"0.89",IF(AND(AO4="B",AO5=25),"0.94",IF(AND(AO4="B",AO5=30),"1",IF(AND(AO4="B",AO5=35),"1.05",IF(AND(AO4="B",AO5=40),"1.09",IF(AND(AO4="B",AO5=45),"1.12",IF(AND(AO4="B",AO5=50),"1.16",IF(AND(AO4="B",AO5=55),"1.19",IF(AND(AO4="B",AO5=60),"1.22",IF(AND(AO4="C",AO5<=15),"1.21",IF(AND(AO4="C",AO5=20),"1.29",IF(AND(AO4="C",AO5=25),"1.35",IF(AND(AO4="C",AO5=30),"1.4",IF(AND(AO4="C",AO5=35),"1.45",IF(AND(AO4="C",AO5=40),"1.49",IF(AND(AO4="C",AO5=45),"1.53",IF(AND(AO4="C",AO5=50),"1.56",IF(AND(AO4="C",AO5=55),"1.59",IF(AND(AO4="C",AO5=60),"1.62",IF(AND(AO4="D",AO5<=15),"1.47",IF(AND(AO4="D",AO5=20),"1.55",IF(AND(AO4="D",AO5=25),"1.61",IF(AND(AO4="D",AO5=30),"1.66",IF(AND(AO4="D",AO5=35),"1.7",IF(AND(AO4="D",AO5=40),"1.74",IF(AND(AO4="D",AO5=45),"1.78",IF(AND(AO4="D",AO5=50),"1.81",IF(AND(AO4="D",AO5=55),"1.84",IF(AND(AO4="D",AO5=60),"1.87",0)))))))))))))))))))))))))))))) -> 0
D15: Eave Height from grade= | E15: 21 | F15: ft. (Max 30') | M15: Endwall: | N15: Sidewall: | O15: Endwall: | P15: Sidewall: | Q15: Endwall: | R15: Sidewall: | S15: Endwall: | T15: Sidewall: | U15: Endwall: | V15: Sidewall: | W15: Endwall: | X15: =IF(W14="Zone 2r:","Peak","Sidewall:") -> Sidewall: | Y15: =IF(E18>7,"Endwall","") | Z15: =IF(E18>7,"Sidewall","") | AA15: =IF(E18>7,"Endwall","") | AB15: =IF(E18>7,"Sidewall","") | AN15: Velocity Pressure Exposure (Kz)= | AO15: =IF(AND(AO4="B",AO5<30),(2.01*((30+AO8)/1200)^(2/7)),IF(AND(AO4="B",AO5>=30),(2.01*((AO5+AO8)/1200)^(2/7)),IF(AO4="C",(2.01*((AO5+AO8)/900)^(2/9.5)),IF(AO4="D",(2.01*((AO5+AO8)/700)^(2/11.5)),0)))) -> 0.91119688
D16: h = | E16: =IF(E19>0,E15+E19,IF(E18<=10,E15,IF(M8="transverse / complex",(E15+(E17*((N7/2)/12)/2)),IF(M8="gable / mono",(E15+(E17*((M7/2)/12)/2)),E15+E19)))) -> 21 | L16: Total Width (ft) each corner / side: | M16: - | N16: - | O16: =IF(MIN(AF5,AG5)<3,3,MIN(AF5,AG5)) -> 3.6 | P16: =IF(MIN(AF6,AG6)<3,3,MIN(AF6,AG6)) -> 6 | Q16: =IF(E18<=7,E16*0.6,"-") -> 12.6 | R16: =IF(E18<=7,E16*0.6,"-") -> 12.6 | S16: =IF(H26="Leave Out Zone 1'","N/A",IF(E18<=7,"-",IF(S14="Zone 2e:","-",IF(MIN(AF6,AG6)<3,3,MIN(AF6,AG6))))) -> N/A | T16: =IF(H26="Leave Out Zone 1'","N/A",IF(E18<=7,"-",IF(MIN(AF5,AG5)<3,3,MIN(AF5,AG5)))) -> N/A | U16: =IF(E18<=7,E16*0.6,IF(MIN(AF6,AG6)<3,3,MIN(AF6,AG6))) -> 12.6 | V16: =IF(U14="Zone 2n:","-",IF(E18<=7,E16*0.6,IF(MIN(AF6,AG6)<3,3,MIN(AF6,AG6)))) -> 12.6 | W16: =IF(W14="Zone 2r:","-",IF(E18<=7,E16*0.6,MIN(AF5,AG5))) -> 12.6 | X16: =IF(E18<=7,E16*0.6,IF(MIN(AF5,AG5)<3,3,MIN(AF5,AG5))) -> 12.6 | Y16: =IF(E18<=7,"",IF(MIN(AF5,AG5)<3,3,MIN(AF5,AG5))) | Z16: =IF(E18<=7,"",IF(MIN(AF6,AG6)<3,3,MIN(AF6,AG6))) | AA16: =IF(E18<=7,"",IF(MIN(AF5,AG5)<3,3,MIN(AF5,AG5))) | AB16: =IF(E18<=7,"",IF(MIN(AF6,AG6)<3,3,MIN(AF6,AG6))) | AN16: Velocity Pressure (Qh)= | AO16: =(0.6*0.00256*AO15*AO9*AO10*AO11*(AO2^2)) -> 20.105231 | AP16: psf
D17: Enter Roof Slope (decimals) = | E17: 0.25 | F17: in 12 | L17: Total Length (ft): | M17: =SUM(M7-O17*2) -> 28.8 | N17: =SUM(N7-P17*2) -> 48 | O17: =IF(MIN(AF5,AG5)<3,3,MIN(AF5,AG5)) -> 3.6 | P17: =IF(MIN(AF6,AG6)<3,3,MIN(AF6,AG6)) -> 6 | Q17: =IF(AF11<=0,"N/A",IF(E18<=7,(M7-U16*2),IF(E18>7,(M7-((T16*2)+(X16*2)))))) -> 10.8 | R17: =IF(AG11<=0,"N/A",IF(E18<=7,(N7-(U16*2)),IF(E18>7,(N7-(U16*4)),0))) -> 34.8 | S17: =IF(H26="Leave Out Zone 1'","N/A",IF(S14="Zone 2e:","-",IF(E19>7,E17*0.4,(M7-(Q16+U16))))) -> N/A | T17: =IF(H26="Leave Out Zone 1'","N/A",IF(E18>7,(N7-(Z16*2)),(N7-(V16*4)))) -> N/A | U17: =IF(E18<=7,(M7),IF(E18>7,(M7-((Y17*2)+(AA17*2))),0)) -> 36 | V17: =IF(U14="Zone 2n:","-",IF(E18<=7,(N7),IF(AND(E18>7,E18<=45),(N7-(X17*2)),0))) -> 60 | W17: =IF(W14="Zone 2r:","-",IF(E18<=7,E16*0.2,IF(MIN(AF5,AG5)<3,3,MIN(AF5,AG5)))) -> 4.2 | X17: =IF(E18<=7,E16*0.2,IF(E18>7,(N7-(AB16*2)))) -> 4.2 | Y17: =IF(E18<=7,"",IF(MIN(AF5,AG5)<3,3,MIN(AF5,AG5))) | Z17: =IF(E18<=7,"",IF(MIN(AF6,AG6)<3,3,MIN(AF6,AG6))) | AA17: =IF(E18<=7,"",IF(MIN(AF5,AG5)<3,3,MIN(AF5,AG5))) | AB17: =IF(E18<=7,"",IF(MIN(AF6,AG6)<3,3,MIN(AF6,AG6)))
D18: Roof Slope (Degrees) = | E18: =ATAN(E17/12)*(180/PI()) -> 1.1934894 | F18: (Degrees) | O18: Each Corner | W18: =IF(W14="Zone 3:","Each Corner","") -> Each Corner | Y18: =IF(E18>7,"Each Corner","") | AM18: Window 1 | AP18: Window 2 | AS18: Window 3 | AV18: Window 4 | AY18: Window 5
D19: Height of Parapet (ft.)= | E19: 0 | AL19: Pos. Zone 4 | AM19: =(1-0.3*(LOG(E71)-LOG(10))/(LOG(500)-LOG(10))) -> #NUM! | AN19: =IF(E18<=10,AM19*0.9,AM19) -> #NUM! | AO19: =AN19-(AO12) -> #NUM! | AP19: =(1-0.3*(LOG(E72)-LOG(10))/(LOG(500)-LOG(10))) -> #NUM! | AQ19: =IF(E18<=10,AP19*0.9,AP19) -> #NUM! | AR19: =AQ19-(AO12) -> #NUM! | AS19: =(1-0.3*(LOG(E73)-LOG(10))/(LOG(500)-LOG(10))) -> #NUM! | AT19: =IF(E18<=10,AS19*0.9,AS19) -> #NUM! | AU19: =AT19-(AO12) -> #NUM! | AV19: =(1-0.3*(LOG(E74)-LOG(10))/(LOG(500)-LOG(10))) -> #NUM! | AW19: =IF(E18<=10,AV19*0.9,AV19) -> #NUM! | AX19: =AW19-(AO12) -> #NUM! | AY19: =(1-0.3*(LOG(E75)-LOG(10))/(LOG(500)-LOG(10))) -> #NUM! | AZ19: =IF(E18<=10,AY19*0.9,AY19) -> #NUM! | BA19: =AZ19-(AO12) -> #NUM!
D20: Overhang: | E20: No | AL20: Pos. Zone 5 | AM20: =(1-0.3*(LOG(E71)-LOG(10))/(LOG(500)-LOG(10))) -> #NUM! | AN20: =IF(E18<=10,AM20*0.9,AM20) -> #NUM! | AO20: =AN20-(AO12) -> #NUM! | AP20: =(1-0.3*(LOG(E72)-LOG(10))/(LOG(500)-LOG(10))) -> #NUM! | AQ20: =IF(E18<=10,AP20*0.9,AP20) -> #NUM! | AR20: =AQ20-(AO12) -> #NUM! | AS20: =(1-0.3*(LOG(E73)-LOG(10))/(LOG(500)-LOG(10))) -> #NUM! | AT20: =IF(E18<=10,AS20*0.9,AS20) -> #NUM! | AU20: =AT20-(AO12) -> #NUM! | AV20: =(1-0.3*(LOG(E74)-LOG(10))/(LOG(500)-LOG(10))) -> #NUM! | AW20: =IF(E18<=10,AV20*0.9,AV20) -> #NUM! | AX20: =AW20-(AO12) -> #NUM! | AY20: =(1-0.3*(LOG(E75)-LOG(10))/(LOG(500)-LOG(10))) -> #NUM! | AZ20: =IF(E18<=10,AY20*0.9,AY20) -> #NUM! | BA20: =AZ20-(AO12) -> #NUM!
D21: Topographic Factor (Kzt) = | E21: 1 | F21: (Avg) | AL21: Neg. Zone 4 | AM21: =-(1.1-0.3*(LOG(E71)-LOG(10))/(LOG(500)-LOG(10))) -> #NUM! | AN21: =IF(E18<=10,AM21*0.9,AM21) -> #NUM! | AO21: =AN21-(AO13) -> #NUM! | AP21: =-(1.1-0.3*(LOG(E72)-LOG(10))/(LOG(500)-LOG(10))) -> #NUM! | AQ21: =IF(E18<=10,AP21*0.9,AP21) -> #NUM! | AR21: =AQ21-(AO13) -> #NUM! | AS21: =-(1.1-0.3*(LOG(E73)-LOG(10))/(LOG(500)-LOG(10))) -> #NUM! | AT21: =IF(E18<=10,AS21*0.9,AS21) -> #NUM! | AU21: =AT21-(AO13) -> #NUM! | AV21: =-(1.1-0.3*(LOG(E74)-LOG(10))/(LOG(500)-LOG(10))) -> #NUM! | AW21: =IF(E18<=10,AV21*0.9,AV21) -> #NUM! | AX21: =AW21-(AO13) -> #NUM! | AY21: =-(1.1-0.3*(LOG(E75)-LOG(10))/(LOG(500)-LOG(10))) -> #NUM! | AZ21: =IF(E18<=10,AY21*0.9,AY21) -> #NUM! | BA21: =AZ21-(AO13) -> #NUM!
D22: Internal Pressure Coefficient (GCpi) | E22: +/- 0.18 | F22: (Enclosed or partially open) | AL22: Neg. Zone 5 | AM22: =-(1.4-0.6*(LOG(E71)-LOG(10))/(LOG(500)-LOG(10))) -> #NUM! | AN22: =IF(E18<=10,AM22*0.9,AM22) -> #NUM! | AO22: =AN22-(AO13) -> #NUM! | AP22: =-(1.4-0.6*(LOG(E72)-LOG(10))/(LOG(500)-LOG(10))) -> #NUM! | AQ22: =IF(E18<=10,AP22*0.9,AP22) -> #NUM! | AR22: =AQ22-(AO13) -> #NUM! | AS22: =-(1.4-0.6*(LOG(E73)-LOG(10))/(LOG(500)-LOG(10))) -> #NUM! | AT22: =IF(E18<=10,AS22*0.9,AS22) -> #NUM! | AU22: =AT22-(AO13) -> #NUM! | AV22: =-(1.4-0.6*(LOG(E74)-LOG(10))/(LOG(500)-LOG(10))) -> #NUM! | AW22: =IF(E18<=10,AV22*0.9,AV22) -> #NUM! | AX22: =AW22-(AO13) -> #NUM! | AY22: =-(1.4-0.6*(LOG(E75)-LOG(10))/(LOG(500)-LOG(10))) -> #NUM! | AZ22: =IF(E18<=10,AY22*0.9,AY22) -> #NUM! | BA22: =AZ22-(AO13) -> #NUM!
D23: Building Height and Exposure (λ=) | E23: =IF(AND(E14="B",E16<=15),"0.82",IF(AND(AND(E14="B"),E16>15,E16<=20),"0.89",IF(AND(AND(E14="B"),E16>20,E16<=25),"0.94",IF(AND(AND(E14="B"),E16>25,E16<=30),"1",IF(AND(AND(E14="B"),E16>30,E16<=35),"1.05",IF(AND(AND(E14="B"),E16>35,E16<=40),"1.09",IF(AND(AND(E14="B"),E16>40,E16<=45),"1.12",IF(AND(AND(E14="B"),E16>45,E16<=50),"1.16",IF(AND(AND(E14="B"),E16>50,E16<=55),"1.19",IF(AND(AND(E14="B"),E16>55,E16<=60),"1.22",IF(AND(E14="C",E15<=15),"1.21",IF(AND(AND(E14="C"),E16>15,E16<=20),"1.29",IF(AND(AND(E14="C"),E16>20,E16<=25),"1.35",IF(AND(AND(E14="C"),E16>25,E16<=30),"1.4",IF(AND(AND(E14="C"),E16>30,E16<=35),"1.45",IF(AND(AND(E14="C"),E16>35,E16<=40),"1.49",IF(AND(AND(E14="C"),E16>40,E16<=45),"1.53",IF(AND(AND(E14="C"),E16>45,E16<=50),"1.56",IF(AND(AND(E14="C"),E16>50,E16<=55),"1.59",IF(AND(AND(E14="C"),E16>55,E16<=60),"1.62",IF(AND(E14="D",E15<=15),"1.47",IF(AND(AND(E14="D"),E16>15,E16<=20),"1.55",IF(AND(AND(E14="D"),E16>20,E16<=25),"1.61",IF(AND(AND(E14="D"),E16>25,E16<=30),"1.66",IF(AND(AND(E14="D"),E16>30,E16<=35),"1.7",IF(AND(AND(E14="D"),E16>35,E16<=40),"1.74",IF(AND(AND(E14="D"),E16>40,E16<=45),"1.78",IF(AND(AND(E14="D"),E16>45,E16<=50),"1.81",IF(AND(AND(E14="D"),E16>50,E16<=55),"1.84",IF(AND(AND(E14="D"),E16>55,E16<=60),"1.87",0)))))))))))))))))))))))))))))) -> 1.35 | AM23: Door 1 | AP23: Door 2 | AS23: Door 3
A24: pnet=λKztIPnet30 - (Section 30.4.2) | AL24: Pos. Zone 4 | AM24: =(1-0.3*(LOG(E81)-LOG(10))/(LOG(500)-LOG(10))) -> #NUM! | AN24: =IF(E18<=10,AM24*0.9,AM24) -> #NUM! | AO24: =AN24-(AO12) -> #NUM! | AP24: =(1-0.3*(LOG(F82)-LOG(10))/(LOG(500)-LOG(10))) -> #VALUE! | AQ24: =IF(E18<=10,AP24*0.9,AP24) -> #VALUE! | AR24: =AQ24-(AO12) -> #VALUE! | AS24: =(1-0.3*(LOG(F83)-LOG(10))/(LOG(500)-LOG(10))) -> 1.0702673 | AT24: =IF(E18<=10,AS24*0.9,AS24) -> 0.96324055 | AU24: =AT24-(AO12) -> 1.1432406
A25: Design Pressure (p) | AL25: Pos. Zone 5 | AM25: =(1-0.3*(LOG(E81)-LOG(10))/(LOG(500)-LOG(10))) -> #NUM! | AN25: =IF(E18<=10,AM25*0.9,AM25) -> #NUM! | AO25: =AN25-(AO12) -> #NUM! | AP25: =(1-0.3*(LOG(F82)-LOG(10))/(LOG(500)-LOG(10))) -> #VALUE! | AQ25: =IF(E18<=10,AP25*0.9,AP25) -> #VALUE! | AR25: =AQ25-(AO12) -> #VALUE! | AS25: =(1-0.3*(LOG(F83)-LOG(10))/(LOG(500)-LOG(10))) -> 1.0702673 | AT25: =IF(E18<=10,AS25*0.9,AS25) -> 0.96324055 | AU25: =AT25-(AO12) -> 1.1432406
A26: Pult (Ultimate Design Pressure) | B26: Zone 4: | D26: Zone 5: | F26: Zone 1: | H26: =IF(AND(E18<=7,((E15*0.6)*4)>=M7),"Leave Out Zone 1'",IF(E18<=7,"Zone 1':",IF(AND(E18>7,E18<=45),"Zone 2e:",0))) -> Leave Out Zone 1' | AL26: Neg. Zone 4 | AM26: =-(1.1-0.3*(LOG(E81)-LOG(10))/(LOG(500)-LOG(10))) -> #NUM! | AN26: =IF(E18<=10,AM26*0.9,AM26) -> #NUM! | AO26: =AN26-(AO13) -> #NUM! | AP26: =-(1.1-0.3*(LOG(F82)-LOG(10))/(LOG(500)-LOG(10))) -> #VALUE! | AQ26: =IF(E18<=10,AP26*0.9,AP26) -> #VALUE! | AR26: =AQ26-(AO13) -> #VALUE! | AS26: =-(1.1-0.3*(LOG(F83)-LOG(10))/(LOG(500)-LOG(10))) -> -1.1702673 | AT26: =IF(E18<=10,AS26*0.9,AS26) -> -1.0532406 | AU26: =AT26-(AO13) -> -1.2332406
B27: Postive | C27: Negative | D27: Postive | E27: Negative | F27: Postive | G27: Negative | H27: =IF(H26="leave out zone 1'","","Postive") | I27: =IF(H26="leave out zone 1'","","Negative") | AL27: Neg. Zone 5 | AM27: =-(1.4-0.6*(LOG(E81)-LOG(10))/(LOG(500)-LOG(10))) -> #NUM! | AN27: =IF(E18<=10,AM27*0.9,AM27) -> #NUM! | AO27: =AN27-(AO13) -> #NUM! | AP27: =-(1.4-0.6*(LOG(F82)-LOG(10))/(LOG(500)-LOG(10))) -> #VALUE! | AQ27: =IF(E18<=10,AP27*0.9,AP27) -> #VALUE! | AR27: =AQ27-(AO13) -> #VALUE! | AS27: =-(1.4-0.6*(LOG(F83)-LOG(10))/(LOG(500)-LOG(10))) -> -1.5405346 | AT27: =IF(E18<=10,AS27*0.9,AS27) -> -1.3864811 | AU27: =AT27-(AO13) -> -1.5664811
B28: =IF(E18<=10,('7-16 Positive'!B105)*E23,IF(AND(E18>7,E18<=20),'7-16 Positive'!E105*E23,IF(AND(E18>20,E18<=27),'7-16 Positive'!H105*E23,IF(AND(E18>27,E18<=45),'7-16 Positive'!K105*E23,0)))) -> 41.04 | C28: =IF(E18<=10,('7-16 Negative'!B105)*E23,IF(AND(E18>7,E18<=20),'7-16 Negative'!E105*E23,IF(AND(E18>20,E18<=27),'7-16 Negative'!H105*E23,IF(AND(E18>27,E18<=45),'7-16 Negative'!K105*E23,0)))) -> -44.55 | D28: =IF(E18<=10,('7-16 Positive'!B106)*E23,IF(AND(E18>7,E18<=20),'7-16 Positive'!E106*E23,IF(AND(E18>20,E18<=27),'7-16 Positive'!H106*E23,IF(AND(E18>27,E18<=45),'7-16 Positive'!K106*E23,0)))) -> 41.04 | E28: =IF(E18<=10,('7-16 Negative'!B106)*E23,IF(AND(E18>7,E18<=20),'7-16 Negative'!E106*E23,IF(AND(E18>20,E18<=27),'7-16 Negative'!H106*E23,IF(AND(E18>27,E18<=45),'7-16 Negative'!K106*E23,0)))) -> -54.945 | F28: =IF(E18<=7,'7-16 Positive'!B107*E23,IF(AND(E18>7,E18<=20),'7-16 Positive'!E107*E23,IF(AND(E18>20,E18<=27),'7-16 Positive'!H107*E23,IF(AND(E18>27,E18<=45),'7-16 Positive'!K107*E23,0)))) -> 16.74 | G28: =IF(AND(E18<=7,E20="no"),'7-16 Negative'!B107*E23,IF(AND(E18>7,AND(E18<=20),E20="no"),'7-16 Negative'!E107*E23,IF(AND(E18>20,AND(E18<=27),E20="no"),'7-16 Negative'!H107*E23,IF(AND(E18>27,AND(E18<=45),E20="no"),'7-16 Negative'!K107*E23,IF(AND(E18<=7,E20="yes"),'7-16 Negative Overhang'!B105*E23,IF(AND(E18>7,AND(E18<=20),E20="yes"),'7-16 Negative Overhang'!E105*E23,IF(AND(#REF!="20 to 27",E20="yes"),'7-16 Negative Overhang'!H105*E23,IF(AND(E18>27,AND(E18<=45),E20="yes"),'7-16 Negative Overhang'!K105*E23,0)))))))) -> -65.34 | H28: =IF(H26="leave out zone 1'","",IF(E18<=7,'7-16 Positive'!B108*E23,IF(AND(E18>7,E18<=20),'7-16 Positive'!E108*E23,IF(AND(E18>20,E18<=27),'7-16 Positive'!H108*E23,IF(AND(E18>27,E18<=45),'7-16 Positive'!K108*E23,0))))) | I28: =IF(H26="leave out zone 1'","",IF(AND(E18<=7,E20="no"),'7-16 Negative'!B108*E23,IF(AND(E18>7,AND(E18<=20),E20="no"),'7-16 Negative'!E108*E23,IF(AND(E18>20,AND(E18<=27),E20="no"),'7-16 Negative'!H108*E23,IF(AND(E18>27,AND(E18<=45),E20="no"),'7-16 Negative'!K108*E23,IF(AND(E18<=7,E20="yes"),'7-16 Negative Overhang'!B105*E23,IF(AND(E18>7,AND(E18<=20),E20="yes"),'7-16 Negative Overhang'!E106*E23,IF(AND(#REF!="20 to 27",E20="yes"),'7-16 Negative Overhang'!H106*E23,IF(AND(E18>27,AND(E18<=45),E20="yes"),'7-16 Negative Overhang'!K106*E23,0)))))))))
B30: =IF(E18<=7,"Zone 2:",IF(AND(E18>7,E18<=45),"Zone 2n:",0)) -> Zone 2: | D30: =IF(E18<=7,"Zone 3:",IF(AND(E18>7,E18<=45),"Zone 2r:",0)) -> Zone 3: | F30: =IF(AND(E18>7,E18<=45),"Zone 3e:","") | H30: =IF(AND(E18>7,E18<=45),"Zone 3r:","")
B31: Postive | C31: Negative | D31: Postive | E31: Negative | F31: =IF(E18<=7,"",IF(AND(E18>7,E18<=45),"Postive",0)) | G31: =IF(E18<=7,"",IF(AND(E18>7,E18<=45),"Negative",0)) | H31: =IF(E18<=7,"",IF(AND(E18>7,E18<=45),"Postive",0)) | I31: =IF(E18<=7,"",IF(AND(E18>7,E18<=45),"Negative",0))
B32: =IF(E18<=7,'7-16 Positive'!B109*E23,IF(AND(E18>7,E18<=20),'7-16 Positive'!E109*E23,IF(AND(E18>20,E18<=27),'7-16 Positive'!H109*E23,IF(AND(E18>27,E18<=45),'7-16 Positive'!K109*E23,0)))) -> 16.74 | C32: =IF(AND(EE17<=7,E20="no"),'7-16 Negative'!B109*E23,IF(AND(E18>7,AND(E18<=20),E20="no"),'7-16 Negative'!E109*E23,IF(AND(E18>20,AND(E18<=27),E20="no"),'7-16 Negative'!H109*E23,IF(AND(E18>27,AND(E18<=45),E20="no"),'7-16 Negative'!K109*E23,IF(AND(E18<=7,E20="yes"),'7-16 Negative Overhang'!B106*E23,IF(AND(E18>7,AND(E18<=20),E20="yes"),'7-16 Negative Overhang'!E107*E23,IF(AND(E18>20,AND(E18<=27),E20="yes"),'7-16 Negative Overhang'!H107*E23,IF(AND(E18>27,AND(E18<=45),E20="yes"),'7-16 Negative Overhang'!K107*E23,0)))))))) -> -86.265 | D32: =IF(E18<=7,'7-16 Positive'!B110*E23,IF(AND(E18>7,E18<=20),'7-16 Positive'!E110*E23,IF(AND(E18>20,E18<=27),'7-16 Positive'!H110*E23,IF(AND(E18>27,E18<=45),'7-16 Positive'!K110*E23,0)))) -> 16.74 | E32: =IF(AND(E18<=7,E20="no"),'7-16 Negative'!B110*E23,IF(AND(E18>7,AND(E18<=20),E20="no"),'7-16 Negative'!E110*E23,IF(AND(E18>20,AND(E18<=27),E20="no"),'7-16 Negative'!H110*E23,IF(AND(E18>27,AND(E18<=45),E20="no"),'7-16 Negative'!K110*E23,IF(AND(E18<=7,E20="yes"),'7-16 Negative Overhang'!B105*E23,IF(AND(E18>7,AND(E18<=20),E20="yes"),'7-16 Negative Overhang'!E108*E23,IF(AND(E18>20,AND(E18<=27),E20="yes"),'7-16 Negative Overhang'!H108*E23,IF(AND(E18>27,AND(E18<=45),E20="yes"),'7-16 Negative Overhang'!K108*E23,0)))))))) -> -117.585 | F32: =IF(E18<=7,"",IF(AND(E18>7,E18<=20),'7-16 Positive'!E111*E23,IF(AND(E18>20,E18<=27),'7-16 Positive'!H111*E23,IF(AND(E18>27,E18<=45),'7-16 Positive'!K111*E23,0)))) | G32: =IF(E18<=7,"",IF(AND(E18>7,AND(E18<=20),E20="no"),'7-16 Negative'!E111*E23,IF(AND(E18>20,AND(E18<=27),E20="no"),'7-16 Negative'!H111*E23,IF(AND(E18>27,AND(E18<=45),E20="no"),'7-16 Negative'!K111*E23,IF(E18<=7,"",IF(AND(E18>7,AND(E18<=20),E20="yes"),'7-16 Negative Overhang'!E109*E23,IF(AND(E18>20,AND(E18<=27),E20="yes"),'7-16 Negative Overhang'!H109*E23,IF(AND(E18>27,AND(E18<=45),E20="yes"),'7-16 Negative Overhang'!K109*E23,0)))))))) | H32: =IF(E18<=7,"",IF(AND(E18>7,E18<=20),'7-16 Positive'!E112*E23,IF(AND(E18>20,E18<=27),'7-16 Positive'!H112*E23,IF(AND(E18>27,E18<=45),'7-16 Positive'!K112*E23,0)))) | I32: =IF(E18<=7,"",IF(AND(E18>7,AND(E18<=20),E20="no"),'7-16 Negative'!E112*E23,IF(AND(E18>20,AND(E18<=27),E20="no"),'7-16 Negative'!H112*E23,IF(AND(E18>27,AND(E18<=45),E20="no"),'7-16 Negative'!K112*E23,IF(E18<=7,"",IF(AND(E18>7,AND(E18<=20),E20="yes"),'7-16 Negative Overhang'!E110*E23,IF(AND(E18>20,AND(E18<=27),E20="yes"),'7-16 Negative Overhang'!H110*E23,IF(AND(E18>27,AND(E18<=45),E20="yes"),'7-16 Negative Overhang'!K110*E23,0))))))))
A34: Pasd (Allowable Stress Design) | B34: =B26 -> Zone 4: | D34: =D26 -> Zone 5: | F34: =F26 -> Zone 1: | H34: =H26 -> Leave Out Zone 1'
B35: Postive | C35: Negative | D35: Postive | E35: Negative | F35: Postive | G35: Negative | H35: =H27 | I35: =I27
B36: =B28*0.6 -> 24.624 | C36: =C28*0.6 -> -26.73 | D36: =D28*0.6 -> 24.624 | E36: =E28*0.6 -> -32.967 | F36: =F28*0.6 -> 10.044 | G36: =G28*0.6 -> -39.204 | H36: =IF(H28="","",H28*0.6) | I36: =IF(I28="","",I28*0.6)
K37: Slope: 0 to 7 Degrees | O37: Slope: 7 to 45 Degrees
B38: =B30 -> Zone 2: | D38: =D30 -> Zone 3: | F38: =F30 | H38: =H30
B39: Postive | C39: Negative | D39: Postive | E39: Negative | F39: =F31 | G39: =G31 | H39: =H31 | I39: =I31
B40: =B32*0.6 -> 10.044 | C40: =C32*0.6 -> -51.759 | D40: =D32*0.6 -> 10.044 | E40: =E32*0.6 -> -70.551 | F40: =IF(E18<=7,"",IF(AND(E18>7,E18<=45),F32*0.6,0)) | G40: =IF(E18<=7,"",IF(AND(E18>7,E18<=45),G32*0.6,0)) | H40: =IF(E18<=7,"",IF(AND(E18>7,E18<=45),H32*0.6,0)) | I40: =IF(E18<=7,"",IF(AND(E18>7,E18<=45),I32*0.6,0))
C42: Max Allowable Pressure: | D42: =MIN(C36,E36,G36,I36,C40,E40,G40,I40) -> -70.551 | E42: psf
A47: BELOW ONLY APPLIES TO EPDM OR TPO (MAX 1/2 IN 12 SLOPE)
...

Sheet C&C 7-10 Simplified
E1: WIND LOADS - Components and Cladding | J1: Wind Speed Conversion
E2: (PART 2 - SIMPLIFIED METHOD) | K2: Wind Speed V(ult) = | L2: 155 | M2: mph
E3: (ASCE 7-10 Applies to 2012 IBC & 2015 IBC) | K3: Wind Speed V(asd) = | L3: =SUM(L2*SQRT(0.6)) -> 120.06248 | M3: mph | AN3: Wind Speed, V = | AO3: =E13 -> 130 | AP3: mph
AC4: Wind Area | AN4: Wind Exposure, λ= | AO4: =E14 -> C
C5: Conditions: | D5: - Simple Diaphragm | L5: Building Dimensions | AC5: =L7*0.1 -> 2.4 | AD5: =E16*0.4 -> 6 | AE5: <---Wind Zones 4 & 5 Endwalls | AN5: h = | AO5: =E16 -> 15 | AP5: ft.
D6: - Low rise / Low slope building | L6: Width: | M6: Lenth: | AC6: =M7*0.1 -> 6 | AD6: =E16*0.4 -> 6 | AE6: <---Wind Zones 4 & 5 Sidewalls
D7: - Regular Shaped | K7: Building Dimensions= | L7: 24 | M7: 60 | AC7: =MIN(L7,M7)*0.1 -> 2.4 | AD7: =E16*0.4 -> 6 | AE7: <---Wind Zones @ Roof | AN7: Enter Roof Slope (decimals) = | AO7: =E17 -> 0.25 | AP7: in 12
D8: - Not Classified as Flexible | K8: Roof Type = | L8: Transverse / Complex | AC8: width | AD8: length | AN8: Roof Slope (Degrees) = | AO8: =E18 -> 1.1934894
D9: - Does not have special response characteristics
D10: - Symetrical with roof slope less than 45 degrees | L10: Ht. to Peak (Ft.) | AC10: =IF(E18<=7,(L7-(U17*2)),IF(AND(E18>7,E18<=45),(L7-(U17*4)),0)) -> 18 | AD10: =IF(E18<=7,(M7-(V17*2)),IF(AND(E18>7,E18<=45),(M7-(V17*2)),0)) -> 48 | AE10: <---Zone 2 | AN10: Topographic Factor (Kzt) = | AO10: 1 | AP10: (Avg)
D11: - Exempt from Torsional requirements | L11: =MAX(AC13,AC14) -> 15.625 | AC11: =IF(E18<=7,(L7-S16*2),IF(AND(E18>7,E18<=27),(L7-(S16*2)),IF(AND(E18>27,E18<=45),(L7-(S16*4))*0))) -> 18 | AD11: =IF(E18<=7,(M7-(T16*2)),IF(AND(E18>7,E18<=45),(M7-(V16*4)),0)) -> 48 | AE11: <---Zone 1 | AN11: Wind Directionanlity Factor (Kd)= | AO11: 0.85
D12: - Effective Wind Area figured at 10 sq. ft. | AN12: Internal Pressure Coefficient (GCpi)= | AO12: =IF(AP12="(enclosed)",-0.18,IF(AP12="(Partially Enclosed)",-0.55,IF(AP12="(open)",0,))) -> -0.18 | AP12: (Enclosed)
D13: Wind Speed, V(ult) = | E13: 130 | F13: mph | M13: Zone Dimensions (FT.) | AC13: =IF(L8="transverse / complex",(E15+(E17*((M7/2)/12))),IF(L8="gable / mono",(E15+(E17*((L7/2)/12))),0)) -> 15.625 | AD13: <---Ht. w/o parapet | AN13: Internal Pressure Coefficient (GCpi)= | AO13: =IF(AP12="(enclosed)",0.18,IF(AP12="(Partially Enclosed)",0.55,IF(AP12="(open)",0))) -> 0.18
D14: Wind Exposure, λ= | E14: C | M14: Zone 4: | O14: Zone 5: | Q14: Zone 1: | S14: Zone 2: | U14: Zone 3: | AC14: =E15+E19 -> 15 | AD14: <---Ht. w/ parapet | AN14: Building Height and Exposure (λ=) | AO14: =IF(AND(AO4="B",AO5<=15),"1",IF(AND(AO4="B",AO5=20),"1",IF(AND(AO4="B",AO5=25),"1",IF(AND(AO4="B",AO5=30),"1",IF(AND(AO4="B",AO5=35),"1.05",IF(AND(AO4="B",AO5=40),"1.09",IF(AND(AO4="B",AO5=45),"1.12",IF(AND(AO4="B",AO5=50),"1.16",IF(AND(AO4="B",AO5=55),"1.19",IF(AND(AO4="B",AO5=60),"1.22",IF(AND(AO4="C",AO5<=15),"1.21",IF(AND(AO4="C",AO5=20),"1.29",IF(AND(AO4="C",AO5=25),"1.35",IF(AND(AO4="C",AO5=30),"1.4",IF(AND(AO4="C",AO5=35),"1.45",IF(AND(AO4="C",AO5=40),"1.49",IF(AND(AO4="C",AO5=45),"1.53",IF(AND(AO4="C",AO5=50),"1.56",IF(AND(AO4="C",AO5=55),"1.59",IF(AND(AO4="C",AO5=60),"1.62",IF(AND(AO4="D",AO5<=15),"1.47",IF(AND(AO4="D",AO5=20),"1.55",IF(AND(AO4="D",AO5=25),"1.61",IF(AND(AO4="D",AO5=30),"1.66",IF(AND(AO4="D",AO5=35),"1.7",IF(AND(AO4="D",AO5=40),"1.74",IF(AND(AO4="D",AO5=45),"1.78",IF(AND(AO4="D",AO5=50),"1.81",IF(AND(AO4="D",AO5=55),"1.84",IF(AND(AO4="D",AO5=60),"1.87",0)))))))))))))))))))))))))))))) -> 1.21
D15: Eave Height from grade= | E15: 15 | F15: ft. (Max 30') | M15: Endwall: | N15: Sidewall: | O15: Endwall: | P15: Sidewall: | Q15: Endwall: | R15: Sidewall: | S15: Endwall: | T15: Sidewall: | U15: Endwall: | V15: Sidewall: | AN15: Velocity Pressure Exposure (Kz)= | AO15: =IF(AND(AO4="B",AO5<30),(2.01*((30)/1200)^(2/7)),IF(AND(AO4="B",AO5>=30),(2.01*((AO5)/1200)^(2/7)),IF(AO4="C",(2.01*((AO5)/900)^(2/9.5)),IF(AO4="D",(2.01*((AO5)/700)^(2/11.5)),0)))) -> 0.84888415
D16: h = | E16: =IF(E19>0,E15+E19,IF(E18<=10,E15,IF(L8="transverse / complex",(E15+(E17*((M7/2)/12)/2)),IF(L8="gable / mono",(E15+(E17*((L7/2)/12)/2)),E15+E19)))) -> 15 | L16: Total Width (ft) each corner / side: | M16: - | N16: - | O16: =IF(MIN(AC5,AD5)<3,3,MIN(AC5,AD5)) -> 3 | P16: =IF(MIN(AC6,AD6)<3,3,MIN(AC6,AD6)) -> 6 | Q16: - | R16: - | S16: =IF(MIN(AC7,AD7)<3,3,MIN(AC7,AD7)) -> 3 | T16: =IF(MIN(AC6,AD6)<3,3,MIN(AC6,AD6)) -> 6 | U16: =IF(MIN(AC7,AD7)<3,3,MIN(AC7,AD7)) -> 3 | V16: =IF(MIN(AC6,AD6)<3,3,MIN(AC6,AD6)) -> 6 | AN16: Velocity Pressure (Qh)= | AO16: =(0.6*0.00256*AO15*AO10*AO11*(AO3^2)) -> 18.730323 | AP16: psf
D17: Enter Roof Slope (decimals) = | E17: 0.25 | F17: in 12 | L17: Total Length (ft): | M17: =SUM(L7-O17*2) -> 18 | N17: =SUM(M7-P17*2) -> 48 | O17: =IF(MIN(AC5,AD5)<3,3,MIN(AC5,AD5)) -> 3 | P17: =IF(MIN(AC6,AD6)<3,3,MIN(AC6,AD6)) -> 6 | Q17: =IF(AC11<=0,"N/A",IF(E18<=7,(L7-S16*2),IF(E18>7,(L7-(S16*4)),0))) -> 18 | R17: =IF(AD11<=0,"N/A",IF(E18<=7,(M7-(T16*2)),IF(E18>7,(M7-(T16*4)),0))) -> 48 | S17: =IF(AC10<=0,"N/A",IF(E18<=7,(L7-(U17*2)),IF(E18>7,(L7-(U17*4)),0))) -> 18 | T17: =IF(AD10<=0,"N/A",IF(E18<=7,(M7-(V17*2)),IF(E18>7,(M7-(V17*2)),0))) -> 48 | U17: =IF(MIN(AC5,AD5)<3,3,MIN(AC5,AD5)) -> 3 | V17: =IF(MIN(AC6,AD6)<3,3,MIN(AC6,AD6)) -> 6
D18: Roof Slope (Degrees) = | E18: =ATAN(E17/12)*(180/PI()) -> 1.1934894 | F18: (Degrees) | O18: Each Corner | U18: Each Corner | AM18: Window 1 | AP18: Window 2 | AS18: Window 3 | AV18: Window 4 | AY18: Window 5
D19: Parapet = | E19: 0 | AL19: Pos. Zone 4 | AM19: =(1-0.3*(LOG(E71)-LOG(10))/(LOG(500)-LOG(10))) -> #NUM! | AN19: =IF(E18<=10,AM19*0.9,AM19) -> #NUM! | AO19: =AN19-(AO12) -> #NUM! | AP19: =(1-0.3*(LOG(E72)-LOG(10))/(LOG(500)-LOG(10))) -> #NUM! | AQ19: =IF(E18<=10,AP19*0.9,AP19) -> #NUM! | AR19: =AQ19-(AO12) -> #NUM! | AS19: =(1-0.3*(LOG(E73)-LOG(10))/(LOG(500)-LOG(10))) -> #NUM! | AT19: =IF(E18<=10,AS19*0.9,AS19) -> #NUM! | AU19: =AT19-(AO12) -> #NUM! | AV19: =(1-0.3*(LOG(E74)-LOG(10))/(LOG(500)-LOG(10))) -> #NUM! | AW19: =IF(E18<=10,AV19*0.9,AV19) -> #NUM! | AX19: =AW19-(AO12) -> #NUM! | AY19: =(1-0.3*(LOG(E75)-LOG(10))/(LOG(500)-LOG(10))) -> #NUM! | AZ19: =IF(E18<=10,AY19*0.9,AY19) -> #NUM! | BA19: =AZ19-(AO12) -> #NUM!
D20: Overhang: | E20: No | AL20: Pos. Zone 5 | AM20: =(1-0.3*(LOG(E71)-LOG(10))/(LOG(500)-LOG(10))) -> #NUM! | AN20: =IF(E18<=10,AM20*0.9,AM20) -> #NUM! | AO20: =AN20-(AO12) -> #NUM! | AP20: =(1-0.3*(LOG(E72)-LOG(10))/(LOG(500)-LOG(10))) -> #NUM! | AQ20: =IF(E18<=10,AP20*0.9,AP20) -> #NUM! | AR20: =AQ20-(AO12) -> #NUM! | AS20: =(1-0.3*(LOG(E73)-LOG(10))/(LOG(500)-LOG(10))) -> #NUM! | AT20: =IF(E18<=10,AS20*0.9,AS20) -> #NUM! | AU20: =AT20-(AO12) -> #NUM! | AV20: =(1-0.3*(LOG(E74)-LOG(10))/(LOG(500)-LOG(10))) -> #NUM! | AW20: =IF(E18<=10,AV20*0.9,AV20) -> #NUM! | AX20: =AW20-(AO12) -> #NUM! | AY20: =(1-0.3*(LOG(E75)-LOG(10))/(LOG(500)-LOG(10))) -> #NUM! | AZ20: =IF(E18<=10,AY20*0.9,AY20) -> #NUM! | BA20: =AZ20-(AO12) -> #NUM!
D21: Topographic Factor (Kzt) = | E21: 1 | F21: (Avg) (Section 26.8) | AL21: Neg. Zone 4 | AM21: =-(1.1-0.3*(LOG(E71)-LOG(10))/(LOG(500)-LOG(10))) -> #NUM! | AN21: =IF(E18<=10,AM21*0.9,AM21) -> #NUM! | AO21: =AN21-(AO13) -> #NUM! | AP21: =-(1.1-0.3*(LOG(E72)-LOG(10))/(LOG(500)-LOG(10))) -> #NUM! | AQ21: =IF(E18<=10,AP21*0.9,AP21) -> #NUM! | AR21: =AQ21-(AO13) -> #NUM! | AS21: =-(1.1-0.3*(LOG(E73)-LOG(10))/(LOG(500)-LOG(10))) -> #NUM! | AT21: =IF(E18<=10,AS21*0.9,AS21) -> #NUM! | AU21: =AT21-(AO13) -> #NUM! | AV21: =-(1.1-0.3*(LOG(E74)-LOG(10))/(LOG(500)-LOG(10))) -> #NUM! | AW21: =IF(E18<=10,AV21*0.9,AV21) -> #NUM! | AX21: =AW21-(AO13) -> #NUM! | AY21: =-(1.1-0.3*(LOG(E75)-LOG(10))/(LOG(500)-LOG(10))) -> #NUM! | AZ21: =IF(E18<=10,AY21*0.9,AY21) -> #NUM! | BA21: =AZ21-(AO13) -> #NUM!
D22: Internal Pressure Coefficient (GCpi) | E22: +/- 0.18 | F22: (Enclosed or partially open) | AL22: Neg. Zone 5 | AM22: =-(1.4-0.6*(LOG(E71)-LOG(10))/(LOG(500)-LOG(10))) -> #NUM! | AN22: =IF(E18<=10,AM22*0.9,AM22) -> #NUM! | AO22: =AN22-(AO13) -> #NUM! | AP22: =-(1.4-0.6*(LOG(E72)-LOG(10))/(LOG(500)-LOG(10))) -> #NUM! | AQ22: =IF(E18<=10,AP22*0.9,AP22) -> #NUM! | AR22: =AQ22-(AO13) -> #NUM! | AS22: =-(1.4-0.6*(LOG(E73)-LOG(10))/(LOG(500)-LOG(10))) -> #NUM! | AT22: =IF(E18<=10,AS22*0.9,AS22) -> #NUM! | AU22: =AT22-(AO13) -> #NUM! | AV22: =-(1.4-0.6*(LOG(E74)-LOG(10))/(LOG(500)-LOG(10))) -> #NUM! | AW22: =IF(E18<=10,AV22*0.9,AV22) -> #NUM! | AX22: =AW22-(AO13) -> #NUM! | AY22: =-(1.4-0.6*(LOG(E75)-LOG(10))/(LOG(500)-LOG(10))) -> #NUM! | AZ22: =IF(E18<=10,AY22*0.9,AY22) -> #NUM! | BA22: =AZ22-(AO13) -> #NUM!
D23: Building Height and Exposure (λ=) | E23: =IF(AND(E16<=30,E14="B"),1,IF(AND(AND(E16>30),E16<=35,E14="B"),1.05,IF(AND(AND(E16>35),E16<=40,E14="B"),1.09,IF(AND(AND(E16>40),E16<=45,E14="B"),1.12,IF(AND(AND(E16>45),E16<=50,E14="B"),1.16,IF(AND(AND(E16>50),E16<=55,E14="B"),1.19,IF(AND(AND(E16>55),E16<=60,E14="B"),1.22,IF(AND(E16<=15,E14="C"),1.21,IF(AND(AND(E16>15),E16<=20,E14="C"),1.29,IF(AND(AND(E16>20),E16<=25,E14="C"),1.35,IF(AND(AND(E16>25),E16<=30,E14="C"),1.4,IF(AND(AND(E16>30),E16<=35,E14="C"),1.45,IF(AND(AND(E16>35),E16<=40,E14="C"),1.49,IF(AND(AND(E16>40),E16<=45,E14="C"),1.53,IF(AND(AND(E16>45),E16<=50,E14="C"),1.56,IF(AND(AND(E16>50),E16<=55,E14="C"),1.59,IF(AND(AND(E16>55),E16<=60,E14="C"),1.62,IF(AND(E16<=15,E14="d"),1.47,IF(AND(AND(E16>15),E16<=20,E14="d"),1.55,IF(AND(AND(E16>20),E16<=25,E14="d"),1.61,IF(AND(AND(E16>25),E16<=30,E14="d"),1.66,IF(AND(AND(E16>30),E16<=35,E14="d"),1.7,IF(AND(AND(E16>35),E16<=40,E14="d"),1.74,IF(AND(AND(E16>40),E16<=45,E14="d"),1.78,IF(AND(AND(E16>45),E16<=50,E14="d"),1.81,IF(AND(AND(E16>50),E16<=55,E14="d"),1.84,IF(AND(AND(E16>55),E16<=60,E14="d"),1.87,0))))))))))))))))))))))))))) -> 1.21 | F23: (Table 30.7-2) | AM23: Door 1 | AP23: Door 2 | AS23: Door 3
A24: p=Ptable(EAF)(RF)Kzt - (Section 30.7.1.1) | AL24: Pos. Zone 4 | AM24: =(1-0.3*(LOG(E81)-LOG(10))/(LOG(500)-LOG(10))) -> #NUM! | AN24: =IF(E18<=10,AM24*0.9,AM24) -> #NUM! | AO24: =AN24-(AO12) -> #NUM! | AP24: =(1-0.3*(LOG(E82)-LOG(10))/(LOG(500)-LOG(10))) -> #NUM! | AQ24: =IF(E18<=10,AP24*0.9,AP24) -> #NUM! | AR24: =AQ24-(AO12) -> #NUM! | AS24: =(1-0.3*(LOG(E83)-LOG(10))/(LOG(500)-LOG(10))) -> #VALUE! | AT24: =IF(E18<=10,AS24*0.9,AS24) -> #VALUE! | AU24: =AT24-(AO12) -> #VALUE!
A25: Design Pressure (p) | AL25: Pos. Zone 5 | AM25: =(1-0.3*(LOG(E81)-LOG(10))/(LOG(500)-LOG(10))) -> #NUM! | AN25: =IF(E18<=10,AM25*0.9,AM25) -> #NUM! | AO25: =AN25-(AO12) -> #NUM! | AP25: =(1-0.3*(LOG(E82)-LOG(10))/(LOG(500)-LOG(10))) -> #NUM! | AQ25: =IF(E18<=10,AP25*0.9,AP25) -> #NUM! | AR25: =AQ25-(AO12) -> #NUM! | AS25: =(1-0.3*(LOG(E83)-LOG(10))/(LOG(500)-LOG(10))) -> #VALUE! | AT25: =IF(E18<=10,AS25*0.9,AS25) -> #VALUE! | AU25: =AT25-(AO12) -> #VALUE!
A26: Pult (Ultimate Design Pressure) | B26: Zone 4: | D26: Zone 5: | F26: Zone 1: | AL26: Neg. Zone 4 | AM26: =-(1.1-0.3*(LOG(E81)-LOG(10))/(LOG(500)-LOG(10))) -> #NUM! | AN26: =IF(E18<=10,AM26*0.9,AM26) -> #NUM! | AO26: =AN26-(AO13) -> #NUM! | AP26: =-(1.1-0.3*(LOG(E82)-LOG(10))/(LOG(500)-LOG(10))) -> #NUM! | AQ26: =IF(E18<=10,AP26*0.9,AP26) -> #NUM! | AR26: =AQ26-(AO13) -> #NUM! | AS26: =-(1.1-0.3*(LOG(E83)-LOG(10))/(LOG(500)-LOG(10))) -> #VALUE! | AT26: =IF(E18<=10,AS26*0.9,AS26) -> #VALUE! | AU26: =AT26-(AO13) -> #VALUE!
B27: Postive | C27: Negative | D27: Postive | E27: Negative | F27: Postive | G27: Negative | AL27: Neg. Zone 5 | AM27: =-(1.4-0.6*(LOG(E81)-LOG(10))/(LOG(500)-LOG(10))) -> #NUM! | AN27: =IF(E18<=10,AM27*0.9,AM27) -> #NUM! | AO27: =AN27-(AO13) -> #NUM! | AP27: =-(1.4-0.6*(LOG(E82)-LOG(10))/(LOG(500)-LOG(10))) -> #NUM! | AQ27: =IF(E18<=10,AP27*0.9,AP27) -> #NUM! | AR27: =AQ27-(AO13) -> #NUM! | AS27: =-(1.4-0.6*(LOG(E83)-LOG(10))/(LOG(500)-LOG(10))) -> #VALUE! | AT27: =IF(E18<=10,AS27*0.9,AS27) -> #VALUE! | AU27: =AT27-(AO13) -> #VALUE!
B28: =IF(E18<=10,('7-10 Positive'!B55)*E23,IF(E18<=7,'7-10 Positive'!B55*E23,IF(AND(E18>7,E18<=27),'7-10 Positive'!E55*E23,IF(AND(E18>27,E18<=45),'7-10 Positive'!H55*E23,0)))) -> 36.784 | C28: =IF(E18<=10,('7-10 Negative'!B55)*E23,IF(E18<=7,'7-10 Negative'!B55*E23,IF(AND(E18>7,E18<=27),'7-10 Negative'!E55*E23,IF(AND(E18>27,E18<=45),'7-10 Negative'!H55*E23,0)))) -> -39.93 | D28: =IF(E18<=10,('7-10 Positive'!B56)*E23,IF(E18<=7,'7-10 Positive'!B56*E23,IF(AND(E18>7,E18<=27),'7-10 Positive'!E56*E23,IF(AND(E18>27,E18<=45),'7-10 Positive'!H56*E23,0)))) -> 36.784 | E28: =IF(E18<=10,('7-10 Negative'!B56)*E23,IF(E18<=7,'7-10 Negative'!B56*E23,IF(AND(E18>7,E18<=27),'7-10 Negative'!E56*E23,IF(AND(E18>27,E18<=45),'7-10 Negative'!H56*E23,0)))) -> -49.247 | F28: =IF(E18<=7,'7-10 Positive'!B57*E23,IF(AND(E18>7,E18<=27),'7-10 Positive'!E57*E23,IF(AND(E18>27,E18<=45),'7-10 Positive'!H57*E23,0))) -> 15.004 | G28: =IF(E18<=7,'7-10 Negative'!B57*E23,IF(AND(E18>7,E18<=27),'7-10 Negative'!E57*E23,IF(AND(E18>27,E18<=45),'7-10 Negative'!H57*E23,0))) -> -36.784
B30: Zone 2: | D30: Zone 3:
B31: Postive | C31: Negative | D31: Postive | E31: Negative
B32: =IF(E18<=7,'7-10 Positive'!B58*E23,IF(AND(E18>7,E18<=27),'7-10 Positive'!E58*E23,IF(AND(E18>27,E18<=45),'7-10 Positive'!H58*E23,0))) -> 15.004 | C32: =IF(AND(E18<=7,E20="no"),'7-10 Negative'!B58*E23,IF(AND(E18>7,AND(E18<=27),E20="no"),'7-10 Negative'!E58*E23,IF(AND(E18>27,AND(E18<=45),E20="no"),'7-10 Negative'!H58*E23,IF(AND(E18<=7,E20="yes"),'7-10 Negative Overhang'!B32*E23,IF(AND(E18>7,AND(E18<=27),E20="yes"),'7-10 Negative Overhang'!E32*E23,IF(AND(E18>27,AND(E18<=45),E20="yes"),'7-10 Negative Overhang'!H32*E23,0)))))) -> -61.71 | D32: =IF(E18<=7,'7-10 Positive'!B59*E23,IF(AND(E18>7,E18<=27),'7-10 Positive'!E59*E23,IF(AND(E18>27,E18<=45),'7-10 Positive'!H59*E23,0))) -> 15.004 | E32: =IF(AND(E18<=7,E20="no"),'7-10 Negative'!B59*E23,IF(AND(E18>7,AND(E18<=27),E20="no"),'7-10 Negative'!E59*E23,IF(AND(E18>27,AND(E18<=45),E20="no"),'7-10 Negative'!H59*E23,IF(AND(E18<=7,E20="yes"),'7-10 Negative Overhang'!B33*E23,IF(AND(E18>7,AND(E18<=27),E20="yes"),'7-10 Negative Overhang'!E33*E23,IF(AND(E18>27,AND(E18<=45),E20="yes"),'7-10 Negative Overhang'!H33*E23,0)))))) -> -92.928
A34: Pasd (Allowable Stress Design) | B34: =B26 -> Zone 4: | D34: =D26 -> Zone 5: | F34: =F26 -> Zone 1:
B35: Postive | C35: Negative | D35: Postive | E35: Negative | F35: Postive | G35: Negative
B36: =(B28*0.6) -> 22.0704 | C36: =(C28*0.6) -> -23.958 | D36: =(D28*0.6) -> 22.0704 | E36: =(E28*0.6) -> -29.5482 | F36: =(F28*0.6) -> 9.0024 | G36: =(G28*0.6) -> -22.0704
B38: =B30 -> Zone 2: | D38: =D30 -> Zone 3:
B39: Postive | C39: Negative | D39: Postive | E39: Negative
B40: =(B32*0.6) -> 9.0024 | C40: =(C32*0.6) -> -37.026 | D40: =(D32*0.6) -> 9.0024 | E40: =(E32*0.6) -> -55.7568 | K40: Slope: 0 to 7 Degrees | O40: Slope: 7 to 27 Degrees | S40: Slope: 27 to 45 Degrees
C42: Max Allowable Pressure: | D42: =MIN(C36,E36,G36,C40,E40) -> -55.7568 | E42: psf
A47: BELOW ONLY APPLIES TO EPDM OR TPO (MAX 1/2 IN 12 SLOPE)
A48: HVHZ or Non-HVHZ: | C48: Non-HVHZ | G48: Insulation / Underlayment
...

Sheet C&C 7-05 Simplified
E1: WIND LOADS - Components and Cladding
E2: (PART 1 - SIMPLIFIED METHOD) | N2: Building Dimensions | AO2: Wind Speed, V = | AP2: =E13 -> 130 | AQ2: mph
E3: (ASCE 7-05 Applies to 2009 IBC) | N3: Width: | O3: Lenth: | AO3: Wind Exposure, λ= | AP3: =E14 -> C
M4: Building Dimensions= | N4: 24 | O4: 60 | AC4: Wind Area | AO4: Mean Roof Height, h = | AP4: =E16 -> 15 | AQ4: ft.
C5: Conditions: | D5: - Simple Diaphragm | M5: Roof Type = | N5: Transverse / Complex | AC5: =N4*0.1 -> 2.4 | AD5: =E16*0.4 -> 6 | AE5: <---Wind Zones 4 & 5 Endwalls | AO5: Enter Roof Slope (decimals) = | AP5: =E17 -> 0.25 | AQ5: in 12
D6: - Low rise / Low slope building | AC6: =O4*0.1 -> 6 | AD6: =E16*0.4 -> 6 | AE6: <---Wind Zones 4 & 5 Sidewalls | AO6: Roof Slope (Degrees) = | AP6: =E18 -> 1.1934894
D7: - Regular Shaped | N7: Ht. to Peak (Ft.) | AC7: =MIN(N4,O4)*0.1 -> 2.4 | AD7: =E16*0.4 -> 6 | AE7: <---Wind Zones @ Roof
D8: - Not Classified as Flexible | N8: =MAX(AC13,AC14) -> 15.625 | AC8: width | AD8: length
D9: - Does not have special response characteristics | AO9: Importance Factor (I)= | AP9: 1 | AQ9: (Change to 1.15 For Risk Cat. III or IV)
D10: - Symetrical with roof slope less than 45 degrees | AC10: =IF(E18<=7,(N4-(V15*2)),IF(AND(E18>7,E18<=45),(N4-(V15*4)),0)) -> 18 | AD10: =IF(E18<=7,(O4-(W14*2)),IF(AND(E18>7,E18<=45),(O4-(W14*2)),0)) -> 48 | AE10: <---Zone 2 | AO10: Topographic Factor (Kzt) = | AP10: 1 | AQ10: (Avg)
D11: - Exempt from Torsional requirements | N11: Zone Dimensions (FT.) | AC11: =IF(E18<=7,(N4-T14*2),IF(AND(E18>7,E18<=27),(N4-(T14*2)),IF(AND(E18>27,E18<=45),(N4-(T14*4))*0))) -> 18 | AD11: =IF(E18<=7,(O4-(U14*2)),IF(AND(E18>7,E18<=45),(O4-(W14*4)),0)) -> 48 | AE11: <---Zone 1 | AO11: Wind Directionanlity Factor (Kd)= | AP11: 0.85
D12: - Effective Wind Area figured at 10 sq. ft. | N12: Zone 4: | P12: Zone 5: | R12: Zone 1: | T12: Zone 2: | V12: Zone 3: | AO12: Internal Pressure Coefficient (GCpi)= | AP12: =IF(AQ12="(enclosed)",-0.18,IF(AQ12="(Partially Enclosed)",-0.55,IF(AQ12="(open)",0,))) -> -0.18 | AQ12: (Enclosed)
D13: Wind Speed, V= | E13: 130 | F13: mph | N13: Endwall: | O13: Sidewall: | P13: Endwall: | Q13: Sidewall: | R13: Endwall: | S13: Sidewall: | T13: Endwall: | U13: Sidewall: | V13: Endwall: | W13: Sidewall: | AC13: =IF(N5="transverse / complex",(E15+(E17*((O4/2)/12))),IF(N5="gable / mono",(E15+(E17*((N4/2)/12))),0)) -> 15.625 | AD13: <---Ht. w/o parapet | AO13: Internal Pressure Coefficient (GCpi)= | AP13: =IF(AQ12="(enclosed)",0.18,IF(AQ12="(Partially Enclosed)",0.55,IF(AQ12="(open)",0))) -> 0.18
D14: Wind Exposure, λ= | E14: C | M14: Total Width (ft) each corner / side: | N14: - | O14: - | P14: =IF(MIN(AC5,AD5)<3,3,MIN(AC5,AD5)) -> 3 | Q14: =IF(MIN(AC6,AD6)<3,3,MIN(AC6,AD6)) -> 6 | R14: - | S14: - | T14: =IF(MIN(AC7,AD7)<3,3,MIN(AC7,AD7)) -> 3 | U14: =IF(MIN(AC6,AD6)<3,3,MIN(AC6,AD6)) -> 6 | V14: =IF(MIN(AC7,AD7)<3,3,MIN(AC7,AD7)) -> 3 | W14: =IF(MIN(AC6,AD6)<3,3,MIN(AC6,AD6)) -> 6 | AC14: =E15+E19 -> 15 | AD14: <---Ht. w/ parapet | AO14: Building Height and Exposure (λ=) | AP14: =IF(AND(AP3="B",AP4<=15),"1",IF(AND(AP3="B",AP4=20),"1",IF(AND(AP3="B",AP4=25),"1",IF(AND(AP3="B",AP4=30),"1",IF(AND(AP3="B",AP4=35),"1.05",IF(AND(AP3="B",AP4=40),"1.09",IF(AND(AP3="B",AP4=45),"1.12",IF(AND(AP3="B",AP4=50),"1.16",IF(AND(AP3="B",AP4=55),"1.19",IF(AND(AP3="B",AP4=60),"1.22",IF(AND(AP3="C",AP4<=15),"1.21",IF(AND(AP3="C",AP4=20),"1.29",IF(AND(AP3="C",AP4=25),"1.35",IF(AND(AP3="C",AP4=30),"1.4",IF(AND(AP3="C",AP4=35),"1.45",IF(AND(AP3="C",AP4=40),"1.49",IF(AND(AP3="C",AP4=45),"1.53",IF(AND(AP3="C",AP4=50),"1.56",IF(AND(AP3="C",AP4=55),"1.59",IF(AND(AP3="C",AP4=60),"1.62",IF(AND(AP3="D",AP4<=15),"1.47",IF(AND(AP3="D",AP4=20),"1.55",IF(AND(AP3="D",AP4=25),"1.61",IF(AND(AP3="D",AP4=30),"1.66",IF(AND(AP3="D",AP4=35),"1.7",IF(AND(AP3="D",AP4=40),"1.74",IF(AND(AP3="D",AP4=45),"1.78",IF(AND(AP3="D",AP4=50),"1.81",IF(AND(AP3="D",AP4=55),"1.84",IF(AND(AP3="D",AP4=60),"1.87",0)))))))))))))))))))))))))))))) -> 1.21
D15: Eave Height from grade= | E15: 15 | F15: ft. (Max 30') | M15: Total Length (ft): | N15: =SUM(N4-P15*2) -> 18 | O15: =SUM(O4-Q15*2) -> 48 | P15: =IF(MIN(AC5,AD5)<3,3,MIN(AC5,AD5)) -> 3 | Q15: =IF(MIN(AC6,AD6)<3,3,MIN(AC6,AD6)) -> 6 | R15: =IF(AC11<=0,"N/A",IF(E18<=7,(N4-T14*2),IF(AND(E18>7,E18<=27),(N4-(T14*2)),IF(AND(E18>27,E18<=45),(N4-(T14*4)),0)))) -> 18 | S15: =IF(AD11<=0,"N/A",IF(E18<=7,(O4-(U14*2)),IF(E18>7,(O4-(U14*4)),0))) -> 48 | T15: =IF(AC10<=0,"N/A",IF(E18<=7,(N4-(V15*2)),IF(E18>7,(N4-(V15*4)),0))) -> 18 | U15: =IF(E18<=7,(O4-(W15*2)),IF(E18>7,(O4-(W15*2)),0)) -> 48 | V15: =IF(MIN(AC5,AD5)<3,3,MIN(AC5,AD5)) -> 3 | W15: =IF(MIN(AC6,AD6)<3,3,MIN(AC6,AD6)) -> 6 | AO15: Velocity Pressure Exposure (Kz)= | AP15: =IF(AND(AP3="B",AP4<30),(2.01*((30+AP8)/1200)^(2/7)),IF(AND(AP3="B",AP4>=30),(2.01*((AP4+AP8)/1200)^(2/7)),IF(AP3="C",(2.01*((AP4+AP8)/900)^(2/9.5)),IF(AP3="D",(2.01*((AP4+AP8)/700)^(2/11.5)),0)))) -> 0.84888415
D16: h = | E16: =IF(E19>0,E15+E19,IF(E18<=10,E15,IF(N5="transverse / complex",(E15+(E17*((O4/2)/12)/2)),IF(N5="gable / mono",(E15+(E17*((N4/2)/12)/2)),E15+E19)))) -> 15 | P16: Each Corner | V16: Each Corner | AO16: Velocity Pressure (Qh)= | AP16: =(0.6*0.00256*AP15*AP10*AP11*AP9*(AP2^2)) -> 18.730323 | AQ16: psf
D17: Enter Roof Slope (decimals) = | E17: 0.25 | F17: in 12
D18: Roof Slope (Degrees) = | E18: =ATAN(E17/12)*(180/PI()) -> 1.1934894 | AN18: Window 1 | AQ18: Window 2 | AT18: Window 3 | AW18: Window 4 | AZ18: Window 5
D19: Parapet = | E19: 0 | AM19: Pos. Zone 4 | AN19: =(1-0.3*(LOG(E60)-LOG(10))/(LOG(500)-LOG(10))) -> #NUM! | AO19: =IF(E18<=10,AN19*0.9,AN19) -> #NUM! | AP19: =AO19-(AP12) -> #NUM! | AQ19: =(1-0.3*(LOG(E61)-LOG(10))/(LOG(500)-LOG(10))) -> #NUM! | AR19: =IF(E18<=10,AQ19*0.9,AQ19) -> #NUM! | AS19: =AR19-(AP12) -> #NUM! | AT19: =(1-0.3*(LOG(E62)-LOG(10))/(LOG(500)-LOG(10))) -> #NUM! | AU19: =IF(E18<=10,AT19*0.9,AT19) -> #NUM! | AV19: =AU19-(AP12) -> #NUM! | AW19: =(1-0.3*(LOG(E63)-LOG(10))/(LOG(500)-LOG(10))) -> #NUM! | AX19: =IF(E18<=10,AW19*0.9,AW19) -> #NUM! | AY19: =AX19-(AP12) -> #NUM! | AZ19: =(1-0.3*(LOG(E64)-LOG(10))/(LOG(500)-LOG(10))) -> #NUM! | BA19: =IF(E18<=10,AZ19*0.9,AZ19) -> #NUM! | BB19: =BA19-(AP12) -> #NUM!
D20: Overhang: | E20: No | AM20: Pos. Zone 5 | AN20: =(1-0.3*(LOG(E60)-LOG(10))/(LOG(500)-LOG(10))) -> #NUM! | AO20: =IF(E18<=10,AN20*0.9,AN20) -> #NUM! | AP20: =AO20-(AP12) -> #NUM! | AQ20: =(1-0.3*(LOG(E61)-LOG(10))/(LOG(500)-LOG(10))) -> #NUM! | AR20: =IF(E18<=10,AQ20*0.9,AQ20) -> #NUM! | AS20: =AR20-(AP12) -> #NUM! | AT20: =(1-0.3*(LOG(E62)-LOG(10))/(LOG(500)-LOG(10))) -> #NUM! | AU20: =IF(E18<=10,AT20*0.9,AT20) -> #NUM! | AV20: =AU20-(AP12) -> #NUM! | AW20: =(1-0.3*(LOG(E63)-LOG(10))/(LOG(500)-LOG(10))) -> #NUM! | AX20: =IF(E18<=10,AW20*0.9,AW20) -> #NUM! | AY20: =AX20-(AP12) -> #NUM! | AZ20: =(1-0.3*(LOG(E64)-LOG(10))/(LOG(500)-LOG(10))) -> #NUM! | BA20: =IF(E18<=10,AZ20*0.9,AZ20) -> #NUM! | BB20: =BA20-(AP12) -> #NUM!
D21: Topographic Factor (Kzt) = | E21: 1 | F21: (Avg) (Section 6.5.7.2) | AM21: Neg. Zone 4 | AN21: =-(1.1-0.3*(LOG(E60)-LOG(10))/(LOG(500)-LOG(10))) -> #NUM! | AO21: =IF(E18<=10,AN21*0.9,AN21) -> #NUM! | AP21: =AO21-(AP13) -> #NUM! | AQ21: =-(1.1-0.3*(LOG(E61)-LOG(10))/(LOG(500)-LOG(10))) -> #NUM! | AR21: =IF(E18<=10,AQ21*0.9,AQ21) -> #NUM! | AS21: =AR21-(AP13) -> #NUM! | AT21: =-(1.1-0.3*(LOG(E62)-LOG(10))/(LOG(500)-LOG(10))) -> #NUM! | AU21: =IF(E18<=10,AT21*0.9,AT21) -> #NUM! | AV21: =AU21-(AP13) -> #NUM! | AW21: =-(1.1-0.3*(LOG(E63)-LOG(10))/(LOG(500)-LOG(10))) -> #NUM! | AX21: =IF(E18<=10,AW21*0.9,AW21) -> #NUM! | AY21: =AX21-(AP13) -> #NUM! | AZ21: =-(1.1-0.3*(LOG(E64)-LOG(10))/(LOG(500)-LOG(10))) -> #NUM! | BA21: =IF(E18<=10,AZ21*0.9,AZ21) -> #NUM! | BB21: =BA21-(AP13) -> #NUM!
D22: Internal Pressure Coefficient (GCpi) | E22: +/- 0.18 | F22: (Enclosed or partially open) | AM22: Neg. Zone 5 | AN22: =-(1.4-0.6*(LOG(E60)-LOG(10))/(LOG(500)-LOG(10))) -> #NUM! | AO22: =IF(E18<=10,AN22*0.9,AN22) -> #NUM! | AP22: =AO22-(AP13) -> #NUM! | AQ22: =-(1.4-0.6*(LOG(E61)-LOG(10))/(LOG(500)-LOG(10))) -> #NUM! | AR22: =IF(E18<=10,AQ22*0.9,AQ22) -> #NUM! | AS22: =AR22-(AP13) -> #NUM! | AT22: =-(1.4-0.6*(LOG(E62)-LOG(10))/(LOG(500)-LOG(10))) -> #NUM! | AU22: =IF(E18<=10,AT22*0.9,AT22) -> #NUM! | AV22: =AU22-(AP13) -> #NUM! | AW22: =-(1.4-0.6*(LOG(E63)-LOG(10))/(LOG(500)-LOG(10))) -> #NUM! | AX22: =IF(E18<=10,AW22*0.9,AW22) -> #NUM! | AY22: =AX22-(AP13) -> #NUM! | AZ22: =-(1.4-0.6*(LOG(E64)-LOG(10))/(LOG(500)-LOG(10))) -> #NUM! | BA22: =IF(E18<=10,AZ22*0.9,AZ22) -> #NUM! | BB22: =BA22-(AP13) -> #NUM!
D23: Building Height and Exposure (λ=) | E23: =IF(AND(E16<=30,E14="B"),1,IF(AND(AND(E16>30),E16<=35,E14="B"),1.05,IF(AND(AND(E16>35),E16<=40,E14="B"),1.09,IF(AND(AND(E16>40),E16<=45,E14="B"),1.12,IF(AND(AND(E16>45),E16<=50,E14="B"),1.16,IF(AND(AND(E16>50),E16<=55,E14="B"),1.19,IF(AND(AND(E16>55),E16<=60,E14="B"),1.22,IF(AND(E16<=15,E14="C"),1.21,IF(AND(AND(E16>15),E16<=20,E14="C"),1.29,IF(AND(AND(E16>20),E16<=25,E14="C"),1.35,IF(AND(AND(E16>25),E16<=30,E14="C"),1.4,IF(AND(AND(E16>30),E16<=35,E14="C"),1.45,IF(AND(AND(E16>35),E16<=40,E14="C"),1.49,IF(AND(AND(E16>40),E16<=45,E14="C"),1.53,IF(AND(AND(E16>45),E16<=50,E14="C"),1.56,IF(AND(AND(E16>50),E16<=55,E14="C"),1.59,IF(AND(AND(E16>55),E16<=60,E14="C"),1.62,IF(AND(E16<=15,E14="d"),1.47,IF(AND(AND(E16>15),E16<=20,E14="d"),1.55,IF(AND(AND(E16>20),E16<=25,E14="d"),1.61,IF(AND(AND(E16>25),E16<=30,E14="d"),1.66,IF(AND(AND(E16>30),E16<=35,E14="d"),1.7,IF(AND(AND(E16>35),E16<=40,E14="d"),1.74,IF(AND(AND(E16>40),E16<=45,E14="d"),1.78,IF(AND(AND(E16>45),E16<=50,E14="d"),1.81,IF(AND(AND(E16>50),E16<=55,E14="d"),1.84,IF(AND(AND(E16>55),E16<=60,E14="d"),1.87,0))))))))))))))))))))))))))) -> 1.21 | F23: (Figure 6-3) | AN23: Door 1 | AQ23: Door 2 | AT23: Door 3
A24: pnet=λKztIPnet30 - (Section 6.4.2.2) | AM24: Pos. Zone 4 | AN24: =(1-0.3*(LOG(E72)-LOG(10))/(LOG(500)-LOG(10))) -> #NUM! | AO24: =IF(E18<=10,AN24*0.9,AN24) -> #NUM! | AP24: =AO24-(AP12) -> #NUM! | AQ24: =(1-0.3*(LOG(E73)-LOG(10))/(LOG(500)-LOG(10))) -> #VALUE! | AR24: =IF(E18<=10,AQ24*0.9,AQ24) -> #VALUE! | AS24: =AR24-(AP12) -> #VALUE! | AT24: =(1-0.3*(LOG(E74)-LOG(10))/(LOG(500)-LOG(10))) -> #NUM! | AU24: =IF(E18<=10,AT24*0.9,AT24) -> #NUM! | AV24: =AU24-(AP12) -> #NUM!
A25: Design Pressure (p) | AM25: Pos. Zone 5 | AN25: =(1-0.3*(LOG(E72)-LOG(10))/(LOG(500)-LOG(10))) -> #NUM! | AO25: =IF(E18<=10,AN25*0.9,AN25) -> #NUM! | AP25: =AO25-(AP12) -> #NUM! | AQ25: =(1-0.3*(LOG(E73)-LOG(10))/(LOG(500)-LOG(10))) -> #VALUE! | AR25: =IF(E18<=10,AQ25*0.9,AQ25) -> #VALUE! | AS25: =AR25-(AP12) -> #VALUE! | AT25: =(1-0.3*(LOG(E74)-LOG(10))/(LOG(500)-LOG(10))) -> #NUM! | AU25: =IF(E18<=10,AT25*0.9,AT25) -> #NUM! | AV25: =AU25-(AP12) -> #NUM!
A26: Allowable Stress Design | B26: Zone 4: | D26: Zone 5: | F26: Zone 1: | AM26: Neg. Zone 4 | AN26: =-(1.1-0.3*(LOG(E72)-LOG(10))/(LOG(500)-LOG(10))) -> #NUM! | AO26: =IF(E18<=10,AN26*0.9,AN26) -> #NUM! | AP26: =AO26-(AP13) -> #NUM! | AQ26: =-(1.1-0.3*(LOG(E73)-LOG(10))/(LOG(500)-LOG(10))) -> #VALUE! | AR26: =IF(E18<=10,AQ26*0.9,AQ26) -> #VALUE! | AS26: =AR26-(AP13) -> #VALUE! | AT26: =-(1.1-0.3*(LOG(E74)-LOG(10))/(LOG(500)-LOG(10))) -> #NUM! | AU26: =IF(E18<=10,AT26*0.9,AT26) -> #NUM! | AV26: =AU26-(AP13) -> #NUM!
B27: Postive | C27: Negative | D27: Postive | E27: Negative | F27: Postive | G27: Negative | AM27: Neg. Zone 5 | AN27: =-(1.4-0.6*(LOG(E72)-LOG(10))/(LOG(500)-LOG(10))) -> #NUM! | AO27: =IF(E18<=10,AN27*0.9,AN27) -> #NUM! | AP27: =AO27-(AP13) -> #NUM! | AQ27: =-(1.4-0.6*(LOG(E73)-LOG(10))/(LOG(500)-LOG(10))) -> #VALUE! | AR27: =IF(E18<=10,AQ27*0.9,AQ27) -> #VALUE! | AS27: =AR27-(AP13) -> #VALUE! | AT27: =-(1.4-0.6*(LOG(E74)-LOG(10))/(LOG(500)-LOG(10))) -> #NUM! | AU27: =IF(E18<=10,AT27*0.9,AT27) -> #NUM! | AV27: =AU27-(AP13) -> #NUM!
