Workbook
Name An: 'Calculation Tables'!$S$5:$S$15
Name Ani: 'Calculation Tables'!$S$5:$S$15
Name Animal: 'Calculation Tables'!$S$5:$S$15
Name bardindex: 'HVAC Reference'!$C$4:$E$12
Name bardsize: 'HVAC Reference'!$A$4:$A$12
Name bardvent: 'HVAC Reference'!$C$3:$E$3
Name CARa: 'Calculation Tables'!$G$3:$G$95
Name CFMtableDaikin: '2009 - 2021 IMC-UMC Multi-Zone'!$K$3:$M$10
Name CFMtableDaikin: '2009 - 2021 IMC-UMC Single Zone'!$G$3:$I$8
Name CFMtableDaikin: '2022 CA Multi-Zone Calculator'!$G$3:$I$8
Name CFMtableDaikin: '2022 CA Single Zone Calculator'!$G$3:$I$8
Name CFMtableDaikin: '2024 IMC-UMC Multi-Zone'!$K$3:$M$10
Name CFMtableDaikin: '2024 IMC-UMC Single'!$G$3:$I$8
Name CFMtableDaikin: '2025 CA Multi-Zone Calculator'!$J$5:$L$10
Name CFMtableDaikin: '2025 CA Single Zone Calculator'!$G$6:$I$11
Name CFMtableDaikin: #REF!
Name Co: 'Calculation Tables'!$S$18:$S$23
Name Coor: 'Calculation Tables'!$A$100:$A$104
Name Cor: 'Calculation Tables'!$S$18:$S$23
Name Dr: 'Calculation Tables'!$S$26:$S$30
Name Dry: 'Calculation Tables'!$A$64:$A$68
Name Ed: 'Calculation Tables'!$S$33:$S$48
Name EdCA: 'Calculation Tables'!$F$3:$F$16
Name Edu: 'Calculation Tables'!$A$21:$A$32
Name ERVINDEX: 'HVAC Reference'!$B$17:$B$18
Name ERVSIZE: 'HVAC Reference'!$A$17:$A$18
Name Fo: 'Calculation Tables'!$S$51:$S$58
Name FoCA: 'Calculation Tables'!$F$19:$F$22
Name Foo: 'Calculation Tables'!$S$51:$S$58
Name Food: 'Calculation Tables'!$A$58:$A$61
Name GenCA: 'Calculation Tables'!$F$25:$F$29
Name Ho: 'Calculation Tables'!$S$61:$S$68
Name Hot: 'Calculation Tables'!$A$43:$A$48
Name HotCA: 'Calculation Tables'!$F$32:$F$37
Name IMCocc1: 'Calculation Tables'!$T$3:$T$161
Name IMCoccDens: 'Calculation Tables'!$D$3:$D$97
Name IMCoccDensity: 'Calculation Tables'!$D$3:$D$104
Name IMCRa: 'Calculation Tables'!$C$3:$C$104
Name IMCRa1: 'Calculation Tables'!$V$3:$V$161
Name IMCRp: 'Calculation Tables'!$B$3:$B$104
Name IMCRp1: 'Calculation Tables'!$U$3:$U$161
Name IMCRp24: 'Calculation Tables'!$U$3:$U$161
Name IMCuse: 'Calculation Tables'!$A$3:$A$104
Name IMCuse1: 'Calculation Tables'!$S$3:$S$161
Name marairref: 'HVAC Reference'!$O$4:$Q$11
Name marvairsize: 'HVAC Reference'!$M$4:$M$11
Name marvairvent: 'HVAC Reference'!$O$3:$Q$3
Name MisCA: 'Calculation Tables'!$F$48:$F$60
Name MultiCO2: 'Calculation Tables'!$N$2:$N$95
Name NONE: 'Calculation Tables'!$A$3
Name NONE1: 'Calculation Tables'!$F$1
Name Of: 'Calculation Tables'!$S$71:$S$77
Name Off: 'Calculation Tables'!$A$5:$A$9
Name OffCA: 'Calculation Tables'!$F$40:$F$45
Name Ou: 'Calculation Tables'!$S$80:$S$97
Name Out: 'Calculation Tables'!$S$80:$S$97
Name Pu: 'Calculation Tables'!$S$100:$S$107
Name Pub: 'Calculation Tables'!$A$12:$A$18
Name PubCA: 'Calculation Tables'!$F$63:$F$70
Name Re: 'Calculation Tables'!$S$110:$S$115

Sheet HVAC Reference
A2: BARD WALL MOUNT OUTDOOR AIR VENTILATION: | G2: DAIKIN ROOF TOP OUTDOOR AIR VENTILATION: | M2: Marvair WALL MOUNT OUTDOOR AIR VENTILATION:
A3: HVAC SIZE: | B3: SYSTEM CFM OUTPUT: | C3: FAD | D3: CRV | E3: ECONOMIZER | G3: HVAC SIZE: | H3: SYSTEM CFM OUTPUT: | I3: FAD | J3: CRV | K3: ECONOMIZER | M3: HVAC SIZE: | N3: SYSTEM CFM OUTPUT: | O3: FAD | P3: CRV | Q3: ECONOMIZER
A4: N/A | B4: 0 | C4: 0 | D4: 0 | E4: 0 | G4: N/A | H4: 0 | I4: 0 | J4: 0 | K4: 0 | M4: N/A | N4: 0 | O4: 0 | P4: 0 | Q4: 0
A5: 1 TON | B5: 420 | C5: =SUM(B5*0.25) -> 105 | D5: =SUM(B5*0.5) -> 210 | E5: =SUM(B5*1) -> 420 | G5: 2 TON | H5: 780 | I5: =SUM(H5*0.25) -> 195 | J5: =SUM(H5*0.5) -> 390 | K5: =SUM(H5*1) -> 780 | M5: 1.5 TON | N5: 660 | O5: =SUM(N5*0.15) -> 99 | P5: =SUM(N5*0.5) -> 330 | Q5: =SUM(N5*1) -> 660
A6: 1.5 TON | B6: 600 | C6: =SUM(B6*0.25) -> 150 | D6: =SUM(B6*0.5) -> 300 | E6: =SUM(B6*1) -> 600 | G6: 2.5 TON | H6: 900 | I6: =SUM(H6*0.25) -> 225 | J6: =SUM(H6*0.5) -> 450 | K6: =SUM(H6*1) -> 900 | M6: 2 TON | N6: 850 | O6: =SUM(N6*0.15) -> 127.5 | P6: =SUM(N6*0.5) -> 425 | Q6: =SUM(N6*1) -> 850
A7: 2 TON | B7: 800 | C7: =SUM(B7*0.25) -> 200 | D7: =SUM(B7*0.5) -> 400 | E7: =SUM(B7*1) -> 800 | G7: 3 TON | H7: 1195 | I7: =SUM(H7*0.25) -> 298.75 | J7: =SUM(H7*0.5) -> 597.5 | K7: =SUM(H7*1) -> 1195 | M7: 2.5 TON | N7: 1070 | O7: =SUM(N7*0.15) -> 160.5 | P7: =SUM(N7*0.5) -> 535 | Q7: =SUM(N7*1) -> 1070
A8: 2.5 TON | B8: 950 | C8: =SUM(B8*0.25) -> 237.5 | D8: =SUM(B8*0.5) -> 475 | E8: =SUM(B8*1) -> 950 | G8: 3.5 TON | H8: 1420 | I8: =SUM(H8*0.25) -> 355 | J8: =SUM(H8*0.5) -> 710 | K8: =SUM(H8*1) -> 1420 | M8: 3 TON | N8: 1200 | O8: =SUM(N8*0.15) -> 180 | P8: =SUM(N8*0.5) -> 600 | Q8: =SUM(N8*1) -> 1200
A9: 3 TON | B9: 1150 | C9: =SUM(B9*0.25) -> 287.5 | D9: =SUM(B9*0.5) -> 575 | E9: =SUM(B9*1) -> 1150 | G9: 4 TON | H9: 1605 | I9: =SUM(H9*0.25) -> 401.25 | J9: =SUM(H9*0.5) -> 802.5 | K9: =SUM(H9*1) -> 1605 | M9: 3.5 TON | N9: 1250 | O9: =SUM(N9*0.15) -> 187.5 | P9: =SUM(N9*0.5) -> 625 | Q9: =SUM(N9*1) -> 1250
A10: 3.5 TON | B10: 1350 | C10: =SUM(B10*0.25) -> 337.5 | D10: =SUM(B10*0.5) -> 675 | E10: =SUM(B10*1) -> 1350 | G10: 5 TON | H10: 1700 | I10: =SUM(H10*0.25) -> 425 | J10: =SUM(H10*0.5) -> 850 | K10: =SUM(H10*1) -> 1700 | M10: 4 TON | N10: 1400 | O10: =SUM(N10*0.15) -> 210 | P10: =SUM(N10*0.5) -> 700 | Q10: =SUM(N10*1) -> 1400
A11: 4 TON | B11: 1550 | C11: =SUM(B11*0.25) -> 387.5 | D11: =SUM(B11*0.5) -> 775 | E11: =SUM(B11*1) -> 1550 | M11: 5 TON | N11: 1750 | O11: =SUM(N11*0.15) -> 262.5 | P11: =SUM(N11*0.5) -> 875 | Q11: =SUM(N11*1) -> 1750
A12: 5 TON | B12: 1750 | C12: =SUM(B12*0.25) -> 437.5 | D12: =SUM(B12*0.5) -> 875 | E12: =SUM(B12*1) -> 1750
A15: THRU-WALL ERV
A16: HVAC SIZE: | B16: SYSTEM CFM OUTPUT:
A17: N/A | B17: 0
A18: THRU-WALL ERV | B18: 30

Sheet Natural Ventilation Calc
A1: NATURAL VENTILATION CALCULATION: | I1: Code: | J1: IMC
A2: =IF(J3="yes","C403.2.5 DOAS","") -> C403.2.5 DOAS | I2: Building Sq. Ft.: | J2: 1400
I3: Is DOAS provided for Washington? | J3: Yes
A4: ="NATURAL VENTILATION PER "&J1&" SECTION 402 (4% OF FLOOR AREA)" -> NATURAL VENTILATION PER IMC SECTION 402 (4% OF FLOOR AREA)
A7: =J2 -> 1400 | B7: SQ. FT. X 4% = | C7: =SUM(A7*0.04) -> 56 | D7: SQ. FT. REQUIRED | I7: Windows
I8: QTY: | J8: Type of Window: | K8: Width (Inches): | L8: Height (Inches): | M8: Total SQ. FT. of Glazing: | N8: Operable Sq. Ft.:
A9: =IF(N15>0,"NET TOTAL OF WINDOW OPENING(S) = "&N15&" SQ. FT. PROVIDED","NET TOTAL OF WINDOW OPENING(S) = 0 SQ. FT. PROVIDED") -> NET TOTAL OF WINDOW OPENING(S) = 5.4 SQ. FT. PROVIDED | I9: 1 | J9: V.S. | K9: 48 | L9: 36 | M9: =SUM(((K9*L9)/144)*I9) -> 12 | N9: =IF(OR(J9="FIXED",J9="STOREFRONT"),0,SUM(((K9*L9)/144)*I9)*0.45) -> 5.4
I10: 0 | J10: V.S. | K10: 0 | L10: 0 | M10: =SUM(((K10*L10)/144)*I10) -> 0 | N10: =IF(OR(J10="FIXED",J10="STOREFRONT"),0,SUM(((K10*L10)/144)*I10)*0.45) -> 0
I11: 0 | J11: V.S. | K11: 0 | L11: 0 | M11: =SUM(((K11*L11)/144)*I11) -> 0 | N11: =IF(OR(J11="FIXED",J11="STOREFRONT"),0,SUM(((K11*L11)/144)*I11)*0.45) -> 0
A12: =IF(N25>0,"NET TOTAL OF DOOR OPENING(S) = "&N25&" SQ. FT. PROVIDED","NET TOTAL OF DOOR OPENING(S) = 0 SQ. FT. PROVIDED") -> NET TOTAL OF DOOR OPENING(S) = 20 SQ. FT. PROVIDED | I12: 0 | J12: V.S. | K12: 0 | L12: 0 | M12: =SUM(((K12*L12)/144)*I12) -> 0 | N12: =IF(OR(J12="FIXED",J12="STOREFRONT"),0,SUM(((K12*L12)/144)*I12)*0.45) -> 0
I13: 0 | J13: V.S. | K13: 0 | L13: 0 | M13: =SUM(((K13*L13)/144)*I13) -> 0 | N13: =IF(OR(J13="FIXED",J13="STOREFRONT"),0,SUM(((K13*L13)/144)*I13)*0.45) -> 0
I14: 0 | J14: V.S. | K14: 0 | L14: 0 | M14: =SUM(((K14*L14)/144)*I14) -> 0 | N14: =IF(OR(J14="FIXED",J14="STOREFRONT"),0,SUM(((K14*L14)/144)*I14)*0.45) -> 0
A15: =IF(AND(N15>0,N25>0),"TOTAL "&N26&" SQ.FT. OF WINDOW AND DOOR OPENINGS PROVIDED",IF(AND(N15>0,N25=0),"TOTAL "&N26&" SQ.FT. OF WINDOW OPENINGS PROVIDED",IF(AND(N15=0,N25>0),"TOTAL "&N26&" SQ.FT. OF DOOR OPENINGS PROVIDED","NO NATURAL VENTILATION PROVIDED"))) -> TOTAL 25.4 SQ.FT. OF WINDOW AND DOOR OPENINGS PROVIDED | I15: Total: | M15: =SUM(M9:M14) -> 12 | N15: =SUM(N9:N14) -> 5.4
I17: Doors
A18: --->> | I18: QTY: | J18: Type of Door: | K18: Width (Inches): | L18: Height (Inches): | M18: Total SQ. FT. of Doors: | N18: Operable Sq. Ft.:
I19: 1 | J19: Swinging | K19: 36 | L19: 80 | M19: =SUM((K19*L19)/144)*I19 -> 20 | N19: =IF(J19="SLIDER",SUM((((K19/2)-2.5)*L19)/144)*I19,SUM((K19*L19)/144)*I19) -> 20
A20: COPY ABOVE AND "PASTESPEC" INTO AUTOCAD | I20: 0 | J20: Swinging | K20: 0 | L20: 0 | M20: =SUM((K20*L20)/144)*I20 -> 0 | N20: =IF(J20="SLIDER",SUM((((K20/2)-2.5)*L20)/144)*I20,SUM((K20*L20)/144)*I20) -> 0
I21: 0 | J21: Swinging | K21: 0 | L21: 0 | M21: =SUM((K21*L21)/144)*I21 -> 0 | N21: =IF(J21="SLIDER",SUM((((K21/2)-2.5)*L21)/144)*I21,SUM((K21*L21)/144)*I21) -> 0
I22: 0 | J22: Swinging | K22: 0 | L22: 0 | M22: =SUM((K22*L22)/144)*I22 -> 0 | N22: =IF(J22="SLIDER",SUM((((K22/2)-2.5)*L22)/144)*I22,SUM((K22*L22)/144)*I22) -> 0
I23: 0 | J23: Swinging | K23: 0 | L23: 0 | M23: =SUM((K23*L23)/144)*I23 -> 0 | N23: =IF(J23="SLIDER",SUM((((K23/2)-2.5)*L23)/144)*I23,SUM((K23*L23)/144)*I23) -> 0
I24: 0 | J24: Swinging | K24: 0 | L24: 0 | M24: =SUM((K24*L24)/144)*I24 -> 0 | N24: =IF(J24="SLIDER",SUM((((K24/2)-2.5)*L24)/144)*I24,SUM((K24*L24)/144)*I24) -> 0
I25: Total: | M25: =SUM(M19:M24) -> 20 | N25: =SUM(N19:N24) -> 20
L26: Total of Windows & Doors: | N26: =IF(AND(N15>0,N25>0),SUM(N15+N25),IF(AND(N15>0,N25=0),SUM(N15),IF(AND(N15=0,N25>0),SUM(N25),0))) -> 25.4

Sheet 2009 - 2021 IMC-UMC Single Zone
A1: Use | B1: FRESH AIR CALCULATION
A2: OFFICES: | B2: OFFICE SPACE | C2: Floor Area (Az): | D2: 0 | E2: <--Enter Sq. Ft.
A3: ------->>>> DON'T COPY AND PASTE THIS PORTION ON PLANS | B3: PEOPLE OUTDOOR FLOW RATE (Rp): | D3: =INDEX(IMCRp,MATCH(B2,IMCuse,0)) -> 5 | G3: Type of HVAC: | H3: BARD | P3: N/A:
B4: AREA OUTDOOR FLOW RATE (Ra): | D4: =INDEX(IMCRa,MATCH(B2,IMCuse,0)) -> 0.06 | P4: OFFICES:
B5: OCCUPANT LOAD DENSITY / 1000 SQ. FT.: | D5: =INDEX(IMCoccDensity,MATCH(B2,IMCuse,0)) -> 5 | F5: HVAC SIZE: | G5: =IF(H3="THRU-WALL ERV","# OF ERV'S:","# OF A/C's:") -> # OF A/C's: | H5: VENTILATION: | I5: VENT RATE: | P5: PUBLIC USES:
B6: OCCUPANT LOAD OF SPACE (Pz): | D6: =ROUNDUP(((D5/1000)*D2),0) -> 0 | F6: 3 TON | G6: 1 | H6: FAD | I6: =IF(AND(H3="thru-wall erv",OR(F6="1 ton",F6="1.5 ton",F6="2 ton",F6="2.5 ton",F6="3 ton",F6="3.5 ton",F6="4 ton",F6="5 ton")),"-",IF(H3="bard",INDEX(bardindex,MATCH(F6,bardsize,0),MATCH(H6,bardvent,0))*G6,IF(H3="RTU",INDEX(rturef,MATCH(F6,rtusize,0),MATCH(H6,rtuvent,0))*G6,IF(H3="MARVAIR",INDEX(marairref,MATCH(F6,marvairsize,0),MATCH(H6,marvairvent,0))*G6,IF(H3="THRU-WALL ERV",INDEX(ERVINDEX,MATCH(F6,ERVSIZE,0))*G6,0))))) -> 287.5 | P6: EDUCATION:
B7: OUTDOOR AIR REQUIRED (Vbz=RpPz+RaAz): | D7: =SUM(D3*D6)+(D4*D2) -> 0 | F7: 4 TON | G7: 0 | H7: FAD | I7: =IF(AND(H3="thru-wall erv",OR(F7="1 ton",F7="1.5 ton",F7="2 ton",F7="2.5 ton",F7="3 ton",F7="3.5 ton",F7="4 ton",F7="5 ton")),"-",IF(H3="bard",INDEX(bardindex,MATCH(F7,bardsize,0),MATCH(H7,bardvent,0))*G7,IF(H3="RTU",INDEX(rturef,MATCH(F7,rtusize,0),MATCH(H7,rtuvent,0))*G7,IF(H3="MARVAIR",INDEX(marairref,MATCH(F7,marvairsize,0),MATCH(H7,marvairvent,0))*G7,IF(H3="THRU-WALL ERV",INDEX(ERVINDEX,MATCH(F7,ERVSIZE,0))*G7,0))))) -> 0 | P7: WORK ROOMS:
B8: TOTAL FRESH AIR SUPPLIED: | D8: =SUM(I6:I8) -> 287.5 | F8: 5 TON | G8: 0 | H8: FAD | I8: =IF(AND(H3="thru-wall erv",OR(F8="1 ton",F8="1.5 ton",F8="2 ton",F8="2.5 ton",F8="3 ton",F8="3.5 ton",F8="4 ton",F8="5 ton")),"-",IF(H3="bard",INDEX(bardindex,MATCH(F8,bardsize,0),MATCH(H8,bardvent,0))*G8,IF(H3="RTU",INDEX(rturef,MATCH(F8,rtusize,0),MATCH(H8,rtuvent,0))*G8,IF(H3="MARVAIR",INDEX(marairref,MATCH(F8,marvairsize,0),MATCH(H8,marvairvent,0))*G8,IF(H3="THRU-WALL ERV",INDEX(ERVINDEX,MATCH(F8,ERVSIZE,0))*G8,0))))) -> 0 | P8: HOTELS, MOTELS, RESORTS AND DORMATORIES:
B9: RESULTS: | C9: =IF(D7>D8,""&D8&" CFM < "&D7&" CFM, THEREFORE NG",IF(D7<D8,""&D8&" CFM > "&D7&" CFM, THEREFORE OK",0)) -> 287.5 CFM > 0 CFM, THEREFORE OK | P9: RETAIL STORES, SALES FLOOR AND SHOWROOM FLOORS:
P10: FOOD AND BEVERAGE SERVICE:
F11: FOR 100% OUTSIDE AIR, USE ECONOMIZER OPTION | P11: DRY CLEANERS, LAUNDRIES:
P12: SPORTS AND AMUSEMENT:
B13: VALUE(S) ABOVE CAN BE FOUND IN: | P13: STORAGE:
B14: IMC: | C14: Table 403.3.1.1 / Zone Calc: Section 403.3.1.1.1.1 | P14: THEATERS:
B15: UMC: | C15: Table 402.1 / Zone Calc: Section 403.2.1 | P15: SPECIALTY SHOPS:
B16: ASHREA: | C16: Table 6-1 / Zone Calc: Section 6.2.4.1 | P16: TRANSPORTATION:
P17: CORRECTIONAL FACILITIES:

Sheet 2009 - 2021 IMC-UMC Multi-Zone
B1: FRESH AIR CALCULATION
A2: USE: | B2: SPACE: | C2: SQUARE FOOTAGE OF AREA (Az): | D2: PEOPLE OUTDOOR FLOW RATE (Rp): | E2: AREA OUTDOOR FLOW RATE (Ra): | F2: OCCUPANT DENSITY /1000 sq. ft.: | G2: OCCUPANT LOAD OF SPACE (Pz) | H2: OUTDOOR AIR REQUIRED (Vbz=RpPz+RaAz):
A3: OFFICES: | B3: OFFICE SPACE | C3: 0 | D3: =INDEX(IMCRp,MATCH(B3,IMCuse,0)) -> 5 | E3: =INDEX(IMCRa,MATCH(B3,IMCuse,0)) -> 0.06 | F3: =INDEX(IMCoccDensity,MATCH(B3,IMCuse,0)) -> 5 | G3: =ROUNDUP(((F3/1000)*C3),0) -> 0 | H3: =SUM(D3*G3)+(E3*C3) -> 0 | K3: Type of HVAC: | L3: BARD | P3: N/A:
A4: N/A: | B4: N/A | C4: 0 | D4: =INDEX(IMCRp,MATCH(B4,IMCuse,0)) -> 0 | E4: =INDEX(IMCRa,MATCH(B4,IMCuse,0)) -> 0 | F4: =INDEX(IMCoccDensity,MATCH(B4,IMCuse,0)) -> 0 | G4: =ROUNDUP(((F4/1000)*C4),0) -> 0 | H4: =SUM(D4*G4)+(E4*C4) -> 0 | P4: OFFICES:
A5: N/A: | B5: N/A | C5: 0 | D5: =INDEX(IMCRp,MATCH(B5,IMCuse,0)) -> 0 | E5: =INDEX(IMCRa,MATCH(B5,IMCuse,0)) -> 0 | F5: =INDEX(IMCoccDensity,MATCH(B5,IMCuse,0)) -> 0 | G5: =ROUNDUP(((F5/1000)*C5),0) -> 0 | H5: =SUM(D5*G5)+(E5*C5) -> 0 | J5: HVAC SIZE: | K5: # OF A/C's: | L5: VENTILATION: | M5: VENT RATE: | P5: PUBLIC USES:
A6: N/A: | B6: N/A | C6: 0 | D6: =INDEX(IMCRp,MATCH(B6,IMCuse,0)) -> 0 | E6: =INDEX(IMCRa,MATCH(B6,IMCuse,0)) -> 0 | F6: =INDEX(IMCoccDensity,MATCH(B6,IMCuse,0)) -> 0 | G6: =ROUNDUP(((F6/1000)*C6),0) -> 0 | H6: =SUM(D6*G6)+(E6*C6) -> 0 | J6: 3 TON | K6: 1 | L6: FAD | M6: =IF(AND(L3="thru-wall erv",OR(J6="1 ton",J6="1.5 ton",J6="2 ton",J6="2.5 ton",J6="3 ton",J6="3.5 ton",J6="4 ton",J6="5 ton")),"-",IF(L3="bard",INDEX(bardindex,MATCH(J6,bardsize,0),MATCH(L6,bardvent,0))*K6,IF(L3="RTU",INDEX(rturef,MATCH(J6,rtusize,0),MATCH(L6,rtuvent,0))*K6,IF(L3="MARVAIR",INDEX(marairref,MATCH(J6,marvairsize,0),MATCH(L6,marvairvent,0))*K6,IF(L3="THRU-WALL ERV",INDEX(ERVINDEX,MATCH(J6,ERVSIZE,0))*K6,0))))) -> 287.5 | P6: EDUCATION:
A7: N/A: | B7: N/A | C7: 0 | D7: =INDEX(IMCRp,MATCH(B7,IMCuse,0)) -> 0 | E7: =INDEX(IMCRa,MATCH(B7,IMCuse,0)) -> 0 | F7: =INDEX(IMCoccDensity,MATCH(B7,IMCuse,0)) -> 0 | G7: =ROUNDUP(((F7/1000)*C7),0) -> 0 | H7: =SUM(D7*G7)+(E7*C7) -> 0 | J7: N/A | K7: 0 | L7: FAD | M7: =IF(AND(L3="thru-wall erv",OR(J7="1 ton",J7="1.5 ton",J7="2 ton",J7="2.5 ton",J7="3 ton",J7="3.5 ton",J7="4 ton",J7="5 ton")),"-",IF(L3="bard",INDEX(bardindex,MATCH(J7,bardsize,0),MATCH(L7,bardvent,0))*K7,IF(L3="RTU",INDEX(rturef,MATCH(J7,rtusize,0),MATCH(L7,rtuvent,0))*K7,IF(L3="MARVAIR",INDEX(marairref,MATCH(J7,marvairsize,0),MATCH(L7,marvairvent,0))*K7,IF(L3="THRU-WALL ERV",INDEX(ERVINDEX,MATCH(J7,ERVSIZE,0))*K7,0))))) -> 0 | P7: WORK ROOMS:
A8: ------->>>> DON'T COPY AND PASTE THIS PORTION ON PLANS | B8: TOTAL OUTDOOR AIR REQUIRED: | D8: =SUM(H3:H7) -> 0 | E8: RESULTS: | G8: =IF(D8>D9,""&D9&" CFM < "&D8&" CFM, THEREFORE NG",IF(D8<D9,""&D9&" CFM > "&D8&" CFM, THEREFORE OK",0)) -> 287.5 CFM > 0 CFM, THEREFORE OK | J8: N/A | K8: 0 | L8: FAD | M8: =IF(AND(L3="thru-wall erv",OR(J8="1 ton",J8="1.5 ton",J8="2 ton",J8="2.5 ton",J8="3 ton",J8="3.5 ton",J8="4 ton",J8="5 ton")),"-",IF(L3="bard",INDEX(bardindex,MATCH(J8,bardsize,0),MATCH(L8,bardvent,0))*K8,IF(L3="RTU",INDEX(rturef,MATCH(J8,rtusize,0),MATCH(L8,rtuvent,0))*K8,IF(L3="MARVAIR",INDEX(marairref,MATCH(J8,marvairsize,0),MATCH(L8,marvairvent,0))*K8,IF(L3="THRU-WALL ERV",INDEX(ERVINDEX,MATCH(J8,ERVSIZE,0))*K8,0))))) -> 0 | P8: HOTELS, MOTELS, RESORTS AND DORMATORIES:
B9: TOTAL FRESH AIR SUPPLIED: | D9: =SUM(M6:M10) -> 287.5 | J9: N/A | K9: 0 | L9: FAD | M9: =IF(AND(L3="thru-wall erv",OR(J9="1 ton",J9="1.5 ton",J9="2 ton",J9="2.5 ton",J9="3 ton",J9="3.5 ton",J9="4 ton",J9="5 ton")),"-",IF(L3="bard",INDEX(bardindex,MATCH(J9,bardsize,0),MATCH(L9,bardvent,0))*K9,IF(L3="RTU",INDEX(rturef,MATCH(J9,rtusize,0),MATCH(L9,rtuvent,0))*K9,IF(L3="MARVAIR",INDEX(marairref,MATCH(J9,marvairsize,0),MATCH(L9,marvairvent,0))*K9,IF(L3="THRU-WALL ERV",INDEX(ERVINDEX,MATCH(J9,ERVSIZE,0))*K9,0))))) -> 0 | P9: RETAIL STORES, SALES FLOOR AND SHOWROOM FLOORS:
J10: N/A | K10: 0 | L10: FAD | M10: =IF(AND(L3="thru-wall erv",OR(J10="1 ton",J10="1.5 ton",J10="2 ton",J10="2.5 ton",J10="3 ton",J10="3.5 ton",J10="4 ton",J10="5 ton")),"-",IF(L3="bard",INDEX(bardindex,MATCH(J10,bardsize,0),MATCH(L10,bardvent,0))*K10,IF(L3="RTU",INDEX(rturef,MATCH(J10,rtusize,0),MATCH(L10,rtuvent,0))*K10,IF(L3="MARVAIR",INDEX(marairref,MATCH(J10,marvairsize,0),MATCH(L10,marvairvent,0))*K10,IF(L3="THRU-WALL ERV",INDEX(ERVINDEX,MATCH(J10,ERVSIZE,0))*K10,0))))) -> 0 | P10: FOOD AND BEVERAGE SERVICE:
P11: DRY CLEANERS, LAUNDRIES:
P12: SPORTS AND AMUSEMENT:
C13: VALUE(S) ABOVE CAN BE FOUND IN: | J13: FOR 100% OUTSIDE AIR, USE ECONOMIZER OPTION | P13: STORAGE:
C14: IMC: | D14: Table 403.3.1.1 / Zone Calc: Section 403.3.1.1.1.1 | P14: THEATERS:
C15: UMC: | D15: Table 402.1 / Zone Calc: Section 403.2.1 | P15: SPECIALTY SHOPS:
C16: ASHREA 62.1: | D16: Table 6-1 / Zone Calc: Section 6.2.4.1 | P16: TRANSPORTATION:
P17: CORRECTIONAL FACILITIES:

Sheet 2024 IMC-UMC Single
A1: Use | B1: FRESH AIR CALCULATION
A2: Offices: | B2: Office spaces | C2: Floor Area (Az): | D2: 0 | E2: <--Enter Sq. Ft.
A3: ------->>>> DON'T COPY AND PASTE THIS PORTION ON PLANS | B3: PEOPLE OUTDOOR FLOW RATE (Rp): | D3: =INDEX(IMCRp1,MATCH(B2,IMCuse1,0)) -> 5 | G3: Type of HVAC: | H3: BARD | P3: N/A:
B4: AREA OUTDOOR FLOW RATE (Ra): | D4: =INDEX(IMCRa1,MATCH(B2,IMCuse1,0)) -> 0.06 | P4: Animal facilities:
B5: OCCUPANT LOAD DENSITY / 1000 SQ. FT.: | D5: =INDEX(IMCocc1,MATCH(B2,IMCuse1,0)) -> 5 | F5: HVAC SIZE: | G5: # OF A/C's: | H5: VENTILATION: | I5: VENT RATE: | P5: Correction facilities:
B6: OCCUPANT LOAD OF SPACE (Pz): | D6: =ROUNDUP(((D5/1000)*D2),0) -> 0 | F6: 3 TON | G6: 2 | H6: FAD | I6: =IF(AND(H3="thru-wall erv",OR(F6="1 ton",F6="1.5 ton",F6="2 ton",F6="2.5 ton",F6="3 ton",F6="3.5 ton",F6="4 ton",F6="5 ton")),"-",IF(H3="bard",INDEX(bardindex,MATCH(F6,bardsize,0),MATCH(H6,bardvent,0))*G6,IF(H3="RTU",INDEX(rturef,MATCH(F6,rtusize,0),MATCH(H6,rtuvent,0))*G6,IF(H3="MARVAIR",INDEX(marairref,MATCH(F6,marvairsize,0),MATCH(H6,marvairvent,0))*G6,IF(H3="THRU-WALL ERV",INDEX(ERVINDEX,MATCH(F6,ERVSIZE,0))*G6,0))))) -> 575 | P6: Dry cleaners, laundries:
B7: OUTDOOR AIR REQUIRED (Vbz=RpPz+RaAz): | D7: =SUM(D3*D6)+(D4*D2) -> 0 | F7: 4 TON | G7: 0 | H7: FAD | I7: =IF(AND(H3="thru-wall erv",OR(F7="1 ton",F7="1.5 ton",F7="2 ton",F7="2.5 ton",F7="3 ton",F7="3.5 ton",F7="4 ton",F7="5 ton")),"-",IF(H3="bard",INDEX(bardindex,MATCH(F7,bardsize,0),MATCH(H7,bardvent,0))*G7,IF(H3="RTU",INDEX(rturef,MATCH(F7,rtusize,0),MATCH(H7,rtuvent,0))*G7,IF(H3="MARVAIR",INDEX(marairref,MATCH(F7,marvairsize,0),MATCH(H7,marvairvent,0))*G7,IF(H3="THRU-WALL ERV",INDEX(ERVINDEX,MATCH(F7,ERVSIZE,0))*G7,0))))) -> 0 | P7: Education:
B8: TOTAL FRESH AIR SUPPLIED: | D8: =SUM(I6:I8) -> 575 | F8: 4 TON | G8: 0 | H8: FAD | I8: =IF(AND(H3="thru-wall erv",OR(F8="1 ton",F8="1.5 ton",F8="2 ton",F8="2.5 ton",F8="3 ton",F8="3.5 ton",F8="4 ton",F8="5 ton")),"-",IF(H3="bard",INDEX(bardindex,MATCH(F8,bardsize,0),MATCH(H8,bardvent,0))*G8,IF(H3="RTU",INDEX(rturef,MATCH(F8,rtusize,0),MATCH(H8,rtuvent,0))*G8,IF(H3="MARVAIR",INDEX(marairref,MATCH(F8,marvairsize,0),MATCH(H8,marvairvent,0))*G8,IF(H3="THRU-WALL ERV",INDEX(ERVINDEX,MATCH(F8,ERVSIZE,0))*G8,0))))) -> 0 | P8: Food and beverage service:
B9: RESULTS: | C9: =IF(D7>D8,""&D8&" CFM < "&D7&" CFM, THEREFORE NG",IF(D7<D8,""&D8&" CFM > "&D7&" CFM, THEREFORE OK",0)) -> 575 CFM > 0 CFM, THEREFORE OK | P9: Hotels, motels, resorts and domitories:
P10: Offices:
F11: FOR 100% OUTSIDE AIR, USE ECONOMIZER OPTION | P11: Outpatien healthcar facilities:
P12: Public spaces:
B13: VALUE(S) ABOVE CAN BE FOUND IN: | P13: Retial stores, sales floors, and show room floors:
B14: IMC: | C14: Table 403.3.1.1 / Zone Calc: Section 403.3.1.1.1.1 | P14: Specialty shops:
B15: UMC: | C15: Table 402.1 / Zone Calc: Section 403.2.1 | P15: Sports and amusement:
B16: ASHREA: | C16: Table 6-1 / Zone Calc: Section 6.2.4.1 | P16: Storage:
P17: Theaters:
P18: Transportation:
P19: Workrooms:

Sheet 2024 IMC-UMC Multi-Zone
B1: FRESH AIR CALCULATION
A2: USE: | B2: SPACE: | C2: SQUARE FOOTAGE OF AREA (Az): | D2: PEOPLE OUTDOOR FLOW RATE (Rp): | E2: AREA OUTDOOR FLOW RATE (Ra): | F2: OCCUPANT DENSITY /1000 sq. ft.: | G2: OCCUPANT LOAD OF SPACE (Pz) | H2: OUTDOOR AIR REQUIRED (Vbz=RpPz+RaAz):
A3: OFFICES: | B3: Office spaces | C3: 0 | D3: =INDEX(IMCRp1,MATCH(B3,IMCuse1,0)) -> 5 | E3: =INDEX(IMCRa1,MATCH(B3,IMCuse1,0)) -> 0.06 | F3: =INDEX(IMCocc1,MATCH(B3,IMCuse1,0)) -> 5 | G3: =ROUNDUP(((F3/1000)*C3),0) -> 0 | H3: =SUM(D3*G3)+(E3*C3) -> 0 | K3: Type of HVAC: | L3: BARD | P3: N/A:
A4: N/A: | B4: N/A | C4: 0 | D4: =INDEX(IMCRp1,MATCH(B4,IMCuse1,0)) -> 0 | E4: =INDEX(IMCRa1,MATCH(B4,IMCuse1,0)) -> 0 | F4: =INDEX(IMCocc1,MATCH(B4,IMCuse1,0)) -> 0 | G4: =ROUNDUP(((F4/1000)*C4),0) -> 0 | H4: =SUM(D4*G4)+(E4*C4) -> 0 | P4: Animal facilities:
A5: N/A: | B5: N/A | C5: 0 | D5: =INDEX(IMCRp1,MATCH(B5,IMCuse1,0)) -> 0 | E5: =INDEX(IMCRa1,MATCH(B5,IMCuse1,0)) -> 0 | F5: =INDEX(IMCocc1,MATCH(B5,IMCuse1,0)) -> 0 | G5: =ROUNDUP(((F5/1000)*C5),0) -> 0 | H5: =SUM(D5*G5)+(E5*C5) -> 0 | J5: HVAC SIZE: | K5: # OF A/C's: | L5: VENTILATION: | M5: VENT RATE: | P5: Correction facilities:
A6: N/A: | B6: N/A | C6: 0 | D6: =INDEX(IMCRp1,MATCH(B6,IMCuse1,0)) -> 0 | E6: =INDEX(IMCRa1,MATCH(B6,IMCuse1,0)) -> 0 | F6: =INDEX(IMCocc1,MATCH(B6,IMCuse1,0)) -> 0 | G6: =ROUNDUP(((F6/1000)*C6),0) -> 0 | H6: =SUM(D6*G6)+(E6*C6) -> 0 | J6: 3 TON | K6: 1 | L6: FAD | M6: =IF(AND(L3="thru-wall erv",OR(J6="1 ton",J6="1.5 ton",J6="2 ton",J6="2.5 ton",J6="3 ton",J6="3.5 ton",J6="4 ton",J6="5 ton")),"-",IF(L3="bard",INDEX(bardindex,MATCH(J6,bardsize,0),MATCH(L6,bardvent,0))*K6,IF(L3="RTU",INDEX(rturef,MATCH(J6,rtusize,0),MATCH(L6,rtuvent,0))*K6,IF(L3="MARVAIR",INDEX(marairref,MATCH(J6,marvairsize,0),MATCH(L6,marvairvent,0))*K6,IF(L3="THRU-WALL ERV",INDEX(ERVINDEX,MATCH(J6,ERVSIZE,0))*K6,0))))) -> 287.5 | P6: Dry cleaners, laundries:
A7: N/A: | B7: N/A | C7: 0 | D7: =INDEX(IMCRp1,MATCH(B7,IMCuse1,0)) -> 0 | E7: =INDEX(IMCRa1,MATCH(B7,IMCuse1,0)) -> 0 | F7: =INDEX(IMCocc1,MATCH(B7,IMCuse1,0)) -> 0 | G7: =ROUNDUP(((F7/1000)*C7),0) -> 0 | H7: =SUM(D7*G7)+(E7*C7) -> 0 | J7: N/A | K7: 1 | L7: FAD | M7: =IF(AND(L3="thru-wall erv",OR(J7="1 ton",J7="1.5 ton",J7="2 ton",J7="2.5 ton",J7="3 ton",J7="3.5 ton",J7="4 ton",J7="5 ton")),"-",IF(L3="bard",INDEX(bardindex,MATCH(J7,bardsize,0),MATCH(L7,bardvent,0))*K7,IF(L3="RTU",INDEX(rturef,MATCH(J7,rtusize,0),MATCH(L7,rtuvent,0))*K7,IF(L3="MARVAIR",INDEX(marairref,MATCH(J7,marvairsize,0),MATCH(L7,marvairvent,0))*K7,IF(L3="THRU-WALL ERV",INDEX(ERVINDEX,MATCH(J7,ERVSIZE,0))*K7,0))))) -> 0 | P7: Education:
A8: ------->>>> DON'T COPY AND PASTE THIS PORTION ON PLANS | B8: TOTAL OUTDOOR AIR REQUIRED: | D8: =SUM(H3:H7) -> 0 | E8: RESULTS: | G8: =IF(D8>D9,""&D9&" CFM < "&D8&" CFM, THEREFORE NG",IF(D8<D9,""&D9&" CFM > "&D8&" CFM, THEREFORE OK",0)) -> 287.5 CFM > 0 CFM, THEREFORE OK | J8: N/A | K8: 0 | L8: FAD | M8: =IF(AND(L3="thru-wall erv",OR(J8="1 ton",J8="1.5 ton",J8="2 ton",J8="2.5 ton",J8="3 ton",J8="3.5 ton",J8="4 ton",J8="5 ton")),"-",IF(L3="bard",INDEX(bardindex,MATCH(J8,bardsize,0),MATCH(L8,bardvent,0))*K8,IF(L3="RTU",INDEX(rturef,MATCH(J8,rtusize,0),MATCH(L8,rtuvent,0))*K8,IF(L3="MARVAIR",INDEX(marairref,MATCH(J8,marvairsize,0),MATCH(L8,marvairvent,0))*K8,IF(L3="THRU-WALL ERV",INDEX(ERVINDEX,MATCH(J8,ERVSIZE,0))*K8,0))))) -> 0 | P8: Food and beverage service:
B9: TOTAL FRESH AIR SUPPLIED: | D9: =SUM(M6:M10) -> 287.5 | J9: N/A | K9: 0 | L9: FAD | M9: =IF(AND(L3="thru-wall erv",OR(J9="1 ton",J9="1.5 ton",J9="2 ton",J9="2.5 ton",J9="3 ton",J9="3.5 ton",J9="4 ton",J9="5 ton")),"-",IF(L3="bard",INDEX(bardindex,MATCH(J9,bardsize,0),MATCH(L9,bardvent,0))*K9,IF(L3="RTU",INDEX(rturef,MATCH(J9,rtusize,0),MATCH(L9,rtuvent,0))*K9,IF(L3="MARVAIR",INDEX(marairref,MATCH(J9,marvairsize,0),MATCH(L9,marvairvent,0))*K9,IF(L3="THRU-WALL ERV",INDEX(ERVINDEX,MATCH(J9,ERVSIZE,0))*K9,0))))) -> 0 | P9: Hotels, motels, resorts and domitories:
J10: N/A | K10: 0 | L10: FAD | M10: =IF(AND(L3="thru-wall erv",OR(J10="1 ton",J10="1.5 ton",J10="2 ton",J10="2.5 ton",J10="3 ton",J10="3.5 ton",J10="4 ton",J10="5 ton")),"-",IF(L3="bard",INDEX(bardindex,MATCH(J10,bardsize,0),MATCH(L10,bardvent,0))*K10,IF(L3="RTU",INDEX(rturef,MATCH(J10,rtusize,0),MATCH(L10,rtuvent,0))*K10,IF(L3="MARVAIR",INDEX(marairref,MATCH(J10,marvairsize,0),MATCH(L10,marvairvent,0))*K10,IF(L3="THRU-WALL ERV",INDEX(ERVINDEX,MATCH(J10,ERVSIZE,0))*K10,0))))) -> 0 | P10: Offices:
P11: Outpatien healthcar facilities:
P12: Public spaces:
C13: VALUE(S) ABOVE CAN BE FOUND IN: | J13: FOR 100% OUTSIDE AIR, USE ECONOMIZER OPTION | P13: Retial stores, sales floors, and show room floors:
C14: IMC: | D14: Table 403.3.1.1 / Zone Calc: Section 403.3.1.1.1.1 | P14: Specialty shops:
C15: UMC: | D15: Table 402.1 / Zone Calc: Section 403.2.1 | P15: Sports and amusement:
C16: ASHREA 62.1: | D16: Table 6-1 / Zone Calc: Section 6.2.4.1 | P16: Storage:
P17: Theaters:
P18: Transportation:
P19: Workrooms:

Sheet Calculation Tables
A1: 2009 - 2021 IMC | F1: N/A | G1: 0 | H1: 2022 CEC SINGLE ZONE TABLE | K1: N/A | L1: 0 | M1: 2022 CEC MULTI-ZONE TABLE | S1: 2024 IMC | Z1: N/A | AA1: 0 | AB1: 2025 CEC SINGLE (Ra x Az) | AE1: N/A | AF1: 0 | AG1: 2025 CEC MULTI-ZONE (Ra x Az) | AM1: N/A | AN1: 0 | AO1: 2025 CEC SINGLE ZONE (Rp x Pz) | AT1: N/A | AU1: 0 | AV1: 2025 CEC MULTI ZONE (Rp x Pz)
A2: BUILDING USE: | B2: PEOPLE OUTDOOR FLOW RATE (Rp): | C2: AREA OUTDOOR FLOW RATE (Ra): | D2: OCCUPANT DENSITY /1000 sq. ft.: | F2: (Educational Facilities:) | K2: (Educational Facilities:) | S2: BUILDING USE: | T2: OCCUPANT DENSITY /1000 sq. ft.: | U2: PEOPLE OUTDOOR FLOW RATE (Rp): | V2: AREA OUTDOOR FLOW RATE (Ra): | Z2: (Educational Facilities:) | AE2: (Educational Facilities:) | AM2: (Educational Facilities:) | AT2: (Educational Facilities:)
A3: N/A | B3: 0 | C3: 0 | D3: 0 | F3: Daycare (through age 4) | G3: =IF(OR('2022 CA Single Zone Calculator'!H6="economizer",'2022 CA Single Zone Calculator'!H7="economizer",'2022 CA Single Zone Calculator'!H8="economizer"),0.15,0.21) -> 0.15 | I3: =IF(G3=0.15,"Title 24: CO2 Sensor required","") -> Title 24: CO2 Sensor required | K3: Daycare (through age 4) | L3: =IF(OR('2022 CA Multi-Zone Calculator'!H6="economizer",'2022 CA Multi-Zone Calculator'!H7="economizer",'2022 CA Multi-Zone Calculator'!H8="economizer"),0.15,0.21) -> 0.15 | N3: =IF(L3=0.15,"Title 24: CO2 Sensor required","") -> Title 24: CO2 Sensor required | S3: N/A | T3: 0 | U3: 0 | V3: 0 | Z3: Daycare (through age 4) | AA3: 0.15 | AB3: =SUM(AA3*'2025 CA Single Zone Calculator'!D2) -> 210 | AC3: =IF(OR('2025 CA Single Zone Calculator'!H9="economizer",'2025 CA Single Zone Calculator'!H10="economizer",'2025 CA Single Zone Calculator'!H11="economizer"),"Title 24: CO2 Sensor required","") -> Title 24: CO2 Sensor required | AE3: Daycare (through age 4) | AF3: 0.15 | AH3: =IF('2025 CA Multi-Zone Calculator'!K7="economizer","Title 24: CO2 Sensor required","") | AM3: Daycare (through age 4) | AN3: 14 | AO3: =SUM(AN3/1000)*15*'2025 CA Single Zone Calculator'!D2 -> 294 | AP3: Title 24: CO2 Sensor required | AT3: Daycare (through age 4) | AU3: 14 | AV3: =SUM(AU3/1000)*15*'2025 CA Single Zone Calculator'!K2 -> 0 | AW3: Title 24: CO2 Sensor required
A4: (OFFICES:) | F4: Daycare sickroom | G4: 0.15 | K4: Daycare sickroom | L4: 0.15 | S4: ANIMAL FACILITIES: | Z4: Daycare sickroom | AA4: 0.15 | AB4: =SUM(AA4*'2025 CA Single Zone Calculator'!D2) -> 210 | AE4: Daycare sickroom | AF4: 0.15 | AM4: Daycare sickroom | AN4: 5 | AO4: =SUM(AN4/1000)*15*'2025 CA Single Zone Calculator'!D2 -> 105 | AT4: Daycare sickroom | AU4: 5 | AV4: =SUM(AU4/1000)*15*'2025 CA Single Zone Calculator'!K2 -> 0
A5: OFFICE SPACE | B5: 5 | C5: 0.06 | D5: 5 | F5: Classrooms (ages 5-8) | G5: =IF(OR('2022 CA Single Zone Calculator'!H6="economizer",'2022 CA Single Zone Calculator'!H7="economizer",'2022 CA Single Zone Calculator'!H8="economizer"),0.15,0.38) -> 0.15 | I5: =IF(G5=0.15,"Title 24: CO2 Sensor required","") -> Title 24: CO2 Sensor required | K5: Classrooms (ages 5-8) | L5: =IF(OR('2022 CA Multi-Zone Calculator'!H6="economizer",'2022 CA Multi-Zone Calculator'!H7="economizer",'2022 CA Multi-Zone Calculator'!H8="economizer"),0.15,0.38) -> 0.15 | N5: =IF(L5=0.15,"Title 24: CO2 Sensor required","") -> Title 24: CO2 Sensor required | S5: Animal exam room (Vet Office) | T5: 20 | U5: 10 | V5: 0.12 | Z5: Classrooms (ages 5-8) | AA5: 0.15 | AB5: =SUM(AA5*'2025 CA Single Zone Calculator'!D2) -> 210 | AC5: =IF(OR('2025 CA Single Zone Calculator'!H9="economizer",'2025 CA Single Zone Calculator'!H10="economizer",'2025 CA Single Zone Calculator'!H11="economizer"),"Title 24: CO2 Sensor required","") -> Title 24: CO2 Sensor required | AE5: Classrooms (ages 5-8) | AF5: 0.15 | AH5: =IF(AF5=0.15,"Title 24: CO2 Sensor required","") -> Title 24: CO2 Sensor required | AM5: Classrooms (ages 5-8) | AN5: 25 | AO5: =SUM(AN5/1000)*15*'2025 CA Single Zone Calculator'!D2 -> 525 | AP5: Title 24: CO2 Sensor required | AT5: Classrooms (ages 5-8) | AU5: 25 | AV5: =SUM(AU5/1000)*15*'2025 CA Single Zone Calculator'!K2 -> 0 | AW5: Title 24: CO2 Sensor required
A6: CONFERENCE ROOM(S) | B6: 5 | C6: 0.06 | D6: 50 | F6: Classrooms (ages 9-18) | G6: =IF(OR('2022 CA Single Zone Calculator'!H6="economizer",'2022 CA Single Zone Calculator'!H7="economizer",'2022 CA Single Zone Calculator'!H8="economizer"),0.15,0.38) -> 0.15 | I6: =IF(G6=0.15,"Title 24: CO2 Sensor required","") -> Title 24: CO2 Sensor required | K6: Classrooms (ages 9-18) | L6: =IF(OR('2022 CA Multi-Zone Calculator'!H6="economizer",'2022 CA Multi-Zone Calculator'!H7="economizer",'2022 CA Multi-Zone Calculator'!H8="economizer"),0.15,0.38) -> 0.15 | N6: =IF(L6=0.15,"Title 24: CO2 Sensor required","") -> Title 24: CO2 Sensor required | S6: Animal imaging (MR/CT/PET) | T6: 20 | U6: 10 | V6: 0.18 | Z6: Classrooms (ages 9-18) | AA6: 0.15 | AB6: =SUM(AA6*'2025 CA Single Zone Calculator'!D2) -> 210 | AC6: =IF(OR('2025 CA Single Zone Calculator'!H9="economizer",'2025 CA Single Zone Calculator'!H10="economizer",'2025 CA Single Zone Calculator'!H11="economizer"),"Title 24: CO2 Sensor required","") -> Title 24: CO2 Sensor required | AE6: Classrooms (ages 9-18) | AF6: 0.15 | AH6: =IF(AF6=0.15,"Title 24: CO2 Sensor required","") -> Title 24: CO2 Sensor required | AM6: Classrooms (ages 9-18) | AN6: 25 | AO6: =SUM(AN6/1000)*15*'2025 CA Single Zone Calculator'!D2 -> 525 | AP6: Title 24: CO2 Sensor required | AT6: Classrooms (ages 9-18) | AU6: 25 | AV6: =SUM(AU6/1000)*15*'2025 CA Single Zone Calculator'!K2 -> 0 | AW6: Title 24: CO2 Sensor required
A7: RECEPTION AREA | B7: 5 | C7: 0.06 | D7: 30 | F7: Lecture/postsecondary classroom | G7: =IF(OR('2022 CA Single Zone Calculator'!H6="economizer",'2022 CA Single Zone Calculator'!H7="economizer",'2022 CA Single Zone Calculator'!H8="economizer"),0.15,0.38) -> 0.15 | I7: =IF(G7=0.15,"Title 24: CO2 Sensor required","") -> Title 24: CO2 Sensor required | K7: Lecture/postsecondary classroom | L7: =IF(OR('2022 CA Multi-Zone Calculator'!H6="economizer",'2022 CA Multi-Zone Calculator'!H7="economizer",'2022 CA Multi-Zone Calculator'!H8="economizer"),0.15,0.38) -> 0.15 | N7: =IF(L7=0.15,"Title 24: CO2 Sensor required","") -> Title 24: CO2 Sensor required | S7: Animal operating rooms | T7: 20 | U7: 10 | V7: 0.18 | Z7: Lecture/postsecondary classroom | AA7: 0.15 | AB7: =SUM(AA7*'2025 CA Single Zone Calculator'!D2) -> 210 | AC7: =IF(OR('2025 CA Single Zone Calculator'!H9="economizer",'2025 CA Single Zone Calculator'!H10="economizer",'2025 CA Single Zone Calculator'!H11="economizer"),"Title 24: CO2 Sensor required","") -> Title 24: CO2 Sensor required | AE7: Lecture/postsecondary classroom | AF7: 0.15 | AH7: =IF(AF7=0.15,"Title 24: CO2 Sensor required","") -> Title 24: CO2 Sensor required | AM7: Lecture/postsecondary classroom | AN7: 25 | AO7: =SUM(AN7/1000)*15*'2025 CA Single Zone Calculator'!D2 -> 525 | AP7: Title 24: CO2 Sensor required | AT7: Lecture/postsecondary classroom | AU7: 25 | AV7: =SUM(AU7/1000)*15*'2025 CA Single Zone Calculator'!K2 -> 0 | AW7: Title 24: CO2 Sensor required
A8: MAIN ENRTY LOBBIES | B8: 5 | C8: 0.06 | D8: 10 | F8: Lecture hall (fixed seats) | G8: =IF(OR('2022 CA Single Zone Calculator'!H6="economizer",'2022 CA Single Zone Calculator'!H7="economizer",'2022 CA Single Zone Calculator'!H8="economizer"),0.15,"-") -> 0.15 | I8: =IF(G8=0.15,"Title 24: CO2 Sensor required","") -> Title 24: CO2 Sensor required | K8: Lecture hall (fixed seats) | L8: =IF(OR('2022 CA Multi-Zone Calculator'!H6="economizer",'2022 CA Multi-Zone Calculator'!H7="economizer",'2022 CA Multi-Zone Calculator'!H8="economizer"),0.15,"-") -> 0.15 | N8: =IF(L8=0.15,"Title 24: CO2 Sensor required","") -> Title 24: CO2 Sensor required | S8: Aniaml postoperative revovery room | T8: 20 | U8: 10 | V8: 0.18 | Z8: Lecture hall (fixed seats) | AA8: 0.15 | AB8: =SUM(AA8*'2025 CA Single Zone Calculator'!D2) -> 210 | AC8: =IF(OR('2025 CA Single Zone Calculator'!H9="economizer",'2025 CA Single Zone Calculator'!H10="economizer",'2025 CA Single Zone Calculator'!H11="economizer"),"Title 24: CO2 Sensor required","") -> Title 24: CO2 Sensor required | AE8: Lecture hall (fixed seats) | AF8: 0.15 | AH8: =IF(AF8=0.15,"Title 24: CO2 Sensor required","") -> Title 24: CO2 Sensor required | AM8: Lecture hall (fixed seats) | AN8: 71 | AO8: =SUM(AN8/1000)*15*'2025 CA Single Zone Calculator'!D2 -> 1491 | AP8: Title 24: CO2 Sensor required | AT8: Lecture hall (fixed seats) | AU8: 71 | AV8: =SUM(AU8/1000)*15*'2025 CA Single Zone Calculator'!K2 -> 0 | AW8: Title 24: CO2 Sensor required
A9: TELEPHONE / DATA ENRTY | B9: 5 | C9: 0.06 | D9: 60 | F9: Art classroom | G9: 0.15 | K9: Art classroom | L9: 0.15 | S9: Animal preparation rooms | T9: 20 | U9: 10 | V9: 0.18 | Z9: Art classroom | AA9: 0.15 | AB9: =SUM(AA9*'2025 CA Single Zone Calculator'!D2) -> 210 | AE9: Art classroom | AF9: 0.15 | AM9: Art classroom | AN9: 25 | AO9: =SUM(AN9/1000)*15*'2025 CA Single Zone Calculator'!D2 -> 525 | AT9: Art classroom | AU9: 25 | AV9: =SUM(AU9/1000)*15*'2025 CA Single Zone Calculator'!K2 -> 0
F10: Science laboratories | G10: 0.15 | K10: Science laboratories | L10: 0.15 | S10: Animal procdure rooms | T10: 20 | U10: 10 | V10: 0.18 | Z10: Science laboratories | AA10: 0.15 | AB10: =SUM(AA10*'2025 CA Single Zone Calculator'!D2) -> 210 | AE10: Science laboratories | AF10: 0.15 | AM10: Science laboratories | AN10: 25 | AO10: =SUM(AN10/1000)*15*'2025 CA Single Zone Calculator'!D2 -> 525 | AT10: Science laboratories | AU10: 25 | AV10: =SUM(AU10/1000)*15*'2025 CA Single Zone Calculator'!K2 -> 0
A11: (PUBLIC USES:) | F11: University/college laboratories | G11: 0.15 | K11: University/college laboratories | L11: 0.15 | S11: Animal surgery scrub | T11: 20 | U11: 10 | V11: 0.18 | Z11: University/college laboratories | AA11: 0.15 | AB11: =SUM(AA11*'2025 CA Single Zone Calculator'!D2) -> 210 | AE11: University/college laboratories | AF11: 0.15 | AM11: University/college laboratories | AN11: 25 | AO11: =SUM(AN11/1000)*15*'2025 CA Single Zone Calculator'!D2 -> 525 | AT11: University/college laboratories | AU11: 25 | AV11: =SUM(AU11/1000)*15*'2025 CA Single Zone Calculator'!K2 -> 0
A12: CORRIDORS | B12: 0 | C12: 0.06 | D12: 0 | F12: Wood/metal shop | G12: 0.15 | K12: Wood/metal shop | L12: 0.15 | S12: Large-animal holding room | T12: 20 | U12: 10 | V12: 0.18 | Z12: Wood/metal shop | AA12: 0.15 | AB12: =SUM(AA12*'2025 CA Single Zone Calculator'!D2) -> 210 | AE12: Wood/metal shop | AF12: 0.15 | AM12: Wood/metal shop | AN12: 10 | AO12: =SUM(AN12/1000)*15*'2025 CA Single Zone Calculator'!D2 -> 210 | AT12: Wood/metal shop | AU12: 10 | AV12: =SUM(AU12/1000)*15*'2025 CA Single Zone Calculator'!K2 -> 0
A13: COURTROOMS | B13: 5 | C13: 0.06 | D13: 70 | F13: Computer lab | G13: 0.15 | K13: Computer lab | L13: 0.15 | S13: Necropsy | T13: 20 | U13: 10 | V13: 0.18 | Z13: Computer lab | AA13: 0.15 | AB13: =SUM(AA13*'2025 CA Single Zone Calculator'!D2) -> 210 | AE13: Computer lab | AF13: 0.15 | AM13: Computer lab | AN13: 25 | AO13: =SUM(AN13/1000)*15*'2025 CA Single Zone Calculator'!D2 -> 525 | AT13: Computer lab | AU13: 25 | AV13: =SUM(AU13/1000)*15*'2025 CA Single Zone Calculator'!K2 -> 0
A14: LEGISTLATIVE CHAMBERS | B14: 5 | C14: 0.06 | D14: 50 | F14: Media center | G14: 0.15 | K14: Media center | L14: 0.15 | S14: Small-animal cage room (static cages) | T14: 20 | U14: 10 | V14: 0.18 | Z14: Media center | AA14: 0.15 | AB14: =SUM(AA14*'2025 CA Single Zone Calculator'!D2) -> 210 | AE14: Media center | AF14: 0.15 | AM14: Media center | AN14: 25 | AO14: =SUM(AN14/1000)*15*'2025 CA Single Zone Calculator'!D2 -> 525 | AT14: Media center | AU14: 25 | AV14: =SUM(AU14/1000)*15*'2025 CA Single Zone Calculator'!K2 -> 0
A15: LIBRARIES | B15: 5 | C15: 0.12 | D15: 10 | F15: Music/theater/dance | G15: =IF(OR('2022 CA Single Zone Calculator'!H6="economizer",'2022 CA Single Zone Calculator'!H7="economizer",'2022 CA Single Zone Calculator'!H8="economizer"),0.15,1.07) -> 0.15 | I15: =IF(G15=0.15,"Title 24: CO2 Sensor required","") -> Title 24: CO2 Sensor required | K15: Music/theater/dance | L15: =IF(OR('2022 CA Multi-Zone Calculator'!H6="economizer",'2022 CA Multi-Zone Calculator'!H7="economizer",'2022 CA Multi-Zone Calculator'!H8="economizer"),0.15,1.07) -> 0.15 | N15: =IF(L15=0.15,"Title 24: CO2 Sensor required","") -> Title 24: CO2 Sensor required | S15: Small-animal cage room (ventilated cages) | T15: 20 | U15: 10 | V15: 0.18 | Z15: Music/theater/dance | AA15: 0.15 | AB15: =SUM(AA15*'2025 CA Single Zone Calculator'!D2) -> 210 | AC15: =IF(OR('2025 CA Single Zone Calculator'!H9="economizer",'2025 CA Single Zone Calculator'!H10="economizer",'2025 CA Single Zone Calculator'!H11="economizer"),"Title 24: CO2 Sensor required","") -> Title 24: CO2 Sensor required | AE15: Music/theater/dance | AF15: 0.15 | AH15: =IF(AF15=0.15,"Title 24: CO2 Sensor required","") -> Title 24: CO2 Sensor required | AM15: Music/theater/dance | AN15: 33 | AO15: =SUM(AN15/1000)*15*'2025 CA Single Zone Calculator'!D2 -> 693 | AP15: Title 24: CO2 Sensor required | AT15: Music/theater/dance | AU15: 33 | AV15: =SUM(AU15/1000)*15*'2025 CA Single Zone Calculator'!K2 -> 0 | AW15: Title 24: CO2 Sensor required
A16: MUSEUMS / GALLERIES | B16: 7.5 | C16: 0.12 | D16: 40 | F16: Multiuse assembly | G16: =IF(OR('2022 CA Single Zone Calculator'!H6="economizer",'2022 CA Single Zone Calculator'!H7="economizer",'2022 CA Single Zone Calculator'!H8="economizer"),0.15,0.5) -> 0.15 | I16: =IF(G16=0.15,"Title 24: CO2 Sensor required","") -> Title 24: CO2 Sensor required | K16: Multiuse assembly | L16: =IF(OR('2022 CA Multi-Zone Calculator'!H6="economizer",'2022 CA Multi-Zone Calculator'!H7="economizer",'2022 CA Multi-Zone Calculator'!H8="economizer"),0.15,0.5) -> 0.15 | N16: =IF(L16=0.15,"Title 24: CO2 Sensor required","") -> Title 24: CO2 Sensor required | Z16: Multiuse assembly | AA16: 0.15 | AB16: =SUM(AA16*'2025 CA Single Zone Calculator'!D2) -> 210 | AC16: =IF(OR('2025 CA Single Zone Calculator'!H9="economizer",'2025 CA Single Zone Calculator'!H10="economizer",'2025 CA Single Zone Calculator'!H11="economizer"),"Title 24: CO2 Sensor required","") -> Title 24: CO2 Sensor required | AE16: Multiuse assembly | AF16: 0.15 | AH16: =IF(AF16=0.15,"Title 24: CO2 Sensor required","") -> Title 24: CO2 Sensor required | AM16: Multiuse assembly | AN16: 33 | AO16: =SUM(AN16/1000)*15*'2025 CA Single Zone Calculator'!D2 -> 693 | AP16: Title 24: CO2 Sensor required | AT16: Multiuse assembly | AU16: 33 | AV16: =SUM(AU16/1000)*15*'2025 CA Single Zone Calculator'!K2 -> 0 | AW16: Title 24: CO2 Sensor required
A17: RELIGIOUS WORSHIP | B17: 5 | C17: 0.06 | D17: 120 | S17: CORRECTIONAL FACILITIES:
A18: SMOKING LOUNGES | B18: 60 | C18: 0 | D18: 70 | F18: (Food and Beverage Service:) | K18: (Food and Beverage Service:) | S18: Booking/waiting | T18: 50 | U18: 7.5 | V18: 0.06 | Z18: (Food and Beverage Service:) | AE18: (Food and Beverage Service:) | AM18: (Food and Beverage Service:) | AT18: (Food and Beverage Service:)
F19: Restaurant dining rooms | G19: =IF(OR('2022 CA Single Zone Calculator'!H6="economizer",'2022 CA Single Zone Calculator'!H7="economizer",'2022 CA Single Zone Calculator'!H8="economizer"),0.15,0.5) -> 0.15 | I19: =IF(G19=0.15,"Title 24: CO2 Sensor required","") -> Title 24: CO2 Sensor required | K19: Restaurant dining rooms | L19: =IF(OR('2022 CA Multi-Zone Calculator'!H6="economizer",'2022 CA Multi-Zone Calculator'!H7="economizer",'2022 CA Multi-Zone Calculator'!H8="economizer"),0.15,0.5) -> 0.15 | N19: =IF(L19=0.15,"Title 24: CO2 Sensor required","") -> Title 24: CO2 Sensor required | S19: Cells without plumbing | T19: 25 | U19: 5 | V19: 0.12 | Z19: Restaurant dining rooms | AA19: 0.15 | AB19: =SUM(AA19*'2025 CA Single Zone Calculator'!D2) -> 210 | AC19: =IF(OR('2025 CA Single Zone Calculator'!H9="economizer",'2025 CA Single Zone Calculator'!H10="economizer",'2025 CA Single Zone Calculator'!H11="economizer"),"Title 24: CO2 Sensor required","") -> Title 24: CO2 Sensor required | AE19: Restaurant dining rooms | AF19: 0.15 | AH19: =IF(AF19=0.15,"Title 24: CO2 Sensor required","") -> Title 24: CO2 Sensor required | AM19: Restaurant dining rooms | AN19: 33 | AO19: =SUM(AN19/1000)*15*'2025 CA Single Zone Calculator'!D2 -> 693 | AP19: Title 24: CO2 Sensor required | AT19: Restaurant dining rooms | AU19: 33 | AV19: =SUM(AU19/1000)*15*'2025 CA Single Zone Calculator'!K2 -> 0 | AW19: Title 24: CO2 Sensor required
A20: (EDUCATION:) | F20: Cafeteria/fast-food dining | G20: =IF(OR('2022 CA Single Zone Calculator'!H6="economizer",'2022 CA Single Zone Calculator'!H7="economizer",'2022 CA Single Zone Calculator'!H8="economizer"),0.15,0.5) -> 0.15 | I20: =IF(G20=0.15,"Title 24: CO2 Sensor required","") -> Title 24: CO2 Sensor required | K20: Cafeteria/fast-food dining | L20: =IF(OR('2022 CA Multi-Zone Calculator'!H6="economizer",'2022 CA Multi-Zone Calculator'!H7="economizer",'2022 CA Multi-Zone Calculator'!H8="economizer"),0.15,0.5) -> 0.15 | N20: =IF(L20=0.15,"Title 24: CO2 Sensor required","") -> Title 24: CO2 Sensor required | S20: Cells with plumbing | T20: 25 | U20: 5 | V20: 0.12 | Z20: Cafeteria/fast-food dining | AA20: 0.15 | AB20: =SUM(AA20*'2025 CA Single Zone Calculator'!D2) -> 210 | AC20: =IF(OR('2025 CA Single Zone Calculator'!H9="economizer",'2025 CA Single Zone Calculator'!H10="economizer",'2025 CA Single Zone Calculator'!H11="economizer"),"Title 24: CO2 Sensor required","") -> Title 24: CO2 Sensor required | AE20: Cafeteria/fast-food dining | AF20: 0.15 | AH20: =IF(AF20=0.15,"Title 24: CO2 Sensor required","") -> Title 24: CO2 Sensor required | AM20: Cafeteria/fast-food dining | AN20: 33 | AO20: =SUM(AN20/1000)*15*'2025 CA Single Zone Calculator'!D2 -> 693 | AP20: Title 24: CO2 Sensor required | AT20: Cafeteria/fast-food dining | AU20: 33 | AV20: =SUM(AU20/1000)*15*'2025 CA Single Zone Calculator'!K2 -> 0 | AW20: Title 24: CO2 Sensor required
A21: CLASSROOM (5-8) | B21: 10 | C21: 0.12 | D21: 25 | F21: Bars, cocktail lounges | G21: =IF(OR('2022 CA Single Zone Calculator'!H6="economizer",'2022 CA Single Zone Calculator'!H7="economizer",'2022 CA Single Zone Calculator'!H8="economizer"),0.2,0.5) -> 0.2 | I21: =IF(G21=0.2,"Title 24: CO2 Sensor required","") -> Title 24: CO2 Sensor required | K21: Bars, cocktail lounges | L21: =IF(OR('2022 CA Multi-Zone Calculator'!H6="economizer",'2022 CA Multi-Zone Calculator'!H7="economizer",'2022 CA Multi-Zone Calculator'!H8="economizer"),0.2,0.5) -> 0.2 | N21: =IF(L21=0.2,"Title 24: CO2 Sensor required","") -> Title 24: CO2 Sensor required | S21: Day room | T21: 30 | U21: 5 | V21: 0.06 | Z21: Bars, cocktail lounges | AA21: 0.5 | AB21: =SUM(AA21*'2025 CA Single Zone Calculator'!D2) -> 700 | AC21: =IF(AA21=0.2,"Title 24: CO2 Sensor required","") | AE21: Bars, cocktail lounges | AF21: 0.5 | AH21: =IF(AF21=0.2,"Title 24: CO2 Sensor required","") | AM21: Bars, cocktail lounges | AN21: 33 | AO21: =SUM(AN21/1000)*15*'2025 CA Single Zone Calculator'!D2 -> 693 | AP21: =IF(AN21=0.2,"Title 24: CO2 Sensor required","") | AT21: Bars, cocktail lounges | AU21: 33 | AV21: =SUM(AU21/1000)*15*'2025 CA Single Zone Calculator'!K2 -> 0 | AW21: =IF(AU21=0.2,"Title 24: CO2 Sensor required","")
A22: CLASSROOM (9+) | B22: 10 | C22: 0.12 | D22: 35 | F22: Kitchen (cooking) | G22: 0.15 | K22: Kitchen (cooking) | L22: 0.15 | S22: Dining halls | T22: 70 | U22: 7.5 | V22: 0.18 | Z22: Kitchen (cooking) | AA22: 0.15 | AB22: =SUM(AA22*'2025 CA Single Zone Calculator'!D2) -> 210 | AE22: Kitchen (cooking) | AF22: 0.15 | AM22: Kitchen (cooking) | AN22: 3 | AO22: =SUM(AN22/1000)*15*'2025 CA Single Zone Calculator'!D2 -> 63 | AT22: Kitchen (cooking) | AU22: 3 | AV22: =SUM(AU22/1000)*15*'2025 CA Single Zone Calculator'!K2 -> 0
A23: DAYCARE (UP TO 4YR) | B23: 10 | C23: 0.18 | D23: 25 | S23: Guard stations | T23: 15 | U23: 5 | V23: 0.06
A24: ART CLASSROOM | B24: 10 | C24: 0.18 | D24: 20 | F24: (General:) | K24: (General:) | Z24: (General:) | AE24: (General:) | AM24: (General:) | AT24: (General:)
A25: AUDITORIUMS | B25: 5 | C25: 0.06 | D25: 150 | F25: Break rooms | G25: =IF(OR('2022 CA Single Zone Calculator'!H6="economizer",'2022 CA Single Zone Calculator'!H7="economizer",'2022 CA Single Zone Calculator'!H8="economizer"),0.15,0.5) -> 0.15 | I25: =IF(G25=0.15,"Title 24: CO2 Sensor required","") -> Title 24: CO2 Sensor required | K25: Break rooms | L25: =IF(OR('2022 CA Multi-Zone Calculator'!H6="economizer",'2022 CA Multi-Zone Calculator'!H7="economizer",'2022 CA Multi-Zone Calculator'!H8="economizer"),0.15,0.5) -> 0.15 | N25: =IF(L25=0.15,"Title 24: CO2 Sensor required","") -> Title 24: CO2 Sensor required | S25: (DRY CLEANERS, LAUNDRIES:) | Z25: Break rooms | AA25: 0.15 | AB25: =SUM(AA25*'2025 CA Single Zone Calculator'!D2) -> 210 | AC25: =IF(OR('2025 CA Single Zone Calculator'!H9="economizer",'2025 CA Single Zone Calculator'!H10="economizer",'2025 CA Single Zone Calculator'!H11="economizer"),"Title 24: CO2 Sensor required","") -> Title 24: CO2 Sensor required | AE25: Break rooms | AF25: 0.15 | AH25: =IF(AF25=0.15,"Title 24: CO2 Sensor required","") -> Title 24: CO2 Sensor required | AM25: Break rooms | AN25: 33 | AO25: =SUM(AN25/1000)*15*'2025 CA Single Zone Calculator'!D2 -> 693 | AP25: Title 24: CO2 Sensor required | AT25: Break rooms | AU25: 33 | AV25: =SUM(AU25/1000)*15*'2025 CA Single Zone Calculator'!K2 -> 0 | AW25: Title 24: CO2 Sensor required
A26: COMPUTER LAB | B26: 10 | C26: 0.12 | D26: 25 | F26: Coffee Stations | G26: =IF(OR('2022 CA Single Zone Calculator'!H6="economizer",'2022 CA Single Zone Calculator'!H7="economizer",'2022 CA Single Zone Calculator'!H8="economizer"),0.15,0.5) -> 0.15 | I26: =IF(G26=0.15,"Title 24: CO2 Sensor required","") -> Title 24: CO2 Sensor required | K26: Coffee Stations | L26: =IF(OR('2022 CA Multi-Zone Calculator'!H6="economizer",'2022 CA Multi-Zone Calculator'!H7="economizer",'2022 CA Multi-Zone Calculator'!H8="economizer"),0.15,0.5) -> 0.15 | N26: =IF(L26=0.15,"Title 24: CO2 Sensor required","") -> Title 24: CO2 Sensor required | S26: Coin-operated dry cleaner | T26: 20 | U26: 15 | V26: 0 | Z26: Coffee Stations | AA26: 0.15 | AB26: =SUM(AA26*'2025 CA Single Zone Calculator'!D2) -> 210 | AC26: =IF(OR('2025 CA Single Zone Calculator'!H9="economizer",'2025 CA Single Zone Calculator'!H10="economizer",'2025 CA Single Zone Calculator'!H11="economizer"),"Title 24: CO2 Sensor required","") -> Title 24: CO2 Sensor required | AE26: Coffee Stations | AF26: 0.15 | AH26: =IF(AF26=0.15,"Title 24: CO2 Sensor required","") -> Title 24: CO2 Sensor required | AM26: Coffee Stations | AN26: 33 | AO26: =SUM(AN26/1000)*15*'2025 CA Single Zone Calculator'!D2 -> 693 | AP26: Title 24: CO2 Sensor required | AT26: Coffee Stations | AU26: 33 | AV26: =SUM(AU26/1000)*15*'2025 CA Single Zone Calculator'!K2 -> 0 | AW26: Title 24: CO2 Sensor required
A27: LECTURE CLASSROOM | B27: 7.5 | C27: 0.06 | D27: 65 | F27: Conference/meeting | G27: =IF(OR('2022 CA Single Zone Calculator'!H6="economizer",'2022 CA Single Zone Calculator'!H7="economizer",'2022 CA Single Zone Calculator'!H8="economizer"),0.15,0.5) -> 0.15 | I27: =IF(G27=0.15,"Title 24: CO2 Sensor required","") -> Title 24: CO2 Sensor required | K27: Conference/meeting | L27: =IF(OR('2022 CA Multi-Zone Calculator'!H6="economizer",'2022 CA Multi-Zone Calculator'!H7="economizer",'2022 CA Multi-Zone Calculator'!H8="economizer"),0.15,0.5) -> 0.15 | S27: Coin-operated laundries | T27: 20 | U27: 7.5 | V27: 0.12 | Z27: Conference/meeting | AA27: 0.15 | AB27: =SUM(AA27*'2025 CA Single Zone Calculator'!D2) -> 210 | AC27: =IF(OR('2025 CA Single Zone Calculator'!H9="economizer",'2025 CA Single Zone Calculator'!H10="economizer",'2025 CA Single Zone Calculator'!H11="economizer"),"Title 24: CO2 Sensor required","") -> Title 24: CO2 Sensor required | AE27: Conference/meeting | AF27: 0.15 | AM27: Conference/meeting | AN27: 33 | AO27: =SUM(AN27/1000)*15*'2025 CA Single Zone Calculator'!D2 -> 693 | AP27: Title 24: CO2 Sensor required | AT27: Conference/meeting | AU27: 33 | AV27: =SUM(AU27/1000)*15*'2025 CA Single Zone Calculator'!K2 -> 0 | AW27: Title 24: CO2 Sensor required
A28: MEDIA CENTER | B28: 10 | C28: 0.12 | D28: 25 | F28: Corridors | G28: 0.15 | K28: Corridors | L28: 0.15 | N28: =IF(L28=0.15,"Title 24: CO2 Sensor required","") -> Title 24: CO2 Sensor required | S28: Commercial dry cleaner | T28: 30 | U28: 30 | V28: 0 | Z28: Corridors | AA28: 0.15 | AB28: =SUM(AA28*'2025 CA Single Zone Calculator'!D2) -> 210 | AE28: Corridors | AF28: 0.15 | AH28: =IF(AF28=0.15,"Title 24: CO2 Sensor required","") -> Title 24: CO2 Sensor required | AM28: Corridors | AN28: 5 | AO28: =SUM(AN28/1000)*15*'2025 CA Single Zone Calculator'!D2 -> 105 | AT28: Corridors | AU28: 5 | AV28: =SUM(AU28/1000)*15*'2025 CA Single Zone Calculator'!K2 -> 0
A29: MULTIUSE ASSEMBLY | B29: 7.5 | C29: 0.06 | D29: 100 | F29: Occupiable storage rooms for liquids or gels | G29: 0.15 | K29: Occupiable storage rooms for liquids or gels | L29: 0.15 | S29: Commercial laundry | T29: 10 | U29: 5 | V29: 0.12 | Z29: Occupiable storage rooms for liquids or gels | AA29: 0.15 | AB29: =SUM(AA29*'2025 CA Single Zone Calculator'!D2) -> 210 | AE29: Occupiable storage rooms for liquids or gels | AF29: 0.15 | AM29: Occupiable storage rooms for liquids or gels | AN29: 2 | AO29: =SUM(AN29/1000)*15*'2025 CA Single Zone Calculator'!D2 -> 42 | AT29: Occupiable storage rooms for liquids or gels | AU29: 2 | AV29: =SUM(AU29/1000)*15*'2025 CA Single Zone Calculator'!K2 -> 0
A30: MUSIC / THEATER / DANCE | B30: 10 | C30: 0.06 | D30: 35 | S30: Storage, pick up | T30: 30 | U30: 7.5 | V30: 0.12
A31: SCIENCE LAB | B31: 10 | C31: 0.18 | D31: 25 | F31: (Hotels, Motels, Resorts, Dormitories:) | K31: (Hotels, Motels, Resorts, Dormitories:) | Z31: (Hotels, Motels, Resorts, Dormitories:) | AE31: (Hotels, Motels, Resorts, Dormitories:) | AM31: (Hotels, Motels, Resorts, Dormitories:) | AT31: (Hotels, Motels, Resorts, Dormitories:)
A32: WOOD / METAL SHOP | B32: 10 | C32: 0.18 | D32: 20 | F32: Bedroom/living room | G32: 0.15 | K32: Bedroom/living room | L32: 0.15 | S32: (EDUCATION:) | Z32: Bedroom/living room | AA32: 0.15 | AB32: =SUM(AA32*'2025 CA Single Zone Calculator'!D2) -> 210 | AE32: Bedroom/living room | AF32: 0.15 | AM32: Bedroom/living room | AN32: 3 | AO32: =SUM(AN32/1000)*15*'2025 CA Single Zone Calculator'!D2 -> 63 | AT32: Bedroom/living room | AU32: 3 | AV32: =SUM(AU32/1000)*15*'2025 CA Single Zone Calculator'!K2 -> 0
F33: Barracks sleeping areas | G33: 0.15 | K33: Barracks sleeping areas | L33: 0.15 | S33: Art classroom | T33: 20 | U33: 10 | V33: 0.18 | Z33: Barracks sleeping areas | AA33: 0.15 | AB33: =SUM(AA33*'2025 CA Single Zone Calculator'!D2) -> 210 | AE33: Barracks sleeping areas | AF33: 0.15 | AM33: Barracks sleeping areas | AN33: 5 | AO33: =SUM(AN33/1000)*15*'2025 CA Single Zone Calculator'!D2 -> 105 | AT33: Barracks sleeping areas | AU33: 5 | AV33: =SUM(AU33/1000)*15*'2025 CA Single Zone Calculator'!K2 -> 0
A34: (WORKROOMS:) | F34: Laundry rooms, central | G34: 0.15 | K34: Laundry rooms, central | L34: 0.15 | S34: Auditoriums | T34: 150 | U34: 5 | V34: 0.06 | Z34: Laundry rooms, central | AA34: 0.15 | AB34: =SUM(AA34*'2025 CA Single Zone Calculator'!D2) -> 210 | AE34: Laundry rooms, central | AF34: 0.15 | AM34: Laundry rooms, central | AN34: 5 | AO34: =SUM(AN34/1000)*15*'2025 CA Single Zone Calculator'!D2 -> 105 | AT34: Laundry rooms, central | AU34: 5 | AV34: =SUM(AU34/1000)*15*'2025 CA Single Zone Calculator'!K2 -> 0
A35: BANK VAULTS / SAFE DEPOSIT | B35: 5 | C35: 0.06 | D35: 5 | F35: Laundry rooms within dwelling units | G35: 0.15 | K35: Laundry rooms within dwelling units | L35: 0.15 | S35: Classrooms (ages 5-8) | T35: 25 | U35: 10 | V35: 0.12 | Z35: Laundry rooms within dwelling units | AA35: 0.15 | AB35: =SUM(AA35*'2025 CA Single Zone Calculator'!D2) -> 210 | AE35: Laundry rooms within dwelling units | AF35: 0.15 | AM35: Laundry rooms within dwelling units | AN35: 5 | AO35: =SUM(AN35/1000)*15*'2025 CA Single Zone Calculator'!D2 -> 105 | AT35: Laundry rooms within dwelling units | AU35: 5 | AV35: =SUM(AU35/1000)*15*'2025 CA Single Zone Calculator'!K2 -> 0
A36: COPY / PRINTING RM | B36: 5 | C36: 0.06 | D36: 4 | F36: Lobbies/pre-function | G36: =IF(OR('2022 CA Single Zone Calculator'!H6="economizer",'2022 CA Single Zone Calculator'!H7="economizer",'2022 CA Single Zone Calculator'!H8="economizer"),0.15,0.5) -> 0.15 | I36: =IF(G36=0.15,"Title 24: CO2 Sensor required","") -> Title 24: CO2 Sensor required | K36: Lobbies/pre-function | L36: =IF(OR('2022 CA Multi-Zone Calculator'!H6="economizer",'2022 CA Multi-Zone Calculator'!H7="economizer",'2022 CA Multi-Zone Calculator'!H8="economizer"),0.15,0.5) -> 0.15 | N36: =IF(L36=0.15,"Title 24: CO2 Sensor required","") -> Title 24: CO2 Sensor required | S36: Classrooms (ages 9 plus) | T36: 35 | U36: 10 | V36: 0.12 | Z36: Lobbies/pre-function | AA36: 0.15 | AB36: =SUM(AA36*'2025 CA Single Zone Calculator'!D2) -> 210 | AC36: =IF(OR('2025 CA Single Zone Calculator'!H9="economizer",'2025 CA Single Zone Calculator'!H10="economizer",'2025 CA Single Zone Calculator'!H11="economizer"),"Title 24: CO2 Sensor required","") -> Title 24: CO2 Sensor required | AE36: Lobbies/pre-function | AF36: 0.15 | AH36: =IF(AF36=0.15,"Title 24: CO2 Sensor required","") -> Title 24: CO2 Sensor required | AM36: Lobbies/pre-function | AN36: 33 | AO36: =SUM(AN36/1000)*15*'2025 CA Single Zone Calculator'!D2 -> 693 | AP36: Title 24: CO2 Sensor required | AT36: Lobbies/pre-function | AU36: 33 | AV36: =SUM(AU36/1000)*15*'2025 CA Single Zone Calculator'!K2 -> 0 | AW36: Title 24: CO2 Sensor required
A37: COMPUTER (WITHOUT PRINTING) | B37: 5 | C37: 0.06 | D37: 4 | F37: Multipurpose assembly | G37: 0.5 | K37: Multipurpose assembly | L37: 0.5 | S37: Computer lab | T37: 25 | U37: 10 | V37: 0.12 | Z37: Multipurpose assembly | AA37: 0.15 | AB37: =SUM(AA37*'2025 CA Single Zone Calculator'!D2) -> 210 | AE37: Multipurpose assembly | AF37: 0.15 | AM37: Multipurpose assembly | AN37: 33 | AO37: =SUM(AN37/1000)*15*'2025 CA Single Zone Calculator'!D2 -> 693 | AT37: Multipurpose assembly | AU37: 33 | AV37: =SUM(AU37/1000)*15*'2025 CA Single Zone Calculator'!K2 -> 0
A38: PHARMACY PREP AREA | B38: 5 | C38: 0.18 | D38: 10 | S38: Corridors | T38: 0 | U38: 0 | V38: 0.06
A39: PHOTO STUDIOS | B39: 5 | C39: 0.12 | D39: 10 | F39: (Office Buildings:) | K39: (Office Buildings:) | S39: Day care (through age 4) | T39: 25 | U39: 10 | V39: 0.18 | Z39: (Office Buildings:) | AE39: (Office Buildings:) | AM39: (Office Buildings:) | AT39: (Office Buildings:)
A40: MEAT PROCESSING | B40: 15 | C40: 0 | D40: 10 | F40: Breakrooms | G40: =IF(OR('2022 CA Single Zone Calculator'!H6="economizer",'2022 CA Single Zone Calculator'!H7="economizer",'2022 CA Single Zone Calculator'!H8="economizer"),0.15,0.5) -> 0.15 | I40: =IF(G40=0.15,"Title 24: CO2 Sensor required","") -> Title 24: CO2 Sensor required | K40: Breakrooms | L40: =IF(OR('2022 CA Multi-Zone Calculator'!H6="economizer",'2022 CA Multi-Zone Calculator'!H7="economizer",'2022 CA Multi-Zone Calculator'!H8="economizer"),0.15,0.5) -> 0.15 | N40: =IF(L40=0.15,"Title 24: CO2 Sensor required","") -> Title 24: CO2 Sensor required | S40: Lecture classroom | T40: 65 | U40: 7.5 | V40: 0.06 | Z40: Breakrooms | AA40: 0.15 | AB40: =SUM(AA40*'2025 CA Single Zone Calculator'!D2) -> 210 | AC40: =IF(OR('2025 CA Single Zone Calculator'!H9="economizer",'2025 CA Single Zone Calculator'!H10="economizer",'2025 CA Single Zone Calculator'!H11="economizer"),"Title 24: CO2 Sensor required","") -> Title 24: CO2 Sensor required | AE40: Breakrooms | AF40: 0.15 | AH40: =IF(AF40=0.15,"Title 24: CO2 Sensor required","") -> Title 24: CO2 Sensor required | AM40: Breakrooms | AN40: 33 | AO40: =SUM(AN40/1000)*15*'2025 CA Single Zone Calculator'!D2 -> 693 | AP40: Title 24: CO2 Sensor required | AT40: Breakrooms | AU40: 33 | AV40: =SUM(AU40/1000)*15*'2025 CA Single Zone Calculator'!K2 -> 0 | AW40: Title 24: CO2 Sensor required
...

Sheet 2022 CA Single Zone Calculator
A1: USE: | B1: FRESH AIR CALCULATION (Table 120.1-A & Section 120.1(c)(3))
A2: Office Buildings: | B2: Office space | C2: Floor Area (Az): | D2: 1400 | E2: <--Enter Square Footage
A3: ------->>>> DON'T COPY AND PASTE THIS PORTION ON PLANS | B3: =IF(OR(H6="economizer",H7="economizer",H8="economizer"),"MIN. VENTILATION AIR RATE FOR DCV (Ra):","TOTAL OUTDOOR AIRFLOW RATE (Rt):") -> MIN. VENTILATION AIR RATE FOR DCV (Ra): | D3: =INDEX(CARa,MATCH(B2,'Calculation Tables'!F2:F95,0)) -> 0.15 | G3: Type of HVAC: | H3: BARD
B4: OUTDOOR AIR REQUIRED: | D4: =SUM(D3*D2) -> 210
B5: TOTAL FRESH AIR SUPPLIED: | D5: =SUM(I6:I8) -> 2300 | F5: HVAC SIZE: | G5: # OF A/C's: | H5: VENTILATION: | I5: VENT RATE: | L5: Office Buildings:
B6: RESULTS: | C6: =IF(D4>D5,""&D5&" CFM < "&D4&" CFM, THEREFORE NG",IF(D4<D5,""&D5&" CFM > "&D4&" CFM, THEREFORE OK",0)) -> 2300 CFM > 210 CFM, THEREFORE OK | F6: 3 TON | G6: 2 | H6: ECONOMIZER | I6: =IF(H3="bard",INDEX(bardindex,MATCH(F6,bardsize,0),MATCH(H6,bardvent,0))*G6,IF(H3="RTU",INDEX(rturef,MATCH(F6,rtusize,0),MATCH(H6,rtuvent,0))*G6,IF(H3="MARVAIR",INDEX(marairref,MATCH(F6,marvairsize,0),MATCH(H6,marvairvent,0))*G6,0))) -> 2300 | L6: Educational Facilities:
F7: N/A | G7: 0 | H7: FAD | I7: =IF(H3="bard",INDEX(bardindex,MATCH(F7,bardsize,0),MATCH(H7,bardvent,0))*G7,IF(H3="RTU",INDEX(rturef,MATCH(F7,rtusize,0),MATCH(H7,rtuvent,0))*G7,IF(H3="MARVAIR",INDEX(marairref,MATCH(F7,marvairsize,0),MATCH(H7,marvairvent,0))*G7,0))) -> 0 | L7: General:
F8: N/A | G8: 0 | H8: FAD | I8: =IF(H3="bard",INDEX(bardindex,MATCH(F8,bardsize,0),MATCH(H8,bardvent,0))*G8,IF(H3="RTU",INDEX(rturef,MATCH(F8,rtusize,0),MATCH(H8,rtuvent,0))*G8,IF(H3="MARVAIR",INDEX(marairref,MATCH(F8,marvairsize,0),MATCH(H8,marvairvent,0))*G8,0))) -> 0 | L8: Hotels, Motels, Resorts, Dormitories:
