Workbook

Sheet Snow Load Conversion
A1: =IF(S7>S6,"ROOF SNOW LOAD (Low Slope), Pm",IF(D13>=15,"ROOF SNOW LOAD (Low Slope), Ps","ROOF SNOW LOAD (Low Slope), Pf")) -> ROOF SNOW LOAD (Low Slope), Pf
B3: Building Width: | C3: 24 | E3: Building Length: | F3: 60 | H3: Roof Slope: | I3: Transverse/Complex | K3: ASCE 7-10: | L3: 2012, 2015 IBC | P3: ASCE 7-10 | S3: =IF(AND(AND(D12<=7),I5=P5,D9<=1.1),0.7*D7*D9*D11*D5,IF(AND(AND(D12<=8),I5=P5,D9<=1.1),0.9*(0.7*D7*D9*D11*D5),IF(AND(AND(D12<=9),I5=P5,D9<=1.1),0.85*(0.7*D7*D9*D11*D5),IF(AND(AND(D12<=10),I5=P5,D9<=1.1),0.78*(0.7*D7*D9*D11*D5),IF(AND(AND(D12<=11),I5=P5,D9<=1.1),0.7*(0.7*D7*D9*D11*D5),IF(AND(AND(D12<=12),I5=P5,D9<=1.1),0.6*(0.7*D7*D9*D11*D5),IF(AND(AND(AND(D12<=9),I5=P5),D9>1.1,D9<1.2),0.7*D7*D9*D11*D5,IF(AND(AND(AND(D12<=10),I5=P5),D9>1.1,D9<1.2),0.95*(0.7*D7*D9*D11*D5),IF(AND(AND(AND(D12<=11),I5=P5),D9>1.1,D9<1.2),0.85*(0.7*D7*D9*D11*D5),IF(AND(AND(AND(D12<=12),I5=P5),D9>1.1,D9<1.2),0.75*(0.7*D7*D9*D11*D5),IF(AND(I5=P5,D9>=1.2),0.7*D7*D9*D11*D5,0.7*D7*D9*D11*D5))))))))))) -> 34.986 | T3: <---Cs formulas for sloped roofs (Not used) (Formulas for top portion)
K4: ASCE 7-16: | L4: 2018, 2021 IBC | P4: ASCE 7-16 | S4: =IF(AND(AND(D12<=7),I5=P5,D9<=1.1),(D22/(0.7*D7*D9*D11)),IF(AND(AND(D12<=8),I5=P5,D9<=1.1),(D22/(0.9*(0.7*D7*D9*D11))),IF(AND(AND(D12<=9),I5=P5,D9<=1.1),(D22/(0.85*(0.7*D7*D9*D11))),IF(AND(AND(D12<=10),I5=P5,D9<=1.1),(D22/(0.78*(0.7*D7*D9*D11))),IF(AND(AND(D12<=11),I5=P5,D9<=1.1),(D22/(0.7*(0.7*D7*D9*D11))),IF(AND(AND(D12<=12),I5=P5,D9<=1.1),(D22/(0.6*(0.7*D7*D9*D11))),IF(AND(AND(AND(D12<=9),I5=P5),D9>1.1,D9<1.2),(D22/(0.7*D7*D9*D11)),IF(AND(AND(AND(D12<=10),I5=P5),D9>1.1,D9<1.2),(D22/(0.95*(0.7*D7*D9*D11))),IF(AND(AND(AND(D12<=11),I5=P5),D9>1.1,D9<1.2),(D22/(0.85*(0.7*D7*D9*D11))),IF(AND(AND(AND(D12<=12),I5=P5),D9>1.1,D9<1.2),(D22/(0.75*(0.7*D7*D9*D11))),IF(AND(I5=P5,D9>=1.2),(D22/(0.7*D7*D9*D11)),(D22/(0.7*D7*D9*D11))))))))))))) -> 36.014406 | T4: <---Cs formulas for sloped roofs (Not used) (Formulas for bottom portion)
C5: Design Ground Snow Load (Pg) = | D5: 42 | E5: psf | H5: ASCE Year: | I5: ASCE 7-22 | K5: ASCE 7-22: | L5: 2024 IBC, FL, VA | P5: ASCE 7-22
C6: Wind Exposure = | D6: C | S6: =SUM(0.7*D7*D9*D11*D5) -> 34.986 | T6: <---Formula for Pf
C7: Exposure (Ce) = | D7: =P31 -> 1 | H7: Roof Insulation Value (R): | I7: 50 | J7: <--Round up to nearest value | S7: =IF(D13>15,0,IF(AND(AND(D10="I"),I5=P5,D13<=15),25,IF(AND(AND(D10="ii"),I5=P5,D13<=15),30,IF(AND(AND(D10="iii"),I5=P5,D13<=15),35,IF(AND(AND(D10="iv"),I5=P5,D13<=15),40,IF(AND(D13<=15,D5<=20),D5*D11,20*D11)))))) -> 30 | T7: <---Formula for Pm
C8: Ventilate Roof?: | D8: No | S8: =IF(AND(D5<10,I5=P5),1.2,IF(AND(I5=P5,D8="yes"),1.2,IF(AND(AND(AND(I5=P5),D8="no"),P21=0,D5>70),INDEX(Y14:Y17,MATCH(P19,P14:P17,0)),IF(AND(AND(I5=P5),D8="no",P21=0),INDEX(R14:X17,MATCH(I7,P14:P17,0),MATCH(D5,R13:Y13,0)),IF(AND(I5=P5,D8="no"),P21,IF(AND(OR(I5=P3,I5=P4,I5=P5),D8="yes"),1.1,1)))))) -> 1.19 | T8: <---Formula for Ct
C9: Thermal Factor (Ct) = | D9: =S8 -> 1.19 | I9: *Default Wind Eposure C if information is unknown | S9: =IF(D10="I",0.8,IF(D10="II",1,IF(D10="III",1.1,IF(D10="IV",1.2)))) -> 1 | T9: <---Formula for Is
C10: Risk Category = | D10: II | I10: *Default Risk Category II if information is unknown | S10: =IF(AND(AND(I5=P5),S6<S7,D13<D16/50),8,IF(AND(AND(OR(I5=P3,I5=P4)),S6<S7,D13<D16/50),5,0)) -> 0 | T10: <---Formula Rain-on-Snow Surcharge
C11: Importance Factor (Is) = | D11: =IF(D10="I",0.8,IF(D10="II",1,IF(D10="III",1.1,IF(D10="IV",1.2)))) -> 1 | I11: *See next tab for Wind Exposure and Risk Category descriptions
C12: Enter Roof Slope (decimals) = | D12: 0.25 | E12: in 12 (Max 3:12) | P12: Thermal Factor, Ct for Heated structures with Unventilated Roofs (Table 7.3-3 of ASCE 7-22)
C13: Roof Slope (Degrees) = | D13: =ATAN(D12/12)*(180/PI()) -> 1.1934894 | P13: Rroof | Q13: Uroof | R13: 10 | S13: 20 | T13: 30 | U13: 40 | V13: 50 | W13: 60 | X13: 70 | Y13: 105
C14: Roof Snow Load (Pf) = | D14: =S6+D17 -> 34.986 | E14: psf | P14: 20 | Q14: =1/P14 -> 0.05 | R14: 1.2 | S14: 1.11 | T14: 1.05 | U14: 1.01 | V14: 1 | W14: 1 | X14: 1 | Y14: 1
C15: Min. Roof Snow Load (Pm) = | D15: =S7 -> 30 | E15: psf | P15: 30 | Q15: =1/P15 -> 0.033333333 | R15: 1.2 | S15: 1.17 | T15: 1.14 | U15: 1.13 | V15: 1.12 | W15: 1.11 | X15: 1.1 | Y15: 1.1
C16: Eave to Ridge Distance = | D16: =IF(I3="transverse/complex",F3/2,IF(I3="single slope",F3,IF(I3="mono (dbl. wide)",C3/2,C3))) -> 30 | E16: ft | P16: 40 | Q16: =1/P16 -> 0.025 | R16: 1.2 | S16: 1.19 | T16: 1.17 | U16: 1.16 | V16: 1.16 | W16: 1.15 | X16: 1.15 | Y16: 1.15
C17: Rain-on-Snow Surcharge Load = | D17: =S10 -> 0 | E17: psf | P17: 50 | Q17: =1/P17 -> 0.02 | R17: 1.2 | S17: 1.2 | T17: 1.19 | U17: 1.19 | V17: 1.19 | W17: 1.18 | X17: 1.18 | Y17: 1.18
C18: =IF(D13>15,"Calculated Roof Snow Load (Ps) =",IF(S7<S6,"Calculated Roof Snow Load (Pf) =","Calculated Roof Snow Load (Pm) =")) -> Calculated Roof Snow Load (Pf) = | D18: =MAX(S6,S7) -> 34.986 | E18: psf | Q18: Row | R18: <--Interpolated values -->
C19: =IF(D13>15,"(Ps = CsPf)",IF(S7<S6,"(Pf = 0.7PgCeCtIs)",IF(S7=S6,"(Pf = Pg x Ce x Ct x I x 0.7)",IF(AND(I5=P5,S7>S6),"(Pm=Pm,max)","(Pm=IsPg)")))) -> (Pf = 0.7PgCeCtIs) | O19: Using R = | P19: =I7 -> 50 | Q19: =IF(P19<P14,1,IF(P19<P15,2,IF(P19<P16,3,4))) -> 4 | R19: =CHOOSE($Q$19-1,R14,R15,R16,R17)+(CHOOSE($Q$19,R14,R15,R16,R17)-CHOOSE($Q$19-1,R14,R15,R16,R17))*($P$19-CHOOSE($Q$19-1,$P$14,$P$15,$P$16,$P$17))/(CHOOSE($Q$19,$P$14,$P$15,$P$16,$P$17)-CHOOSE($Q$19-1,$P$14,$P$15,$P$16,$P$17)) -> 1.2 | S19: =CHOOSE($Q$19-1,S14,S15,S16,S17)+(CHOOSE($Q$19,S14,S15,S16,S17)-CHOOSE($Q$19-1,S14,S15,S16,S17))*($P$19-CHOOSE($Q$19-1,$P$14,$P$15,$P$16,$P$17))/(CHOOSE($Q$19,$P$14,$P$15,$P$16,$P$17)-CHOOSE($Q$19-1,$P$14,$P$15,$P$16,$P$17)) -> 1.2 | T19: =CHOOSE($Q$19-1,T14,T15,T16,T17)+(CHOOSE($Q$19,T14,T15,T16,T17)-CHOOSE($Q$19-1,T14,T15,T16,T17))*($P$19-CHOOSE($Q$19-1,$P$14,$P$15,$P$16,$P$17))/(CHOOSE($Q$19,$P$14,$P$15,$P$16,$P$17)-CHOOSE($Q$19-1,$P$14,$P$15,$P$16,$P$17)) -> 1.19 | U19: =CHOOSE($Q$19-1,U14,U15,U16,U17)+(CHOOSE($Q$19,U14,U15,U16,U17)-CHOOSE($Q$19-1,U14,U15,U16,U17))*($P$19-CHOOSE($Q$19-1,$P$14,$P$15,$P$16,$P$17))/(CHOOSE($Q$19,$P$14,$P$15,$P$16,$P$17)-CHOOSE($Q$19-1,$P$14,$P$15,$P$16,$P$17)) -> 1.19 | V19: =CHOOSE($Q$19-1,V14,V15,V16,V17)+(CHOOSE($Q$19,V14,V15,V16,V17)-CHOOSE($Q$19-1,V14,V15,V16,V17))*($P$19-CHOOSE($Q$19-1,$P$14,$P$15,$P$16,$P$17))/(CHOOSE($Q$19,$P$14,$P$15,$P$16,$P$17)-CHOOSE($Q$19-1,$P$14,$P$15,$P$16,$P$17)) -> 1.19 | W19: =CHOOSE($Q$19-1,W14,W15,W16,W17)+(CHOOSE($Q$19,W14,W15,W16,W17)-CHOOSE($Q$19-1,W14,W15,W16,W17))*($P$19-CHOOSE($Q$19-1,$P$14,$P$15,$P$16,$P$17))/(CHOOSE($Q$19,$P$14,$P$15,$P$16,$P$17)-CHOOSE($Q$19-1,$P$14,$P$15,$P$16,$P$17)) -> 1.18 | X19: =CHOOSE($Q$19-1,X14,X15,X16,X17)+(CHOOSE($Q$19,X14,X15,X16,X17)-CHOOSE($Q$19-1,X14,X15,X16,X17))*($P$19-CHOOSE($Q$19-1,$P$14,$P$15,$P$16,$P$17))/(CHOOSE($Q$19,$P$14,$P$15,$P$16,$P$17)-CHOOSE($Q$19-1,$P$14,$P$15,$P$16,$P$17)) -> 1.18 | Y19: =CHOOSE($Q$19-1,Y14,Y15,Y16,Y17)+(CHOOSE($Q$19,Y14,Y15,Y16,Y17)-CHOOSE($Q$19-1,Y14,Y15,Y16,Y17))*($P$19-CHOOSE($Q$19-1,$P$14,$P$15,$P$16,$P$17))/(CHOOSE($Q$19,$P$14,$P$15,$P$16,$P$17)-CHOOSE($Q$19-1,$P$14,$P$15,$P$16,$P$17)) -> 1.18
A20: ROOF SNOW LOAD TO GROUND LOAD CONVERSION | O20: Pg = | P20: =D5 -> 42 | R20: =IF(AND(($P$20-R13)<10,$P$20>R13),R19+(S19-R19)*($P$20-R13)/(S13-R13),"") | S20: =IF(AND(($P$20-S13)<10,$P$20>S13),S19+(T19-S19)*($P$20-S13)/(T13-S13),"") | T20: =IF(AND(($P$20-T13)<10,$P$20>T13),T19+(U19-T19)*($P$20-T13)/(U13-T13),"") | U20: =IF(AND(($P$20-U13)<10,$P$20>U13),U19+(V19-U19)*($P$20-U13)/(V13-U13),"") -> 1.19 | V20: =IF(AND(($P$20-V13)<10,$P$20>V13),V19+(W19-V19)*($P$20-V13)/(W13-V13),"") | W20: =IF(AND(($P$20-W13)<10,$P$20>W13),W19+(X19-W19)*($P$20-W13)/(X13-W13),"") | X20: =IF(AND(($P$20-X13)<10,$P$20>X13),X19+(Y19-X19)*($P$20-X13)/(Y13-X13),"")
O21: Use Ct= | P21: =IF(I7=">50",1.2,SUM(R20:X20)) -> 1.19
C22: Roof Snow Load = | D22: 30 | E22: psf | F22: Note: Values above need to be adjusted accordingly (Cells D6, D8, D10 & D12)
C23: Ground Snow Load = | D23: =SUM((D22)/(0.7*D7*D9*D11)) -> 36.014406 | E23: psf
P24: Table 7.3-1. Exposure Factor, Ce
Q25: Fully | R25: Partial | S25: Sheltered
P26: B | Q26: 0.9 | R26: 1 | S26: 1.2
P27: C | Q27: 0.9 | R27: 1 | S27: 1.1
P28: D | Q28: 0.8 | R28: 0.9 | S28: 1
P30: Partial | Q30: <--Default is Partially Exposed
P31: =INDEX(Q26:S28,MATCH(D6,P26:P28,0),MATCH(P30,Q25:S25,0)) -> 1 | Q31: <--Formula changes based on Exposure above

Sheet Risk Cat. - Exposure
A1: Risk Category | B1: Nature of Occupancy | E1: Note: RED is new to the 2024 IBC
A2: I | B2: Buildings and other structures that represent a low hazard to human life in the event of failure, including bu not limited to: | D2: <---Risk Cat. I is very rare
C3: -Agricultural facilities.
C4: -Certain temporary facilities
C5: -Minor storage facilities
A6: II | B6: Buildings and other structures except thos listed in Risk Categories I, III and IV. | D6: <---Most common risk Category
A7: III | B7: Buildings and other structures that represent a substantial hazard to human life in the event of failure, including but not limited to:
C8: -Florida State Funded Educational Facilities (SREF) | D8: <---Common Item
C9: -Buildings and other structures whose primary occupancy is public assembly with an occupant load greater than 300. | D9: <---Common Item
C10: -Buildings and other structures containing one or more public assembly spaces, each having an occupant load greater than 300 and a cumulative occupant load of these public assembly spaces greater than 2,500.
C11: -Buildings and other structures containing E or Group I-4 occupancies or conbination thereof, with an occupant load greater than 250. | D11: <---Common Item
C12: -Buildings and other structures containing educational occupancies for strudents above the 12th grade with an occupant load greater than 500.
C13: -Group I-3, Condition 1 occupancies.
C14: -Any other occupancy with an occupant load greater than 5,000.
C15: -Power-generating stations with individual power units rated 75 Mwac (magawatts, alternating current) or greater, water treatment facilities for potable water, wasstewater treatment facilities and other public utility facilities not included in Risk Cat. IV.
C16: -Buildings and other structures not included in Risk Cat. IV containing quantities or toxic or explosive materials that:
C17: 1. Exceed maximum allowable quantities per control area as given in Table 307.1(1) or 307.1(2) per outdoor control area in accordance with the IFC.
C18: 2. Are sufficient to pose a threat to the public if realeased.
A19: IV | B19: Buildings and other structures designated as essential facilities and buildings where loss of function represents a substantial hazard to occupants or users, including but not limited to:
C20: -Group I-2, Condition 2 occupancies.
C21: -Ambulatory care facilities having emergency surgery or emergency treatment facilities.
C22: -Group I-3 occupancies other than Condition 1.
C23: -Fire, rescue, ambulance and police stations and emergency vehicle garages. | D23: <---Apply to fire station(s) sleeping quarters
C24: -Designated eartquake, hurricane or other emergency shelters.
C25: -Public utility facilities providing power generation, potable water treatment, or wastewater treatment.
C26: -Power-generating stations and other public utility facilities required as emergency backup facilties required for emergency response.
C27: -Buildings and other structures containing quantities of highly toxic materials that:
C28: 1. Exceed maximum allowable quantities per control area as given in Table 307.1(2) per outdoor control area in accordance with the IFC.
C29: 2. Are sufficient to pose a threat to the public if realeased.
C30: -Aviation control towers, air traffic control centers and emergency aircraft hangers.
C31: -Buildings and other structures having critical national defense functions.
C32: -Water storage facilities and pump structures required to maintain water pressure for fire suppression.
A35: Wind Exposure Categories:
A36: Exposure: | B36: Description | D36: Example:
A37: B | B37: -For buildings with a mean roof height of less than 30 feet. | D37: Terrain with numerous, closely spaced obstructions that have the sinze of single-family dwellings ro larger.
B38: -Where ground surface roughness, as defined by Surface Roughness B, prevails in the upwind direction for a distance or not less than 1,500 feet.
B39: -Buildings with a mean roof height greater than 30 feert, exposure B shall apoply where Surface Roughness B prevails in the upwind direction for a distance of not less than 2,600 feet or 20 times the height of the building, whichever is greater. | D39: -Urban and suburban areas and wooded areas.
A40: C | B40: -Expsosure C shall apply for all cases where Exposure B or D does not apply. | D40: Open terrain with scattered obstructions that have heights gennerally less than 30 feet. | K40: <---Most common Wind Exposure
D41: -Flat, open country.
D42: -Grasslands.
...

Sheet Sheet1
C3: Snow Density (g): | D3: =IF(0.13*'Snow Load Conversion'!D5+14>30,30,0.13*'Snow Load Conversion'!D5+14) -> 19.46 | E3: pcf
C4: Balanced Snow Load (hb): | D4: =SUM('Snow Load Conversion'!D18/Sheet1!D3) -> 1.7978417 | E4: ft.
C5: Obstruction (Parapet) Ht: | D5: 3 | E5: ft.
C6: Clear Ht (hc): | D6: =IF(D5=0,0,IF(D5-D4<=0,0,D5-D4)) -> 1.2021583
C7: Leeward Drift (hd): | D7: =IF(D5=0,0,SUM(0.43*'Snow Load Conversion'!F3^(1/3)*('Snow Load Conversion'!D5+10)^(1/4)-1.5)) -> 3.020499 | E7: ft.
C8: hw | D8: =IF(D5=0,0,SUM(0.75*(0.43*'Snow Load Conversion'!C3^(1/3)*('Snow Load Conversion'!D5+10)^(1/4)-1.5))) -> 1.3730491 | E8: ft.
C9: Design Drift Ht (hd): | D9: =MIN(D7,D8,D6) -> 1.2021583
C10: Ratio (hc/hb): | D10: =SUM(D6/D4) -> 0.66866747 | E10: =IF(D10>=0.2,"Snow drifts required to be applied","") -> Snow drifts required to be applied
C11: Drift Length: | D11: =IF(D9<=D6,4*D9,4*D9^2/D6) -> 4.8086331
C12: Wt. of Drift at Heigh End (pd): | D12: =D9*D3 -> 23.394
C13: Rain-On-Snow Surch (prs): | D13: ='Snow Load Conversion'!D17 -> 0
C14: Balanced Snow Load pf(bal): | D14: =MAX('Snow Load Conversion'!D18,'Snow Load Conversion'!D5) -> 42
C15: Total Snow Load p(total): | D15: =SUM(D14+D12) -> 65.394

Sheet AK Ground - Snow Loads
A1: ALASKA GROUND SNOW LOAD REQUIREMENTS | K1: =SUM(D4-500)*0.15 -> 0
A2: CITY / TOWN: | B2: GROUND SNOW LOAD REQUIREMENT (lb/ft2): | C2: MIN. ROOF SNOW LOAD (lb/ft2): | D2: ELEVATION: | K2: =SUM(D25-500)*0.15 -> 0 | L2: (Pm) | M2: (Pf)
A3: Adak | B3: =IF(AND('Snow Load Conversion'!I5='Snow Load Conversion'!P5,'Snow Load Conversion'!D10="I"),32,IF(AND('Snow Load Conversion'!I5='Snow Load Conversion'!P5,'Snow Load Conversion'!D10="II"),40,IF(AND('Snow Load Conversion'!I5='Snow Load Conversion'!P5,'Snow Load Conversion'!D10="III"),46,IF(AND('Snow Load Conversion'!I5='Snow Load Conversion'!P5,'Snow Load Conversion'!D10="IV"),50,30)))) -> 40 | C3: =MAX(L3,M3) -> 33.32 | D3: 100 | E3: *Enter information on Snow Load Conversion Tab | L3: =IF(AND(AND('Snow Load Conversion'!D10="I"),'Snow Load Conversion'!I5='Snow Load Conversion'!P5,'Snow Load Conversion'!D13<=15),25,IF(AND(AND('Snow Load Conversion'!D10="ii"),'Snow Load Conversion'!I5='Snow Load Conversion'!P5,'Snow Load Conversion'!D13<=15),30,IF(AND(AND('Snow Load Conversion'!D10="iii"),'Snow Load Conversion'!I5='Snow Load Conversion'!P5,'Snow Load Conversion'!D13<=15),35,IF(AND(AND('Snow Load Conversion'!D10="iv"),'Snow Load Conversion'!I5='Snow Load Conversion'!P5,'Snow Load Conversion'!D13<=15),40,IF(B3<=20,B3*'Snow Load Conversion'!D11,20*'Snow Load Conversion'!D11))))) -> 30 | M3: =(0.7*'Snow Load Conversion'!D7*'Snow Load Conversion'!D9*'Snow Load Conversion'!D11*B3)+'Snow Load Conversion'!D17 -> 33.32 | O3: Additioanl Ground Snow Loads can be found at:
A4: Anchorage/Eagle River | B4: =IF(AND('Snow Load Conversion'!I5='Snow Load Conversion'!P5,'Snow Load Conversion'!D10="I"),64,IF(AND('Snow Load Conversion'!I5='Snow Load Conversion'!P5,'Snow Load Conversion'!D10="II"),80,IF(AND('Snow Load Conversion'!I5='Snow Load Conversion'!P5,'Snow Load Conversion'!D10="III"),92,IF(AND('Snow Load Conversion'!I5='Snow Load Conversion'!P5,'Snow Load Conversion'!D10="IV"),100,50))))+IF(D4>500,K1,0) -> 80 | C4: =MAX(L4,M4) -> 66.64 | D4: 500 | E4: <--Enter Elevation (Base: 500 feet) | L4: =IF(AND(AND('Snow Load Conversion'!D10="I"),'Snow Load Conversion'!I5='Snow Load Conversion'!P5,'Snow Load Conversion'!D13<=15),25,IF(AND(AND('Snow Load Conversion'!D10="ii"),'Snow Load Conversion'!I5='Snow Load Conversion'!P5,'Snow Load Conversion'!D13<=15),30,IF(AND(AND('Snow Load Conversion'!D10="iii"),'Snow Load Conversion'!I5='Snow Load Conversion'!P5,'Snow Load Conversion'!D13<=15),35,IF(AND(AND('Snow Load Conversion'!D10="iv"),'Snow Load Conversion'!I5='Snow Load Conversion'!P5,'Snow Load Conversion'!D13<=15),40,IF(B4<=20,B4*'Snow Load Conversion'!D11,20*'Snow Load Conversion'!D11))))) -> 30 | M4: =(0.7*'Snow Load Conversion'!D7*'Snow Load Conversion'!D9*'Snow Load Conversion'!D11*B4)+'Snow Load Conversion'!D17 -> 66.64 | O4: https://seaak.net/alaska-snow-loads
A5: =IF('Snow Load Conversion'!I5='Snow Load Conversion'!P5,"Artic Village","Angoon") -> Artic Village | B5: =IF(AND('Snow Load Conversion'!I5='Snow Load Conversion'!P5,'Snow Load Conversion'!D10="I"),38,IF(AND('Snow Load Conversion'!I5='Snow Load Conversion'!P5,'Snow Load Conversion'!D10="II"),48,IF(AND('Snow Load Conversion'!I5='Snow Load Conversion'!P5,'Snow Load Conversion'!D10="III"),55,IF(AND('Snow Load Conversion'!I5='Snow Load Conversion'!P5,'Snow Load Conversion'!D10="IV"),60,70)))) -> 48 | C5: =MAX(L5,M5) -> 39.984 | D5: 2100 | E5: *Ground Snow Loads apply to 7-10, 7-16, and 7-22 (as applicable) | L5: =IF(AND(AND('Snow Load Conversion'!D10="I"),'Snow Load Conversion'!I5='Snow Load Conversion'!P5,'Snow Load Conversion'!D13<=15),25,IF(AND(AND('Snow Load Conversion'!D10="ii"),'Snow Load Conversion'!I5='Snow Load Conversion'!P5,'Snow Load Conversion'!D13<=15),30,IF(AND(AND('Snow Load Conversion'!D10="iii"),'Snow Load Conversion'!I5='Snow Load Conversion'!P5,'Snow Load Conversion'!D13<=15),35,IF(AND(AND('Snow Load Conversion'!D10="iv"),'Snow Load Conversion'!I5='Snow Load Conversion'!P5,'Snow Load Conversion'!D13<=15),40,IF(B5<=20,B5*'Snow Load Conversion'!D11,20*'Snow Load Conversion'!D11))))) -> 30 | M5: =(0.7*'Snow Load Conversion'!D7*'Snow Load Conversion'!D9*'Snow Load Conversion'!D11*B5)+'Snow Load Conversion'!D17 -> 39.984
A6: Barrow (Utqiagvik) | B6: =IF(AND('Snow Load Conversion'!I5='Snow Load Conversion'!P5,'Snow Load Conversion'!D10="I"),32,IF(AND('Snow Load Conversion'!I5='Snow Load Conversion'!P5,'Snow Load Conversion'!D10="II"),40,IF(AND('Snow Load Conversion'!I5='Snow Load Conversion'!P5,'Snow Load Conversion'!D10="III"),46,IF(AND('Snow Load Conversion'!I5='Snow Load Conversion'!P5,'Snow Load Conversion'!D10="IV"),50,25)))) -> 40 | C6: =MAX(L6,M6) -> 33.32 | D6: 100 | L6: =IF(AND(AND('Snow Load Conversion'!D10="I"),'Snow Load Conversion'!I5='Snow Load Conversion'!P5,'Snow Load Conversion'!D13<=15),25,IF(AND(AND('Snow Load Conversion'!D10="ii"),'Snow Load Conversion'!I5='Snow Load Conversion'!P5,'Snow Load Conversion'!D13<=15),30,IF(AND(AND('Snow Load Conversion'!D10="iii"),'Snow Load Conversion'!I5='Snow Load Conversion'!P5,'Snow Load Conversion'!D13<=15),35,IF(AND(AND('Snow Load Conversion'!D10="iv"),'Snow Load Conversion'!I5='Snow Load Conversion'!P5,'Snow Load Conversion'!D13<=15),40,IF(B6<=20,B6*'Snow Load Conversion'!D11,20*'Snow Load Conversion'!D11))))) -> 30 | M6: =(0.7*'Snow Load Conversion'!D7*'Snow Load Conversion'!D9*'Snow Load Conversion'!D11*B6)+'Snow Load Conversion'!D17 -> 33.32
A7: Barter | B7: 35 | C7: =MAX(L7,M7) -> 30 | D7: 56 | L7: =IF(AND(AND('Snow Load Conversion'!D10="I"),'Snow Load Conversion'!I5='Snow Load Conversion'!P5,'Snow Load Conversion'!D13<=15),25,IF(AND(AND('Snow Load Conversion'!D10="ii"),'Snow Load Conversion'!I5='Snow Load Conversion'!P5,'Snow Load Conversion'!D13<=15),30,IF(AND(AND('Snow Load Conversion'!D10="iii"),'Snow Load Conversion'!I5='Snow Load Conversion'!P5,'Snow Load Conversion'!D13<=15),35,IF(AND(AND('Snow Load Conversion'!D10="iv"),'Snow Load Conversion'!I5='Snow Load Conversion'!P5,'Snow Load Conversion'!D13<=15),40,IF(B7<=20,B7*'Snow Load Conversion'!D11,20*'Snow Load Conversion'!D11))))) -> 30 | M7: =(0.7*'Snow Load Conversion'!D7*'Snow Load Conversion'!D9*'Snow Load Conversion'!D11*B7)+'Snow Load Conversion'!D17 -> 29.155
A8: Bethel | B8: =IF(AND('Snow Load Conversion'!I5='Snow Load Conversion'!P5,'Snow Load Conversion'!D10="I"),51,IF(AND('Snow Load Conversion'!I5='Snow Load Conversion'!P5,'Snow Load Conversion'!D10="II"),64,IF(AND('Snow Load Conversion'!I5='Snow Load Conversion'!P5,'Snow Load Conversion'!D10="III"),74,IF(AND('Snow Load Conversion'!I5='Snow Load Conversion'!P5,'Snow Load Conversion'!D10="IV"),80,40)))) -> 64 | C8: =MAX(L8,M8) -> 53.312 | D8: 100 | L8: =IF(AND(AND('Snow Load Conversion'!D10="I"),'Snow Load Conversion'!I5='Snow Load Conversion'!P5,'Snow Load Conversion'!D13<=15),25,IF(AND(AND('Snow Load Conversion'!D10="ii"),'Snow Load Conversion'!I5='Snow Load Conversion'!P5,'Snow Load Conversion'!D13<=15),30,IF(AND(AND('Snow Load Conversion'!D10="iii"),'Snow Load Conversion'!I5='Snow Load Conversion'!P5,'Snow Load Conversion'!D13<=15),35,IF(AND(AND('Snow Load Conversion'!D10="iv"),'Snow Load Conversion'!I5='Snow Load Conversion'!P5,'Snow Load Conversion'!D13<=15),40,IF(B8<=20,B8*'Snow Load Conversion'!D11,20*'Snow Load Conversion'!D11))))) -> 30 | M8: =(0.7*'Snow Load Conversion'!D7*'Snow Load Conversion'!D9*'Snow Load Conversion'!D11*B8)+'Snow Load Conversion'!D17 -> 53.312
A9: =IF('Snow Load Conversion'!I5='Snow Load Conversion'!P5,"Bettles","Big Delta") -> Bettles | B9: =IF(AND('Snow Load Conversion'!I5='Snow Load Conversion'!P5,'Snow Load Conversion'!D10="I"),102,IF(AND('Snow Load Conversion'!I5='Snow Load Conversion'!P5,'Snow Load Conversion'!D10="II"),128,IF(AND('Snow Load Conversion'!I5='Snow Load Conversion'!P5,'Snow Load Conversion'!D10="III"),147,IF(AND('Snow Load Conversion'!I5='Snow Load Conversion'!P5,'Snow Load Conversion'!D10="IV"),160,50)))) -> 128 | C9: =MAX(L9,M9) -> 106.624 | D9: 700 | L9: =IF(AND(AND('Snow Load Conversion'!D10="I"),'Snow Load Conversion'!I5='Snow Load Conversion'!P5,'Snow Load Conversion'!D13<=15),25,IF(AND(AND('Snow Load Conversion'!D10="ii"),'Snow Load Conversion'!I5='Snow Load Conversion'!P5,'Snow Load Conversion'!D13<=15),30,IF(AND(AND('Snow Load Conversion'!D10="iii"),'Snow Load Conversion'!I5='Snow Load Conversion'!P5,'Snow Load Conversion'!D13<=15),35,IF(AND(AND('Snow Load Conversion'!D10="iv"),'Snow Load Conversion'!I5='Snow Load Conversion'!P5,'Snow Load Conversion'!D13<=15),40,IF(B9<=20,B9*'Snow Load Conversion'!D11,20*'Snow Load Conversion'!D11))))) -> 30 | M9: =(0.7*'Snow Load Conversion'!D7*'Snow Load Conversion'!D9*'Snow Load Conversion'!D11*B9)+'Snow Load Conversion'!D17 -> 106.624
A10: Cantwell | B10: =IF(AND('Snow Load Conversion'!I5='Snow Load Conversion'!P5,'Snow Load Conversion'!D10="I"),109,IF(AND('Snow Load Conversion'!I5='Snow Load Conversion'!P5,'Snow Load Conversion'!D10="II"),136,IF(AND('Snow Load Conversion'!I5='Snow Load Conversion'!P5,'Snow Load Conversion'!D10="III"),156,IF(AND('Snow Load Conversion'!I5='Snow Load Conversion'!P5,'Snow Load Conversion'!D10="IV"),170,"NOT IN 7-10 OR 7-16")))) -> 136 | C10: =IF(B10="NOT IN 7-10 OR 7-16","NOT IN 7-10 OR 7-16",MAX(L10,M10)) -> 113.288 | D10: 2100 | L10: =IF(AND(AND('Snow Load Conversion'!D10="I"),'Snow Load Conversion'!I5='Snow Load Conversion'!P5,'Snow Load Conversion'!D13<=15),25,IF(AND(AND('Snow Load Conversion'!D10="ii"),'Snow Load Conversion'!I5='Snow Load Conversion'!P5,'Snow Load Conversion'!D13<=15),30,IF(AND(AND('Snow Load Conversion'!D10="iii"),'Snow Load Conversion'!I5='Snow Load Conversion'!P5,'Snow Load Conversion'!D13<=15),35,IF(AND(AND('Snow Load Conversion'!D10="iv"),'Snow Load Conversion'!I5='Snow Load Conversion'!P5,'Snow Load Conversion'!D13<=15),40,IF(B10<=20,B10*'Snow Load Conversion'!D11,20*'Snow Load Conversion'!D11))))) -> 30 | M10: =(0.7*'Snow Load Conversion'!D7*'Snow Load Conversion'!D9*'Snow Load Conversion'!D11*B10)+'Snow Load Conversion'!D17 -> 113.288
A11: Cold Bay | B11: =IF(AND('Snow Load Conversion'!I5='Snow Load Conversion'!P5,'Snow Load Conversion'!D10="I"),45,IF(AND('Snow Load Conversion'!I5='Snow Load Conversion'!P5,'Snow Load Conversion'!D10="II"),56,IF(AND('Snow Load Conversion'!I5='Snow Load Conversion'!P5,'Snow Load Conversion'!D10="III"),64,IF(AND('Snow Load Conversion'!I5='Snow Load Conversion'!P5,'Snow Load Conversion'!D10="IV"),70,25)))) -> 56 | C11: =MAX(L11,M11) -> 46.648 | D11: 100 | L11: =IF(AND(AND('Snow Load Conversion'!D10="I"),'Snow Load Conversion'!I5='Snow Load Conversion'!P5,'Snow Load Conversion'!D13<=15),25,IF(AND(AND('Snow Load Conversion'!D10="ii"),'Snow Load Conversion'!I5='Snow Load Conversion'!P5,'Snow Load Conversion'!D13<=15),30,IF(AND(AND('Snow Load Conversion'!D10="iii"),'Snow Load Conversion'!I5='Snow Load Conversion'!P5,'Snow Load Conversion'!D13<=15),35,IF(AND(AND('Snow Load Conversion'!D10="iv"),'Snow Load Conversion'!I5='Snow Load Conversion'!P5,'Snow Load Conversion'!D13<=15),40,IF(B11<=20,B11*'Snow Load Conversion'!D11,20*'Snow Load Conversion'!D11))))) -> 30 | M11: =(0.7*'Snow Load Conversion'!D7*'Snow Load Conversion'!D9*'Snow Load Conversion'!D11*B11)+'Snow Load Conversion'!D17 -> 46.648
A12: Cordova | B12: =IF(AND('Snow Load Conversion'!I5='Snow Load Conversion'!P5,'Snow Load Conversion'!D10="I"),128,IF(AND('Snow Load Conversion'!I5='Snow Load Conversion'!P5,'Snow Load Conversion'!D10="II"),160,IF(AND('Snow Load Conversion'!I5='Snow Load Conversion'!P5,'Snow Load Conversion'!D10="III"),184,IF(AND('Snow Load Conversion'!I5='Snow Load Conversion'!P5,'Snow Load Conversion'!D10="IV"),200,100)))) -> 160 | C12: =MAX(L12,M12) -> 133.28 | D12: 100 | L12: =IF(AND(AND('Snow Load Conversion'!D10="I"),'Snow Load Conversion'!I5='Snow Load Conversion'!P5,'Snow Load Conversion'!D13<=15),25,IF(AND(AND('Snow Load Conversion'!D10="ii"),'Snow Load Conversion'!I5='Snow Load Conversion'!P5,'Snow Load Conversion'!D13<=15),30,IF(AND(AND('Snow Load Conversion'!D10="iii"),'Snow Load Conversion'!I5='Snow Load Conversion'!P5,'Snow Load Conversion'!D13<=15),35,IF(AND(AND('Snow Load Conversion'!D10="iv"),'Snow Load Conversion'!I5='Snow Load Conversion'!P5,'Snow Load Conversion'!D13<=15),40,IF(B12<=20,B12*'Snow Load Conversion'!D11,20*'Snow Load Conversion'!D11))))) -> 30 | M12: =(0.7*'Snow Load Conversion'!D7*'Snow Load Conversion'!D9*'Snow Load Conversion'!D11*B12)+'Snow Load Conversion'!D17 -> 133.28
A13: Deadhorse | B13: =IF(AND('Snow Load Conversion'!I5='Snow Load Conversion'!P5,'Snow Load Conversion'!D10="I"),32,IF(AND('Snow Load Conversion'!I5='Snow Load Conversion'!P5,'Snow Load Conversion'!D10="II"),40,IF(AND('Snow Load Conversion'!I5='Snow Load Conversion'!P5,'Snow Load Conversion'!D10="III"),46,IF(AND('Snow Load Conversion'!I5='Snow Load Conversion'!P5,'Snow Load Conversion'!D10="IV"),50,"NOT IN 7-10 OR 7-16")))) -> 40 | C13: =IF(B13="NOT IN 7-10 OR 7-16","NOT IN 7-10 OR 7-16",MAX(L13,M13)) -> 33.32 | D13: 100 | L13: =IF(AND(AND('Snow Load Conversion'!D10="I"),'Snow Load Conversion'!I5='Snow Load Conversion'!P5,'Snow Load Conversion'!D13<=15),25,IF(AND(AND('Snow Load Conversion'!D10="ii"),'Snow Load Conversion'!I5='Snow Load Conversion'!P5,'Snow Load Conversion'!D13<=15),30,IF(AND(AND('Snow Load Conversion'!D10="iii"),'Snow Load Conversion'!I5='Snow Load Conversion'!P5,'Snow Load Conversion'!D13<=15),35,IF(AND(AND('Snow Load Conversion'!D10="iv"),'Snow Load Conversion'!I5='Snow Load Conversion'!P5,'Snow Load Conversion'!D13<=15),40,IF(B13<=20,B13*'Snow Load Conversion'!D11,20*'Snow Load Conversion'!D11))))) -> 30 | M13: =(0.7*'Snow Load Conversion'!D7*'Snow Load Conversion'!D9*'Snow Load Conversion'!D11*B13)+'Snow Load Conversion'!D17 -> 33.32
A14: Delta Junction | B14: =IF(AND('Snow Load Conversion'!I5='Snow Load Conversion'!P5,'Snow Load Conversion'!D10="I"),51,IF(AND('Snow Load Conversion'!I5='Snow Load Conversion'!P5,'Snow Load Conversion'!D10="II"),64,IF(AND('Snow Load Conversion'!I5='Snow Load Conversion'!P5,'Snow Load Conversion'!D10="III"),74,IF(AND('Snow Load Conversion'!I5='Snow Load Conversion'!P5,'Snow Load Conversion'!D10="IV"),80,"NOT IN 7-10 OR 7-16")))) -> 64 | C14: =IF(B14="NOT IN 7-10 OR 7-16","NOT IN 7-10 OR 7-16",MAX(L14,M14)) -> 53.312 | D14: 400 | L14: =IF(AND(AND('Snow Load Conversion'!D10="I"),'Snow Load Conversion'!I5='Snow Load Conversion'!P5,'Snow Load Conversion'!D13<=15),25,IF(AND(AND('Snow Load Conversion'!D10="ii"),'Snow Load Conversion'!I5='Snow Load Conversion'!P5,'Snow Load Conversion'!D13<=15),30,IF(AND(AND('Snow Load Conversion'!D10="iii"),'Snow Load Conversion'!I5='Snow Load Conversion'!P5,'Snow Load Conversion'!D13<=15),35,IF(AND(AND('Snow Load Conversion'!D10="iv"),'Snow Load Conversion'!I5='Snow Load Conversion'!P5,'Snow Load Conversion'!D13<=15),40,IF(B14<=20,B14*'Snow Load Conversion'!D11,20*'Snow Load Conversion'!D11))))) -> 30 | M14: =(0.7*'Snow Load Conversion'!D7*'Snow Load Conversion'!D9*'Snow Load Conversion'!D11*B14)+'Snow Load Conversion'!D17 -> 53.312
A15: Dillingham | B15: =IF(AND('Snow Load Conversion'!I5='Snow Load Conversion'!P5,'Snow Load Conversion'!D10="I"),141,IF(AND('Snow Load Conversion'!I5='Snow Load Conversion'!P5,'Snow Load Conversion'!D10="II"),176,IF(AND('Snow Load Conversion'!I5='Snow Load Conversion'!P5,'Snow Load Conversion'!D10="III"),202,IF(AND('Snow Load Conversion'!I5='Snow Load Conversion'!P5,'Snow Load Conversion'!D10="IV"),220,"NOT IN 7-10 OR 7-16")))) -> 176 | C15: =IF(B15="NOT IN 7-10 OR 7-16","NOT IN 7-10 OR 7-16",MAX(L15,M15)) -> 146.608 | D15: 100 | L15: =IF(AND(AND('Snow Load Conversion'!D10="I"),'Snow Load Conversion'!I5='Snow Load Conversion'!P5,'Snow Load Conversion'!D13<=15),25,IF(AND(AND('Snow Load Conversion'!D10="ii"),'Snow Load Conversion'!I5='Snow Load Conversion'!P5,'Snow Load Conversion'!D13<=15),30,IF(AND(AND('Snow Load Conversion'!D10="iii"),'Snow Load Conversion'!I5='Snow Load Conversion'!P5,'Snow Load Conversion'!D13<=15),35,IF(AND(AND('Snow Load Conversion'!D10="iv"),'Snow Load Conversion'!I5='Snow Load Conversion'!P5,'Snow Load Conversion'!D13<=15),40,IF(B15<=20,B15*'Snow Load Conversion'!D11,20*'Snow Load Conversion'!D11))))) -> 30 | M15: =(0.7*'Snow Load Conversion'!D7*'Snow Load Conversion'!D9*'Snow Load Conversion'!D11*B15)+'Snow Load Conversion'!D17 -> 146.608
A16: Emmonak | B16: =IF(AND('Snow Load Conversion'!I5='Snow Load Conversion'!P5,'Snow Load Conversion'!D10="I"),128,IF(AND('Snow Load Conversion'!I5='Snow Load Conversion'!P5,'Snow Load Conversion'!D10="II"),160,IF(AND('Snow Load Conversion'!I5='Snow Load Conversion'!P5,'Snow Load Conversion'!D10="III"),184,IF(AND('Snow Load Conversion'!I5='Snow Load Conversion'!P5,'Snow Load Conversion'!D10="IV"),200,"NOT IN 7-10 OR 7-16")))) -> 160 | C16: =IF(B16="NOT IN 7-10 OR 7-16","NOT IN 7-10 OR 7-16",MAX(L16,M16)) -> 133.28 | D16: 100 | L16: =IF(AND(AND('Snow Load Conversion'!D10="I"),'Snow Load Conversion'!I5='Snow Load Conversion'!P5,'Snow Load Conversion'!D13<=15),25,IF(AND(AND('Snow Load Conversion'!D10="ii"),'Snow Load Conversion'!I5='Snow Load Conversion'!P5,'Snow Load Conversion'!D13<=15),30,IF(AND(AND('Snow Load Conversion'!D10="iii"),'Snow Load Conversion'!I5='Snow Load Conversion'!P5,'Snow Load Conversion'!D13<=15),35,IF(AND(AND('Snow Load Conversion'!D10="iv"),'Snow Load Conversion'!I5='Snow Load Conversion'!P5,'Snow Load Conversion'!D13<=15),40,IF(B16<=20,B16*'Snow Load Conversion'!D11,20*'Snow Load Conversion'!D11))))) -> 30 | M16: =(0.7*'Snow Load Conversion'!D7*'Snow Load Conversion'!D9*'Snow Load Conversion'!D11*B16)+'Snow Load Conversion'!D17 -> 133.28
A17: Fairbanks | B17: =IF(AND('Snow Load Conversion'!I5='Snow Load Conversion'!P5,'Snow Load Conversion'!D10="I"),77,IF(AND('Snow Load Conversion'!I5='Snow Load Conversion'!P5,'Snow Load Conversion'!D10="II"),96,IF(AND('Snow Load Conversion'!I5='Snow Load Conversion'!P5,'Snow Load Conversion'!D10="III"),110,IF(AND('Snow Load Conversion'!I5='Snow Load Conversion'!P5,'Snow Load Conversion'!D10="IV"),120,60)))) -> 96 | C17: =MAX(L17,M17) -> 79.968 | D17: 1200 | L17: =IF(AND(AND('Snow Load Conversion'!D10="I"),'Snow Load Conversion'!I5='Snow Load Conversion'!P5,'Snow Load Conversion'!D13<=15),25,IF(AND(AND('Snow Load Conversion'!D10="ii"),'Snow Load Conversion'!I5='Snow Load Conversion'!P5,'Snow Load Conversion'!D13<=15),30,IF(AND(AND('Snow Load Conversion'!D10="iii"),'Snow Load Conversion'!I5='Snow Load Conversion'!P5,'Snow Load Conversion'!D13<=15),35,IF(AND(AND('Snow Load Conversion'!D10="iv"),'Snow Load Conversion'!I5='Snow Load Conversion'!P5,'Snow Load Conversion'!D13<=15),40,IF(B17<=20,B17*'Snow Load Conversion'!D11,20*'Snow Load Conversion'!D11))))) -> 30 | M17: =(0.7*'Snow Load Conversion'!D7*'Snow Load Conversion'!D9*'Snow Load Conversion'!D11*B17)+'Snow Load Conversion'!D17 -> 79.968
A18: Fort Yukon | B18: =IF(AND('Snow Load Conversion'!I5='Snow Load Conversion'!P5,'Snow Load Conversion'!D10="I"),64,IF(AND('Snow Load Conversion'!I5='Snow Load Conversion'!P5,'Snow Load Conversion'!D10="II"),80,IF(AND('Snow Load Conversion'!I5='Snow Load Conversion'!P5,'Snow Load Conversion'!D10="III"),92,IF(AND('Snow Load Conversion'!I5='Snow Load Conversion'!P5,'Snow Load Conversion'!D10="IV"),100,60)))) -> 80 | C18: =MAX(L18,M18) -> 66.64 | D18: 400 | L18: =IF(AND(AND('Snow Load Conversion'!D10="I"),'Snow Load Conversion'!I5='Snow Load Conversion'!P5,'Snow Load Conversion'!D13<=15),25,IF(AND(AND('Snow Load Conversion'!D10="ii"),'Snow Load Conversion'!I5='Snow Load Conversion'!P5,'Snow Load Conversion'!D13<=15),30,IF(AND(AND('Snow Load Conversion'!D10="iii"),'Snow Load Conversion'!I5='Snow Load Conversion'!P5,'Snow Load Conversion'!D13<=15),35,IF(AND(AND('Snow Load Conversion'!D10="iv"),'Snow Load Conversion'!I5='Snow Load Conversion'!P5,'Snow Load Conversion'!D13<=15),40,IF(B18<=20,B18*'Snow Load Conversion'!D11,20*'Snow Load Conversion'!D11))))) -> 30 | M18: =(0.7*'Snow Load Conversion'!D7*'Snow Load Conversion'!D9*'Snow Load Conversion'!D11*B18)+'Snow Load Conversion'!D17 -> 66.64
A19: Galena | B19: =IF(AND('Snow Load Conversion'!I5='Snow Load Conversion'!P5,'Snow Load Conversion'!D10="I"),77,IF(AND('Snow Load Conversion'!I5='Snow Load Conversion'!P5,'Snow Load Conversion'!D10="II"),96,IF(AND('Snow Load Conversion'!I5='Snow Load Conversion'!P5,'Snow Load Conversion'!D10="III"),110,IF(AND('Snow Load Conversion'!I5='Snow Load Conversion'!P5,'Snow Load Conversion'!D10="IV"),120,60)))) -> 96 | C19: =MAX(L19,M19) -> 79.968 | D19: 200 | L19: =IF(AND(AND('Snow Load Conversion'!D10="I"),'Snow Load Conversion'!I5='Snow Load Conversion'!P5,'Snow Load Conversion'!D13<=15),25,IF(AND(AND('Snow Load Conversion'!D10="ii"),'Snow Load Conversion'!I5='Snow Load Conversion'!P5,'Snow Load Conversion'!D13<=15),30,IF(AND(AND('Snow Load Conversion'!D10="iii"),'Snow Load Conversion'!I5='Snow Load Conversion'!P5,'Snow Load Conversion'!D13<=15),35,IF(AND(AND('Snow Load Conversion'!D10="iv"),'Snow Load Conversion'!I5='Snow Load Conversion'!P5,'Snow Load Conversion'!D13<=15),40,IF(B19<=20,B19*'Snow Load Conversion'!D11,20*'Snow Load Conversion'!D11))))) -> 30 | M19: =(0.7*'Snow Load Conversion'!D7*'Snow Load Conversion'!D9*'Snow Load Conversion'!D11*B19)+'Snow Load Conversion'!D17 -> 79.968
A20: Girdwood | B20: =IF(AND('Snow Load Conversion'!I5='Snow Load Conversion'!P5,'Snow Load Conversion'!D10="I"),179,IF(AND('Snow Load Conversion'!I5='Snow Load Conversion'!P5,'Snow Load Conversion'!D10="II"),224,IF(AND('Snow Load Conversion'!I5='Snow Load Conversion'!P5,'Snow Load Conversion'!D10="III"),258,IF(AND('Snow Load Conversion'!I5='Snow Load Conversion'!P5,'Snow Load Conversion'!D10="IV"),280,"NOT IN 7-10 OR 7-16")))) -> 224 | C20: =IF(B20="NOT IN 7-10 OR 7-16","NOT IN 7-10 OR 7-16",MAX(L20,M20)) -> 186.592 | D20: 200 | L20: =IF(AND(AND('Snow Load Conversion'!D10="I"),'Snow Load Conversion'!I5='Snow Load Conversion'!P5,'Snow Load Conversion'!D13<=15),25,IF(AND(AND('Snow Load Conversion'!D10="ii"),'Snow Load Conversion'!I5='Snow Load Conversion'!P5,'Snow Load Conversion'!D13<=15),30,IF(AND(AND('Snow Load Conversion'!D10="iii"),'Snow Load Conversion'!I5='Snow Load Conversion'!P5,'Snow Load Conversion'!D13<=15),35,IF(AND(AND('Snow Load Conversion'!D10="iv"),'Snow Load Conversion'!I5='Snow Load Conversion'!P5,'Snow Load Conversion'!D13<=15),40,IF(B20<=20,B20*'Snow Load Conversion'!D11,20*'Snow Load Conversion'!D11))))) -> 30 | M20: =(0.7*'Snow Load Conversion'!D7*'Snow Load Conversion'!D9*'Snow Load Conversion'!D11*B20)+'Snow Load Conversion'!D17 -> 186.592
A21: Glennallen | B21: =IF(AND('Snow Load Conversion'!I5='Snow Load Conversion'!P5,'Snow Load Conversion'!D10="I"),58,IF(AND('Snow Load Conversion'!I5='Snow Load Conversion'!P5,'Snow Load Conversion'!D10="II"),72,IF(AND('Snow Load Conversion'!I5='Snow Load Conversion'!P5,'Snow Load Conversion'!D10="III"),83,IF(AND('Snow Load Conversion'!I5='Snow Load Conversion'!P5,'Snow Load Conversion'!D10="IV"),90,"NOT IN 7-10 OR 7-16")))) -> 72 | C21: =IF(B21="NOT IN 7-10 OR 7-16","NOT IN 7-10 OR 7-16",MAX(L21,M21)) -> 59.976 | D21: 1400 | L21: =IF(AND(AND('Snow Load Conversion'!D10="I"),'Snow Load Conversion'!I5='Snow Load Conversion'!P5,'Snow Load Conversion'!D13<=15),25,IF(AND(AND('Snow Load Conversion'!D10="ii"),'Snow Load Conversion'!I5='Snow Load Conversion'!P5,'Snow Load Conversion'!D13<=15),30,IF(AND(AND('Snow Load Conversion'!D10="iii"),'Snow Load Conversion'!I5='Snow Load Conversion'!P5,'Snow Load Conversion'!D13<=15),35,IF(AND(AND('Snow Load Conversion'!D10="iv"),'Snow Load Conversion'!I5='Snow Load Conversion'!P5,'Snow Load Conversion'!D13<=15),40,IF(B21<=20,B21*'Snow Load Conversion'!D11,20*'Snow Load Conversion'!D11))))) -> 30 | M21: =(0.7*'Snow Load Conversion'!D7*'Snow Load Conversion'!D9*'Snow Load Conversion'!D11*B21)+'Snow Load Conversion'!D17 -> 59.976
A22: Gulkana | B22: 70 | C22: =MAX(L22,M22) -> 58.31 | D22: 1400 | L22: =IF(AND(AND('Snow Load Conversion'!D10="I"),'Snow Load Conversion'!I5='Snow Load Conversion'!P5,'Snow Load Conversion'!D13<=15),25,IF(AND(AND('Snow Load Conversion'!D10="ii"),'Snow Load Conversion'!I5='Snow Load Conversion'!P5,'Snow Load Conversion'!D13<=15),30,IF(AND(AND('Snow Load Conversion'!D10="iii"),'Snow Load Conversion'!I5='Snow Load Conversion'!P5,'Snow Load Conversion'!D13<=15),35,IF(AND(AND('Snow Load Conversion'!D10="iv"),'Snow Load Conversion'!I5='Snow Load Conversion'!P5,'Snow Load Conversion'!D13<=15),40,IF(B22<=20,B22*'Snow Load Conversion'!D11,20*'Snow Load Conversion'!D11))))) -> 30 | M22: =(0.7*'Snow Load Conversion'!D7*'Snow Load Conversion'!D9*'Snow Load Conversion'!D11*B22)+'Snow Load Conversion'!D17 -> 58.31
A23: Haines | B23: =IF(AND('Snow Load Conversion'!I5='Snow Load Conversion'!P5,'Snow Load Conversion'!D10="I"),237,IF(AND('Snow Load Conversion'!I5='Snow Load Conversion'!P5,'Snow Load Conversion'!D10="II"),296,IF(AND('Snow Load Conversion'!I5='Snow Load Conversion'!P5,'Snow Load Conversion'!D10="III"),340,IF(AND('Snow Load Conversion'!I5='Snow Load Conversion'!P5,'Snow Load Conversion'!D10="IV"),370,"NOT IN 7-10 OR 7-16")))) -> 296 | C23: =IF(B23="NOT IN 7-10 OR 7-16","NOT IN 7-10 OR 7-16",MAX(L23,M23)) -> 246.568 | D23: 100 | L23: =IF(AND(AND('Snow Load Conversion'!D10="I"),'Snow Load Conversion'!I5='Snow Load Conversion'!P5,'Snow Load Conversion'!D13<=15),25,IF(AND(AND('Snow Load Conversion'!D10="ii"),'Snow Load Conversion'!I5='Snow Load Conversion'!P5,'Snow Load Conversion'!D13<=15),30,IF(AND(AND('Snow Load Conversion'!D10="iii"),'Snow Load Conversion'!I5='Snow Load Conversion'!P5,'Snow Load Conversion'!D13<=15),35,IF(AND(AND('Snow Load Conversion'!D10="iv"),'Snow Load Conversion'!I5='Snow Load Conversion'!P5,'Snow Load Conversion'!D13<=15),40,IF(B23<=20,B23*'Snow Load Conversion'!D11,20*'Snow Load Conversion'!D11))))) -> 30 | M23: =(0.7*'Snow Load Conversion'!D7*'Snow Load Conversion'!D9*'Snow Load Conversion'!D11*B23)+'Snow Load Conversion'!D17 -> 246.568
A24: Holy Cross | B24: =IF(AND('Snow Load Conversion'!I5='Snow Load Conversion'!P5,'Snow Load Conversion'!D10="I"),154,IF(AND('Snow Load Conversion'!I5='Snow Load Conversion'!P5,'Snow Load Conversion'!D10="II"),192,IF(AND('Snow Load Conversion'!I5='Snow Load Conversion'!P5,'Snow Load Conversion'!D10="III"),221,IF(AND('Snow Load Conversion'!I5='Snow Load Conversion'!P5,'Snow Load Conversion'!D10="IV"),240,"NOT IN 7-10 OR 7-16")))) -> 192 | C24: =IF(B24="NOT IN 7-10 OR 7-16","NOT IN 7-10 OR 7-16",MAX(L24,M24)) -> 159.936 | D24: 100 | L24: =IF(AND(AND('Snow Load Conversion'!D10="I"),'Snow Load Conversion'!I5='Snow Load Conversion'!P5,'Snow Load Conversion'!D13<=15),25,IF(AND(AND('Snow Load Conversion'!D10="ii"),'Snow Load Conversion'!I5='Snow Load Conversion'!P5,'Snow Load Conversion'!D13<=15),30,IF(AND(AND('Snow Load Conversion'!D10="iii"),'Snow Load Conversion'!I5='Snow Load Conversion'!P5,'Snow Load Conversion'!D13<=15),35,IF(AND(AND('Snow Load Conversion'!D10="iv"),'Snow Load Conversion'!I5='Snow Load Conversion'!P5,'Snow Load Conversion'!D13<=15),40,IF(B24<=20,B24*'Snow Load Conversion'!D11,20*'Snow Load Conversion'!D11))))) -> 30 | M24: =(0.7*'Snow Load Conversion'!D7*'Snow Load Conversion'!D9*'Snow Load Conversion'!D11*B24)+'Snow Load Conversion'!D17 -> 159.936
A25: Homer | B25: =IF(AND('Snow Load Conversion'!I5='Snow Load Conversion'!P5,'Snow Load Conversion'!D10="I"),58,IF(AND('Snow Load Conversion'!I5='Snow Load Conversion'!P5,'Snow Load Conversion'!D10="II"),72,IF(AND('Snow Load Conversion'!I5='Snow Load Conversion'!P5,'Snow Load Conversion'!D10="III"),83,IF(AND('Snow Load Conversion'!I5='Snow Load Conversion'!P5,'Snow Load Conversion'!D10="IV"),90,40))))+IF(D25>500,K2,0) -> 72 | C25: =MAX(L25,M25) -> 59.976 | D25: 500 | E25: <--Enter Elevation (Base: 500 feet) | L25: =IF(AND(AND('Snow Load Conversion'!D10="I"),'Snow Load Conversion'!I5='Snow Load Conversion'!P5,'Snow Load Conversion'!D13<=15),25,IF(AND(AND('Snow Load Conversion'!D10="ii"),'Snow Load Conversion'!I5='Snow Load Conversion'!P5,'Snow Load Conversion'!D13<=15),30,IF(AND(AND('Snow Load Conversion'!D10="iii"),'Snow Load Conversion'!I5='Snow Load Conversion'!P5,'Snow Load Conversion'!D13<=15),35,IF(AND(AND('Snow Load Conversion'!D10="iv"),'Snow Load Conversion'!I5='Snow Load Conversion'!P5,'Snow Load Conversion'!D13<=15),40,IF(B25<=20,B25*'Snow Load Conversion'!D11,20*'Snow Load Conversion'!D11))))) -> 30 | M25: =(0.7*'Snow Load Conversion'!D7*'Snow Load Conversion'!D9*'Snow Load Conversion'!D11*B25)+'Snow Load Conversion'!D17 -> 59.976
A26: Iliamna | B26: =IF(AND('Snow Load Conversion'!I5='Snow Load Conversion'!P5,'Snow Load Conversion'!D10="I"),102,IF(AND('Snow Load Conversion'!I5='Snow Load Conversion'!P5,'Snow Load Conversion'!D10="II"),128,IF(AND('Snow Load Conversion'!I5='Snow Load Conversion'!P5,'Snow Load Conversion'!D10="III"),147,IF(AND('Snow Load Conversion'!I5='Snow Load Conversion'!P5,'Snow Load Conversion'!D10="IV"),160,"NOT IN 7-10 OR 7-16")))) -> 128 | C26: =IF(B26="NOT IN 7-10 OR 7-16","NOT IN 7-10 OR 7-16",MAX(L26,M26)) -> 106.624 | D26: 200 | L26: =IF(AND(AND('Snow Load Conversion'!D10="I"),'Snow Load Conversion'!I5='Snow Load Conversion'!P5,'Snow Load Conversion'!D13<=15),25,IF(AND(AND('Snow Load Conversion'!D10="ii"),'Snow Load Conversion'!I5='Snow Load Conversion'!P5,'Snow Load Conversion'!D13<=15),30,IF(AND(AND('Snow Load Conversion'!D10="iii"),'Snow Load Conversion'!I5='Snow Load Conversion'!P5,'Snow Load Conversion'!D13<=15),35,IF(AND(AND('Snow Load Conversion'!D10="iv"),'Snow Load Conversion'!I5='Snow Load Conversion'!P5,'Snow Load Conversion'!D13<=15),40,IF(B26<=20,B26*'Snow Load Conversion'!D11,20*'Snow Load Conversion'!D11))))) -> 30 | M26: =(0.7*'Snow Load Conversion'!D7*'Snow Load Conversion'!D9*'Snow Load Conversion'!D11*B26)+'Snow Load Conversion'!D17 -> 106.624
A27: Juneau | B27: =IF(AND('Snow Load Conversion'!I5='Snow Load Conversion'!P5,'Snow Load Conversion'!D10="I"),90,IF(AND('Snow Load Conversion'!I5='Snow Load Conversion'!P5,'Snow Load Conversion'!D10="II"),112,IF(AND('Snow Load Conversion'!I5='Snow Load Conversion'!P5,'Snow Load Conversion'!D10="III"),129,IF(AND('Snow Load Conversion'!I5='Snow Load Conversion'!P5,'Snow Load Conversion'!D10="IV"),140,60)))) -> 112 | C27: =MAX(L27,M27) -> 93.296 | D27: 100 | L27: =IF(AND(AND('Snow Load Conversion'!D10="I"),'Snow Load Conversion'!I5='Snow Load Conversion'!P5,'Snow Load Conversion'!D13<=15),25,IF(AND(AND('Snow Load Conversion'!D10="ii"),'Snow Load Conversion'!I5='Snow Load Conversion'!P5,'Snow Load Conversion'!D13<=15),30,IF(AND(AND('Snow Load Conversion'!D10="iii"),'Snow Load Conversion'!I5='Snow Load Conversion'!P5,'Snow Load Conversion'!D13<=15),35,IF(AND(AND('Snow Load Conversion'!D10="iv"),'Snow Load Conversion'!I5='Snow Load Conversion'!P5,'Snow Load Conversion'!D13<=15),40,IF(B27<=20,B27*'Snow Load Conversion'!D11,20*'Snow Load Conversion'!D11))))) -> 30 | M27: =(0.7*'Snow Load Conversion'!D7*'Snow Load Conversion'!D9*'Snow Load Conversion'!D11*B27)+'Snow Load Conversion'!D17 -> 93.296
A28: Kaktovik | B28: =IF(AND('Snow Load Conversion'!I5='Snow Load Conversion'!P5,'Snow Load Conversion'!D10="I"),58,IF(AND('Snow Load Conversion'!I5='Snow Load Conversion'!P5,'Snow Load Conversion'!D10="II"),72,IF(AND('Snow Load Conversion'!I5='Snow Load Conversion'!P5,'Snow Load Conversion'!D10="III"),83,IF(AND('Snow Load Conversion'!I5='Snow Load Conversion'!P5,'Snow Load Conversion'!D10="IV"),90,"NOT IN 7-10 OR 7-16")))) -> 72 | C28: =IF(B28="NOT IN 7-10 OR 7-16","NOT IN 7-10 OR 7-16",MAX(L28,M28)) -> 59.976 | D28: 100 | L28: =IF(AND(AND('Snow Load Conversion'!D10="I"),'Snow Load Conversion'!I5='Snow Load Conversion'!P5,'Snow Load Conversion'!D13<=15),25,IF(AND(AND('Snow Load Conversion'!D10="ii"),'Snow Load Conversion'!I5='Snow Load Conversion'!P5,'Snow Load Conversion'!D13<=15),30,IF(AND(AND('Snow Load Conversion'!D10="iii"),'Snow Load Conversion'!I5='Snow Load Conversion'!P5,'Snow Load Conversion'!D13<=15),35,IF(AND(AND('Snow Load Conversion'!D10="iv"),'Snow Load Conversion'!I5='Snow Load Conversion'!P5,'Snow Load Conversion'!D13<=15),40,IF(B28<=20,B28*'Snow Load Conversion'!D11,20*'Snow Load Conversion'!D11))))) -> 30 | M28: =(0.7*'Snow Load Conversion'!D7*'Snow Load Conversion'!D9*'Snow Load Conversion'!D11*B28)+'Snow Load Conversion'!D17 -> 59.976
A29: Kenai/Soldotna | B29: =IF(AND('Snow Load Conversion'!I5='Snow Load Conversion'!P5,'Snow Load Conversion'!D10="I"),83,IF(AND('Snow Load Conversion'!I5='Snow Load Conversion'!P5,'Snow Load Conversion'!D10="II"),104,IF(AND('Snow Load Conversion'!I5='Snow Load Conversion'!P5,'Snow Load Conversion'!D10="III"),120,IF(AND('Snow Load Conversion'!I5='Snow Load Conversion'!P5,'Snow Load Conversion'!D10="IV"),130,70)))) -> 104 | C29: =MAX(L29,M29) -> 86.632 | D29: 200 | L29: =IF(AND(AND('Snow Load Conversion'!D10="I"),'Snow Load Conversion'!I5='Snow Load Conversion'!P5,'Snow Load Conversion'!D13<=15),25,IF(AND(AND('Snow Load Conversion'!D10="ii"),'Snow Load Conversion'!I5='Snow Load Conversion'!P5,'Snow Load Conversion'!D13<=15),30,IF(AND(AND('Snow Load Conversion'!D10="iii"),'Snow Load Conversion'!I5='Snow Load Conversion'!P5,'Snow Load Conversion'!D13<=15),35,IF(AND(AND('Snow Load Conversion'!D10="iv"),'Snow Load Conversion'!I5='Snow Load Conversion'!P5,'Snow Load Conversion'!D13<=15),40,IF(B29<=20,B29*'Snow Load Conversion'!D11,20*'Snow Load Conversion'!D11))))) -> 30 | M29: =(0.7*'Snow Load Conversion'!D7*'Snow Load Conversion'!D9*'Snow Load Conversion'!D11*B29)+'Snow Load Conversion'!D17 -> 86.632
A30: Ketchikan | B30: =IF(AND('Snow Load Conversion'!I5='Snow Load Conversion'!P5,'Snow Load Conversion'!D10="I"),38,IF(AND('Snow Load Conversion'!I5='Snow Load Conversion'!P5,'Snow Load Conversion'!D10="II"),48,IF(AND('Snow Load Conversion'!I5='Snow Load Conversion'!P5,'Snow Load Conversion'!D10="III"),55,IF(AND('Snow Load Conversion'!I5='Snow Load Conversion'!P5,'Snow Load Conversion'!D10="IV"),60,"NOT IN 7-10 OR 7-16")))) -> 48 | C30: =IF(B30="NOT IN 7-10 OR 7-16","NOT IN 7-10 OR 7-16",MAX(L30,M30)) -> 39.984 | D30: 100 | L30: =IF(AND(AND('Snow Load Conversion'!D10="I"),'Snow Load Conversion'!I5='Snow Load Conversion'!P5,'Snow Load Conversion'!D13<=15),25,IF(AND(AND('Snow Load Conversion'!D10="ii"),'Snow Load Conversion'!I5='Snow Load Conversion'!P5,'Snow Load Conversion'!D13<=15),30,IF(AND(AND('Snow Load Conversion'!D10="iii"),'Snow Load Conversion'!I5='Snow Load Conversion'!P5,'Snow Load Conversion'!D13<=15),35,IF(AND(AND('Snow Load Conversion'!D10="iv"),'Snow Load Conversion'!I5='Snow Load Conversion'!P5,'Snow Load Conversion'!D13<=15),40,IF(B30<=20,B30*'Snow Load Conversion'!D11,20*'Snow Load Conversion'!D11))))) -> 30 | M30: =(0.7*'Snow Load Conversion'!D7*'Snow Load Conversion'!D9*'Snow Load Conversion'!D11*B30)+'Snow Load Conversion'!D17 -> 39.984
A31: Kobuk | B31: =IF(AND('Snow Load Conversion'!I5='Snow Load Conversion'!P5,'Snow Load Conversion'!D10="I"),115,IF(AND('Snow Load Conversion'!I5='Snow Load Conversion'!P5,'Snow Load Conversion'!D10="II"),144,IF(AND('Snow Load Conversion'!I5='Snow Load Conversion'!P5,'Snow Load Conversion'!D10="III"),166,IF(AND('Snow Load Conversion'!I5='Snow Load Conversion'!P5,'Snow Load Conversion'!D10="IV"),180,"NOT IN 7-10 OR 7-16")))) -> 144 | C31: =IF(B31="NOT IN 7-10 OR 7-16","NOT IN 7-10 OR 7-16",MAX(L31,M31)) -> 119.952 | D31: 200 | L31: =IF(AND(AND('Snow Load Conversion'!D10="I"),'Snow Load Conversion'!I5='Snow Load Conversion'!P5,'Snow Load Conversion'!D13<=15),25,IF(AND(AND('Snow Load Conversion'!D10="ii"),'Snow Load Conversion'!I5='Snow Load Conversion'!P5,'Snow Load Conversion'!D13<=15),30,IF(AND(AND('Snow Load Conversion'!D10="iii"),'Snow Load Conversion'!I5='Snow Load Conversion'!P5,'Snow Load Conversion'!D13<=15),35,IF(AND(AND('Snow Load Conversion'!D10="iv"),'Snow Load Conversion'!I5='Snow Load Conversion'!P5,'Snow Load Conversion'!D13<=15),40,IF(B31<=20,B31*'Snow Load Conversion'!D11,20*'Snow Load Conversion'!D11))))) -> 30 | M31: =(0.7*'Snow Load Conversion'!D7*'Snow Load Conversion'!D9*'Snow Load Conversion'!D11*B31)+'Snow Load Conversion'!D17 -> 119.952
A32: Kodiak | B32: =IF(AND('Snow Load Conversion'!I5='Snow Load Conversion'!P5,'Snow Load Conversion'!D10="I"),45,IF(AND('Snow Load Conversion'!I5='Snow Load Conversion'!P5,'Snow Load Conversion'!D10="II"),56,IF(AND('Snow Load Conversion'!I5='Snow Load Conversion'!P5,'Snow Load Conversion'!D10="III"),64,IF(AND('Snow Load Conversion'!I5='Snow Load Conversion'!P5,'Snow Load Conversion'!D10="IV"),70,30)))) -> 56 | C32: =MAX(L32,M32) -> 46.648 | D32: 100 | L32: =IF(AND(AND('Snow Load Conversion'!D10="I"),'Snow Load Conversion'!I5='Snow Load Conversion'!P5,'Snow Load Conversion'!D13<=15),25,IF(AND(AND('Snow Load Conversion'!D10="ii"),'Snow Load Conversion'!I5='Snow Load Conversion'!P5,'Snow Load Conversion'!D13<=15),30,IF(AND(AND('Snow Load Conversion'!D10="iii"),'Snow Load Conversion'!I5='Snow Load Conversion'!P5,'Snow Load Conversion'!D13<=15),35,IF(AND(AND('Snow Load Conversion'!D10="iv"),'Snow Load Conversion'!I5='Snow Load Conversion'!P5,'Snow Load Conversion'!D13<=15),40,IF(B32<=20,B32*'Snow Load Conversion'!D11,20*'Snow Load Conversion'!D11))))) -> 30 | M32: =(0.7*'Snow Load Conversion'!D7*'Snow Load Conversion'!D9*'Snow Load Conversion'!D11*B32)+'Snow Load Conversion'!D17 -> 46.648
A33: Kotzebue | B33: =IF(AND('Snow Load Conversion'!I5='Snow Load Conversion'!P5,'Snow Load Conversion'!D10="I"),77,IF(AND('Snow Load Conversion'!I5='Snow Load Conversion'!P5,'Snow Load Conversion'!D10="II"),96,IF(AND('Snow Load Conversion'!I5='Snow Load Conversion'!P5,'Snow Load Conversion'!D10="III"),110,IF(AND('Snow Load Conversion'!I5='Snow Load Conversion'!P5,'Snow Load Conversion'!D10="IV"),120,60)))) -> 96 | C33: =MAX(L33,M33) -> 79.968 | D33: 100 | L33: =IF(AND(AND('Snow Load Conversion'!D10="I"),'Snow Load Conversion'!I5='Snow Load Conversion'!P5,'Snow Load Conversion'!D13<=15),25,IF(AND(AND('Snow Load Conversion'!D10="ii"),'Snow Load Conversion'!I5='Snow Load Conversion'!P5,'Snow Load Conversion'!D13<=15),30,IF(AND(AND('Snow Load Conversion'!D10="iii"),'Snow Load Conversion'!I5='Snow Load Conversion'!P5,'Snow Load Conversion'!D13<=15),35,IF(AND(AND('Snow Load Conversion'!D10="iv"),'Snow Load Conversion'!I5='Snow Load Conversion'!P5,'Snow Load Conversion'!D13<=15),40,IF(B33<=20,B33*'Snow Load Conversion'!D11,20*'Snow Load Conversion'!D11))))) -> 30 | M33: =(0.7*'Snow Load Conversion'!D7*'Snow Load Conversion'!D9*'Snow Load Conversion'!D11*B33)+'Snow Load Conversion'!D17 -> 79.968
A34: McGrath | B34: =IF(AND('Snow Load Conversion'!I5='Snow Load Conversion'!P5,'Snow Load Conversion'!D10="I"),83,IF(AND('Snow Load Conversion'!I5='Snow Load Conversion'!P5,'Snow Load Conversion'!D10="II"),104,IF(AND('Snow Load Conversion'!I5='Snow Load Conversion'!P5,'Snow Load Conversion'!D10="III"),120,IF(AND('Snow Load Conversion'!I5='Snow Load Conversion'!P5,'Snow Load Conversion'!D10="IV"),130,70)))) -> 104 | C34: =MAX(L34,M34) -> 86.632 | D34: 400 | L34: =IF(AND(AND('Snow Load Conversion'!D10="I"),'Snow Load Conversion'!I5='Snow Load Conversion'!P5,'Snow Load Conversion'!D13<=15),25,IF(AND(AND('Snow Load Conversion'!D10="ii"),'Snow Load Conversion'!I5='Snow Load Conversion'!P5,'Snow Load Conversion'!D13<=15),30,IF(AND(AND('Snow Load Conversion'!D10="iii"),'Snow Load Conversion'!I5='Snow Load Conversion'!P5,'Snow Load Conversion'!D13<=15),35,IF(AND(AND('Snow Load Conversion'!D10="iv"),'Snow Load Conversion'!I5='Snow Load Conversion'!P5,'Snow Load Conversion'!D13<=15),40,IF(B34<=20,B34*'Snow Load Conversion'!D11,20*'Snow Load Conversion'!D11))))) -> 30 | M34: =(0.7*'Snow Load Conversion'!D7*'Snow Load Conversion'!D9*'Snow Load Conversion'!D11*B34)+'Snow Load Conversion'!D17 -> 86.632
A35: Nenana | B35: =IF(AND('Snow Load Conversion'!I5='Snow Load Conversion'!P5,'Snow Load Conversion'!D10="I"),96,IF(AND('Snow Load Conversion'!I5='Snow Load Conversion'!P5,'Snow Load Conversion'!D10="II"),120,IF(AND('Snow Load Conversion'!I5='Snow Load Conversion'!P5,'Snow Load Conversion'!D10="III"),138,IF(AND('Snow Load Conversion'!I5='Snow Load Conversion'!P5,'Snow Load Conversion'!D10="IV"),150,80)))) -> 120 | C35: =MAX(L35,M35) -> 99.96 | D35: 400 | L35: =IF(AND(AND('Snow Load Conversion'!D10="I"),'Snow Load Conversion'!I5='Snow Load Conversion'!P5,'Snow Load Conversion'!D13<=15),25,IF(AND(AND('Snow Load Conversion'!D10="ii"),'Snow Load Conversion'!I5='Snow Load Conversion'!P5,'Snow Load Conversion'!D13<=15),30,IF(AND(AND('Snow Load Conversion'!D10="iii"),'Snow Load Conversion'!I5='Snow Load Conversion'!P5,'Snow Load Conversion'!D13<=15),35,IF(AND(AND('Snow Load Conversion'!D10="iv"),'Snow Load Conversion'!I5='Snow Load Conversion'!P5,'Snow Load Conversion'!D13<=15),40,IF(B35<=20,B35*'Snow Load Conversion'!D11,20*'Snow Load Conversion'!D11))))) -> 30 | M35: =(0.7*'Snow Load Conversion'!D7*'Snow Load Conversion'!D9*'Snow Load Conversion'!D11*B35)+'Snow Load Conversion'!D17 -> 99.96
A36: Nikiski | B36: =IF(AND('Snow Load Conversion'!I5='Snow Load Conversion'!P5,'Snow Load Conversion'!D10="I"),102,IF(AND('Snow Load Conversion'!I5='Snow Load Conversion'!P5,'Snow Load Conversion'!D10="II"),128,IF(AND('Snow Load Conversion'!I5='Snow Load Conversion'!P5,'Snow Load Conversion'!D10="III"),147,IF(AND('Snow Load Conversion'!I5='Snow Load Conversion'!P5,'Snow Load Conversion'!D10="IV"),160,"NOT IN 7-10 OR 7-16")))) -> 128 | C36: =IF(B36="NOT IN 7-10 OR 7-16","NOT IN 7-10 OR 7-16",MAX(L36,M36)) -> 106.624 | D36: 200 | L36: =IF(AND(AND('Snow Load Conversion'!D10="I"),'Snow Load Conversion'!I5='Snow Load Conversion'!P5,'Snow Load Conversion'!D13<=15),25,IF(AND(AND('Snow Load Conversion'!D10="ii"),'Snow Load Conversion'!I5='Snow Load Conversion'!P5,'Snow Load Conversion'!D13<=15),30,IF(AND(AND('Snow Load Conversion'!D10="iii"),'Snow Load Conversion'!I5='Snow Load Conversion'!P5,'Snow Load Conversion'!D13<=15),35,IF(AND(AND('Snow Load Conversion'!D10="iv"),'Snow Load Conversion'!I5='Snow Load Conversion'!P5,'Snow Load Conversion'!D13<=15),40,IF(B36<=20,B36*'Snow Load Conversion'!D11,20*'Snow Load Conversion'!D11))))) -> 30 | M36: =(0.7*'Snow Load Conversion'!D7*'Snow Load Conversion'!D9*'Snow Load Conversion'!D11*B36)+'Snow Load Conversion'!D17 -> 106.624
A37: Nome | B37: =IF(AND('Snow Load Conversion'!I5='Snow Load Conversion'!P5,'Snow Load Conversion'!D10="I"),90,IF(AND('Snow Load Conversion'!I5='Snow Load Conversion'!P5,'Snow Load Conversion'!D10="II"),112,IF(AND('Snow Load Conversion'!I5='Snow Load Conversion'!P5,'Snow Load Conversion'!D10="III"),129,IF(AND('Snow Load Conversion'!I5='Snow Load Conversion'!P5,'Snow Load Conversion'!D10="IV"),140,70)))) -> 112 | C37: =MAX(L37,M37) -> 93.296 | D37: 100 | L37: =IF(AND(AND('Snow Load Conversion'!D10="I"),'Snow Load Conversion'!I5='Snow Load Conversion'!P5,'Snow Load Conversion'!D13<=15),25,IF(AND(AND('Snow Load Conversion'!D10="ii"),'Snow Load Conversion'!I5='Snow Load Conversion'!P5,'Snow Load Conversion'!D13<=15),30,IF(AND(AND('Snow Load Conversion'!D10="iii"),'Snow Load Conversion'!I5='Snow Load Conversion'!P5,'Snow Load Conversion'!D13<=15),35,IF(AND(AND('Snow Load Conversion'!D10="iv"),'Snow Load Conversion'!I5='Snow Load Conversion'!P5,'Snow Load Conversion'!D13<=15),40,IF(B37<=20,B37*'Snow Load Conversion'!D11,20*'Snow Load Conversion'!D11))))) -> 30 | M37: =(0.7*'Snow Load Conversion'!D7*'Snow Load Conversion'!D9*'Snow Load Conversion'!D11*B37)+'Snow Load Conversion'!D17 -> 93.296
A38: Palmer/Wasilla | B38: =IF(AND('Snow Load Conversion'!I5='Snow Load Conversion'!P5,'Snow Load Conversion'!D10="I"),64,IF(AND('Snow Load Conversion'!I5='Snow Load Conversion'!P5,'Snow Load Conversion'!D10="II"),80,IF(AND('Snow Load Conversion'!I5='Snow Load Conversion'!P5,'Snow Load Conversion'!D10="III"),92,IF(AND('Snow Load Conversion'!I5='Snow Load Conversion'!P5,'Snow Load Conversion'!D10="IV"),100,50)))) -> 80 | C38: =MAX(L38,M38) -> 66.64 | D38: 500 | L38: =IF(AND(AND('Snow Load Conversion'!D10="I"),'Snow Load Conversion'!I5='Snow Load Conversion'!P5,'Snow Load Conversion'!D13<=15),25,IF(AND(AND('Snow Load Conversion'!D10="ii"),'Snow Load Conversion'!I5='Snow Load Conversion'!P5,'Snow Load Conversion'!D13<=15),30,IF(AND(AND('Snow Load Conversion'!D10="iii"),'Snow Load Conversion'!I5='Snow Load Conversion'!P5,'Snow Load Conversion'!D13<=15),35,IF(AND(AND('Snow Load Conversion'!D10="iv"),'Snow Load Conversion'!I5='Snow Load Conversion'!P5,'Snow Load Conversion'!D13<=15),40,IF(B38<=20,B38*'Snow Load Conversion'!D11,20*'Snow Load Conversion'!D11))))) -> 30 | M38: =(0.7*'Snow Load Conversion'!D7*'Snow Load Conversion'!D9*'Snow Load Conversion'!D11*B38)+'Snow Load Conversion'!D17 -> 66.64
A39: Pertersburg | B39: =IF(AND('Snow Load Conversion'!I5='Snow Load Conversion'!P5,'Snow Load Conversion'!D10="I"),122,IF(AND('Snow Load Conversion'!I5='Snow Load Conversion'!P5,'Snow Load Conversion'!D10="II"),152,IF(AND('Snow Load Conversion'!I5='Snow Load Conversion'!P5,'Snow Load Conversion'!D10="III"),175,IF(AND('Snow Load Conversion'!I5='Snow Load Conversion'!P5,'Snow Load Conversion'!D10="IV"),190,150)))) -> 152 | C39: =MAX(L39,M39) -> 126.616 | D39: 100 | L39: =IF(AND(AND('Snow Load Conversion'!D10="I"),'Snow Load Conversion'!I5='Snow Load Conversion'!P5,'Snow Load Conversion'!D13<=15),25,IF(AND(AND('Snow Load Conversion'!D10="ii"),'Snow Load Conversion'!I5='Snow Load Conversion'!P5,'Snow Load Conversion'!D13<=15),30,IF(AND(AND('Snow Load Conversion'!D10="iii"),'Snow Load Conversion'!I5='Snow Load Conversion'!P5,'Snow Load Conversion'!D13<=15),35,IF(AND(AND('Snow Load Conversion'!D10="iv"),'Snow Load Conversion'!I5='Snow Load Conversion'!P5,'Snow Load Conversion'!D13<=15),40,IF(B39<=20,B39*'Snow Load Conversion'!D11,20*'Snow Load Conversion'!D11))))) -> 30 | M39: =(0.7*'Snow Load Conversion'!D7*'Snow Load Conversion'!D9*'Snow Load Conversion'!D11*B39)+'Snow Load Conversion'!D17 -> 126.616
