Workbook

Sheet Fixture Chart
A1: Quantity: | B1: Fixture: | C1: WSFU: | D1: DFU:
A2: 0 | B2: Lavatory (Public) | C2: =IF(AND(OR(B2=B78,B2=B73,B2=B74,B2=B79),G2="UPC"),INDEX(C58:C83,MATCH(B2,B58:B83,0)),IF(G2="ipc",INDEX(C28:C55,MATCH(B2,B28:B55,0))*A2,IF(G2="Upc",INDEX(C58:C83,MATCH(B2,B58:B83,0))*A2))) -> 0 | D2: =IF(G2="ipc",INDEX(D28:D55,MATCH(B2,B28:B523,0)),IF(G2="Upc",INDEX(D58:D83,MATCH(B2,B58:B83,0))))*A2 -> 0 | F2: Code: | G2: IPC
A3: 0 | B3: Water Closet (FV-Public) | C3: =IF(AND(OR(B3=B78,B3=B73,B3=B74,B3=B79),G2="UPC"),INDEX(C58:C83,MATCH(B3,B58:B83,0)),IF(G2="ipc",INDEX(C28:C55,MATCH(B3,B28:B55,0))*A3,IF(G2="Upc",INDEX(C58:C83,MATCH(B3,B58:B83,0))*A3))) -> 0 | D3: =IF(G2="ipc",INDEX(D28:D55,MATCH(B3,B28:B55,0)),IF(G2="Upc",INDEX(D58:D83,MATCH(B3,B58:B83,0))))*A3 -> 0 | F3: Pressure Range: | G3: 30-39 | H3: PSI
A4: 0 | B4: N/A | C4: =IF(AND(OR(B4=B78,B4=B73,B4=B74,B4=B79),G2="UPC"),INDEX(C58:C83,MATCH(B4,B58:B83,0)),IF(G2="ipc",INDEX(C28:C55,MATCH(B4,B28:B55,0))*A4,IF(G2="Upc",INDEX(C58:C83,MATCH(B4,B58:B83,0))*A4))) -> 0 | D4: =IF(G2="ipc",INDEX(D28:D55,MATCH(B4,B28:B55,0)),IF(G2="Upc",INDEX(D58:D83,MATCH(B4,B58:B83,0))))*A4 -> 0 | F4: Developed Pipe Length: | G4: 100 | H4: FT.
A5: 0 | B5: N/A | C5: =IF(AND(OR(B5=B78,B5=B73,B5=B74,B5=B79),G2="UPC"),INDEX(C58:C83,MATCH(B5,B58:B83,0)),IF(G2="ipc",INDEX(C28:C55,MATCH(B5,B28:B55,0))*A5,IF(G2="Upc",INDEX(C58:C83,MATCH(B5,B58:B83,0))*A5))) -> 0 | D5: =IF(G2="ipc",INDEX(D28:D55,MATCH(B5,B28:B55,0)),IF(G2="Upc",INDEX(D58:D83,MATCH(B5,B58:B83,0))))*A5 -> 0 | F5: DO NOT "PASTESPEC" THE ABOVE ON DRAWINGS
A6: 0 | B6: N/A | C6: =IF(AND(OR(B6=B78,B6=B73,B6=B74,B6=B79),G2="UPC"),INDEX(C58:C83,MATCH(B6,B58:B83,0)),IF(G2="ipc",INDEX(C28:C55,MATCH(B6,B28:B55,0))*A6,IF(G2="Upc",INDEX(C58:C83,MATCH(B6,B58:B83,0))*A6))) -> 0 | D6: =IF(G2="ipc",INDEX(D28:D55,MATCH(B6,B28:B55,0)),IF(G2="Upc",INDEX(D58:D83,MATCH(B6,B58:B83,0))))*A6 -> 0
A7: 0 | B7: N/A | C7: =IF(AND(OR(B7=B78,B7=B73,B7=B74,B7=B79),G2="UPC"),INDEX(C58:C83,MATCH(B7,B58:B83,0)),IF(G2="ipc",INDEX(C28:C55,MATCH(B7,B28:B55,0))*A7,IF(G2="Upc",INDEX(C58:C83,MATCH(B7,B58:B83,0))*A7))) -> 0 | D7: =IF(G2="ipc",INDEX(D28:D55,MATCH(B7,B28:B55,0)),IF(G2="Upc",INDEX(D58:D83,MATCH(B7,B58:B83,0))))*A7 -> 0
A8: 0 | B8: N/A | C8: =IF(AND(OR(B8=B78,B8=B73,B8=B74,B8=B79),G2="UPC"),INDEX(C58:C83,MATCH(B8,B58:B83,0)),IF(G2="ipc",INDEX(C28:C55,MATCH(B8,B28:B55,0))*A8,IF(G2="Upc",INDEX(C58:C83,MATCH(B8,B58:B83,0))*A8))) -> 0 | D8: =IF(G2="ipc",INDEX(D28:D55,MATCH(B8,B28:B55,0)),IF(G2="Upc",INDEX(D58:D83,MATCH(B8,B58:B83,0))))*A8 -> 0
A9: 0 | B9: N/A | C9: =IF(AND(OR(B9=B78,B9=B73,B9=B74,B9=B79),G2="UPC"),INDEX(C58:C83,MATCH(B9,B58:B83,0)),IF(G2="ipc",INDEX(C28:C55,MATCH(B9,B28:B55,0))*A9,IF(G2="Upc",INDEX(C58:C83,MATCH(B9,B58:B83,0))*A9))) -> 0 | D9: =IF(G2="ipc",INDEX(D28:D55,MATCH(B9,B28:B55,0)),IF(G2="Upc",INDEX(D58:D83,MATCH(B9,B58:B83,0))))*A9 -> 0
A10: 0 | B10: N/A | C10: =IF(AND(OR(B10=B78,B10=B73,B10=B74,B10=B79),G2="UPC"),INDEX(C58:C83,MATCH(B10,B58:B83,0)),IF(G2="ipc",INDEX(C28:C55,MATCH(B10,B28:B55,0))*A10,IF(G2="Upc",INDEX(C58:C83,MATCH(B10,B58:B83,0))*A10))) -> 0 | D10: =IF(G2="ipc",INDEX(D28:D55,MATCH(B10,B28:B55,0)),IF(G2="Upc",INDEX(D58:D83,MATCH(B10,B58:B83,0))))*A10 -> 0
A11: 0 | B11: N/A | C11: =IF(AND(OR(B11=B78,B11=B73,B11=B74,B11=B79),G2="UPC"),INDEX(C58:C83,MATCH(B11,B58:B83,0)),IF(G2="ipc",INDEX(C28:C55,MATCH(B11,B28:B55,0))*A11,IF(G2="Upc",INDEX(C58:C83,MATCH(B11,B58:B83,0))*A11))) -> 0 | D11: =IF(G2="ipc",INDEX(D28:D55,MATCH(B11,B28:B55,0)),IF(G2="Upc",INDEX(D58:D83,MATCH(B11,B58:B83,0))))*A11 -> 0
A12: Total Fixture Units: | C12: =SUM(C2:C11) -> 0 | D12: =SUM(D2:D11) -> 0
A13: Inlet Size & Main Waste Trunk Size: | C13: =IF(C12=0,0,INDEX(C114:L114,MATCH(G4,C107:L107,0))) -> 0 | D13: =IF(G2="IPC",B103,A103) -> 0
A14: =IF(G2="ipc","Inlet and Main Waste are based on "&F41&" and "&F44&" with a total developed pipe length of "&G4&" feet and PSI rating of "&G3&".",IF(G2="upc","Inlet and Main Waste are based on "&G41&" and "&G44&" with a total developed pipe length of "&G4&" feet and a PSI rating of "&G3&".","")) -> Inlet and Main Waste are based on Table E201.1 and Table 710.1(1) with a total developed pipe length of 100 feet and PSI rating of 30-39.
B27: Fixtures (IPC) | F27: Pressure Range (IPC) | G27: Pressure Range (UPC) | J27: Developed Length
B28: N/A | C28: 0 | D28: 0 | F28: 30-39 | G28: 30-45 | J28: 40
B29: Bathtub (Private) | C29: 1.4 | D29: 2 | F29: 40-49 | G29: 46-60 | J29: 60
B30: Bathtub (Public) | C30: 4 | D30: 2 | F30: 50-60 | J30: 80
B31: Clothes Washer | C31: 4 | D31: 3 | J31: 100
B32: Dish Washer | C32: 1.4 | D32: 2 | J32: 150
B33: Drinking Fountain | C33: 0.25 | D33: 0.5 | J33: 200
B34: Kitchen Sink (Private) | C34: 1.4 | D34: 2 | J34: 250
B35: Kitchen / Bar Sink | C35: 4 | D35: 2 | J35: 300
B36: Kitchen Sink (Hotel/Resta) | C36: 4 | D36: 2 | J36: 400
B37: Lavatory (Private) | C37: 0.7 | D37: 1 | J37: 500
B38: Lavatory (Public) | C38: 2 | D38: 1
B39: Service / Mop Sink | C39: 3 | D39: 2
B40: Shower Head (Public) | C40: 4 | D40: 2 | F40: IPC Supply table | G40: UPC supply Table
B41: Shower Head (Private) | C41: 1.4 | D41: 2 | F41: Table E201.1 | G41: Table 610.4
B42: Eye Wash Station | C42: 4 | D42: 2
B43: Urinal (3/4" valve) >=1 GPF | C43: 5 | D43: 4 | F43: IPC Waste table | G43: UPC waste table
B44: Urinal (3/4" valve) <1 GPF | C44: 5 | D44: 2 | F44: Table 710.1(1) | G44: Table 703.2
B45: Urinal (Waterless) | C45: 0 | D45: 2
B46: Washing Machine (Private) | C46: 1.4 | D46: 3
B47: Washing Machine (Pub 8#) | C47: 3 | D47: 3
B48: Washing Machine (Pub 15#) | C48: 4 | D48: 3
B49: Water Closet (FV-Private) | C49: 6 | D49: 4
B50: Water Closet (FV-Public) | C50: 10 | D50: 4
B51: Water Closet (Tank-Private) | C51: 2.2 | D51: 3
B52: Water Closet (Tank-Public) | C52: 5 | D52: 4
...

Sheet Supply (IPC)
D1: SERIAL NUMBER:
A4: INLET PIPE SIZING CHART (IPC)
A5: *Based on Table E103.3(2) IPC
A7: Quantity | C7: Description | G7: Fixture Units | J7: Minimum Pipe Size | M7: Fixture Units
G8: Cold | H8: Hot | I8: Total | J8: Table 604.5 of the IPC | M8: Cold | N8: Hot | O8: Total
A9: 0 | C9: Bathtub (Private) | G9: 1 | H9: 1 | I9: 1.4 | J9: 1/2" | M9: =$A9*G9 -> 0 | N9: =$A9*H9 -> 0 | O9: =$A9*I9 -> 0
A10: 0 | C10: Bathtub (Public) | G10: 3 | H10: 3 | I10: 4 | J10: 1/2" | M10: =$A10*G10 -> 0 | N10: =$A10*H10 -> 0 | O10: =$A10*I10 -> 0
A11: 0 | C11: Dish Washer | G11: 0 | H11: 1.4 | I11: 1.4 | J11: 1/2" | M11: =$A11*G11 -> 0 | N11: =$A11*H11 -> 0 | O11: =$A11*I11 -> 0
A12: 0 | C12: Drinking Fountain | G12: 0.25 | H12: 0 | I12: 0.25 | J12: 3/8" | M12: =$A12*G12 -> 0 | N12: =$A12*H12 -> 0 | O12: =$A12*I12 -> 0
A13: 0 | C13: Kitchen Sink (Private) | G13: 1 | H13: 1 | I13: 1.4 | J13: 1/2" | M13: =$A13*G13 -> 0 | N13: =$A13*H13 -> 0 | O13: =$A13*I13 -> 0
A14: 0 | C14: Kitchen Sink (Hotel/Resta) | G14: 3 | H14: 3 | I14: 4 | J14: 1/2" | M14: =$A14*G14 -> 0 | N14: =$A14*H14 -> 0 | O14: =$A14*I14 -> 0
A15: 0 | C15: Kitchen / Bar Sink | G15: 3 | H15: 3 | I15: 4 | J15: 1/2" | M15: =$A15*G15 -> 0 | N15: =$A15*H15 -> 0 | O15: =$A15*I15 -> 0
A16: 0 | C16: Lavatory(Private) | G16: 0.5 | H16: 0.5 | I16: 0.7 | J16: 3/8" | M16: =$A16*G16 -> 0 | N16: =$A16*H16 -> 0 | O16: =$A16*I16 -> 0
A17: 0 | C17: Lavatory(Public) | G17: 1.5 | H17: 1.5 | I17: 2 | J17: 3/8" | M17: =$A17*G17 -> 0 | N17: =$A17*H17 -> 0 | O17: =$A17*I17 -> 0
A18: 0 | C18: Service Sink | G18: 2.25 | H18: 2.25 | I18: 3 | J18: 1/2" | M18: =$A18*G18 -> 0 | N18: =$A18*H18 -> 0 | O18: =$A18*I18 -> 0
A19: 0 | C19: Shower Head(Public) | G19: 3 | H19: 3 | I19: 4 | J19: 1/2" | M19: =$A19*G19 -> 0 | N19: =$A19*H19 -> 0 | O19: =$A19*I19 -> 0
A20: 0 | C20: Shower Head(Private) | G20: 1 | H20: 1 | I20: 1.4 | J20: 1/2" | M20: =$A20*G20 -> 0 | N20: =$A20*H20 -> 0 | O20: =$A20*I20 -> 0
... A32: 0 | C32: Hose Bib (Assumed) | G32: 5 | H32: 0 | I32: 5 | J32: 1/2" | M32: =$A32*G32 -> 0 | N32: =$A32*H32 -> 0 | O32: =$A32*I32 -> 0
A33: 0 | C33: Misc(Fill-in) | G33: 0 | H33: 0 | I33: 0 | M33: =$A33*G33 -> 0 | N33: =$A33*H33 -> 0 | O33: =$A33*I33 -> 0
A34: 0 | C34: Misc(Fill-in) | G34: 0 | H34: 0 | I34: 0 | M34: =$A34*G34 -> 0 | N34: =$A34*H34 -> 0 | O34: =$A34*I34 -> 0
J35: Total Fixture Units | M35: =SUM(M9:M34) -> 0 | N35: =SUM(N9:N34) -> 0 | O35: =SUM(O9:O34) -> 0
A37: *Based on Table E201.1 of the IPC
A38: 2009 (Pg #141), 2012 (Pg #143) & 2015 (Pg X)
A39: 60' RUNS | D39: 80' RUNS | G39: 100' RUNS | J39: 150' RUNS | M39: 300' RUNS
A40: 30 to 39 PSI
A41: 2 | B41: 1/2" PIPE | D41: 1.5 | E41: 1/2" PIPE | G41: 1.5 | H41: 1/2" PIPE | J41: 1 | K41: 1/2" PIPE | M41: 0.5 | N41: 1/2" PIPE
A42: 7.5 | B42: 3/4" PIPE | D42: 6 | E42: 3/4" PIPE | G42: 5.5 | H42: 3/4" PIPE | J42: 4 | K42: 3/4" PIPE | M42: 2.5 | N42: 3/4" PIPE
A43: 32 | B43: 1" PIPE | D43: 27 | E43: 1" PIPE | G43: 21 | H43: 1" PIPE | J43: 13.5 | K43: 1" PIPE | M43: 7 | N43: 1" PIPE
A44: 80 | B44: 1 1/4" PIPE | D44: 80 | E44: 1 1/4" PIPE | G44: 75 | H44: 1 1/4" PIPE | J44: 54 | K44: 1 1/4" PIPE | M44: 25 | N44: 1 1/4" PIPE
A45: 151 | B45: 1 1/2" PIPE | D45: 151 | E45: 1 1/2" PIPE | G45: 151 | H45: 1 1/2" PIPE | J45: 128 | K45: 1 1/2" PIPE | M45: 72 | N45: 1 1/2" PIPE
A46: 365 | B46: 2" PIPE | D46: 365 | E46: 2" PIPE | G46: 365 | H46: 2" PIPE | J46: 318 | K46: 2" PIPE | M46: 201 | N46: 2" PIPE
A47: 533 | B47: 2 1/2" PIPE | D47: 533 | E47: 2 1/2" PIPE | G47: 533 | H47: 2 1/2" PIPE | J47: 533 | K47: 2 1/2" PIPE | M47: 409 | N47: 2 1/2" PIPE
A48: 40 to 49 PSI
A49: 2.5 | B49: 1/2" PIPE | D49: 2 | E49: 1/2" PIPE | G49: 1.5 | H49: 1/2" PIPE | J49: 1.5 | K49: 1/2" PIPE | M49: 0.5 | N49: 1/2" PIPE
A50: 9.5 | B50: 3/4" PIPE | D50: 8.5 | E50: 3/4" PIPE | G50: 7 | H50: 3/4" PIPE | J50: 5.5 | K50: 3/4" PIPE | M50: 3 | N50: 3/4" PIPE
A51: 32 | B51: 1" PIPE | D51: 32 | E51: 1" PIPE | G51: 32 | H51: 1" PIPE | J51: 21 | K51: 1" PIPE | M51: 9.5 | N51: 1" PIPE
A52: 80 | B52: 1 1/4" PIPE | D52: 80 | E52: 1 1/4" PIPE | G52: 80 | H52: 1 1/4" PIPE | J52: 75 | K52: 1 1/4" PIPE | M52: 39 | N52: 1 1/4" PIPE
A53: 151 | B53: 1 1/2" PIPE | D53: 151 | E53: 1 1/2" PIPE | G53: 151 | H53: 1 1/2" PIPE | J53: 151 | K53: 1 1/2" PIPE | M53: 98 | N53: 1 1/2" PIPE
A54: 365 | B54: 2" PIPE | D54: 365 | E54: 2" PIPE | G54: 365 | H54: 2" PIPE | J54: 365 | K54: 2" PIPE | M54: 270 | N54: 2" PIPE
A55: 533 | B55: 2 1/2" PIPE | D55: 533 | E55: 2 1/2" PIPE | G55: 533 | H55: 2 1/2" PIPE | J55: 533 | K55: 2 1/2" PIPE | M55: 528 | N55: 2 1/2" PIPE
...

Sheet Waste (IPC)
D1: SERIAL NUMBER:
A4: WASTE MAIN TRUNK SIZE (IPC)
A5: *Based on Table 709.1 (Drain) Table 906.1 (Vent) of the IPC
A7: Quantity | C7: Description | H7: Fixture Units | K7: Min. Trap Size | M7: Min. Drain Size | O7: Total
A8: 0 | C8: Bathtub or Bath/Shower | H8: 2 | J8: = | K8: 1.5" | M8: 1.5" | O8: =H8*A8 -> 0
A9: 0 | C9: Clothes Washer | H9: 3 | J9: = | K9: 2" | M9: 2" | O9: =H9*A9 -> 0
A10: 0 | C10: Dish Washer | H10: 2 | J10: = | K10: 1.5" | M10: 2" | O10: =H10*A10 -> 0
A11: 0 | C11: Drinking Fountain | H11: 0.5 | J11: = | K11: 1.25" | M11: 1.25" | O11: =H11*A11 -> 0
A12: 0 | C12: Floor Drain | H12: 2 | J12: = | K12: 2" | M12: 2" | O12: =H12*A12 -> 0
A13: 0 | C13: Floor sink | H13: 2 | J13: = | K13: 2" | M13: 2" | O13: =H13*A13 -> 0
A14: 0 | C14: Shower (5.7 gpm or less) | H14: 2 | J14: = | K14: 1.5" | M14: 2" | O14: =H14*A14 -> 0
A15: 0 | C15: Shower (> 5.7 to = 12.3 gpm) | H15: 3 | J15: = | K15: 2" | M15: 2" | O15: =H15*A15 -> 0
A16: 0 | C16: Shower (> 12.3 to = 25.8 gpm) | H16: 5 | J16: = | K16: 3" | M16: 3" | O16: =H16*A16 -> 0
A17: 0 | C17: Shower (> 25.8 to = 55.6 gpm) | H17: 6 | J17: = | K17: 4" | M17: 4" | O17: =H17*A17 -> 0
A18: 0 | C18: Eye Wash Station | H18: 2 | J18: = | K18: 2" | M18: 2" | O18: =H18*A18 -> 0
A19: 0 | C19: Lavatory | H19: 1 | J19: = | K19: 1.25" | M19: 1.5" | O19: =H19*A19 -> 0
... A21: 0 | C21: Bar | H21: 2 | J21: = | K21: 1.5" | M21: 2" | O21: =H21*A21 -> 0
A22: 0 | C22: Misc(Fill-in) | J22: = | O22: =H22*A22 -> 0
A23: 0 | C23: Misc(Fill-in) | J23: = | O23: =H23*A23 -> 0
A24: 0 | C24: Misc(Fill-in) | J24: = | O24: =H24*A24 -> 0
A25: 0 | C25: Misc(Fill-in) | J25: = | O25: =H25*A25 -> 0
A26: 0 | C26: Misc(Fill-in) | J26: = | O26: =H26*A26 -> 0
A27: 0 | C27: Misc(Fill-in) | J27: = | O27: =H27*A27 -> 0
A28: 0 | C28: Misc(Fill-in) | J28: = | O28: =H28*A28 -> 0
A29: 0 | C29: Misc(Fill-in) | J29: = | O29: =H29*A29 -> 0
A30: Urinals
A31: 0 | C31: Urinal (> 1.0 GPF) | H31: 4 | J31: = | K31: Integral | M31: 2" | O31: =H31*A31 -> 0
A32: 0 | C32: Urinal (<=1.0 GPF) | H32: 2 | J32: = | K32: Integral | M32: 2" | O32: =H32*A32 -> 0
A33: 0 | C33: Urinal(Waterless) | H33: 0.5 | J33: = | K33: Integral | M33: 2" | O33: =H33*A33 -> 0
A34: Water Closets (1.6 GPF) Gravity Tank
A35: 0 | C35: Private | H35: 3 | J35: = | K35: Integral | M35: 3" | O35: =H35*A35 -> 0
A36: 0 | C36: Public | H36: 4 | J36: = | K36: Integral | M36: 3" | O36: =H36*A36 -> 0
A37: Water Closets (>1.6 GPF) Gravity Tank
A38: 0 | C38: Private | H38: 4 | J38: = | K38: Integral | M38: 3" | O38: =H38*A38 -> 0
A39: 0 | C39: Public | H39: 6 | J39: = | K39: Integral | M39: 3" | O39: =H39*A39 -> 0
A40: Water Closets Flushometer Tank
A41: 0 | C41: Private / Public | H41: 4 | J41: = | K41: Integral | M41: 3" | O41: =H41*A41 -> 0
K42: Total Fixture Units | N42: = | O42: =SUM(O8:O19,O21:O29,O32:O33,O35:O36,O38:O41) -> 0
K43: Min. Vent Size (in) | N43: = | O43: =IF(O42<=2,"1-1/4",(IF(O42<=10,"1-1/2",(IF(O42<=20,"2",(IF(O42<=102,"3",IF(O42<=320,"4")))))))) -> 1-1/4
K44: Main Trunk Size (in) | N44: = | O44: =IF((SUM(A32:B33,A35:B36,A38:B41))=0,"2",IF((SUM(A32:B33,A35:B36,A38:B41))<=3,"3",IF((SUM(A32:B33,A35:B36,A38:B41))>=4,"4",IF(O42<=21,"2",IF(O42<=42,"3",IF(O42<=216,"4")))))) -> 2
...

Sheet Supply (UPC & CPC)
D1: SERIAL NUMBER:
A4: INLET PIPE SIZING CHART (CPC & UPC)
A5: *Based on Table 610.3 (Drain & Vents)
A7: Quantity | C7: Description | F7: Fixture Units | I7: Minimum Pipe Size | N7: Total Overall
N8: Water F.U.
A9: 0 | C9: Bar Sink | F9: 2 | I9: 1/2" | N9: =A9*F9 -> 0
A10: 0 | C10: Bathtub | F10: 4 | I10: 1/2" | N10: =A10*F10 -> 0
A11: 0 | C11: Dish Washer | F11: 1.5 | I11: 1/2" | N11: =A11*F11 -> 0
A12: 0 | C12: Drinking Fountain | F12: 0.5 | I12: 1/2" | N12: =A12*F12 -> 0
A13: 0 | C13: Kitchen Sink | F13: 1.5 | I13: 1/2" | N13: =A13*F13 -> 0
A14: 0 | C14: Lavatory | F14: 1 | I14: 1/2" | N14: =A14*F14 -> 0
A15: 0 | C15: Service Sink | F15: 3 | I15: 1/2" | N15: =A15*F15 -> 0
A16: 0 | C16: Shower Head | F16: 2 | I16: 1/2" | N16: =A16*F16 -> 0
A17: 0 | C17: 1st Urinal | F17: 20 | I17: 3/4" | N17: =A17*F17 -> 0
A18: 0 | C18: 2nd Urinal | F18: 15 | I18: 3/4" | N18: =A18*F18 -> 0
A19: 0 | C19: 3rd Urinal | F19: 10 | I19: 3/4" | N19: =A19*F19 -> 0
A20: 0 | C20: 4th Urinal | F20: 8 | I20: 3/4" | N20: =A20*F20 -> 0
... A27: 0 | C27: 3rd Water Closet FV | F27: 20 | I27: 1" | N27: =A27*F27 -> 0
A28: 0 | C28: 4th Water Closet FV | F28: 15 | I28: 1 | N28: =A28*F28 -> 0
A29: 0 | C29: 5th Water Closet FV + | F29: 10 | I29: 1" | N29: =A29*F29 -> 0
A30: 0 | C30: Water Closet (Tank) | F30: 2.5 | I30: 1/2" | N30: =A30*F30 -> 0
A31: 0 | C31: Drain | F31: 1 | I31: 3/8" | N31: =A31*F31 -> 0
A32: 0 | C32: Misc(Fill-in) | N32: =A32*F32 -> 0
A33: 0 | C33: Misc(Fill-in) | N33: =A33*F33 -> 0
A34: 0 | C34: Misc(Fill-in) | N34: =A34*F34 -> 0
A35: 0 | C35: Misc(Fill-in) | N35: =A35*F35 -> 0
K36: Total Fixture Units | N36: =N9+N10+N11+N12+N13+N14+N15+N16+N17+N18+N19+N20+N21+N22+N23+N25+N26+N27+N28+N29+N30+N31+N32+N33+N34+N35 -> 0
A38: *Based on Table 610.4 of the 2012 UPC (Pg. #106)
A39: *Based on Table 610.4 of the 2016 CPC (Pg. #151)
A40: 60' RUNS | D40: 80' RUNS | G40: 100' RUNS | J40: 150' RUNS | M40: 300' RUNS
A41: 30 to 45 PSI
A42: 5 | B42: 1/2" PIPE | D42: 4 | E42: 1/2" PIPE | G42: 3 | H42: 1/2" PIPE | J42: 2 | K42: 1/2" PIPE | M42: 1 | N42: 1/2" PIPE
A43: 16 | B43: 3/4" PIPE | D43: 14 | E43: 3/4" PIPE | G43: 12 | H43: 3/4" PIPE | J43: 9 | K43: 3/4" PIPE | M43: 5 | N43: 3/4" PIPE
A44: 31 | B44: 1" PIPE | D44: 27 | E44: 1" PIPE | G44: 25 | H44: 1" PIPE | J44: 20 | K44: 1" PIPE | M44: 13 | N44: 1" PIPE
A45: 68 | B45: 1 1/4" PIPE | D45: 57 | E45: 1 1/4" PIPE | G45: 48 | H45: 1 1/4" PIPE | J45: 38 | K45: 1 1/4" PIPE | M45: 25 | N45: 1 1/4" PIPE
A46: 151 | B46: 1 1/2" PIPE | D46: 129 | E46: 1 1/2" PIPE | G46: 110 | H46: 1 1/2" PIPE | J46: 80 | K46: 1 1/2" PIPE | M46: 46 | N46: 1 1/2" PIPE
A47: 370 | B47: 2" PIPE | D47: 292 | E47: 2" PIPE | G47: 265 | H47: 2" PIPE | J47: 217 | K47: 2" PIPE | M47: 147 | N47: 2" PIPE
A48: 445 | B48: 2 1/2" PIPE | D48: 390 | E48: 2 1/2" PIPE | G48: 370 | H48: 2 1/2" PIPE | J48: 330 | K48: 2 1/2" PIPE | M48: 265 | N48: 2 1/2" PIPE
A49: 46 to 60 PSI
A50: 7 | B50: 1/2" PIPE | D50: 6 | E50: 1/2" PIPE | G50: 5 | H50: 1/2" PIPE | J50: 4 | K50: 1/2" PIPE | M50: 2 | N50: 1/2" PIPE
...

Sheet Waste (UPC & CPC)
D1: SERIAL NUMBER:
A4: WASTE MAIN TRUNK SIZE (UPC & CPC)
A5: *Based on Table 702.1 of the UPC and CPC
A7: Quantity | C7: Description | H7: Fixture Units | K7: Min. Trap Size | M7: Min. Drain Size | O7: Total
A8: 0 | C8: Bathtub or Bath/Shower | H8: 2 | J8: = | K8: 1.5" | M8: 1.5" | O8: =H8*A8 -> 0
A9: 0 | C9: Clothes Washer | H9: 3 | J9: = | K9: 2" | M9: 2" | O9: =H9*A9 -> 0
A10: 0 | C10: Dish Washer | H10: 2 | J10: = | K10: 1.5" | M10: 2" | O10: =H10*A10 -> 0
A11: 0 | C11: Drinking Fountain (Public) | H11: 0.5 | J11: = | K11: 1.25" | M11: 1.25" | O11: =H11*A11 -> 0
A12: 0 | C12: Drinking Fountain (Assembly) | H12: 1 | J12: = | K12: 1.25" | M12: 1.25" | O12: =H12*A12 -> 0
A13: 0 | C13: Floor Drain | H13: 2 | J13: = | K13: 2" | M13: 2" | O13: =H13*A13 -> 0
A14: 0 | C14: Floor sink | H14: 2 | J14: = | K14: 2" | M14: 2" | O14: =H14*A14 -> 0
A15: 0 | C15: Shower | H15: 2 | J15: = | K15: 2" | M15: 2" | O15: =H15*A15 -> 0
A16: 0 | C16: Lavatory | H16: 1 | J16: = | K16: 1.25" | M16: 1.5" | O16: =H16*A16 -> 0
A17: 0 | C17: Misc(Fill-in) | J17: = | O17: =H17*A17 -> 0
A18: 0 | C18: Misc(Fill-in) | J18: = | O18: =H18*A18 -> 0
A19: 0 | C19: Misc(Fill-in) | J19: = | O19: =H19*A19 -> 0
A20: Sinks
A21: 0 | C21: Bar | H21: 2 | J21: = | K21: 1.5" | M21: 2" | O21: =H21*A21 -> 0
A22: 0 | C22: Clinical | H22: 6 | J22: = | K22: 3" | M22: 3" | O22: =H22*A22 -> 0
A23: 0 | C23: Commercial w/ Food Waste | H23: 3 | J23: = | K23: 1.5" | M23: 2" | O23: =H23*A23 -> 0
A24: 0 | C24: Exam Room | H24: 1 | J24: = | K24: 1.5" | M24: 1.5" | O24: =H24*A24 -> 0
A25: 0 | C25: Service Or Mop Sink (2" Drain) | H25: 3 | J25: = | K25: 2" | M25: 2" | O25: =H25*A25 -> 0
A26: 0 | C26: Service Or Mop Sink (3" Drain) | H26: 3 | J26: = | K26: 3" | M26: 3" | O26: =H26*A26 -> 0
A27: Urinals
A28: 0 | C28: Urinal (1.0 GPF) Private/Public | H28: 2 | J28: = | K28: Integral | M28: 2" | O28: =H28*A28 -> 0
A29: 0 | C29: Urinal (1.0 GPF) Assembly | H29: 5 | J29: = | K29: Integral | M29: 2" | O29: =H29*A29 -> 0
A30: 0 | C30: Urinal (> 1.0 GPF) Private/Public | H30: 2 | J30: = | K30: Integral | M30: 2" | O30: =H30*A30 -> 0
A31: 0 | C31: Urinal (> 1.0 GPF) Assembly | H31: 6 | J31: = | K31: Integral | M31: 2" | O31: =H31*A31 -> 0
A32: 0 | C32: Urinal(Waterless) | H32: 0 | J32: = | K32: Integral | M32: 2" | O32: =H32*A32 -> 0
A33: Water Closets (1.6 GPF) Gravity Tank, Flushometer Tank & Flushometer Valve
A34: 0 | C34: Private | H34: 3 | J34: = | K34: Integral | M34: 3" | O34: =H34*A34 -> 0
A35: 0 | C35: Public | H35: 4 | J35: = | K35: Integral | M35: 3" | O35: =H35*A35 -> 0
A36: 0 | C36: Assembly | H36: 6 | J36: = | K36: Integral | M36: 3" | O36: =H36*A36 -> 0
A37: Water Closets (>1.6 GPF) Gravity Tank, Flushometer Tank & Flushometer Valve
A38: 0 | C38: Private | H38: 4 | J38: = | K38: Integral | M38: 3" | O38: =H38*A38 -> 0
A39: 0 | C39: Public | H39: 6 | J39: = | K39: Integral | M39: 3" | O39: =H39*A39 -> 0
A40: 0 | C40: Assembly | H40: 8 | J40: = | K40: Integral | M40: 3" | O40: =H40*A40 -> 0
K41: Total Fixture Units | N41: = | O41: =SUM(O8:O19,O21:O26,O28:O32,O34:O36,O38:O40) -> 0
K42: Min. Vent Size (in) | N42: = | O42: =IF(O41<=1,"1-1/4",(IF(O41<=8,"1-1/2",(IF(O41<=24,"2",(IF(O41<=84,"3",IF(O41<=256,"4")))))))) -> 1-1/4
K43: Main Trunk Size (in) | N43: = | O43: =IF((SUM(A28:B32,A34:B36,A38:B40))=0,"2",IF((SUM(A28:B32,A34:B36,A38:B40))<=3,"3",IF((SUM(A28:B32,A34:B36,A38:B40))>=4,"4",IF(O41<=21,"2",IF(O41<=42,"3",IF(O41<=216,"4")))))) -> 2
...

Sheet Supply (248 CMR) (MA)
D1: SERIAL NUMBER:
A4: INLET PIPE SIZING CHART (Massachusetts) | R4: Building Type: | S4: Business and Mercantile: | AI4: Residential:
A5: *Based on 248 CMR 10:14 | R5: Use: | S5: General | AG5: Residential: | AI5: One or Two Family Dwelling | AJ5: 0.5
AG6: School: | AI6: Multi-residential | AJ6: 0.35
A7: Quantity | C7: Description | G7: Fixture Units | J7: Minimum Pipe Size | M7: Fixture Units | R7: Demand Factor (Table 2): | S7: =IF(S4=AG5,INDEX(AJ5:AJ7,MATCH(S5,AI5:AI7,0)),IF(S4=AG6,INDEX(AJ9:AJ10,MATCH(S5,AI9:AI10,0)),IF(S4=AG7,INDEX(AJ12,MATCH(S5,AI12,0)),IF(S4=AG8,INDEX(AJ14:AJ16,MATCH(S5,AI14:AI16,0)),IF(S4=AG9,INDEX(AJ18:AJ20,MATCH(S5,AI18:AI20,0)),IF(S4=AG10,INDEX(AJ21,MATCH(S5,AI21,0)),0)))))) -> 1 | AG7: Institutional: | AI7: Hotel | AJ7: 0.7
G8: Cold | H8: Hot | I8: Total | J8: Table 1 | M8: Cold | N8: Hot | O8: Total | AG8: Assembly: | AI8: School:
A9: 0 | C9: Bathtub (with or without single shower head) | G9: 2 | H9: 2 | I9: 2 | J9: 1/2" | M9: =$A9*G9 -> 0 | N9: =$A9*H9 -> 0 | O9: =M9+N9 -> 0 | AG9: Business and Mercantile: | AI9: General | AJ9: 0.75
A10: 0 | C10: Bidet | G10: 1 | H10: 0 | I10: 1 | J10: 3/8" | M10: =$A10*G10 -> 0 | N10: =$A10*H10 -> 0 | O10: =M10+N10 -> 0 | AG10: Industrial: | AI10: Shower Room | AJ10: 1
A11: 0 | C11: Drinking Water Station | G11: 1 | H11: 0 | I11: 1 | J11: 3/8" | M11: =$A11*G11 -> 0 | N11: =$A11*H11 -> 0 | O11: =M11+N11 -> 0 | AI11: Institutional:
A12: 0 | C12: Dishwasher (Domestic) | G12: 0 | H12: 2 | I12: 2 | J12: 1/2" | M12: =$A12*G12 -> 0 | N12: =$A12*H12 -> 0 | O12: =M12+N12 -> 0 | AI12: General | AJ12: 0.45
A13: 0 | C13: Dishwasher (Commercial) | G13: 0 | H13: 6 | I13: 6 | J13: 3/4" | M13: =$A13*G13 -> 0 | N13: =$A13*H13 -> 0 | O13: =M13+N13 -> 0 | AI13: Assembly:
A14: 0 | C14: Kitchen sink, Residential | G14: 2 | H14: 2 | I14: 2 | J14: 1/2" | M14: =$A14*G14 -> 0 | N14: =$A14*H14 -> 0 | O14: =M14+N14 -> 0 | AI14: General | AJ14: 0.25
A15: 0 | C15: Kitchen sink, Commercial (Pot and Scullery) | G15: 6 | H15: 6 | I15: 6 | J15: 3/4" | M15: =$A15*G15 -> 0 | N15: =$A15*H15 -> 0 | O15: =M15+N15 -> 0 | AI15: Restaurant, Café | AJ15: 0.7
A16: 0 | C16: Vegatable Prep or Bar Sink (Residential) | G16: 2 | H16: 2 | I16: 2 | J16: 1/2" | M16: =$A16*G16 -> 0 | N16: =$A16*H16 -> 0 | O16: =M16+N16 -> 0 | AI16: Club House | AJ16: 0.6
A17: 0 | C17: Hand Wash Sinks | G17: 1 | H17: 1 | I17: 1 | J17: 3/8" | M17: =$A17*G17 -> 0 | N17: =$A17*H17 -> 0 | O17: =M17+N17 -> 0 | AI17: Business and Mercantile
A18: 0 | C18: Shampoo Sinks | G18: 1 | H18: 1 | I18: 1 | J18: 3/8" | M18: =$A18*G18 -> 0 | N18: =$A18*H18 -> 0 | O18: =M18+N18 -> 0 | AI18: General | AJ18: 1
A19: 0 | C19: Lavatory | G19: 1 | H19: 1 | I19: 1 | J19: 3/8" | M19: =$A19*G19 -> 0 | N19: =$A19*H19 -> 0 | O19: =M19+N19 -> 0 | AI19: Industrial | AJ19: 0.25
A20: 0 | C20: Utility Laundry Sinks, 1, 2, or 3 compartments | G20: 2 | H20: 2 | I20: 2 | J20: 1/2" | M20: =$A20*G20 -> 0 | N20: =$A20*H20 -> 0 | O20: =M20+N20 -> 0 | AI20: Laundry | AJ20: 1
A21: 0 | C21: Shower Valve (Single head) | G21: 2 | H21: 2 | I21: 2 | J21: 1/2" | M21: =$A21*G21 -> 0 | N21: =$A21*H21 -> 0 | O21: =M21+N21 -> 0 | AI21: Industrial, Exclusive of Process Piping | AJ21: 0.9
A22: 0 | C22: Shower Valve (Multi-head) | G22: 6 | H22: 6 | I22: 6 | J22: 3/4" | M22: =$A22*G22 -> 0 | N22: =$A22*H22 -> 0 | O22: =M22+N22 -> 0
A23: 0 | C23: Sinks (service, slop) | G23: 2 | H23: 2 | I23: 2 | J23: 1/2" | M23: =$A23*G23 -> 0 | N23: =$A23*H23 -> 0 | O23: =M23+N23 -> 0
A24: 0 | C24: Sinks flushing rim | G24: 6 | H24: 0 | I24: 6 | J24: 3/4" | M24: =$A24*G24 -> 0 | N24: =$A24*H24 -> 0 | O24: =M24+N24 -> 0
A25: 0 | C25: Laundry Valve | G25: 2 | H25: 2 | I25: 2 | J25: 1/2" | M25: =$A25*G25 -> 0 | N25: =$A25*H25 -> 0 | O25: =M25+N25 -> 0
A26: 0 | C26: Urinal (flush valve) | G26: 6 | H26: 0 | I26: 6 | J26: 3/4" | M26: =$A26*G26 -> 0 | N26: =$A26*H26 -> 0 | O26: =M26+N26 -> 0
A27: 0 | C27: Water Closet (Tank) | G27: 1 | H27: 0 | I27: 1 | J27: 3/8" | M27: =$A27*G27 -> 0 | N27: =$A27*H27 -> 0 | O27: =M27+N27 -> 0
A28: 0 | C28: Water Closet (Flush valve) | G28: 12 | H28: 0 | I28: 12 | J28: 1" | M28: =$A28*G28 -> 0 | N28: =$A28*H28 -> 0 | O28: =M28+N28 -> 0
A29: 0 | C29: Hose Connections/Sillcocks/Wall Hydrants | G29: 2 | H29: 0 | I29: 2 | J29: 1/2" | M29: =$A29*G29 -> 0 | N29: =$A29*H29 -> 0 | O29: =M29+N29 -> 0
A30: 0 | C30: Misc(Fill-in) | M30: =$A30*G30 -> 0 | N30: =$A30*H30 -> 0 | O30: =M30+N30 -> 0
A31: 0 | C31: Misc(Fill-in) | M31: =$A31*G31 -> 0 | N31: =$A31*H31 -> 0 | O31: =M31+N31 -> 0
A32: 0 | C32: Misc(Fill-in) | M32: =$A32*G32 -> 0 | N32: =$A32*H32 -> 0 | O32: =M32+N32 -> 0
J33: Total Fixture Units | M33: =SUM(M9:M32) -> 0 | N33: =SUM(N9:N32) -> 0 | O33: =SUM(O9:O32) -> 0
A36: *248 CMR, Table 3 | G36: Cold | K36: Hot
A37: 248 CMR Page - 159 | G37: Size | H37: F.U. W/ Demand Factor | K37: Size | L37: F.U. W/ Demand Factor
A38: Capacity Value | D38: Nom. Pipe Size | G38: =IF(H38=0,0,IF(H38<=C39,"1/2""",IF(H38<=C40,"3/4""",IF(H38<=C41,"1""",IF(H38<=C42,"1-1/4""",IF(H38<=C43,"1-1/2""",IF(H38<=C44,"2""",IF(H38<=C45,"2-1/2""",IF(H38<=C46,"3""",IF(H38<=C47,"3-1/2""",IF(H38<=C48,"4""",IF(H38<=C49,"5""",IF(H38<=C50,"6""",0))))))))))))) -> 0 | H38: =SUM(M33*S7) -> 0 | K38: =IF(L38=0,0,IF(L38<=C39,"1/2""",IF(L38<=C40,"3/4""",IF(L38<=C41,"1""",IF(L38<=C42,"1-1/4""",IF(L38<=C43,"1-1/2""",IF(L38<=C44,"2""",IF(L38<=C45,"2-1/2""",IF(L38<=C46,"3""",IF(L38<=C47,"3-1/2""",IF(L38<=C48,"4""",IF(L38<=C49,"5""",IF(L38<=C50,"6""",0))))))))))))) -> 0 | L38: =SUM(N33*S7) -> 0
A39: 1 | B39: to | C39: 4 | D39: 1/2" PIPE
A40: 4.1 | B40: to | C40: 9 | D40: 3/4" PIPE
A41: 9.1 | B41: to | C41: 16.5 | D41: 1" PIPE
A42: 16.6 | B42: to | C42: 28 | D42: 1 1/4" PIPE | G42: INLET
A43: 28.1 | B43: to | C43: 55 | D43: 1 1/2" PIPE | G43: Size | H43: F.U. W/ Demand Factor
A44: 55.1 | B44: to | C44: 107.5 | D44: 2" PIPE | G44: =IF(H44=0,0,IF(H44<=C39,"1/2""",IF(H44<=C40,"3/4""",IF(H44<=C41,"1""",IF(H44<=C42,"1-1/4""",IF(H44<=C43,"1-1/2""",IF(H44<=C44,"2""",IF(H44<=C45,"2-1/2""",IF(H44<=C46,"3""",IF(H44<=C47,"3-1/2""",IF(H44<=C48,"4""",IF(H44<=C49,"5""",IF(H44<=C50,"6""",0))))))))))))) -> 0 | H44: =SUM(O33*S7) -> 0
...

Sheet Waste (248 CMR) (MA)
D1: SERIAL NUMBER:
A4: WASTE MAIN TRUNK SIZE (Massachusetts)
A5: *248 CMR Table 1
A7: Quantity | C7: Description | H7: Fixture Units | K7: Min. Trap Size | M7: Min. Drain Size | O7: Total
A8: 0 | C8: Bathtub or Bath/Shower | H8: 2 | J8: = | K8: 1-1/2" | M8: 1-1/2" | O8: =H8*A8 -> 0
A9: 0 | C9: Bidet | H9: 2 | J9: = | K9: 1-1/4" | M9: 1-1/4" | O9: =H9*A9 -> 0
A10: 0 | C10: Dental Chair unit or Cuspidor | H10: 1 | J10: = | K10: 1-1/2" | M10: 1-1/2" | O10: =H10*A10 -> 0
A11: 0 | C11: Dental Lavatory | H11: 1 | J11: = | K11: 1-1/4" | M11: 1-1/4" | O11: =H11*A11 -> 0
A12: 0 | C12: Drinking Fountain / Water Station | H12: 1 | J12: = | K12: 1-1/4" | M12: 1-1/4" | O12: =H12*A12 -> 0
A13: 0 | C13: Dishwasher (Commercial) | H13: 6 | J13: = | K13: See Equipment | M13: See Equipment | O13: =H13*A13 -> 0
A14: 0 | C14: Dishwasher (Residential) | H14: 1 | J14: = | K14: 1-1/4" | M14: 1-1/4" | O14: =H14*A14 -> 0
A15: 0 | C15: Floor / Trench drain (2") | H15: 4 | J15: = | K15: 2" | M15: 2" | O15: =H15*A15 -> 0
A16: 0 | C16: Floor / Trench drain (3") | H16: 5 | J16: = | K16: 3" | M16: 3" | O16: =H16*A16 -> 0
A17: 0 | C17: Floor / Trench drain (4") | H17: 6 | J17: = | K17: 4" | M17: 4" | O17: =H17*A17 -> 0
A18: 0 | C18: Kitchen sink (Residential) | H18: 2 | J18: = | K18: 1-1/4" | M18: 1-1/4" | O18: =H18*A18 -> 0
A19: 0 | C19: Lavatory | H19: 1 | J19: = | K19: 1-1/4" | M19: 1-1/4" | O19: =H19*A19 -> 0
... A29: 0 | C29: Misc (4") | H29: 6 | J29: = | K29: 4" | M29: 4" | O29: =H29*A29 -> 0
A30: Sinks
A31: 0 | C31: Surgeons | H31: 3 | J31: = | K31: 3" | M31: 3" | O31: =H31*A31 -> 0
A32: 0 | C32: Flushing rim (with valve) | H32: 6 | J32: = | K32: 2-1/2" | M32: 2-1/2" | O32: =H32*A32 -> 0
A33: 0 | C33: Service sink with Trap Standard | H33: 3 | J33: = | K33: 3" | M33: 3" | O33: =H33*A33 -> 0
A34: 0 | C34: Service sink with P-Trap | H34: 2 | J34: = | K34: 2" | M34: 2" | O34: =H34*A34 -> 0
A35: 0 | C35: Commercial Pot, Scullery, etc | H35: 4 | J35: = | K35: 3" | M35: 3" | O35: =H35*A35 -> 0
A36: 0 | C36: Shampoo | H36: 2 | J36: = | K36: 1-1/2" | M36: 1-1/2" | O36: =H36*A36 -> 0
A37: Urinals and Water Closets
A38: 0 | C38: Toilet (Tank type) | H38: 4 | J38: = | K38: Integral | M38: 3" | O38: =H38*A38 -> 0
A39: 0 | C39: Toilet (Flush Valve) | H39: 6 | J39: = | K39: Integral | M39: 3" | O39: =H39*A39 -> 0
A40: 0 | C40: Urinal (Floor Mtd) | H40: 6 | J40: = | K40: Integral | M40: 2" | O40: =H40*A40 -> 0
A41: 0 | C41: Urinal (Wall Mtd) | H41: 4 | J41: = | K41: Integral | M41: 2" | O41: =H41*A41 -> 0
A42: 0 | C42: Urinal(Waterless) | H42: 1 | J42: = | K42: Integral | M42: 2" | O42: =H42*A42 -> 0
A43: Wash Sink
A44: 0 | C44: Circular or Multiple (ea. 20" of usable length) | H44: 1 | J44: = | K44: Integral | M44: 1-1/2" | O44: =H44*A44 -> 0
K45: Total Fixture Units | N45: = | O45: =SUM(O8:O29,O31:O36,O38:O42,O44) -> 0
K46: Min. Vent Size @ Branch | N46: = | O46: =IF(O45<=1,"1-1/4""",IF(O45<=4,"1-1/2""",IF(O45<=10,"2""",IF(O45<=28,"2-1/2""",IF(O45<=102,"3""",IF(O45<=320,"4""")))))) -> 1-1/4"
K47: Min. Vent Size thru Roof (in) | N47: = | O47: =IF(O45>102,4,3) -> 3 | P47: See 10.16(2) - At least one full size main stack vent shall be 3" (Use chart below)
K48: Main Trunk Size | N48: = | O48: =IF(SUM(A38:B42)>=4,"4""",IF(O45<=3,"1-1/2""",IF(O45<=6,"2""",IF(O45<=12,"2-1/2""",IF(O45<=34,"3""",IF(O45<=160,"4""",IF(O45<=360,"5""",IF(O45<=620,"6""",IF(O45<=1400,"8""",IF(O45<=2500,"10""",IF(O45<=3900,"12""",IF(O45<=7000,"15""")))))))))))) -> 1-1/2"
A51: *Minimum size of any building drain serving a water closet shall be 3"
A53: **4 or more water closets/urinals require a minimum of 4"
A57: Diameter of Vent 1 | D57: 0 | E57: in
A58: Diameter of Vent 2 | D58: 0 | E58: in
...

Sheet Supply (NSPC) (NJ)
D1: SERIAL NUMBER:
U2: TANK TYPE (GPM)
U3: Cold | V3: Hot | W3: Total | Y3: WSFU | Z3: GPM (Tanks) | AB3: WSFU | AC3: GPM (Valve) | AG3: Note: Hot water copper piping must be taken at 5 feet per second (Section 10.14.1 & B.7.3)
A4: INLET PIPE SIZING CHART (National Plumbing Code Standard) | U4: =IF(SUM(L9+L10+L11+L12+L13+L14+L15+L16+L17+L18+L19+L20+L21+L22+L25+L26+L27+L28+L30+L31+L32+L33+L34+L35)=0,0,ROUNDUP(INDEX(Z4:Z263,MATCH(SUM(L9+L10+L11+L12+L13+L14+L15+L16+L17+L18+L19+L20+L21+L22+L25+L26+L27+L28+L30+L31+L32+L33+L34+L35),Y4:Y263,1)),1)) -> 7.5 | V4: =IF(SUM(M9+M10+M11+M12+M13+M14+M15+M16+M17+M18+M19+M20+M21+M22+M25+M26+M27+M28+M30+M31+M32+M33+M34+M35)=0,0,ROUNDUP(INDEX(Z4:Z263,MATCH(SUM(M9+M10+M11+M12+M13+M14+M15+M16+M17+M18+M19+M20+M21+M22+M25+M26+M27+M28+M30+M31+M32+M33+M34+M35),Y4:Y263,1)),1)) -> 1 | W4: =IF(SUM(N9+N10+N11+N12+N13+N14+N15+N16+N17+N18+N19+N20+N21+N22+N25+N26+N27+N28+N30+N31+N32+N33+N34+N35)=0,0,ROUNDUP(INDEX(Z4:Z263,MATCH(SUM(N9+N10+N11+N12+N13+N14+N15+N16+N17+N18+N19+N20+N21+N22+N25+N26+N27+N28+N30+N31+N32+N33+N34+N35),Y4:Y263,1)),1)) -> 7.5 | Y4: 1 | Z4: 1 | AG4: TABLE B.7.3.B - TYPE K COPPER
A5: *Based on 10.14, Appendix B, and Appendix K | Y5: 2 | Z5: 2 | AG5: PIPE SIZE | AH5: 4 FPS VELOCITY | AL5: PIPE SIZE | AM5: 5 FPS VELOCITY (Hot Water) | AQ5: PIPE SIZE | AR5: 8 FPS VELOCITY | AW5: 4 FPS (F.V.) (PER GPM)
P6: Building Use: | Q6: Other than Dwelling Units | U6: FLUSH VALVE (GPM) | Y6: 3 | Z6: 3 | AH6: WSFU (TANK) | AI6: WSFU (VALVE) | AJ6: FLOW (GPM) | AK6: PSI/100FT | AM6: WSFU (TANK) | AN6: WSFU (VALVE) | AO6: FLOW (GPM) | AP6: PSI/100FT | AR6: WSFU (TANK) | AS6: WSFU (VALVE) | AT6: FLOW (GPM) | AU6: PSI/100FT | AW6: COLD | AY6: TOTAL
A7: Quantity | C7: Description | F7: Fixture Units (WSFU) | I7: Minimum Pipe Size | L7: Fixture Units (WSFU) | U7: =IF(SUM(L23+L24+L29)=0,0,ROUNDUP(INDEX(AC8:AC263,MATCH(SUM(L23+L24+L29),AB8:AB263,1)),1)) -> 22 | V7: 0 | W7: =IF(SUM(L23+L24+L29)=0,0,ROUNDUP(INDEX(AC8:AC263,MATCH(SUM(N23+N24+N29),AB8:AB263,1)),1)) -> 22 | Y7: 4 | Z7: 4 | AG7: 3/8" | AJ7: 1.6 | AK7: 8.4 | AL7: 3/8" | AO7: 2 | AP7: 12.7 | AQ7: 3/8" | AR7: 3 | AT7: 3.2 | AU7: 30.4 | AW7: =IF(U7=0,0,IF(L37=0,0,IF(L37<=AJ8,"1/2""",IF(L37<=AJ9,"3/4""",IF(L37<=AJ10,"1""",IF(L37<=AJ11,"1-1/4""",IF(L37<=AJ12,"1-1/2""",IF(L37<=AJ13,"2""",IF(L36<=AJ14,"2-1/2""",IF(L37<=AJ15,"3""",IF(L37<=AJ16,"4""",IF(L37<=AJ17,"5""",IF(L37<=AJ18,"6""",0))))))))))))) -> 2" | AY7: =IF(W7=0,0,IF(N37=0,0,IF(N37<=AJ8,"1/2""",IF(N37<=AJ9,"3/4""",IF(N37<=AJ10,"1""",IF(N37<=AJ11,"1-1/4""",IF(N37<=AJ12,"1-1/2""",IF(N37<=AJ13,"2""",IF(N37<=AJ14,"2-1/2""",IF(N37<=AJ15,"3""",IF(N37<=AJ16,"4""",IF(N37<=AJ17,"5""",IF(N37<=AJ18,"6""",0))))))))))))) -> 2"
F8: Cold | G8: Hot | H8: Total | L8: Cold | M8: Hot | N8: Total | Y8: 5 | Z8: 4.5 | AB8: 5 | AC8: 22 | AG8: 1/2" | AJ8: 2.7 | AK8: 6.1 | AL8: 1/2" | AM8: 3 | AO8: 3.4 | AP8: 9.3 | AQ8: 1/2" | AR8: 6 | AT8: 5.4 | AU8: 22.1
A9: 0 | C9: Bar Sink | F9: =IF(Q6="Serving 3 or more dwelling units",0.4,0.8) -> 0.8 | G9: =IF(Q6="Serving 3 or more dwelling units",0.4,0.8) -> 0.8 | H9: =IF(Q6="Serving 3 or more dwelling units",0.5,1) -> 1 | I9: 3/8" | L9: =$A9*F9 -> 0 | M9: =$A9*G9 -> 0 | N9: =$A9*H9 -> 0 | P9: Type of Pipe Used: | Q9: CPVC/PVC/ABS/Plastic Schedule 40 | Y9: 6 | Z9: 5 | AB9: 6 | AC9: 23 | AG9: 3/4" | AH9: 6 | AJ9: 5.4 | AK9: 4.1 | AL9: 3/4" | AM9: 8 | AO9: 6.8 | AP9: 6.2 | AQ9: 3/4" | AR9: 15 | AT9: 10.9 | AU9: 14.8 | AW9: 5 / 8 FPS (PER GPM)
A10: 0 | C10: Bathtub or Combo Bath/Shower | F10: =IF(Q6="Serving 3 or more dwelling units",2.6,3) -> 3 | G10: =IF(Q6="Serving 3 or more dwelling units",2.6,3) -> 3 | H10: =IF(Q6="Serving 3 or more dwelling units",3.5,4) -> 4 | I10: 1/2" | L10: =$A10*F10 -> 0 | M10: =$A10*G10 -> 0 | N10: =$A10*H10 -> 0 | Y10: 7 | Z10: 6 | AB10: 7 | AC10: 24 | AG10: 1" | AH10: 13 | AJ10: 9.7 | AK10: 2.9 | AL10: 1" | AM10: 16 | AO10: 12.1 | AP10: 4.4 | AQ10: 1" | AR10: 29 | AT10: 19.4 | AU10: 10.6 | AW10: COLD | AX10: HOT | AY10: TOTAL
A11: 0 | C11: Bidet | F11: =IF(Q6="Serving 3 or more dwelling units",0.4,0.8) -> 0.8 | G11: =IF(Q6="Serving 3 or more dwelling units",0.4,0.8) -> 0.8 | H11: =IF(Q6="Serving 3 or more dwelling units",0.5,1) -> 1 | I11: 1/2" | L11: =$A11*F11 -> 0 | M11: =$A11*G11 -> 0 | N11: =$A11*H11 -> 0 | Y11: 8 | Z11: 7 | AB11: 8 | AC11: 25 | AG11: 1-1/4" | AH11: 22 | AJ11: 15.2 | AK11: 2.3 | AL11: 1-1/4" | AM11: 28 | AO11: 19 | AP11: 3.4 | AQ11: 1-1/4" | AR11: 53 | AS11: 14 | AT11: 30.4 | AU11: 8.1 | AW11: =IF(L37=0,0,IF(L37<=AT8,"1/2""",IF(L37<=AT9,"3/4""",IF(L37<=AT10,"1""",IF(L37<=AT11,"1-1/4""",IF(L37<=AT12,"1-1/2""",IF(L37<=AT13,"2""",IF(L37<=AT14,"2-1/2""",IF(L37<=AT15,"3""",IF(L37<=AT16,"4""",IF(L37<=AT17,"5""",IF(L37<=AT18,"6""",0)))))))))))) -> 1-1/4" | AX11: =IF(M37=0,0,IF(M37<=AO8,"1/2""",IF(M37<=AO9,"3/4""",IF(M37<=AO10,"1""",IF(M37<=AO11,"1-1/4""",IF(M37<=AO12,"1-1/2""",IF(M37<=AO13,"2""",IF(M37<=AO14,"2-1/2""",IF(M37<=AO15,"3""",IF(M37<=AO16,"4""",IF(M37<=AO17,"5""",IF(M37<=AO18,"6""",0)))))))))))) -> 1/2" | AY11: =IF(N37=0,0,IF(N37<=AT8,"1/2""",IF(N37<=AT9,"3/4""",IF(N37<=AT10,"1""",IF(N37<=AT11,"1-1/4""",IF(N37<=AT12,"1-1/2""",IF(N37<=AT13,"2""",IF(N37<=AT14,"2-1/2""",IF(N37<=AT15,"3""",IF(N37<=AT16,"4""",IF(N37<=AT17,"5""",IF(N37<=AT18,"6""",0)))))))))))) -> 1-1/4"
A12: 0 | C12: Clothes Washer (Domestic) | F12: =IF(Q6="Serving 3 or more dwelling units",1.9,3) -> 3 | G12: =IF(Q6="Serving 3 or more dwelling units",1.9,3) -> 3 | H12: =IF(Q6="Serving 3 or more dwelling units",2.5,4) -> 4 | I12: 1/2" | L12: =$A12*F12 -> 0 | M12: =$A12*G12 -> 0 | N12: =$A12*H12 -> 0 | Y12: 9 | Z12: 7.5 | AB12: 9 | AC12: 26 | AG12: 1-1/2" | AH12: 33 | AI12: 5 | AJ12: 21.5 | AK12: 1.8 | AL12: 1-1/2" | AM12: 45 | AN12: 10 | AO12: 26.9 | AP12: 2.8 | AQ12: 1-1/2" | AR12: 96 | AS12: 33 | AT12: 43 | AU12: 6.7
A13: 0 | C13: Dishwasher (Domestic) | F13: 0 | G13: =IF(Q6="Serving 3 or more dwelling units",1,1.5) -> 1.5 | H13: =IF(Q6="Serving 3 or more dwelling units",1,1.5) -> 1.5 | I13: 1/2' | L13: =$A13*F13 -> 0 | M13: =$A13*G13 -> 0 | N13: =$A13*H13 -> 0 | Y13: 10 | Z13: 8 | AB13: 10 | AC13: 27 | AG13: 2" | AH13: 75 | AI13: 24 | AJ13: 37.6 | AK13: 1.3 | AL13: 2" | AM13: 112 | AN13: 40 | AO13: 47 | AP13: 2 | AQ13: 2" | AR13: 251 | AS13: 126 | AT13: 75.2 | AU13: 4.8 | AW13: TOTALS (HIGHER VALUE)
A14: 0 | C14: Drinking Fountian or Water Cooler | F14: =IF(Q6="heavy-use assembly",0.8,0.5) -> 0.5 | G14: 0 | H14: =IF(Q6="heavy-use assembly",0.8,0.5) -> 0.5 | I14: 3/8" | L14: =$A14*F14 -> 0 | M14: =$A14*G14 -> 0 | N14: =$A14*H14 -> 0 | Y14: 11 | Z14: 8.5 | AB14: 11 | AC14: 28 | AG14: 2-1/2" | AH14: 165 | AI14: 69 | AJ14: 58.1 | AK14: 1 | AL14: 2-1/2" | AM14: 238 | AN14: 115 | AO14: 72.6 | AP14: 1.6 | AQ14: 2-1/2" | AR14: 456 | AS14: 341 | AT14: 116.1 | AU14: 3.7 | AW14: COLD | AX14: HOT | AY14: TOTAL
A15: 0 | C15: Hose Bib (First) | F15: 2.5 | G15: 0 | H15: 2.5 | I15: 1/2" | L15: =$A15*F15 -> 0 | M15: =$A15*G15 -> 0 | N15: =$A15*H15 -> 0 | Y15: 12 | Z15: 9 | AB15: 12 | AC15: 29 | AG15: 3" | AH15: 289 | AI15: 159 | AJ15: 82.8 | AK15: 0.8 | AL15: 3" | AM15: 392 | AN15: 267 | AO15: 103.4 | AP15: 1.3 | AQ15: 3" | AR15: 725 | AS15: 682 | AT15: 165.5 | AU15: 3 | AW15: =IF(AW7>0,AW7,AW11) -> 2" | AX15: =AX11 -> 1/2" | AY15: =IF(AY7>0,AY7,AY11) -> 2"
A16: 0 | C16: Hose Bib (Each additional) | F16: 1 | G16: 0 | H16: 1 | I16: 1/2" | L16: =$A16*F16 -> 0 | M16: =$A16*G16 -> 0 | N16: =$A16*H16 -> 0 | Y16: 13 | Z16: 10 | AB16: 13 | AC16: 29.5 | AG16: 4" | AH16: 615 | AI16: 541 | AJ16: 145.7 | AK16: 0.6 | AL16: 4" | AM16: 826 | AN16: 801 | AO16: 182.1 | AP16: 0.9 | AQ16: 4" | AR16: 1678 | AS16: 1678 | AT16: 291.4 | AU16: 2.2
A17: 0 | C17: Kitchen Sink (Domestic) | F17: =IF(Q6="Serving 3 or more dwelling units",0.8,1.1) -> 1.1 | G17: =IF(Q6="Serving 3 or more dwelling units",0.8,1.1) -> 1.1 | H17: =IF(Q6="Serving 3 or more dwelling units",1,1.5) -> 1.5 | I17: 1/2" | L17: =$A17*F17 -> 0 | M17: =$A17*G17 -> 0 | N17: =$A17*H17 -> 0 | Y17: 14 | Z17: 10.5 | AB17: 14 | AC17: 30 | AG17: 5" | AH17: 1134 | AI17: 1134 | AJ17: 226.1 | AK17: 0.5 | AL17: 5" | AM17: 1605 | AN17: 1605 | AO17: 282.6 | AP17: 0.7 | AQ17: 5" | AR17: 3191 | AS17: 3191 | AT17: 452.2 | AU17: 1.7
A18: 0 | C18: Laundry Sink | F18: =IF(Q6="Serving 3 or more dwelling units",0.8,1.5) -> 1.5 | G18: =IF(Q6="Serving 3 or more dwelling units",0.8,1.5) -> 1.5 | H18: =IF(Q6="Serving 3 or more dwelling units",1,2) -> 2 | I18: 1/2" | L18: =$A18*F18 -> 0 | M18: =$A18*G18 -> 0 | N18: =$A18*H18 -> 0 | Y18: 15 | Z18: 11 | AB18: 15 | AC18: 31 | AG18: 6" | AH18: 1978 | AI18: 1978 | AJ18: 322.8 | AK18: 0.4 | AL18: 6" | AM18: 2713 | AN18: 2713 | AO18: 403.5 | AP18: 6 | AQ18: 6" | AR18: 5910 | AS18: 5910 | AT18: 645.5 | AU18: 1.4
A19: 2 | C19: Lavatory | F19: =IF(Q6="Serving 3 or more dwelling units",0.4,0.8) -> 0.8 | G19: =IF(Q6="Serving 3 or more dwelling units",0.4,0.8) -> 0.8 | H19: =IF(Q6="Serving 3 or more dwelling units",0.5,1) -> 1 | I19: 3/8" | L19: =$A19*F19 -> 1.6 | M19: =$A19*G19 -> 1.6 | N19: =$A19*H19 -> 2 | Y19: 16 | Z19: 12 | AB19: 16 | AC19: 32
A20: 0 | C20: Service Sink or Mop Basin | F20: 2.3 | G20: 2.3 | H20: 3 | I20: 1/2" | L20: =$A20*F20 -> 0 | M20: =$A20*G20 -> 0 | N20: =$A20*H20 -> 0 | Y20: 17 | Z20: 12.5 | AB20: 17 | AC20: 33 | AG20: TABLE B.7.3.C - TYPE L COPPER
A21: 0 | C21: Shower | F21: 1.5 | G21: 1.5 | H21: 2 | I21: 1/2" | L21: =$A21*F21 -> 0 | M21: =$A21*G21 -> 0 | N21: =$A21*H21 -> 0 | Y21: 18 | Z21: 13 | AB21: 18 | AC21: 33.5 | AG21: PIPE SIZE | AH21: 4 FPS VELOCITY | AL21: PIPE SIZE | AM21: 5 FPS VELOCITY (Hot Water) | AQ21: PIPE SIZE | AR21: 8 FPS VELOCITY | AW21: 4 FPS (F.V.) (PER GPM)
A22: 0 | C22: Shower (Continuous Use) | F22: 3.8 | G22: 3.8 | H22: 5 | I22: 3/4" | L22: =$A22*F22 -> 0 | M22: =$A22*G22 -> 0 | N22: =$A22*H22 -> 0 | Y22: 19 | Z22: 13.5 | AB22: 19 | AC22: 34 | AH22: WSFU (TANK) | AI22: WSFU (VALVE) | AJ22: FLOW (GPM) | AK22: PSI/100FT | AM22: WSFU (TANK) | AN22: WSFU (VALVE) | AO22: FLOW (GPM) | AP22: PSI/100FT | AR22: WSFU (TANK) | AS22: WSFU (VALVE) | AT22: FLOW (GPM) | AU22: PSI/100FT | AW22: COLD | AY22: TOTAL
A23: 0 | C23: Urinal (1.0 GPF) | F23: =IF(Q6="heavy-use assembly",5,4) -> 4 | G23: 0 | H23: =IF(Q6="heavy-use assembly",5,4) -> 4 | I23: 3/4" | L23: =$A23*F23 -> 0 | M23: =$A23*G23 -> 0 | N23: =$A23*H23 -> 0 | Y23: 20 | Z23: 14 | AB23: 20 | AC23: 35 | AG23: 3/8" | AJ23: 1.8 | AK23: 7.8 | AL23: 3/8" | AM23: 2 | AO23: 2.3 | AP23: 11.7 | AQ23: 3/8" | AR23: 4 | AT23: 3.6 | AU23: 28 | AW23: =IF(U7=0,0,IF(L37=0,0,IF(L37<=AJ24,"1/2""",IF(L37<=AJ25,"3/4""",IF(L37<=AJ26,"1""",IF(L37<=AJ27,"1-1/4""",IF(L37<=AJ28,"1-1/2""",IF(L37<=AJ29,"2""",IF(L37<=AJ30,"2-1/2""",IF(L37<=AJ31,"3""",IF(L37<=AJ32,"4""",IF(L37<=AJ33,"5""",IF(L37<=AJ34,"6""",0))))))))))))) -> 2" | AX23: 0 | AY23: =IF(W7=0,0,IF(N37<=AJ24,"1/2""",IF(N37<=AJ25,"3/4""",IF(N37<=AJ26,"1""",IF(N37<=AJ27,"1-1/4""",IF(N37<=AJ28,"1-1/2""",IF(N37<=AJ29,"2""",IF(N37<=AJ30,"2-1/2""",IF(N37<=AJ31,"3""",IF(N37<=AJ32,"4""",IF(N37<=AJ33,"5""",IF(N37<=AJ34,"6""",0)))))))))))) -> 2"
A24: 0 | C24: Urinal (Greater than 1.0 GPF) | F24: =IF(Q6="heavy-use assembly",6,5) -> 5 | G24: 0 | H24: =IF(Q6="heavy-use assembly",6,5) -> 5 | I24: 3/4" | L24: =$A24*F24 -> 0 | M24: =$A24*G24 -> 0 | N24: =$A24*H24 -> 0 | Y24: 21 | Z24: 14.6 | AB24: 21 | AC24: 35.6 | AG24: 1/2" | AH24: 3 | AJ24: 2.9 | AK24: 5.9 | AL24: 1/2" | AM24: 4 | AO24: 3.6 | AP24: 8.9 | AQ24: 1/2" | AR24: 7 | AT24: 5.8 | AU24: 21.3
A25: 0 | C25: Wash Fountian (Per rated user) | I25: See Fixture Specs | L25: =$A25*F25 -> 0 | M25: =$A25*G25 -> 0 | N25: =$A25*H25 -> 0 | Y25: 22 | Z25: 15.2 | AB25: 22 | AC25: 36.2 | AG25: 3/4" | AH25: 7 | AJ25: 6 | AK25: 3.9 | AL25: 3/4" | AM25: 9 | AO25: 7.5 | AP25: 5.8 | AQ25: 3/4" | AR25: 16 | AT25: 12.1 | AU25: 13.9 | AW25: 5 / 8 FPS (PER GPM)
A26: 0 | C26: Wash Sink (1 or 2 faucets, per faucet) | I26: See Fixture Specs | L26: =$A26*F26 -> 0 | M26: =$A26*G26 -> 0 | N26: =$A26*H26 -> 0 | Y26: 23 | Z26: 15.8 | AB26: 23 | AC26: 36.8 | AG26: 1" | AH26: 14 | AJ26: 10.3 | AK26: 2.8 | AL26: 1" | AM26: 18 | AO26: 12.9 | AP26: 4.3 | AQ26: 1" | AR26: 31 | AT26: 20.6 | AU26: 10.2 | AW26: COLD | AX26: HOT | AY26: TOTAL
A27: 3 | C27: Water Closet (Gravity Tank) | F27: =IF(Q6="heavy-use assembly",4,2.5) -> 2.5 | G27: 0 | H27: =IF(Q6="heavy-use assembly",4,2.5) -> 2.5 | I27: 1/2" | L27: =$A27*F27 -> 7.5 | M27: =$A27*G27 -> 0 | N27: =$A27*H27 -> 7.5 | Y27: 24 | Z27: 16.4 | AB27: 24 | AC27: 37.4 | AG27: 1-1/4" | AH27: 23 | AJ27: 15.7 | AK27: 2.2 | AL27: 1-1/4" | AM27: 29 | AO27: 19.5 | AP27: 3.3 | AQ27: 1-1/4" | AR27: 56 | AS27: 15 | AT27: 31.3 | AU27: 8 | AW27: =IF(L37=0,0,IF(L37<=AT24,"1/2""",IF(L37<=AT25,"3/4""",IF(L37<=AT26,"1""",IF(L37<=AT27,"1-1/4""",IF(L37<=AT28,"1-1/2""",IF(L37<=AT29,"2""",IF(L37<=AT30,"2-1/2""",IF(L37<=AT31,"3""",IF(L37<=AT32,"4""",IF(L37<=AT33,"5""",IF(L37<=AT34,"6""",0)))))))))))) -> 1-1/4" | AX27: =IF(M37=0,0,IF(M37<=AO24,"1/2""",IF(M37<=AO25,"3/4""",IF(M37<=AO26,"1""",IF(M37<=AO27,"1-1/4""",IF(M37<=AO28,"1-1/2""",IF(M37<=AO29,"2""",IF(M37<=AO30,"2-1/2""",IF(M37<=AO31,"3""",IF(M37<=AO32,"4""",IF(M37<=AO33,"5""",IF(M37<=AO34,"6""",0)))))))))))) -> 1/2" | AY27: =IF(N37=0,0,IF(N37<=AT24,"1/2""",IF(N37<=AT25,"3/4""",IF(N37<=AT26,"1""",IF(N37<=AT27,"1-1/4""",IF(N37<=AT28,"1-1/2""",IF(N37<=AT29,"2""",IF(N37<=AT30,"2-1/2""",IF(N37<=AT31,"3""",IF(N37<=AT32,"4""",IF(N37<=AT33,"5""",IF(N37<=AT34,"6""",0)))))))))))) -> 1-1/4"
A28: 0 | C28: Water Closet (Flush Tank) | F28: =IF(Q6="heavy-use assembly",3.5,2.5) -> 2.5 | G28: 0 | H28: =IF(Q6="heavy-use assembly",3.5,2.5) -> 2.5 | I28: 1/2" | L28: =$A28*F28 -> 0 | M28: =$A28*G28 -> 0 | N28: =$A28*H28 -> 0 | Y28: 25 | Z28: 17 | AB28: 25 | AC28: 38 | AG28: 1-1/2" | AH28: 34 | AI28: 5 | AJ28: 22.2 | AK28: 1.8 | AL28: 1-1/2" | AM28: 47 | AN28: 11 | AO28: 27.7 | AP28: 2.7 | AQ28: 1-1/2" | AR28: 101 | AS28: 36 | AT28: 44.4 | AU28: 6.5
A29: 1 | C29: Water Closet (Flush Valve) | F29: =IF(Q6="heavy-use assembly",8,5) -> 5 | G29: 0 | H29: =IF(Q6="heavy-use assembly",8,5) -> 5 | I29: 1" | L29: =$A29*F29 -> 5 | M29: =$A29*G29 -> 0 | N29: =$A29*H29 -> 5 | Y29: 26 | Z29: 17.6 | AB29: 26 | AC29: 38.6 | AG29: 2" | AH29: 79 | AI29: 26 | AJ29: 38.6 | AK29: 1.3 | AL29: 2" | AM29: 117 | AN29: 43 | AO29: 48.2 | AP29: 2 | AQ29: 2" | AR29: 261 | AS29: 136 | AT29: 77.2 | AU29: 4.7 | AW29: TOTALS (HIGHER VALUE)
A30: 0 | C30: Whirlpool Bath or Combo Bath/Shower | F30: 3 | G30: 3 | H30: 4 | I30: 1/2" | L30: =$A30*F30 -> 0 | M30: =$A30*G30 -> 0 | N30: =$A30*H30 -> 0 | Y30: 27 | Z30: 18.2 | AB30: 27 | AC30: 39.2 | AG30: 2-1/2" | AH30: 173 | AI30: 73 | AJ30: 59.5 | AK30: 1 | AL30: 2-1/2" | AM30: 247 | AN30: 120 | AO30: 74.4 | AP30: 1.5 | AQ30: 2-1/2" | AR30: 470 | AS30: 360 | AT30: 119 | AU30: 3.7 | AW30: COLD | AX30: HOT | AY30: TOTAL
A31: 0 | C31: Misc(Fill-in) | F31: 5 | G31: 0 | H31: 5 | L31: =$A31*F31 -> 0 | M31: =$A31*G31 -> 0 | N31: =$A31*H31 -> 0 | Y31: 28 | Z31: 18.8 | AB31: 28 | AC31: 39.8 | AG31: 3" | AH31: 300 | AI31: 170 | AJ31: 84.9 | AK31: 0.8 | AL31: 3" | AM31: 406 | AN31: 281 | AO31: 106.2 | AP31: 1.3 | AQ31: 3" | AR31: 749 | AS31: 713 | AT31: 169.9 | AU31: 3 | AW31: =IF(AW23>0,AW23,AW27) -> 2" | AX31: =AX27 -> 1/2" | AY31: =IF(AY23>0,AY23,AY27) -> 2"
A32: 0 | C32: Misc(Fill-in) | F32: 0 | G32: 0 | H32: 0 | L32: =$A32*F32 -> 0 | M32: =$A32*G32 -> 0 | N32: =$A32*H32 -> 0 | Y32: 29 | Z32: 19.4 | AB32: 29 | AC32: 40.4 | AG32: 4" | AH32: 635 | AI32: 567 | AJ32: 149.3 | AK32: 0.6 | AL32: 4" | AM32: 854 | AN32: 833 | AO32: 186.7 | AP32: 0.9 | AQ32: 4" | AR32: 1739 | AS32: 1739 | AT32: 298.7 | AU32: 2.2
A33: 0 | C33: Misc(Fill-in) | F33: 0 | G33: 0 | H33: 0 | L33: =$A33*F33 -> 0 | M33: =$A33*G33 -> 0 | N33: =$A33*H33 -> 0 | Y33: 30 | Z33: 20 | AB33: 30 | AC33: 41 | AG33: 5" | AH33: 1189 | AI33: 1189 | AJ33: 232.7 | AK33: 0.5 | AL33: 5" | AM33: 1674 | AN33: 1674 | AO33: 290.9 | AP33: 0.7 | AQ33: 5" | AR33: 3338 | AS33: 3338 | AT33: 465.5 | AU33: 1.7
A34: 0 | C34: Misc(Fill-in) | F34: 0 | G34: 0 | H34: 0 | L34: 0 | M34: 0 | N34: 0 | Y34: 31 | Z34: 20.5 | AB34: 31 | AC34: 41.6 | AG34: 6" | AH34: 2087 | AI34: 2087 | AJ34: 334.6 | AK34: 0.4 | AL34: 6" | AM34: 2847 | AN34: 2874 | AO34: 418.2 | AP34: 0.6 | AQ34: 6" | AR34: 6382 | AS34: 6382 | AT34: 669.1 | AU34: 1.4
A35: 0 | C35: Misc(Fill-in) | F35: 0 | G35: 0 | H35: 0 | L35: 0 | M35: 0 | N35: 0 | Y35: 32 | Z35: 21 | AB35: 32 | AC35: 42.2
I36: Total Fixture Units (WSFU) | L36: =SUM(L9:L35) -> 14.1 | M36: =SUM(M9:M35) -> 1.6 | N36: =SUM(N9:N35) -> 14.5 | Y36: 33 | Z36: 21.5 | AB36: 33 | AC36: 42.8 | AG36: TABLE B.7.3.D - TYPE M COPPER
I37: Gallons per Minute (GPM) | L37: =SUM(U4+U7) -> 29.5 | M37: =SUM(V4+V7) -> 1 | N37: =SUM(W4+W7) -> 29.5 | O37: *LIMITED TO 1,000 WSFU (See Appendix K for greater than 1,000 WSFU) | Y37: 34 | Z37: 22 | AB37: 34 | AC37: 43.4 | AG37: PIPE SIZE | AH37: 4 FPS VELOCITY | AL37: PIPE SIZE | AM37: 5 FPS VELOCITY (Hot Water) | AQ37: PIPE SIZE | AR37: 8 FPS VELOCITY | AW37: 4 FPS (F.V.) (PER GPM)
Y38: 35 | Z38: 22.5 | AB38: 35 | AC38: 44 | AH38: WSFU (TANK) | AI38: WSFU (VALVE) | AJ38: FLOW (GPM) | AK38: PSI/100FT | AM38: WSFU (TANK) | AN38: WSFU (VALVE) | AO38: FLOW (GPM) | AP38: PSI/100FT | AR38: WSFU (TANK) | AS38: WSFU (VALVE) | AT38: FLOW (GPM) | AU38: PSI/100FT | AW38: COLD | AY38: TOTAL
Y39: 36 | Z39: 23 | AB39: 36 | AC39: 44.6 | AG39: 3/8" | AJ39: 2 | AK39: 7.3 | AL39: 3/8" | AO39: 2.5 | AP39: 11.1 | AQ39: 3/8" | AR39: 4 | AT39: 4 | AU39: 26.6 | AW39: =IF(U7=0,0,IF(L37=0,0,IF(L37<=AJ40,"1/2""",IF(L37<=AJ41,"3/4""",IF(L37<=AJ42,"1""",IF(L37<=AJ43,"1-1/4""",IF(L37<=AJ44,"1-1/2""",IF(L37<=AJ45,"2""",IF(L37<=AJ46,"2-1/2""",IF(L37<=AJ47,"3""",IF(L37<=AJ48,"4""",IF(L37<=AJ49,"5""",IF(L37<=AJ50,"6""",0))))))))))))) -> 2" | AX39: 0 | AY39: =IF(W7=0,0,IF(N37<=AJ40,"1/2""",IF(N37<=AJ41,"3/4""",IF(N37<=AJ42,"1""",IF(N37<=AJ43,"1-1/4""",IF(N37<=AJ44,"1-1/2""",IF(N37<=AJ45,"2""",IF(N37<=AJ46,"2-1/2""",IF(N37<=AJ47,"3""",IF(N37<=AJ48,"4""",IF(N37<=AJ49,"5""",IF(N37<=AJ50,"6""",0)))))))))))) -> 2"
A40: =IF(U7>0,"Based on 4 FPS Velocity","Based on 8 FPS Velocity") -> Based on 4 FPS Velocity | E40: =IF(OR(Q9="type k copper",Q9="type l copper",Q9="type m copper"),"Based on 5 FPS Velocity","Based on 8 FPS Velocity") -> Based on 8 FPS Velocity | Y40: 37 | Z40: 23.5 | AB40: 37 | AC40: 45.2 | AG40: 1/2" | AH40: 3 | AJ40: 3.2 | AK40: 5.6 | AL40: 1/2" | AM40: 4 | AO40: 4 | AP40: 8.5 | AQ40: 1/2" | AR40: 7 | AT40: 6.3 | AU40: 20.2
...

Sheet Waste (NSPC) (NJ)
D1: SERIAL NUMBER:
A4: WASTE MAIN TRUNK SIZE (National Plumbing Code Standard)
A5: Table 11.4.1 (FU), Table 11.5.1B, Table 11.5.7, Table 12.16.4, Table 12.16.6, Section 12.16.8(b)
Q6: Building Use: | R6: Other than Dwelling Units
A7: Quantity | C7: Description | H7: Fixture Units | K7: Min. Trap Size | M7: Min. Drain Size | O7: Total
A8: 0 | C8: Bathtub or Bath/Shower | H8: 2 | J8: = | K8: 1-1/2" | M8: 1-1/2" | O8: =H8*A8 -> 0
A9: 0 | C9: Bidet | H9: 1 | J9: = | K9: 1-1/4" | M9: 1-1/4" | O9: =H9*A9 -> 0
A10: 0 | C10: Clothes Washer (Domestic) | H10: 3 | J10: = | K10: 2" | M10: 2" | O10: =H10*A10 -> 0
A11: 0 | C11: Drinking Fountain / Water Cooler | H11: 0.5 | J11: = | K11: 1-1/4" | M11: 1-1/4" | O11: =H11*A11 -> 0
A12: 0 | C12: Drinking Fountain / Water Station | H12: 1 | J12: = | K12: 1-1/4" | M12: 1-1/4" | O12: =H12*A12 -> 0
A13: 0 | C13: Floor Drain | H13: 0 | J13: = | K13: Varies | M13: Varies | O13: =H13*A13 -> 0
A14: 0 | C14: Food Waste Disposer | H14: 3 | J14: = | K14: 2" | M14: 2" | O14: =H14*A14 -> 0
A15: 0 | C15: Kitchen Sink (Domestic) | H15: 2 | J15: = | K15: 1-1/2" | M15: 1-1/2" | O15: =H15*A15 -> 0
A16: 0 | C16: Kitchen Sink (Domestic with Disposer) | H16: 2 | J16: = | K16: 1-1/2" | M16: 1-1/2" | O16: =H16*A16 -> 0
A17: 0 | C17: Kitchen Sink (Domestic with Dishwasher) | H17: 3 | J17: = | K17: 1-1/2" | M17: 1-1/2" | O17: =H17*A17 -> 0
A18: 0 | C18: Kitchen Sink (Domestic with Dishwasher & Disposer) | H18: 3 | J18: = | K18: 1-1/2" | M18: 1-1/2" | O18: =H18*A18 -> 0
A19: 0 | C19: Laundry Sink (1 or 2 Compartment) | H19: 2 | J19: = | K19: 1-1/2" | M19: 1-1/2" | O19: =H19*A19 -> 0
... A23: 0 | C23: Shower (Single) | H23: 2 | J23: = | K23: 1-1/2" | M23: 1-1/2" | O23: =H23*A23 -> 0
A24: 0 | C24: Shower (Multiple Heads) - Enter # of Heads | H24: =IF(A24=1,2,IF(A24=2,5,IF(A24=3,12,IF(A24=4,18,IF(A24=5,22,IF(A24=6,25,IF(A24=7,30,IF(A24=8,35,0)))))))) -> 0 | J24: = | K24: =IF(A24<=4,"2""","3""") -> 2" | M24: =IF(A24<=4,"2""","3""") -> 2"
A25: 0 | C25: Sink (1-1/2" Trap) | H25: 2 | J25: = | K25: 1-1/2" | M25: 1-1/2" | O25: =H25*A25 -> 0
A26: 0 | C26: Sink (2" Trap) | H26: 3 | J26: = | K26: 2" | M26: 2" | O26: =H26*A26 -> 0
A27: 0 | C27: Sink (3" Trap) | H27: 5 | J27: = | K27: 3" | M27: 3" | O27: =H27*A27 -> 0
A28: 0 | C28: Urinal (1.0 GPF) | H28: =IF(R6="heavy-use assembly",5,4) -> 4 | J28: = | K28: Integral | M28: 2" | O28: =H28*A28 -> 0
A29: 0 | C29: Urinal (greater than 1.0 GPF) | H29: =IF(R6="heavy-use assembly",6,5) -> 5 | J29: = | K29: Integral | M29: 2" | O29: =H29*A29 -> 0
A30: 0 | C30: Wash Fountain (1-1/2" Trap) | H30: 2 | J30: = | K30: 1-1/2" | M30: 1-1/2" | O30: =H30*A30 -> 0
A31: 0 | C31: Wash Fountain (2" Trap) | H31: 3 | J31: = | K31: 2" | M31: 2" | O31: =H31*A31 -> 0
A32: 0 | C32: Wash Sink (1-1/2" Trap) | H32: 2 | J32: = | K32: 1-1/2" | M32: 1-1/2" | O32: =H32*A32 -> 0
A33: 0 | C33: Toilet (Tank or Gravity type) | H33: =IF(OR(R6="Individual Dwelling Units",R6="Serving 3 or More Dwelling Units"),3,IF(R6="heavy-use assembly",6,4)) -> 4 | J33: = | K33: Integral | M33: 3"
A34: 0 | C34: Toilet (Flush Valve) | H34: =IF(OR(R6="Individual Dwelling Units",R6="Serving 3 or More Dwelling Units"),3,IF(R6="heavy-use assembly",6,4)) -> 4 | J34: = | K34: Integral | M34: 3"
A35: 0 | C35: Whirlpool Bath or Comb. Bath / Shower | H35: 2 | J35: = | K35: 1-1/2" | M35: 1-1/2"
A36: 0 | C36: Misc (1-1/4" or less) | H36: 1 | J36: = | K36: 1-1/4" | M36: 1-1/4" | O36: =H36*A36 -> 0
A37: 0 | C37: Misc (1-1/2") | H37: 2 | J37: = | K37: 1-1/2" | M37: 1-1/2" | O37: =H37*A37 -> 0
A38: 0 | C38: Misc (2") | H38: 3 | J38: = | K38: 2" | M38: 2" | O38: =H38*A38 -> 0
A39: 0 | C39: Misc (3") | H39: 5 | J39: = | K39: 3" | M39: 3" | O39: =H39*A39 -> 0
A40: 0 | C40: Misc (4") | H40: 6 | J40: = | K40: 4" | M40: 4" | O40: =H40*A40 -> 0
K41: Total Fixture Units | N41: = | O41: =SUM(O8:O40) -> 0
K42: Min. Vent Size @ Branch | N42: = | O42: =IF(O41=0,0,IF(AND(O41<=20,Q42="no"),"1-1/2""",IF(AND(O41<=160,Q42="no"),"2""",IF(AND(O41<=360,Q42="no"),"3""",IF(AND(O41<=1400,Q42="no"),"4""",IF(AND(O41<=2500,Q42="no"),"5""",IF(AND(O41<=3900,Q42="no"),"6""",IF(AND(O41<=7000,Q42="no"),"8""",IF(AND(O41<=6,Q42="yes"),"1-1/2""",IF(AND(O41<=20,Q42="yes"),"2""",IF(AND(O41<=160,Q42="yes"),"3""",IF(AND(O41<=620,Q42="yes"),"4""",IF(AND(O41<=1400,Q42="yes"),"5""",IF(AND(O41<=2500,Q42="yes"),"6""",IF(AND(O41<=3900,Q42="yes"),"8""",IF(AND(O41<=7000,Q42="yes"),"10""")))))))))))))))) -> 0 | Q42: No | R42: <-- Is total deveoped length of vent pipe greater than 40?:
K43: Main Trunk Size | N43: = | O43: =IF(SUM(A28+A29+A33+A34>=4),4,IF(O41<=3,1.5,IF(O41<=6,2,IF(O41<=20,3,IF(O41<=160,4,IF(O41<=360,5,IF(O41<=620,6,IF(O41<=1260,8,IF(O41<=2250,10,IF(O41<=3500,12,IF(O41<=6300,15))))))))))) -> 1.5
A47: *Minimum size of any building drain serving a water closet shall be 3"
A49: **4 or more water closets/urinals require a minimum of 4"
...

Sheet Supply (ISPC) (IL)
D1: SERIAL NUMBER:
U2: TANK TYPE (GPM)
U3: Cold | V3: Hot | W3: Total | Y3: WSFU | Z3: GPM (Tanks) | AA3: Pipe Size | AC3: WSFU | AD3: GPM (Valve) | AE3: Pipe Size
A4: INLET PIPE SIZING CHART (Illinois State Plumbing Code) | U4: =IF(SUM(L9+L10+L11+L12+L13+L14+L15+L16+L17+L18+L21+L22+L24+L25+L26+L27+L28)=0,0,IF(SUM(L9+L10+L11+L12+L13+L14+L15+L16+L17+L18+L21+L22+L24+L25+L26+L27+L28)<=2,2,ROUNDUP(INDEX(Z4:Z43,MATCH(SUM(L9+L10+L11+L12+L13+L14+L15+L16+L17+L18+L21+L22+L24+L25+L26+L27+L28),Y4:Y43,1)),1))) -> 2 | V4: =IF(SUM(M9+M10+M11+M12+M13+M14+M15+M16+M17+M18+M21+M22+M24+M25+M26+M27+M28)=0,0,IF(SUM(M9+M10+M11+M12+M13+M14+M15+M16+M17+M18+M21+M22+M24+M25+M26+M27+M28)<=2,2,ROUNDUP(INDEX(Z4:Z43,MATCH(SUM(M9+M10+M11+M12+M13+M14+M15+M16+M17+M18+M21+M22+M24+M25+M26+M27+M28),Y4:Y43,1)),1))) -> 2 | W4: =IF(SUM(N9+N10+N11+N12+N13+N14+N15+N16+N17+N18+N21+N22+N24+N25+N26+N27+N28)=0,0,IF(SUM(N9+N10+N11+N12+N13+N14+N15+N16+N17+N18+N21+N22+N24+N25+N26+N27+N28)<=2,2,ROUNDUP(INDEX(Z4:Z43,MATCH(SUM(N9+N10+N11+N12+N13+N14+N15+N16+N17+N18+N21+N22+N24+N25+N26+N27+N28),Y4:Y43,1)),1))) -> 2 | Y4: 2 | Z4: 2 | AA4: 1/2"
A5: *Based on Section 890.APPENDIX A, Tables M, N, and O | Y5: 4 | Z5: 3 | AA5: 1/2"
U6: FLUSH VALVE (GPM) | Y6: 6 | Z6: 5 | AA6: 1/2"
A7: Quantity | C7: Description | F7: Fixture Units (WSFU) | I7: Minimum Pipe Size | L7: Fixture Units (WSFU) | U7: =IF(SUM(L19+L20+L23)=0,0,ROUNDUP(INDEX(AD7:AD43,MATCH(SUM(L19+L20+L23),AC7:AC43,1)),1)) -> 0 | V7: 0 | W7: =IF(SUM(N19+N20+N23)=0,0,ROUNDUP(INDEX(AD7:AD43,MATCH(SUM(N19+N20+N23),AC7:AC43,1)),1)) -> 0 | Y7: 8 | Z7: 6.5 | AA7: 3/4" | AC7: 5 | AD7: 24 | AE7: 1"
F8: Cold | G8: Hot | H8: Total | L8: Cold | M8: Hot | N8: Total | Y8: 10 | Z8: 8 | AA8: 3/4" | AC8: 10 | AD8: 27 | AE8: 1-1/4"
A9: 0 | C9: Bathtub (Private) | F9: 1.5 | G9: 1.5 | H9: 2 | I9: 1/2" | L9: =$A9*F9 -> 0 | M9: =$A9*G9 -> 0 | N9: =$A9*H9 -> 0 | U9: SIZE | Y9: 12 | Z9: 9.2 | AA9: 3/4" | AC9: 12 | AD9: 28.6 | AE9: 1-1/4"
A10: 0 | C10: Bathtub (Public) | F10: 3 | G10: 3 | H10: 4 | I10: 1/2" | L10: =$A10*F10 -> 0 | M10: =$A10*G10 -> 0 | N10: =$A10*H10 -> 0 | U10: =IF(AND(U7>=5,L29<=AC11),AE11,IF(AND(U7>=5,L29<=AC15),AE15,IF(AND(U7>=5,L29<=AC25),AE25,IF(AND(U7>=5,L29<=AC32),AE32,IF(AND(U7>=5,L29<=AC38),AE38,IF(AND(U7>=5,L29<=AC42),AE42,IF(AND(U7>=5,L29<=AC43),AE43,IF(L29<=Y6,AA6,IF(L29<=Y11,AA11,IF(L29<=Y14,AA14,IF(L29<=Y18,AA18,IF(L29<=Y23,AA23,IF(L29<=Y30,AA30,IF(L29<=Y35,AA35,IF(L29<=Y38,AA38,IF(L29<=Y42,AA42,IF(L29<=Y43,AA43,0))))))))))))))))) -> 1/2" | V10: =IF(AND(U7>=5,M29<=AC11),AE11,IF(AND(U7>=5,M29<=AC15),AE15,IF(AND(U7>=5,M29<=AC25),AE25,IF(AND(U7>=5,M29<=AC32),AE32,IF(AND(U7>=5,M29<=AC38),AE38,IF(AND(U7>=5,M29<=AC42),AE42,IF(AND(U7>=5,M29<=AC43),AE43,IF(M29<=Y6,AA6,IF(M29<=Y11,AA11,IF(M29<=Y14,AA14,IF(M29<=Y18,AA18,IF(M29<=Y23,AA23,IF(M29<=Y30,AA30,IF(M29<=Y35,AA35,IF(M29<=Y38,AA38,IF(M29<=Y42,AA42,IF(M29<=Y43,AA43,0))))))))))))))))) -> 1/2" | W10: =IF(AND(U7>=5,N29<=AC11),AE11,IF(AND(U7>=5,N29<=AC15),AE15,IF(AND(U7>=5,N29<=AC25),AE25,IF(AND(U7>=5,N29<=AC32),AE32,IF(AND(U7>=5,N29<=AC38),AE38,IF(AND(U7>=5,N29<=AC42),AE42,IF(AND(U7>=5,N29<=AC43),AE43,IF(N29<=Y11,AA11,IF(N29<=Y14,AA14,IF(N29<=Y18,AA18,IF(N29<=Y23,AA23,IF(N29<=Y30,AA30,IF(N29<=Y35,AA35,IF(N29<=Y38,AA38,IF(N29<=Y42,AA42,IF(N29<=Y43,AA43,0)))))))))))))))) -> 3/4" | Y10: 14 | Z10: 10.4 | AA10: 3/4" | AC10: 14 | AD10: 30.2 | AE10: 1-1/4"
A11: 0 | C11: Dish Washer | F11: 0 | G11: 1.4 | H11: 1.4 | I11: 1/2" | L11: =$A11*F11 -> 0 | M11: =$A11*G11 -> 0 | N11: =$A11*H11 -> 0 | Y11: 16 | Z11: 11.6 | AA11: 3/4" | AC11: 16 | AD11: 31.8 | AE11: 1-1/4"
A12: 0 | C12: Drinking Fountain | F12: 0.25 | G12: 0 | H12: 0.25 | I12: 3/8" | L12: =$A12*F12 -> 0 | M12: =$A12*G12 -> 0 | N12: =$A12*H12 -> 0 | Y12: 20 | Z12: 14 | AA12: 1" | AC12: 20 | AD12: 35 | AE12: 1-1/2"
A13: 0 | C13: Kitchen Sink(Private) | F13: 1.5 | G13: 1.5 | H13: 2 | I13: 1/2" | L13: =$A13*F13 -> 0 | M13: =$A13*G13 -> 0 | N13: =$A13*H13 -> 0 | Y13: 25 | Z13: 17 | AA13: 1" | AC13: 25 | AD13: 38 | AE13: 1-1/2"
A14: 0 | C14: Kitchen Sink(Hotel/Resta) | F14: 3 | G14: 3 | H14: 4 | I14: 1/2" | L14: =$A14*F14 -> 0 | M14: =$A14*G14 -> 0 | N14: =$A14*H14 -> 0 | Y14: 30 | Z14: 20 | AA14: 1" | AC14: 30 | AD14: 41 | AE14: 1-1/2"
A15: 1 | C15: Lavatory(Private) | F15: 0.75 | G15: 0.75 | H15: 1 | I15: 3/8" | L15: =$A15*F15 -> 0.75 | M15: =$A15*G15 -> 0.75 | N15: =$A15*H15 -> 1 | Y15: 35 | Z15: 22.5 | AA15: 1-1/4" | AC15: 35 | AD15: 43.8 | AE15: 1-1/2"
A16: 0 | C16: Lavatory(Public) | F16: 1 | G16: 1 | H16: 2 | I16: 3/8" | L16: =$A16*F16 -> 0 | M16: =$A16*G16 -> 0 | N16: =$A16*H16 -> 0 | Y16: 40 | Z16: 25 | AA16: 1-1/4" | AC16: 40 | AD16: 46.5 | AE16: 2"
A17: 0 | C17: Service Sink | F17: 2 | G17: 2 | H17: 3 | I17: 1/2" | L17: =$A17*F17 -> 0 | M17: =$A17*G17 -> 0 | N17: =$A17*H17 -> 0 | Y17: 45 | Z17: 27 | AA17: 1-1/4" | AC17: 45 | AD17: 49 | AE17: 2"
A18: 0 | C18: Shower Head(Public) | F18: 2 | G18: 2 | H18: 3 | I18: 1/2" | L18: =$A18*F18 -> 0 | M18: =$A18*G18 -> 0 | N18: =$A18*H18 -> 0 | Y18: 50 | Z18: 29 | AA18: 1-1/4" | AC18: 50 | AD18: 51.5 | AE18: 2"
A19: 0 | C19: Urinal(3/4" valve) | F19: 5 | G19: 0 | H19: 5 | I19: 3/4" | L19: =$A19*F19 -> 0 | M19: =$A19*G19 -> 0 | N19: =$A19*H19 -> 0 | Y19: 60 | Z19: 32 | AA19: 1-1/2" | AC19: 60 | AD19: 55 | AE19: 2"
A20: 0 | C20: Urinal(1" valve) | F20: 10 | G20: 0 | H20: 10 | I20: 1" | L20: =$A20*F20 -> 0 | M20: =$A20*G20 -> 0 | N20: =$A20*H20 -> 0 | Y20: 70 | Z20: 35 | AA20: 1-1/2" | AC20: 70 | AD20: 58.5 | AE20: 2"
A21: 0 | C21: Washing Machine(Private 8#) | F21: 1.5 | G21: 1.5 | H21: 2 | I21: 1/2" | L21: =$A21*F21 -> 0 | M21: =$A21*G21 -> 0 | N21: =$A21*H21 -> 0 | Y21: 80 | Z21: 38 | AA21: 1-1/2" | AC21: 80 | AD21: 62 | AE21: 2"
A22: 0 | C22: Washing Machine(Pub 15#) | F22: 3 | G22: 3 | H22: 4 | I22: 1/2" | L22: =$A22*F22 -> 0 | M22: =$A22*G22 -> 0 | N22: =$A22*H22 -> 0 | Y22: 90 | Z22: 41 | AA22: 1-1/2" | AC22: 90 | AD22: 64.8 | AE22: 2"
... A26: 0 | C26: Hose Bib (Assumed) | F26: 3 | G26: 0 | H26: 4 | I26: 1/2" | L26: =$A26*F26 -> 0 | M26: =$A26*G26 -> 0 | N26: =$A26*H26 -> 0 | Y26: 160 | Z26: 57 | AA26: 2" | AC26: 160 | AD26: 82.5 | AE26: 2-1/2"
A27: 0 | C27: Misc(Fill-in) | F27: 0 | G27: 0 | H27: 0 | L27: =$A27*F27 -> 0 | M27: =$A27*G27 -> 0 | N27: =$A27*H27 -> 0 | Y27: 180 | Z27: 61 | AA27: 2" | AC27: 180 | AD27: 87 | AE27: 2-1/2"
A28: 0 | C28: Misc(Fill-in) | F28: 0 | G28: 0 | H28: 0 | L28: =$A28*F28 -> 0 | M28: =$A28*G28 -> 0 | N28: =$A28*H28 -> 0 | O28: *LIMITED TO 2,000 WSFU | Y28: 200 | Z28: 65 | AA28: 2" | AC28: 200 | AD28: 91.5 | AE28: 2-1/2"
I29: Total Fixture Units (WSFU) | L29: =SUM(L9:L28) -> 0.75 | M29: =SUM(M9:M28) -> 0.75 | N29: =SUM(N9:N28) -> 1 | Y29: 225 | Z29: 70 | AA29: 2" | AC29: 225 | AD29: 97 | AE29: 2-1/2"
