Workbook

Sheet Occupant Calculator
A1: CBC Section 1004 / IBC Section 1004
A2: Occupancy Use: | B2: Occupant Load Factor: | C2: Square Footage: | D2: # Of Persons
A3: Accesory Storage, Mechanical Equipment | B3: 300 Gross | C3: 0 | D3: =ROUNDUP((C3/300),0) -> 0 | F3: Note:
A4: Airport Terminal (Baggage Claim) | B4: 20 Gross | C4: 0 | D4: =ROUNDUP((C4/20),0) -> 0 | F4: Gross: overall area (including walls)
A5: Airport Terminal (Baggage Handling) | B5: 300 Gross | C5: 0 | D5: =ROUNDUP((C5/300),0) -> 0 | F5: Net: actual wall-to-wall square footage
A6: Airport Terminal (Concourse) | B6: 100 Gross | C6: 0 | D6: =ROUNDUP((C6/100),0) -> 0
A7: Airport Terminal (Waiting Areas) | B7: 15 Gross | C7: 0 | D7: =ROUNDUP((C7/15),0) -> 0
A8: Assembly (Casino) | B8: 11 Gross | C8: 0 | D8: =ROUNDUP((C8/11),0) -> 0
A9: Assembly (With Tables & Chairs) | B9: 15 Net | C9: 0 | D9: =ROUNDUP((C9/15),0) -> 0 | E9: <--- Use for Conference Rooms & Break Rooms
A10: Assembly (Concentrated) | B10: 7 Net | C10: 0 | D10: =ROUNDUP((C10/7),0) -> 0
A11: Assembly (Standing) | B11: 5 Net | C11: 0 | D11: =ROUNDUP((C11/5),0) -> 0
A12: Business (2006 - 2015 IBC) | B12: 100 Gross | C12: 0 | D12: =ROUNDUP((C12/100),0) -> 0
A13: Business (2018-2024 IBC & 2025 CBC) | B13: 150 Gross | C13: 0 | D13: =ROUNDUP((C13/150),0) -> 0
A14: Courtrooms | B14: 40 Net | C14: 0 | D14: =ROUNDUP((C14/40),0) -> 0
A15: Day Care | B15: 35 Net | C15: 0 | D15: =ROUNDUP((C15/35),0) -> 0
A16: Dormatories | B16: 50 Gross | C16: 0 | D16: =ROUNDUP((C16/50),0) -> 0
A17: Educational (Includes Adult Education) | B17: 20 Net | C17: 0 | D17: =ROUNDUP((C17/20),0) -> 0
A18: Educational (Shops or Vocational areas) | B18: 50 Net | C18: 0 | D18: =ROUNDUP((C18/50),0) -> 0
A19: Exercise Rooms | B19: 50 Gross | C19: 0 | D19: =ROUNDUP((C19/50),0) -> 0
A20: Institutional (Inpatient) | B20: 240 Gross | C20: 0 | D20: =ROUNDUP((C20/240),0) -> 0
A21: Institutional (Outpatient) | B21: 100 Gross | C21: 0 | D21: =ROUNDUP((C21/100),0) -> 0
A22: Institutional (Sleeping Areas) | B22: 120 Gross | C22: 0 | D22: =ROUNDUP((C22/120),0) -> 0
A23: Commercial Kitchens | B23: 200 Gross | C23: 0 | D23: =ROUNDUP((C23/200),0) -> 0
A24: Lab (Educational) | B24: 50 Net | C24: 0 | D24: =ROUNDUP((C24/50),0) -> 0
A25: Lab (Non-Educational) | B25: 100 Net | C25: 0 | D25: =ROUNDUP((C25/100),0) -> 0
A26: Library (Reading Rm) | B26: 50 Net | C26: 0 | D26: =ROUNDUP((C26/50),0) -> 0
A27: Library (Stack Areas) | B27: 100 Gross | C27: 0 | D27: =ROUNDUP((C27/100),0) -> 0
A28: Locker Rooms | B28: 50 Gross | C28: 0 | D28: =ROUNDUP((C28/50),0) -> 0
A29: Mercantile | B29: 60 Gross | C29: 0 | D29: =ROUNDUP((C29/60),0) -> 0
A30: Mercantile (Storage, Stock) | B30: 300 Gross | C30: 0 | D30: =ROUNDUP((C30/300),0) -> 0
A31: Residential | B31: 200 Gross | C31: 0 | D31: =ROUNDUP((C31/200),0) -> 0
A32: Stage and Platforms | B32: 15 Net | C32: 0 | D32: =ROUNDUP((C32/15),0) -> 0
A33: Warehouses | B33: 500 Gross | C33: 0 | D33: =ROUNDUP((C33/500),0) -> 0
B34: TOTAL # OF OCCUPANTS: | D34: =SUM(D3:D33) -> 0

Sheet 2009 - 2015 IPC
A1: Classification: | C1: Occupancy: | D1: Description: | F1: Water Closets: | H1: Urinals: | I1: Lavatories: | K1: Bathtubs / Showers: | L1: Drinking Fountain: | M1: Other: | N1: Manual Occupant Load Override: | W1: WATER CLOSETS | Y1: LAVATORIES | AA1: fountain | AB1: shower
F2: Male: | G2: Female: | I2: Male: | J2: Female: | N2: Male: | O2: Female: | W2: 2009 - 2021 IPC | X2: 2009 - 2021 IPC | Y2: 2009 - 2021 IPC | Z2: 2009 - 2021 IPC | AA2: 2021 - 2021 IPC | AB2: 2021 - 2021 IPC
A3: Assembly | C3: A-1 | D3: Theaters and other buildings for the performing arts and motion pictures | F3: =IF(AND(OR(N3>0,O3>0),N3+O3<=15),"Single restroom okay for 15 or less (IPC 403.2(2))",IF(AND(OR(N3>0,O3>0),N3+O3>Q5),W4,IF(AND(OR(N3>0,O3>0),N3+O3<Q5),W4,IF(Q5<=15,"Single restroom okay for 15 or less (IPC 403.2(2))",W4)))) -> Single restroom okay for 15 or less (IPC 403.2(2)) | G3: =IF(F3="Single restroom okay for 15 or less (IPC 403.2(2))","-",X4) -> - | H3: Can substitute up to 67% of required fixtures (IPC 419.2) | I3: =Y4 -> 0 | J3: =IF(F3="Single restroom okay for 15 or less (IPC 403.2(2))","-",Z4) -> - | K3: - | L3: =IF(F3="Single restroom okay for 15 or less (IPC 403.2(2))","15 or less Fountain exempt(IPC 410.2)",AA4) -> 15 or less Fountain exempt(IPC 410.2) | M3: 1 service sink | N3: 0 | O3: =N3 -> 0 | Q3: Total Occupant Load: | W3: male | X3: female | Y3: male | Z3: female | AA3: fountain | AB3: shower
U4: Theater | V4: a-1 | W4: =IF(N3>0,ROUNDUP((N3/125),0),ROUNDUP((Q8/125),0)) -> 0 | X4: =IF(O3>0,ROUNDUP((O3/65),0),ROUNDUP((R8/65),0)) -> 0 | Y4: =IF(N3>0,ROUNDUP((N3/200),0),ROUNDUP((Q8/200),0)) -> 0 | Z4: =IF(O3>0,ROUNDUP((O3/200),0),ROUNDUP((R8/200),0)) -> 0 | AA4: =IF(OR(N3>0,O3>0),ROUNDUP((N3+O3)/500,0),ROUNDUP(Q5/500,0)) -> 0 | AB4: -
Q5: ='Occupant Calculator'!D34 -> 0 | U5: night clubs | V5: a-2 | W5: =IF(N9>0,ROUNDUP((N9/40),0),ROUNDUP((Q8/40),0)) -> 0 | X5: =IF(O9>0,ROUNDUP((O9/40),0),ROUNDUP((R8/40),0)) -> 0 | Y5: =IF(N9>0,ROUNDUP((N9/75),0),ROUNDUP((Q8/75),0)) -> 0 | Z5: =IF(O9>0,ROUNDUP((O9/75),0),ROUNDUP((R8/75),0)) -> 0 | AA5: =IF(OR(N9>0,O9>0),ROUNDUP((N9+O9)/500,0),ROUNDUP(Q5/500,0)) -> 0 | AB5: -
U6: restaurants | V6: a-2 | W6: =IF(N15>0,ROUNDUP((N15/75),0),ROUNDUP((Q8/75),0)) -> 0 | X6: =IF(O15>0,ROUNDUP((O15/75),0),ROUNDUP((R8/75),0)) -> 0 | Y6: =IF(N15>0,ROUNDUP((N15/200),0),ROUNDUP((Q8/200),0)) -> 0 | Z6: =IF(O15>0,ROUNDUP((O15/200),0),ROUNDUP((R8/200),0)) -> 0 | AA6: =IF(OR(N15>0,O15>0),ROUNDUP((N15+O15)/500,0),ROUNDUP(Q5/500,0)) -> 0 | AB6: -
Q7: Male: | R7: Female: | U7: auditoriums | V7: a-3 | W7: =IF(N21>0,ROUNDUP((N21/125),0),ROUNDUP((Q8/125),0)) -> 0 | X7: =IF(O21>0,ROUNDUP((O21/65),0),ROUNDUP((R8/65),0)) -> 0 | Y7: =IF(N21>0,ROUNDUP((N21/200),0),ROUNDUP((Q8/200),0)) -> 0 | Z7: =IF(O21>0,ROUNDUP((O21/200),0),ROUNDUP((R8/200),0)) -> 0 | AA7: =IF(OR(N21>0,O21>0),ROUNDUP((N21+O21)/500,0),ROUNDUP(Q5/500,0)) -> 0 | AB7: -
Q8: =ROUNDUP((Q5/2),1) -> 0 | R8: =ROUNDUP((Q5/2),1) -> 0 | U8: casinos | V8: a-3 | W8: =IF(AND(N31>0,N31<=400),(ROUNDUP(N31/100,0)),IF(N31>400,(ROUNDUP(N31/250,0))+3,IF(AND(Q8>0,Q8<=400),(ROUNDUP(Q8/100,0)),IF(Q8>400,(ROUNDUP(Q8/250,0))+3,0)))) -> 0 | X8: =IF(AND(O31>0,O31<=400),(ROUNDUP(O31/50,0)),IF(O31>400,(ROUNDUP(O31/150,0))+5,IF(AND(R8>0,R8<=400),(ROUNDUP(R8/50,0)),IF(R8>400,(ROUNDUP(R8/150,0))+5,0)))) -> 0 | Y8: =IF(AND(N31>0,N31<=250),1,IF(AND(N31>250,N31<=500),2,IF(AND(N31>500,N31<=750),3,IF(N31>750,(ROUNDUP(N31/500,0)+2),IF(AND(Q8>0,Q8<=250),1,IF(AND(Q8>250,Q8<=500),2,IF(AND(Q8>500,Q8<=750),3,IF(Q8>750,(ROUNDUP(Q8/500,0)+2),0)))))))) -> 0 | Z8: =IF(AND(O31>0,O31<=250),1,IF(AND(O31>250,O31<=500),2,IF(AND(O31>500,O31<=750),3,IF(O31>750,(ROUNDUP(O31/500,0)+2),IF(AND(R8>0,R8<=250),1,IF(AND(R8>250,R8<=500),2,IF(AND(R8>500,R8<=750),3,IF(R8>750,(ROUNDUP(R8/500,0)+2),0)))))))) -> 0 | AA8: =IF(OR(N31>0,O31>0),ROUNDUP((N31+O31)/1000,0),ROUNDUP(Q5/1000,0)) -> 0 | AB8: -
C9: A-2 | D9: Nightclubs, bars, taverns, dance halls, and buildings for similar purposes | F9: =IF(AND(OR(N9>0,O9>0),N9+O9<=15),"Single restroom okay for 15 or less (IPC 403.2(2))",IF(AND(OR(N9>0,O9>0),N9+O9>Q5),W5,IF(AND(OR(N9>0,O9>0),N9+O9<Q5),W5,IF(Q5<=15,"Single restroom okay for 15 or less (IPC 403.2(2))",W5)))) -> Single restroom okay for 15 or less (IPC 403.2(2)) | G9: =IF(F9="Single restroom okay for 15 or less (IPC 403.2(2))","-",X5) -> - | H9: Can substitute up to 67% of required fixtures (IPC 419.2) | I9: =Y5 -> 0 | J9: =IF(F9="Single restroom okay for 15 or less (IPC 403.2(2))","-",Z5) -> - | K9: - | L9: =IF(F9="Single restroom okay for 15 or less (IPC 403.2(2))","15 or less Fountain exempt(IPC 410.2)",AA5) -> 15 or less Fountain exempt(IPC 410.2) | M9: 1 service sink | N9: 0 | O9: =N9 -> 0 | U9: passenger terminal | V9: a-3 | W9: =IF(N37>0,ROUNDUP((N37/50),0),ROUNDUP((Q8/500),0)) -> 0 | X9: =ROUNDUP((R8/500),0) -> 0 | Y9: =IF(N37>0,ROUNDUP((N37/750),0),ROUNDUP((Q8/750),0)) -> 0 | Z9: =IF(O37>0,ROUNDUP((O37/750),0),ROUNDUP((R8/750),0)) -> 0 | AA9: =IF(OR(N37>0,O37>0),ROUNDUP((N37+O37)/1000,0),ROUNDUP(Q5/1000,0)) -> 0 | AB9: -
U10: religious | V10: a-3 | W10: =IF(N43>0,ROUNDUP((N43/150),0),ROUNDUP((Q8/150),0)) -> 0 | X10: =ROUNDUP((R8/75),0) -> 0 | Y10: =IF(N43>0,ROUNDUP((N43/200),0),ROUNDUP((Q8/200),0)) -> 0 | Z10: =IF(O43>0,ROUNDUP((O43/200),0),ROUNDUP((R8/200),0)) -> 0 | AA10: =IF(OR(N43>0,O43>0),ROUNDUP((N43+O43)/1000,0),ROUNDUP(Q5/1000,0)) -> 0 | AB10: -
U11: collseums | V11: a-4 | W11: =IF(AND(N49>0,N49<=1500),(ROUNDUP(N49/75,0)),IF(N49>1500,(ROUNDUP(N49/120,0))+8,IF(AND(Q8>0,Q8<=1500),(ROUNDUP(Q8/75,0)),IF(Q8>1500,(ROUNDUP(Q8/120,0))+8,0)))) -> 0 | X11: =IF(AND(O49>0,O49<=1520),(ROUNDUP(O49/40,0)),IF(O49>1520,(ROUNDUP(O49/60,0))+12,IF(AND(R8>0,R8<=1520),(ROUNDUP(R8/40,0)),IF(R8>1520,(ROUNDUP(R8/60,0))+12,0)))) -> 0 | Y11: =IF(N49<0,ROUNDUP((N49/200),0),ROUNDUP((Q8/200),0)) -> 0 | Z11: =IF(O49>0,ROUNDUP((O49/150),0),ROUNDUP((R8/150),0)) -> 0 | AA11: =IF(OR(N49>0,O49>0),ROUNDUP((N49+O49)/1000,0),ROUNDUP(Q5/1000,0)) -> 0 | AB11: -
U12: stadiums | V12: a-5 | W12: =IF(AND(N55>0,N55<=1500),(ROUNDUP(N55/75,0)),IF(N55>1500,(ROUNDUP(N55/120,0))+8,IF(AND(Q8>0,Q8<=1500),(ROUNDUP(Q8/75,0)),IF(Q8>1500,(ROUNDUP(Q8/120,0))+8,0)))) -> 0 | X12: =IF(AND(O55>0,O55<=1520),(ROUNDUP(O55/40,0)),IF(O55>1520,(ROUNDUP(O55/60,0))+12,IF(AND(R8>0,R8<=1520),(ROUNDUP(R8/40,0)),IF(R8>1520,(ROUNDUP(R8/60,0))+12,0)))) -> 0 | Y12: =IF(N55>0,ROUNDUP((N55/200),0),ROUNDUP((Q8/200),0)) -> 0 | Z12: =IF(O55>0,ROUNDUP((O55/150),0),ROUNDUP((R8/150),0)) -> 0 | AA12: =IF(OR(N55>0,O55>0),ROUNDUP((N55+O55)/1000,0),ROUNDUP(Q5/1000,0)) -> 0 | AB12: -
U13: business | V13: b | W13: =IF(AND(N62>0,N62<=25),1,IF(AND(N62>25,N62<=50),2,IF(N62>50,(ROUNDUP(N62/50,0)+1),IF(AND(Q8>0,Q8<=25),1,IF(AND(Q8>25,Q8<=50),2,IF(Q8>50,(ROUNDUP(Q8/50,0)+1),0)))))) -> 0 | X13: =IF(AND(O62>0,O62<=25),1,IF(AND(O62>25,O62<=50),2,IF(O62>50,(ROUNDUP(O62/50,0)+1),IF(AND(R8>0,R8<=25),1,IF(AND(R8>25,R8<=50),2,IF(R8>50,(ROUNDUP(R8/50,0)+1),0)))))) -> 0 | Y13: =IF(AND(N62>0,N62<=40),1,IF(AND(N62>40,N62<=80),2,IF(N62>80,(ROUNDUP(N62/80,0)+1),IF(AND(Q8>0,Q8<=40),1,IF(AND(Q8>40,Q8<=80),2,IF(Q8>80,(ROUNDUP(Q8/80,0)+1),0)))))) -> 0 | Z13: =IF(AND(O62>0,O62<=40),1,IF(AND(O62>40,O62<=80),2,IF(O62>80,(ROUNDUP(O62/80,0)+1),IF(AND(R8>0,R8<=40),1,IF(AND(R8>40,R8<=80),2,IF(R8>80,(ROUNDUP(R8/80,0)+1),0)))))) -> 0 | AA13: =IF(OR(N62>0,O62>0),ROUNDUP((N62+O62)/100,0),ROUNDUP(Q5/100,0)) -> 0 | AB13: -
U14: educational | V14: e | W14: =IF(N73>0,ROUNDUP((N73/50),0),ROUNDUP((Q8/50),0)) -> 0 | X14: =IF(O73>0,ROUNDUP((O73/50),0),ROUNDUP((R8/50),0)) -> 0 | Y14: =IF(N73>0,ROUNDUP((N73/50),0),ROUNDUP((Q8/50),0)) -> 0 | Z14: =IF(O73>0,ROUNDUP((O73/50),0),ROUNDUP((R8/50),0)) -> 0 | AA14: =IF(OR(N73>0,O73>0),ROUNDUP((N73+O73)/100,0),ROUNDUP(Q5/100,0)) -> 0 | AB14: -
D15: Restaurants, banquet halls, and food courts | F15: =IF(AND(OR(N15>0,O15>0),N15+O15<=15),"Single restroom okay for 15 or less (IPC 403.2(2))",IF(AND(OR(N15>0,O15>0),N15+O15>Q5),W6,IF(AND(OR(N15>0,O15>0),N15+O15<Q5),W6,IF(Q5<=15,"Single restroom okay for 15 or less (IPC 403.2(2))",W6)))) -> Single restroom okay for 15 or less (IPC 403.2(2)) | G15: =IF(F15="Single restroom okay for 15 or less (IPC 403.2(2))","-",X6) -> - | H15: Can substitute up to 67% of required fixtures (IPC 419.2) | I15: =Y6 -> 0 | J15: =IF(F15="Single restroom okay for 15 or less (IPC 403.2(2))","-",Z6) -> - | K15: - | L15: =IF(F15="Single restroom okay for 15 or less (IPC 403.2(2))","15 or less Fountain exempt(IPC 410.2)",AA6) -> 15 or less Fountain exempt(IPC 410.2) | M15: 1 service sink | N15: 0 | O15: =N15 -> 0 | U15: factory | V15: f-1 & f-2 | W15: =IF(N79>0,ROUNDUP((N79/100),0),ROUNDUP((Q8/100),0)) -> 0 | X15: =IF(O79>0,ROUNDUP((O79/100),0),ROUNDUP((R8/100),0)) -> 0 | Y15: =IF(N79>0,ROUNDUP((N79/100),0),ROUNDUP((Q8/100),0)) -> 0 | Z15: =IF(O79>0,ROUNDUP((O79/100),0),ROUNDUP((R8/100),0)) -> 0 | AA15: =IF(OR(N79>0,O79>0),ROUNDUP((N79+O79)/400,0),ROUNDUP(Q5/400,0)) -> 0 | AB15: See section 411 if eyewash stations are provided
U16: res. Care | V16: i-1 | W16: =IF(N86>0,ROUNDUP((N86/10),0),ROUNDUP((Q8/10),0)) -> 0 | X16: =IF(O86>0,ROUNDUP((O86/10),0),ROUNDUP((R8/10),0)) -> 0 | Y16: =IF(N86>0,ROUNDUP((N86/10),0),ROUNDUP((Q8/10),0)) -> 0 | Z16: =IF(O86>0,ROUNDUP((O86/10),0),ROUNDUP((R8/10),0)) -> 0 | AA16: =IF(OR(N86>0,O86>0),ROUNDUP((N86+O86)/100,0),ROUNDUP(Q5/100,0)) -> 0 | AB16: =IF(OR(N86>0,O86>0),ROUNDUP((N86+O86)/8,0),ROUNDUP(Q5/8,0)) -> 0
U17: employees | V17: i-2 | W17: =IF(N96>0,ROUNDUP((N96/25),0),ROUNDUP((Q8/25),0)) -> 0 | X17: =IF(O96>0,ROUNDUP((O96/25),0),ROUNDUP((R8/25),0)) -> 0 | Y17: =IF(N96>0,ROUNDUP((N96/35),0),ROUNDUP((Q8/35),0)) -> 0 | Z17: =IF(O96>0,ROUNDUP((O96/35),0),ROUNDUP((R8/35),0)) -> 0 | AA17: =IF(OR(N96>0,O96>0),ROUNDUP((N96+O96)/100,0),ROUNDUP(Q5/100,0)) -> 0 | AB17: -
U18: visitors | V18: i-2 | W18: =IF(N102>0,ROUNDUP((N102/75),0),ROUNDUP((Q8/75),0)) -> 0 | X18: =IF(O102>0,ROUNDUP((O102/75),0),ROUNDUP((R8/75),0)) -> 0 | Y18: =IF(N102>0,ROUNDUP((N102/100),0),ROUNDUP((Q8/100),0)) -> 0 | Z18: =IF(O102>0,ROUNDUP((O102/100),0),ROUNDUP((R8/100),0)) -> 0 | AA18: =IF(OR(N102>0,O102>0),ROUNDUP((N102+O102)/500,0),ROUNDUP(Q5/500,0)) -> 0 | AB18: -
U19: reformitories | V19: i-3 | W19: =IF(N111>0,ROUNDUP((N111/15),0),ROUNDUP((Q8/15),0)) -> 0 | X19: =IF(O111>0,ROUNDUP((O111/15),0),ROUNDUP((R8/15),0)) -> 0 | Y19: =IF(N111>0,ROUNDUP((N111/15),0),ROUNDUP((Q8/15),0)) -> 0 | Z19: =IF(O111>0,ROUNDUP((O111/15),0),ROUNDUP((R8/15),0)) -> 0 | AA19: =IF(OR(N111>0,O111>0),ROUNDUP((N111+O111)/100,0),ROUNDUP(Q5/100,0)) -> 0 | AB19: =IF(OR(N111>0,O111>0),ROUNDUP((N111+O111)/15,0),ROUNDUP(Q5/15,0)) -> 0
U20: employees | V20: i-3 | W20: =IF(N117>0,ROUNDUP((N117/25),0),ROUNDUP((Q8/25),0)) -> 0 | X20: =IF(O117>0,ROUNDUP((O117/25),0),ROUNDUP((R8/25),0)) -> 0 | Y20: =IF(N117>0,ROUNDUP((N117/35),0),ROUNDUP((Q8/35),0)) -> 0 | Z20: =IF(O117>0,ROUNDUP((O117/35),0),ROUNDUP((R8/35),0)) -> 0 | AA20: =IF(OR(N117>0,O117>0),ROUNDUP((N117+O117)/100,0),ROUNDUP(Q5/100,0)) -> 0 | AB20: -
C21: A-3 | D21: Auditoriums without permanent seating, art galleries, exhibitions halls, museums, lecture halls, libraries, arcades, and gymnasiums | F21: =IF(AND(OR(N21>0,O21>0),N21+O21<=15),"Single restroom okay for 15 or less (IPC 403.2(2))",IF(AND(OR(N21>0,O21>0),N21+O21>Q5),W7,IF(AND(OR(N21>0,O21>0),N21+O21<Q5),W7,IF(Q5<=15,"Single restroom okay for 15 or less (IPC 403.2(2))",W7)))) -> Single restroom okay for 15 or less (IPC 403.2(2)) | G21: =IF(F21="Single restroom okay for 15 or less (IPC 403.2(2))","-",X7) -> - | H21: Can substitute up to 67% of required fixtures (IPC 419.2) | I21: =Y7 -> 0 | J21: =IF(F21="Single restroom okay for 15 or less (IPC 403.2(2))","-",Z7) -> - | K21: - | L21: =IF(F21="Single restroom okay for 15 or less (IPC 403.2(2))","15 or less Fountain exempt(IPC 410.2)",AA7) -> 15 or less Fountain exempt(IPC 410.2) | M21: 1 service sink | N21: 0 | O21: =N21 -> 0 | U21: daycare | V21: i-4 | W21: =IF(N123>0,ROUNDUP((N123/15),0),ROUNDUP((Q8/15),0)) -> 0 | X21: =IF(O123>0,ROUNDUP((O123/15),0),ROUNDUP((R8/15),0)) -> 0 | Y21: =IF(N123>0,ROUNDUP((N123/15),0),ROUNDUP((Q8/15),0)) -> 0 | Z21: =IF(O123>0,ROUNDUP((O123/15),0),ROUNDUP((R8/15),0)) -> 0 | AA21: =IF(OR(N123>0,O123>0),ROUNDUP((N123+O123)/100,0),ROUNDUP(Q5/100,0)) -> 0 | AB21: 1
U22: mercantile | V22: m | W22: =IF(N129>0,ROUNDUP((N129/500),0),ROUNDUP((Q8/500),0)) -> 0 | X22: =IF(O129>0,ROUNDUP((O129/500),0),ROUNDUP((R8/500),0)) -> 0 | Y22: =IF(N129>0,ROUNDUP((N129/750),0),ROUNDUP((Q8/750),0)) -> 0 | Z22: =IF(O129>0,ROUNDUP((O129/750),0),ROUNDUP((R8/750),0)) -> 0 | AA22: =IF(OR(N129>0,O129>0),ROUNDUP((N129+O129)/1000,0),ROUNDUP(Q5/1000,0)) -> 0 | AB22: -
U23: dormitories | V23: r-2 | W23: =IF(N140>0,ROUNDUP((N140/10),0),ROUNDUP((Q5/10),0)) -> 0 | X23: =IF(N140>0,ROUNDUP((N140/10),0),ROUNDUP((R8/10),0)) -> 0 | Y23: =IF(N140>0,ROUNDUP((N140/10),0),ROUNDUP((Q5/10),0)) -> 0 | Z23: - | AA23: =IF(N140>0,ROUNDUP(N140/100,0),ROUNDUP(Q5/100,0)) -> 0 | AB23: =IF(N140>0,ROUNDUP(N140/8,0),ROUNDUP(Q5/8,0)) -> 0
U24: congregate | V24: r-3 | W24: =IF(N156>0,ROUNDUP((N156/10),0),ROUNDUP((Q5/10),0)) -> 0 | X24: =IF(N156>0,ROUNDUP((N156/10),0),ROUNDUP((R8/10),0)) -> 0 | Y24: =IF(N156>0,ROUNDUP((N156/10),0),ROUNDUP((Q5/10),0)) -> 0 | Z24: - | AA24: =IF(N156>0,ROUNDUP(N156/100,0),ROUNDUP(Q5/100,0)) -> 0 | AB24: =IF(N156>0,ROUNDUP(N156/8,0),ROUNDUP(Q5/8,0)) -> 0
U25: storage | V25: s-1 & s-2 | W25: =IF(N171>0,ROUNDUP((N171/100),0),ROUNDUP((Q5/100),0)) -> 0 | X25: =IF(N171>0,ROUNDUP((N171/100),0),ROUNDUP((R8/100),0)) -> 0 | Y25: =IF(N171>0,ROUNDUP((N171/100),0),ROUNDUP((Q5/100),0)) -> 0 | Z25: - | AA25: =IF(N171>0,ROUNDUP(N171/1000,0),ROUNDUP(Q5/1000,0)) -> 0 | AB25: See section 411 if eyewash stations are provided
D31: Casino Gaming areas | F31: =IF(AND(OR(N31>0,O31>0),N31+O31<=15),"Single restroom okay for 15 or less (IPC 403.2(2))",IF(AND(OR(N31>0,O31>0),N31+O31>Q5),W8,IF(AND(OR(N31>0,O31>0),N31+O31<Q5),W8,IF(Q5<=15,"Single restroom okay for 15 or less (IPC 403.2(2))",W8)))) -> Single restroom okay for 15 or less (IPC 403.2(2)) | G31: =IF(F31="Single restroom okay for 15 or less (IPC 403.2(2))","-",X8) -> - | H31: Can substitute up to 67% of required fixtures (IPC 419.2) | I31: =Y8 -> 0 | J31: =IF(F31="Single restroom okay for 15 or less (IPC 403.2(2))","-",Z8) -> - | K31: - | L31: =IF(F31="Single restroom okay for 15 or less (IPC 403.2(2))","15 or less Fountain exempt(IPC 410.2)",AA8) -> 15 or less Fountain exempt(IPC 410.2) | M31: 1 service sink | N31: 0 | O31: =N31 -> 0
D37: Passenger terminals and transportation facilities | F37: =IF(AND(OR(N37>0,O37>0),N37+O37<=15),"Single restroom okay for 15 or less (IPC 403.2(2))",IF(AND(OR(N37>0,O37>0),N37+O37>Q5),W9,IF(AND(OR(N37>0,O37>0),N37+O37<Q5),W9,IF(Q5<=15,"Single restroom okay for 15 or less (IPC 403.2(2))",W9)))) -> Single restroom okay for 15 or less (IPC 403.2(2)) | G37: =IF(F37="Single restroom okay for 15 or less (IPC 403.2(2))","-",X9) -> - | H37: Can substitute up to 67% of required fixtures (IPC 419.2) | I37: =Y9 -> 0 | J37: =IF(F37="Single restroom okay for 15 or less (IPC 403.2(2))","-",Z9) -> - | K37: - | L37: =IF(F37="Single restroom okay for 15 or less (IPC 403.2(2))","15 or less Fountain exempt(IPC 410.2)",AA9) -> 15 or less Fountain exempt(IPC 410.2) | M37: 1 service sink | N37: 0 | O37: =N37 -> 0
D43: Places of worship and other religious services | F43: =IF(AND(OR(N43>0,O43>0),N43+O43<=15),"Single restroom okay for 15 or less (IPC 403.2(2))",IF(AND(OR(N43>0,O43>0),N43+O43>Q5),W10,IF(AND(OR(N43>0,O43>0),N43+O43<Q5),W10,IF(Q5<=15,"Single restroom okay for 15 or less (IPC 403.2(2))",W10)))) -> Single restroom okay for 15 or less (IPC 403.2(2)) | G43: =IF(F43="Single restroom okay for 15 or less (IPC 403.2(2))","-",X10) -> - | H43: Can substitute up to 67% of required fixtures (IPC 419.2) | I43: =Y10 -> 0 | J43: =IF(F43="Single restroom okay for 15 or less (IPC 403.2(2))","-",Z10) -> - | K43: - | L43: =IF(F43="Single restroom okay for 15 or less (IPC 403.2(2))","15 or less Fountain exempt(IPC 410.2)",AA10) -> 15 or less Fountain exempt(IPC 410.2) | M43: 1 service sink | N43: 0 | O43: =N43 -> 0
C49: A-4 | D49: Colliseums, arenas, skating rinks, pools and tennis courts for indoor sporting events and activities | F49: =IF(AND(OR(N49>0,O49>0),N49+O49<=15),"Single restroom okay for 15 or less (IPC 403.2(2))",IF(AND(OR(N49>0,O49>0),N49+O49>Q5),W11,IF(AND(OR(N49>0,O49>0),N49+O49<Q5),W11,IF(Q5<=15,"Single restroom okay for 15 or less (IPC 403.2(2))",W11)))) -> Single restroom okay for 15 or less (IPC 403.2(2)) | G49: =IF(F49="Single restroom okay for 15 or less (IPC 403.2(2))","-",X11) -> - | H49: Can substitute up to 67% of required fixtures (IPC 419.2) | I49: =Y11 -> 0 | J49: =IF(F49="Single restroom okay for 15 or less (IPC 403.2(2))","-",Z11) -> - | K49: - | L49: =IF(F49="Single restroom okay for 15 or less (IPC 403.2(2))","15 or less Fountain exempt(IPC 410.2)",AA11) -> 15 or less Fountain exempt(IPC 410.2) | M49: 1 service sink | N49: 0 | O49: =N49 -> 0
C55: A-5 | D55: Stadiums, amusement parks, bleachers and grand stands for outdoor sporting events and activities | F55: =IF(AND(OR(N55>0,O55>0),N55+O55<=15),"Single restroom okay for 15 or less (IPC 403.2(2))",IF(AND(OR(N55>0,O55>0),N55+O55>Q5),W12,IF(AND(OR(N55>0,O55>0),N55+O55<Q5),W12,IF(Q5<=15,"Single restroom okay for 15 or less (IPC 403.2(2))",W12)))) -> Single restroom okay for 15 or less (IPC 403.2(2)) | G55: =IF(F55="Single restroom okay for 15 or less (IPC 403.2(2))","-",X12) -> - | H55: Can substitute up to 67% of required fixtures (IPC 419.2) | I55: =Y12 -> 0 | J55: =IF(F55="Single restroom okay for 15 or less (IPC 403.2(2))","-",Z12) -> - | K55: - | L55: =IF(F55="Single restroom okay for 15 or less (IPC 403.2(2))","15 or less Fountain exempt(IPC 410.2)",AA12) -> 15 or less Fountain exempt(IPC 410.2) | M55: 1 service sink | N55: 0 | O55: =N55 -> 0
A62: Bussiness | C62: B | D62: Buildings for the transaction of business, professional services, other services involving merchandise, office buildings, banks, light industrial, ambulatory care and similar uses | F62: =IF(AND(OR(N62>0,O62>0),N62+O62<=15),"Single restroom okay for 15 or less (IPC 403.2(2))",IF(AND(OR(N62>0,O62>0),N62+O62>Q5),W13,IF(AND(OR(N62>0,O62>0),N62+O62<Q5),W13,IF(Q5<=15,"Single restroom okay for 15 or less (IPC 403.2(2))",W13)))) -> Single restroom okay for 15 or less (IPC 403.2(2)) | G62: =IF(F62="Single restroom okay for 15 or less (IPC 403.2(2))","-",X13) -> - | H62: Can substitute up to 50% of required fixtures (IPC 419.2) | I62: =Y13 -> 0 | J62: =IF(F62="Single restroom okay for 15 or less (IPC 403.2(2))","-",Z13) -> - | K62: - | L62: =IF(F62="Single restroom okay for 15 or less (IPC 403.2(2))","15 or less Fountain exempt(IPC 410.2)",AA13) -> 15 or less Fountain exempt(IPC 410.2) | M62: =IF(F62="Single restroom okay for 15 or less (IPC 403.2(2))","15 or less Service sink exempt (IPC 403.1(e))","1 service sink") -> 15 or less Service sink exempt (IPC 403.1(e)) | N62: 0 | O62: =N62 -> 0
A73: Educational | C73: E | D73: Educational Facilities | F73: =IF(AND(OR(N73>0,O73>0),N73+O73<=15),"Single restroom okay for 15 or less (IPC 403.2(2))",IF(AND(OR(N73>0,O73>0),N73+O73>Q5),W14,IF(AND(OR(N73>0,O73>0),N73+O73<Q5),W14,IF(Q5<=15,"Single restroom okay for 15 or less (IPC 403.2(2))",W14)))) -> Single restroom okay for 15 or less (IPC 403.2(2)) | G73: =IF(F73="Single restroom okay for 15 or less (IPC 403.2(2))","-",X14) -> - | H73: Can substitute up to 67% of required fixtures (IPC 419.2) | I73: =Y14 -> 0 | J73: =IF(F73="Single restroom okay for 15 or less (IPC 403.2(2))","-",Z14) -> - | K73: - | L73: =IF(F73="Single restroom okay for 15 or less (IPC 403.2(2))","15 or less Fountain exempt(IPC 410.2)",AA14) -> 15 or less Fountain exempt(IPC 410.2) | M73: 1 service sink | N73: 0 | O73: =N73 -> 0
A79: Factory or Industrial | C79: F1 & F2 | D79: Structures in which occupants are engages in work fabricating, assembly or processing of products or materials | F79: =IF(AND(OR(N79>0,O79>0),N79+O79<=15),"Single restroom okay for 15 or less (IPC 403.2(2))",IF(AND(OR(N79>0,O79>0),N79+O79>Q5),W15,IF(AND(OR(N79>0,O79>0),N79+O79<Q5),W15,IF(Q5<=15,"Single restroom okay for 15 or less (IPC 403.2(2))",W15)))) -> Single restroom okay for 15 or less (IPC 403.2(2)) | G79: =IF(F79="Single restroom okay for 15 or less (IPC 403.2(2))","-",X15) -> - | H79: Can substitute up to 50% of required fixtures (IPC 419.2) | I79: =Y15 -> 0 | J79: =IF(F79="Single restroom okay for 15 or less (IPC 403.2(2))","-",Z15) -> - | K79: =AB15 -> See section 411 if eyewash stations are provided | L79: =IF(F79="Single restroom okay for 15 or less (IPC 403.2(2))","15 or less Fountain exempt(IPC 410.2)",AA15) -> 15 or less Fountain exempt(IPC 410.2) | M79: 1 service sink | N79: 0 | O79: =N79 -> 0
A86: Institutional | C86: I-1 | D86: Residential Care | F86: =IF(AND(OR(N86>0,O86>0),N86+O86<=15),"Single restroom okay for 15 or less (IPC 403.2(2))",IF(AND(OR(N86>0,O86>0),N86+O86>Q5),W16,IF(AND(OR(N86>0,O86>0),N86+O86<Q5),W16,IF(Q5<=15,"Single restroom okay for 15 or less (IPC 403.2(2))",W16)))) -> Single restroom okay for 15 or less (IPC 403.2(2)) | G86: =IF(F86="Single restroom okay for 15 or less (IPC 403.2(2))","-",X16) -> - | H86: Can substitute up to 50% of required fixtures (IPC 419.2) | I86: =Y16 -> 0 | J86: =IF(F86="Single restroom okay for 15 or less (IPC 403.2(2))","-",Z16) -> - | K86: =AB16 -> 0 | L86: =IF(F86="Single restroom okay for 15 or less (IPC 403.2(2))","15 or less Fountain exempt(IPC 410.2)",AA16) -> 15 or less Fountain exempt(IPC 410.2) | M86: 1 service sink | N86: 0 | O86: =N86 -> 0
C92: I-2 | D92: Hospitals, ambulatory nursing home care recipient | F92: 1 per room | H92: - | I92: 1 per room | K92: =IF(OR(N92>0,O92>0),ROUNDUP((N92+O92)/15,0),ROUNDUP(Q5/15,0)) -> 0 | L92: =IF(OR(N92>0,O92>0),ROUNDUP((N92+O92)/100,0),ROUNDUP(Q5/100,0)) -> 0 | M92: 1 service sink | N92: 0 | O92: =N92 -> 0
D96: Emplyees, other than residential care | F96: =IF(AND(OR(N96>0,O96>0),N96+O96<=15),"Single restroom okay for 15 or less (IPC 403.2(2))",IF(AND(OR(N96>0,O96>0),N96+O96>Q5),W17,IF(AND(OR(N96>0,O96>0),N96+O96<Q5),W17,IF(Q5<=15,"Single restroom okay for 15 or less (IPC 403.2(2))",W17)))) -> Single restroom okay for 15 or less (IPC 403.2(2)) | G96: =IF(F96="Single restroom okay for 15 or less (IPC 403.2(2))","-",X17) -> - | H96: - | I96: =Y17 -> 0 | J96: =IF(F96="Single restroom okay for 15 or less (IPC 403.2(2))","-",Z17) -> - | K96: - | L96: =IF(AND(OR(N96>0,O96>0),N96+O96<=15),"15 or less Fountain exempt(IPC 410.2)",IF(Q5<=15,"15 or less Fountain exempt(IPC 410.2)",AA17)) -> 15 or less Fountain exempt(IPC 410.2) | M96: - | N96: 0 | O96: =N96 -> 0
D102: Visitors, other than residential care | F102: =IF(AND(OR(N102>0,O102>0),N102+O102<=15),"Single restroom okay for 15 or less (IPC 403.2(2))",IF(AND(OR(N102>0,O102>0),N102+O102>Q5),W18,IF(AND(OR(N102>0,O102>0),N102+O102<Q5),W18,IF(Q5<=15,"Single restroom okay for 15 or less (IPC 403.2(2))",W18)))) -> Single restroom okay for 15 or less (IPC 403.2(2)) | G102: =IF(F102="Single restroom okay for 15 or less (IPC 403.2(2))","-",X18) -> - | H102: - | I102: =Y18 -> 0 | J102: =IF(F102="Single restroom okay for 15 or less (IPC 403.2(2))","-",Z18) -> - | K102: - | L102: =IF(AND(OR(N102>0,O102>0),N102+O102<=15),"15 or less Fountain exempt(IPC 410.2)",IF(Q5<=15,"15 or less Fountain exempt(IPC 410.2)",AA18)) -> 15 or less Fountain exempt(IPC 410.2) | M102: - | N102: 0 | O102: =N102 -> 0
C108: I-3 | D108: Prisonsers | F108: 1 per cell | H108: - | I108: 1 per cell | K108: 1 per 100 | L108: ="1 per 100" -> 1 per 100 | M108: 1 service sink | N108: 0 | O108: =N108 -> 0
D111: Reformitories, detention centers, and correctional centers | F111: =IF(AND(OR(N111>0,O111>0),N111+O111<=15),"Single restroom okay for 15 or less (IPC 403.2(2))",IF(AND(OR(N111>0,O111>0),N111+O111>Q5),W19,IF(AND(OR(N111>0,O111>0),N111+O111<Q5),W19,IF(Q5<=15,"Single restroom okay for 15 or less (IPC 403.2(2))",W19)))) -> Single restroom okay for 15 or less (IPC 403.2(2)) | G111: =IF(F111="Single restroom okay for 15 or less (IPC 403.2(2))","-",X19) -> - | H111: - | I111: =Y19 -> 0 | J111: =IF(F111="Single restroom okay for 15 or less (IPC 403.2(2))","-",Z19) -> - | K111: =AB19 -> 0 | L111: =IF(F111="Single restroom okay for 15 or less (IPC 403.2(2))","15 or less Fountain exempt(IPC 410.2)",AA19) -> 15 or less Fountain exempt(IPC 410.2) | M111: 1 service sink | N111: 0 | O111: =N111 -> 0
D117: Employees | F117: =IF(AND(OR(N117>0,O117>0),N117+O117<=15),"Single restroom okay for 15 or less (IPC 403.2(2))",IF(AND(OR(N117>0,O117>0),N117+O117>Q5),W20,IF(AND(OR(N117>0,O117>0),N117+O117<Q5),W20,IF(Q5<=15,"Single restroom okay for 15 or less (IPC 403.2(2))",W20)))) -> Single restroom okay for 15 or less (IPC 403.2(2)) | G117: =IF(F117="Single restroom okay for 15 or less (IPC 403.2(2))","-",X20) -> - | H117: - | I117: =Y20 -> 0 | J117: =IF(F117="Single restroom okay for 15 or less (IPC 403.2(2))","-",Z20) -> - | K117: - | L117: =IF(F117="Single restroom okay for 15 or less (IPC 403.2(2))","15 or less Fountain exempt(IPC 410.2)",AA20) -> 15 or less Fountain exempt(IPC 410.2) | M117: - | N117: 0 | O117: =N117 -> 0
...

Sheet 2018 IPC
A1: Classification: | C1: Occupancy: | D1: Description: | F1: Water Closets: | H1: Urinals: | I1: Lavatories: | K1: Bathtubs / Showers: | L1: Drinking Fountain: | M1: Other: | N1: Manual Occupant Load Override: | W1: WATER CLOSETS | Y1: LAVATORIES | AA1: fountain | AB1: shower
F2: Male: | G2: Female: | I2: Male: | J2: Female: | N2: Male: | O2: Female: | W2: 2009 - 2021 IPC | X2: 2009 - 2021 IPC | Y2: 2009 - 2021 IPC | Z2: 2009 - 2021 IPC | AA2: 2021 - 2021 IPC | AB2: 2021 - 2021 IPC
A3: Assembly | C3: A-1 | D3: Theaters and other buildings for the performing arts and motion pictures | F3: =IF(AND(OR(N3>0,O3>0),N3+O3<=15),"Single restroom okay for 15 or less (IPC 403.2(2))",IF(AND(OR(N3>0,O3>0),N3+O3>Q5),W4,IF(AND(OR(N3>0,O3>0),N3+O3<Q5),W4,IF(Q5<=15,"Single restroom okay for 15 or less (IPC 403.2(2))",W4)))) -> Single restroom okay for 15 or less (IPC 403.2(2)) | G3: =IF(F3="Single restroom okay for 15 or less (IPC 403.2(2))","-",X4) -> - | H3: Can substitute up to 67% of required fixtures (IPC 424.2) | I3: =Y4 -> 0 | J3: =IF(F3="Single restroom okay for 15 or less (IPC 403.2(2))","-",Z4) -> - | K3: - | L3: =IF(F3="Single restroom okay for 15 or less (IPC 403.2(2))","15 or less Fountain exempt(IPC 410.2)",AA4) -> 15 or less Fountain exempt(IPC 410.2) | M3: 1 service sink | N3: 0 | O3: =N3 -> 0 | Q3: Total Occupant Load: | W3: male | X3: female | Y3: male | Z3: female | AA3: fountain | AB3: shower
U4: Theater | V4: a-1 | W4: =IF(N3>0,ROUNDUP((N3/125),0),ROUNDUP((Q8/125),0)) -> 0 | X4: =IF(O3>0,ROUNDUP((O3/65),0),ROUNDUP((R8/65),0)) -> 0 | Y4: =IF(N3>0,ROUNDUP((N3/200),0),ROUNDUP((Q8/200),0)) -> 0 | Z4: =IF(O3>0,ROUNDUP((O3/200),0),ROUNDUP((R8/200),0)) -> 0 | AA4: =IF(OR(N3>0,O3>0),ROUNDUP((N3+O3)/500,0),ROUNDUP(Q5/500,0)) -> 0 | AB4: -
Q5: ='Occupant Calculator'!D34 -> 0 | U5: night clubs | V5: a-2 | W5: =IF(N9>0,ROUNDUP((N9/40),0),ROUNDUP((Q8/40),0)) -> 0 | X5: =IF(O9>0,ROUNDUP((O9/40),0),ROUNDUP((R8/40),0)) -> 0 | Y5: =IF(N9>0,ROUNDUP((N9/75),0),ROUNDUP((Q8/75),0)) -> 0 | Z5: =IF(O9>0,ROUNDUP((O9/75),0),ROUNDUP((R8/75),0)) -> 0 | AA5: =IF(OR(N9>0,O9>0),ROUNDUP((N9+O9)/500,0),ROUNDUP(Q5/500,0)) -> 0 | AB5: -
U6: restaurants | V6: a-2 | W6: =IF(N15>0,ROUNDUP((N15/75),0),ROUNDUP((Q8/75),0)) -> 0 | X6: =IF(O15>0,ROUNDUP((O15/75),0),ROUNDUP((R8/75),0)) -> 0 | Y6: =IF(N15>0,ROUNDUP((N15/200),0),ROUNDUP((Q8/200),0)) -> 0 | Z6: =IF(O15>0,ROUNDUP((O15/200),0),ROUNDUP((R8/200),0)) -> 0 | AA6: =IF(OR(N15>0,O15>0),ROUNDUP((N15+O15)/500,0),ROUNDUP(Q5/500,0)) -> 0 | AB6: -
Q7: Male: | R7: Female: | U7: auditoriums | V7: a-3 | W7: =IF(N21>0,ROUNDUP((N21/125),0),ROUNDUP((Q8/125),0)) -> 0 | X7: =IF(O21>0,ROUNDUP((O21/65),0),ROUNDUP((R8/65),0)) -> 0 | Y7: =IF(N21>0,ROUNDUP((N21/200),0),ROUNDUP((Q8/200),0)) -> 0 | Z7: =IF(O21>0,ROUNDUP((O21/200),0),ROUNDUP((R8/200),0)) -> 0 | AA7: =IF(OR(N21>0,O21>0),ROUNDUP((N21+O21)/500,0),ROUNDUP(Q5/500,0)) -> 0 | AB7: -
Q8: =ROUNDUP((Q5/2),1) -> 0 | R8: =ROUNDUP((Q5/2),1) -> 0 | U8: casinos | V8: a-3 | W8: =IF(AND(N31>0,N31<=400),(ROUNDUP(N31/100,0)),IF(N31>400,(ROUNDUP(N31/250,0))+3,IF(AND(Q8>0,Q8<=400),(ROUNDUP(Q8/100,0)),IF(Q8>400,(ROUNDUP(Q8/250,0))+3,0)))) -> 0 | X8: =IF(AND(O31>0,O31<=400),(ROUNDUP(O31/50,0)),IF(O31>400,(ROUNDUP(O31/150,0))+5,IF(AND(R8>0,R8<=400),(ROUNDUP(R8/50,0)),IF(R8>400,(ROUNDUP(R8/150,0))+5,0)))) -> 0 | Y8: =IF(AND(N31>0,N31<=250),1,IF(AND(N31>250,N31<=500),2,IF(AND(N31>500,N31<=750),3,IF(N31>750,(ROUNDUP(N31/500,0)+2),IF(AND(Q8>0,Q8<=250),1,IF(AND(Q8>250,Q8<=500),2,IF(AND(Q8>500,Q8<=750),3,IF(Q8>750,(ROUNDUP(Q8/500,0)+2),0)))))))) -> 0 | Z8: =IF(AND(O31>0,O31<=250),1,IF(AND(O31>250,O31<=500),2,IF(AND(O31>500,O31<=750),3,IF(O31>750,(ROUNDUP(O31/500,0)+2),IF(AND(R8>0,R8<=250),1,IF(AND(R8>250,R8<=500),2,IF(AND(R8>500,R8<=750),3,IF(R8>750,(ROUNDUP(R8/500,0)+2),0)))))))) -> 0 | AA8: =IF(OR(N31>0,O31>0),ROUNDUP((N31+O31)/1000,0),ROUNDUP(Q5/1000,0)) -> 0 | AB8: -
C9: A-2 | D9: Nightclubs, bars, taverns, dance halls, and buildings for similar purposes | F9: =IF(AND(OR(N9>0,O9>0),N9+O9<=15),"Single restroom okay for 15 or less (IPC 403.2(2))",IF(AND(OR(N9>0,O9>0),N9+O9>Q5),W5,IF(AND(OR(N9>0,O9>0),N9+O9<Q5),W5,IF(Q5<=15,"Single restroom okay for 15 or less (IPC 403.2(2))",W5)))) -> Single restroom okay for 15 or less (IPC 403.2(2)) | G9: =IF(F9="Single restroom okay for 15 or less (IPC 403.2(2))","-",X5) -> - | H9: Can substitute up to 67% of required fixtures (IPC 424.2) | I9: =Y5 -> 0 | J9: =IF(F9="Single restroom okay for 15 or less (IPC 403.2(2))","-",Z5) -> - | K9: - | L9: =IF(F9="Single restroom okay for 15 or less (IPC 403.2(2))","15 or less Fountain exempt(IPC 410.2)",AA5) -> 15 or less Fountain exempt(IPC 410.2) | M9: 1 service sink | N9: 0 | O9: =N9 -> 0 | U9: passenger terminal | V9: a-3 | W9: =IF(N37>0,ROUNDUP((N37/50),0),ROUNDUP((Q8/500),0)) -> 0 | X9: =ROUNDUP((R8/500),0) -> 0 | Y9: =IF(N37>0,ROUNDUP((N37/750),0),ROUNDUP((Q8/750),0)) -> 0 | Z9: =IF(O37>0,ROUNDUP((O37/750),0),ROUNDUP((R8/750),0)) -> 0 | AA9: =IF(OR(N37>0,O37>0),ROUNDUP((N37+O37)/1000,0),ROUNDUP(Q5/1000,0)) -> 0 | AB9: -
U10: religious | V10: a-3 | W10: =IF(N43>0,ROUNDUP((N43/150),0),ROUNDUP((Q8/150),0)) -> 0 | X10: =ROUNDUP((R8/75),0) -> 0 | Y10: =IF(N43>0,ROUNDUP((N43/200),0),ROUNDUP((Q8/200),0)) -> 0 | Z10: =IF(O43>0,ROUNDUP((O43/200),0),ROUNDUP((R8/200),0)) -> 0 | AA10: =IF(OR(N43>0,O43>0),ROUNDUP((N43+O43)/1000,0),ROUNDUP(Q5/1000,0)) -> 0 | AB10: -
U11: collseums | V11: a-4 | W11: =IF(AND(N49>0,N49<=1500),(ROUNDUP(N49/75,0)),IF(N49>1500,(ROUNDUP(N49/120,0))+8,IF(AND(Q8>0,Q8<=1500),(ROUNDUP(Q8/75,0)),IF(Q8>1500,(ROUNDUP(Q8/120,0))+8,0)))) -> 0 | X11: =IF(AND(O49>0,O49<=1520),(ROUNDUP(O49/40,0)),IF(O49>1520,(ROUNDUP(O49/60,0))+12,IF(AND(R8>0,R8<=1520),(ROUNDUP(R8/40,0)),IF(R8>1520,(ROUNDUP(R8/60,0))+12,0)))) -> 0 | Y11: =IF(N49<0,ROUNDUP((N49/200),0),ROUNDUP((Q8/200),0)) -> 0 | Z11: =IF(O49>0,ROUNDUP((O49/150),0),ROUNDUP((R8/150),0)) -> 0 | AA11: =IF(OR(N49>0,O49>0),ROUNDUP((N49+O49)/1000,0),ROUNDUP(Q5/1000,0)) -> 0 | AB11: -
U12: stadiums | V12: a-5 | W12: =IF(AND(N55>0,N55<=1500),(ROUNDUP(N55/75,0)),IF(N55>1500,(ROUNDUP(N55/120,0))+8,IF(AND(Q8>0,Q8<=1500),(ROUNDUP(Q8/75,0)),IF(Q8>1500,(ROUNDUP(Q8/120,0))+8,0)))) -> 0 | X12: =IF(AND(O55>0,O55<=1520),(ROUNDUP(O55/40,0)),IF(O55>1520,(ROUNDUP(O55/60,0))+12,IF(AND(R8>0,R8<=1520),(ROUNDUP(R8/40,0)),IF(R8>1520,(ROUNDUP(R8/60,0))+12,0)))) -> 0 | Y12: =IF(N55>0,ROUNDUP((N55/200),0),ROUNDUP((Q8/200),0)) -> 0 | Z12: =IF(O55>0,ROUNDUP((O55/150),0),ROUNDUP((R8/150),0)) -> 0 | AA12: =IF(OR(N55>0,O55>0),ROUNDUP((N55+O55)/1000,0),ROUNDUP(Q5/1000,0)) -> 0 | AB12: -
U13: business | V13: b | W13: =IF(AND(N62>0,N62<=25),1,IF(AND(N62>25,N62<=50),2,IF(N62>50,(ROUNDUP(N62/50,0)+1),IF(AND(Q8>0,Q8<=25),1,IF(AND(Q8>25,Q8<=50),2,IF(Q8>50,(ROUNDUP(Q8/50,0)+1),0)))))) -> 0 | X13: =IF(AND(O62>0,O62<=25),1,IF(AND(O62>25,O62<=50),2,IF(O62>50,(ROUNDUP(O62/50,0)+1),IF(AND(R8>0,R8<=25),1,IF(AND(R8>25,R8<=50),2,IF(R8>50,(ROUNDUP(R8/50,0)+1),0)))))) -> 0 | Y13: =IF(AND(N62>0,N62<=40),1,IF(AND(N62>40,N62<=80),2,IF(N62>80,(ROUNDUP(N62/80,0)+1),IF(AND(Q8>0,Q8<=40),1,IF(AND(Q8>40,Q8<=80),2,IF(Q8>80,(ROUNDUP(Q8/80,0)+1),0)))))) -> 0 | Z13: =IF(AND(O62>0,O62<=40),1,IF(AND(O62>40,O62<=80),2,IF(O62>80,(ROUNDUP(O62/80,0)+1),IF(AND(R8>0,R8<=40),1,IF(AND(R8>40,R8<=80),2,IF(R8>80,(ROUNDUP(R8/80,0)+1),0)))))) -> 0 | AA13: =IF(OR(N62>0,O62>0),ROUNDUP((N62+O62)/100,0),ROUNDUP(Q5/100,0)) -> 0 | AB13: -
U14: educational | V14: e | W14: =IF(N74>0,ROUNDUP((N74/50),0),ROUNDUP((Q8/50),0)) -> 0 | X14: =IF(O74>0,ROUNDUP((O74/50),0),ROUNDUP((R8/50),0)) -> 0 | Y14: =IF(N74>0,ROUNDUP((N74/50),0),ROUNDUP((Q8/50),0)) -> 0 | Z14: =IF(O74>0,ROUNDUP((O74/50),0),ROUNDUP((R8/50),0)) -> 0 | AA14: =IF(OR(N74>0,O74>0),ROUNDUP((N74+O74)/100,0),ROUNDUP(Q5/100,0)) -> 0 | AB14: -
D15: Restaurants, banquet halls, and food courts | F15: =IF(AND(OR(N15>0,O15>0),N15+O15<=15),"Single restroom okay for 15 or less (IPC 403.2(2))",IF(AND(OR(N15>0,O15>0),N15+O15>Q5),W6,IF(AND(OR(N15>0,O15>0),N15+O15<Q5),W6,IF(Q5<=15,"Single restroom okay for 15 or less (IPC 403.2(2))",W6)))) -> Single restroom okay for 15 or less (IPC 403.2(2)) | G15: =IF(F15="Single restroom okay for 15 or less (IPC 403.2(2))","-",X6) -> - | H15: Can substitute up to 67% of required fixtures (IPC 424.2) | I15: =Y6 -> 0 | J15: =IF(F15="Single restroom okay for 15 or less (IPC 403.2(2))","-",Z6) -> - | K15: - | L15: =IF(F15="Single restroom okay for 15 or less (IPC 403.2(2))","15 or less Fountain exempt(IPC 410.2)",AA6) -> 15 or less Fountain exempt(IPC 410.2) | M15: 1 service sink | N15: 0 | O15: =N15 -> 0 | U15: factory | V15: f-1 & f-2 | W15: =IF(N80>0,ROUNDUP((N80/100),0),ROUNDUP((Q8/100),0)) -> 0 | X15: =IF(O80>0,ROUNDUP((O80/100),0),ROUNDUP((R8/100),0)) -> 0 | Y15: =IF(N80>0,ROUNDUP((N80/100),0),ROUNDUP((Q8/100),0)) -> 0 | Z15: =IF(O80>0,ROUNDUP((O80/100),0),ROUNDUP((R8/100),0)) -> 0 | AA15: =IF(OR(N80>0,O80>0),ROUNDUP((N80+O80)/400,0),ROUNDUP(Q5/400,0)) -> 0 | AB15: See section 411 if eyewash stations are provided
U16: res. Care | V16: i-1 | W16: =IF(N87>0,ROUNDUP((N87/10),0),ROUNDUP((Q8/10),0)) -> 0 | X16: =IF(O87>0,ROUNDUP((O87/10),0),ROUNDUP((R8/10),0)) -> 0 | Y16: =IF(N87>0,ROUNDUP((N87/10),0),ROUNDUP((Q8/10),0)) -> 0 | Z16: =IF(O87>0,ROUNDUP((O87/10),0),ROUNDUP((R8/10),0)) -> 0 | AA16: =IF(OR(N87>0,O87>0),ROUNDUP((N87+O87)/100,0),ROUNDUP(Q5/100,0)) -> 0 | AB16: =IF(OR(N87>0,O87>0),ROUNDUP((N87+O87)/8,0),ROUNDUP(Q5/8,0)) -> 0
U17: employees | V17: i-2 | W17: =IF(N96>0,ROUNDUP((N96/25),0),ROUNDUP((Q8/25),0)) -> 0 | X17: =IF(O96>0,ROUNDUP((O96/25),0),ROUNDUP((R8/25),0)) -> 0 | Y17: =IF(N96>0,ROUNDUP((N96/35),0),ROUNDUP((Q8/35),0)) -> 0 | Z17: =IF(O96>0,ROUNDUP((O96/35),0),ROUNDUP((R8/35),0)) -> 0 | AA17: =IF(OR(N96>0,O96>0),ROUNDUP((N96+O96)/100,0),ROUNDUP(Q5/100,0)) -> 0 | AB17: -
U18: visitors | V18: i-2 | W18: =IF(N102>0,ROUNDUP((N102/75),0),ROUNDUP((Q8/75),0)) -> 0 | X18: =IF(O102>0,ROUNDUP((O102/75),0),ROUNDUP((R8/75),0)) -> 0 | Y18: =IF(N102>0,ROUNDUP((N102/100),0),ROUNDUP((Q8/100),0)) -> 0 | Z18: =IF(O102>0,ROUNDUP((O102/100),0),ROUNDUP((R8/100),0)) -> 0 | AA18: =IF(OR(N102>0,O102>0),ROUNDUP((N102+O102)/500,0),ROUNDUP(Q5/500,0)) -> 0 | AB18: -
U19: reformitories | V19: i-3 | W19: =IF(N111>0,ROUNDUP((N111/15),0),ROUNDUP((Q8/15),0)) -> 0 | X19: =IF(O111>0,ROUNDUP((O111/15),0),ROUNDUP((R8/15),0)) -> 0 | Y19: =IF(N111>0,ROUNDUP((N111/15),0),ROUNDUP((Q8/15),0)) -> 0 | Z19: =IF(O111>0,ROUNDUP((O111/15),0),ROUNDUP((R8/15),0)) -> 0 | AA19: =IF(OR(N111>0,O111>0),ROUNDUP((N111+O111)/100,0),ROUNDUP(Q5/100,0)) -> 0 | AB19: =IF(OR(N111>0,O111>0),ROUNDUP((N111+O111)/15,0),ROUNDUP(Q5/15,0)) -> 0
U20: employees | V20: i-3 | W20: =IF(N117>0,ROUNDUP((N117/25),0),ROUNDUP((Q8/25),0)) -> 0 | X20: =IF(O117>0,ROUNDUP((O117/25),0),ROUNDUP((R8/25),0)) -> 0 | Y20: =IF(N117>0,ROUNDUP((N117/35),0),ROUNDUP((Q8/35),0)) -> 0 | Z20: =IF(O117>0,ROUNDUP((O117/35),0),ROUNDUP((R8/35),0)) -> 0 | AA20: =IF(OR(N117>0,O117>0),ROUNDUP((N117+O117)/100,0),ROUNDUP(Q5/100,0)) -> 0 | AB20: -
C21: A-3 | D21: Auditoriums without permanent seating, art galleries, exhibitions halls, museums, lecture halls, libraries, arcades, and gymnasiums | F21: =IF(AND(OR(N21>0,O21>0),N21+O21<=15),"Single restroom okay for 15 or less (IPC 403.2(2))",IF(AND(OR(N21>0,O21>0),N21+O21>Q5),W7,IF(AND(OR(N21>0,O21>0),N21+O21<Q5),W7,IF(Q5<=15,"Single restroom okay for 15 or less (IPC 403.2(2))",W7)))) -> Single restroom okay for 15 or less (IPC 403.2(2)) | G21: =IF(F21="Single restroom okay for 15 or less (IPC 403.2(2))","-",X7) -> - | H21: Can substitute up to 67% of required fixtures (IPC 424.2) | I21: =Y7 -> 0 | J21: =IF(F21="Single restroom okay for 15 or less (IPC 403.2(2))","-",Z7) -> - | K21: - | L21: =IF(F21="Single restroom okay for 15 or less (IPC 403.2(2))","15 or less Fountain exempt(IPC 410.2)",AA7) -> 15 or less Fountain exempt(IPC 410.2) | M21: 1 service sink | N21: 0 | O21: =N21 -> 0 | U21: daycare | V21: i-4 | W21: =IF(N123>0,ROUNDUP((N123/15),0),ROUNDUP((Q8/15),0)) -> 0 | X21: =IF(O123>0,ROUNDUP((O123/15),0),ROUNDUP((R8/15),0)) -> 0 | Y21: =IF(N123>0,ROUNDUP((N123/15),0),ROUNDUP((Q8/15),0)) -> 0 | Z21: =IF(O123>0,ROUNDUP((O123/15),0),ROUNDUP((R8/15),0)) -> 0 | AA21: =IF(OR(N123>0,O123>0),ROUNDUP((N123+O123)/100,0),ROUNDUP(Q5/100,0)) -> 0 | AB21: 1
U22: mercantile | V22: m | W22: =IF(N129>0,ROUNDUP((N129/500),0),ROUNDUP((Q8/500),0)) -> 0 | X22: =IF(O129>0,ROUNDUP((O129/500),0),ROUNDUP((R8/500),0)) -> 0 | Y22: =IF(N129>0,ROUNDUP((N129/750),0),ROUNDUP((Q8/750),0)) -> 0 | Z22: =IF(O129>0,ROUNDUP((O129/750),0),ROUNDUP((R8/750),0)) -> 0 | AA22: =IF(OR(N129>0,O129>0),ROUNDUP((N129+O129)/1000,0),ROUNDUP(Q5/1000,0)) -> 0 | AB22: -
U23: dormitories | V23: r-2 | W23: =IF(N140>0,ROUNDUP((N140/10),0),ROUNDUP((Q5/10),0)) -> 0 | X23: =IF(N140>0,ROUNDUP((N140/10),0),ROUNDUP((R8/10),0)) -> 0 | Y23: =IF(N140>0,ROUNDUP((N140/10),0),ROUNDUP((Q5/10),0)) -> 0 | Z23: - | AA23: =IF(N140>0,ROUNDUP(N140/100,0),ROUNDUP(Q5/100,0)) -> 0 | AB23: =IF(N140>0,ROUNDUP(N140/8,0),ROUNDUP(Q5/8,0)) -> 0
U24: congregate | V24: r-3 | W24: =IF(N151>0,ROUNDUP((N151/10),0),ROUNDUP((Q5/10),0)) -> 0 | X24: =IF(N151>0,ROUNDUP((N151/10),0),ROUNDUP((R8/10),0)) -> 0 | Y24: =IF(N151>0,ROUNDUP((N151/10),0),ROUNDUP((Q5/10),0)) -> 0 | Z24: - | AA24: =IF(N151>0,ROUNDUP(N151/100,0),ROUNDUP(Q5/100,0)) -> 0 | AB24: =ROUNDUP((Q5/8),0) -> 0
U25: storage | V25: s-1 & s-2 | W25: =IF(N161>0,ROUNDUP((N161/100),0),ROUNDUP((Q5/100),0)) -> 0 | X25: =IF(N161>0,ROUNDUP((N161/100),0),ROUNDUP((R8/100),0)) -> 0 | Y25: =IF(N161>0,ROUNDUP((N161/100),0),ROUNDUP((Q5/100),0)) -> 0 | Z25: - | AA25: =IF(N161>0,ROUNDUP(N161/1000,0),ROUNDUP(Q5/1000,0)) -> 0 | AB25: See section 411 if eyewash stations are provided
D31: Casino Gaming areas | F31: =IF(AND(OR(N31>0,O31>0),N31+O31<=15),"Single restroom okay for 15 or less (IPC 403.2(2))",IF(AND(OR(N31>0,O31>0),N31+O31>Q5),W8,IF(AND(OR(N31>0,O31>0),N31+O31<Q5),W8,IF(Q5<=15,"Single restroom okay for 15 or less (IPC 403.2(2))",W8)))) -> Single restroom okay for 15 or less (IPC 403.2(2)) | G31: =IF(F31="Single restroom okay for 15 or less (IPC 403.2(2))","-",X8) -> - | H31: Can substitute up to 67% of required fixtures (IPC 424.2) | I31: =Y8 -> 0 | J31: =IF(F31="Single restroom okay for 15 or less (IPC 403.2(2))","-",Z8) -> - | K31: - | L31: =IF(F31="Single restroom okay for 15 or less (IPC 403.2(2))","15 or less Fountain exempt(IPC 410.2)",AA8) -> 15 or less Fountain exempt(IPC 410.2) | M31: 1 service sink | N31: 0 | O31: =N31 -> 0
D37: Passenger terminals and transportation facilities | F37: =IF(AND(OR(N37>0,O37>0),N37+O37<=15),"Single restroom okay for 15 or less (IPC 403.2(2))",IF(AND(OR(N37>0,O37>0),N37+O37>Q5),W9,IF(AND(OR(N37>0,O37>0),N37+O37<Q5),W9,IF(Q5<=15,"Single restroom okay for 15 or less (IPC 403.2(2))",W9)))) -> Single restroom okay for 15 or less (IPC 403.2(2)) | G37: =IF(F37="Single restroom okay for 15 or less (IPC 403.2(2))","-",X9) -> - | H37: Can substitute up to 67% of required fixtures (IPC 424.2) | I37: =Y9 -> 0 | J37: =IF(F37="Single restroom okay for 15 or less (IPC 403.2(2))","-",Z9) -> - | K37: - | L37: =IF(F37="Single restroom okay for 15 or less (IPC 403.2(2))","15 or less Fountain exempt(IPC 410.2)",AA9) -> 15 or less Fountain exempt(IPC 410.2) | M37: 1 service sink | N37: 0 | O37: =N37 -> 0
D43: Places of worship and other religious services | F43: =IF(AND(OR(N43>0,O43>0),N43+O43<=15),"Single restroom okay for 15 or less (IPC 403.2(2))",IF(AND(OR(N43>0,O43>0),N43+O43>Q5),W10,IF(AND(OR(N43>0,O43>0),N43+O43<Q5),W10,IF(Q5<=15,"Single restroom okay for 15 or less (IPC 403.2(2))",W10)))) -> Single restroom okay for 15 or less (IPC 403.2(2)) | G43: =IF(F43="Single restroom okay for 15 or less (IPC 403.2(2))","-",X10) -> - | H43: Can substitute up to 67% of required fixtures (IPC 424.2) | I43: =Y10 -> 0 | J43: =IF(F43="Single restroom okay for 15 or less (IPC 403.2(2))","-",Z10) -> - | K43: - | L43: =IF(F43="Single restroom okay for 15 or less (IPC 403.2(2))","15 or less Fountain exempt(IPC 410.2)",AA10) -> 15 or less Fountain exempt(IPC 410.2) | M43: 1 service sink | N43: 0 | O43: =N43 -> 0
C49: A-4 | D49: Colliseums, arenas, skating rinks, pools and tennis courts for indoor sporting events and activities | F49: =IF(AND(OR(N49>0,O49>0),N49+O49<=15),"Single restroom okay for 15 or less (IPC 403.2(2))",IF(AND(OR(N49>0,O49>0),N49+O49>Q5),W11,IF(AND(OR(N49>0,O49>0),N49+O49<Q5),W11,IF(Q5<=15,"Single restroom okay for 15 or less (IPC 403.2(2))",W11)))) -> Single restroom okay for 15 or less (IPC 403.2(2)) | G49: =IF(F49="Single restroom okay for 15 or less (IPC 403.2(2))","-",X11) -> - | H49: Can substitute up to 67% of required fixtures (IPC 424.2) | I49: =Y11 -> 0 | J49: =IF(F49="Single restroom okay for 15 or less (IPC 403.2(2))","-",Z11) -> - | K49: - | L49: =IF(F49="Single restroom okay for 15 or less (IPC 403.2(2))","15 or less Fountain exempt(IPC 410.2)",AA11) -> 15 or less Fountain exempt(IPC 410.2) | M49: 1 service sink | N49: 0 | O49: =N49 -> 0
C55: A-5 | D55: Stadiums, amusement parks, bleachers and grand stands for outdoor sporting events and activities | F55: =IF(AND(OR(N55>0,O55>0),N55+O55<=15),"Single restroom okay for 15 or less (IPC 403.2(2))",IF(AND(OR(N55>0,O55>0),N55+O55>Q5),W12,IF(AND(OR(N55>0,O55>0),N55+O55<Q5),W12,IF(Q5<=15,"Single restroom okay for 15 or less (IPC 403.2(2))",W12)))) -> Single restroom okay for 15 or less (IPC 403.2(2)) | G55: =IF(F55="Single restroom okay for 15 or less (IPC 403.2(2))","-",X12) -> - | H55: Can substitute up to 67% of required fixtures (IPC 424.2) | I55: =Y12 -> 0 | J55: =IF(F55="Single restroom okay for 15 or less (IPC 403.2(2))","-",Z12) -> - | K55: - | L55: =IF(F55="Single restroom okay for 15 or less (IPC 403.2(2))","15 or less Fountain exempt(IPC 410.2)",AA12) -> 15 or less Fountain exempt(IPC 410.2) | M55: 1 service sink | N55: 0 | O55: =N55 -> 0
A62: Bussiness | C62: B | D62: Buildings for the transaction of business, professional services, other services involving merchandise, office buildings, banks, light industrial, ambulatory care and similar uses | F62: =IF(AND(OR(N62>0,O62>0),N62+O62<=25),"Single restroom okay for 25 or less (IPC 403.2(2))",IF(AND(OR(N62>0,O62>0),N62+O62>Q5),W13,IF(AND(OR(N62>0,O62>0),N62+O62<Q5),W13,IF(Q5<=25,"Single restroom okay for 25 or less (IPC 403.2(2))",W13)))) -> Single restroom okay for 25 or less (IPC 403.2(2)) | G62: =IF(F62="Single restroom okay for 25 or less (IPC 403.2(2))","-",X13) -> - | H62: Can substitute up to 50% of required fixtures (IPC 424.2) | I62: =Y13 -> 0 | J62: =IF(F62="Single restroom okay for 25 or less (IPC 403.2(2))","-",Z13) -> - | K62: - | L62: =IF(AND(OR(N62>0,O62>0),N62+O62<=15),"15 or less Fountain exempt(IPC 410.2)",IF(AND(OR(N62>0,O62>0),N62+O62>Q5),AA13,IF(AND(OR(N62>0,O62>0),N62+O62<Q5),AA13,IF(Q5<=25,"15 or less Fountain exempt(IPC 410.2)",AA13)))) -> 15 or less Fountain exempt(IPC 410.2) | M62: =IF(AND(OR(N62>0,O62>0),((N62+O62)<=15)),"15 or less Service sink exempt (IPC 403.1(e))",IF(AND(OR(N62>0,O62>0),N62+O62>Q5),"1 service sink",IF(AND(OR(N62>0,O62>0),N62+O62<Q5),"1 service sink",IF(Q5<=15,"15 or less Service sink exempt (IPC 403.1(e))","1 service sink")))) -> 15 or less Service sink exempt (IPC 403.1(e)) | N62: 0 | O62: =N62 -> 0
A74: Educational | C74: E | D74: Educational Facilities | F74: =IF(AND(OR(N74>0,O74>0),N74+O74<=15),"Single restroom okay for 15 or less (IPC 403.2(2))",IF(AND(OR(N74>0,O74>0),N74+O74>Q5),W14,IF(AND(OR(N74>0,O74>0),N74+O74<Q5),W14,IF(Q5<=15,"Single restroom okay for 15 or less (IPC 403.2(2))",W14)))) -> Single restroom okay for 15 or less (IPC 403.2(2)) | G74: =IF(F74="Single restroom okay for 15 or less (IPC 403.2(2))","-",X14) -> - | H74: Can substitute up to 67% of required fixtures (IPC 424.2) | I74: =Y14 -> 0 | J74: =IF(F74="Single restroom okay for 15 or less (IPC 403.2(2))","-",Z14) -> - | K74: - | L74: =IF(F74="Single restroom okay for 15 or less (IPC 403.2(2))","15 or less Fountain exempt(IPC 410.2)",AA14) -> 15 or less Fountain exempt(IPC 410.2) | M74: 1 service sink | N74: 0 | O74: =N74 -> 0
A80: Factory or Industrial | C80: F1 & F2 | D80: Structures in which occupants are engages in work fabricating, assembly or processing of products or materials | F80: =IF(AND(OR(N80>0,O80>0),N80+O80<=15),"Single restroom okay for 15 or less (IPC 403.2(2))",IF(AND(OR(N80>0,O80>0),N80+O80>Q5),W15,IF(AND(OR(N80>0,O80>0),N80+O80<Q5),W15,IF(Q5<=15,"Single restroom okay for 15 or less (IPC 403.2(2))",W15)))) -> Single restroom okay for 15 or less (IPC 403.2(2)) | G80: =IF(F80="Single restroom okay for 15 or less (IPC 403.2(2))","-",X15) -> - | H80: Can substitute up to 50% of required fixtures | I80: =Y15 -> 0 | J80: =IF(F80="Single restroom okay for 15 or less (IPC 403.2(2))","-",Z15) -> - | K80: =AB15 -> See section 411 if eyewash stations are provided | L80: =IF(F80="Single restroom okay for 15 or less (IPC 403.2(2))","15 or less Fountain exempt(IPC 410.2)",AA15) -> 15 or less Fountain exempt(IPC 410.2) | M80: 1 service sink | N80: 0 | O80: =N80 -> 0
A87: Institutional | C87: I-1 | D87: Residential Care | F87: =IF(AND(OR(N87>0,O87>0),N87+O87<=15),"Single restroom okay for 15 or less (IPC 403.2(2))",IF(AND(OR(N87>0,O87>0),N87+O87>Q5),W16,IF(AND(OR(N87>0,O87>0),N87+O87<Q5),W16,IF(Q5<=15,"Single restroom okay for 15 or less (IPC 403.2(2))",W16)))) -> Single restroom okay for 15 or less (IPC 403.2(2)) | G87: =IF(F87="Single restroom okay for 15 or less (IPC 403.2(2))","-",X16) -> - | H87: Can substitute up to 50% of required fixtures (IPC 424.2) | I87: =Y16 -> 0 | J87: =IF(F87="Single restroom okay for 15 or less (IPC 403.2(2))","-",Z16) -> - | K87: =AB16 -> 0 | L87: =IF(F87="Single restroom okay for 15 or less (IPC 403.2(2))","15 or less Fountain exempt(IPC 410.2)",AA16) -> 15 or less Fountain exempt(IPC 410.2) | M87: 1 service sink | N87: 0 | O87: =N87 -> 0
C93: I-2 | D93: Hospitals, ambulatory nursing home care recipient | F93: 1 per room | H93: - | I93: 1 per room | K93: =IF(OR(N93>0,O93>0),ROUNDUP((N93+O93)/15,0),ROUNDUP(Q5/15,0)) -> 0 | L93: =IF(OR(N93>0,O93>0),ROUNDUP((N93+O93)/100,0),ROUNDUP(Q5/100,0)) -> 0 | M93: 1 service sink | N93: 0 | O93: =N93 -> 0
D96: Emplyees, other than residential care | F96: =IF(AND(OR(N96>0,O96>0),N96+O96<=15),"Single restroom okay for 15 or less (IPC 403.2(2))",IF(AND(OR(N96>0,O96>0),N96+O96>Q5),W17,IF(AND(OR(N96>0,O96>0),N96+O96<Q5),W17,IF(Q5<=15,"Single restroom okay for 15 or less (IPC 403.2(2))",W17)))) -> Single restroom okay for 15 or less (IPC 403.2(2)) | G96: =IF(F96="Single restroom okay for 15 or less (IPC 403.2(2))","-",X17) -> - | H96: - | I96: =Y17 -> 0 | J96: =IF(F96="Single restroom okay for 15 or less (IPC 403.2(2))","-",Z17) -> - | K96: - | L96: =IF(AND(OR(N96>0,O96>0),N96+O96<=15),"15 or less Fountain exempt(IPC 410.2)",IF(Q5<=15,"15 or less Fountain exempt(IPC 410.2)",AA17)) -> 15 or less Fountain exempt(IPC 410.2) | M96: - | N96: 0 | O96: =N96 -> 0
D102: Visitors, other than residential care | F102: =IF(AND(OR(N102>0,O102>0),N102+O102<=15),"Single restroom okay for 15 or less (IPC 403.2(2))",IF(AND(OR(N102>0,O102>0),N102+O102>Q5),W18,IF(AND(OR(N102>0,O102>0),N102+O102<Q5),W18,IF(Q5<=15,"Single restroom okay for 15 or less (IPC 403.2(2))",W18)))) -> Single restroom okay for 15 or less (IPC 403.2(2)) | G102: =IF(F102="Single restroom okay for 15 or less (IPC 403.2(2))","-",X18) -> - | H102: - | I102: =Y18 -> 0 | J102: =IF(F102="Single restroom okay for 15 or less (IPC 403.2(2))","-",Z18) -> - | K102: - | L102: =IF(AND(OR(N102>0,O102>0),N102+O102<=15),"15 or less Fountain exempt(IPC 410.2)",IF(Q5<=15,"15 or less Fountain exempt(IPC 410.2)",AA18)) -> 15 or less Fountain exempt(IPC 410.2) | M102: - | N102: 0 | O102: =N102 -> 0
C108: I-3 | D108: Prisonsers | F108: 1 per cell | H108: - | I108: 1 per cell | K108: 1 per 100 | L108: ="1 per 100" -> 1 per 100 | M108: 1 service sink | N108: 0 | O108: =N108 -> 0
D111: Reformitories, detention centers, and correctional centers | F111: =IF(AND(OR(N111>0,O111>0),N111+O111<=15),"Single restroom okay for 15 or less (IPC 403.2(2))",IF(AND(OR(N111>0,O111>0),N111+O111>Q5),W19,IF(AND(OR(N111>0,O111>0),N111+O111<Q5),W19,IF(Q5<=15,"Single restroom okay for 15 or less (IPC 403.2(2))",W19)))) -> Single restroom okay for 15 or less (IPC 403.2(2)) | G111: =IF(F111="Single restroom okay for 15 or less (IPC 403.2(2))","-",X19) -> - | H111: - | I111: =Y19 -> 0 | J111: =IF(F111="Single restroom okay for 15 or less (IPC 403.2(2))","-",Z18) -> - | K111: =AB19 -> 0 | L111: =IF(F111="Single restroom okay for 15 or less (IPC 403.2(2))","15 or less Fountain exempt(IPC 410.2)",AA19) -> 15 or less Fountain exempt(IPC 410.2) | M111: 1 service sink | N111: 0 | O111: =N111 -> 0
D117: Employees | F117: =IF(AND(OR(N117>0,O117>0),N117+O117<=15),"Single restroom okay for 15 or less (IPC 403.2(2))",IF(AND(OR(N117>0,O117>0),N117+O117>Q5),W20,IF(AND(OR(N117>0,O117>0),N117+O117<Q5),W20,IF(Q5<=15,"Single restroom okay for 15 or less (IPC 403.2(2))",W20)))) -> Single restroom okay for 15 or less (IPC 403.2(2)) | G117: =IF(F117="Single restroom okay for 15 or less (IPC 403.2(2))","-",X20) -> - | H117: - | I117: =Y20 -> 0 | J117: =IF(F117="Single restroom okay for 15 or less (IPC 403.2(2))","-",Z20) -> - | K117: - | L117: =IF(F117="Single restroom okay for 15 or less (IPC 403.2(2))","15 or less Fountain exempt(IPC 410.2)",AA20) -> 15 or less Fountain exempt(IPC 410.2) | M117: - | N117: 0 | O117: =N117 -> 0
...

Sheet 2021 IPC
A1: Classification: | C1: Occupancy: | D1: Description: | F1: Water Closets: | H1: Urinals: | I1: Lavatories: | K1: Bathtubs / Showers: | L1: Drinking Fountain: | M1: Other: | N1: Manual Occupant Load Override: | W1: WATER CLOSETS | Y1: LAVATORIES | AA1: fountain | AB1: shower
F2: Male: | G2: Female: | I2: Male: | J2: Female: | N2: Male: | O2: Female: | W2: 2009 - 2021 IPC | X2: 2009 - 2021 IPC | Y2: 2009 - 2021 IPC | Z2: 2009 - 2021 IPC | AA2: 2021 - 2021 IPC | AB2: 2021 - 2021 IPC
A3: Assembly | C3: A-1 | D3: Theaters and other buildings for the performing arts and motion pictures | F3: =IF(AND(OR(N3>0,O3>0),N3+O3<=15),"Single restroom okay for 15 or less (IPC 403.2(2))",IF(AND(OR(N3>0,O3>0),N3+O3>Q5),W4,IF(AND(OR(N3>0,O3>0),N3+O3<Q5),W4,IF(Q5<=15,"Single restroom okay for 15 or less (IPC 403.2(2))",W4)))) -> Single restroom okay for 15 or less (IPC 403.2(2)) | G3: =IF(F3="Single restroom okay for 15 or less (IPC 403.2(2))","-",X4) -> - | H3: Can substitute up to 67% of required fixtures (IPC 424.2) | I3: =Y4 -> 0 | J3: =IF(F3="Single restroom okay for 15 or less (IPC 403.2(2))","-",Z4) -> - | K3: - | L3: =IF(F3="Single restroom okay for 15 or less (IPC 403.2(2))","15 or less Fountain exempt(IPC 410.2)",AA4) -> 15 or less Fountain exempt(IPC 410.2) | M3: 1 service sink | N3: 0 | O3: =N3 -> 0 | Q3: Total Occupant Load: | W3: male | X3: female | Y3: male | Z3: female | AA3: fountain | AB3: shower
U4: Theater | V4: a-1 | W4: =IF(N3>0,ROUNDUP((N3/125),0),ROUNDUP((Q8/125),0)) -> 0 | X4: =IF(O3>0,ROUNDUP((O3/65),0),ROUNDUP((R8/65),0)) -> 0 | Y4: =IF(N3>0,ROUNDUP((N3/200),0),ROUNDUP((Q8/200),0)) -> 0 | Z4: =IF(O3>0,ROUNDUP((O3/200),0),ROUNDUP((R8/200),0)) -> 0 | AA4: =IF(OR(N3>0,O3>0),ROUNDUP((N3+O3)/500,0),ROUNDUP(Q5/500,0)) -> 0 | AB4: -
Q5: ='Occupant Calculator'!D34 -> 0 | U5: night clubs | V5: a-2 | W5: =IF(N9>0,ROUNDUP((N9/40),0),ROUNDUP((Q8/40),0)) -> 0 | X5: =IF(O9>0,ROUNDUP((O9/40),0),ROUNDUP((R8/40),0)) -> 0 | Y5: =IF(N9>0,ROUNDUP((N9/75),0),ROUNDUP((Q8/75),0)) -> 0 | Z5: =IF(O9>0,ROUNDUP((O9/75),0),ROUNDUP((R8/75),0)) -> 0 | AA5: =IF(OR(N9>0,O9>0),ROUNDUP((N9+O9)/500,0),ROUNDUP(Q5/500,0)) -> 0 | AB5: -
U6: restaurants | V6: a-2 | W6: =IF(N15>0,ROUNDUP((N15/75),0),ROUNDUP((Q8/75),0)) -> 0 | X6: =IF(O15>0,ROUNDUP((O15/75),0),ROUNDUP((R8/75),0)) -> 0 | Y6: =IF(N15>0,ROUNDUP((N15/200),0),ROUNDUP((Q8/200),0)) -> 0 | Z6: =IF(O15>0,ROUNDUP((O15/200),0),ROUNDUP((R8/200),0)) -> 0 | AA6: =IF(OR(N15>0,O15>0),ROUNDUP((N15+O15)/500,0),ROUNDUP(Q5/500,0)) -> 0 | AB6: -
Q7: Male: | R7: Female: | U7: auditoriums | V7: a-3 | W7: =IF(N21>0,ROUNDUP((N21/125),0),ROUNDUP((Q8/125),0)) -> 0 | X7: =IF(O21>0,ROUNDUP((O21/65),0),ROUNDUP((R8/65),0)) -> 0 | Y7: =IF(N21>0,ROUNDUP((N21/200),0),ROUNDUP((Q8/200),0)) -> 0 | Z7: =IF(O21>0,ROUNDUP((O21/200),0),ROUNDUP((R8/200),0)) -> 0 | AA7: =IF(OR(N21>0,O21>0),ROUNDUP((N21+O21)/500,0),ROUNDUP(Q5/500,0)) -> 0 | AB7: -
Q8: =ROUNDUP((Q5/2),1) -> 0 | R8: =ROUNDUP((Q5/2),1) -> 0 | U8: casinos | V8: a-3 | W8: =IF(AND(N31>0,N31<=400),(ROUNDUP(N31/100,0)),IF(N31>400,(ROUNDUP(N31/250,0))+3,IF(AND(Q8>0,Q8<=400),(ROUNDUP(Q8/100,0)),IF(Q8>400,(ROUNDUP(Q8/250,0))+3,0)))) -> 0 | X8: =IF(AND(O31>0,O31<=400),(ROUNDUP(O31/50,0)),IF(O31>400,(ROUNDUP(O31/150,0))+5,IF(AND(R8>0,R8<=400),(ROUNDUP(R8/50,0)),IF(R8>400,(ROUNDUP(R8/150,0))+5,0)))) -> 0 | Y8: =IF(AND(N31>0,N31<=250),1,IF(AND(N31>250,N31<=500),2,IF(AND(N31>500,N31<=750),3,IF(N31>750,(ROUNDUP(N31/500,0)+2),IF(AND(Q8>0,Q8<=250),1,IF(AND(Q8>250,Q8<=500),2,IF(AND(Q8>500,Q8<=750),3,IF(Q8>750,(ROUNDUP(Q8/500,0)+2),0)))))))) -> 0 | Z8: =IF(AND(O31>0,O31<=250),1,IF(AND(O31>250,O31<=500),2,IF(AND(O31>500,O31<=750),3,IF(O31>750,(ROUNDUP(O31/500,0)+2),IF(AND(R8>0,R8<=250),1,IF(AND(R8>250,R8<=500),2,IF(AND(R8>500,R8<=750),3,IF(R8>750,(ROUNDUP(R8/500,0)+2),0)))))))) -> 0 | AA8: =IF(OR(N31>0,O31>0),ROUNDUP((N31+O31)/1000,0),ROUNDUP(Q5/1000,0)) -> 0 | AB8: -
C9: A-2 | D9: Nightclubs, bars, taverns, dance halls, and buildings for similar purposes | F9: =IF(AND(OR(N9>0,O9>0),N9+O9<=15),"Single restroom okay for 15 or less (IPC 403.2(2))",IF(AND(OR(N9>0,O9>0),N9+O9>Q5),W5,IF(AND(OR(N9>0,O9>0),N9+O9<Q5),W5,IF(Q5<=15,"Single restroom okay for 15 or less (IPC 403.2(2))",W5)))) -> Single restroom okay for 15 or less (IPC 403.2(2)) | G9: =IF(F9="Single restroom okay for 15 or less (IPC 403.2(2))","-",X5) -> - | H9: Can substitute up to 67% of required fixtures (IPC 424.2) | I9: =Y5 -> 0 | J9: =IF(F9="Single restroom okay for 15 or less (IPC 403.2(2))","-",Z5) -> - | K9: - | L9: =IF(F9="Single restroom okay for 15 or less (IPC 403.2(2))","15 or less Fountain exempt(IPC 410.2)",AA5) -> 15 or less Fountain exempt(IPC 410.2) | M9: 1 service sink | N9: 0 | O9: =N9 -> 0 | U9: passenger terminal | V9: a-3 | W9: =IF(N37>0,ROUNDUP((N37/50),0),ROUNDUP((Q8/500),0)) -> 0 | X9: =ROUNDUP((R8/500),0) -> 0 | Y9: =IF(N37>0,ROUNDUP((N37/750),0),ROUNDUP((Q8/750),0)) -> 0 | Z9: =IF(O37>0,ROUNDUP((O37/750),0),ROUNDUP((R8/750),0)) -> 0 | AA9: =IF(OR(N37>0,O37>0),ROUNDUP((N37+O37)/1000,0),ROUNDUP(Q5/1000,0)) -> 0 | AB9: -
P10: Notes: | U10: religious | V10: a-3 | W10: =IF(N43>0,ROUNDUP((N43/150),0),ROUNDUP((Q8/150),0)) -> 0 | X10: =ROUNDUP((R8/75),0) -> 0 | Y10: =IF(N43>0,ROUNDUP((N43/200),0),ROUNDUP((Q8/200),0)) -> 0 | Z10: =IF(O43>0,ROUNDUP((O43/200),0),ROUNDUP((R8/200),0)) -> 0 | AA10: =IF(OR(N43>0,O43>0),ROUNDUP((N43+O43)/1000,0),ROUNDUP(Q5/1000,0)) -> 0 | AB10: -
P11: 1. 2021 WA State Building Code, 2902.5.1: Occupant loads with 30 or less persons do not require a drinking fountain. | U11: collseums | V11: a-4 | W11: =IF(AND(N49>0,N49<=1500),(ROUNDUP(N49/75,0)),IF(N49>1500,(ROUNDUP(N49/120,0))+8,IF(AND(Q8>0,Q8<=1500),(ROUNDUP(Q8/75,0)),IF(Q8>1500,(ROUNDUP(Q8/120,0))+8,0)))) -> 0 | X11: =IF(AND(O49>0,O49<=1520),(ROUNDUP(O49/40,0)),IF(O49>1520,(ROUNDUP(O49/60,0))+12,IF(AND(R8>0,R8<=1520),(ROUNDUP(R8/40,0)),IF(R8>1520,(ROUNDUP(R8/60,0))+12,0)))) -> 0 | Y11: =IF(N49<0,ROUNDUP((N49/200),0),ROUNDUP((Q8/200),0)) -> 0 | Z11: =IF(O49>0,ROUNDUP((O49/150),0),ROUNDUP((R8/150),0)) -> 0 | AA11: =IF(OR(N49>0,O49>0),ROUNDUP((N49+O49)/1000,0),ROUNDUP(Q5/1000,0)) -> 0 | AB11: -
