Workbook

Sheet Axles (Hitch on Left)
A1: Module Width | B1: =(Weight!D8) -> 12 | C1: ft | E1: MOD: | F1: 0
A2: Module Length | B2: =(Weight!D9) -> 56 | C2: ft
A4: Chassis
B5: PSF | C5: Width | D5: Length | E5: Load (P) | F5: X | G5: X*P | H5: Y | I5: Y*P
B6: =(Weight!J56) -> 3.25 | C6: =B1 -> 12 | D6: =B2 -> 56 | E6: =B6*C6*D6 -> 2184 | F6: =B2/2 -> 28 | G6: =F6*E6 -> 61152 | H6: =(B1/2) -> 6 | I6: =H6*E6 -> 13104 | J6: w/o offset
H7: =(B1/2)+(B108/12) -> 6 | I7: =H7*E6 -> 13104 | J7: w/ offset
A8: Floor
B9: PSF | C9: Width | D9: Length | E9: Load (P) | F9: X | G9: X*P | H9: Y | I9: Y*P
B10: =(Weight!J31) -> 7.7 | C10: =B1 -> 12 | D10: =B2 -> 56 | E10: =B10*C10*D10 -> 5174.4 | F10: =B2/2 -> 28 | G10: =F10*E10 -> 144883.2 | H10: =B1/2 -> 6 | I10: =H10*E10 -> 31046.4
A12: Roof
B13: PSF | C13: Width | D13: Length | E13: Load (P) | F13: X | G13: X*P | H13: Y | I13: Y*P
A14: Bearing Wall | B14: =IF(Weight!E41>0,Weight!J47-Weight!F41,Weight!J47) -> 9.3510682 | C14: =($B$1+(Weight!E42/12))/2 -> 6.0833333 | E14: =B14*C14*D14 -> 0 | F14: =B2/2 -> 28 | G14: =F14*E14 -> 0 | I14: =H14*E14 -> 0
A15: Bearing Wall | B15: =IF(Weight!E41>0,Weight!J47-Weight!F41,Weight!J47) -> 9.3510682 | C15: =($B$1+(Weight!E42/12))/2 -> 6.0833333 | E15: =B15*C15*D15 -> 0 | F15: =B2/2 -> 28 | G15: =F15*E15 -> 0 | I15: =H15*E15 -> 0
A16: Post 1 | B16: =IF(Weight!E41>0,Weight!J47-Weight!F41,Weight!J47) -> 9.3510682 | C16: =($B$1+(Weight!E42/12))/2 -> 6.0833333 | E16: =B16*C16*D16 -> 0 | G16: =F16*E16 -> 0 | I16: =H16*E16 -> 0
A17: Post 2 | B17: =IF(Weight!E41>0,Weight!J47-Weight!F41,Weight!J47) -> 9.3510682 | C17: =($B$1+(Weight!E42/12))/2 -> 6.0833333 | E17: =B17*C17*D17 -> 0 | G17: =F17*E17 -> 0 | I17: =H17*E17 -> 0
A18: Post 3 | B18: =IF(Weight!E41>0,Weight!J47-Weight!F41,Weight!J47) -> 9.3510682 | C18: =($B$1+(Weight!E42/12))/2 -> 6.0833333 | E18: =B18*C18*D18 -> 0 | G18: =F18*E18 -> 0 | I18: =H18*E18 -> 0
A19: Post 4 | B19: =IF(Weight!E41>0,Weight!J47-Weight!F41,Weight!J47) -> 9.3510682 | C19: =($B$1+(Weight!E42/12))/2 -> 6.0833333 | E19: =B19*C19*D19 -> 0 | G19: =F19*E19 -> 0 | I19: =H19*E19 -> 0
A20: Post 5 | B20: =IF(Weight!E41>0,Weight!J47-Weight!F41,Weight!J47) -> 9.3510682 | C20: =($B$1+(Weight!E42/12))/2 -> 6.0833333 | E20: =B20*C20*D20 -> 0 | G20: =F20*E20 -> 0 | I20: =H20*E20 -> 0
A21: Post 6 | B21: =IF(Weight!E41>0,Weight!J47-Weight!F41,Weight!J47) -> 9.3510682 | C21: =($B$1+(Weight!E42/12))/2 -> 6.0833333 | E21: =B21*C21*D21 -> 0 | G21: =F21*E21 -> 0 | I21: =H21*E21 -> 0
A22: Post 7 | B22: =IF(Weight!E41>0,Weight!J47-Weight!F41,Weight!J47) -> 9.3510682 | C22: =($B$1+(Weight!E42/12))/2 -> 6.0833333 | E22: =B22*C22*D22 -> 0 | G22: =F22*E22 -> 0 | I22: =H22*E22 -> 0
A23: Post 8 | B23: =IF(Weight!E41>0,Weight!J47-Weight!F41,Weight!J47) -> 9.3510682 | C23: =($B$1+(Weight!E42/12))/2 -> 6.0833333 | E23: =B23*C23*D23 -> 0 | G23: =F23*E23 -> 0 | I23: =H23*E23 -> 0
A24: =IF(Weight!E41=1,Weight!C41,"-") -> - | B24: =IF(Weight!E41=1,INDEX(Materials!K73:K79,MATCH(A24,Materials!I73:I79,0)),Materials!B69) -> 0 | C24: =IF(A24="1-ply wood girder:",0.13,IF(A24="2-ply wood girder:",0.25,IF(A24="3-ply wood girder:",0.35,IF(A24="4-ply wood girder:",0.5,IF(A24="bar joist:",0.54,IF(A24="4-ply wood girder:",0.5,IF(A24="1-Ply 1-3/4""x16"" Microlam:",0.15,0.29))))))) -> 0.29 | E24: =B24*C24*D24 -> 0 | F24: =B2/2 -> 28 | G24: =F24*E24 -> 0 | H24: =IF(AND(Weight!E41=0,OR(H14="",H14=0)),0,IF(AND(AND(AND(AND(AND(Weight!E41>0),Weight!D16="n",Weight!D17="y",H14>0,H14<6)))),B1-(C24/2),IF(AND(AND(AND(AND(Weight!E41>0),Weight!D16="n",Weight!D17="y",H14>6))),(C24/2),IF(AND(AND(AND(AND(Weight!E41>0),Weight!D16="n"),Weight!D17="n",H14>6)),(C24/2),IF(AND(AND(AND(Weight!E41>0),Weight!D16="n",Weight!D17="n")),(C24/2),0))))) -> 0 | I24: =H24*E24 -> 0
A25: =IF(Weight!E41=1,Weight!C41,"-") -> - | B25: =IF(Weight!E41=1,INDEX(Materials!K73:K79,MATCH(A25,Materials!I73:I79,0)),Materials!B69) -> 0 | C25: =IF(A25="1-ply wood girder:",0.13,IF(A25="2-ply wood girder:",0.25,IF(A25="3-ply wood girder:",0.35,IF(A25="4-ply wood girder:",0.5,IF(A25="bar joist:",0.54,IF(A25="4-ply wood girder:",0.5,IF(A25="1-Ply 1-3/4""x16"" Microlam:",0.15,0.29))))))) -> 0.29 | E25: =B25*C25*D25 -> 0 | F25: =B2/2 -> 28 | G25: =F25*E25 -> 0 | H25: =IF(AND(Weight!E41=0,OR(H15="",H15=0)),0,IF(AND(AND(AND(AND(AND(Weight!E41>0),Weight!D16="n",Weight!D17="y",H15>0,H15<6)))),B1-(C25/2),IF(AND(AND(AND(AND(Weight!E41>0),Weight!D16="n",Weight!D17="y",H15>6))),(C25/2),IF(AND(AND(AND(AND(Weight!E41>0),Weight!D16="n"),Weight!D17="n",H15>6)),(C25/2),IF(AND(AND(AND(Weight!E41>0),Weight!D16="n",Weight!D17="n")),B1-(C25/2),0))))) -> 0 | I25: =H25*E25 -> 0
A26: Beam Wrapped w/ 5/8" Gyp | B26: =Materials!B67 -> 0.575 | E26: =B26*C26*D26 -> 0 | F26: =B2/2 -> 28 | G26: =F26*E26 -> 0 | I26: =H26*E26 -> 0
A27: Beam Wrapped w/ 5/8" Gyp | B27: =Materials!B67 -> 0.575 | E27: =B27*C27*D27 -> 0 | F27: =B2/2 -> 28 | G27: =F27*E27 -> 0 | I27: =H27*E27 -> 0
A28: Totals | E28: =SUM(E14:E27) -> 0 | G28: =SUM(G14:G27) -> 0 | I28: =SUM(I14:I27) -> 0
A30: Walls
B31: PSF | C31: Hieght | D31: Length | E31: Load (P) | F31: X | G31: X*P | H31: Y | I31: Y*P
A32: SIDEWALL | B32: =SUM(Weight!J71) -> 6.9 | C32: =SUM(Weight!D10) -> 10 | E32: =B32*C32*D32 -> 0 | F32: =B2/2 -> 28 | G32: =F32*E32 -> 0 | I32: =H32*E32 -> 0
A33: SIDEWALL | B33: =SUM(Weight!J71) -> 6.9 | C33: =SUM(Weight!D10) -> 10 | E33: =B33*C33*D33 -> 0 | F33: =B2/2 -> 28 | G33: =F33*E33 -> 0 | I33: =H33*E33 -> 0
A34: ENDWALL | B34: =SUM(Weight!J71) -> 6.9 | C34: =SUM(Weight!D11) -> 10 | E34: =B34*C34*D34 -> 0 | G34: =F34*E34 -> 0 | I34: =H34*E34 -> 0
A35: ENDWALL | B35: =SUM(Weight!J71) -> 6.9 | C35: =SUM(Weight!D11) -> 10 | E35: =B35*C35*D35 -> 0 | G35: =F35*E35 -> 0 | I35: =H35*E35 -> 0
A36: INTERIOR WALL | B36: =SUM(Weight!J84) -> 6.54 | C36: =SUM(Weight!D13) -> 8.1 | E36: =B36*C36*D36 -> 0 | G36: =F36*E36 -> 0 | I36: =H36*E36 -> 0
A37: 6 | B37: =SUM(Weight!J84) -> 6.54 | C37: =SUM(Weight!D13) -> 8.1 | E37: =B37*C37*D37 -> 0 | G37: =F37*E37 -> 0 | I37: =H37*E37 -> 0
A38: 7 | B38: =SUM(Weight!J84) -> 6.54 | C38: =SUM(Weight!D13) -> 8.1 | E38: =B38*C38*D38 -> 0 | G38: =F38*E38 -> 0 | I38: =H38*E38 -> 0
A39: 8 | B39: =SUM(Weight!J84) -> 6.54 | C39: =SUM(Weight!D13) -> 8.1 | E39: =B39*C39*D39 -> 0 | G39: =F39*E39 -> 0 | I39: =H39*E39 -> 0
A40: 9 | B40: =SUM(Weight!J84) -> 6.54 | C40: =SUM(Weight!D13) -> 8.1 | E40: =B40*C40*D40 -> 0 | G40: =F40*E40 -> 0 | I40: =H40*E40 -> 0
A41: 10 | B41: =SUM(Weight!J84) -> 6.54 | C41: =SUM(Weight!D13) -> 8.1 | E41: =B41*C41*D41 -> 0 | G41: =F41*E41 -> 0 | I41: =H41*E41 -> 0
A42: 11 | B42: =SUM(Weight!J84) -> 6.54 | C42: =SUM(Weight!D13) -> 8.1 | E42: =B42*C42*D42 -> 0 | G42: =F42*E42 -> 0 | I42: =H42*E42 -> 0
A43: 12 | B43: =SUM(Weight!J84) -> 6.54 | C43: =SUM(Weight!D13) -> 8.1 | E43: =B43*C43*D43 -> 0 | G43: =F43*E43 -> 0 | I43: =H43*E43 -> 0
...

Sheet Axles (Hitch on Right)
A1: Module Width | B1: =(Weight!D8) -> 12 | C1: ft | E1: MOD: | F1: 0
A2: Module Length | B2: =(Weight!D9) -> 56 | C2: ft
A4: Chassis
B5: PSF | C5: Width | D5: Length | E5: Load (P) | F5: X | G5: X*P | H5: Y | I5: Y*P
B6: =(Weight!J56) -> 3.25 | C6: =B1 -> 12 | D6: =B2 -> 56 | E6: =B6*C6*D6 -> 2184 | F6: =B2/2 -> 28 | G6: =F6*E6 -> 61152 | H6: =(B1/2) -> 6 | I6: =H6*E6 -> 13104 | J6: w/o offset
H7: =(B1/2)+(B108/12) -> 6 | I7: =H7*E6 -> 13104 | J7: w/ offset
A8: Floor
B9: PSF | C9: Width | D9: Length | E9: Load (P) | F9: X | G9: X*P | H9: Y | I9: Y*P
B10: =(Weight!J31) -> 7.7 | C10: =B1 -> 12 | D10: =B2 -> 56 | E10: =B10*C10*D10 -> 5174.4 | F10: =B2/2 -> 28 | G10: =F10*E10 -> 144883.2 | H10: =B1/2 -> 6 | I10: =H10*E10 -> 31046.4
A12: Roof
B13: PSF | C13: Width | D13: Length | E13: Load (P) | F13: X | G13: X*P | H13: Y | I13: Y*P
A14: Bearing Wall | B14: =IF(Weight!E41>0,Weight!J47-Weight!F41,Weight!J47) -> 9.3510682 | C14: =($B$1+(Weight!E42/12))/2 -> 6.0833333 | E14: =B14*C14*D14 -> 0 | F14: =B2/2 -> 28 | G14: =F14*E14 -> 0 | I14: =H14*E14 -> 0
A15: Bearing Wall | B15: =IF(Weight!E41>0,Weight!J47-Weight!F41,Weight!J47) -> 9.3510682 | C15: =($B$1+(Weight!E42/12))/2 -> 6.0833333 | E15: =B15*C15*D15 -> 0 | F15: =B2/2 -> 28 | G15: =F15*E15 -> 0 | I15: =H15*E15 -> 0
A16: Post 1 | B16: =IF(Weight!E41>0,Weight!J47-Weight!F41,Weight!J47) -> 9.3510682 | C16: =($B$1+(Weight!E42/12))/2 -> 6.0833333 | E16: =B16*C16*D16 -> 0 | G16: =F16*E16 -> 0 | I16: =H16*E16 -> 0
A17: Post 2 | B17: =IF(Weight!E41>0,Weight!J47-Weight!F41,Weight!J47) -> 9.3510682 | C17: =($B$1+(Weight!E42/12))/2 -> 6.0833333 | E17: =B17*C17*D17 -> 0 | G17: =F17*E17 -> 0 | I17: =H17*E17 -> 0
A18: Post 3 | B18: =IF(Weight!E41>0,Weight!J47-Weight!F41,Weight!J47) -> 9.3510682 | C18: =($B$1+(Weight!E42/12))/2 -> 6.0833333 | E18: =B18*C18*D18 -> 0 | G18: =F18*E18 -> 0 | I18: =H18*E18 -> 0
A19: Post 4 | B19: =IF(Weight!E41>0,Weight!J47-Weight!F41,Weight!J47) -> 9.3510682 | C19: =($B$1+(Weight!E42/12))/2 -> 6.0833333 | E19: =B19*C19*D19 -> 0 | G19: =F19*E19 -> 0 | I19: =H19*E19 -> 0
A20: Post 5 | B20: =IF(Weight!E41>0,Weight!J47-Weight!F41,Weight!J47) -> 9.3510682 | C20: =($B$1+(Weight!E42/12))/2 -> 6.0833333 | E20: =B20*C20*D20 -> 0 | G20: =F20*E20 -> 0 | I20: =H20*E20 -> 0
A21: Post 6 | B21: =IF(Weight!E41>0,Weight!J47-Weight!F41,Weight!J47) -> 9.3510682 | C21: =($B$1+(Weight!E42/12))/2 -> 6.0833333 | E21: =B21*C21*D21 -> 0 | G21: =F21*E21 -> 0 | I21: =H21*E21 -> 0
A22: Post 7 | B22: =IF(Weight!E41>0,Weight!J47-Weight!F41,Weight!J47) -> 9.3510682 | C22: =($B$1+(Weight!E42/12))/2 -> 6.0833333 | E22: =B22*C22*D22 -> 0 | G22: =F22*E22 -> 0 | I22: =H22*E22 -> 0
A23: Post 8 | B23: =IF(Weight!E41>0,Weight!J47-Weight!F41,Weight!J47) -> 9.3510682 | C23: =($B$1+(Weight!E42/12))/2 -> 6.0833333 | E23: =B23*C23*D23 -> 0 | G23: =F23*E23 -> 0 | I23: =H23*E23 -> 0
A24: =IF(Weight!E41=1,Weight!C41,"-") -> - | B24: =IF(Weight!E41=1,INDEX(Materials!K73:K79,MATCH(A24,Materials!I73:I79,0)),Materials!B69) -> 0 | C24: =IF(A24="1-ply wood girder:",0.13,IF(A24="2-ply wood girder:",0.25,IF(A24="3-ply wood girder:",0.35,IF(A24="4-ply wood girder:",0.5,IF(A24="bar joist:",0.54,IF(A24="4-ply wood girder:",0.5,IF(A24="1-Ply 1-3/4""x16"" Microlam:",0.15,0.29))))))) -> 0.29 | E24: =B24*C24*D24 -> 0 | F24: =B2/2 -> 28 | G24: =F24*E24 -> 0 | H24: =IF(AND(Weight!E41=0,OR(H14="",H14=0)),0,IF(AND(AND(AND(AND(AND(Weight!E41>0),Weight!D16="n",Weight!D17="y",H14>0,H14<6)))),B1-(C24/2),IF(AND(AND(AND(AND(Weight!E41>0),Weight!D16="n",Weight!D17="y",H14>6))),(C24/2),IF(AND(AND(AND(AND(Weight!E41>0),Weight!D16="n"),Weight!D17="n",H14>6)),(C24/2),IF(AND(AND(AND(Weight!E41>0),Weight!D16="n",Weight!D17="n")),(C24/2),0))))) -> 0 | I24: =H24*E24 -> 0
A25: =IF(Weight!E41=1,Weight!C41,"-") -> - | B25: =IF(Weight!E41=1,INDEX(Materials!K73:K79,MATCH(A25,Materials!I73:I79,0)),Materials!B69) -> 0 | C25: =IF(A25="1-ply wood girder:",0.13,IF(A25="2-ply wood girder:",0.25,IF(A25="3-ply wood girder:",0.35,IF(A25="4-ply wood girder:",0.5,IF(A25="bar joist:",0.54,IF(A25="4-ply wood girder:",0.5,IF(A25="1-Ply 1-3/4""x16"" Microlam:",0.15,0.29))))))) -> 0.29 | E25: =B25*C25*D25 -> 0 | F25: =B2/2 -> 28 | G25: =F25*E25 -> 0 | H25: =IF(AND(Weight!E41=0,OR(H15="",H15=0)),0,IF(AND(AND(AND(AND(AND(Weight!E41>0),Weight!D16="n",Weight!D17="y",H15>0,H15<6)))),B1-(C25/2),IF(AND(AND(AND(AND(Weight!E41>0),Weight!D16="n",Weight!D17="y",H15>6))),(C25/2),IF(AND(AND(AND(AND(Weight!E41>0),Weight!D16="n"),Weight!D17="n",H15>6)),(C25/2),IF(AND(AND(AND(Weight!E41>0),Weight!D16="n",Weight!D17="n")),B1-(C25/2),0))))) -> 0 | I25: =H25*E25 -> 0
A26: Beam Wrapped w/ 5/8" Gyp | B26: =Materials!B67 -> 0.575 | E26: =B26*C26*D26 -> 0 | F26: =B2/2 -> 28 | G26: =F26*E26 -> 0 | I26: =H26*E26 -> 0
A27: Beam Wrapped w/ 5/8" Gyp | B27: =Materials!B67 -> 0.575 | E27: =B27*C27*D27 -> 0 | F27: =B2/2 -> 28 | G27: =F27*E27 -> 0 | I27: =H27*E27 -> 0
A28: Totals | E28: =SUM(E14:E27) -> 0 | G28: =SUM(G14:G27) -> 0 | I28: =SUM(I14:I27) -> 0
A30: Walls
B31: PSF | C31: Hieght | D31: Length | E31: Load (P) | F31: X | G31: X*P | H31: Y | I31: Y*P
A32: SIDEWALL | B32: =SUM(Weight!J71) -> 6.9 | C32: =SUM(Weight!D10) -> 10 | E32: =B32*C32*D32 -> 0 | F32: =B2/2 -> 28 | G32: =F32*E32 -> 0 | I32: =H32*E32 -> 0
A33: SIDEWALL | B33: =SUM(Weight!J71) -> 6.9 | C33: =SUM(Weight!D10) -> 10 | E33: =B33*C33*D33 -> 0 | F33: =B2/2 -> 28 | G33: =F33*E33 -> 0 | I33: =H33*E33 -> 0
A34: ENDWALL | B34: =SUM(Weight!J71) -> 6.9 | C34: =SUM(Weight!D11) -> 10 | E34: =B34*C34*D34 -> 0 | G34: =F34*E34 -> 0 | I34: =H34*E34 -> 0
A35: ENDWALL | B35: =SUM(Weight!J71) -> 6.9 | C35: =SUM(Weight!D11) -> 10 | E35: =B35*C35*D35 -> 0 | G35: =F35*E35 -> 0 | I35: =H35*E35 -> 0
A36: INTERIOR WALL | B36: =SUM(Weight!J84) -> 6.54 | C36: =SUM(Weight!D13) -> 8.1 | E36: =B36*C36*D36 -> 0 | G36: =F36*E36 -> 0 | I36: =H36*E36 -> 0
A37: 6 | B37: =SUM(Weight!J84) -> 6.54 | C37: =SUM(Weight!D13) -> 8.1 | E37: =B37*C37*D37 -> 0 | G37: =F37*E37 -> 0 | I37: =H37*E37 -> 0
A38: 7 | B38: =SUM(Weight!J84) -> 6.54 | C38: =SUM(Weight!D13) -> 8.1 | E38: =B38*C38*D38 -> 0 | G38: =F38*E38 -> 0 | I38: =H38*E38 -> 0
A39: 8 | B39: =SUM(Weight!J84) -> 6.54 | C39: =SUM(Weight!D13) -> 8.1 | E39: =B39*C39*D39 -> 0 | G39: =F39*E39 -> 0 | I39: =H39*E39 -> 0
A40: 9 | B40: =SUM(Weight!J84) -> 6.54 | C40: =SUM(Weight!D13) -> 8.1 | E40: =B40*C40*D40 -> 0 | G40: =F40*E40 -> 0 | I40: =H40*E40 -> 0
A41: 10 | B41: =SUM(Weight!J84) -> 6.54 | C41: =SUM(Weight!D13) -> 8.1 | E41: =B41*C41*D41 -> 0 | G41: =F41*E41 -> 0 | I41: =H41*E41 -> 0
A42: 11 | B42: =SUM(Weight!J84) -> 6.54 | C42: =SUM(Weight!D13) -> 8.1 | E42: =B42*C42*D42 -> 0 | G42: =F42*E42 -> 0 | I42: =H42*E42 -> 0
A43: 12 | B43: =SUM(Weight!J84) -> 6.54 | C43: =SUM(Weight!D13) -> 8.1 | E43: =B43*C43*D43 -> 0 | G43: =F43*E43 -> 0 | I43: =H43*E43 -> 0
...

Sheet Weight
A1: MODULE WEIGHT WORKSHEET
A3: THE INTENT OF THIS WORKSHEET IS TO GIVE THE USER AN APPROXIMATION OF THE
A4: OVERALL MODULE WEIGHT AND AN APPROXIMATION OF THE NUMBER OF AXLES AND
A5: TIRES REQUIRED. THIS IS ONLY A ROUGH ESTIMATE.
G6: Factory: | H6: SSI
A7: BASIC INFO:
C8: Module Width: | D8: 12 | E8: ft.
C9: Module Length: | D9: 56 | E9: ft.
C10: Sidewall Height: | D10: 10 | E10: ft. (Use 8' for mono pitched roofs and 12' for complex, 10' single wides)
C11: Endwall Height: | D11: 10 | E11: ft. (Use 10.5' for mono pitched roofs and 12' for complex, 10' single wides)
C12: Interior Partition Length: | D12: 16 | E12: ft.
C13: Interior Partition Height: | D13: 8.1 | E13: =IF(H6="pmi","ft. (8'-0"" standard)",IF(OR(H6="amtex",H6="indicom"),"ft. (8'-3"" standard)","ft. (8'-6"" standard)")) -> ft. (8'-6" standard)
C14: Base Cabinet Length: | D14: 0 | E14: ft.
C15: Overhead Cabinet Length: | D15: 0 | E15: ft.
C16: Single Wide? | D16: Y | E16: (Y = Single Wide or N = Multi-wide)
C17: Sidewall Module? | D17: Y | E17: (Y = Sidewall Module, N = Interior Module)(Must be "Y" if Single Wide.)
C18: Axle Capcity: | D18: 6000 | E18: lbs | F18: =IF(D18=7000,"HD Tires Required","")
A20: FLOOR:
A21: =IF(H6="PMI","(Base floor includes 2x8 Joists @ 16"" o.c., 3/4"" floor decking, R-19 insulation, Mobi-Flex Bottom Board, & VCT)","(Base floor includes 2x8 Joists @ 16"" o.c., 3/4"" floor decking, R-30 insulation, Mobi-Flex Bottom Board, & VCT)") -> (Base floor includes 2x8 Joists @ 16" o.c., 3/4" floor decking, R-30 insulation, Mobi-Flex Bottom Board, & VCT)
B22: Base Weight = | C22: =ROUNDUP(Assemblies!F8,1) -> 7.7 | D22: psf
B24: Floor Joists: | C24: 2x10 Joists @ 16" o.c.: | E24: 0 | F24: =INDEX(Materials!B4:B6,MATCH(C24,Materials!A4:A6,0)) -> 0.87649714 | G24: psf (1.33 for 12" o.c., 0.67 for 24" o.c.)
B25: Deck / Underlayment: | C25: 1/4" Fiberock | E25: 0 | F25: =INDEX(Materials!B12:B20,MATCH(C25,Materials!A12:A20,0)) -> 1.4 | G25: psf
B26: Additional Decking: | C26: 3/4" MegaBoard: | E26: 0 | F26: =INDEX(Materials!B17:B20,MATCH(C26,Materials!A17:A20,0)) -> 3.9 | G26: psf
B27: Flooring: | C27: No Flooring: | E27: 0 | F27: =INDEX(Materials!B22:B26,MATCH(C27,Materials!A22:A26,0)) -> -1.4 | G27: psf
B28: Flooring: | C28: .080 Sheet Vinyl: | E28: 0 | F28: =INDEX(Materials!B22:B26,MATCH(C28,Materials!A22:A26,0)) -> -0.6 | G28: psf
B29: Bottom Board: | C29: 30ga Galv. Bottom Board: | E29: 0 | F29: =INDEX(Materials!B29:B30,MATCH(C29,Materials!A29:A30,0)) -> 0.416 | G29: psf
B30: Misc: | C30: Single Rim Joists: | E30: 0 | F30: =IF(AND(E30>0,E24=0),Materials!N5,IF(AND(Weight!E30>0,Weight!E24>0),INDEX(Materials!N4:N11,MATCH(C24,Materials!I4:I11,0)),Materials!N5)) -> -0.48857143 | G30: psf
H31: Revised Weight: | J31: =C22+(E24*F24)+(E25*F25)+(E26*F26)+(E27*F27)+(E28*F28)+(E29*F29)+(E30*F30) -> 7.7 | K31: psf
A32: ROOF:
A33: =IF(H6="PMI","(Base roof includes: 2x8 rafters @ 16"" o.c., 1/2 plywood over 1/2"" gyp, suspended ceiling, R-30 Insul., 4-layer plywood beam, and 45 Mil EPDM roofing)","(Base roof includes: 2x8 rafters @ 16"" o.c., 1/2"" plywood, suspended ceiling, R-38 Insul., 4-layer plywood beam and 45 Mil EPDM roofing)") -> (Base roof includes: 2x8 rafters @ 16" o.c., 1/2" plywood, suspended ceiling, R-38 Insul., 4-layer plywood beam and 45 Mil EPDM roofing)
B34: Base Weight = | C34: =ROUNDUP(Assemblies!F20,1) -> 6.8 | D34: psf | E34: =IF(AND(D16="n",D17="y"),"(Mate Beam figured on one side only)",IF(D16="y","(Mate Beam has been removed from base weight)","")) -> (Mate Beam has been removed from base weight)
B36: Rafters: | C36: 2x10 Rafters @ 16" o.c.: | E36: 1 | F36: =INDEX(Materials!B34:B41,MATCH(C36,Materials!A34:A41,0)) -> 1.0519598 | G36: psf (1.33 for 12" o.c., 0.67 for 24" o.c.)
B37: Roof Sheathing: | C37: 1/4" Dens Deck Under EPDM: | E37: 0 | F37: =INDEX(Materials!B51:B59,MATCH(C37,Materials!A51:A59,0)) -> -0.3 | G37: psf
B38: Roof Sheathing: | C38: H-Sheild HD (Polyiso): | E38: 0 | F38: =INDEX(Materials!B51:B59,MATCH(C38,Materials!A51:A59,0)) -> 0.61 | G38: psf
B39: Roof Sheathing: | C39: 2" Polyiso Board: | E39: 1 | F39: =INDEX(Materials!B51:B59,MATCH(C39,Materials!A51:A59,0)) -> 0.5 | G39: psf
B40: Roofing Material: | C40: 26Ga PBR / R-Panel Over Felt: | E40: 0 | F40: =INDEX(Materials!B42:B48,MATCH(C40,Materials!A42:A48,0)) -> 0.8 | G40: psf
B41: Mateline Beam: | C41: Steel Girder: | E41: 0 | F41: =INDEX(Materials!B69:B142,MATCH(C41,Materials!A69:A142,0)) -> 0 | G41: psf | H41: =IF(AND(OR(C41="steel girder:",C41="bar joist"),E41>0),"(See Assemblies tab - Size and type of material can be adjusted for Girder and Bar Joists)","")
B42: Overhang: | C42: Along Side (Enter Length in inches): | E42: 2 | F42: =IF(E42=0,0,IF(AND(D16="y",E36=0),Materials!M35*2,IF(D16="y",INDEX(Materials!M34:M42,MATCH(Weight!C36,Materials!A33:A41,0))*2,IF(E36=0,Materials!M35,INDEX(Materials!M34:M42,MATCH(Weight!C36,Materials!A33:A41,0)))))) -> 1.0477575 | G42: psf
B43: Overhang: | C43: At Ends (Enter length in inches): | E43: 2 | F43: =IF(E43=0,0,IF(E36=0,Materials!N35,INDEX(Materials!N34:N42,MATCH(Weight!C36,Materials!A33:A41,0)))) -> -0.048649106 | G43: psf
B44: Misc: | C44: 5/8" Type X Gypsum underside of raters: | E44: 0 | F44: =INDEX(Materials!B60:B66,MATCH(C44,Materials!A60:A66,0)) -> 2.6 | G44: psf
...

Sheet Materials
A1: NOTE: ONLY THE BASE COMPONENTS SHOULD BE EDITED. ALL OTHER CELLS WILL AUTOMATICALLY ADJUST
A2: Floor: | B2: PSF:
A3: 2x8 Joists @ 16" o.c.: | B3: =L5 -> 3.1757143 | C3: base component | I3: Floor Joists: | J3: PLF | K3: Grade | L3: PSF | M3: PSF (Sng. Rim) | N3: Difference | O3: Assumed 12'x60' Mod w/ dbl. Rim on Each Side / 16" o.c. (45 joists) + (20) total for Rims
A4: 2x6 Joists @ 16" o.c.: | B4: =SUM(L4-B3) -> -0.83381648 | I4: 2x6 Joists @ 16" o.c.: | J4: =IF(Weight!H6="pmi",1.5619,2.1625) -> 2.1625 | K4: =IF(Weight!H6="pmi","#2 HF","#2 SYP") -> #2 SYP | L4: =IF(AND(Weight!D8>10,Weight!D8<=12),SUM(J4*12*((Weight!D9/1.334)+((Weight!D9/12)*4)))/(Weight!D8*Weight!D9),0) -> 2.3418978 | M4: =IF(AND(Weight!D8>10,Weight!D8<=12),SUM(J4*12*((Weight!D9/1.334)+((Weight!D9/12)*2)))/(Weight!D8*Weight!D9),0) -> 1.9814811 | N4: =SUM(M4-L4) -> -0.36041667
A5: 2x10 Joists @ 16" o.c.: | B5: =SUM(L6-B3) -> 0.87649714 | I5: 2x8 Joists @ 16" o.c.: | J5: =IF(Weight!H6="pmi",2.0583,2.85) -> 2.85 | K5: =IF(Weight!H6="pmi","#2 HF","#2 SYP") -> #2 SYP | L5: =SUM(J5*12*65)/700 -> 3.1757143 | M5: =SUM(J5*12*55)/700 -> 2.6871429 | N5: =SUM(M5-L5) -> -0.48857143
A6: 2x12 Joists @ 16" o.c.: | B6: =SUM(L7-B3) -> 1.7522143 | I6: 2x10 Joists @ 16" o.c.: | J6: =IF(Weight!H6="pmi",2.6266,3.6366) -> 3.6366 | K6: =IF(Weight!H6="pmi","#2 HF","#2 SYP") -> #2 SYP | L6: =SUM(J6*12*65)/700 -> 4.0522114 | M6: =SUM(J6*12*55)/700 -> 3.4287943 | N6: =SUM(M6-L6) -> -0.62341714
A7: 2x6 Treated Joists @ 16" o.c.: | B7: =SUM(L8-B3) -> -0.55992857 | I7: 2x12 Joists @ 16" o.c.: | J7: =IF(Weight!H6="pmi",3.1941,4.4225) -> 4.4225 | K7: =IF(Weight!H6="pmi","#2 HF","#2 SYP") -> #2 SYP | L7: =SUM(J7*12*65)/700 -> 4.9279286 | M7: =SUM(J7*12*55)/700 -> 4.1697857 | N7: =SUM(M7-L7) -> -0.75814286
A8: 2x8 Treated Joists @ 16" o.c.: | B8: =SUM(L9-B3) -> 0.272064 | I8: 2x6 Treated Joists @ 16" o.c.: | J8: =IF(Weight!H6="pmi",1.7425,2.3475) -> 2.3475 | K8: =IF(Weight!H6="pmi","#2 HF","#2 SYP") -> #2 SYP | L8: =SUM(J8*12*65)/700 -> 2.6157857 | M8: =SUM(J8*12*55)/700 -> 2.2133571 | N8: =SUM(M8-L8) -> -0.40242857
A9: 2x10 Treated Joists @ 16" o.c.: | B9: =SUM(L10-B3) -> 1.2229286 | I9: 2x8 Treated Joists @ 16" o.c.: | J9: =IF(Weight!H6="pmi",2.2975,3.09416) -> 3.09416 | K9: =IF(Weight!H6="pmi","#2 HF","#2 SYP") -> #2 SYP | L9: =SUM(J9*12*65)/700 -> 3.4477783 | M9: =SUM(J9*12*55)/700 -> 2.9173509 | N9: =SUM(M9-L9) -> -0.53042743
A10: 2x12 Treated Joists @ 16" o.c.: | B10: =SUM(L11-B3) -> 2.1737486 | I10: 2x10 Treated Joists @ 16" o.c.: | J10: =IF(Weight!H6="pmi",2.9308,3.9475) -> 3.9475 | K10: =IF(Weight!H6="pmi","#2 HF","#2 SYP") -> #2 SYP | L10: =SUM(J10*12*65)/700 -> 4.3986429 | M10: =SUM(J10*12*55)/700 -> 3.7219286 | N10: =SUM(M10-L10) -> -0.67671429
A11: 3/4" Floor Decking: | B11: 2.2 | C11: base component | I11: 2x12 Treated Joists @ 16" o.c.: | J11: =IF(Weight!H6="pmi",3.565,4.8008) -> 4.8008 | K11: =IF(Weight!H6="pmi","#2 HF","#2 SYP") -> #2 SYP | L11: =SUM(J11*12*65)/700 -> 5.3494629 | M11: =SUM(J11*12*55)/700 -> 4.5264686 | N11: =SUM(M11-L11) -> -0.82299429
A12: 1-1/8" Floor Decking: | B12: =SUM(3.3-B11) -> 1.1 | I12: Used this webiste for Lumber Weights based on Grade (8% moisture content assumed untreated / 35% moisture content for treated):
A13: (2) Layers 3/4" Floor Decking: | B13: =SUM(4.4-B11) -> 2.2 | I13: https://www.builderscalculator.com/lumber-weight-calculator/
A14: 22ga B-Deck: | B14: 1.6
A15: 20ga B-Deck: | B15: 2
A16: 3/4" Concrete Sub-Floor: | B16: =SUM(5.32-B11) -> 3.12
A17: 1/4" Hardibacker: | B17: 1.9 | C17: base component
A18: 1/4" Fiberock | B18: 1.4 | C18: base component
A19: 1/2" Fiberock | B19: 2.1 | C19: base component
A20: 3/4" MegaBoard: | B20: 3.9 | C20: base component
A21: 1/8" VCT | B21: 1.4 | C21: base component
A22: No Flooring: | B22: =SUM(-B21) -> -1.4
A23: Rolled Carpet: | B23: =SUM(0.6-B21) -> -0.8
A24: Carpet Squares: | B24: =SUM(1.4-B21) -> 0
A25: .080 Sheet Vinyl: | B25: =SUM(0.8-B21) -> -0.6
A26: Vinyl Plank Flooring: | B26: =SUM(2.3-B21) -> 0.9
A27: Ceramic with Grout (Include Backer Bd): | B27: =SUM(4.9-B21) -> 3.5 | C27: (3/8" ceramic with 1/8" grout spacers and grout is included / need to add min. 1/4" underlayment if chosen)
A28: Shepweave II Bottom Board: | B28: 0.24 | C28: base component
A29: 30ga Galv. Bottom Board: | B29: =SUM(0.656-B28) -> 0.416
A30: 29GA PBU Panel: | B30: =SUM(0.656-B28) -> 0.416
A32: Roofing:
A33: 2x8 Rafters @ 16" o.c.: | B33: =L35 -> 2.6832462 | C33: base component | I33: Rafters | J33: PLF | K33: Grade | L33: PSF | M33: Overhang along sides ## | N33: Overhang @ Ends
A34: 2x6 Rafters @ 16" o.c.: | B34: =SUM(L34-B33) -> -0.64727429 | I34: 2x6 | J34: =IF(Weight!H6="pmi",1.5616,2.1625) -> 2.1625 | K34: =IF(Weight!H6="pmi","#2 HF","#2 SYP") -> #2 SYP | L34: =SUM(J34*(Weight!D8+0.33)*((Weight!D9/1.334)+((Weight!D9/12)*2)))/(Weight!D8*Weight!D9) -> 2.0359719 | M34: =SUM(J34*(Weight!D8+0.33+Weight!E42/12)*((Weight!D9/1.334)+((Weight!D9/12)*2))+((Weight!E42/12)*Weight!D9*M30))/(Weight!D8*Weight!D9)-L34 -> 0.027520571 | N34: =SUM(J34*(Weight!D8)*(Weight!D9+(Weight!E43/12*2)/1.334)+((Weight!D9/12)*2)+(40*(Weight!E43/12)*2))/(Weight!D8*Weight!D9)-L34 -> 0.16990749
A35: 2x10 Rafters @ 16" o.c.: | B35: =SUM(L36-B33) -> 1.0519598 | I35: 2x8 | J35: =IF(Weight!H6="pmi",2.0583,2.85) -> 2.85 | K35: =IF(Weight!H6="pmi","#2 HF","#2 SYP") -> #2 SYP | L35: =SUM(J35*(Weight!D8+0.33)*((Weight!D9/1.334)+((Weight!D9/12)*2)))/(Weight!D8*Weight!D9) -> 2.6832462 | M35: =SUM(J35*(Weight!D8+0.33+Weight!E42/12)*((Weight!D9/1.334)+((Weight!D9/12)*2))+((Weight!E42/12)*Weight!D9*M30))/(Weight!D8*Weight!D9)-L35 -> 0.036269886 | N35: =SUM(J35*(Weight!D8)*(Weight!D9+(Weight!E43/12*2)/1.334)+((Weight!D9/12)*2)+(40*(Weight!E43/12)*2))/(Weight!D8*Weight!D9)-L35 -> 0.21320086
A36: 2x12 Rafters @ 16" o.c.: | B36: =SUM(L37-B33) -> 1.8591694 | I36: 2x10++ | J36: =IF(Weight!H6="pmi",2.6266,3.6366) -> 3.6366 | K36: =IF(Weight!H6="pmi","#2 HF","#2 SYP") -> #2 SYP | L36: =SUM(J36*(Weight!D8+0.33)*((Weight!D9/1.334)+((Weight!D9/12)*3)))/(Weight!D8*Weight!D9) -> 3.735206 | M36: =SUM(J36*(Weight!D8+0.33+Weight!E42/12)*((Weight!D9/1.334)+((Weight!D9/12)*4.5)))/(Weight!D8*Weight!D9)-L36 -> 0.52387876 | N36: =SUM(J36*(Weight!D8)*(Weight!D9+(Weight!E43/12*2)/1.334)+((Weight!D9/12)*2)+(40*(Weight!E43/12)*2))/(Weight!D8*Weight!D9)-L36 -> -0.048649106
A37: Wood Truss @ 16" o.c. | B37: =SUM(L38-B33) -> 2.2910752 | C37: (Truss is assumed to be 62lbs @ 12' long) | I37: 2x12++ | J37: =IF(Weight!H6="pmi",3.1941,4.4225) -> 4.4225 | K37: =IF(Weight!H6="pmi","#2 HF","#2 SYP") -> #2 SYP | L37: =SUM(J37*(Weight!D8+0.33)*((Weight!D9/1.334)+((Weight!D9/12)*3)))/(Weight!D8*Weight!D9) -> 4.5424156 | M37: =SUM(J37*(Weight!D8+0.33+Weight!E42/12)*((Weight!D9/1.334)+((Weight!D9/12)*4.5)))/(Weight!D8*Weight!D9)-L37 -> 0.63709338 | N37: =SUM(J37*(Weight!D8)*(Weight!D9+(Weight!E43/12*2)/1.334)+((Weight!D9/12)*2)+(40*(Weight!E43/12)*2))/(Weight!D8*Weight!D9)-L37 -> -0.066451961
A38: 8" Steel Rafter (16ga) @ 16" o.c.: | B38: =SUM(L39-B33) -> -0.35776615 | C38: (Asumed 2" Flange) | I38: Truss** | J38: 5.166 | K38: Wood | L38: =SUM(J38*(Weight!D8+0.33)*((Weight!D9/1.334)+((Weight!D9/12)*2.25)))/(Weight!D8*Weight!D9) -> 4.9743214 | M38: =SUM(J38*(Weight!D8+0.33+Weight!E42/12)*((Weight!D9/1.334)+((Weight!D9/12)*2.75)))/(Weight!D8*Weight!D9)-L38 -> 0.29139769 | N38: =SUM(J38*(Weight!D8+0.33)*(Weight!D9+(Weight!E43/12*2)/1.334)+((Weight!D9/12)*2)+(40*(Weight!E43/12)*2))/(Weight!D8*Weight!D9)-L38 -> 0.39115863
A39: 8" Steel Rafter (14ga) @ 16" o.c.: | B39: =SUM(L40-B33) -> 0.22595757 | C39: (Asumed 2" Flange) | I39: 8" (16ga) | J39: 2.47 | K39: Steel | L39: =SUM(J39*(Weight!D8+0.33)*((Weight!D9/1.334)+((Weight!D9/12)*2)))/(Weight!D8*Weight!D9) -> 2.32548 | M39: =SUM(J39*(Weight!D8+0.33+Weight!E42/12)*((Weight!D9/1.334)+((Weight!D9/12)*3)))/(Weight!D8*Weight!D9)-L39 -> 0.24578645 | N39: =SUM(J39*(Weight!D8+0.33)*(Weight!D9+(Weight!E43/12*2)/1.334)+((Weight!D9/12)*2)+(40*(Weight!E43/12)*2))/(Weight!D8*Weight!D9)-L39 -> 0.25749952
A40: 10" Steel Rafter (16ga) @ 16" o.c.: | B40: =SUM(L41-B33) -> 0.0094148988 | C40: (Asumed 2" Flange) | I40: 8" (14ga) | J40: 3.09 | K40: Steel | L40: =SUM(J40*(Weight!D8+0.33)*((Weight!D9/1.334)+((Weight!D9/12)*2)))/(Weight!D8*Weight!D9) -> 2.9092037 | M40: =SUM(J40*(Weight!D8+0.33+Weight!E42/12)*((Weight!D9/1.334)+((Weight!D9/12)*3)))/(Weight!D8*Weight!D9)-L40 -> 0.30748183 | N40: =SUM(J40*(Weight!D8+0.33)*(Weight!D9+(Weight!E43/12*2)/1.334)+((Weight!D9/12)*2)+(40*(Weight!E43/12)*2))/(Weight!D8*Weight!D9)-L40 -> 0.31366834
A41: 10" Steel Rafter (14ga) @ 16" o.c.: | B41: =SUM(L42-B33) -> 0.67787271 | C41: (Asumed 2" Flange) | I41: 10" (16ga) | J41: 2.86 | K41: Steel | L41: =SUM(J41*(Weight!D8+0.33)*((Weight!D9/1.334)+((Weight!D9/12)*2)))/(Weight!D8*Weight!D9) -> 2.6926611 | M41: =SUM(J41*(Weight!D8+0.33+Weight!E42/12)*((Weight!D9/1.334)+((Weight!D9/12)*3)))/(Weight!D8*Weight!D9)-L41 -> 0.28459483 | N41: =SUM(J41*(Weight!D8+0.33)*(Weight!D9+(Weight!E43/12*2)/1.334)+((Weight!D9/12)*2)+(40*(Weight!E43/12)*2))/(Weight!D8*Weight!D9)-L41 -> 0.29283152
...

Sheet Assemblies
A1: Floor Assembly: | F1: PSF | G1: Unit
A2: 2x8 #2 HF Floor Joists: | F2: =IF(AND(Weight!B55="12"" I-Beam TX Perimeter:",Weight!E55=1),Materials!B3,IF(Weight!E55=1,0,Materials!B3)) -> 3.1757143 | G2: sq. ft.
A3: 3/4" T&G Decking: | F3: =Materials!B11 -> 2.2 | G3: sq. ft.
A4: =IF(Weight!H6="PMI",Materials!A147,Materials!A148) -> R-30 Fiberglass: | F4: =INDEX(Materials!B145:B150,MATCH(Assemblies!A4,Materials!A145:A150,0)) -> 0.33 | G4: sq. ft.
A5: Shepweave II Bottom Board: | F5: =Materials!B30 -> 0.416 | G5: sq. ft.
A6: 1/8" VCT: | F6: =Materials!B21 -> 1.4 | G6: sq. ft.
A7: Fasteners / Nails / Glue | F7: =Materials!B181 -> 0.1 | G7: sq. ft.
F8: =SUM(F2:F7) -> 7.6217143 | G8: Total per Sq. Ft.
A10: Roof Assembly:
A11: 30", 4-Layer Plywood matebeam (2-Sides): | F11: =IF(Weight!D16="y",0,Materials!B68) -> 0 | G11: sq. ft.
A12: 2x8 #2 HF Rafters @ 16" o.c. | F12: =Materials!B33 -> 2.6832462 | G12: sq. ft.
A13: 1/2" CDX Plywood Sheathing: | F13: =Materials!B49 -> 1.5 | G13: sq. ft.
A14: 1/2" Gypsum Roof Deck: | F14: =Materials!B50 -> 2.2 | G14: sq. ft.
A15: 45 Mil EPDM: | F15: =Materials!B42 -> 0.29 | G15: sq. ft.
A16: Netting: | F16: =Materials!B78 -> 0.05 | G16: sq. ft.
A17: =IF(Weight!H6="PMI",Materials!A147,Materials!A150) -> R-38 Fiberglass: | F17: =INDEX(Materials!B145:B150,MATCH(Assemblies!A17,Materials!A145:A150,0)) -> 0.44 | G17: sq. ft.
A18: Suspended Ceiling / Lights : | F18: =Materials!B77 -> 1.7 | G18: sq. ft.
A19: Fasteners / Nails / Glue: | F19: =Materials!B181 -> 0.1 | G19: sq. ft.
F20: =IF(Weight!H6="PMI",SUM(F11:F19),SUM(F11:F13,F15:F19)) -> 6.7632462 | G20: Total per Sq. Ft. | I20: `
A22: Exterior Wall Assembly:
A23: 2x6 #2 HF Studs (Top & Bottom Plates Included): | F23: =Materials!B83 -> 2.2717172 | G23: sq. ft.
A24: 1/2" Gypsum: | F24: =Materials!B90 -> 2 | G24: sq. ft.
A25: R-19 Insulation: | F25: =Materials!B147 -> 0.22 | G25: sq. ft.
A26: 7/16" LP Smart Panel: | F26: =Materials!B107 -> 1.7 | G26: sq. ft.
A27: House Wrap / PlyDry | F27: =Materials!B114 -> 0.01 | G27: sq. ft.
A28: Windows / Doors: | F28: =Materials!B182 -> 0.1 | G28: sq. ft.
A29: Fasteners / Nails / Glue: | F29: =Materials!B181 -> 0.1 | G29: sq. ft.
F30: =SUM(F23:F29) -> 6.4017172 | G30: Total per Sq. Ft.
A32: Interior Wall Assembly: (Assumed 12' long, 10' tall)
A33: 2x4 #2 HF Studs (Top & Bottom Plates Included): | F33: =Materials!B117 -> 1.4452848 | G33: sq. ft.
A34: 1/2" Gypsum (Both sides): | F34: =Materials!B121 -> 4 | G34: sq. ft.
A35: Fasteners / Nails / Glue: | F35: =Materials!B181 -> 0.1 | G35: sq. ft.
F36: =SUM(F33:F35) -> 5.5452848 | G36: Total per Sq. Ft.
A38: Steel Girder Assembly (Assumed to be tapered)
D39: Truss Peak Ht (in): | E39: 30 | K39: Steel Angle Weight: | P39: PLF | Q39: Total (12' tall)
D40: Truss Heel Ht (in): | E40: =SUM(E39-(F46/2)*(E42)) -> 23.115 | K40: Steel Angle: | L40: PLF | O40: HSS3x3x3/16 Steel Post: | P40: 6.87 | Q40: =SUM(P40*12)*2+50 -> 214.88 | R40: <--100 lbs added for (4) Posts Caps / Assumed (2) Posts total
D41: Truss Length (ft): | E41: =Weight!D9 -> 56 | K41: L5x3x5/16" | L41: 8.19 | O41: HSS3.5x3.5x1/4 Steel Post: | P41: 10.51 | Q41: =SUM(P41*12)*2+50 -> 302.24 | R41: <--100 lbs added for (4) Posts Caps / Assumed (2) Posts total
D42: Pitch: | E42: 0.25 | K42: L5x3x3/8" | L42: 9.74 | O42: 3.5x5.25 LVL Post: | P42: 4.9 | Q42: =SUM(P42*12)*2 -> 117.6
D43: Truss Sq. Ft.: | E43: =SUM((E39/12)*E41)-(E39*E42)*2 -> 125 | K43: L5x3x7/16" | L43: 11.3 | O43: 5.25x5.25 LVL Post: | P43: 7.1 | Q43: =SUM(P43*12)*2 -> 170.4
D44: Angle Type: | E44: PLF: | F44: Length (ft) | G44: Weight: | K44: L5x3x1/2" | L44: 12.8
...
