Workbook

Sheet General Info
A3: General Information Sheet | D3: NO TOUCHY, TOUCHY IF TEXT IS BLACK
A5: Job: | B5: 56x60 Office | C5: Job Name
A6: Job #: | B6: 24289
A7: Date: | B7: 45601
A8: By:
A9: Chk'd By:
A10: Load Solar Time: | B10: 5:00pm
A11: Zone: | B11: N/A
A12: total building square footage | B12: 3600 | C12: this is used for Roof and Floor Only
A14: Outside Dsgn Temp Heating (F): | B14: 25 | C14: based on location, If Triple code use -10
A15: Outside Dsgn Temp Cooling (F): | B15: 84 | C15: based on location, If Triple code use 110
A16: Inside Dsgn Temp Heating (F): | B16: 72 | C16: Per C302.1 IECC (Energy Code)
A17: Inside Dsgn Temp Cooling (F): | B17: 75 | C17: Per C302.1 IECC (Energy Code)
F18: Standard
A19: Roof U value | B19: =1/50 -> 0.02 | C19: 1 divided by r-value | E19: Typically: | F19: R-51 | G19: R-30+R-20 (non Vented Roof)
A20: Wall U value (Side Walls Only) | B20: =1/(21+5) -> 0.038461538 | C20: 1 divided by r-value | F20: R-21 | G20: R-21+R3.2CI (Idaho sidewalls Only)
A21: Wall U value (End Walls Only) | B21: =1/(21+5) -> 0.038461538 | C21: 1 divided by r-value | F21: R-21 | G21: R-21+R5 (Triple Code per WA / 2021 IECC, ALL Walls)
A22: Floor U value | B22: =1/30 -> 0.033333333 | C22: 1 divided by r-value | F22: R-30
A23: Glass U value | B23: 0.28 | C23: Min U-Value Per 2021 IECC
A24: Glass SC | B24: 0.68 | C24: Double Glass with Thermal Break and 1/4" Air Space
A25: Door U value | B25: =1/12 -> 0.083333333 | C25: Typical (1 divided by r-value)
A26: Roll Up Door | B26: =1/7.7 -> 0.12987013 | C26: Typical (1 divided by r-value)
A27: Store Front Door Value | B27: =1/3.4 -> 0.29411765
A28: People Sensible | B28: 250
A29: People Latent | B29: 200 | C29: Occupant at moderately active office work
A30: Lights per SF | B30: 1
A31: Computers | B31: 250
A32: # of Exhaust Fans | B32: 2
A34: # of Doors @ 20sq ft (36x80) | B34: 2 | C34: Quantity of doors
A35: # of Doors @ 21sq ft (36x84) | B35: 0
A36: # of Doors @ 32 sq ft (48x96) | B36: 0
A37: other doors (28sf) | B37: 0
A39: Group B - Office Facilities
A40: Office sq ft | B40: 0 | C40: Total area Square Footage.
A41: Lobby Area sq ft | B41: 0
A42: Conference Room sq ft | B42: 0 | D42: Printer | E42: 130
A43: Break area/kitchen sq ft | B43: 0
A44: Telephone / Data Room sq ft | B44: 0
A45: Printer Room | B45: 0
A47: Wall SQ FT | C47: Wood | D47: Container | E47: Windows | F47: Store Front
...

Sheet ASHRAE data
B3: Design Criteria that this sheet is currently set for is in blue.
B7: 44 Degree N. Latitude
C8: Jan. | D8: Feb. | E8: Mar. | F8: Apr. | G8: May. | H8: June | I8: July | J8: Aug. | K8: Sep. | L8: Oct. | M8: Nov. | N8: Dec.
B9: North | C9: 17 | D9: 22 | E9: 27 | F9: 33 | G9: 36 | H9: 47 | I9: 37 | J9: 34 | K9: 28 | L9: 23 | M9: 18 | N9: 15
B10: NE | C10: 17 | D10: 43 | E10: 87 | F10: 136 | G10: 162 | H10: 169 | I10: 159 | J10: 132 | K10: 80 | L10: 42 | M10: 18 | N10: 15
B11: East | C11: 138 | D11: 178 | E11: 211 | F11: 221 | G11: 219 | H11: 215 | I11: 215 | J11: 214 | K11: 198 | L11: 171 | M11: 135 | N11: 115
B12: SE | C12: 232 | D12: 246 | E12: 238 | F12: 210 | G12: 183 | H12: 171 | I12: 179 | J12: 202 | K12: 227 | L12: 237 | M12: 227 | N12: 217
B13: South | C13: 252 | D13: 247 | E13: 218 | F13: 171 | G13: 132 | H13: 115 | I13: 128 | J13: 165 | K13: 211 | L13: 239 | M13: 248 | N13: 246
B14: SW | C14: 232 | D14: 246 | E14: 238 | F14: 210 | G14: 183 | H14: 171 | I14: 179 | J14: 202 | K14: 227 | L14: 237 | M14: 227 | N14: 217
B15: W | C15: 138 | D15: 178 | E15: 211 | F15: 221 | G15: 219 | H15: 215 | I15: 215 | J15: 214 | K15: 198 | L15: 171 | M15: 135 | N15: 115
B16: NW | C16: 17 | D16: 43 | E16: 87 | F16: 136 | G16: 162 | H16: 169 | I16: 159 | J16: 132 | K16: 80 | L16: 42 | M16: 18 | N16: 15
B17: Horiz. | C17: 109 | D17: 160 | E17: 206 | F17: 240 | G17: 257 | H17: 261 | I17: 254 | J17: 236 | K17: 199 | L17: 157 | M17: 109 | N17: 89
B19: SOLER TIME (CLF) FOR GLASS
B20: WALL TYPE
B21: LIGHT | C21: 0.125 | D21: 0.14583333 | E21: 0.16666667 | F21: 0.1875 | G21: 0.20833333 | H21: 0.22916667 | I21: 0.25 | J21: 0.27083333 | K21: 0.3125
B22: North | C22: 0.82 | D22: =(C22+E22)/2 -> 0.785 | E22: 0.75 | F22: =(E22+G22)/2 -> 0.75 | G22: 0.75 | H22: =(G22+I22)/2 -> 0.795 | I22: 0.84 | J22: =(I22+K22)/2 -> 0.725 | K22: 0.61
B23: NE | C23: 0.28 | D23: =(C23+E23)/2 -> 0.27 | E23: 0.26 | F23: =(E23+G23)/2 -> 0.245 | G23: 0.23 | H23: =(G23+I23)/2 -> 0.21 | I23: 0.19 | J23: =(I23+K23)/2 -> 0.17 | K23: 0.15
B24: East | C24: 0.29 | D24: =(C24+E24)/2 -> 0.27 | E24: 0.25 | F24: =(E24+G24)/2 -> 0.235 | G24: 0.22 | H24: =(G24+I24)/2 -> 0.205 | I24: 0.19 | J24: =(I24+K24)/2 -> 0.17 | K24: 0.15
B25: SE | C25: 0.37 | D25: =(C25+E25)/2 -> 0.35 | E25: 0.33 | F25: =(E25+G25)/2 -> 0.305 | G25: 0.28 | H25: =(G25+I25)/2 -> 0.26 | I25: 0.24 | J25: =(I25+K25)/2 -> 0.215 | K25: 0.19
B26: South | C26: 0.59 | D26: =(C26+E26)/2 -> 0.545 | E26: 0.5 | F26: =(E26+G26)/2 -> 0.465 | G26: 0.43 | H26: =(G26+I26)/2 -> 0.395 | I26: 0.36 | J26: =(I26+K26)/2 -> 0.32 | K26: 0.28
B27: SW | C27: 0.6 | D27: =(C27+E27)/2 -> 0.63 | E27: 0.66 | F27: =(E27+G27)/2 -> 0.66 | G27: 0.66 | H27: =(G27+I27)/2 -> 0.62 | I27: 0.58 | J27: =(I27+K27)/2 -> 0.505 | K27: 0.43
B28: W | C28: 0.45 | D28: =(C28+E28)/2 -> 0.51 | E28: 0.57 | F28: =(E28+G28)/2 -> 0.605 | G28: 0.64 | H28: =(G28+I28)/2 -> 0.625 | I28: 0.61 | J28: =(I28+K28)/2 -> 0.525 | K28: 0.44
B29: NW | C29: 0.33 | D29: =(C29+E29)/2 -> 0.4 | E29: 0.47 | F29: =(E29+G29)/2 -> 0.53 | G29: 0.59 | H29: =(G29+I29)/2 -> 0.595 | I29: 0.6 | J29: =(I29+K29)/2 -> 0.51 | K29: 0.42
B30: Horiz. | C30: 0.73 | D30: =(C30+E30)/2 -> 0.66 | E30: 0.59 | F30: =(E30+G30)/2 -> 0.59 | G30: 0.59 | H30: =(G30+I30)/2 -> 0.53 | I30: 0.47 | J30: =(I30+K30)/2 -> 0.42 | K30: 0.37
B31: WALL TYPE
B32: MEDIUM | C32: 0.125 | D32: 0.14583333 | E32: 0.16666667 | F32: 0.1875 | G32: 0.20833333 | H32: 0.22916667 | I32: 0.25 | J32: 0.27083333 | K32: 0.3125
B33: North | C33: 0.76 | D33: =(C33+E33)/2 -> 0.75 | E33: 0.74 | F33: =(E33+G33)/2 -> 0.745 | G33: 0.75 | H33: =(G33+I33)/2 -> 0.77 | I33: 0.79 | J33: =(I33+K33)/2 -> 0.7 | K33: 0.61
B34: NE | C34: 0.28 | D34: =(C34+E34)/2 -> 0.27 | E34: 0.26 | F34: =(E34+G34)/2 -> 0.245 | G34: 0.23 | H34: =(G34+I34)/2 -> 0.22 | I34: 0.21 | J34: =(I34+K34)/2 -> 0.19 | K34: 0.17
B35: East | C35: 0.29 | D35: =(C35+E35)/2 -> 0.275 | E35: 0.26 | F35: =(E35+G35)/2 -> 0.245 | G35: 0.23 | H35: =(G35+I35)/2 -> 0.22 | I35: 0.21 | J35: =(I35+K35)/2 -> 0.19 | K35: 0.17
B36: SE | C36: 0.36 | D36: =(C36+E36)/2 -> 0.345 | E36: 0.33 | F36: =(E36+G36)/2 -> 0.31 | G36: 0.29 | H36: =(G36+I36)/2 -> 0.27 | I36: 0.25 | J36: =(I36+K36)/2 -> 0.23 | K36: 0.21
B37: South | C37: 0.53 | D37: =(C37+E37)/2 -> 0.5 | E37: 0.47 | F37: =(E37+G37)/2 -> 0.44 | G37: 0.41 | H37: =(G37+I37)/2 -> 0.385 | I37: 0.36 | J37: =(I37+K37)/2 -> 0.325 | K37: 0.29
B38: SW | C38: 0.53 | D38: =(C38+E38)/2 -> 0.555 | E38: 0.58 | F38: =(E38+G38)/2 -> 0.585 | G38: 0.59 | H38: =(G38+I38)/2 -> 0.56 | I38: 0.53 | J38: =(I38+K38)/2 -> 0.47 | K38: 0.41
B39: W | C39: 0.4 | D39: =(C39+E39)/2 -> 0.45 | E39: 0.5 | F39: =(E39+G39)/2 -> 0.53 | G39: 0.56 | H39: =(G39+I39)/2 -> 0.555 | I39: 0.55 | J39: =(I39+K39)/2 -> 0.48 | K39: 0.41
B40: NW | C40: 0.3 | D40: =(C40+E40)/2 -> 0.36 | E40: 0.42 | F40: =(E40+G40)/2 -> 0.465 | G40: 0.51 | H40: =(G40+I40)/2 -> 0.525 | I40: 0.54 | J40: =(I40+K40)/2 -> 0.465 | K40: 0.39
B41: Horiz. | C41: 0.66 | D41: =(C41+E41)/2 -> 0.61 | E41: 0.56 | F41: =(E41+G41)/2 -> 0.56 | G41: 0.56 | H41: =(G41+I41)/2 -> 0.515 | I41: 0.47 | J41: =(I41+K41)/2 -> 0.425 | K41: 0.38
B42: WALL TYPE
B43: HEAVY | C43: 0.125 | D43: 0.14583333 | E43: 0.16666667 | F43: 0.1875 | G43: 0.20833333 | H43: 0.22916667 | I43: 0.25 | J43: 0.27083333 | K43: 0.3125
B44: North | C44: 0.72 | D44: =(C44+E44)/2 -> 0.71 | E44: 0.7 | F44: =(E44+G44)/2 -> 0.7 | G44: 0.7 | H44: =(G44+I44)/2 -> 0.725 | I44: 0.75 | J44: =(I44+K44)/2 -> 0.66 | K44: 0.57
B45: NE | C45: 0.26 | D45: =(C45+E45)/2 -> 0.25 | E45: 0.24 | F45: =(E45+G45)/2 -> 0.23 | G45: 0.22 | H45: =(G45+I45)/2 -> 0.21 | I45: 0.2 | J45: =(I45+K45)/2 -> 0.185 | K45: 0.17
B46: East | C46: 0.26 | D46: =(C46+E46)/2 -> 0.245 | E46: 0.23 | F46: =(E46+G46)/2 -> 0.225 | G46: 0.22 | H46: =(G46+I46)/2 -> 0.205 | I46: 0.19 | J46: =(I46+K46)/2 -> 0.18 | K46: 0.17
...

Sheet Clg Block - Block
A1: Cooling Load Calc. Sheet
B3: Job: | C3: ='General Info'!B5 -> 56x60 Office | E3: Time: | G3: ='General Info'!B10 -> 5:00pm
B4: Job #: | C4: ='General Info'!B6 -> 24289 | E4: Zone: | G4: Block
B5: Date: | C5: ='General Info'!B7 -> 45601 | E5: Area or Room Name: | G5: Block
B6: By: | C6: ='General Info'!B8 -> 0 | E6: Outside Dsgn Temp (F): | G6: ='General Info'!B15 -> 84
B7: Chk'd By: | C7: ='General Info'!B9 -> 0 | E7: Inside Dsgn Temp (F): | G7: ='General Info'!B17 -> 75
E8: Floor Area (sq. ft.): | G8: ='General Info'!B12 -> 3600
A11: Roof | C11: Area | D11: U-value | E11: DT | I11: Sensible | J11: Latent
C12: =G8 -> 3600 | D12: ='General Info'!B19 -> 0.02 | E12: =G$6-G$7+25 -> 34 | I12: =C12*D12*E12 -> 2448
H13: Subtotal: | I13: =SUM(I12:I12) -> 2448
A15: Wall | C15: Area | D15: U-value | E15: DT | I15: Sensible | J15: Latent
B16: North | C16: ='General Info'!B48 -> 0 | D16: ='General Info'!$B$20 -> 0.038461538 | E16: =G$6-G$7 -> 9 | I16: =C16*D16*E16 -> 0
B17: East | C17: ='General Info'!B49 -> 0 | D17: ='General Info'!$B$21 -> 0.038461538 | E17: =G$6-G$7+5 -> 14 | I17: =C17*D17*E17 -> 0
B18: South | C18: ='General Info'!B50 -> 0 | D18: ='General Info'!$B$20 -> 0.038461538 | E18: =G$6-G$7+5 -> 14 | I18: =C18*D18*E18 -> 0
B19: West | C19: ='General Info'!B51 -> 0 | D19: ='General Info'!$B$21 -> 0.038461538 | E19: =G$6-G$7+5 -> 14 | I19: =C19*D19*E19 -> 0
H20: Subtotal: | I20: =SUM(I16:I19) -> 0
A22: Floor | C22: Area | D22: U-value | E22: DT | I22: Sensible | J22: Latent
C23: =G8 -> 3600 | D23: ='General Info'!B22 -> 0.033333333 | E23: =G$6-G$7 -> 9 | I23: =C23*D23*E23 -> 1080 | Q23: sqft of each space
H24: Subtotal: | I24: =SUM(I23:I23) -> 1080
M25: Outdoor Ventillation Requirments per 2021 IMC section 403.3 (Office Area) | W25: Mixed Air Temp Calculation (TRA x (%TRA) + TOSA x (%TOSA)
A26: Solar | C26: Area | D26: SHGF | E26: CLF | F26: SC | I26: Sensible | J26: Latent | N26: Rp | O26: Pz | P26: Ra | Q26: Az | R26: Occy/1000 s. ft | S26: Total cfm | W26: RA | X26: 1200 | Y26: cfm
B27: North | C27: ='General Info'!E48 -> 0 | D27: 47 | E27: 0.72 | F27: ='General Info'!$B$24 -> 0.68 | I27: =C27*D27*E27*F27 -> 0 | M27: Office Area | N27: 5 | O27: =ROUNDUP(((R27/1000)*Q27),0) -> 0 | P27: 0.06 | Q27: ='General Info'!B40 -> 0 | R27: 5 | S27: =(N27*O27)+(P27*Q27) -> 0 | W27: RAT | X27: 70 | Y27: deg F.
B28: East | C28: ='General Info'!E49 -> 0 | D28: 215 | E28: 0.29 | F28: ='General Info'!$B$24 -> 0.68 | I28: =C28*D28*E28*F28 -> 0 | M28: Lobbies | N28: 5 | O28: =ROUNDUP(((R28/1000)*Q28),1) -> 0 | P28: 0.06 | Q28: ='General Info'!B41 -> 0 | R28: 10 | S28: =(N28*O28)+(P28*Q28) -> 0 | W28: OAT | X28: -14 | Y28: deg F.
B29: South | C29: ='General Info'!E50 -> 0 | D29: 115 | E29: 0.55 | F29: ='General Info'!$B$24 -> 0.68 | I29: =C29*D29*E29*F29 -> 0 | M29: Confrence Rm | N29: 5 | O29: =ROUNDUP(((R29/1000)*Q29),1) -> 0 | P29: 0.06 | Q29: ='General Info'!B42 -> 0 | R29: 50 | S29: =(N29*O29)+(P29*Q29) -> 0 | W29: %RA | X29: 0.7 | Y29: %
B30: W | C30: ='General Info'!E51 -> 0 | D30: 215 | E30: 0.54 | F30: ='General Info'!$B$24 -> 0.68 | I30: =C30*D30*E30*F30 -> 0 | M30: Break Area | N30: 7.5 | O30: =ROUNDUP(((R30/1000)*Q30),1) -> 0 | P30: 0.18 | Q30: ='General Info'!B43 -> 0 | R30: 70 | S30: =(N30*O30)+(P30*Q30) -> 0 | W30: %OSA | X30: 0.3 | Y30: %
B31: Horiz. | C31: 0 | D31: 261 | E31: 0.64 | F31: ='General Info'!$B$24 -> 0.68 | I31: =C31*D31*E31*F31 -> 0 | M31: Tele/Data Room | N31: 5 | O31: =ROUNDUP(((R31/1000)*Q31),1) -> 0 | P31: 0.06 | Q31: ='General Info'!B44 -> 0 | R31: 60 | S31: =(N31*O31)+(P31*Q31) -> 0
H32: Subtotal: | I32: =SUM(I27:I31) -> 0 | M32: Printer Room | N32: 5 | O32: =ROUNDUP(((R32/1000)*Q32),0) -> 0 | P32: 0.06 | Q32: ='General Info'!B45 -> 0 | R32: 4 | S32: =(N32*O32)+(P32*Q32) -> 0 | W32: MAT= | X32: =(X27*X29)+(X30*X28) -> 44.8 | Y32: deg.F
M33: Subtotal | O33: =SUM(O27:O32) -> 0 | Q33: =SUM(Q27:Q32) -> 0 | S33: =SUM(S27:S32) -> 0
A34: Glazing | C34: Area | D34: U-value | E34: DT | I34: Sensible | J34: Latent | M34: OSA= | N34: =S33 -> 0 | O34: =SUM(O27:O32) -> 0 | W34: BTU Requirements
C35: =SUM(C27:C31) -> 0 | D35: ='General Info'!B23 -> 0.28 | E35: =G$6-G$7 -> 9 | I35: =C35*D35*E35 -> 0 | W35: SAT | X35: 105 | Y35: deg F.
H36: Subtotal: | I36: =SUM(I35:I35) -> 0 | M36: Pz=People per zone | W36: Delta "T" | X36: =X35-X32 -> 60.2 | Y36: deg F.
M37: Az=Zone floor area | W37: AS Constant | X37: 1.05
A38: Metal Door | C38: Area | D38: U-value | E38: DT | I38: Sensible | J38: Latent | M38: Rp=CFM/ person (table 403.3.1.1) | W38: Total BTU | X38: =X26*X36*X37 -> 75852 | Y38: BTU/H
C39: =(20*'General Info'!B34)+(21*'General Info'!B35)+(32*'General Info'!B36) -> 40 | D39: ='General Info'!B25 -> 0.083333333 | E39: =G$6-G$7 -> 9 | I39: =C39*D39*E39 -> 30 | M39: Ra=CFM/Ft (table 403.3.1.1) | W39: Total KW | X39: =X38/3412 -> 22.23095 | Y39: kW
C40: =(32*'General Info'!B37) -> 0 | D40: ='General Info'!B26 -> 0.12987013 | E40: =G$6-G$7 -> 9 | I40: =C40*D40*E40 -> 0 | M40: Occupancy per 1000 sq. f.t (table 403.3.1.1)
H41: Subtotal: | I41: =SUM(I39:I40) -> 30
M42: Outdoor Ventillation Requirments per 2021 IMC section 403.3 (Education)
A43: Storefront Door | C43: Area | D43: U-value | E43: DT | I43: Sensible | J43: Latent | N43: Rp | O43: Pz | P43: Ra | Q43: Az | R43: Occy/1000 s. ft | S43: Total cfm
C44: 0 | D44: ='General Info'!B27 -> 0.29411765 | E44: =G$6-G$7 -> 9 | I44: =C44*D44*E44 -> 0 | M44: Art Classroom | N44: 10 | O44: =Q44/1000*R44 -> 0 | P44: 0.18 | Q44: ='General Info'!B54 -> 0 | R44: 20 | S44: =(N44*O44)+(P44*Q44) -> 0
H45: Subtotal: | I45: =SUM(I44:I44) -> 0 | M45: Auditoriums | N45: 5 | O45: =Q45/1000*R45 -> 0 | P45: 0.06 | Q45: ='General Info'!B55 -> 0 | R45: 150 | S45: =(N45*O45)+(P45*Q45) -> 0
...

Sheet Htg Block - Block
A1: Heating Load Calc. Sheet
B3: Job: | C3: ='General Info'!B5 -> 56x60 Office | E3: Time: | G3: ='General Info'!B10 -> 5:00pm
B4: Job #: | C4: ='General Info'!B6 -> 24289 | E4: Zone: | G4: ='Clg Block - Block'!G4:H4 -> Block
B5: Date: | C5: ='General Info'!B7 -> 45601 | E5: Area or Room Name: | G5: ='Clg Block - Block'!G5:H5 -> Block
B6: By: | C6: ='General Info'!B8 -> 0 | E6: Outside Dsgn Temp (F): | G6: ='General Info'!B14 -> 25
B7: Chk'd By: | C7: ='General Info'!B9 -> 0 | E7: Inside Dsgn Temp (F): | G7: ='General Info'!B16 -> 72
E8: Floor Area (sq. ft.): | G8: ='General Info'!B12 -> 3600
A11: Roof | C11: Area | D11: U-value | E11: DT | I11: Sensible
C12: ='Clg Block - Block'!C12 -> 3600 | D12: ='General Info'!B19 -> 0.02 | E12: =G7-G6 -> 47 | I12: =C12*D12*E12 -> 3384
H13: Subtotal: | I13: =SUM(I12:I12) -> 3384
A15: Floor | C15: Area | D15: U-value | E15: DT | I15: Sensible
C16: ='Clg Block - Block'!G8 -> 3600 | D16: ='General Info'!B22 -> 0.033333333 | E16: 40 | I16: =C16*D16*E16 -> 4800
H17: Subtotal: | I17: =SUM(I16:I16) -> 4800
A19: Wall | C19: Area | D19: U-value | E19: DT | I19: Sensible
B20: North | C20: ='General Info'!B48 -> 0 | D20: ='Clg Block - Block'!D16 -> 0.038461538 | E20: =G7-G6 -> 47 | I20: =C20*D20*E20 -> 0
B21: East | C21: ='General Info'!B49 -> 0 | D21: ='Clg Block - Block'!D17 -> 0.038461538 | E21: =G7-G6 -> 47 | I21: =C21*D21*E21 -> 0
B22: South | C22: ='General Info'!B50 -> 0 | D22: ='Clg Block - Block'!D18 -> 0.038461538 | E22: =G7-G6 -> 47 | I22: =C22*D22*E22 -> 0
B23: West | C23: ='General Info'!B51 -> 0 | D23: ='Clg Block - Block'!D19 -> 0.038461538 | E23: =G7-G6 -> 47 | I23: =C23*D23*E23 -> 0
H24: Subtotal: | I24: =SUM(I20:I23) -> 0
A26: Metal Door | C26: Area | D26: U-value | E26: DT | I26: Sensible
C27: ='Clg Block - Block'!C39 -> 40 | D27: ='General Info'!B25 -> 0.083333333 | E27: =G$7-G$6 -> 47 | I27: =C27*D27*E27 -> 156.66667
C28: ='Clg Block - Block'!C40 -> 0 | D28: ='General Info'!B26 -> 0.12987013 | E28: =G$7-G$6 -> 47 | I28: =C28*D28*E28 -> 0
H29: Subtotal: | I29: =SUM(I27:I27) -> 156.66667
A31: Storefront Door | C31: Area | D31: U-value | E31: DT | I31: Sensible
C32: ='Clg Block - Block'!C44 -> 0 | D32: ='General Info'!B25*0 -> 0 | E32: =G$7-G$6 -> 47 | I32: =C32*D32*E32 -> 0
H33: Subtotal: | I33: =SUM(I32:I32) -> 0
A35: Glazing | C35: Area | D35: U-value | E35: DT | I35: Sensible
C36: ='Clg Block - Block'!C35 -> 0 | D36: ='General Info'!B23 -> 0.28 | E36: =G7-G6 -> 47 | I36: =C36*D36*E36 -> 0
H37: Subtotal: | I37: =SUM(I36:I36) -> 0
A39: OSA | C39: Ventillation | D39: Exhaust | E39: total | F39: DT | I39: Sensible
C40: OSA | D40: OSA | E40: OSA
C41: ='Clg Block - Block'!N34 -> 0 | D41: ='General Info'!B32*100 -> 200 | E41: =C41+D41 -> 200 | F41: =G7-G6 -> 47 | I41: =E41*F41 -> 9400
H42: Subtotal: | I42: =SUM(I41) -> 9400
H43: Totals for Area: | I43: =I42+I37+I24+I13+I29+I33+I17 -> 17740.667
H44: kW | I44: =I43/3416 -> 5.1934036
