Workbook
Name CFMBardUMC: 'CA Endmount Calc'!$M$3:$O$10
Name CFMtable: 'IMC-UMC Endmount HVAC Calc'!$I$3:$K$11
Name CFMtableDaikin: 'IMC-UMC Rooftop HVAC Calc'!$J$3:$L$10
Name CFMtableDaikinUMC: 'CA Rooftop Calc'!$J$3:$L$10
Name ClimateZone09: 'IMC-UMC Endmount HVAC Calc'!$X$2:$X$18
Name EerEquipment: 'IMC-UMC Endmount HVAC Calc'!$V$23:$V$32
Name EerHVACsize: 'IMC-UMC Endmount HVAC Calc'!$W$22:$AE$22
Name EerTable: 'IMC-UMC Endmount HVAC Calc'!$W$23:$AE$32
Name Exceptions09: 'IMC-UMC Endmount HVAC Calc'!$Y$2:$Y$18
Name FreshAirType: 'IMC-UMC Endmount HVAC Calc'!$I$2:$K$2
Name FRESHairtypeUMC: 'CA Endmount Calc'!$M$2:$O$2
Name HVACsize: 'IMC-UMC Endmount HVAC Calc'!$G$3:$G$11
Name HVACsizeDaikinUMC: 'CA Rooftop Calc'!$H$3:$H$10
Name HVACsizeUMC: 'CA Endmount Calc'!$K$3:$K$10
Name RTUsizes: 'IMC-UMC Rooftop HVAC Calc'!$H$3:$H$10
Name SeerEquipment: 'IMC-UMC Endmount HVAC Calc'!$V$37:$V$46
Name SeerHVACsize: 'IMC-UMC Endmount HVAC Calc'!$W$36:$AE$36
Name SeerTable: 'IMC-UMC Endmount HVAC Calc'!$W$37:$AE$46
Name VENTtypeDaikin: 'IMC-UMC Rooftop HVAC Calc'!$J$2:$L$2
Name VENTtypeDaikinUMC: 'CA Rooftop Calc'!$J$2:$L$2

Sheet Occupant Calculator
A1: CBC Section 1004 / IBC Section 1004
A2: Occupancy Use: | B2: Occupant Load Factor: | C2: Square Footage: | D2: # Of Persons
A3: Accesory Storage, Mechanical Equipment | B3: 300 Gross | C3: 0 | D3: =ROUNDUP((C3/300),0) -> 0
A4: Assembly (Casino) | B4: 11 Gross | C4: 0 | D4: =ROUNDUP((C4/11),1) -> 0
A5: Assembly (With Tables & Chairs) | B5: 15 Net | C5: 0 | D5: =ROUNDUP((C5/15),1) -> 0 | E5: <--- Use for Conference Rooms & Break Rooms
A6: Assembly (Concentrated) | B6: 7 Net | C6: 0 | D6: =ROUNDUP((C6/7),1) -> 0
A7: Assembly (Standing) | B7: 5 Net | C7: 0 | D7: =ROUNDUP((C7/5),1) -> 0
A8: Business (2006 - 2015 IBC) | B8: 100 Gross | C8: 0 | D8: =ROUNDUP((C8/100),1) -> 0
A9: Business (2018 IBC & 2019 CBC) | B9: 150 Gross | C9: 50000 | D9: =ROUNDUP((C9/150),1) -> 333.4
A10: Courtrooms | B10: 40 Net | C10: 0 | D10: =ROUNDUP((C10/40),1) -> 0
A11: Day Care | B11: 35 Net | C11: 0 | D11: =ROUNDUP((C11/35),1) -> 0
A12: Dormatories | B12: 50 Gross | C12: 0 | D12: =ROUNDUP((C12/50),1) -> 0
A13: Educational (Includes Adult Education) | B13: 20 Net | C13: 0 | D13: =ROUNDUP((C13/20),1) -> 0 | E13: =+D13/3 -> 0
A14: Exercise Rooms | B14: 50 Gross | C14: 0 | D14: =ROUNDUP((C14/50),1) -> 0
A15: Institutional (Inpatient) | B15: 240 Gross | C15: 0 | D15: =ROUNDUP((C15/240),0) -> 0
A16: Institutional (Outpatient) | B16: 100 Gross | C16: 0 | D16: =ROUNDUP((C16/100),1) -> 0
A17: Institutional (Sleeping Areas) | B17: 120 Gross | C17: 0 | D17: =ROUNDUP((C17/120),1) -> 0 | F17: Note:
A18: Commercial Kitchens | B18: 200 Gross | C18: 0 | D18: =ROUNDUP((C18/200),0) -> 0 | F18: Gross: overall area (including walls)
A19: Lab (Educational) | B19: 50 Net | C19: 0 | D19: =ROUNDUP((C19/50),1) -> 0 | F19: Net: actual wall-to-wall square footage
A20: Lab (Non-Educational) | B20: 100 Net | C20: 0 | D20: =ROUNDUP((C20/100),1) -> 0
A21: Library (Reading Rm) | B21: 50 Net | C21: 0 | D21: =ROUNDUP((C21/50),1) -> 0
A22: Library (Stack Areas) | B22: 100 Gross | C22: 0 | D22: =ROUNDUP((C22/100),1) -> 0
A23: Locker Rooms | B23: 50 Gross | C23: 0 | D23: =ROUNDUP((C23/50),1) -> 0
A24: Mercantile | B24: 60 Gross | C24: 0 | D24: =ROUNDUP((C24/60),1) -> 0
A25: Mercantile (Storage, Stock) | B25: 300 Gross | C25: 0 | D25: =ROUNDUP((C25/300),0) -> 0
B26: TOTAL # OF OCCUPANTS: | D26: =SUM(D3:D25) -> 333.4

Sheet IMC-UMC Vent. Rate
A1: IMC MINIMUM VENTILATION RATE:
A2: BUILDING USE: | B2: PEOPLE OUTDOOR FLOW RATE (Rp): | C2: AREA OUTDOOR FLOW RATE (Ra): | D2: OCCUPANT DENSITY /1000 sq. ft.: | E2: SQUARE FOOTAGE OF BDLG/AREA (Az): | F2: TOTAL OUTDOOR AIR REQUIRED (Vbz=RpPz+RaAz): | G2: EXHAUST REQUIRED: | H2: OCCUPANT LOAD OF SPACE (Pz) | I2: ZONE OUTDOOR AIRFLOW (Voz & Vot) COOLING | J2: ZONE OUTDOOR AIRFLOW (Voz & Vot) HEATING
A3: OFFICES
A4: OFFICE SPACE(S) | B4: 5 | C4: 0.06 | D4: 5 | E4: =+'Occupant Calculator'!C9 -> 50000 | F4: =SUM(B4*H4)+(C4*E4) -> 4250 | G4: - | H4: =ROUNDUP(((D4/1000)*E4),1) -> 250 | I4: =SUM(F4/1) -> 4250 | J4: =SUM(F4/0.8) -> 5312.5
A5: CONFERENCE ROOMS | B5: 5 | C5: 0.06 | D5: 50 | E5: 0 | F5: =SUM(B5*H5)+(C5*E5) -> 0 | G5: - | H5: =ROUNDUP(((D5/1000)*E5),1) -> 0 | I5: =SUM(F5/1) -> 0 | J5: =SUM(F5/0.8) -> 0
A6: RECEPTION AREA | B6: 5 | C6: 0.06 | D6: 30 | E6: 0 | F6: =SUM(B6*H6)+(C6*E6) -> 0 | G6: - | H6: =ROUNDUP(((D6/1000)*E6),1) -> 0 | I6: =SUM(F6/1) -> 0 | J6: =SUM(F6/0.8) -> 0
A7: COPY / PRINTING RM | B7: 5 | C7: 0.06 | D7: 4 | E7: 0 | F7: =SUM(B7*H7)+(C7*E7) -> 0 | G7: =SUM(E7*0.5) -> 0 | H7: =ROUNDUP(((D7/1000)*E7),1) -> 0 | I7: =SUM(F7/1) -> 0 | J7: =SUM(F7/0.8) -> 0
A8: LOBBIES | B8: 5 | C8: 0.06 | D8: 10 | E8: 0 | F8: =SUM(B8*H8)+(C8*E8) -> 0 | G8: - | H8: =ROUNDUP(((D8/1000)*E8),1) -> 0 | I8: =SUM(F8/1) -> 0 | J8: =SUM(F8/0.8) -> 0
A9: DINING ROOM | B9: 7.5 | C9: 0.18 | D9: 70 | E9: 0 | F9: =SUM(B9*H9)+(C9*E9) -> 0 | G9: - | H9: =ROUNDUP(((D9/1000)*E9),1) -> 0 | I9: =SUM(F9/1) -> 0 | J9: =SUM(F9/0.8) -> 0
A10: CAFETERIA | B10: 7.5 | C10: 0.18 | D10: 100 | E10: 0 | F10: =SUM(B10*H10)+(C10*E10) -> 0 | G10: - | H10: =ROUNDUP(((D10/1000)*E10),1) -> 0 | I10: =SUM(F10/1) -> 0 | J10: =SUM(F10/0.8) -> 0
A11: PHARMACY PREP AREA | B11: 5 | C11: 0.18 | D11: 10 | E11: 0 | F11: =SUM(B11*H11)+(C11*E11) -> 0 | G11: - | H11: =ROUNDUP(((D11/1000)*E11),1) -> 0 | I11: =SUM(F11/1) -> 0 | J11: =SUM(F11/0.8) -> 0
E12: TOTAL OUTDOOR AIR REQUIRED: | F12: =SUM(1*(F4+F5+F6+F7+F8+F9+F11+F10)) -> 4250
A14: EDUCATIONAL
A15: CLASSROOM (5-8) | B15: 10 | C15: 0.12 | D15: 25 | E15: 0 | F15: =SUM(B15*H15)+(C15*E15) -> 0 | G15: - | H15: =ROUNDUP(((D15/1000)*E15),1) -> 0 | I15: =SUM(F15/1) -> 0 | J15: =SUM(F15/0.8) -> 0
A16: CLASSROOM (9+) | B16: 10 | C16: 0.12 | D16: 35 | E16: 0 | F16: =SUM(B16*H16)+(C16*E16) -> 0 | G16: - | H16: =ROUNDUP(((D16/1000)*E16),1) -> 0 | I16: =SUM(F16/1) -> 0 | J16: =SUM(F16/0.8) -> 0
A17: DAYCARE (UP TO 4YR) | B17: 10 | C17: 0.18 | D17: 25 | E17: 0 | F17: =SUM(B17*H17)+(C17*E17) -> 0 | G17: - | H17: =ROUNDUP(((D17/1000)*E17),1) -> 0 | I17: =SUM(F17/1) -> 0 | J17: =SUM(F17/0.8) -> 0
A18: AUDITORIUMS | B18: 5 | C18: 0.06 | D18: 150 | E18: 0 | F18: =SUM(B18*H18)+(C18*E18) -> 0 | G18: - | H18: =ROUNDUP(((D18/1000)*E18),1) -> 0 | I18: =SUM(F18/1) -> 0 | J18: =SUM(F18/0.8) -> 0
A19: ART CLASSROOM | B19: 10 | C19: 0.18 | D19: 20 | E19: 0 | F19: =SUM(B19*H19)+(C19*E19) -> 0 | G19: =SUM(E19*0.7) -> 0 | H19: =ROUNDUP(((D19/1000)*E19),1) -> 0 | I19: =SUM(F19/1) -> 0 | J19: =SUM(F19/0.8) -> 0
A20: SCIENCE LAB | B20: 10 | C20: 0.18 | D20: 25 | E20: 0 | F20: =SUM(B20*H20)+(C20*E20) -> 0 | G20: =SUM(E20*1) -> 0 | H20: =ROUNDUP(((D20/1000)*E20),1) -> 0 | I20: =SUM(F20/1) -> 0 | J20: =SUM(F20/0.8) -> 0
A21: WOOD/METAL SHOP | B21: 10 | C21: 0.18 | D21: 20 | E21: 0 | F21: =SUM(B21*H21)+(C21*E21) -> 0 | G21: =SUM(E21*0.5) -> 0 | H21: =ROUNDUP(((D21/1000)*E21),1) -> 0 | I21: =SUM(F21/1) -> 0 | J21: =SUM(F21/0.8) -> 0
A22: COMPUTER LAB | B22: 10 | C22: 0.12 | D22: 25 | E22: 0 | F22: =SUM(B22*H22)+(C22*E22) -> 0 | G22: - | H22: =ROUNDUP(((D22/1000)*E22),1) -> 0 | I22: =SUM(F22/1) -> 0 | J22: =SUM(F22/0.8) -> 0
A23: MULTIUSE ASSEMBLY | B23: 7.5 | C23: 0.06 | D23: 100 | E23: 0 | F23: =SUM(B23*H23)+(C23*E23) -> 0 | G23: - | H23: =ROUNDUP(((D23/1000)*E23),1) -> 0 | I23: =SUM(F23/1) -> 0 | J23: =SUM(F23/0.8) -> 0
E24: TOTAL OUTDOOR AIR REQUIRED: | F24: =SUM(F15:F23) -> 0
A26: PUBLIC SPACES / GENERAL USE
A27: CORRIDORS | B27: - | C27: 0.06 | D27: 0 | E27: 0 | F27: =SUM(E27*C27) -> 0 | G27: - | H27: =ROUNDUP(((D27/1000)*E27),1) -> 0 | I27: =SUM(F27/1) -> 0 | J27: =SUM(F27/0.8) -> 0
A28: RELIGIOUS WORSHIP | B28: 5 | C28: 0.06 | D28: 120 | E28: 0 | F28: =SUM(B28*H28)+(C28*E28) -> 0 | G28: - | H28: =ROUNDUP(((D28/1000)*E28),1) -> 0 | I28: =SUM(F28/1) -> 0 | J28: =SUM(F28/0.8) -> 0
A29: COURTROOMS | B29: 5 | C29: 0.06 | D29: 70 | E29: 0 | F29: =SUM(B29*H29)+(C29*E29) -> 0 | G29: - | H29: =ROUNDUP(((D29/1000)*E29),1) -> 0 | I29: =SUM(F29/1) -> 0 | J29: =SUM(F29/0.8) -> 0
A30: AEROBICS ROOM | B30: 20 | C30: 0.06 | D30: 40 | E30: 0 | F30: =SUM(B30*H30)+(C30*E30) -> 0 | G30: - | H30: =ROUNDUP(((D30/1000)*E30),1) -> 0 | I30: =SUM(F30/1) -> 0 | J30: =SUM(F30/0.8) -> 0
A31: COPY / PRINTING ROOM | B31: - | C31: - | D31: - | E31: 0 | F31: - | G31: =SUM(E31*0.5) -> 0 | H31: - | I31: - | J31: -
A32: JANITOR CLOSET (UMC/CMC) | B32: - | C32: - | D32: - | E32: 0 | F32: - | G32: =SUM(E32*1) -> 0 | H32: - | I32: - | J32: -
A33: WEIGHT ROOM | B33: 20 | C33: 0.06 | D33: 10 | E33: 0 | F33: =SUM(B33*H33)+(C33*E33) -> 0 | G33: - | H33: =ROUNDUP(((D33/1000)*E33),1) -> 0 | I33: =SUM(F33/1) -> 0 | J33: =SUM(F33/0.8) -> 0
A34: LOCKER (ATHLETIC / HEALTH CARE) | B34: - | C34: - | D34: - | E34: 0 | F34: - | G34: =SUM(E34*0.5) -> 0 | H34: - | I34: - | J34: -
A35: LOCKER/DRESSING RM (OTHER) | B35: - | C35: - | D35: - | E35: 0 | F35: - | G35: =SUM(E35*0.25) -> 0 | H35: - | I35: - | J35: -
A36: SOILED LAUNDRY STORAGE | B36: - | C36: - | D36: - | E36: 0 | F36: - | G36: =SUM(E36*0.1) -> 0 | H36: - | I36: - | J36: -
A37: SHOWER (PER HEAD) | B37: TOTAL # OF SHOWERS: | D37: 1 | E37: - | F37: - | G37: =SUM(D37*50) -> 50 | H37: - | I37: - | J37: -
A38: TOILET ROOMS | B38: TOTAL # OF W.C. / URINALS: | D38: 2 | E38: - | F38: - | G38: =SUM(D38*70) -> 140 | H38: - | I38: - | J38: -
E39: TOTAL OUTDOOR AIR REQUIRED: | F39: =SUM(F27:F38) -> 0
A41: RETAIL
A42: SALES | B42: 7.5 | C42: 0.12 | D42: 15 | E42: 0 | F42: =SUM(E42*C42) -> 0 | G42: - | H42: =ROUNDUP(((D42/1000)*E42),1) -> 0 | I42: =SUM(F42/1) -> 0 | J42: =SUM(F42/0.8) -> 0
A43: DRESSING ROOMS | B43: - | C43: - | D43: - | E43: 0 | F43: - | G43: =SUM(E43*0.25) -> 0 | H43: - | I43: - | J43: -
...

Sheet IMC-UMC Endmount HVAC Calc
A1: WALL MOUNT HVAC'S | G1: BARD WALL MOUNT OUTDOOR AIR VENTILATION: | U1: 2009 IECC | V1: SEER: | W1: EER: | Y1: IECC Climate Zone: | AB1: 2012 IECC | AC1: SEER: | AD1: EER: | AE1: IECC Climate Zone: | AI1: 2015 IECC | AJ1: SEER: | AK1: EER: | AL1: IECC Climate Zone: | AP1: 2018 IECC | AQ1: SEER: | AR1: EER: | AS1: IECC Climate Zone: | AW1: 2019 CEC | AX1: SEER: | AY1: EER: | AZ1: 1 | BA1: =IF(((E22*0.7)+E22)<G22,"Meets Exception","Doesn't Meet") -> Doesn't Meet
A2: A/C SIZE: | B2: # OF A/C's: | C2: VENTILATION TYPE: | D2: VENTILATION RATE: | E2: COOLING BTU: | G2: HVAC SIZE: | H2: SYSTEM CFM OUTPUT: | I2: F.A.D. | J2: C.R.V. | K2: ECONOMIZER | M2: HVAC HEAT STRIP BTHU CONV. | U2: Bard AC | V2: - | W2: 9 | X2: 1A | Y2: Not Required | AB2: Bard AC | AC2: - | AD2: 9 | AE2: 1A | AF2: Not Required | AI2: Bard AC | AJ2: - | AK2: 9 | AL2: 1A | AM2: Not Required | AP2: Bard AC | AQ2: - | AR2: 9 | AS2: 1A | AT2: Not Required | AW2: Bard AC | AX2: - | AY2: 11 | AZ2: 2 | BA2: =IF(((E22*0.65)+E22)<G22,"Meets Exception","Doesn't Meet") -> Doesn't Meet
A3: 3 TON | B3: 4 | C3: ECONOMIZER | D3: =INDEX(CFMtable,MATCH(A3,HVACsize,0),MATCH(C3,FreshAirType,0))*B3 -> 4600 | E3: =IF(AND(B3>0,A3="1 TON"),"12,000",IF(AND(B3>0,A3="1.5 TON"),"18,000",IF(AND(B3>0,A3="2 TON"),"24,000",IF(AND(B3>0,A3="2.5 TON"),"30,000",IF(AND(B3>0,A3="3 TON"),"36,000",IF(AND(B3>0,A3="3.5 TON"),"42,000",IF(AND(B3>0,A3="4 TON"),"48,000",IF(AND(B3>0,A3="5 TON"),"60,000",0)))))))) -> 36,000 | G3: N/A | H3: 0 | I3: 0 | J3: 0 | K3: 0 | M3: ENTER KW: | N3: 0 | U3: Bard HP | V3: - | W3: 9 | X3: 1B | Y3: Not Required | AB3: Bard HP | AC3: - | AD3: 9 | AE3: 1B | AF3: Not Required | AI3: Bard HP | AJ3: - | AK3: 9 | AL3: 1B | AM3: Not Required | AP3: Bard HP | AQ3: - | AR3: 9 | AS3: 1B | AT3: Not Required | AW3: Bard HP | AX3: - | AY3: 11 | AZ3: 3 | BA3: =IF(((E22*0.65)+E22)<G22,"Meets Exception","Doesn't Meet") -> Doesn't Meet
A4: N/A | B4: 0 | C4: F.A.D. | D4: =INDEX(CFMtable,MATCH(A4,HVACsize,0),MATCH(C4,FreshAirType,0))*B4 -> 0 | E4: =IF(AND(B4>0,A4="1 TON"),"12,000",IF(AND(B4>0,A4="1.5 TON"),"18,000",IF(AND(B4>0,A4="2 TON"),"24,000",IF(AND(B4>0,A4="2.5 TON"),"30,000",IF(AND(B4>0,A4="3 TON"),"36,000",IF(AND(B4>0,A4="3.5 TON"),"42,000",IF(AND(B4>0,A4="4 TON"),"48,000",IF(AND(B4>0,A4="5 TON"),"60,000",0)))))))) -> 0 | G4: 1 TON | H4: 420 | I4: =SUM(H4*0.25) -> 105 | J4: =SUM(H4*0.5) -> 210 | K4: =SUM(H4*1) -> 420 | M4: = BTHU: | N4: =SUM( N3*3.412142) -> 0 | U4: Roof Top AC (1P) | V4: 13 | W4: =SUM((1.12*V4)-(0.02*V4^2)) -> 11.18 | X4: 2A | Y4: Not Required | AB4: Roof Top AC (1P) | AC4: 13 | AD4: =SUM((1.12*AC4)-(0.02*AC4^2)) -> 11.18 | AE4: 2A | AF4: No Exception | AI4: Roof Top AC (1P) | AJ4: 14 | AK4: =SUM((1.12*AJ4)-(0.02*AJ4^2)) -> 11.76 | AL4: 2A | AM4: No Exception | AP4: Roof Top AC (1P) | AQ4: 14 | AR4: =SUM((1.12*AQ4)-(0.02*AQ4^2)) -> 11.76 | AS4: 2A | AT4: =IF(((E22*0.1)+E22)<G22,"Meets Exception","Doesn't Meet") -> Meets Exception | AW4: Roof Top AC (1P) | AX4: 14 | AY4: 11 | AZ4: 4 | BA4: =IF(((E22*0.65)+E22)<G22,"Meets Exception","Doesn't Meet") -> Doesn't Meet
A5: N/A | B5: 0 | C5: F.A.D. | D5: =INDEX(CFMtable,MATCH(A5,HVACsize,0),MATCH(C5,FreshAirType,0))*B5 -> 0 | E5: =IF(AND(B5>0,A5="1 TON"),"12,000",IF(AND(B5>0,A5="1.5 TON"),"18,000",IF(AND(B5>0,A5="2 TON"),"24,000",IF(AND(B5>0,A5="2.5 TON"),"30,000",IF(AND(B5>0,A5="3 TON"),"36,000",IF(AND(B5>0,A5="3.5 TON"),"42,000",IF(AND(B5>0,A5="4 TON"),"48,000",IF(AND(B5>0,A5="5 TON"),"60,000",0)))))))) -> 0 | G5: 1.5 TON | H5: 600 | I5: =SUM(H5*0.25) -> 150 | J5: =SUM(H5*0.5) -> 300 | K5: =SUM(H5*1) -> 600 | U5: Roof Top AC (3P) | V5: 13 | W5: =SUM((1.12*V5)-(0.02*V5^2)) -> 11.18 | X5: 2B | Y5: =IF(((E22*0.1)+E22)<G22,"Meets Exception","Doesn't Meet") -> Meets Exception | AB5: Roof Top AC (3P) | AC5: 13 | AD5: =SUM((1.12*AC5)-(0.02*AC5^2)) -> 11.18 | AE5: 2B | AF5: =IF(((E22*0.1)+E22)<G22,"Meets Exception","Doesn't Meet") -> Meets Exception | AI5: Roof Top AC (3P) | AJ5: 14 | AK5: =SUM((1.12*AJ5)-(0.02*AJ5^2)) -> 11.76 | AL5: 2B | AM5: =IF(((E22*0.1)+E22)<G22,"Meets Exception","Doesn't Meet") -> Meets Exception | AP5: Roof Top AC (3P) | AQ5: 14 | AR5: =SUM((1.12*AQ5)-(0.02*AQ5^2)) -> 11.76 | AS5: 2B | AT5: =IF(((E22*0.1)+E22)<G22,"Meets Exception","Doesn't Meet") -> Meets Exception | AW5: Roof Top AC (3P) | AX5: 14 | AY5: 11 | AZ5: 5 | BA5: =IF(((E22*0.7)+E22)<G22,"Meets Exception","Doesn't Meet") -> Doesn't Meet
A6: N/A | B6: 0 | C6: F.A.D. | D6: =INDEX(CFMtable,MATCH(A6,HVACsize,0),MATCH(C6,FreshAirType,0))*B6 -> 0 | E6: =IF(AND(B6>0,A6="1 TON"),"12,000",IF(AND(B6>0,A6="1.5 TON"),"18,000",IF(AND(B6>0,A6="2 TON"),"24,000",IF(AND(B6>0,A6="2.5 TON"),"30,000",IF(AND(B6>0,A6="3 TON"),"36,000",IF(AND(B6>0,A6="3.5 TON"),"42,000",IF(AND(B6>0,A6="4 TON"),"48,000",IF(AND(B6>0,A6="5 TON"),"60,000",0)))))))) -> 0 | G6: 2 TON | H6: 800 | I6: =SUM(H6*0.25) -> 200 | J6: =SUM(H6*0.5) -> 400 | K6: =SUM(H6*1) -> 800 | U6: Roof Top HP (1P) | V6: 13 | W6: =SUM((1.12*V6)-(0.02*V6^2)) -> 11.18 | X6: 3A | Y6: No Exception | AB6: Roof Top HP (1P) | AC6: 13 | AD6: =SUM((1.12*AC6)-(0.02*AC6^2)) -> 11.18 | AE6: 3A | AF6: No Exception | AI6: Roof Top HP (1P) | AJ6: 14 | AK6: =SUM((1.12*AJ6)-(0.02*AJ6^2)) -> 11.76 | AL6: 3A | AM6: No Exception | AP6: Roof Top HP (1P) | AQ6: 14 | AR6: =SUM((1.12*AQ6)-(0.02*AQ6^2)) -> 11.76 | AS6: 3A | AT6: =IF(((E22*0.15)+E22)<G22,"Meets Exception","Doesn't Meet") -> Meets Exception | AW6: Roof Top HP (1P) | AX6: 14 | AY6: 11 | AZ6: 6 | BA6: =IF(((E22*0.3)+E22)<G22,"Meets Exception","Doesn't Meet") -> Doesn't Meet
A7: N/A | B7: 0 | C7: F.A.D. | D7: =INDEX(CFMtable,MATCH(A7,HVACsize,0),MATCH(C7,FreshAirType,0))*B7 -> 0 | E7: =IF(AND(B7>0,A7="1 TON"),"12,000",IF(AND(B7>0,A7="1.5 TON"),"18,000",IF(AND(B7>0,A7="2 TON"),"24,000",IF(AND(B7>0,A7="2.5 TON"),"30,000",IF(AND(B7>0,A7="3 TON"),"36,000",IF(AND(B7>0,A7="3.5 TON"),"42,000",IF(AND(B7>0,A7="4 TON"),"48,000",IF(AND(B7>0,A7="5 TON"),"60000",0)))))))) -> 0 | G7: 2.5 TON | H7: 950 | I7: =SUM(H7*0.25) -> 237.5 | J7: =SUM(H7*0.5) -> 475 | K7: =SUM(H7*1) -> 950 | M7: IECC ECONOMIZER REQUIREMENTS: | U7: Roof Top HP (3P) | V7: 13 | W7: =SUM((1.12*V7)-(0.02*V7^2)) -> 11.18 | X7: 3B | Y7: =IF(((E22*0.15)+E22)<G22,"Meets Exception","") -> Meets Exception | AB7: Roof Top HP (3P) | AC7: 13 | AD7: =SUM((1.12*AC7)-(0.02*AC7^2)) -> 11.18 | AE7: 3B | AF7: =IF(((E22*0.15)+E22)<G22,"Meets Exception","Doesn't Meet") -> Meets Exception | AI7: Roof Top HP (3P) | AJ7: 14 | AK7: =SUM((1.12*AJ7)-(0.02*AJ7^2)) -> 11.76 | AL7: 3B | AM7: =IF(((E22*0.15)+E22)<G22,"Meets Exception","Doesn't Meet") -> Meets Exception | AP7: Roof Top HP (3P) | AQ7: 14 | AR7: =SUM((1.12*AQ7)-(0.02*AQ7^2)) -> 11.76 | AS7: 3B | AT7: =IF(((E22*0.15)+E22)<G22,"Meets Exception","Doesn't Meet") -> Meets Exception | AW7: Roof Top HP (3P) | AX7: 14 | AY7: 11 | AZ7: 7 | BA7: =IF(((E22*0.3)+E22)<G22,"Meets Exception","Doesn't Meet") -> Doesn't Meet
G8: 3 TON | H8: 1150 | I8: =SUM(H8*0.25) -> 287.5 | J8: =SUM(H8*0.5) -> 575 | K8: =SUM(H8*1) -> 1150 | M8: 2009 | N8: OVER 4.5 TON / > 300,00 BTU | U8: Split System | V8: 13 | W8: =SUM((1.12*V8)-(0.02*V8^2)) -> 11.18 | X8: 3C | Y8: No Exception | AB8: Split System | AC8: 13 | AD8: =SUM((1.12*AC8)-(0.02*AC8^2)) -> 11.18 | AE8: 3C | AF8: No Exception | AI8: Split System | AJ8: 13 | AK8: =SUM((1.12*AJ8)-(0.02*AJ8^2)) -> 11.18 | AL8: 3C | AM8: No Exception | AP8: Split System | AQ8: 13 | AR8: =SUM((1.12*AQ8)-(0.02*AQ8^2)) -> 11.18 | AS8: 3C | AT8: No Exception | AW8: Split System | AX8: 13 | AY8: 12.2 | AZ8: 8 | BA8: =IF(((E22*0.3)+E22)<G22,"Meets Exception","Doesn't Meet") -> Doesn't Meet
G9: 3.5 TON | H9: 1350 | I9: =SUM(H9*0.25) -> 337.5 | J9: =SUM(H9*0.5) -> 675 | K9: =SUM(H9*1) -> 1350 | M9: 2012 | N9: OVER 2.5 TON / > 300,000 BTU | U9: Minisplit AC | V9: 13 | W9: =SUM((1.12*V9)-(0.02*V9^2)) -> 11.18 | X9: 4A | Y9: No Exception | AB9: Minisplit AC | AC9: 13 | AD9: =SUM((1.12*AC9)-(0.02*AC9^2)) -> 11.18 | AE9: 4A | AF9: No Exception | AI9: Minisplit AC | AJ9: 13 | AK9: =SUM((1.12*AJ9)-(0.02*AJ9^2)) -> 11.18 | AL9: 4A | AM9: No Exception | AP9: Minisplit AC | AQ9: 13 | AR9: =SUM((1.12*AQ9)-(0.02*AQ9^2)) -> 11.18 | AS9: 4A | AT9: =IF(((E22*0.2)+E22)<G22,"Meets Exception","Doesn't Meet") -> Meets Exception | AW9: Minisplit AC | AX9: 13 | AY9: =SUM((1.12*AX9)-(0.02*AX9^2)) -> 11.18 | AZ9: 9 | BA9: =IF(((E22*0.3)+E22)<G22,"Meets Exception","Doesn't Meet") -> Doesn't Meet
G10: 4 TON | H10: 1550 | I10: =SUM(H10*0.25) -> 387.5 | J10: =SUM(H10*0.5) -> 775 | K10: =SUM(H10*1) -> 1550 | M10: 2015 | N10: OVER 4.5 TON / > 300,00 BTU | U10: Thru Wall | V10: 12 | W10: =SUM((1.12*V10)-(0.02*V10^2)) -> 10.56 | X10: 4B | Y10: =IF(((E22*0.2)+E22)<G22,"Meets Exception","Doesn't Meet") -> Meets Exception | AB10: Thru Wall | AC10: 12 | AD10: =SUM((1.12*AC10)-(0.02*AC10^2)) -> 10.56 | AE10: 4B | AF10: =IF(((E22*0.2)+E22)<G22,"Meets Exception","Doesn't Meet") -> Meets Exception | AI10: Thru Wall | AJ10: 12 | AK10: =SUM((1.12*AJ10)-(0.02*AJ10^2)) -> 10.56 | AL10: 4B | AM10: =IF(((E22*0.2)+E22)<G22,"Meets Exception","Doesn't Meet") -> Meets Exception | AP10: Thru Wall | AQ10: 12 | AR10: =SUM((1.12*AQ10)-(0.02*AQ10^2)) -> 10.56 | AS10: 4B | AT10: =IF(((E22*0.2)+E22)<G22,"Meets Exception","Doesn't Meet") -> Meets Exception | AW10: Thru Wall | AX10: - | AY10: 9.3 | AZ10: 10 | BA10: =IF(((E22*0.3)+E22)<G22,"Meets Exception","Doesn't Meet") -> Doesn't Meet
G11: 5 TON | H11: 1750 | I11: =SUM(H11*0.25) -> 437.5 | J11: =SUM(H11*0.5) -> 875 | K11: =SUM(H11*1) -> 1750 | M11: 2018 | N11: OVER 4.5 TON / > 300,00 BTU | U11: PTAC | V11: - | W11: =SUM(12.5-(0.213*(B22*12000)/1000)) -> -0.28 | X11: 4C | Y11: No Exception | AB11: PTAC | AC11: - | AD11: =SUM(13.8-(0.3*(B22*12000)/1000)) -> -4.2 | AE11: 4C | AF11: No Exception | AI11: PTAC | AJ11: - | AK11: =SUM(14-(0.3*(B22*12000)/1000)) -> -4 | AL11: 4C | AM11: No Exception | AP11: PTAC | AQ11: - | AR11: =SUM(14-(0.3*(B22*12000)/1000)) -> -4 | AS11: 4C | AT11: No Exception | AW11: PTAC | AX11: - | AY11: =SUM(14-(0.213*(B22*12000)/1000)) -> 1.22 | AZ11: 11 | BA11: =IF(((E22*0.3)+E22)<G22,"Meets Exception","Doesn't Meet") -> Doesn't Meet
X12: 5A | Y12: No Exception | AE12: 5A | AF12: No Exception | AL12: 5A | AM12: No Exception | AS12: 5A | AT12: No Exception | AZ12: 12 | BA12: =IF(((E22*0.3)+E22)<G22,"Meets Exception","Doesn't Meet") -> Doesn't Meet
A13: OUTDOOR AIR PROPOSED: | B13: TOTAL NEEDED: | C13: ADD'L REQUIRED: | D13: TOTAL COOLING BTU: | E13: BTU REDUCTION BASED ON FRESH AIR TYPE: | G13: VENTILATION REQUIREMENT: | X13: 5B | Y13: No Exception | AE13: 5B | AF13: No Exception | AL13: 5B | AM13: No Exception | AS13: 5B | AT13: No Exception | AZ13: 13 | BA13: =IF(((E22*0.3)+E22)<G22,"Meets Exception","Doesn't Meet") -> Doesn't Meet
A14: =SUM(D3:D7) -> 4600 | B14: =SUM('IMC-UMC Vent. Rate'!F47) -> 4250 | C14: =IF(A14>B14,"NO ADD'L NEEDED",IF(A14<B14,(B14-A14),"")) -> NO ADD'L NEEDED | D14: =IF(B3>0,(E3*B3),0)+IF(B4>0,(E4*B4),0)+IF(B5>0,(E5*B5),0)+IF(B6>0,(E6*B6),0)+IF(B7>0,(E7*B7),0) -> 144000 | E14: =IF(C3="F.A.D.",(B3*E3),0)+IF(C3="C.R.V.",((B3*(E3/2)))+IF(C3="ECONOMIZER",((B3*(-E3))),0))+IF(C4="F.A.D.",(B4*E4),0)+IF(C4="C.R.V.",((B4*(E4/2)))+IF(C4="ECONOMIZER",((B4*(-E4))),0))+IF(C5="F.A.D.",(B5*E5),0)+IF(C5="C.R.V.",((B5*(E5/2)))+IF(C5="ECONOMIZER",((B5*(-E5))),0))+IF(C6="F.A.D.",(B6*E6),0)+IF(C6="C.R.V.",((B6*(E6/2)))+IF(C6="ECONOMIZER",((B6*(-E6))),0))+IF(C7="F.A.D.",(B7*E7),0)+IF(C7="C.R.V.",((B7*(E7/2)))+IF(C7="ECONOMIZER",((B7*(-E7))),0)) -> 0 | G14: =IF(E14>300000,"ECONOMIZERS REQUIRED",IF((((OR(A3="5 TON",A4="5 TON",A5="5 TON",A6="5 TON",A7="5 TON")))),"ECONOMIZERS REQUIRED @ 5 TON",IF(I22="meets exception","Meets Exception","NO ADD'L VENTILATION REQUIRED"))) -> NO ADD'L VENTILATION REQUIRED | U14: =INDEX(Exceptions09,MATCH(D22,ClimateZone09,0)) -> Not Required | X14: 5C | Y14: No Exception | AB14: =INDEX(AF2:AF18,MATCH(D22,AE2:AE18,0)) -> No Exception | AE14: 5C | AF14: No Exception | AI14: =INDEX(AM2:AM18,MATCH(D22,AL2:AL18,0)) -> No Exception | AL14: 5C | AM14: No Exception | AP14: =INDEX(AT2:AT18,MATCH(D22,AS2:AS18,0)) -> Meets Exception | AS14: 5C | AT14: No Exception | AW14: =INDEX(BA1:BA16,MATCH(#REF!,AZ1:AZ16,0)) -> #REF! | AZ14: 14 | BA14: =IF(((E22*0.3)+E22)<G22,"Meets Exception","Doesn't Meet") -> Doesn't Meet
G15: Note: 2012 IECC: HVAC's 3-Ton or Greater require Economizers | X15: 6A | Y15: No Exception | AE15: 6A | AF15: No Exception | AL15: 6A | AM15: No Exception | AS15: 6A | AT15: No Exception | AZ15: 15 | BA15: =IF(((E22*0.3)+E22)<G22,"Meets Exception","Doesn't Meet") -> Doesn't Meet
A16: NOTES: | X16: 6B | Y16: No Exception | AE16: 6B | AF16: No Exception | AL16: 6B | AM16: No Exception | AS16: 6B | AT16: No Exception | AZ16: 16 | BA16: =IF(((E22*0.7)+E22)<G22,"Meets Exception","Doesn't Meet") -> Doesn't Meet
A17: 1. WHEN ECONOMIZERS ARE REQUIRED OVER 300,000 BTU, LOOK AT CHART AND BRING THE TOTAL UNDER 300,000. NOT ALL HVAC'S NEED ECONOMIZERS. | X17: 7 | Y17: Not Required | AE17: 7 | AF17: No Exception | AL17: 7 | AM17: Not in 2015 Code | AS17: 7 | AT17: Not in 2018 Code
A18: 2. WHEN CRV'S ARE REQUIRED, LOOK AT CHART AND MEET THE ADDITIONAL REQUIRED. NOT ALL HVAC'S NEED CRV'S IN CASES. | X18: 8 | Y18: Not Required | AE18: 8 | AF18: No Exception | AL18: 8 | AM18: Not in 2015 Code | AS18: 8 | AT18: Not in 2018 Code
A20: ECONOMIZER EXCEPTION
A21: Code Year: | B21: HVAC Size (Tons): | C21: HVAC Type: | D21: IECC Climate Zone: | E21: Min. EER Rating: | F21: Min. SEER Rating: | G21: Equipment EER Rating: | H21: Equipment SEER Rating: | I21: Results: | U21: PMI Elec. Equip. | W21: Equipment Size EER Rating
A22: 2015 IECC | B22: 5 | C22: Bard AC | D22: 2A | E22: =IF(AND(OR(A22="2009 iecc",A22="2012 iecc",A22="2015 iecc",A22="2018 iecc"),C22="Bard ac"),W2,IF(AND(OR(A22="2009 iecc",A22="2012 iecc",A22="2015 iecc",A22="2018 iecc"),C22="Bard HP"),W3,IF(AND(OR(A22="2009 iecc",A22="2012 iecc"),C22="roof top ac (1P)"),W4,IF(AND(OR(A22="2009 iecc",A22="2012 iecc"),C22="roof top ac (3P)"),W5,IF(AND(OR(A22="2009 iecc",A22="2012 iecc"),C22="roof top hp (1P)"),W6,IF(AND(OR(A22="2009 iecc",A22="2012 iecc"),C22="roof top hp (3P)"),W7,IF(AND(OR(A22="2009 iecc",A22="2012 iecc"),C22="split system"),W8,IF(AND(OR(A22="2009 iecc",A22="2012 iecc"),C22="minisplit ac"),W9,IF(AND(OR(A22="2009 iecc",A22="2012 iecc"),C22="thru wall"),W10,IF(AND(OR(A22="2015 iecc",A22="2018 iecc"),C22="roof top ac (1P)"),AK4,IF(AND(OR(A22="2015 iecc",A22="2018 iecc"),C22="roof top ac (3P)"),AK5,IF(AND(OR(A22="2015 iecc",A22="2018 iecc"),C22="roof top hp (1P)"),AK6,IF(AND(OR(A22="2015 iecc",A22="2018 iecc"),C22="roof top hp (3P)"),AK7,IF(AND(OR(A22="2015 iecc",A22="2018 iecc"),C22="split system"),AK8,IF(AND(OR(A22="2015 iecc",A22="2018 iecc"),C22="minisplit ac"),AK9,IF(AND(OR(A22="2015 iecc",A22="2018 iecc"),C22="thru wall"),AK10,IF(AND(A22="2009 iecc",C22="ptac"),W11,IF(AND(A22="2012 iecc",C22="ptac"),AD11,IF(AND(A22="2015 iecc",C22="ptac"),AK11,IF(AND(A22="2018 iecc",C22="ptac"),AR11,IF(AND(A22="2019 cec",C22="Bard ac"),AY2,IF(AND(A22="2019 cec",C22="Bard HP"),AY3,IF(AND(A22="2019 cec",C22="roof top ac (1P)"),AY4,IF(AND(A22="2019 cec",C22="roof top ac (3P)"),AY5,IF(AND(A22="2019 cec",C22="roof top hp (1P)"),AY6,IF(AND(A22="2019 cec",C22="roof top hp (3P)"),AY7,IF(AND(A22="2019 cec",C22="split system"),AY8,IF(AND(A22="2019 cec",C22="minisplit ac"),AY9,IF(AND(A22="2019 cec",C22="thru wall"),AY10,IF(AND(A22="2019 cec",C22="ptac"),AY11,"")))))))))))))))))))))))))))))) -> 9 | F22: =IF(AND(OR(A22="2009 iecc",A22="2012 iecc",A22="2015 iecc",A22="2018 iecc",A22="2019 cec"),C22="Bard ac"),V2,IF(AND(OR(A22="2009 iecc",A22="2012 iecc",A22="2015 iecc",A22="2018 iecc",A22="2019 cec"),C22="Bard HP"),V3,IF(AND(OR(A22="2009 iecc",A22="2012 iecc"),C22="roof top ac (1P)"),V4,IF(AND(OR(A22="2009 iecc",A22="2012 iecc"),C22="roof top ac (3P)"),V5,IF(AND(OR(A22="2009 iecc",A22="2012 iecc"),C22="roof top hp (1P)"),V6,IF(AND(OR(A22="2009 iecc",A22="2012 iecc"),C22="roof top hp (3P)"),V7,IF(AND(OR(A22="2009 iecc",A22="2012 iecc"),C22="split system"),V8,IF(AND(OR(A22="2009 iecc",A22="2012 iecc"),C22="minisplit ac"),V9,IF(AND(OR(A22="2009 iecc",A22="2012 iecc"),C22="thru wall"),V10,IF(AND(OR(A22="2015 iecc",A22="2018 iecc",A22="2019 cec"),C22="roof top ac (1P)"),AJ4,IF(AND(OR(A22="2015 iecc",A22="2018 iecc",A22="2019 cec"),C22="roof top ac (3P)"),AJ5,IF(AND(OR(A22="2015 iecc",A22="2018 iecc",A22="2019 cec"),C22="roof top hp (1P)"),AJ6,IF(AND(OR(A22="2015 iecc",A22="2018 iecc",A22="2019 cec"),C22="roof top hp (3P)"),AJ7,IF(AND(OR(A22="2015 iecc",A22="2018 iecc",A22="2019 cec"),C22="split system"),AJ8,IF(AND(OR(A22="2015 iecc",A22="2018 iecc",A22="2019 cec"),C22="minisplit ac"),AJ9,IF(AND(OR(A22="2015 iecc",A22="2018 iecc"),C22="thru wall"),AJ10,IF(AND(A22="2019 cec",C22="thru wall"),AX10,IF(AND(OR(A22="2009 iecc",A22="2012 iecc",A22="2015 iecc",A22="2018 iecc",A22="2019 cec"),C22="ptac"),V11,"")))))))))))))))))) -> - | G22: =INDEX(EerTable,MATCH(C22,EerEquipment,0),MATCH(B22,EerHVACsize,0)) -> 11 | H22: =INDEX(SeerTable,MATCH(C22,SeerEquipment,0),MATCH(B22,SeerHVACsize,0)) -> - | I22: =IF(A22="2009 iecc",U14,IF(A22="2012 iecc",AB14,IF(A22="2015 iecc",AI14,IF(A22="2018 iecc",AP14,IF(A22="2019 cec",AW14,""))))) -> No Exception | W22: 0.75 | X22: 1 | Y22: 1.5 | Z22: 2 | AA22: 2.5 | AB22: 3 | AC22: 3.5 | AD22: 4 | AE22: 5
V23: Bard AC | W23: - | X23: 11 | Y23: 11.3 | Z23: 11.2 | AA23: 11.2 | AB23: 11 | AC23: 11 | AD23: 11 | AE23: 11
V24: Bard HP | W24: - | X24: - | Y24: 11 | Z24: 11 | AA24: 11 | AB24: 11 | AC24: 11 | AD24: 11 | AE24: 11
V25: Roof Top AC (1P) | W25: - | X25: - | Y25: - | Z25: - | AA25: - | AB25: 12.5 | AC25: 12.5 | AD25: 12 | AE25: 12
V26: Roof Top AC (3P) | W26: - | X26: - | Y26: - | Z26: - | AA26: - | AB26: 13 | AC26: 13 | AD26: 12.5 | AE26: 12.5
V27: Roof Top HP (1P) | W27: - | X27: - | Y27: - | Z27: - | AA27: - | AB27: 13 | AC27: 13 | AD27: 12 | AE27: 12
V28: Roof Top HP (3P) | W28: - | X28: - | Y28: - | Z28: - | AA28: - | AB28: 13 | AC28: 13 | AD28: 12.5 | AE28: 12.5
V29: Minisplit AC | W29: 10.4 | X29: 10.6 | Y29: 12.2 | Z29: 9.2 | AA29: - | AB29: - | AC29: - | AD29: - | AE29: -
V30: Split System
V31: Thru Wall
V32: PTAC
U35: PMI Elec. Equip. | W35: Equipment Size SEER Rating
W36: 0.75 | X36: 1 | Y36: 1.5 | Z36: 2 | AA36: 2.5 | AB36: 3 | AC36: 3.5 | AD36: 4 | AE36: 5
V37: Bard AC | W37: - | X37: - | Y37: - | Z37: - | AA37: - | AB37: - | AC37: - | AD37: - | AE37: -
V38: Bard HP | W38: - | X38: - | Y38: - | Z38: - | AA38: - | AB38: - | AC38: - | AD38: - | AE38: -
V39: Roof Top AC (1P) | W39: - | X39: - | Y39: - | Z39: - | AA39: - | AB39: 15 | AC39: 15 | AD39: 15 | AE39: 15
V40: Roof Top AC (3P) | W40: - | X40: - | Y40: - | Z40: - | AA40: - | AB40: 15 | AC40: 15 | AD40: 15 | AE40: 15
V41: Roof Top HP (1P) | W41: - | X41: - | Y41: - | Z41: - | AA41: - | AB41: 15.5 | AC41: 15.5 | AD41: 15 | AE41: 15
V42: Roof Top HP (3P) | W42: - | X42: - | Y42: - | Z42: - | AA42: - | AB42: 15 | AC42: 15 | AD42: 15 | AE42: 15
V43: Minisplit AC | W43: 16 | X43: 16 | Y43: 16 | Z43: 16 | AA43: - | AB43: - | AC43: - | AD43: - | AE43: -
...

Sheet IMC-UMC Rooftop HVAC Calc
A1: RTU HVAC'S | H1: DAIKIN ROOF TOP OUTDOOR AIR VENTILATION: | U1: 2009 IECC | V1: SEER: | W1: EER: | Y1: IECC Climate Zone: | AB1: 2012 IECC | AC1: SEER: | AD1: EER: | AE1: IECC Climate Zone: | AI1: 2015 IECC | AJ1: SEER: | AK1: EER: | AL1: IECC Climate Zone: | AP1: 2018 IECC | AQ1: SEER: | AR1: EER: | AS1: IECC Climate Zone: | AW1: 2019 CEC | AX1: SEER: | AY1: EER: | AZ1: 1 | BA1: =IF(((E22*0.7)+E22)<G22,"Meets Exception","Doesn't Meet") -> Doesn't Meet
A2: A/C SIZE: | B2: # OF A/C's: | C2: VENTILATION TYPE: | D2: VENTILATION RATE: | E2: COOLING BTU: | H2: HVAC SIZE: | I2: SYSTEM CFM OUTPUT: | J2: F.A.D. | K2: C.R.V. | L2: ECONOMIZER | N2: HVAC HEAT STRIP BTHU CONV. | U2: Bard AC | V2: - | W2: 9 | X2: 1A | Y2: Not Required | AB2: Bard AC | AC2: - | AD2: 9 | AE2: 1A | AF2: Not Required | AI2: Bard AC | AJ2: - | AK2: 9 | AL2: 1A | AM2: Not Required | AP2: Bard AC | AQ2: - | AR2: 9 | AS2: 1A | AT2: Not Required | AW2: Bard AC | AX2: - | AY2: 11 | AZ2: 2 | BA2: =IF(((E22*0.65)+E22)<G22,"Meets Exception","Doesn't Meet") -> Doesn't Meet
A3: 3 TON | B3: 0 | C3: F.A.D. | D3: =INDEX(CFMtableDaikin,MATCH(A3,RTUsizes,0),MATCH(C3,VENTtypeDaikin,0))*B3 -> 0 | E3: =IF(AND(B3>0,A3="1 TON"),"12,000",IF(AND(B3>0,A3="1.5 TON"),"18,000",IF(AND(B3>0,A3="2 TON"),"24,000",IF(AND(B3>0,A3="2.5 TON"),"30,000",IF(AND(B3>0,A3="3 TON"),"36,000",IF(AND(B3>0,A3="3.5 TON"),"42,000",IF(AND(B3>0,A3="4 TON"),"48,000",IF(AND(B3>0,A3="5 TON"),"60,000",0)))))))) -> 0 | H3: N/A | I3: 0 | J3: 0 | K3: 0 | L3: 0 | N3: ENTER KW: | O3: 0 | U3: Bard HP | V3: - | W3: 9 | X3: 1B | Y3: Not Required | AB3: Bard HP | AC3: - | AD3: 9 | AE3: 1B | AF3: Not Required | AI3: Bard HP | AJ3: - | AK3: 9 | AL3: 1B | AM3: Not Required | AP3: Bard HP | AQ3: - | AR3: 9 | AS3: 1B | AT3: Not Required | AW3: Bard HP | AX3: - | AY3: 11 | AZ3: 3 | BA3: =IF(((E22*0.65)+E22)<G22,"Meets Exception","Doesn't Meet") -> Doesn't Meet
A4: N/A | B4: 0 | C4: F.A.D. | D4: =INDEX(CFMtableDaikin,MATCH(A4,RTUsizes,0),MATCH(C4,VENTtypeDaikin,0))*B4 -> 0 | E4: =IF(AND(B4>0,A4="1 TON"),"12,000",IF(AND(B4>0,A4="1.5 TON"),"18,000",IF(AND(B4>0,A4="2 TON"),"24,000",IF(AND(B4>0,A4="2.5 TON"),"30,000",IF(AND(B4>0,A4="3 TON"),"36,000",IF(AND(B4>0,A4="3.5 TON"),"42,000",IF(AND(B4>0,A4="4 TON"),"48,000",IF(AND(B4>0,A4="5 TON"),"60,000",0)))))))) -> 0 | H4: 2 TON | I4: 780 | J4: =SUM(I4*0.25) -> 195 | K4: =SUM(I4*0.5) -> 390 | L4: =SUM(I4*1) -> 780 | N4: = BTHU: | O4: =SUM( O3*3.412142) -> 0 | U4: Roof Top AC (1P) | V4: 13 | W4: =SUM((1.12*V4)-(0.02*V4^2)) -> 11.18 | X4: 2A | Y4: Not Required | AB4: Roof Top AC (1P) | AC4: 13 | AD4: =SUM((1.12*AC4)-(0.02*AC4^2)) -> 11.18 | AE4: 2A | AF4: No Exception | AI4: Roof Top AC (1P) | AJ4: 14 | AK4: =SUM((1.12*AJ4)-(0.02*AJ4^2)) -> 11.76 | AL4: 2A | AM4: No Exception | AP4: Roof Top AC (1P) | AQ4: 14 | AR4: =SUM((1.12*AQ4)-(0.02*AQ4^2)) -> 11.76 | AS4: 2A | AT4: =IF(((E22*0.1)+E22)<G22,"Meets Exception","Doesn't Meet") -> Doesn't Meet | AW4: Roof Top AC (1P) | AX4: 14 | AY4: 11 | AZ4: 4 | BA4: =IF(((E22*0.65)+E22)<G22,"Meets Exception","Doesn't Meet") -> Doesn't Meet
A5: N/A | B5: 0 | C5: F.A.D. | D5: =INDEX(CFMtableDaikin,MATCH(A5,RTUsizes,0),MATCH(C5,VENTtypeDaikin,0))*B5 -> 0 | E5: =IF(AND(B5>0,A5="1 TON"),"12,000",IF(AND(B5>0,A5="1.5 TON"),"18,000",IF(AND(B5>0,A5="2 TON"),"24,000",IF(AND(B5>0,A5="2.5 TON"),"30,000",IF(AND(B5>0,A5="3 TON"),"36,000",IF(AND(B5>0,A5="3.5 TON"),"42,000",IF(AND(B5>0,A5="4 TON"),"48,000",IF(AND(B5>0,A5="5 TON"),"60,000",0)))))))) -> 0 | H5: 2.5 TON | I5: 900 | J5: =SUM(I5*0.25) -> 225 | K5: =SUM(I5*0.5) -> 450 | L5: =SUM(I5*1) -> 900 | U5: Roof Top AC (3P) | V5: 13 | W5: =SUM((1.12*V5)-(0.02*V5^2)) -> 11.18 | X5: 2B | Y5: =IF(((E22*0.1)+E22)<G22,"Meets Exception","Doesn't Meet") -> Doesn't Meet | AB5: Roof Top AC (3P) | AC5: 13 | AD5: =SUM((1.12*AC5)-(0.02*AC5^2)) -> 11.18 | AE5: 2B | AF5: =IF(((E22*0.1)+E22)<G22,"Meets Exception","Doesn't Meet") -> Doesn't Meet | AI5: Roof Top AC (3P) | AJ5: 14 | AK5: =SUM((1.12*AJ5)-(0.02*AJ5^2)) -> 11.76 | AL5: 2B | AM5: =IF(((E22*0.1)+E22)<G22,"Meets Exception","Doesn't Meet") -> Doesn't Meet | AP5: Roof Top AC (3P) | AQ5: 14 | AR5: =SUM((1.12*AQ5)-(0.02*AQ5^2)) -> 11.76 | AS5: 2B | AT5: =IF(((E22*0.1)+E22)<G22,"Meets Exception","Doesn't Meet") -> Doesn't Meet | AW5: Roof Top AC (3P) | AX5: 14 | AY5: 11 | AZ5: 5 | BA5: =IF(((E22*0.7)+E22)<G22,"Meets Exception","Doesn't Meet") -> Doesn't Meet
A6: N/A | B6: 0 | C6: F.A.D. | D6: =INDEX(CFMtableDaikin,MATCH(A6,RTUsizes,0),MATCH(C6,VENTtypeDaikin,0))*B6 -> 0 | E6: =IF(AND(B6>0,A6="1 TON"),"12,000",IF(AND(B6>0,A6="1.5 TON"),"18,000",IF(AND(B6>0,A6="2 TON"),"24,000",IF(AND(B6>0,A6="2.5 TON"),"30,000",IF(AND(B6>0,A6="3 TON"),"36,000",IF(AND(B6>0,A6="3.5 TON"),"42,000",IF(AND(B6>0,A6="4 TON"),"48,000",IF(AND(B6>0,A6="5 TON"),"60,000",0)))))))) -> 0 | H6: 3 TON | I6: 1195 | J6: =SUM(I6*0.25) -> 298.75 | K6: =SUM(I6*0.5) -> 597.5 | L6: =SUM(I6*1) -> 1195 | U6: Roof Top HP (1P) | V6: 13 | W6: =SUM((1.12*V6)-(0.02*V6^2)) -> 11.18 | X6: 3A | Y6: No Exception | AB6: Roof Top HP (1P) | AC6: 13 | AD6: =SUM((1.12*AC6)-(0.02*AC6^2)) -> 11.18 | AE6: 3A | AF6: No Exception | AI6: Roof Top HP (1P) | AJ6: 14 | AK6: =SUM((1.12*AJ6)-(0.02*AJ6^2)) -> 11.76 | AL6: 3A | AM6: No Exception | AP6: Roof Top HP (1P) | AQ6: 14 | AR6: =SUM((1.12*AQ6)-(0.02*AQ6^2)) -> 11.76 | AS6: 3A | AT6: =IF(((E22*0.15)+E22)<G22,"Meets Exception","Doesn't Meet") -> Doesn't Meet | AW6: Roof Top HP (1P) | AX6: 14 | AY6: 11 | AZ6: 6 | BA6: =IF(((E22*0.3)+E22)<G22,"Meets Exception","Doesn't Meet") -> Doesn't Meet
A7: N/A | B7: 0 | C7: F.A.D. | D7: =INDEX(CFMtableDaikin,MATCH(A7,RTUsizes,0),MATCH(C7,VENTtypeDaikin,0))*B7 -> 0 | E7: =IF(AND(B7>0,A7="1 TON"),"12,000",IF(AND(B7>0,A7="1.5 TON"),"18,000",IF(AND(B7>0,A7="2 TON"),"24,000",IF(AND(B7>0,A7="2.5 TON"),"30,000",IF(AND(B7>0,A7="3 TON"),"36,000",IF(AND(B7>0,A7="3.5 TON"),"42,000",IF(AND(B7>0,A7="4 TON"),"48,000",IF(AND(B7>0,A7="5 TON"),"60000",0)))))))) -> 0 | H7: 3.5 TON | I7: 1420 | J7: =SUM(I7*0.25) -> 355 | K7: =SUM(I7*0.5) -> 710 | L7: =SUM(I7*1) -> 1420 | N7: IECC ECONOMIZER REQUIREMENTS: | U7: Roof Top HP (3P) | V7: 13 | W7: =SUM((1.12*V7)-(0.02*V7^2)) -> 11.18 | X7: 3B | Y7: =IF(((E22*0.15)+E22)<G22,"Meets Exception","") | AB7: Roof Top HP (3P) | AC7: 13 | AD7: =SUM((1.12*AC7)-(0.02*AC7^2)) -> 11.18 | AE7: 3B | AF7: =IF(((E22*0.15)+E22)<G22,"Meets Exception","Doesn't Meet") -> Doesn't Meet | AI7: Roof Top HP (3P) | AJ7: 14 | AK7: =SUM((1.12*AJ7)-(0.02*AJ7^2)) -> 11.76 | AL7: 3B | AM7: =IF(((E22*0.15)+E22)<G22,"Meets Exception","Doesn't Meet") -> Doesn't Meet | AP7: Roof Top HP (3P) | AQ7: 14 | AR7: =SUM((1.12*AQ7)-(0.02*AQ7^2)) -> 11.76 | AS7: 3B | AT7: =IF(((E22*0.15)+E22)<G22,"Meets Exception","Doesn't Meet") -> Doesn't Meet | AW7: Roof Top HP (3P) | AX7: 14 | AY7: 11 | AZ7: 7 | BA7: =IF(((E22*0.3)+E22)<G22,"Meets Exception","Doesn't Meet") -> Doesn't Meet
H8: 4 TON | I8: 1605 | J8: =SUM(I8*0.25) -> 401.25 | K8: =SUM(I8*0.5) -> 802.5 | L8: =SUM(I8*1) -> 1605 | N8: 2009 | O8: OVER 4.5 TON / > 300,00 BTU | U8: Split System | V8: 13 | W8: =SUM((1.12*V8)-(0.02*V8^2)) -> 11.18 | X8: 3C | Y8: No Exception | AB8: Split System | AC8: 13 | AD8: =SUM((1.12*AC8)-(0.02*AC8^2)) -> 11.18 | AE8: 3C | AF8: No Exception | AI8: Split System | AJ8: 13 | AK8: =SUM((1.12*AJ8)-(0.02*AJ8^2)) -> 11.18 | AL8: 3C | AM8: No Exception | AP8: Split System | AQ8: 13 | AR8: =SUM((1.12*AQ8)-(0.02*AQ8^2)) -> 11.18 | AS8: 3C | AT8: No Exception | AW8: Split System | AX8: 13 | AY8: 12.2 | AZ8: 8 | BA8: =IF(((E22*0.3)+E22)<G22,"Meets Exception","Doesn't Meet") -> Doesn't Meet
H9: 5 TON | I9: 1800 | J9: =SUM(I9*0.25) -> 450 | K9: =SUM(I9*0.5) -> 900 | L9: =SUM(I9*1) -> 1800 | N9: 2012 | O9: OVER 2.5 TON / > 300,000 BTU | U9: Minisplit AC | V9: 13 | W9: =SUM((1.12*V9)-(0.02*V9^2)) -> 11.18 | X9: 4A | Y9: No Exception | AB9: Minisplit AC | AC9: 13 | AD9: =SUM((1.12*AC9)-(0.02*AC9^2)) -> 11.18 | AE9: 4A | AF9: No Exception | AI9: Minisplit AC | AJ9: 13 | AK9: =SUM((1.12*AJ9)-(0.02*AJ9^2)) -> 11.18 | AL9: 4A | AM9: No Exception | AP9: Minisplit AC | AQ9: 13 | AR9: =SUM((1.12*AQ9)-(0.02*AQ9^2)) -> 11.18 | AS9: 4A | AT9: =IF(((E22*0.2)+E22)<G22,"Meets Exception","Doesn't Meet") -> Doesn't Meet | AW9: Minisplit AC | AX9: 13 | AY9: =SUM((1.12*AX9)-(0.02*AX9^2)) -> 11.18 | AZ9: 9 | BA9: =IF(((E22*0.3)+E22)<G22,"Meets Exception","Doesn't Meet") -> Doesn't Meet
H10: 5 TON | I10: 1700 | J10: =SUM(I10*0.25) -> 425 | K10: =SUM(I10*0.5) -> 850 | L10: =SUM(I10*1) -> 1700 | N10: 2015 | O10: OVER 4.5 TON / > 300,00 BTU | U10: Thru Wall | V10: 12 | W10: =SUM((1.12*V10)-(0.02*V10^2)) -> 10.56 | X10: 4B | Y10: =IF(((E22*0.2)+E22)<G22,"Meets Exception","Doesn't Meet") -> Doesn't Meet | AB10: Thru Wall | AC10: 12 | AD10: =SUM((1.12*AC10)-(0.02*AC10^2)) -> 10.56 | AE10: 4B | AF10: =IF(((E22*0.2)+E22)<G22,"Meets Exception","Doesn't Meet") -> Doesn't Meet | AI10: Thru Wall | AJ10: 12 | AK10: =SUM((1.12*AJ10)-(0.02*AJ10^2)) -> 10.56 | AL10: 4B | AM10: =IF(((E22*0.2)+E22)<G22,"Meets Exception","Doesn't Meet") -> Doesn't Meet | AP10: Thru Wall | AQ10: 12 | AR10: =SUM((1.12*AQ10)-(0.02*AQ10^2)) -> 10.56 | AS10: 4B | AT10: =IF(((E22*0.2)+E22)<G22,"Meets Exception","Doesn't Meet") -> Doesn't Meet | AW10: Thru Wall | AX10: - | AY10: 9.3 | AZ10: 10 | BA10: =IF(((E22*0.3)+E22)<G22,"Meets Exception","Doesn't Meet") -> Doesn't Meet
H11: NOTE: THE ABOVE CFM OUTPUT IS BASED ON A DAIKEN HVAC UNIT. CFM OUTPUT MAY VARY BASED ON BRAND OF HVAC. | N11: 2018 | O11: OVER 4.5 TON / > 300,00 BTU | U11: PTAC | V11: - | W11: =SUM(12.5-(0.213*(B22*12000)/1000)) -> 4.832 | X11: 4C | Y11: No Exception | AB11: PTAC | AC11: - | AD11: =SUM(13.8-(0.3*(B22*12000)/1000)) -> 3 | AE11: 4C | AF11: No Exception | AI11: PTAC | AJ11: - | AK11: =SUM(14-(0.3*(B22*12000)/1000)) -> 3.2 | AL11: 4C | AM11: No Exception | AP11: PTAC | AQ11: - | AR11: =SUM(14-(0.3*(B22*12000)/1000)) -> 3.2 | AS11: 4C | AT11: No Exception | AW11: PTAC | AX11: - | AY11: =SUM(14-(0.213*(B22*12000)/1000)) -> 6.332 | AZ11: 11 | BA11: =IF(((E22*0.3)+E22)<G22,"Meets Exception","Doesn't Meet") -> Doesn't Meet
X12: 5A | Y12: No Exception | AE12: 5A | AF12: No Exception | AL12: 5A | AM12: No Exception | AS12: 5A | AT12: No Exception | AZ12: 12 | BA12: =IF(((E22*0.3)+E22)<G22,"Meets Exception","Doesn't Meet") -> Doesn't Meet
A13: OUTDOOR AIR PROPOSED: | B13: TOTAL NEEDED: | C13: ADD'L REQUIRED: | D13: TOTAL COOLING BTU: | E13: BTU REDUCTION BASED ON FRESH AIR TYPE: | G13: VENTILATION REQUIREMENT: | X13: 5B | Y13: No Exception | AE13: 5B | AF13: No Exception | AL13: 5B | AM13: No Exception | AS13: 5B | AT13: No Exception | AZ13: 13 | BA13: =IF(((E22*0.3)+E22)<G22,"Meets Exception","Doesn't Meet") -> Doesn't Meet
A14: =SUM(D3:D7) -> 0 | B14: =SUM('IMC-UMC Vent. Rate'!F47) -> 4250 | C14: =IF(A14>B14,"NO ADD'L NEEDED",IF(A14<B14,(B14-A14),"")) -> 4250 | D14: =IF(B3>0,(E3*B3),0)+IF(B4>0,(E4*B4),0)+IF(B5>0,(E5*B5),0)+IF(B6>0,(E6*B6),0)+IF(B7>0,(E7*B7),0) -> 0 | E14: =IF(C3="F.A.D.",(B3*E3),0)+IF(C3="C.R.V.",((B3*(E3/2)))+IF(C3="ECONOMIZER",((B3*(-E3))),0))+IF(C4="F.A.D.",(B4*E4),0)+IF(C4="C.R.V.",((B4*(E4/2)))+IF(C4="ECONOMIZER",((B4*(-E4))),0))+IF(C5="F.A.D.",(B5*E5),0)+IF(C5="C.R.V.",((B5*(E5/2)))+IF(C5="ECONOMIZER",((B5*(-E5))),0))+IF(C6="F.A.D.",(B6*E6),0)+IF(C6="C.R.V.",((B6*(E6/2)))+IF(C6="ECONOMIZER",((B6*(-E6))),0))+IF(C7="F.A.D.",(B7*E7),0)+IF(C7="C.R.V.",((B7*(E7/2)))+IF(C7="ECONOMIZER",((B7*(-E7))),0)) -> 0 | G14: =IF(E14>300000,"ECONOMIZERS REQUIRED",IF((((OR(A3="5 TON",A4="5 TON",A5="5 TON",A6="5 TON",A7="5 TON")))),"ECONOMIZERS REQUIRED @ 5 TON","NO ADD'L VENTILATION REQUIRED")) -> NO ADD'L VENTILATION REQUIRED | U14: =INDEX(Exceptions09,MATCH(D22,ClimateZone09,0)) -> Meets Exception | X14: 5C | Y14: No Exception | AB14: =INDEX(AF2:AF18,MATCH(D22,AE2:AE18,0)) -> Doesn't Meet | AE14: 5C | AF14: No Exception | AI14: =INDEX(AM2:AM18,MATCH(D22,AL2:AL18,0)) -> Doesn't Meet | AL14: 5C | AM14: No Exception | AP14: =INDEX(AT2:AT18,MATCH(D22,AS2:AS18,0)) -> Doesn't Meet | AS14: 5C | AT14: No Exception | AW14: =INDEX(BA1:BA16,MATCH(#REF!,AZ1:AZ16,0)) -> #REF! | AZ14: 14 | BA14: =IF(((E22*0.3)+E22)<G22,"Meets Exception","Doesn't Meet") -> Doesn't Meet
G15: Note: 2012 IECC: HVAC's 3-Ton or Greater require Economizers | X15: 6A | Y15: No Exception | AE15: 6A | AF15: No Exception | AL15: 6A | AM15: No Exception | AS15: 6A | AT15: No Exception | AZ15: 15 | BA15: =IF(((E22*0.3)+E22)<G22,"Meets Exception","Doesn't Meet") -> Doesn't Meet
A16: NOTES: | X16: 6B | Y16: No Exception | AE16: 6B | AF16: No Exception | AL16: 6B | AM16: No Exception | AS16: 6B | AT16: No Exception | AZ16: 16 | BA16: =IF(((E22*0.7)+E22)<G22,"Meets Exception","Doesn't Meet") -> Doesn't Meet
A17: 1. WHEN ECONOMIZERS ARE REQUIRED OVER 300,000 BTU, LOOK AT CHART AND BRING THE TOTAL UNDER 300,000. NOT ALL HVAC'S NEED ECONOMIZERS. | X17: 7 | Y17: Not Required | AE17: 7 | AF17: No Exception | AL17: 7 | AM17: Not in 2015 Code | AS17: 7 | AT17: Not in 2018 Code
A18: 2. WHEN CRV'S ARE REQUIRED, LOOK AT CHART AND MEET THE ADDITIONAL REQUIRED. NOT ALL HVAC'S NEED CRV'S IN CASES. | X18: 8 | Y18: Not Required | AE18: 8 | AF18: No Exception | AL18: 8 | AM18: Not in 2015 Code | AS18: 8 | AT18: Not in 2018 Code
A20: ECONOMIZER EXCEPTION
A21: Code Year: | B21: HVAC Size (Tons): | C21: HVAC Type: | D21: IECC Climate Zone: | E21: Min. EER Rating: | F21: Min. SEER Rating: | G21: Equipment EER Rating: | H21: Equipment SEER Rating: | I21: Results: | U21: PMI Elec. Equip. | W21: Equipment Size EER Rating
A22: 2018 IECC | B22: 3 | C22: Roof Top AC (1P) | D22: 2B | E22: =IF(AND(OR(A22="2009 iecc",A22="2012 iecc",A22="2015 iecc",A22="2018 iecc"),C22="Bard ac"),W2,IF(AND(OR(A22="2009 iecc",A22="2012 iecc",A22="2015 iecc",A22="2018 iecc"),C22="Bard HP"),W3,IF(AND(OR(A22="2009 iecc",A22="2012 iecc"),C22="roof top ac (1P)"),W4,IF(AND(OR(A22="2009 iecc",A22="2012 iecc"),C22="roof top ac (3P)"),W5,IF(AND(OR(A22="2009 iecc",A22="2012 iecc"),C22="roof top hp (1P)"),W6,IF(AND(OR(A22="2009 iecc",A22="2012 iecc"),C22="roof top hp (3P)"),W7,IF(AND(OR(A22="2009 iecc",A22="2012 iecc"),C22="split system"),W8,IF(AND(OR(A22="2009 iecc",A22="2012 iecc"),C22="minisplit ac"),W9,IF(AND(OR(A22="2009 iecc",A22="2012 iecc"),C22="thru wall"),W10,IF(AND(OR(A22="2015 iecc",A22="2018 iecc"),C22="roof top ac (1P)"),AK4,IF(AND(OR(A22="2015 iecc",A22="2018 iecc"),C22="roof top ac (3P)"),AK5,IF(AND(OR(A22="2015 iecc",A22="2018 iecc"),C22="roof top hp (1P)"),AK6,IF(AND(OR(A22="2015 iecc",A22="2018 iecc"),C22="roof top hp (3P)"),AK7,IF(AND(OR(A22="2015 iecc",A22="2018 iecc"),C22="split system"),AK8,IF(AND(OR(A22="2015 iecc",A22="2018 iecc"),C22="minisplit ac"),AK9,IF(AND(OR(A22="2015 iecc",A22="2018 iecc"),C22="thru wall"),AK10,IF(AND(A22="2009 iecc",C22="ptac"),W11,IF(AND(A22="2012 iecc",C22="ptac"),AD11,IF(AND(A22="2015 iecc",C22="ptac"),AK11,IF(AND(A22="2018 iecc",C22="ptac"),AR11,IF(AND(A22="2019 cec",C22="Bard ac"),AY2,IF(AND(A22="2019 cec",C22="Bard HP"),AY3,IF(AND(A22="2019 cec",C22="roof top ac (1P)"),AY4,IF(AND(A22="2019 cec",C22="roof top ac (3P)"),AY5,IF(AND(A22="2019 cec",C22="roof top hp (1P)"),AY6,IF(AND(A22="2019 cec",C22="roof top hp (3P)"),AY7,IF(AND(A22="2019 cec",C22="split system"),AY8,IF(AND(A22="2019 cec",C22="minisplit ac"),AY9,IF(AND(A22="2019 cec",C22="thru wall"),AY10,IF(AND(A22="2019 cec",C22="ptac"),AY11,"")))))))))))))))))))))))))))))) -> 11.76 | F22: =IF(AND(OR(A22="2009 iecc",A22="2012 iecc",A22="2015 iecc",A22="2018 iecc",A22="2019 cec"),C22="Bard ac"),V2,IF(AND(OR(A22="2009 iecc",A22="2012 iecc",A22="2015 iecc",A22="2018 iecc",A22="2019 cec"),C22="Bard HP"),V3,IF(AND(OR(A22="2009 iecc",A22="2012 iecc"),C22="roof top ac (1P)"),V4,IF(AND(OR(A22="2009 iecc",A22="2012 iecc"),C22="roof top ac (3P)"),V5,IF(AND(OR(A22="2009 iecc",A22="2012 iecc"),C22="roof top hp (1P)"),V6,IF(AND(OR(A22="2009 iecc",A22="2012 iecc"),C22="roof top hp (3P)"),V7,IF(AND(OR(A22="2009 iecc",A22="2012 iecc"),C22="split system"),V8,IF(AND(OR(A22="2009 iecc",A22="2012 iecc"),C22="minisplit ac"),V9,IF(AND(OR(A22="2009 iecc",A22="2012 iecc"),C22="thru wall"),V10,IF(AND(OR(A22="2015 iecc",A22="2018 iecc",A22="2019 cec"),C22="roof top ac (1P)"),AJ4,IF(AND(OR(A22="2015 iecc",A22="2018 iecc",A22="2019 cec"),C22="roof top ac (3P)"),AJ5,IF(AND(OR(A22="2015 iecc",A22="2018 iecc",A22="2019 cec"),C22="roof top hp (1P)"),AJ6,IF(AND(OR(A22="2015 iecc",A22="2018 iecc",A22="2019 cec"),C22="roof top hp (3P)"),AJ7,IF(AND(OR(A22="2015 iecc",A22="2018 iecc",A22="2019 cec"),C22="split system"),AJ8,IF(AND(OR(A22="2015 iecc",A22="2018 iecc",A22="2019 cec"),C22="minisplit ac"),AJ9,IF(AND(OR(A22="2015 iecc",A22="2018 iecc"),C22="thru wall"),AJ10,IF(AND(A22="2019 cec",C22="thru wall"),AX10,IF(AND(OR(A22="2009 iecc",A22="2012 iecc",A22="2015 iecc",A22="2018 iecc",A22="2019 cec"),C22="ptac"),V11,"")))))))))))))))))) -> 14 | G22: =INDEX(EerTable,MATCH(C22,EerEquipment,0),MATCH(B22,EerHVACsize,0)) -> 12.5 | H22: =INDEX(SeerTable,MATCH(C22,SeerEquipment,0),MATCH(B22,SeerHVACsize,0)) -> 15 | I22: =IF(A22="2009 iecc",U14,IF(A22="2012 iecc",AB14,IF(A22="2015 iecc",AI14,IF(A22="2018 iecc",AP14,IF(A22="2019 cec",AW14,""))))) -> Doesn't Meet | W22: 0.75 | X22: 1 | Y22: 1.5 | Z22: 2 | AA22: 2.5 | AB22: 3 | AC22: 3.5 | AD22: 4 | AE22: 5
V23: Bard AC | W23: - | X23: 11 | Y23: 11.3 | Z23: 11.2 | AA23: 11.2 | AB23: 11 | AC23: 11 | AD23: 11 | AE23: 11
V24: Bard HP | W24: - | X24: - | Y24: 11 | Z24: 11 | AA24: 11 | AB24: 11 | AC24: 11 | AD24: 11 | AE24: 11
V25: Roof Top AC (1P) | W25: - | X25: - | Y25: - | Z25: - | AA25: - | AB25: 12.5 | AC25: 12.5 | AD25: 12 | AE25: 12
V26: Roof Top AC (3P) | W26: - | X26: - | Y26: - | Z26: - | AA26: - | AB26: 13 | AC26: 13 | AD26: 12.5 | AE26: 12.5
V27: Roof Top HP (1P) | W27: - | X27: - | Y27: - | Z27: - | AA27: - | AB27: 13 | AC27: 13 | AD27: 12 | AE27: 12
V28: Roof Top HP (3P) | W28: - | X28: - | Y28: - | Z28: - | AA28: - | AB28: 13 | AC28: 13 | AD28: 12.5 | AE28: 12.5
V29: Minisplit AC | W29: 10.4 | X29: 10.6 | Y29: 12.2 | Z29: 9.2 | AA29: - | AB29: - | AC29: - | AD29: - | AE29: -
V30: Split System
V31: Thru Wall
V32: PTAC
U35: PMI Elec. Equip. | W35: Equipment Size SEER Rating
W36: 0.75 | X36: 1 | Y36: 1.5 | Z36: 2 | AA36: 2.5 | AB36: 3 | AC36: 3.5 | AD36: 4 | AE36: 5
V37: Bard AC | W37: - | X37: - | Y37: - | Z37: - | AA37: - | AB37: - | AC37: - | AD37: - | AE37: -
V38: Bard HP | W38: - | X38: - | Y38: - | Z38: - | AA38: - | AB38: - | AC38: - | AD38: - | AE38: -
V39: Roof Top AC (1P) | W39: - | X39: - | Y39: - | Z39: - | AA39: - | AB39: 15 | AC39: 15 | AD39: 15 | AE39: 15
V40: Roof Top AC (3P) | W40: - | X40: - | Y40: - | Z40: - | AA40: - | AB40: 15 | AC40: 15 | AD40: 15 | AE40: 15
V41: Roof Top HP (1P) | W41: - | X41: - | Y41: - | Z41: - | AA41: - | AB41: 15.5 | AC41: 15.5 | AD41: 15 | AE41: 15
V42: Roof Top HP (3P) | W42: - | X42: - | Y42: - | Z42: - | AA42: - | AB42: 15 | AC42: 15 | AD42: 15 | AE42: 15
V43: Minisplit AC | W43: 16 | X43: 16 | Y43: 16 | Z43: 16 | AA43: - | AB43: - | AC43: - | AD43: - | AE43: -
...

Sheet CA Outisde Air
A1: 2022 CEC / Table 120.1-A
A2: BUILDING USE: | B2: =IF(I4="YES","MIN. VENTILATION AIR RATE FOR DCV (Ra):","TOTAL OUTDOOR AIRFLOW RATE (Rt):") -> TOTAL OUTDOOR AIRFLOW RATE (Rt): | C2: SQUARE FOOTAGE | D2: OUTSIDE AIR REQUIRED | E2: Notes:
A3: Educational Facilities
A4: Daycare (through age 4) | B4: =IF(I4="yes",0.15,0.21) -> 0.21 | D4: =SUM(B4*C4) -> 0 | E4: =IF(I4="yes","Title 24: CO2 Sensor required","") | I4: No | J4: :Economizer, CRV, or ERV Installed
A5: Daycare sickroom | B5: 0.15 | D5: =SUM(B5*C5) -> 0
A6: Classrooms (ages 5-8) | B6: =IF(I4="yes",0.15,0.38) -> 0.38 | D6: =SUM(B6*C6) -> 0 | E6: =IF(I4="yes","Title 24: CO2 Sensor required","")
A7: Classrooms (ages 9-18) | B7: =IF(I4="yes",0.15,0.38) -> 0.38 | D7: =SUM(B7*C7) -> 0 | E7: =IF(I4="yes","Title 24: CO2 Sensor required","")
A8: Lecture/postsecondary classroom | B8: =IF(I4="yes",0.15,0.38) -> 0.38 | D8: =SUM(B8*C8) -> 0 | E8: =IF(I4="yes","Title 24: CO2 Sensor required","")
A9: Lecture hall (fixed seats) | B9: =IF(I4="yes",0.15,"-") -> - | E9: =IF(I4="yes","Title 24: CO2 Sensor required","")
A10: Art classroom | B10: 0.15 | D10: =SUM(B10*C10) -> 0
A11: Science laboratories | B11: 0.15 | D11: =SUM(B11*C11) -> 0
A12: University/college laboratories | B12: 0.15 | D12: =SUM(B12*C12) -> 0
A13: Wood/metal shop | B13: 0.15 | D13: =SUM(B13*C13) -> 0
A14: Computer lab | B14: 0.15 | D14: =SUM(B14*C14) -> 0
A15: Media center | B15: 0.15 | D15: =SUM(B15*C15) -> 0
A16: Music/theater/dance | B16: =IF(I4="yes",0.15,1.07) -> 1.07 | D16: =SUM(B16*C16) -> 0 | E16: =IF(I4="yes","Title 24: CO2 Sensor required","")
A17: Multiuse assembly | B17: =IF(I4="yes",0.15,0.5) -> 0.5 | D17: =SUM(B17*C17) -> 0 | E17: =IF(I4="yes","Title 24: CO2 Sensor required","")
A18: Food and Beverage Service
A19: Restaurant dining rooms | B19: =IF(I4="yes",0.15,0.5) -> 0.5 | D19: =SUM(B19*C19) -> 0 | E19: =IF(I4="yes","Title 24: CO2 Sensor required","")
A20: Cafeteria/fast-food dining | B20: =IF(I4="yes",0.15,0.5) -> 0.5 | D20: =SUM(B20*C20) -> 0 | E20: =IF(I4="yes","Title 24: CO2 Sensor required","")
A21: Bars, cocktail lounges | B21: =IF(I4="yes",0.2,0.5) -> 0.5 | D21: =SUM(B21*C21) -> 0 | E21: =IF(I4="yes","Title 24: CO2 Sensor required","")
A22: Kitchen (cooking) | B22: 0.15 | D22: =SUM(B22*C22) -> 0
A23: General
A24: Break rooms | B24: =IF(I4="yes",0.15,0.5) -> 0.5 | D24: =SUM(B24*C24) -> 0 | E24: =IF(I4="yes","Title 24: CO2 Sensor required","")
A25: Coffee Stations | B25: =IF(I4="yes",0.15,0.5) -> 0.5 | D25: =SUM(B25*C25) -> 0 | E25: =IF(I4="yes","Title 24: CO2 Sensor required","")
A26: Conference/meeting | B26: =IF(I4="yes",0.15,0.5) -> 0.5 | D26: =SUM(B26*C26) -> 0 | E26: =IF(I4="yes","Title 24: CO2 Sensor required","")
A27: Corridors | B27: 0.15 | D27: =SUM(B27*C27) -> 0
A28: Occupiable storage rooms for liquids or gels | B28: 0.15 | D28: =SUM(B28*C28) -> 0
A29: Hotels, Motels, Resorts, Dormitories
A30: Bedroom/living room | B30: 0.15 | D30: =SUM(B30*C30) -> 0
A31: Barracks sleeping areas | B31: 0.15 | D31: =SUM(B31*C31) -> 0
A32: Laundry rooms, central | B32: 0.15 | D32: =SUM(B32*C32) -> 0
A33: Laundry rooms within dwelling units | B33: 0.15 | D33: =SUM(B33*C33) -> 0
A34: Lobbies/pre-function | B34: =IF(I4="yes",0.15,0.5) -> 0.5 | D34: =SUM(B34*C34) -> 0 | E34: =IF(I4="yes","Title 24: CO2 Sensor required","")
A35: Multipurpose assembly | B35: 0.5 | D35: =SUM(B35*C35) -> 0
A36: Office Buildings
A37: Breakrooms | B37: =IF(I4="yes",0.15,0.5) -> 0.5 | D37: =SUM(B37*C37) -> 0 | E37: =IF(I4="yes","Title 24: CO2 Sensor required","")
A38: Main entry lobbies | B38: =IF(I4="yes",0.15,0.5) -> 0.5 | D38: =SUM(B38*C38) -> 0 | E38: =IF(I4="yes","Title 24: CO2 Sensor required","")
A39: Occupiable storage rooms for dry materials | B39: 0.15 | D39: =SUM(B39*C39) -> 0
A40: Office space | B40: 0.15 | D40: =SUM(B40*C40) -> 0
...

Sheet  CA Vent Rate
A1: 2019 CA ENERGY CODE: CHAPTER 3 / SECTION 120.1.2 (A) (B)
A5: NOTE:
A6: THERE ARE (2) METHODS OF FIGURING THE REQUIRED OUTSIDE AIR, BUT THE GREATER OF THE TWO MUST BE USED.
A11: OVERALL BUILDING SQUARE FOOTAGE: | E11: 0
A13: TOTAL OCCUPANT LOAD: | E13: =SUM('Occupant Calculator'!D26) -> 333.4 | F13: <---- USE OCCUPANT CALCULATOR OR ENTER # OF OCCUPANTS, IF CELL IS OVERWRITTEN THEN USE FORMULA: =SUM('Occupant Calculator'!D27)
A16: METHOD 1: OVERALL BUILDING SQ. FT.: | E16: =SUM(E11*0.15) -> 0
A17: METHOD 2: OVERALL OCCUPANCY: | E17: =SUM(E13*15) -> 5001

Sheet CA Endmount Calc
A1: WALL MOUNT HVAC'S | K1: BARD WALL MOUNT OUTDOOR AIR VENTILATION:
A2: A/C SIZE: | B2: # OF A/C's: | C2: VENTILATION TYPE: | D2: VENTILATION RATE: | E2: COOLING BTU: | G2: CA ECONOMIZER REQUIREMENTS: | K2: HVAC SIZE: | L2: CFM OUTPUT: | M2: F.A.D. | N2: C.R.V. | O2: ECONOMIZER | P2: ERV | R2: HVAC HEAT STRIP BTHU CONV. | X2: =IF(C3="F.A.D.",(B3*E3),0)+IF(C3="C.R.V.",((B3*(E3/2)))+IF(C3="ECONOMIZER",((B3*(-E3))),0))+IF(C4="F.A.D.",(B4*E4),0)+IF(C4="C.R.V.",((B4*(E4/2)))+IF(C4="ECONOMIZER",((B4*(-E4))),0))+IF(C5="F.A.D.",(B5*E5),0)+IF(C5="C.R.V.",((B5*(E5/2)))+IF(C5="ECONOMIZER",((B5*(-E5))),0))+IF(C6="F.A.D.",(B6*E6),0)+IF(C6="C.R.V.",((B6*(E6/2)))+IF(C6="ECONOMIZER",((B6*(-E6))),0))+IF(C7="F.A.D.",(B7*E7),0)+IF(C7="C.R.V.",((B7*(E7/2)))+IF(C7="ECONOMIZER",((B7*(-E7))),0))+IF(C3="ERV",(B3*(E3-12000)),0)+IF(AND(C3="ERV",(OR(A3="1.5 TON",A3="2 TON"))),B3*(E3-7500),IF(AND(C3="ERV",(OR(A3="2.5 TON",A3="3 TON"))),B3*(E3-12000),IF(AND(C3="ERV",(OR(A3="3.5 TON",A3="4 TON",A3="5 TON"))),B3*(E3-13500),0)))+IF(AND(C4="ERV",(OR(A4="1.5 TON",A4="2 TON"))),B4*(E4-7500),IF(AND(C4="ERV",(OR(A4="2.5 TON",A4="3 TON"))),B4*(E4-12000),IF(AND(C4="ERV",(OR(A4="3.5 TON",A4="4 TON",A4="5 TON"))),B4*(E4-13500),0)))+IF(AND(C5="ERV",(OR(A5="1.5 TON",A5="2 TON"))),B5*(E5-7500),IF(AND(C5="ERV",(OR(A5="2.5 TON",A5="3 TON"))),B5*(E5-12000),IF(AND(C5="ERV",(OR(A5="3.5 TON",A5="4 TON",A5="5 TON"))),B5*(E5-13500),0)))+IF(AND(C6="ERV",(OR(A6="1.5 TON",A6="2 TON"))),B6*(E6-7500),IF(AND(C6="ERV",(OR(A6="2.5 TON",A6="3 TON"))),B6*(E6-12000),IF(AND(C6="ERV",(OR(A6="3.5 TON",A6="4 TON",A6="5 TON"))),B6*(E6-13500),0)))+IF(AND(C7="ERV",(OR(A7="1.5 TON",A7="2 TON"))),B7*(E7-7500),IF(AND(C7="ERV",(OR(A7="2.5 TON",A7="3 TON"))),B7*(E7-12000),IF(AND(C7="ERV",(OR(A7="3.5 TON",A7="4 TON",A7="5 TON"))),B7*(E7-13500),0))) -> 0
A3: 3 TON | B3: 0 | C3: F.A.D. | D3: =INDEX(M3:P10,MATCH(A3,HVACsizeUMC,0),MATCH(C3,M2:P2,0))*B3 -> 0 | E3: =IF(AND(B3>0,A3="1 TON"),"12,000",IF(AND(B3>0,A3="1.5 TON"),"18,000",IF(AND(B3>0,A3="2 TON"),"24,000",IF(AND(B3>0,A3="2.5 TON"),"30,000",IF(AND(B3>0,A3="3 TON"),"36,000",IF(AND(B3>0,A3="3.5 TON"),"42,000",IF(AND(B3>0,A3="4 TON"),"48,000",IF(AND(B3>0,A3="5 TON"),"60,000",0)))))))) -> 0 | G3: CA / UMC: | H3: OVER 2.5 TON | K3: N/A | L3: 0 | M3: 0 | N3: 0 | O3: 0 | P3: 0 | R3: ENTER KW: | S3: 0
A4: N/A | B4: 0 | C4: F.A.D. | D4: =INDEX(M3:P10,MATCH(A4,HVACsizeUMC,0),MATCH(C4,M2:P2,0))*B4 -> 0 | E4: =IF(AND(B4>0,A4="1 TON"),"12,000",IF(AND(B4>0,A4="1.5 TON"),"18,000",IF(AND(B4>0,A4="2 TON"),"24,000",IF(AND(B4>0,A4="2.5 TON"),"30,000",IF(AND(B4>0,A4="3 TON"),"36,000",IF(AND(B4>0,A4="3.5 TON"),"42,000",IF(AND(B4>0,A4="4 TON"),"48,000",IF(AND(B4>0,A4="5 TON"),"60,000",0)))))))) -> 0 | G4: Exception: ERV is provided, then no greater than 4 Ton | K4: 1.5 TON | L4: 600 | M4: =SUM(L4*0.25) -> 150 | N4: =SUM(L4*0.5) -> 300 | O4: =SUM(L4*1) -> 600 | P4: 250 | R4: = BTHU: | S4: =SUM( S3*3.412142) -> 0
A5: N/A | B5: 0 | C5: F.A.D. | D5: =INDEX(M3:P10,MATCH(A5,HVACsizeUMC,0),MATCH(C5,M2:P2,0))*B5 -> 0 | E5: =IF(AND(B5>0,A5="1 TON"),"12,000",IF(AND(B5>0,A5="1.5 TON"),"18,000",IF(AND(B5>0,A5="2 TON"),"24,000",IF(AND(B5>0,A5="2.5 TON"),"30,000",IF(AND(B5>0,A5="3 TON"),"36,000",IF(AND(B5>0,A5="3.5 TON"),"42,000",IF(AND(B5>0,A5="4 TON"),"48,000",IF(AND(B5>0,A5="5 TON"),"60,000",0)))))))) -> 0 | K5: 2 TON | L5: 800 | M5: =SUM(L5*0.25) -> 200 | N5: =SUM(L5*0.5) -> 400 | O5: =SUM(L5*1) -> 800 | P5: 250
A6: N/A | B6: 0 | C6: F.A.D. | D6: =INDEX(M3:P10,MATCH(A6,HVACsizeUMC,0),MATCH(C6,M2:P2,0))*B6 -> 0 | E6: =IF(AND(B6>0,A6="1 TON"),"12,000",IF(AND(B6>0,A6="1.5 TON"),"18,000",IF(AND(B6>0,A6="2 TON"),"24,000",IF(AND(B6>0,A6="2.5 TON"),"30,000",IF(AND(B6>0,A6="3 TON"),"36,000",IF(AND(B6>0,A6="3.5 TON"),"42,000",IF(AND(B6>0,A6="4 TON"),"48,000",IF(AND(B6>0,A6="5 TON"),"60,000",0)))))))) -> 0 | K6: 2.5 TON | L6: 950 | M6: =SUM(L6*0.25) -> 237.5 | N6: =SUM(L6*0.5) -> 475 | O6: =SUM(L6*1) -> 950 | P6: 400
A7: N/A | B7: 0 | C7: F.A.D. | D7: =INDEX(M3:P10,MATCH(A7,HVACsizeUMC,0),MATCH(C7,M2:P2,0))*B7 -> 0 | E7: =IF(AND(B7>0,A7="1 TON"),"12,000",IF(AND(B7>0,A7="1.5 TON"),"18,000",IF(AND(B7>0,A7="2 TON"),"24,000",IF(AND(B7>0,A7="2.5 TON"),"30,000",IF(AND(B7>0,A7="3 TON"),"36,000",IF(AND(B7>0,A7="3.5 TON"),"42,000",IF(AND(B7>0,A7="4 TON"),"48,000",IF(AND(B7>0,A7="5 TON"),"60000",0)))))))) -> 0 | K7: 3 TON | L7: 1150 | M7: =SUM(L7*0.25) -> 287.5 | N7: =SUM(L7*0.5) -> 575 | O7: =SUM(L7*1) -> 1150 | P7: 400
C8: =IF(AND(B3>0,A3="5 TON"),"ECONOMIZER REQUIRED @ 5 TON",IF(AND(B4>0,A4="5 TON"),"ECONOMIZER REQUIRED @ 5 TON",IF(AND(B5>0,A5="5 TON"),"ECONOMIZER REQUIRED @ 5 TON",IF(AND(B6>0,A6="5 TON"),"ECONOMIZER REQUIRED @ 5 TON",IF(AND(B7>0,A7="5 TON"),"ECONOMIZER REQUIRED @ 5 TON","NO ADD'L VENTILATION REQUIRED"))))) -> NO ADD'L VENTILATION REQUIRED | K8: 3.5 TON | L8: 1350 | M8: =SUM(L8*0.25) -> 337.5 | N8: =SUM(L8*0.5) -> 675 | O8: =SUM(L8*1) -> 1350 | P8: 450
K9: 4 TON | L9: 1550 | M9: =SUM(L9*0.25) -> 387.5 | N9: =SUM(L9*0.5) -> 775 | O9: =SUM(L9*1) -> 1550 | P9: 450
K10: 5 TON | L10: 1750 | M10: =SUM(L10*0.25) -> 437.5 | N10: =SUM(L10*0.5) -> 875 | O10: =SUM(L10*1) -> 1750 | P10: 450
K11: NOTE: THE ABOVE CFM OUTPUT IS BASED ON A BARD HVAC UNIT. CFM OUTPUT MAY VARY BASED ON BRAND OF HVAC.
A13: OUTDOOR AIR PROPOSED: | B13: TOTAL NEEDED: | C13: ADD'L REQUIRED: | D13: TOTAL COOLING BTU: | E13: VENTILATION REQUIREMENT:
A14: =SUM(D3:D7) -> 0 | B14: ='CA Outisde Air'!D89 -> 0 | C14: =IF(A14>B14,"NO ADD'L NEEDED",IF(A14<B14,(B14-A14),"")) | D14: =IF(B3>0,(E3*B3),0)+IF(B4>0,(E4*B4),0)+IF(B5>0,(E5*B5),0)+IF(B6>0,(E6*B6),0)+IF(B7>0,(E7*B7),0) -> 0 | E14: =IF(AND(B3>0,A3="5 TON"),"ECONOMIZER REQUIRED @ 5 TON",IF(AND(B4>0,A4="5 TON"),"ECONOMIZER REQUIRED @ 5 TON",IF(AND(B5>0,A5="5 TON"),"ECONOMIZER REQUIRED @ 5 TON",IF(AND(B6>0,A6="5 TON"),"ECONOMIZER REQUIRED @ 5 TON",IF(AND(B7>0,A7="5 TON"),"ECONOMIZER REQUIRED @ 5 TON",IF(AND(AND(B3>0),(C3="F.A.D."),(OR(A3="3 TON",A3="3.5 TON",A3="4 TON",A3="5 TON"))),"ECONOMIZER REQUIRED @ UNIT(S) W/O ERV",IF(AND(AND(B3>0),(C3="C.R.V."),(OR(A3="3 TON",A3="3.5 TON",A3="4 TON",A3="5 TON"))),"ECONOMIZER REQUIRED @ UNIT(S) W/O ERV",IF(AND(AND(B3>0),(C3="ERV"),A3="5 TON"),"ECONOMIZER REQUIRED @ 5 TON",IF(AND(AND(B4>0),(C4="F.A.D."),(OR(A4="3 TON",A4="3.5 TON",A4="4 TON",A4="5 TON"))),"ECONOMIZER REQUIRED @ UNIT(S) W/O ERV",IF(AND(AND(B4>0),(C4="C.R.V."),(OR(A4="3 TON",A4="3.5 TON",A4="4 TON",A4="5 TON"))),"ECONOMIZER REQUIRED @ UNIT(S) W/O ERV",IF(AND(AND(B4>0),(C4="ERV"),A4="5 TON"),"ECONOMIZER REQUIRED @ 5 TON",IF(AND(AND(B5>0),(C5="F.A.D."),(OR(A5="3 TON",A5="3.5 TON",A5="4 TON",A5="5 TON"))),"ECONOMIZER REQUIRED @ UNIT(S) W/O ERV",IF(AND(AND(B5>0),(C5="C.R.V."),(OR(A5="3 TON",A5="3.5 TON",A5="4 TON",A5="5 TON"))),"ECONOMIZER REQUIRED @ UNIT(S) W/O ERV",IF(AND(AND(B5>0),(C5="ERV"),A5="5 TON"),"ECONOMIZER REQUIRED @ 5 TON",IF(AND(AND(B6>0),(C6="F.A.D."),(OR(A6="3 TON",A6="3.5 TON",A6="4 TON",A6="5 TON"))),"ECONOMIZER REQUIRED @ UNIT(S) W/O ERV",IF(AND(AND(B6>0),(C6="C.R.V."),(OR(A6="3 TON",A6="3.5 TON",A6="4 TON",A6="5 TON"))),"ECONOMIZER REQUIRED @ UNIT(S) W/O ERV",IF(AND(AND(B6>0),(C6="ERV"),A6="5 TON"),"ECONOMIZER REQUIRED @ 5 TON",IF(AND(AND(B7>0),(C7="F.A.D."),(OR(A7="3 TON",A7="3.5 TON",A7="4 TON",A7="5 TON"))),"ECONOMIZER REQUIRED @ UNIT(S) W/O ERV",IF(AND(AND(B7>0),(C7="C.R.V."),(OR(A7="3 TON",A7="3.5 TON",A7="4 TON",A7="5 TON"))),"ECONOMIZER REQUIRED @ UNIT(S) W/O ERV",IF(AND(AND(B7>0),(C7="ERV"),A7="5 TON"),"ECONOMIZER REQUIRED @ 5 TON","NO ADD'L VENTILATION REQUIRED")))))))))))))))))))) -> NO ADD'L VENTILATION REQUIRED
A16: NOTES:
A17: 1. WHEN MULTIPLE HVAC'S ARE SERVING COMMON A AREA(S) THEN SMOKE DUCT DETECTION WILL BE REQUIRED FOR THOSE HVAC'S.
A18: 2. WHEN CRV'S ARE REQUIRED, LOOK AT CHART AND MEET THE ADDITIONAL REQUIRED. NOT ALL HVAC'S NEED CRV'S IN SOME CASES.

Sheet CA Rooftop Calc
A1: RTU HVAC'S | H1: DAIKIN ROOF TOP OUTDOOR AIR VENTILATION:
