Workbook
Name HEIGHT: Check!$B$3
Name intwall: Check!$B$5
Name LENGTH: Check!$B$2
Name MODS: Check!$B$4
Name perimeter: Check!$E$2
Name perimsqft: Check!$E$3
Name sqft: Check!$E$1
Name WIDTH: Check!$B$1

Sheet Paste Here
A1: lblSize | B1: txtFactoredCost | C1: cmbCategory | D1: cmbSubCategory | E1: txtBOMDesc | F1: txtAddOnDescription | G1: txtNotes | H1: txtQuantity | I1: txtUM | J1: txtPrice | K1: txtFilterCategory | L1: txtFilterSubCategory | M1: txtFilterDesc | N1: Item | O1: Category | P1: SubCategory | Q1: QuoteDetailDesc | R1: Quantity | S1: UM | T1: ItemPrice | U1: TotalPrice | V1: Notes | W1: QuoteDetailsKey
A2: Size: 48 x 60 x 12 SF: 2,880 Interior Wall: 262 Total cost for selected items: $163,842.36 Total cost with factors: | B2: $355,469.53 | C2: FRAME | D2: OUTRIGGER | N2: BOM | O2: FRAME | P2: OUTRIGGER | Q2: Chassis Basement 12' X 60' - 12" X 11.8# I-Beam OR/CM/MC 8'/8'/8' | R2: 4 | S2: EA | T2: 2632.92 | U2: 10531.68 | W2: 62405
A3: Size: 48 x 60 x 12 SF: 2,880 Interior Wall: 262 Total cost for selected items: $163,842.36 Total cost with factors: | B3: $355,469.53 | C3: FRAME | D3: OUTRIGGER | N3: BOM | O3: FRAME | P3: AXLES | Q3: Five Axle (5 Brake Axles) | R3: 4 | S3: EA | T3: 2033.65 | U3: 8134.6 | W3: 62504
A4: Size: 48 x 60 x 12 SF: 2,880 Interior Wall: 262 Total cost for selected items: $163,842.36 Total cost with factors: | B4: $355,469.53 | C4: FRAME | D4: OUTRIGGER | N4: BOM | O4: FRAME | P4: MISC | Q4: Outrigger For 12' Wide (Add-On) | R4: 8 | S4: PAIR | T4: 25.46 | U4: 203.68 | V4: Outriggers 4' O/C at exterior side walls | W4: 62407
A5: Size: 48 x 60 x 12 SF: 2,880 Interior Wall: 262 Total cost for selected items: $163,842.36 Total cost with factors: | B5: $355,469.53 | C5: FRAME | D5: OUTRIGGER | N5: BOM | O5: FLOOR | P5: JOIST | Q5: 2 X 8 @ 12" O/C | R5: 2380 | S5: SF | T5: 1.28 | U5: 3046.4 | V5: 150 psf Gym Room, 125 PSF Storage, / 100 psf Break area & Corridor | W5: 62514
A6: Size: 48 x 60 x 12 SF: 2,880 Interior Wall: 262 Total cost for selected items: $163,842.36 Total cost with factors: | B6: $355,469.53 | C6: FRAME | D6: OUTRIGGER | N6: BOM | O6: FLOOR | P6: JOIST | Q6: 2 X 8 @ 16" O/C | R6: 500 | S6: SF | T6: 1.1 | U6: 550 | V6: 50 psf Offices | W6: 62408
A7: Size: 48 x 60 x 12 SF: 2,880 Interior Wall: 262 Total cost for selected items: $163,842.36 Total cost with factors: | B7: $355,469.53 | C7: FRAME | D7: OUTRIGGER | N7: BOM | O7: FLOOR | P7: DECKING | Q7: 1-1/8" T&G OSB | R7: 2880 | S7: SF | T7: 1.15 | U7: 3312 | W7: 62515
A8: Size: 48 x 60 x 12 SF: 2,880 Interior Wall: 262 Total cost for selected items: $163,842.36 Total cost with factors: | B8: $355,469.53 | C8: FRAME | D8: OUTRIGGER | N8: BOM | O8: FLOOR | P8: INSULATION | Q8: R-30 Unfaced (2 layers R-15) | R8: 2880 | S8: SF | T8: 1.39 | U8: 4003.2 | W8: 62410
A9: Size: 48 x 60 x 12 SF: 2,880 Interior Wall: 262 Total cost for selected items: $163,842.36 Total cost with factors: | B9: $355,469.53 | C9: FRAME | D9: OUTRIGGER | N9: BOM | O9: FLOOR | P9: COVERING | Q9: Floor Tile VCT - 1/8" X 12" X 12" | R9: 2760 | S9: SF | T9: 1.57 | U9: 4333.2 | V9: VCT flooring throughout except in restrooms | W9: 62413
A10: Size: 48 x 60 x 12 SF: 2,880 Interior Wall: 262 Total cost for selected items: $163,842.36 Total cost with factors: | B10: $355,469.53 | C10: FRAME | D10: OUTRIGGER | N10: BOM | O10: FLOOR | P10: COVERING | Q10: Sheet Vinyl - Mohawk | R10: 224 | S10: SF | T10: 2.52 | U10: 564.48 | V10: restroom floor only | W10: 62411
A11: Size: 48 x 60 x 12 SF: 2,880 Interior Wall: 262 Total cost for selected items: $163,842.36 Total cost with factors: | B11: $355,469.53 | C11: FRAME | D11: OUTRIGGER | N11: BOM | O11: FLOOR | P11: COVERING | Q11: Underlayment - 1/4" X 4' X 8' Plywood | R11: 128 | S11: SF | T11: 0.62 | U11: 79.36 | V11: For sheet vinyl floor in restrooms only | W11: 62412
A12: Size: 48 x 60 x 12 SF: 2,880 Interior Wall: 262 Total cost for selected items: $163,842.36 Total cost with factors: | B12: $355,469.53 | C12: FRAME | D12: OUTRIGGER | N12: BOM | O12: FLOOR | P12: MISC | Q12: Bottom Board Mobile-Flex | R12: 2910 | S12: SF | T12: 0.07 | U12: 203.7 | W12: 62414
A13: Size: 48 x 60 x 12 SF: 2,880 Interior Wall: 262 Total cost for selected items: $163,842.36 Total cost with factors: | B13: $355,469.53 | C13: FRAME | D13: OUTRIGGER | N13: BOM | O13: EXTERIOR WALL | P13: STUDS | Q13: 2 X 6 Ext. Wall Framing | R13: 2592 | S13: SF | T13: 1.1 | U13: 2851.2 | W13: 62415
A14: Size: 48 x 60 x 12 SF: 2,880 Interior Wall: 262 Total cost for selected items: $163,842.36 Total cost with factors: | B14: $355,469.53 | C14: FRAME | D14: OUTRIGGER | N14: Add On | O14: EXTERIOR WALL | P14: SHEATHING | Q14: Visqueen Vapor Barrier 6 Mil | R14: 640 | S14: SF | T14: 0.1 | U14: 64 | V14: Humidor Vapor Barrier - Install on wall studs, under MR Gyp | W14: 62657
A15: Size: 48 x 60 x 12 SF: 2,880 Interior Wall: 262 Total cost for selected items: $163,842.36 Total cost with factors: | B15: $355,469.53 | C15: FRAME | D15: OUTRIGGER | N15: BOM | O15: EXTERIOR WALL | P15: SIDING | Q15: Smart Panel - 3/8" - 8" O/C Grooves - W/House Wrap | R15: 2592 | S15: SF | T15: 2.22 | U15: 5754.24 | W15: 62418
A16: Size: 48 x 60 x 12 SF: 2,880 Interior Wall: 262 Total cost for selected items: $163,842.36 Total cost with factors: | B16: $355,469.53 | C16: FRAME | D16: OUTRIGGER | N16: Add On | O16: EXTERIOR WALL | P16: COVERING | Q16: 1x4 SE WRC Red Cedar | R16: 224 | S16: LF | T16: 1.44 | U16: 322.56 | V16: Base, Ceiling, and Corner Trim inside Humidor Room | W16: 62662
A17: Size: 48 x 60 x 12 SF: 2,880 Interior Wall: 262 Total cost for selected items: $163,842.36 Total cost with factors: | B17: $355,469.53 | C17: FRAME | D17: OUTRIGGER | N17: Add On | O17: EXTERIOR WALL | P17: COVERING | Q17: 1x6 T&G Red Cedar Siding (Raw) | R17: 512 | S17: SF | T17: 9.77 | U17: 5002.24 | V17: Humidor Room Wall Finish | W17: 62661
A18: Size: 48 x 60 x 12 SF: 2,880 Interior Wall: 262 Total cost for selected items: $163,842.36 Total cost with factors: | B18: $355,469.53 | C18: FRAME | D18: OUTRIGGER | N18: Add On | O18: EXTERIOR WALL | P18: COVERING | Q18: 5/8" MR Gypsum 4 x 12 (Exterior Wall) | R18: 32 | S18: LF | T18: 8.35 | U18: 267.2 | V18: Walls in Humidor room. | W18: 62658
A19: Size: 48 x 60 x 12 SF: 2,880 Interior Wall: 262 Total cost for selected items: $163,842.36 Total cost with factors: | B19: $355,469.53 | C19: FRAME | D19: OUTRIGGER | N19: BOM | O19: EXTERIOR WALL | P19: COVERING | Q19: 5/8" Vinyl Covered Gypsum 9' To 10' Tall (Exterior Wall) | R19: 184 | S19: LF | T19: 12.58 | U19: 2314.72 | V19: 9' VCG panels on exterior walls; VCG finish, except in Humidor room. | W19: 62517
A20: Size: 48 x 60 x 12 SF: 2,880 Interior Wall: 262 Total cost for selected items: $163,842.36 Total cost with factors: | B20: $355,469.53 | C20: FRAME | D20: OUTRIGGER | N20: Add On | O20: EXTERIOR WALL | P20: COVERING | Q20: Sheetrock Tape Only | R20: 256 | S20: SF | T20: 1 | U20: 256 | V20: No texture just joint tape in humidor only. | W20: 62791
A21: Size: 48 x 60 x 12 SF: 2,880 Interior Wall: 262 Total cost for selected items: $163,842.36 Total cost with factors: | B21: $355,469.53 | C21: FRAME | D21: OUTRIGGER | N21: Add On | O21: EXTERIOR WALL | P21: COVERING | Q21: Vapor Barrier Primer | R21: 512 | S21: SF | T21: 0.26 | U21: 133.12 | V21: 2 coats in Humidor only. | W21: 62792
A22: Size: 48 x 60 x 12 SF: 2,880 Interior Wall: 262 Total cost for selected items: $163,842.36 Total cost with factors: | B22: $355,469.53 | C22: FRAME | D22: OUTRIGGER | N22: BOM | O22: EXTERIOR WALL | P22: INSULATION | Q22: R-21 Unfaced (Exterior Wall) | R22: 2592 | S22: SF | T22: 0.56 | U22: 1451.52 | W22: 62420
A23: Size: 48 x 60 x 12 SF: 2,880 Interior Wall: 262 Total cost for selected items: $163,842.36 Total cost with factors: | B23: $355,469.53 | C23: FRAME | D23: OUTRIGGER | N23: BOM | O23: INTERIOR WALL | P23: STUDS | Q23: 2 X 4 Wall Framing - 8' Tall | R23: 292 | S23: LF | T23: 4.72 | U23: 1378.24 | W23: 62421
A24: Size: 48 x 60 x 12 SF: 2,880 Interior Wall: 262 Total cost for selected items: $163,842.36 Total cost with factors: | B24: $355,469.53 | C24: FRAME | D24: OUTRIGGER | N24: BOM | O24: INTERIOR WALL | P24: STUDS | Q24: Upgrade to Plumbing Wall | R24: 8 | S24: LF | T24: 4.21 | U24: 33.68 | V24: 2x6 Plumbing Wall shared by both restrooms | W24: 62422
A25: Size: 48 x 60 x 12 SF: 2,880 Interior Wall: 262 Total cost for selected items: $163,842.36 Total cost with factors: | B25: $355,469.53 | C25: FRAME | D25: OUTRIGGER | N25: BOM | O25: INTERIOR WALL | P25: INSULATION | Q25: R-11 Unfaced Int. Wall @ 8' Tall | R25: 250 | S25: LF | T25: 1.82 | U25: 455 | V25: Insulate All Interior Walls | W25: 62423
A26: Size: 48 x 60 x 12 SF: 2,880 Interior Wall: 262 Total cost for selected items: $163,842.36 Total cost with factors: | B26: $355,469.53 | C26: FRAME | D26: OUTRIGGER | N26: BOM | O26: INTERIOR WALL | P26: COVERING | Q26: 4' FRP Wainscot | R26: 30 | S26: LF | T26: 11.61 | U26: 348.3 | V26: Per code in Restrooms and Janitor Closet | W26: 62424
A27: Size: 48 x 60 x 12 SF: 2,880 Interior Wall: 262 Total cost for selected items: $163,842.36 Total cost with factors: | B27: $355,469.53 | C27: FRAME | D27: OUTRIGGER | N27: Add On | O27: INTERIOR WALL | P27: COVERING | Q27: 5/8" MR Gypsum 4 x 12 (Interior Wall) | R27: 32 | S27: LF | T27: 8.35 | U27: 267.2 | V27: Walls in Humidor room. (1) Side | W27: 62659
A28: Size: 48 x 60 x 12 SF: 2,880 Interior Wall: 262 Total cost for selected items: $163,842.36 Total cost with factors: | B28: $355,469.53 | C28: FRAME | D28: OUTRIGGER | N28: BOM | O28: INTERIOR WALL | P28: COVERING | Q28: 5/8" Type X Gypsum - Unfinished 8' Tall | R28: 48 | S28: LF | T28: 6.65 | U28: 319.2 | V28: 1 hour rated corridor, 1 layer 5/8 type X gyp under VCG - 1 side | W28: 62518
A29: Size: 48 x 60 x 12 SF: 2,880 Interior Wall: 262 Total cost for selected items: $163,842.36 Total cost with factors: | B29: $355,469.53 | C29: FRAME | D29: OUTRIGGER | N29: BOM | O29: INTERIOR WALL | P29: COVERING | Q29: 5/8" Vinyl Covered Gypsum 8' Tall | R29: 246 | S29: LF | T29: 20.74 | U29: 5102.04 | V29: VCG wall finish, except in Humidor room. | W29: 62425
A30: Size: 48 x 60 x 12 SF: 2,880 Interior Wall: 262 Total cost for selected items: $163,842.36 Total cost with factors: | B30: $355,469.53 | C30: FRAME | D30: OUTRIGGER | N30: Add On | O30: INTERIOR WALL | P30: COVERING | Q30: Sheetrock Tape Only | R30: 256 | S30: SF | T30: 1 | U30: 256 | V30: No texture just joint tape in humidor only. | W30: 62793
A31: Size: 48 x 60 x 12 SF: 2,880 Interior Wall: 262 Total cost for selected items: $163,842.36 Total cost with factors: | B31: $355,469.53 | C31: FRAME | D31: OUTRIGGER | N31: Add On | O31: INTERIOR WALL | P31: COVERING | Q31: Vapor Barrier Primer | R31: 512 | S31: SF | T31: 0.26 | U31: 133.12 | V31: 2 coats in Humidor only. | W31: 62794
A32: Size: 48 x 60 x 12 SF: 2,880 Interior Wall: 262 Total cost for selected items: $163,842.36 Total cost with factors: | B32: $355,469.53 | C32: FRAME | D32: OUTRIGGER | N32: BOM | O32: INTERIOR WALL | P32: COLUMNS | Q32: Roof Support Column - Concealed | R32: 18 | S32: EA | T32: 59.29 | U32: 1067.22 | V32: Concealed in both end walls at mod lines and one pair of columns concealed inside interior walls at each mod line | W32: 62426
A33: Size: 48 x 60 x 12 SF: 2,880 Interior Wall: 262 Total cost for selected items: $163,842.36 Total cost with factors: | B33: $355,469.53 | C33: FRAME | D33: OUTRIGGER | N33: BOM | O33: INTERIOR WALL | P33: MISC | Q33: Interior Shearwall - Add | R33: 48 | S33: LF | T33: 9.44 | U33: 453.12 | V33: Full Height Shear Wall | W33: 62519
A34: Size: 48 x 60 x 12 SF: 2,880 Interior Wall: 262 Total cost for selected items: $163,842.36 Total cost with factors: | B34: $355,469.53 | C34: FRAME | D34: OUTRIGGER | N34: BOM | O34: INTERIOR WALL | P34: MISC | Q34: Wall Extended To Rafters | R34: 208 | S34: LF | T34: 5.83 | U34: 1212.64 | V34: Rated Corridor, Restrooms, Humidor room | W34: 62427
A35: Size: 48 x 60 x 12 SF: 2,880 Interior Wall: 262 Total cost for selected items: $163,842.36 Total cost with factors: | B35: $355,469.53 | C35: FRAME | D35: OUTRIGGER | N35: BOM | O35: COVE BASE | P35: COVE BASE | Q35: Wall Base Vinyl 4" | R35: 740 | S35: LF | T35: 1.02 | U35: 754.8 | V35: Throughout Except in Humidor Room | W35: 62428
... A37: Size: 48 x 60 x 12 SF: 2,880 Interior Wall: 262 Total cost for selected items: $163,842.36 Total cost with factors: | B37: $355,469.53 | C37: FRAME | D37: OUTRIGGER | N37: BOM | O37: ROOF | P37: MATE BEAM | Q37: LVL - 1 1/2" x 24"- Up to 60' | R37: 600 | S37: LF | T37: 10.93 | U37: 6558 | V37: Double LVL at mod line spanning gym. | W37: 62430
A38: Size: 48 x 60 x 12 SF: 2,880 Interior Wall: 262 Total cost for selected items: $163,842.36 Total cost with factors: | B38: $355,469.53 | C38: FRAME | D38: OUTRIGGER | N38: BOM | O38: ROOF | P38: MATE BEAM | Q38: Modline Strap | R38: 3 | S38: SET | T38: 60.16 | U38: 180.48 | W38: 62431
A39: Size: 48 x 60 x 12 SF: 2,880 Interior Wall: 262 Total cost for selected items: $163,842.36 Total cost with factors: | B39: $355,469.53 | C39: FRAME | D39: OUTRIGGER | N39: BOM | O39: ROOF | P39: INSULATION | Q39: R-38 Unfaced | R39: 2880 | S39: SF | T39: 1.02 | U39: 2937.6 | W39: 62522
A40: Size: 48 x 60 x 12 SF: 2,880 Interior Wall: 262 Total cost for selected items: $163,842.36 Total cost with factors: | B40: $355,469.53 | C40: FRAME | D40: OUTRIGGER | N40: BOM | O40: ROOF | P40: DECKING | Q40: 5/8" OSB Decking | R40: 2880 | S40: SF | T40: 0.48 | U40: 1382.4 | W40: 62523
A41: Size: 48 x 60 x 12 SF: 2,880 Interior Wall: 262 Total cost for selected items: $163,842.36 Total cost with factors: | B41: $355,469.53 | C41: FRAME | D41: OUTRIGGER | N41: BOM | O41: ROOF | P41: COVERING | Q41: EPDM .045 - Black (Multi Wides) Class C | R41: 2880 | S41: SF | T41: 2.14 | U41: 6163.2 | W41: 62435
...

Sheet Sheet1
A1: Cat & SubCat | B1: =+'Paste Here'!N1 -> Item | C1: =+'Paste Here'!O1 -> Category | D1: =+'Paste Here'!P1 -> SubCategory | E1: =+'Paste Here'!Q1 -> QuoteDetailDesc | F1: =+'Paste Here'!R1 -> Quantity | G1: =+'Paste Here'!S1 -> UM | H1: =+'Paste Here'!T1 -> ItemPrice | I1: =+'Paste Here'!U1 -> TotalPrice | ... K1: =+'Paste Here'!W1 -> QuoteDetailsKey
A2: =+CONCATENATE(C2,D2) -> FRAMEOUTRIGGER | B2: =+'Paste Here'!N2 -> BOM | C2: =+'Paste Here'!O2 -> FRAME | D2: =+'Paste Here'!P2 -> OUTRIGGER | E2: =+'Paste Here'!Q2 -> Chassis Basement 12' X 60' - 12" X 11.8# I-Beam OR/CM/MC 8'/8'/8' | F2: =+'Paste Here'!R2 -> 4 | G2: =+'Paste Here'!S2 -> EA | H2: =+'Paste Here'!T2 -> 2632.92 | I2: =+'Paste Here'!U2 -> 10531.68 | ... K2: =+'Paste Here'!W2 -> 62405
A3: =+CONCATENATE(C3,D3) -> FRAMEAXLES | B3: =+'Paste Here'!N3 -> BOM | C3: =+'Paste Here'!O3 -> FRAME | D3: =+'Paste Here'!P3 -> AXLES | E3: =+'Paste Here'!Q3 -> Five Axle (5 Brake Axles) | F3: =+'Paste Here'!R3 -> 4 | G3: =+'Paste Here'!S3 -> EA | H3: =+'Paste Here'!T3 -> 2033.65 | I3: =+'Paste Here'!U3 -> 8134.6 | ... K3: =+'Paste Here'!W3 -> 62504
A4: =+CONCATENATE(C4,D4) -> FRAMEMISC | B4: =+'Paste Here'!N4 -> BOM | C4: =+'Paste Here'!O4 -> FRAME | D4: =+'Paste Here'!P4 -> MISC | E4: =+'Paste Here'!Q4 -> Outrigger For 12' Wide (Add-On) | F4: =+'Paste Here'!R4 -> 8 | G4: =+'Paste Here'!S4 -> PAIR | H4: =+'Paste Here'!T4 -> 25.46 | I4: =+'Paste Here'!U4 -> 203.68 | ... K4: =+'Paste Here'!W4 -> 62407
A5: =+CONCATENATE(C5,D5) -> FLOORJOIST | B5: =+'Paste Here'!N5 -> BOM | C5: =+'Paste Here'!O5 -> FLOOR | D5: =+'Paste Here'!P5 -> JOIST | E5: =+'Paste Here'!Q5 -> 2 X 8 @ 12" O/C | F5: =+'Paste Here'!R5 -> 2380 | G5: =+'Paste Here'!S5 -> SF | H5: =+'Paste Here'!T5 -> 1.28 | I5: =+'Paste Here'!U5 -> 3046.4 | ... K5: =+'Paste Here'!W5 -> 62514
A6: =+CONCATENATE(C6,D6) -> FLOORJOIST | B6: =+'Paste Here'!N6 -> BOM | C6: =+'Paste Here'!O6 -> FLOOR | D6: =+'Paste Here'!P6 -> JOIST | E6: =+'Paste Here'!Q6 -> 2 X 8 @ 16" O/C | F6: =+'Paste Here'!R6 -> 500 | G6: =+'Paste Here'!S6 -> SF | H6: =+'Paste Here'!T6 -> 1.1 | I6: =+'Paste Here'!U6 -> 550 | ... K6: =+'Paste Here'!W6 -> 62408
A7: =+CONCATENATE(C7,D7) -> FLOORDECKING | B7: =+'Paste Here'!N7 -> BOM | C7: =+'Paste Here'!O7 -> FLOOR | D7: =+'Paste Here'!P7 -> DECKING | E7: =+'Paste Here'!Q7 -> 1-1/8" T&G OSB | F7: =+'Paste Here'!R7 -> 2880 | G7: =+'Paste Here'!S7 -> SF | H7: =+'Paste Here'!T7 -> 1.15 | I7: =+'Paste Here'!U7 -> 3312 | ... K7: =+'Paste Here'!W7 -> 62515
A8: =+CONCATENATE(C8,D8) -> FLOORINSULATION | B8: =+'Paste Here'!N8 -> BOM | C8: =+'Paste Here'!O8 -> FLOOR | D8: =+'Paste Here'!P8 -> INSULATION | E8: =+'Paste Here'!Q8 -> R-30 Unfaced (2 layers R-15) | F8: =+'Paste Here'!R8 -> 2880 | G8: =+'Paste Here'!S8 -> SF | H8: =+'Paste Here'!T8 -> 1.39 | I8: =+'Paste Here'!U8 -> 4003.2 | ... K8: =+'Paste Here'!W8 -> 62410
A9: =+CONCATENATE(C9,D9) -> FLOORCOVERING | B9: =+'Paste Here'!N9 -> BOM | C9: =+'Paste Here'!O9 -> FLOOR | D9: =+'Paste Here'!P9 -> COVERING | E9: =+'Paste Here'!Q9 -> Floor Tile VCT - 1/8" X 12" X 12" | F9: =+'Paste Here'!R9 -> 2760 | G9: =+'Paste Here'!S9 -> SF | H9: =+'Paste Here'!T9 -> 1.57 | I9: =+'Paste Here'!U9 -> 4333.2 | ... K9: =+'Paste Here'!W9 -> 62413
A10: =+CONCATENATE(C10,D10) -> FLOORCOVERING | B10: =+'Paste Here'!N10 -> BOM | C10: =+'Paste Here'!O10 -> FLOOR | D10: =+'Paste Here'!P10 -> COVERING | E10: =+'Paste Here'!Q10 -> Sheet Vinyl - Mohawk | F10: =+'Paste Here'!R10 -> 224 | G10: =+'Paste Here'!S10 -> SF | H10: =+'Paste Here'!T10 -> 2.52 | I10: =+'Paste Here'!U10 -> 564.48 | ... K10: =+'Paste Here'!W10 -> 62411
A11: =+CONCATENATE(C11,D11) -> FLOORCOVERING | B11: =+'Paste Here'!N11 -> BOM | C11: =+'Paste Here'!O11 -> FLOOR | D11: =+'Paste Here'!P11 -> COVERING | E11: =+'Paste Here'!Q11 -> Underlayment - 1/4" X 4' X 8' Plywood | F11: =+'Paste Here'!R11 -> 128 | G11: =+'Paste Here'!S11 -> SF | H11: =+'Paste Here'!T11 -> 0.62 | I11: =+'Paste Here'!U11 -> 79.36 | ... K11: =+'Paste Here'!W11 -> 62412
A12: =+CONCATENATE(C12,D12) -> FLOORMISC | B12: =+'Paste Here'!N12 -> BOM | C12: =+'Paste Here'!O12 -> FLOOR | D12: =+'Paste Here'!P12 -> MISC | E12: =+'Paste Here'!Q12 -> Bottom Board Mobile-Flex | F12: =+'Paste Here'!R12 -> 2910 | G12: =+'Paste Here'!S12 -> SF | H12: =+'Paste Here'!T12 -> 0.07 | I12: =+'Paste Here'!U12 -> 203.7 | ... K12: =+'Paste Here'!W12 -> 62414
A13: =+CONCATENATE(C13,D13) -> EXTERIOR WALLSTUDS | B13: =+'Paste Here'!N13 -> BOM | C13: =+'Paste Here'!O13 -> EXTERIOR WALL | D13: =+'Paste Here'!P13 -> STUDS | E13: =+'Paste Here'!Q13 -> 2 X 6 Ext. Wall Framing | F13: =+'Paste Here'!R13 -> 2592 | G13: =+'Paste Here'!S13 -> SF | H13: =+'Paste Here'!T13 -> 1.1 | I13: =+'Paste Here'!U13 -> 2851.2 | ... K13: =+'Paste Here'!W13 -> 62415
... A1032: =+CONCATENATE(C1032,D1032) -> 00 | B1032: =+'Paste Here'!N1032 -> 0 | C1032: =+'Paste Here'!O1032 -> 0 | D1032: =+'Paste Here'!P1032 -> 0 | E1032: =+'Paste Here'!Q1032 -> 0 | F1032: =+'Paste Here'!R1032 -> 0 | G1032: =+'Paste Here'!S1032 -> 0 | H1032: =+'Paste Here'!T1032 -> 0 | I1032: =+'Paste Here'!U1032 -> 0 | ... K1032: =+'Paste Here'!W1032 -> 0

Sheet Check
A1: Building Width | B1: 48 | D1: SQFT | E1: =+B1*B2 -> 2880
A2: Building Length | B2: 60 | D2: Perimeter Length | E2: =+(B1+B2)*2 -> 216
A3: Building Height | B3: 12 | D3: Perimeter SQFT | E3: =+E2*B3 -> 2592
A4: Mods | B4: 4
A5: Interior Wall LF | B5: 262
A7: Category | B7: SubCategory | C7: Description | D7: Value Found | E7: Value Expected | F7: Deviance | G7: Notes
A8: FRAME | B8: OUTRIGGER | C8: - | D8: =+SUMIF('Paste Here'!P:P,B8,'Paste Here'!R:R) -> 4 | E8: =+$B$4 -> 4 | F8: =+D8-E8 -> 0
A9: FRAME | B9: AXLES | C9: =+VLOOKUP(B9,'Paste Here'!P:Q,2,FALSE) -> Five Axle (5 Brake Axles) | D9: =+SUMIF('Paste Here'!P:P,B9,'Paste Here'!R:R) -> 4 | E9: =+$B$4 -> 4 | F9: =+D9-E9 -> 0
A10: FLOOR | B10: JOIST | C10: =+VLOOKUP(B10,'Paste Here'!P:Q,2,FALSE) -> 2 X 8 @ 12" O/C | D10: =+SUMIFS('Paste Here'!R:R,'Paste Here'!P:P,B10,'Paste Here'!O:O,A10) -> 2880 | E10: =+$E$1 -> 2880 | F10: =+D10-E10 -> 0
A11: FLOOR | B11: DECKING | C11: =+VLOOKUP(B11,'Paste Here'!P:Q,2,FALSE) -> 1-1/8" T&G OSB | D11: =+SUMIFS('Paste Here'!R:R,'Paste Here'!P:P,B11,'Paste Here'!O:O,Check!A11) -> 2880 | E11: =+$E$1 -> 2880 | F11: =+D11-E11 -> 0
A12: FLOOR | B12: INSULATION | C12: =+VLOOKUP(B12,'Paste Here'!P:Q,2,FALSE) -> R-30 Unfaced (2 layers R-15) | D12: =+SUMIFS('Paste Here'!R:R,'Paste Here'!P:P,B12,'Paste Here'!O:O,Check!A12) -> 2880 | E12: =+$E$1 -> 2880 | F12: =+D12-E12 -> 0
A13: FLOOR | B13: COVERING | C13: =IFERROR(+VLOOKUP(A13&B13,Sheet1!A:F,5,FALSE),"-") -> Floor Tile VCT - 1/8" X 12" X 12" | D13: =IF(SUMIFS('Paste Here'!R:R,'Paste Here'!P:P,B13,'Paste Here'!O:O,Check!A13)>$E$1*1.2,SUMIFS('Paste Here'!R:R,'Paste Here'!P:P,B13,'Paste Here'!O:O,Check!A13),$E$1) -> 2880 | E13: =+$E$1 -> 2880 | F13: =+D13-E13 -> 0 | G13: Value expected often less than actual with rolled goods
A14: EXTERIOR WALL | B14: STUDS | C14: =IFERROR(+VLOOKUP(A14&B14,Sheet1!A:F,5,FALSE),"-") -> 2 X 6 Ext. Wall Framing | D14: =IFERROR(VLOOKUP(A14&B14,Sheet1!A:F,6,FALSE),0) -> 2592 | E14: =($B$1+$B$2)*$B$3*2 -> 2592 | F14: =+D14-E14 -> 0
A15: EXTERIOR WALL | B15: SHEATHING | C15: =IFERROR(+VLOOKUP(A15&B15,Sheet1!A:F,5,FALSE),"-") -> Visqueen Vapor Barrier 6 Mil | D15: =IFERROR(VLOOKUP(A15&B15,Sheet1!A:F,6,FALSE),0) -> 640 | E15: =IF(IFERROR(MATCH("Smart Panel",C16,-1),0)=0,perimsqft,IF($B$2/($B$1)>4,$B$1*$B$3*2,0)) -> 0 | F15: =+D15-E15 -> 640 | G15: If building length is 4x greater than width, sheathing on end walls
A16: EXTERIOR WALL | B16: SIDING | C16: =IFERROR(+VLOOKUP(A16&B16,Sheet1!A:F,5,FALSE),"-") -> Smart Panel - 3/8" - 8" O/C Grooves - W/House Wrap | D16: =+SUMIFS('Paste Here'!R:R,'Paste Here'!P:P,B16,'Paste Here'!O:O,Check!A16) -> 2592 | E16: =($B$1+$B$2)*$B$3*2 -> 2592 | F16: =+D16-E16 -> 0 | G16: =MATCH("Smart Panel",Table1[[#This Row],[Description]],-1) -> 1
A17: EXTERIOR WALL | B17: COVERING | C17: =IFERROR(+VLOOKUP(A17&B17,Sheet1!A:F,5,FALSE),"-") -> 1x4 SE WRC Red Cedar | D17: =IFERROR(VLOOKUP(A17&B17,Sheet1!A:F,6,FALSE),0) -> 224 | E17: =($B$1+$B$2)*2 -> 216 | F17: =+D17-E17 -> 8
A18: EXTERIOR WALL | B18: INSULATION | C18: =IFERROR(+VLOOKUP(A18&B18,Sheet1!A:F,5,FALSE),"-") -> R-21 Unfaced (Exterior Wall) | D18: =IFERROR(VLOOKUP(A18&B18,Sheet1!A:F,6,FALSE),0) -> 2592 | E18: =($B$1+$B$2)*$B$3*2 -> 2592 | F18: =+D18-E18 -> 0
A19: INTERIOR WALL | B19: STUDS | C19: =IFERROR(+VLOOKUP(A19&B19,Sheet1!A:F,5,FALSE),"-") -> 2 X 4 Wall Framing - 8' Tall | D19: =+SUMIF(Sheet1!A:A,Check!A19&Check!B19,Sheet1!F:F) -> 300 | E19: =+$B$5 -> 262 | F19: =+D19-E19 -> 38
A20: INTERIOR WALL | B20: INSULATION | C20: =IFERROR(+VLOOKUP(A20&B20,Sheet1!A:F,5,FALSE),"-") -> R-11 Unfaced Int. Wall @ 8' Tall | D20: =IFERROR(VLOOKUP(A20&B20,Sheet1!A:F,6,FALSE),0) -> 250 | E20: =+D20 -> 250 | F20: =+D20-E20 -> 0
A21: INTERIOR WALL | B21: COVERING | C21: 4' FRP Wainscot | D21: =+VLOOKUP(Table1[[#This Row],[Description]],'Paste Here'!Q:R,2,FALSE) -> 30 | E21: =+MAX(D50*10) -> 20 | F21: =+D21-E21 -> 10
A22: INTERIOR WALL | B22: COVERING | C22: =IFERROR(+VLOOKUP(A22&B22,Sheet1!A:F,5,FALSE),"-") -> 4' FRP Wainscot | D22: =+SUMIFS('Paste Here'!R:R,'Paste Here'!P:P,B22,'Paste Here'!O:O,Check!A22) -> 1124 | E22: =+intwall -> 262 | F22: =+D22-E22 -> 862
A23: INTERIOR WALL | B23: COLUMNS | C23: =IFERROR(+VLOOKUP(A23&B23,Sheet1!A:F,5,FALSE),"-") -> Roof Support Column - Concealed | D23: =+SUMIFS('Paste Here'!R:R,'Paste Here'!P:P,B23,'Paste Here'!O:O,Check!A23) -> 18 | E23: =+IF(MODS=1,0,IF(LENGTH>40,(MODS-1)*4,(MODS-1)*2)) -> 12 | F23: =+D23-E23 -> 6
A24: INTERIOR WALL | B24: MISC | C24: Interior Shearwall - Add | D24: =IFERROR(VLOOKUP(A24&B24,Sheet1!A:F,6,FALSE),0) -> 48 | E24: =IF($B$2/($B$1/$B$4)>4,$B$1,0) -> 48 | F24: =+D24-E24 -> 0
A25: COVE BASE | B25: COVE BASE | C25: =IFERROR(+VLOOKUP(A25&B25,Sheet1!A:F,5,FALSE),"-") -> Wall Base Vinyl 4" | D25: =IFERROR(VLOOKUP(A25&B25,Sheet1!A:F,6,FALSE),0) -> 740 | E25: =+intwall*2+perimeter -> 740 | F25: =+D25-E25 -> 0
A26: ROOF | B26: TRUSSES | C26: =IFERROR(+VLOOKUP(A26&B26,Sheet1!A:F,5,FALSE),"-") -> Truss - 12' Wide Mod-Transverse 24" O/C | D26: =IFERROR(VLOOKUP(A26&B26,Sheet1!A:F,6,FALSE),0) -> 2880 | E26: =+sqft -> 2880 | F26: =+D26-E26 -> 0
A27: ROOF | B27: JOIST | C27: =IFERROR(+VLOOKUP(A27&B27,Sheet1!A:F,5,FALSE),"-") -> - | D27: =IFERROR(VLOOKUP(A27&B27,Sheet1!A:F,6,FALSE),0) -> 0 | E27: =+IF(D26<>0,0,sqft) -> 0 | F27: =+D27-E27 -> 0
A28: ROOF | B28: MATE BEAM | C28: =IFERROR(+VLOOKUP(A28&B28,Sheet1!A:F,5,FALSE),"-") -> LVL - 1 1/2" x 24"- Up to 60' | D28: =IFERROR(VLOOKUP(A28&B28,Sheet1!A:F,6,FALSE),0) -> 600 | E28: =+IF(B4>2,B2*2*B4,IF(B4=1,0,B2*2)) -> 480 | F28: =+D28-E28 -> 120
A29: ROOF | B29: INSULATION | C29: =IFERROR(+VLOOKUP(A29&B29,Sheet1!A:F,5,FALSE),"-") -> R-38 Unfaced | D29: =IFERROR(VLOOKUP(A29&B29,Sheet1!A:F,6,FALSE),0) -> 2880 | E29: =+sqft -> 2880 | F29: =+D29-E29 -> 0
A30: ROOF | B30: DECKING | C30: =IFERROR(+VLOOKUP(A30&B30,Sheet1!A:F,5,FALSE),"-") -> 5/8" OSB Decking | D30: =IFERROR(VLOOKUP(A30&B30,Sheet1!A:F,6,FALSE),0) -> 2880 | E30: =+sqft -> 2880 | F30: =+D30-E30 -> 0
A31: ROOF | B31: COVERING | C31: =IFERROR(+VLOOKUP(A31&B31,Sheet1!A:F,5,FALSE),"-") -> EPDM .045 - Black (Multi Wides) Class C | D31: =IFERROR(VLOOKUP(A31&B31,Sheet1!A:F,6,FALSE),0) -> 2880 | E31: =+sqft -> 2880 | F31: =+D31-E31 -> 0
A32: ROOF | B32: CEILING | C32: =IFERROR(+VLOOKUP(A32&B32,Sheet1!A:F,5,FALSE),"-") -> 1x8 SE WRC Red Cedar | D32: =IFERROR(VLOOKUP(A32&B32,Sheet1!A:F,6,FALSE),0) -> 252 | E32: =+sqft -> 2880 | F32: =+D32-E32 -> -2628
A33: WINDOW | B33: MISC | C33: =IFERROR(+VLOOKUP(A33&B33,Sheet1!A:F,5,FALSE),"-") -> Farmyard Hickory Window Trim Upgrade | D33: =IFERROR(VLOOKUP(A33&B33,Sheet1!A:F,6,FALSE),0) -> 9 | E33: - | F33: 0
A34: WINDOW | B34: WINDOW 4030 - VINYL | C34: =IFERROR(+VLOOKUP(A34&B34,Sheet1!A:F,5,FALSE),"-") -> 4030 - H/S - Dual Glazed - Vinyl Frame - Clear Low E | D34: =IFERROR(VLOOKUP(A34&B34,Sheet1!A:F,6,FALSE),0) -> 9 | E34: - | F34: 0
A35: EXTERIOR DOOR | B35: DOOR | C35: =IFERROR(+VLOOKUP(A35&B35,Sheet1!A:F,5,FALSE),"-") -> 36X80 - 20ga Door W/Med Adj. Steel Frame (4-5/8" to 8") | D35: =IFERROR(VLOOKUP(A35&B35,Sheet1!A:F,6,FALSE),0) -> 2 | E35: - | F35: 0
A36: EXTERIOR DOOR | B36: LOCKSET | C36: =IFERROR(+VLOOKUP(A36&B36,Sheet1!A:F,5,FALSE),"-") -> Cal-Royal A2200 Panic Rim Exit Device with Escutcheon Entrance Lever Trim | D36: =IFERROR(VLOOKUP(A36&B36,Sheet1!A:F,6,FALSE),0) -> 2 | E36: - | F36: 0
A37: EXTERIOR DOOR | B37: HARDWARE | C37: =IFERROR(+VLOOKUP(A37&B37,Sheet1!A:F,5,FALSE),"-") -> Closer - S Parker 900 BCAL | D37: =IFERROR(VLOOKUP(A37&B37,Sheet1!A:F,6,FALSE),0) -> 2 | E37: - | F37: 0
A38: INTERIOR DOOR | B38: DOOR | C38: =IFERROR(+VLOOKUP(A38&B38,Sheet1!A:F,5,FALSE),"-") -> 36X80 - 20-Minute Label - Alpine Oak - W/ Timely Jamb | D38: =IFERROR(VLOOKUP(A38&B38,Sheet1!A:F,6,FALSE),0) -> 7 | E38: - | F38: 0
A39: INTERIOR DOOR | B39: LOCKSET | C39: =IFERROR(+VLOOKUP(A39&B39,Sheet1!A:F,5,FALSE),"-") -> Passage - Grade 2 - Lever | D39: =IFERROR(VLOOKUP(A39&B39,Sheet1!A:F,6,FALSE),0) -> 9 | E39: - | F39: 0
A40: INTERIOR DOOR | B40: HARDWARE | C40: =IFERROR(+VLOOKUP(A40&B40,Sheet1!A:F,5,FALSE),"-") -> - | D40: =IFERROR(VLOOKUP(A40&B40,Sheet1!A:F,6,FALSE),0) -> 0 | E40: - | F40: 0
A41: ELECTRICAL | B41: PANEL | C41: =IFERROR(+VLOOKUP(A41&B41,Sheet1!A:F,5,FALSE),"-") -> Nema 3R, External, 200 Amp Single Phase W/Main | D41: =IFERROR(VLOOKUP(A41&B41,Sheet1!A:F,6,FALSE),0) -> 2 | E41: Check Calculator | F41: =IF(D41<>0,"CHECK CALC","ADD PANEL") -> CHECK CALC
...
